{"type":"trade","sid":2,"seq":136,"msg":{"trade_id":"5bee7851-7a13-6faf-52a6-570f89c54e61","market_ticker":"KXBTCPERP1","price":"6.3616","count":"1.00","taker_side":"ask","ts_ms":1781237160276}}

{"type":"trade","sid":2,"seq":137,"msg":{"trade_id":"94921fcb-79c8-621f-6c24-817e2502d0bf","market_ticker":"KXBTCPERP1","price":"6.3616","count":"1.00","taker_side":"ask","ts_ms":1781237160276}}

{"type":"trade","sid":2,"seq":138,"msg":{"trade_id":"b54ef69f-ef14-6318-4a69-b14f4063c284","market_ticker":"KXBTCPERP1","price":"6.3616","count":"1.00","taker_side":"ask","ts_ms":1781237160276}}

{"type":"trade","sid":2,"seq":139,"msg":{"trade_id":"4763dc48-547d-6dea-4c45-4c06b0796746","market_ticker":"KXBTCPERP1","price":"6.3615","count":"1.00","taker_side":"ask","ts_ms":1781237160276}}

{"type":"trade","sid":2,"seq":140,"msg":{"trade_id":"ee1c5c80-7e1d-6e4a-775a-c2989abd7884","market_ticker":"KXBTCPERP1","price":"6.3614","count":"1.00","taker_side":"ask","ts_ms":1781237160276}}

{"type":"trade","sid":2,"seq":141,"msg":{"trade_id":"9a0c9fca-370a-6e70-75ae-66fbc81a3f8d","market_ticker":"KXBTCPERP1","price":"6.3614","count":"1.00","taker_side":"ask","ts_ms":1781237160276}}

{"type":"trade","sid":2,"seq":142,"msg":{"trade_id":"a98483ad-e64a-6aa2-666a-c553a4e9a951","market_ticker":"KXBTCPERP1","price":"6.3614","count":"1.00","taker_side":"ask","ts_ms":1781237160276}}

{"type":"trade","sid":2,"seq":143,"msg":{"trade_id":"ba005801-dd37-6c9b-4735-695a07972fb6","market_ticker":"KXBTCPERP1","price":"6.3614","count":"1.00","taker_side":"ask","ts_ms":1781237160276}}

{"type":"trade","sid":2,"seq":144,"msg":{"trade_id":"e0928acf-039d-66bd-458c-ffec6153698f","market_ticker":"KXBTCPERP1","price":"6.3614","count":"1.00","taker_side":"ask","ts_ms":1781237160276}}

{"type":"trade","sid":2,"seq":145,"msg":{"trade_id":"52bf7389-bd04-6d0e-4c5b-1eb7d9183b3e","market_ticker":"KXBTCPERP1","price":"6.3613","count":"1.00","taker_side":"ask","ts_ms":1781237160276}}

{"type":"trade","sid":2,"seq":146,"msg":{"trade_id":"e3c4e88f-1303-669f-5c99-301a90b4b3c1","market_ticker":"KXBTCPERP1","price":"6.3613","count":"1.00","taker_side":"ask","ts_ms":1781237160276}}

{"type":"trade","sid":2,"seq":147,"msg":{"trade_id":"d60e4cde-9d3c-64bb-4af3-f1ea033153b3","market_ticker":"KXBTCPERP1","price":"6.3613","count":"1.00","taker_side":"ask","ts_ms":1781237160276}}

{"type":"trade","sid":2,"seq":148,"msg":{"trade_id":"1b65430b-99bc-66b7-67db-7a151c9a527d","market_ticker":"KXBTCPERP1","price":"6.3612","count":"1.00","taker_side":"ask","ts_ms":1781237160276}}

{"type":"trade","sid":2,"seq":149,"msg":{"trade_id":"f780207e-dfff-60f2-7d07-3a15d09f2ff7","market_ticker":"KXBTCPERP1","price":"6.3612","count":"1.00","taker_side":"ask","ts_ms":1781237160276}}

{"type":"trade","sid":2,"seq":150,"msg":{"trade_id":"3175eb01-1516-6484-6d54-5fc89ce0dc93","market_ticker":"KXBTCPERP1","price":"6.3612","count":"1.00","taker_side":"ask","ts_ms":1781237160276}}

{"type":"trade","sid":2,"seq":151,"msg":{"trade_id":"0d328c54-1bcc-6caf-7619-11c6fb9b96f9","market_ticker":"KXBTCPERP1","price":"6.3611","count":"1.00","taker_side":"ask","ts_ms":1781237160276}}

{"type":"trade","sid":2,"seq":152,"msg":{"trade_id":"7ad293af-d02f-6a1f-7fe7-2764419c6f82","market_ticker":"KXBTCPERP1","price":"6.3610","count":"1.00","taker_side":"ask","ts_ms":1781237160276}}

{"type":"trade","sid":2,"seq":153,"msg":{"trade_id":"9c8a6223-daa5-655a-50e7-9dfb9cea6916","market_ticker":"KXBTCPERP1","price":"6.3610","count":"1.00","taker_side":"ask","ts_ms":1781237160276}}

{"type":"trade","sid":2,"seq":154,"msg":{"trade_id":"2c3f9d37-5f56-68b2-697d-da7539e32da8","market_ticker":"KXBTCPERP1","price":"6.3610","count":"1.00","taker_side":"ask","ts_ms":1781237160276}}

{"type":"trade","sid":2,"seq":155,"msg":{"trade_id":"8d645e52-2c3b-6731-4d25-c119c5b2340e","market_ticker":"KXBTCPERP1","price":"6.3610","count":"1.00","taker_side":"ask","ts_ms":1781237160276}}

{"type":"trade","sid":2,"seq":156,"msg":{"trade_id":"86c9aca7-5f19-65e1-787c-e836602c8e8b","market_ticker":"KXBTCPERP1","price":"6.3609","count":"1.00","taker_side":"ask","ts_ms":1781237160276}}

{"type":"trade","sid":2,"seq":157,"msg":{"trade_id":"1e8862b1-37d1-6bf8-4139-6e0fe761c91c","market_ticker":"KXBTCPERP1","price":"6.3608","count":"1.00","taker_side":"ask","ts_ms":1781237160276}}

{"type":"trade","sid":2,"seq":158,"msg":{"trade_id":"78ac787f-4d05-60de-65c7-0867f2159258","market_ticker":"KXBTCPERP1","price":"6.3608","count":"1.00","taker_side":"ask","ts_ms":1781237160276}}

{"type":"trade","sid":2,"seq":159,"msg":{"trade_id":"c8d09ece-673d-6c39-620b-b33fb40020bf","market_ticker":"KXBTCPERP1","price":"6.3608","count":"1.00","taker_side":"ask","ts_ms":1781237160276}}

{"type":"trade","sid":2,"seq":160,"msg":{"trade_id":"2ac581d4-7ae9-6096-4c51-fe69cc1aef61","market_ticker":"KXBTCPERP1","price":"6.3606","count":"1.00","taker_side":"ask","ts_ms":1781237160276}}

{"type":"trade","sid":2,"seq":161,"msg":{"trade_id":"418bd4df-e735-62be-7567-b3afc6aa1faa","market_ticker":"KXBTCPERP1","price":"6.3606","count":"1.00","taker_side":"ask","ts_ms":1781237160276}}

{"type":"trade","sid":2,"seq":162,"msg":{"trade_id":"bb741bc5-e6cc-6708-6b1a-a1460744fafe","market_ticker":"KXBTCPERP1","price":"6.3606","count":"1.00","taker_side":"ask","ts_ms":1781237160276}}

{"type":"trade","sid":2,"seq":163,"msg":{"trade_id":"b8bd498f-9195-60ce-4fa5-8c031ba9012e","market_ticker":"KXBTCPERP1","price":"6.3606","count":"1.00","taker_side":"ask","ts_ms":1781237160276}}

{"type":"trade","sid":2,"seq":164,"msg":{"trade_id":"afafb3fe-f030-621c-6478-4dcfab6f2640","market_ticker":"KXBTCPERP1","price":"6.3605","count":"1.00","taker_side":"ask","ts_ms":1781237160276}}

{"type":"trade","sid":2,"seq":165,"msg":{"trade_id":"32c41320-eba4-6af1-44e2-9c26d0266099","market_ticker":"KXBTCPERP1","price":"6.3605","count":"1.00","taker_side":"ask","ts_ms":1781237160276}}

{"type":"trade","sid":2,"seq":166,"msg":{"trade_id":"3029ba63-b774-6830-5519-2fedd28ec4c0","market_ticker":"KXBTCPERP1","price":"6.3605","count":"1.00","taker_side":"ask","ts_ms":1781237160276}}

{"type":"trade","sid":2,"seq":167,"msg":{"trade_id":"ecd74f96-708b-6acb-4906-589fbc27d8ec","market_ticker":"KXBTCPERP1","price":"6.3605","count":"1.00","taker_side":"ask","ts_ms":1781237160276}}

{"type":"trade","sid":2,"seq":168,"msg":{"trade_id":"c9aa53cf-5dd8-61d3-48af-d45ffbf97992","market_ticker":"KXBTCPERP1","price":"6.3604","count":"1.00","taker_side":"ask","ts_ms":1781237160276}}

{"type":"trade","sid":2,"seq":169,"msg":{"trade_id":"0ae8fa3f-e835-621e-4ef8-f94e1dcd0dfc","market_ticker":"KXBTCPERP1","price":"6.3604","count":"1.00","taker_side":"ask","ts_ms":1781237160276}}

{"type":"trade","sid":2,"seq":170,"msg":{"trade_id":"862a7e1c-4aa4-6333-5774-a7d4917292f6","market_ticker":"KXBTCPERP1","price":"6.3603","count":"1.00","taker_side":"ask","ts_ms":1781237160276}}

{"type":"trade","sid":2,"seq":171,"msg":{"trade_id":"d9110650-e457-6c5a-7c83-13fd1fe8546e","market_ticker":"KXBTCPERP1","price":"6.3603","count":"1.00","taker_side":"ask","ts_ms":1781237160276}}

{"type":"trade","sid":2,"seq":172,"msg":{"trade_id":"819cbd2f-7c87-6f9b-61aa-ef121a0a2335","market_ticker":"KXBTCPERP1","price":"6.3603","count":"1.00","taker_side":"ask","ts_ms":1781237160276}}

{"type":"trade","sid":2,"seq":173,"msg":{"trade_id":"4e91ea6a-1e87-6f06-4e44-41574a64ff16","market_ticker":"KXBTCPERP1","price":"6.3603","count":"1.00","taker_side":"ask","ts_ms":1781237160276}}

{"type":"trade","sid":2,"seq":174,"msg":{"trade_id":"4d88e0d4-37b2-601d-6bbf-1ddbf392eaad","market_ticker":"KXBTCPERP1","price":"6.3602","count":"1.00","taker_side":"ask","ts_ms":1781237160276}}

{"type":"trade","sid":2,"seq":175,"msg":{"trade_id":"7af937f9-3833-6179-42f4-59208d732e05","market_ticker":"KXBTCPERP1","price":"6.3602","count":"1.00","taker_side":"ask","ts_ms":1781237160276}}

{"type":"trade","sid":2,"seq":176,"msg":{"trade_id":"7a10a3b6-ff8b-6709-6a60-65459f1c0281","market_ticker":"KXBTCPERP1","price":"6.3602","count":"1.00","taker_side":"ask","ts_ms":1781237160276}}

{"type":"trade","sid":2,"seq":177,"msg":{"trade_id":"58f9f78f-d798-622c-5cb7-c6b8099dcaf4","market_ticker":"KXBTCPERP1","price":"6.3599","count":"1.00","taker_side":"ask","ts_ms":1781237160276}}

{"type":"trade","sid":2,"seq":178,"msg":{"trade_id":"b6aae020-16cc-6931-72f2-5a1c550c23dd","market_ticker":"KXBTCPERP1","price":"6.3599","count":"1.00","taker_side":"ask","ts_ms":1781237160276}}

{"type":"trade","sid":2,"seq":179,"msg":{"trade_id":"14619414-b67f-6c34-4ed7-ee5fddda3be8","market_ticker":"KXBTCPERP1","price":"6.3598","count":"1.00","taker_side":"ask","ts_ms":1781237160276}}

{"type":"trade","sid":2,"seq":180,"msg":{"trade_id":"c3901ce6-eb2b-677d-50f7-62473c69a4f8","market_ticker":"KXBTCPERP1","price":"6.3598","count":"1.00","taker_side":"ask","ts_ms":1781237160276}}

{"type":"trade","sid":2,"seq":181,"msg":{"trade_id":"733f67f1-70f6-6544-4501-62f751e2607a","market_ticker":"KXBTCPERP1","price":"6.3597","count":"1.00","taker_side":"ask","ts_ms":1781237160276}}

{"type":"trade","sid":2,"seq":182,"msg":{"trade_id":"f1f0ed8c-63ce-6aa5-7ad1-4ef8070b9720","market_ticker":"KXBTCPERP1","price":"6.3597","count":"1.00","taker_side":"ask","ts_ms":1781237160276}}

{"type":"trade","sid":2,"seq":183,"msg":{"trade_id":"d50246e6-d9b0-68f2-54dc-a25c35dab06e","market_ticker":"KXBTCPERP1","price":"6.3597","count":"1.00","taker_side":"ask","ts_ms":1781237160276}}

{"type":"trade","sid":2,"seq":184,"msg":{"trade_id":"5f4b03c6-c331-64bb-7e36-aafbacefa51f","market_ticker":"KXBTCPERP1","price":"6.3597","count":"1.00","taker_side":"ask","ts_ms":1781237160276}}

{"type":"trade","sid":2,"seq":185,"msg":{"trade_id":"fd986242-b30c-621e-6a8b-dceee5f95354","market_ticker":"KXBTCPERP1","price":"6.3597","count":"1.00","taker_side":"ask","ts_ms":1781237160276}}

{"type":"trade","sid":2,"seq":186,"msg":{"trade_id":"83855b96-d0e5-6264-6ccd-808a3f2f97c9","market_ticker":"KXBTCPERP1","price":"6.3597","count":"1.00","taker_side":"ask","ts_ms":1781237160276}}

{"type":"trade","sid":2,"seq":187,"msg":{"trade_id":"7e6fe4e6-5254-6d31-65b3-1c6ea6fe8d6c","market_ticker":"KXBTCPERP1","price":"6.3596","count":"1.00","taker_side":"ask","ts_ms":1781237160276}}

{"type":"trade","sid":2,"seq":188,"msg":{"trade_id":"204ce069-4360-6fa3-626d-575d15d22096","market_ticker":"KXBTCPERP1","price":"6.3596","count":"1.00","taker_side":"ask","ts_ms":1781237160276}}

{"type":"trade","sid":2,"seq":189,"msg":{"trade_id":"9d4eea82-077e-69b4-6700-eaa500bc791b","market_ticker":"KXBTCPERP1","price":"6.3596","count":"1.00","taker_side":"ask","ts_ms":1781237160276}}

{"type":"trade","sid":2,"seq":190,"msg":{"trade_id":"29abc113-e2ca-6b21-5483-c1c935fedc9e","market_ticker":"KXBTCPERP1","price":"6.3595","count":"1.00","taker_side":"ask","ts_ms":1781237160276}}

{"type":"trade","sid":2,"seq":191,"msg":{"trade_id":"c744b20c-fa8a-6769-45d1-a8f36dac728c","market_ticker":"KXBTCPERP1","price":"6.3594","count":"1.00","taker_side":"ask","ts_ms":1781237160276}}

{"type":"trade","sid":2,"seq":192,"msg":{"trade_id":"dd2d0344-34ef-6277-7ea8-4dc630d9b00d","market_ticker":"KXBTCPERP1","price":"6.3594","count":"1.00","taker_side":"ask","ts_ms":1781237160276}}

{"type":"trade","sid":2,"seq":193,"msg":{"trade_id":"78f3fdc1-d55c-6633-7d46-bf74bfbb4d60","market_ticker":"KXBTCPERP1","price":"6.3594","count":"1.00","taker_side":"ask","ts_ms":1781237160276}}

{"type":"trade","sid":2,"seq":194,"msg":{"trade_id":"6418cef0-d6b2-6bba-583c-7c51edbcb85f","market_ticker":"KXBTCPERP1","price":"6.3594","count":"1.00","taker_side":"ask","ts_ms":1781237160276}}

{"type":"trade","sid":2,"seq":195,"msg":{"trade_id":"eabb3ab3-e1f8-6910-69d6-19f91be89b03","market_ticker":"KXBTCPERP1","price":"6.3594","count":"1.00","taker_side":"ask","ts_ms":1781237160276}}

{"type":"trade","sid":2,"seq":196,"msg":{"trade_id":"1a785775-f209-6ee3-5414-69cc5d16ec47","market_ticker":"KXBTCPERP1","price":"6.3593","count":"1.00","taker_side":"ask","ts_ms":1781237160276}}

{"type":"trade","sid":2,"seq":197,"msg":{"trade_id":"df42ba20-0325-6962-6beb-6068447610e5","market_ticker":"KXBTCPERP1","price":"6.3593","count":"1.00","taker_side":"ask","ts_ms":1781237160276}}

{"type":"trade","sid":2,"seq":198,"msg":{"trade_id":"b9219f55-2826-6e26-7e41-f74d40efc848","market_ticker":"KXBTCPERP1","price":"6.3593","count":"1.00","taker_side":"ask","ts_ms":1781237160276}}

{"type":"trade","sid":2,"seq":199,"msg":{"trade_id":"61b78dd9-88dd-6dc1-5c64-ad5f548bf4a1","market_ticker":"KXBTCPERP1","price":"6.3593","count":"1.00","taker_side":"ask","ts_ms":1781237160276}}

{"type":"trade","sid":2,"seq":200,"msg":{"trade_id":"31dadf58-8456-6ea8-71ba-837a9b788ebe","market_ticker":"KXBTCPERP1","price":"6.3592","count":"1.00","taker_side":"ask","ts_ms":1781237160276}}

{"type":"trade","sid":2,"seq":201,"msg":{"trade_id":"625f0da4-1f37-63f4-75b6-782f751f64ec","market_ticker":"KXBTCPERP1","price":"6.3592","count":"1.00","taker_side":"ask","ts_ms":1781237160276}}

{"type":"trade","sid":2,"seq":202,"msg":{"trade_id":"e5e17965-bb4d-638b-4f74-3a415813fc2f","market_ticker":"KXBTCPERP1","price":"6.3592","count":"1.00","taker_side":"ask","ts_ms":1781237160276}}

{"type":"trade","sid":2,"seq":203,"msg":{"trade_id":"68de25b0-d0fe-60c4-5372-c8a991e7dccb","market_ticker":"KXBTCPERP1","price":"6.3591","count":"1.00","taker_side":"ask","ts_ms":1781237160276}}

{"type":"trade","sid":2,"seq":204,"msg":{"trade_id":"21dc5bd9-682c-6cfa-7a1f-c5c989dfb5cd","market_ticker":"KXBTCPERP1","price":"6.3590","count":"1.00","taker_side":"ask","ts_ms":1781237160276}}

{"type":"trade","sid":2,"seq":205,"msg":{"trade_id":"9943218a-1611-6e10-5412-253cedf3d158","market_ticker":"KXBTCPERP1","price":"6.3589","count":"1.00","taker_side":"ask","ts_ms":1781237160276}}

{"type":"trade","sid":2,"seq":206,"msg":{"trade_id":"006099b9-d300-67dc-714d-cf264e1fb02e","market_ticker":"KXBTCPERP1","price":"6.3589","count":"1.00","taker_side":"ask","ts_ms":1781237160276}}

{"type":"trade","sid":2,"seq":207,"msg":{"trade_id":"12b88c56-f533-6ed1-4d85-d9d8779e6775","market_ticker":"KXBTCPERP1","price":"6.3589","count":"1.00","taker_side":"ask","ts_ms":1781237160276}}

{"type":"trade","sid":2,"seq":208,"msg":{"trade_id":"10bc906a-169c-6b10-6790-bc38dac49530","market_ticker":"KXBTCPERP1","price":"6.3588","count":"1.00","taker_side":"ask","ts_ms":1781237160276}}

{"type":"trade","sid":2,"seq":209,"msg":{"trade_id":"a501ae7b-e973-6829-7528-0605938504e7","market_ticker":"KXBTCPERP1","price":"6.3588","count":"1.00","taker_side":"ask","ts_ms":1781237160276}}

{"type":"trade","sid":2,"seq":210,"msg":{"trade_id":"8cde657d-2eef-6ae4-452a-4208dee8c073","market_ticker":"KXBTCPERP1","price":"6.3588","count":"1.00","taker_side":"ask","ts_ms":1781237160276}}

{"type":"trade","sid":2,"seq":211,"msg":{"trade_id":"98e48608-f3f6-6031-7eb2-13e44f6d7a32","market_ticker":"KXBTCPERP1","price":"6.3588","count":"1.00","taker_side":"ask","ts_ms":1781237160276}}

{"type":"trade","sid":2,"seq":212,"msg":{"trade_id":"ddac3c7c-eb41-615d-7144-1711a46ab612","market_ticker":"KXBTCPERP1","price":"6.3587","count":"1.00","taker_side":"ask","ts_ms":1781237160276}}

{"type":"trade","sid":2,"seq":213,"msg":{"trade_id":"77c3dda4-e33d-632d-61b2-e0d21a144bdc","market_ticker":"KXBTCPERP1","price":"6.3586","count":"1.00","taker_side":"ask","ts_ms":1781237160276}}

{"type":"trade","sid":2,"seq":214,"msg":{"trade_id":"f726db5f-1cef-6345-7298-3250b2139788","market_ticker":"KXBTCPERP1","price":"6.3586","count":"1.00","taker_side":"ask","ts_ms":1781237160276}}

{"type":"trade","sid":2,"seq":215,"msg":{"trade_id":"f601a871-b340-60ab-6012-3f220ca01333","market_ticker":"KXBTCPERP1","price":"6.3586","count":"1.00","taker_side":"ask","ts_ms":1781237160276}}

{"type":"trade","sid":2,"seq":216,"msg":{"trade_id":"8c2243ad-73bd-6ec6-7a0e-7886d00fab6d","market_ticker":"KXBTCPERP1","price":"6.3585","count":"1.00","taker_side":"ask","ts_ms":1781237160276}}

{"type":"trade","sid":2,"seq":217,"msg":{"trade_id":"cfe3efea-0ef1-6830-70f6-79865b44f1d5","market_ticker":"KXBTCPERP1","price":"6.3585","count":"1.00","taker_side":"ask","ts_ms":1781237160276}}

{"type":"trade","sid":2,"seq":218,"msg":{"trade_id":"cc6b30ce-4b92-6853-5b29-412df20b3e41","market_ticker":"KXBTCPERP1","price":"6.3584","count":"1.00","taker_side":"ask","ts_ms":1781237160276}}

{"type":"trade","sid":2,"seq":219,"msg":{"trade_id":"0e7177df-26c0-6bf1-4eb5-a229c1a8a754","market_ticker":"KXBTCPERP1","price":"6.3583","count":"1.00","taker_side":"ask","ts_ms":1781237160276}}

{"type":"trade","sid":2,"seq":220,"msg":{"trade_id":"213c247b-7baa-6de8-5eba-6af794ced363","market_ticker":"KXBTCPERP1","price":"6.3582","count":"1.00","taker_side":"ask","ts_ms":1781237160276}}

{"type":"trade","sid":2,"seq":221,"msg":{"trade_id":"782915ec-5df8-67bf-79bc-72775f72409a","market_ticker":"KXBTCPERP1","price":"6.3582","count":"1.00","taker_side":"ask","ts_ms":1781237160276}}

{"type":"trade","sid":2,"seq":222,"msg":{"trade_id":"a993bec6-df5c-6276-4128-bfc5c0e93604","market_ticker":"KXBTCPERP1","price":"6.3582","count":"1.00","taker_side":"ask","ts_ms":1781237160276}}

{"type":"trade","sid":2,"seq":223,"msg":{"trade_id":"4de470d5-b63b-624b-4594-e3ca246f37f5","market_ticker":"KXBTCPERP1","price":"6.3581","count":"1.00","taker_side":"ask","ts_ms":1781237160276}}

{"type":"trade","sid":2,"seq":224,"msg":{"trade_id":"49e1f34e-3e42-6a44-57a1-ed2bed838e84","market_ticker":"KXBTCPERP1","price":"6.3581","count":"1.00","taker_side":"ask","ts_ms":1781237160276}}

{"type":"trade","sid":2,"seq":225,"msg":{"trade_id":"a01a9d0e-424f-6cfe-7398-3b09cfb3b66f","market_ticker":"KXBTCPERP1","price":"6.3580","count":"1.00","taker_side":"ask","ts_ms":1781237160276}}

{"type":"trade","sid":2,"seq":226,"msg":{"trade_id":"8bf231be-6c2d-6abe-5114-3791b1bdd61b","market_ticker":"KXBTCPERP1","price":"6.3580","count":"1.00","taker_side":"ask","ts_ms":1781237160276}}

{"type":"trade","sid":2,"seq":227,"msg":{"trade_id":"f5033d3e-56dc-6e70-7ee4-e4d08372ecf3","market_ticker":"KXBTCPERP1","price":"6.3580","count":"1.00","taker_side":"ask","ts_ms":1781237160276}}

{"type":"trade","sid":2,"seq":228,"msg":{"trade_id":"2ccaa35c-e3a0-6589-660f-9d79999c1898","market_ticker":"KXBTCPERP1","price":"6.3580","count":"1.00","taker_side":"ask","ts_ms":1781237160276}}

{"type":"trade","sid":2,"seq":229,"msg":{"trade_id":"c061cc86-2454-6a6e-77da-dabfedd8561b","market_ticker":"KXBTCPERP1","price":"6.3579","count":"1.00","taker_side":"ask","ts_ms":1781237160276}}

{"type":"trade","sid":2,"seq":230,"msg":{"trade_id":"e4579093-e134-6a4d-694e-3a55a3432996","market_ticker":"KXBTCPERP1","price":"6.3579","count":"1.00","taker_side":"ask","ts_ms":1781237160276}}

{"type":"trade","sid":2,"seq":231,"msg":{"trade_id":"5f3d49b7-ac13-6334-5674-97318a7d06a7","market_ticker":"KXBTCPERP1","price":"6.3578","count":"1.00","taker_side":"ask","ts_ms":1781237160276}}

{"type":"trade","sid":2,"seq":232,"msg":{"trade_id":"bd9bdda6-a3db-61aa-7717-b8001d718523","market_ticker":"KXBTCPERP1","price":"6.3578","count":"1.00","taker_side":"ask","ts_ms":1781237160276}}

{"type":"trade","sid":2,"seq":233,"msg":{"trade_id":"044edeac-6c2c-61d0-6ef3-d5ae2bae47dc","market_ticker":"KXBTCPERP1","price":"6.3578","count":"1.00","taker_side":"ask","ts_ms":1781237160276}}

{"type":"trade","sid":2,"seq":234,"msg":{"trade_id":"c3e32e41-bbf6-6085-480a-569ea55f9e5f","market_ticker":"KXBTCPERP1","price":"6.3577","count":"1.00","taker_side":"ask","ts_ms":1781237160276}}

{"type":"trade","sid":2,"seq":235,"msg":{"trade_id":"3834ba36-a6da-65f2-7a28-4442233f63bd","market_ticker":"KXBTCPERP1","price":"6.3577","count":"1.00","taker_side":"ask","ts_ms":1781237160276}}

{"type":"trade","sid":2,"seq":236,"msg":{"trade_id":"fcdb30f0-00ba-6172-5190-c970cde7e503","market_ticker":"KXBTCPERP1","price":"6.3577","count":"1.00","taker_side":"ask","ts_ms":1781237160276}}

{"type":"trade","sid":2,"seq":237,"msg":{"trade_id":"6431cf64-f548-6be8-534b-eae4b0895ed2","market_ticker":"KXBTCPERP1","price":"6.3577","count":"1.00","taker_side":"ask","ts_ms":1781237160276}}

{"type":"trade","sid":2,"seq":238,"msg":{"trade_id":"d4e9d264-8f45-6fd3-4cf5-1bb70d69ac98","market_ticker":"KXBTCPERP1","price":"6.3576","count":"1.00","taker_side":"ask","ts_ms":1781237160276}}

{"type":"trade","sid":2,"seq":239,"msg":{"trade_id":"da6e3a55-2fea-649e-7d0a-bb05213d5567","market_ticker":"KXBTCPERP1","price":"6.3576","count":"1.00","taker_side":"ask","ts_ms":1781237160276}}

{"type":"trade","sid":2,"seq":240,"msg":{"trade_id":"d7260492-affe-66c6-62e5-75fa16bdd52a","market_ticker":"KXBTCPERP1","price":"6.3576","count":"1.00","taker_side":"ask","ts_ms":1781237160276}}

{"type":"trade","sid":2,"seq":241,"msg":{"trade_id":"232212d0-aeb4-6b0e-7896-db2c536fc9a8","market_ticker":"KXBTCPERP1","price":"6.3576","count":"1.00","taker_side":"ask","ts_ms":1781237160276}}

{"type":"trade","sid":2,"seq":242,"msg":{"trade_id":"f7d9b024-6a9e-6e01-7fc3-af9956a32df4","market_ticker":"KXBTCPERP1","price":"6.3575","count":"1.00","taker_side":"ask","ts_ms":1781237160276}}

{"type":"trade","sid":2,"seq":243,"msg":{"trade_id":"7ad61abc-f504-60c3-5c0d-529287865206","market_ticker":"KXBTCPERP1","price":"6.3575","count":"1.00","taker_side":"ask","ts_ms":1781237160276}}

{"type":"trade","sid":2,"seq":244,"msg":{"trade_id":"44393550-f677-6422-6437-b71a82e9d061","market_ticker":"KXBTCPERP1","price":"6.3575","count":"1.00","taker_side":"ask","ts_ms":1781237160276}}

{"type":"trade","sid":2,"seq":245,"msg":{"trade_id":"3a110264-48c6-6e57-642b-e4aabb68889d","market_ticker":"KXBTCPERP1","price":"6.3575","count":"1.00","taker_side":"ask","ts_ms":1781237160276}}

{"type":"trade","sid":2,"seq":246,"msg":{"trade_id":"55d6a351-f24f-61ee-4e3b-4838ccd55d44","market_ticker":"KXBTCPERP1","price":"6.3574","count":"1.00","taker_side":"ask","ts_ms":1781237160276}}

{"type":"trade","sid":2,"seq":247,"msg":{"trade_id":"882dd44a-f48b-62b1-696b-5dd3a4711296","market_ticker":"KXBTCPERP1","price":"6.3573","count":"1.00","taker_side":"ask","ts_ms":1781237160276}}

{"type":"trade","sid":2,"seq":248,"msg":{"trade_id":"7dbd0482-aabc-659d-48f4-e3f87938a488","market_ticker":"KXBTCPERP1","price":"6.3573","count":"1.00","taker_side":"ask","ts_ms":1781237160276}}

{"type":"trade","sid":2,"seq":249,"msg":{"trade_id":"aa28ea1e-0e2d-657e-491e-07204f7a29af","market_ticker":"KXBTCPERP1","price":"6.3573","count":"1.00","taker_side":"ask","ts_ms":1781237160276}}

{"type":"trade","sid":2,"seq":250,"msg":{"trade_id":"ccef0d07-b48e-60a5-451b-84ef26382566","market_ticker":"KXBTCPERP1","price":"6.3573","count":"1.00","taker_side":"ask","ts_ms":1781237160276}}

{"type":"trade","sid":2,"seq":251,"msg":{"trade_id":"ea45850a-3613-6f4f-5197-a475c77a3362","market_ticker":"KXBTCPERP1","price":"6.3573","count":"1.00","taker_side":"ask","ts_ms":1781237160276}}

{"type":"trade","sid":2,"seq":252,"msg":{"trade_id":"0434a648-347f-6200-44bf-c0ff3c2fa9b6","market_ticker":"KXBTCPERP1","price":"6.3572","count":"1.00","taker_side":"ask","ts_ms":1781237160276}}

{"type":"trade","sid":2,"seq":253,"msg":{"trade_id":"0c6f1e3c-56ce-6732-5f9a-6f61fe0cdf55","market_ticker":"KXBTCPERP1","price":"6.3572","count":"1.00","taker_side":"ask","ts_ms":1781237160276}}

{"type":"trade","sid":2,"seq":254,"msg":{"trade_id":"38570046-32f3-655a-4d25-7f0d188d0479","market_ticker":"KXBTCPERP1","price":"6.3572","count":"1.00","taker_side":"ask","ts_ms":1781237160276}}

{"type":"trade","sid":2,"seq":255,"msg":{"trade_id":"a3e5d41f-4d2e-675a-64a9-f66373c252f4","market_ticker":"KXBTCPERP1","price":"6.3571","count":"1.00","taker_side":"ask","ts_ms":1781237160276}}

{"type":"trade","sid":2,"seq":256,"msg":{"trade_id":"316c8a18-bb71-67c2-7ec9-9221ad016b74","market_ticker":"KXBTCPERP1","price":"6.3571","count":"1.00","taker_side":"ask","ts_ms":1781237160276}}

{"type":"trade","sid":2,"seq":257,"msg":{"trade_id":"2538b53e-9970-6f97-5656-fbd6d6018567","market_ticker":"KXBTCPERP1","price":"6.3570","count":"1.00","taker_side":"ask","ts_ms":1781237160276}}

{"type":"trade","sid":2,"seq":258,"msg":{"trade_id":"9ef7c7c3-7ff2-69ad-79df-8d053354c4ab","market_ticker":"KXBTCPERP1","price":"6.3570","count":"1.00","taker_side":"ask","ts_ms":1781237160276}}

{"type":"trade","sid":2,"seq":259,"msg":{"trade_id":"4cd208ca-3185-6e46-5719-93b5c7d65bd3","market_ticker":"KXBTCPERP1","price":"6.3570","count":"1.00","taker_side":"ask","ts_ms":1781237160276}}

{"type":"trade","sid":2,"seq":260,"msg":{"trade_id":"abf4f8d6-e75d-6598-42fb-c35150b716e3","market_ticker":"KXBTCPERP1","price":"6.3570","count":"1.00","taker_side":"ask","ts_ms":1781237160276}}

{"type":"trade","sid":2,"seq":261,"msg":{"trade_id":"63f956ad-a0ae-6581-6376-2d533772166d","market_ticker":"KXBTCPERP1","price":"6.3569","count":"1.00","taker_side":"ask","ts_ms":1781237160276}}

{"type":"trade","sid":2,"seq":262,"msg":{"trade_id":"69373bbf-7dff-674e-45da-77c4b4b03fcd","market_ticker":"KXBTCPERP1","price":"6.3569","count":"1.00","taker_side":"ask","ts_ms":1781237160276}}

{"type":"trade","sid":2,"seq":263,"msg":{"trade_id":"fe1c0f50-0df2-60b9-415b-d82c4c2b3127","market_ticker":"KXBTCPERP1","price":"6.3568","count":"1.00","taker_side":"ask","ts_ms":1781237160276}}

{"type":"trade","sid":2,"seq":264,"msg":{"trade_id":"49a3d9c4-4487-6aae-717d-16bc09d9dd13","market_ticker":"KXBTCPERP1","price":"6.3568","count":"1.00","taker_side":"ask","ts_ms":1781237160276}}

{"type":"trade","sid":2,"seq":265,"msg":{"trade_id":"fdf91da0-2029-60e0-7787-22e02a375a0b","market_ticker":"KXBTCPERP1","price":"6.3568","count":"1.00","taker_side":"ask","ts_ms":1781237160276}}

{"type":"trade","sid":2,"seq":266,"msg":{"trade_id":"b9281568-0f77-699f-6b6f-931b7118f198","market_ticker":"KXBTCPERP1","price":"6.3568","count":"1.00","taker_side":"ask","ts_ms":1781237160276}}

{"type":"trade","sid":2,"seq":267,"msg":{"trade_id":"98c1eda2-f065-6873-429c-597fff0a28fd","market_ticker":"KXBTCPERP1","price":"6.3568","count":"1.00","taker_side":"ask","ts_ms":1781237160276}}

{"type":"trade","sid":2,"seq":268,"msg":{"trade_id":"2a5f609d-954e-63f9-5f95-a7a2994a4b91","market_ticker":"KXBTCPERP1","price":"6.3567","count":"1.00","taker_side":"ask","ts_ms":1781237160276}}

{"type":"trade","sid":2,"seq":269,"msg":{"trade_id":"ec85229d-5046-6e02-529e-e4ee965f2e50","market_ticker":"KXBTCPERP1","price":"6.3567","count":"1.00","taker_side":"ask","ts_ms":1781237160276}}

{"type":"trade","sid":2,"seq":270,"msg":{"trade_id":"4dd54e04-46f3-62ce-74a4-12ff93098734","market_ticker":"KXBTCPERP1","price":"6.3566","count":"1.00","taker_side":"ask","ts_ms":1781237160276}}

{"type":"trade","sid":2,"seq":271,"msg":{"trade_id":"080dda10-24c3-69ea-69d8-4dbb99a06cd7","market_ticker":"KXBTCPERP1","price":"6.3566","count":"1.00","taker_side":"ask","ts_ms":1781237160276}}

{"type":"trade","sid":2,"seq":272,"msg":{"trade_id":"5a914550-ab4f-6030-4454-fe0004712c4a","market_ticker":"KXBTCPERP1","price":"6.3565","count":"1.00","taker_side":"ask","ts_ms":1781237160276}}

{"type":"trade","sid":2,"seq":273,"msg":{"trade_id":"268b8eed-019f-6fca-55f5-c17b4cfd75fb","market_ticker":"KXBTCPERP1","price":"6.3565","count":"1.00","taker_side":"ask","ts_ms":1781237160276}}

{"type":"trade","sid":2,"seq":274,"msg":{"trade_id":"608b9a1c-a8bf-660c-48f1-f2c8c6258daf","market_ticker":"KXBTCPERP1","price":"6.3565","count":"1.00","taker_side":"ask","ts_ms":1781237160276}}

{"type":"trade","sid":2,"seq":275,"msg":{"trade_id":"e5a61d86-a27a-6db2-4c0b-752b20fa7d73","market_ticker":"KXBTCPERP1","price":"6.3564","count":"1.00","taker_side":"ask","ts_ms":1781237160276}}

{"type":"trade","sid":2,"seq":276,"msg":{"trade_id":"8ea51b6d-c9d2-6fe2-6fb9-73c4272f8b92","market_ticker":"KXBTCPERP1","price":"6.3564","count":"1.00","taker_side":"ask","ts_ms":1781237160276}}

{"type":"trade","sid":2,"seq":277,"msg":{"trade_id":"75724266-787d-6d60-6e08-403d29fb2036","market_ticker":"KXBTCPERP1","price":"6.3564","count":"1.00","taker_side":"ask","ts_ms":1781237160276}}

{"type":"trade","sid":2,"seq":278,"msg":{"trade_id":"1f42aaa8-2f87-6087-747e-207293d97e9e","market_ticker":"KXBTCPERP1","price":"6.3564","count":"1.00","taker_side":"ask","ts_ms":1781237160276}}

{"type":"trade","sid":2,"seq":279,"msg":{"trade_id":"012a2ac7-badb-637f-755a-af346916d121","market_ticker":"KXBTCPERP1","price":"6.3563","count":"1.00","taker_side":"ask","ts_ms":1781237160276}}

{"type":"trade","sid":2,"seq":280,"msg":{"trade_id":"a0ccfa88-d0bf-666f-56f5-fb2f8674d9a8","market_ticker":"KXBTCPERP1","price":"6.3563","count":"1.00","taker_side":"ask","ts_ms":1781237160276}}

{"type":"trade","sid":2,"seq":281,"msg":{"trade_id":"efd0091d-d5c7-626c-6c47-de167398f235","market_ticker":"KXBTCPERP1","price":"6.3562","count":"1.00","taker_side":"ask","ts_ms":1781237160276}}

{"type":"trade","sid":2,"seq":282,"msg":{"trade_id":"f14b37e0-7138-6e9c-4204-ba78cd4e3b4a","market_ticker":"KXBTCPERP1","price":"6.3562","count":"1.00","taker_side":"ask","ts_ms":1781237160276}}

{"type":"trade","sid":2,"seq":283,"msg":{"trade_id":"0d7e4fc6-5f3c-62d0-5d18-aa98adcac672","market_ticker":"KXBTCPERP1","price":"6.3561","count":"1.00","taker_side":"ask","ts_ms":1781237160276}}

{"type":"trade","sid":2,"seq":284,"msg":{"trade_id":"bc40bcea-2166-6072-5367-b56c71a7d605","market_ticker":"KXBTCPERP1","price":"6.3561","count":"1.00","taker_side":"ask","ts_ms":1781237160276}}

{"type":"trade","sid":2,"seq":285,"msg":{"trade_id":"87345224-9195-6a6d-6b5f-99622b58f20f","market_ticker":"KXBTCPERP1","price":"6.3561","count":"1.00","taker_side":"ask","ts_ms":1781237160276}}

{"type":"trade","sid":2,"seq":286,"msg":{"trade_id":"9208f222-c59b-6b2d-7fad-02257ca16c82","market_ticker":"KXBTCPERP1","price":"6.3560","count":"1.00","taker_side":"ask","ts_ms":1781237160276}}

{"type":"trade","sid":2,"seq":287,"msg":{"trade_id":"164d236c-9135-6cf7-44a0-bfa409ad5b3a","market_ticker":"KXBTCPERP1","price":"6.3559","count":"1.00","taker_side":"ask","ts_ms":1781237160276}}

{"type":"trade","sid":2,"seq":288,"msg":{"trade_id":"aa9c029b-dbfd-6e9b-6317-1dbac3d86761","market_ticker":"KXBTCPERP1","price":"6.3559","count":"1.00","taker_side":"ask","ts_ms":1781237160276}}

{"type":"trade","sid":2,"seq":289,"msg":{"trade_id":"3d5ab84f-9fd6-6eae-4e69-6ecf1ac3ceb1","market_ticker":"KXBTCPERP1","price":"6.3558","count":"1.00","taker_side":"ask","ts_ms":1781237160276}}

{"type":"trade","sid":2,"seq":290,"msg":{"trade_id":"3250214e-11a1-62a3-5422-c18e0322a932","market_ticker":"KXBTCPERP1","price":"6.3558","count":"1.00","taker_side":"ask","ts_ms":1781237160276}}

{"type":"trade","sid":2,"seq":291,"msg":{"trade_id":"e4703b70-a7d4-674c-45a0-6f2067512049","market_ticker":"KXBTCPERP1","price":"6.3558","count":"1.00","taker_side":"ask","ts_ms":1781237160276}}

{"type":"trade","sid":2,"seq":292,"msg":{"trade_id":"b6d7151d-22e7-6a65-5e39-b7068819332c","market_ticker":"KXBTCPERP1","price":"6.3558","count":"1.00","taker_side":"ask","ts_ms":1781237160276}}

{"type":"trade","sid":2,"seq":293,"msg":{"trade_id":"553ca5d3-cf45-60d2-7aaf-7eca3199e660","market_ticker":"KXBTCPERP1","price":"6.3557","count":"1.00","taker_side":"ask","ts_ms":1781237160276}}

{"type":"trade","sid":2,"seq":294,"msg":{"trade_id":"a94083ab-d00d-6fd3-64ce-c381e812d7c9","market_ticker":"KXBTCPERP1","price":"6.3557","count":"1.00","taker_side":"ask","ts_ms":1781237160276}}

{"type":"trade","sid":2,"seq":295,"msg":{"trade_id":"ae779afc-8f62-6295-4e0f-a0706b671d4c","market_ticker":"KXBTCPERP1","price":"6.3557","count":"1.00","taker_side":"ask","ts_ms":1781237160276}}

{"type":"trade","sid":2,"seq":296,"msg":{"trade_id":"1d99c5df-6e56-68a0-4ced-b9b7a8feb455","market_ticker":"KXBTCPERP1","price":"6.3557","count":"1.00","taker_side":"ask","ts_ms":1781237160276}}

{"type":"trade","sid":2,"seq":297,"msg":{"trade_id":"76b4e25d-ef36-6aee-6c2c-18b0bc749c26","market_ticker":"KXBTCPERP1","price":"6.3556","count":"1.00","taker_side":"ask","ts_ms":1781237160276}}

{"type":"trade","sid":2,"seq":298,"msg":{"trade_id":"87fa72b3-fa0a-6c61-6833-3f9660080c7d","market_ticker":"KXBTCPERP1","price":"6.3556","count":"1.00","taker_side":"ask","ts_ms":1781237160276}}

{"type":"trade","sid":2,"seq":299,"msg":{"trade_id":"d83733f7-1ece-6313-57c8-1991b1e4ea59","market_ticker":"KXBTCPERP1","price":"6.3555","count":"1.00","taker_side":"ask","ts_ms":1781237160276}}

{"type":"trade","sid":2,"seq":300,"msg":{"trade_id":"05baf55a-c613-642c-7a44-a075dc839643","market_ticker":"KXBTCPERP1","price":"6.3554","count":"1.00","taker_side":"ask","ts_ms":1781237160276}}

{"type":"trade","sid":2,"seq":301,"msg":{"trade_id":"9cf32f90-75ea-6378-764a-c18618a67659","market_ticker":"KXBTCPERP1","price":"6.3554","count":"1.00","taker_side":"ask","ts_ms":1781237160276}}

{"type":"trade","sid":2,"seq":302,"msg":{"trade_id":"54cef35f-7883-6d60-4440-09c245b65742","market_ticker":"KXBTCPERP1","price":"6.3554","count":"1.00","taker_side":"ask","ts_ms":1781237160276}}

{"type":"trade","sid":2,"seq":303,"msg":{"trade_id":"3421547e-265c-6a9c-74c2-b4933b8c2c8d","market_ticker":"KXBTCPERP1","price":"6.3554","count":"1.00","taker_side":"ask","ts_ms":1781237160276}}

{"type":"trade","sid":2,"seq":304,"msg":{"trade_id":"d1c7a07e-ccfa-6826-5ea5-badd3291d628","market_ticker":"KXBTCPERP1","price":"6.3554","count":"1.00","taker_side":"ask","ts_ms":1781237160276}}

{"type":"trade","sid":2,"seq":305,"msg":{"trade_id":"14d4a2b9-9199-6ab0-4a25-e52def06dcc2","market_ticker":"KXBTCPERP1","price":"6.3553","count":"1.00","taker_side":"ask","ts_ms":1781237160276}}

{"type":"trade","sid":2,"seq":306,"msg":{"trade_id":"f22d279d-4f01-63b8-4955-cfa90511ad5d","market_ticker":"KXBTCPERP1","price":"6.3553","count":"1.00","taker_side":"ask","ts_ms":1781237160276}}

{"type":"trade","sid":2,"seq":307,"msg":{"trade_id":"ba595424-0987-6461-4674-3871de67d421","market_ticker":"KXBTCPERP1","price":"6.3553","count":"1.00","taker_side":"ask","ts_ms":1781237160276}}

{"type":"trade","sid":2,"seq":308,"msg":{"trade_id":"74e5dbac-07a9-60e6-5c52-e094735ef5a1","market_ticker":"KXBTCPERP1","price":"6.3552","count":"1.00","taker_side":"ask","ts_ms":1781237160276}}

{"type":"trade","sid":2,"seq":309,"msg":{"trade_id":"6c27588c-2fe0-628d-70ea-bf59aaa4a1a6","market_ticker":"KXBTCPERP1","price":"6.3552","count":"1.00","taker_side":"ask","ts_ms":1781237160276}}

{"type":"trade","sid":2,"seq":310,"msg":{"trade_id":"d747bb59-f80d-6e45-4314-fca24c05a36a","market_ticker":"KXBTCPERP1","price":"6.3551","count":"1.00","taker_side":"ask","ts_ms":1781237160276}}

{"type":"trade","sid":2,"seq":311,"msg":{"trade_id":"a6591869-1421-62dc-5ff6-3555db6deb0c","market_ticker":"KXBTCPERP1","price":"6.3550","count":"1.00","taker_side":"ask","ts_ms":1781237160276}}

{"type":"trade","sid":2,"seq":312,"msg":{"trade_id":"8098db4c-2eda-613a-6abf-8adcbf49f97a","market_ticker":"KXBTCPERP1","price":"6.3550","count":"1.00","taker_side":"ask","ts_ms":1781237160276}}

{"type":"trade","sid":2,"seq":313,"msg":{"trade_id":"06fa8ef0-7e9e-6fdc-6714-7f09d87d7623","market_ticker":"KXBTCPERP1","price":"6.3550","count":"1.00","taker_side":"ask","ts_ms":1781237160276}}

{"type":"trade","sid":2,"seq":314,"msg":{"trade_id":"53d95fdf-909d-6e01-5a79-df9f19d2bafa","market_ticker":"KXBTCPERP1","price":"6.3550","count":"1.00","taker_side":"ask","ts_ms":1781237160276}}

{"type":"trade","sid":2,"seq":315,"msg":{"trade_id":"5d25077b-859a-66ea-7337-1d475ad888fa","market_ticker":"KXBTCPERP1","price":"6.3549","count":"1.00","taker_side":"ask","ts_ms":1781237160276}}

{"type":"trade","sid":2,"seq":316,"msg":{"trade_id":"47b6ba94-ccf1-6e21-484c-e158e7741154","market_ticker":"KXBTCPERP1","price":"6.3549","count":"1.00","taker_side":"ask","ts_ms":1781237160276}}

{"type":"trade","sid":2,"seq":317,"msg":{"trade_id":"161777c5-9cf3-6467-729f-78d9db63dbce","market_ticker":"KXBTCPERP1","price":"6.3549","count":"1.00","taker_side":"ask","ts_ms":1781237160276}}

{"type":"trade","sid":2,"seq":318,"msg":{"trade_id":"b6d26cc7-c1de-647c-5503-04bfc3c18340","market_ticker":"KXBTCPERP1","price":"6.3549","count":"1.00","taker_side":"ask","ts_ms":1781237160276}}

{"type":"trade","sid":2,"seq":319,"msg":{"trade_id":"f06736af-3514-6abf-7f94-1560e1c9ff22","market_ticker":"KXBTCPERP1","price":"6.3549","count":"1.00","taker_side":"ask","ts_ms":1781237160276}}

{"type":"trade","sid":2,"seq":320,"msg":{"trade_id":"d01ae900-678c-6515-41d6-2cc061c36844","market_ticker":"KXBTCPERP1","price":"6.3549","count":"1.00","taker_side":"ask","ts_ms":1781237160276}}

{"type":"trade","sid":2,"seq":321,"msg":{"trade_id":"f79b5fd4-b7d7-6b2d-624c-7c7c6c27ead2","market_ticker":"KXBTCPERP1","price":"6.3549","count":"1.00","taker_side":"ask","ts_ms":1781237160276}}

{"type":"trade","sid":2,"seq":322,"msg":{"trade_id":"2b6662bf-bec9-6333-48a3-41435d48715a","market_ticker":"KXBTCPERP1","price":"6.3548","count":"1.00","taker_side":"ask","ts_ms":1781237160276}}

{"type":"trade","sid":2,"seq":323,"msg":{"trade_id":"ce4baf94-3bd5-63cf-56f5-1c1f08f705fd","market_ticker":"KXBTCPERP1","price":"6.3548","count":"1.00","taker_side":"ask","ts_ms":1781237160276}}

{"type":"trade","sid":2,"seq":324,"msg":{"trade_id":"8af1bd01-5a18-6ad9-589e-09a141385eea","market_ticker":"KXBTCPERP1","price":"6.3547","count":"1.00","taker_side":"ask","ts_ms":1781237160276}}

{"type":"trade","sid":2,"seq":325,"msg":{"trade_id":"c1386e29-022f-69a3-7474-64f1af4bc74c","market_ticker":"KXBTCPERP1","price":"6.3547","count":"1.00","taker_side":"ask","ts_ms":1781237160276}}

{"type":"trade","sid":2,"seq":326,"msg":{"trade_id":"59938483-7d1a-65a6-452e-66945bb98e19","market_ticker":"KXBTCPERP1","price":"6.3547","count":"1.00","taker_side":"ask","ts_ms":1781237160276}}

{"type":"trade","sid":2,"seq":327,"msg":{"trade_id":"2418dcd5-4fc9-61cd-7654-fa894681ebc1","market_ticker":"KXBTCPERP1","price":"6.3547","count":"1.00","taker_side":"ask","ts_ms":1781237160276}}

{"type":"trade","sid":2,"seq":328,"msg":{"trade_id":"7997ca94-5fb6-6289-59ff-e4d7e7f529d8","market_ticker":"KXBTCPERP1","price":"6.3547","count":"1.00","taker_side":"ask","ts_ms":1781237160276}}

{"type":"trade","sid":2,"seq":329,"msg":{"trade_id":"bec3f32a-0516-64bd-512e-25cc20b5c129","market_ticker":"KXBTCPERP1","price":"6.3546","count":"1.00","taker_side":"ask","ts_ms":1781237160276}}

{"type":"trade","sid":2,"seq":330,"msg":{"trade_id":"e4ce9cfe-4cc4-69e6-5a92-4e6f6dfacce6","market_ticker":"KXBTCPERP1","price":"6.3546","count":"1.00","taker_side":"ask","ts_ms":1781237160276}}

{"type":"trade","sid":2,"seq":331,"msg":{"trade_id":"97900d20-5316-6efe-7ba9-e56ebca5a569","market_ticker":"KXBTCPERP1","price":"6.3546","count":"1.00","taker_side":"ask","ts_ms":1781237160276}}

{"type":"trade","sid":2,"seq":332,"msg":{"trade_id":"966d24c3-ba2e-6f06-59bb-0c0d45d9bb4d","market_ticker":"KXBTCPERP1","price":"6.3545","count":"1.00","taker_side":"ask","ts_ms":1781237160276}}

{"type":"trade","sid":2,"seq":333,"msg":{"trade_id":"55b107f0-5287-68d2-68fa-858739f1b774","market_ticker":"KXBTCPERP1","price":"6.3545","count":"1.00","taker_side":"ask","ts_ms":1781237160276}}

{"type":"trade","sid":2,"seq":334,"msg":{"trade_id":"a41de8ec-729b-6bae-4792-7041a9b27ad6","market_ticker":"KXBTCPERP1","price":"6.3545","count":"1.00","taker_side":"ask","ts_ms":1781237160276}}

{"type":"trade","sid":2,"seq":335,"msg":{"trade_id":"0456f4f2-bba2-6bde-6b88-2ff335b868d3","market_ticker":"KXBTCPERP1","price":"6.3544","count":"1.00","taker_side":"ask","ts_ms":1781237160276}}

{"type":"trade","sid":2,"seq":336,"msg":{"trade_id":"00deb1b8-8594-680b-76e2-1e3f1e2809ec","market_ticker":"KXBTCPERP1","price":"6.3544","count":"1.00","taker_side":"ask","ts_ms":1781237160276}}

{"type":"trade","sid":2,"seq":337,"msg":{"trade_id":"2b850eec-a272-6ee4-7430-9f5807ec9b69","market_ticker":"KXBTCPERP1","price":"6.3544","count":"1.00","taker_side":"ask","ts_ms":1781237160276}}

{"type":"trade","sid":2,"seq":338,"msg":{"trade_id":"256b0dc5-6714-667f-4926-336085dabf53","market_ticker":"KXBTCPERP1","price":"6.3543","count":"1.00","taker_side":"ask","ts_ms":1781237160276}}

{"type":"trade","sid":2,"seq":339,"msg":{"trade_id":"238cf05b-90c0-609d-6e31-e9881ca718a6","market_ticker":"KXBTCPERP1","price":"6.3543","count":"1.00","taker_side":"ask","ts_ms":1781237160276}}

{"type":"trade","sid":2,"seq":340,"msg":{"trade_id":"8a3323d6-b5b6-6a21-51df-298241a0575b","market_ticker":"KXBTCPERP1","price":"6.3542","count":"1.00","taker_side":"ask","ts_ms":1781237160276}}

{"type":"trade","sid":2,"seq":341,"msg":{"trade_id":"22cc90f3-0f7c-6b5c-7ed2-1975f4904dae","market_ticker":"KXBTCPERP1","price":"6.3541","count":"1.00","taker_side":"ask","ts_ms":1781237160276}}

{"type":"trade","sid":2,"seq":342,"msg":{"trade_id":"a3421fdb-2445-6bc5-5f1b-68b2267b6bd7","market_ticker":"KXBTCPERP1","price":"6.3541","count":"1.00","taker_side":"ask","ts_ms":1781237160276}}

{"type":"trade","sid":2,"seq":343,"msg":{"trade_id":"6b92ffa1-3dae-6150-429a-4a988eacee9f","market_ticker":"KXBTCPERP1","price":"6.3541","count":"1.00","taker_side":"ask","ts_ms":1781237160276}}

{"type":"trade","sid":2,"seq":344,"msg":{"trade_id":"b8f52c6c-6447-6450-5565-28172657e50f","market_ticker":"KXBTCPERP1","price":"6.3541","count":"1.00","taker_side":"ask","ts_ms":1781237160276}}

{"type":"trade","sid":2,"seq":345,"msg":{"trade_id":"9503c9fe-11dd-69f2-7f3b-3129bceae768","market_ticker":"KXBTCPERP1","price":"6.3540","count":"1.00","taker_side":"ask","ts_ms":1781237160276}}

{"type":"trade","sid":2,"seq":346,"msg":{"trade_id":"d411a8e6-8169-6f78-573f-58272f24779c","market_ticker":"KXBTCPERP1","price":"6.3540","count":"1.00","taker_side":"ask","ts_ms":1781237160276}}

{"type":"trade","sid":2,"seq":347,"msg":{"trade_id":"fa8a1c9a-80f1-67ae-5805-ef7fa2807b97","market_ticker":"KXBTCPERP1","price":"6.3540","count":"1.00","taker_side":"ask","ts_ms":1781237160276}}

{"type":"trade","sid":2,"seq":348,"msg":{"trade_id":"5e1f4bae-258d-6114-575e-a3ff4e9d964f","market_ticker":"KXBTCPERP1","price":"6.3540","count":"1.00","taker_side":"ask","ts_ms":1781237160276}}

{"type":"trade","sid":2,"seq":349,"msg":{"trade_id":"04a3cd8c-a1ec-6abd-5891-1b8058ee7d7f","market_ticker":"KXBTCPERP1","price":"6.3540","count":"1.00","taker_side":"ask","ts_ms":1781237160276}}

{"type":"trade","sid":2,"seq":350,"msg":{"trade_id":"93381e48-1196-6a2e-7f48-a2c80195ce41","market_ticker":"KXBTCPERP1","price":"6.3540","count":"1.00","taker_side":"ask","ts_ms":1781237160276}}

{"type":"trade","sid":2,"seq":351,"msg":{"trade_id":"d2668685-dbd2-6108-5869-cba0d098b1bb","market_ticker":"KXBTCPERP1","price":"6.3539","count":"1.00","taker_side":"ask","ts_ms":1781237160276}}

{"type":"trade","sid":2,"seq":352,"msg":{"trade_id":"c4fad914-67a7-6e54-6840-ceaf8676e990","market_ticker":"KXBTCPERP1","price":"6.3539","count":"1.00","taker_side":"ask","ts_ms":1781237160276}}

{"type":"trade","sid":2,"seq":353,"msg":{"trade_id":"871b3f56-bf95-6a35-7751-cf96a7b89475","market_ticker":"KXBTCPERP1","price":"6.3539","count":"1.00","taker_side":"ask","ts_ms":1781237160276}}

{"type":"trade","sid":2,"seq":354,"msg":{"trade_id":"852835fd-94f2-6b64-685f-36e0e864c701","market_ticker":"KXBTCPERP1","price":"6.3539","count":"1.00","taker_side":"ask","ts_ms":1781237160276}}

{"type":"trade","sid":2,"seq":355,"msg":{"trade_id":"ae256a49-a7a5-6c3e-63e3-b5393325ec21","market_ticker":"KXBTCPERP1","price":"6.3539","count":"1.00","taker_side":"ask","ts_ms":1781237160276}}

{"type":"trade","sid":2,"seq":356,"msg":{"trade_id":"a7b5d430-5ae9-62e9-5e12-2d4e5b8802a4","market_ticker":"KXBTCPERP1","price":"6.3538","count":"1.00","taker_side":"ask","ts_ms":1781237160276}}

{"type":"trade","sid":2,"seq":357,"msg":{"trade_id":"5a09f0a2-8bc9-680a-4424-232852137340","market_ticker":"KXBTCPERP1","price":"6.3538","count":"1.00","taker_side":"ask","ts_ms":1781237160276}}

{"type":"trade","sid":2,"seq":358,"msg":{"trade_id":"de1ea726-5b20-661e-4c56-a2651368128a","market_ticker":"KXBTCPERP1","price":"6.3538","count":"1.00","taker_side":"ask","ts_ms":1781237160276}}

{"type":"trade","sid":2,"seq":359,"msg":{"trade_id":"ef4a4dff-dbbe-627a-448b-fc84db3fe5d2","market_ticker":"KXBTCPERP1","price":"6.3538","count":"1.00","taker_side":"ask","ts_ms":1781237160276}}

{"type":"trade","sid":2,"seq":360,"msg":{"trade_id":"b9be9ce7-23fa-61bf-40b0-2f81e4722ab8","market_ticker":"KXBTCPERP1","price":"6.3538","count":"1.00","taker_side":"ask","ts_ms":1781237160276}}

{"type":"trade","sid":2,"seq":361,"msg":{"trade_id":"1a49ef71-5f51-6502-55d8-8f449530cd25","market_ticker":"KXBTCPERP1","price":"6.3537","count":"1.00","taker_side":"ask","ts_ms":1781237160276}}

{"type":"trade","sid":2,"seq":362,"msg":{"trade_id":"68c07929-1a55-626d-446b-6f24cc02f7fb","market_ticker":"KXBTCPERP1","price":"6.3537","count":"1.00","taker_side":"ask","ts_ms":1781237160276}}

{"type":"trade","sid":2,"seq":363,"msg":{"trade_id":"977418e6-468e-690a-53be-cf4c76c9b9da","market_ticker":"KXBTCPERP1","price":"6.3536","count":"1.00","taker_side":"ask","ts_ms":1781237160276}}

{"type":"trade","sid":2,"seq":364,"msg":{"trade_id":"9a606703-6620-6474-7c4f-14c309517bd9","market_ticker":"KXBTCPERP1","price":"6.3536","count":"1.00","taker_side":"ask","ts_ms":1781237160276}}

{"type":"trade","sid":2,"seq":365,"msg":{"trade_id":"cc76d3be-bf14-6d17-66ad-b9822c8ba4de","market_ticker":"KXBTCPERP1","price":"6.3536","count":"1.00","taker_side":"ask","ts_ms":1781237160276}}

{"type":"trade","sid":2,"seq":366,"msg":{"trade_id":"62ef65cb-8f11-6590-4ef8-727c75e840a0","market_ticker":"KXBTCPERP1","price":"6.3535","count":"1.00","taker_side":"ask","ts_ms":1781237160276}}

{"type":"trade","sid":2,"seq":367,"msg":{"trade_id":"15477fe3-2547-64c7-4ed7-b06c76f9816b","market_ticker":"KXBTCPERP1","price":"6.3535","count":"1.00","taker_side":"ask","ts_ms":1781237160276}}

{"type":"trade","sid":2,"seq":368,"msg":{"trade_id":"33ac7aa4-7d9e-6434-4487-f42059535180","market_ticker":"KXBTCPERP1","price":"6.3535","count":"1.00","taker_side":"ask","ts_ms":1781237160276}}

{"type":"trade","sid":2,"seq":369,"msg":{"trade_id":"e0185199-31e6-690b-6b70-0be8a5c0ce0d","market_ticker":"KXBTCPERP1","price":"6.3534","count":"1.00","taker_side":"ask","ts_ms":1781237160276}}

{"type":"trade","sid":2,"seq":370,"msg":{"trade_id":"6022ac32-1863-67e7-56a2-9529e0e04df3","market_ticker":"KXBTCPERP1","price":"6.3534","count":"1.00","taker_side":"ask","ts_ms":1781237160276}}

{"type":"trade","sid":2,"seq":371,"msg":{"trade_id":"27349eb2-84cd-6301-54cd-31004a220386","market_ticker":"KXBTCPERP1","price":"6.3533","count":"1.00","taker_side":"ask","ts_ms":1781237160276}}

{"type":"trade","sid":2,"seq":372,"msg":{"trade_id":"4c61d109-0453-6fea-4070-b89bc894ade6","market_ticker":"KXBTCPERP1","price":"6.3533","count":"1.00","taker_side":"ask","ts_ms":1781237160276}}

{"type":"trade","sid":2,"seq":373,"msg":{"trade_id":"739503e5-3b67-6cae-6ea9-503842fe6cec","market_ticker":"KXBTCPERP1","price":"6.3533","count":"1.00","taker_side":"ask","ts_ms":1781237160276}}

{"type":"trade","sid":2,"seq":374,"msg":{"trade_id":"a9ee294e-d341-64cd-75e3-e907b19d4663","market_ticker":"KXBTCPERP1","price":"6.3531","count":"1.00","taker_side":"ask","ts_ms":1781237160276}}

{"type":"trade","sid":2,"seq":375,"msg":{"trade_id":"94b5079b-b3a0-69b8-416b-20001089c567","market_ticker":"KXBTCPERP1","price":"6.3530","count":"1.00","taker_side":"ask","ts_ms":1781237160276}}

{"type":"trade","sid":2,"seq":376,"msg":{"trade_id":"9623120c-195d-63e2-5562-1eee5324f640","market_ticker":"KXBTCPERP1","price":"6.3530","count":"1.00","taker_side":"ask","ts_ms":1781237160276}}

{"type":"trade","sid":2,"seq":377,"msg":{"trade_id":"b1463351-1ed1-6fca-4ae0-6cd98208e6d9","market_ticker":"KXBTCPERP1","price":"6.3530","count":"1.00","taker_side":"ask","ts_ms":1781237160276}}

{"type":"trade","sid":2,"seq":378,"msg":{"trade_id":"e6d5a437-4e94-6f82-6784-01441071d5fb","market_ticker":"KXBTCPERP1","price":"6.3528","count":"1.00","taker_side":"ask","ts_ms":1781237160276}}

{"type":"trade","sid":2,"seq":379,"msg":{"trade_id":"e63bc011-7cd6-6f21-653c-9d56af76d2ed","market_ticker":"KXBTCPERP1","price":"6.3528","count":"1.00","taker_side":"ask","ts_ms":1781237160276}}

{"type":"trade","sid":2,"seq":380,"msg":{"trade_id":"7e29b813-12bf-635a-4052-3282838cc96b","market_ticker":"KXBTCPERP1","price":"6.3528","count":"1.00","taker_side":"ask","ts_ms":1781237160276}}

{"type":"trade","sid":2,"seq":381,"msg":{"trade_id":"e30a0f8d-38b6-6520-6c3e-37f17086eab1","market_ticker":"KXBTCPERP1","price":"6.3528","count":"1.00","taker_side":"ask","ts_ms":1781237160276}}

{"type":"trade","sid":2,"seq":382,"msg":{"trade_id":"e4cf7936-5b66-6a9b-6abe-8fc86e5f4927","market_ticker":"KXBTCPERP1","price":"6.3527","count":"1.00","taker_side":"ask","ts_ms":1781237160276}}

{"type":"trade","sid":2,"seq":383,"msg":{"trade_id":"46400714-601a-6229-4cc8-fe3f633dd15a","market_ticker":"KXBTCPERP1","price":"6.3527","count":"1.00","taker_side":"ask","ts_ms":1781237160276}}

{"type":"trade","sid":2,"seq":384,"msg":{"trade_id":"de6395d6-6732-6147-5d25-1e17f6b05c0d","market_ticker":"KXBTCPERP1","price":"6.3527","count":"1.00","taker_side":"ask","ts_ms":1781237160276}}

{"type":"trade","sid":2,"seq":385,"msg":{"trade_id":"19650ab6-31f2-6777-69cc-3d4cd9f3f3d5","market_ticker":"KXBTCPERP1","price":"6.3526","count":"1.00","taker_side":"ask","ts_ms":1781237160276}}

{"type":"trade","sid":2,"seq":386,"msg":{"trade_id":"22d7cd95-3f74-6439-7091-6968d5882ae3","market_ticker":"KXBTCPERP1","price":"6.3526","count":"1.00","taker_side":"ask","ts_ms":1781237160276}}

{"type":"trade","sid":2,"seq":387,"msg":{"trade_id":"ed7cc824-5f7a-6efd-589a-27529fadf80d","market_ticker":"KXBTCPERP1","price":"6.3526","count":"1.00","taker_side":"ask","ts_ms":1781237160276}}

{"type":"trade","sid":2,"seq":388,"msg":{"trade_id":"ca9af8a9-23e7-6ea1-5ac0-c2fe14af346e","market_ticker":"KXBTCPERP1","price":"6.3526","count":"1.00","taker_side":"ask","ts_ms":1781237160276}}

{"type":"trade","sid":2,"seq":389,"msg":{"trade_id":"d60d62ab-7535-6cce-52dd-c7bf1a2dc2dc","market_ticker":"KXBTCPERP1","price":"6.3526","count":"1.00","taker_side":"ask","ts_ms":1781237160276}}

{"type":"trade","sid":2,"seq":390,"msg":{"trade_id":"cf2f0780-886f-6e7a-4171-abc49edb4c05","market_ticker":"KXBTCPERP1","price":"6.3525","count":"1.00","taker_side":"ask","ts_ms":1781237160276}}

{"type":"trade","sid":2,"seq":391,"msg":{"trade_id":"62dee329-c8b2-682f-7a67-75d4d88e3d5f","market_ticker":"KXBTCPERP1","price":"6.3525","count":"1.00","taker_side":"ask","ts_ms":1781237160276}}

{"type":"trade","sid":2,"seq":392,"msg":{"trade_id":"d820ae67-6cd6-65cb-4888-0a797e0fd11c","market_ticker":"KXBTCPERP1","price":"6.3525","count":"1.00","taker_side":"ask","ts_ms":1781237160276}}

{"type":"trade","sid":2,"seq":393,"msg":{"trade_id":"33a137bc-def0-62ec-7acd-2be3349ce6a2","market_ticker":"KXBTCPERP1","price":"6.3524","count":"1.00","taker_side":"ask","ts_ms":1781237160276}}

{"type":"trade","sid":2,"seq":394,"msg":{"trade_id":"725587ec-b7f5-62d4-53b2-fe3aae246257","market_ticker":"KXBTCPERP1","price":"6.3524","count":"1.00","taker_side":"ask","ts_ms":1781237160276}}

{"type":"trade","sid":2,"seq":395,"msg":{"trade_id":"992b055e-127e-66b4-4f13-4b492a8dafe8","market_ticker":"KXBTCPERP1","price":"6.3524","count":"1.00","taker_side":"ask","ts_ms":1781237160276}}

{"type":"trade","sid":2,"seq":396,"msg":{"trade_id":"64b5ed43-6fc5-65cb-5e4f-3ab3acc7d160","market_ticker":"KXBTCPERP1","price":"6.3523","count":"1.00","taker_side":"ask","ts_ms":1781237160276}}

{"type":"trade","sid":2,"seq":397,"msg":{"trade_id":"0592a9af-fa96-6d32-7579-6e13aba55fc6","market_ticker":"KXBTCPERP1","price":"6.3523","count":"1.00","taker_side":"ask","ts_ms":1781237160276}}

{"type":"trade","sid":2,"seq":398,"msg":{"trade_id":"f24e65f1-6084-673d-434a-fad906c9f519","market_ticker":"KXBTCPERP1","price":"6.3523","count":"1.00","taker_side":"ask","ts_ms":1781237160276}}

{"type":"trade","sid":2,"seq":399,"msg":{"trade_id":"d4cf3248-834e-6819-46ee-5b81dd4e85ce","market_ticker":"KXBTCPERP1","price":"6.3523","count":"1.00","taker_side":"ask","ts_ms":1781237160276}}

{"type":"trade","sid":2,"seq":400,"msg":{"trade_id":"d5ccc274-61c7-6ab6-795d-508bfbf0d552","market_ticker":"KXBTCPERP1","price":"6.3522","count":"1.00","taker_side":"ask","ts_ms":1781237160276}}

{"type":"trade","sid":2,"seq":401,"msg":{"trade_id":"e6806187-37a8-62e6-7953-fdf62464769d","market_ticker":"KXBTCPERP1","price":"6.3522","count":"1.00","taker_side":"ask","ts_ms":1781237160276}}

{"type":"trade","sid":2,"seq":402,"msg":{"trade_id":"257d5044-d29d-6d7d-7795-82a3917d1778","market_ticker":"KXBTCPERP1","price":"6.3522","count":"1.00","taker_side":"ask","ts_ms":1781237160276}}

{"type":"trade","sid":2,"seq":403,"msg":{"trade_id":"3c2c2e4c-4b14-6225-7a5e-647ad614efd3","market_ticker":"KXBTCPERP1","price":"6.3521","count":"1.00","taker_side":"ask","ts_ms":1781237160276}}

{"type":"trade","sid":2,"seq":404,"msg":{"trade_id":"e9f883cb-b77d-6787-7758-2dfc12c784c4","market_ticker":"KXBTCPERP1","price":"6.3521","count":"1.00","taker_side":"ask","ts_ms":1781237160276}}

{"type":"trade","sid":2,"seq":405,"msg":{"trade_id":"7c724fe9-db3e-6213-4b83-9d1c11ae688a","market_ticker":"KXBTCPERP1","price":"6.3521","count":"1.00","taker_side":"ask","ts_ms":1781237160276}}

{"type":"trade","sid":2,"seq":406,"msg":{"trade_id":"ff8bd1f1-fb67-6849-53b0-1d2e2f5c5bd7","market_ticker":"KXBTCPERP1","price":"6.3521","count":"1.00","taker_side":"ask","ts_ms":1781237160276}}

{"type":"trade","sid":2,"seq":407,"msg":{"trade_id":"d56a6d23-4182-6dfb-7f17-611038f2a46d","market_ticker":"KXBTCPERP1","price":"6.3520","count":"1.00","taker_side":"ask","ts_ms":1781237160276}}

{"type":"trade","sid":2,"seq":408,"msg":{"trade_id":"50c3432f-a91e-61ad-489f-b29fe03dfa45","market_ticker":"KXBTCPERP1","price":"6.3519","count":"1.00","taker_side":"ask","ts_ms":1781237160276}}

{"type":"trade","sid":2,"seq":409,"msg":{"trade_id":"402b45d9-f01d-69ba-712d-fc3954c9d35b","market_ticker":"KXBTCPERP1","price":"6.3519","count":"1.00","taker_side":"ask","ts_ms":1781237160276}}

{"type":"trade","sid":2,"seq":410,"msg":{"trade_id":"567ad182-4727-6be2-5ab0-853cf0bf708f","market_ticker":"KXBTCPERP1","price":"6.3519","count":"1.00","taker_side":"ask","ts_ms":1781237160276}}

{"type":"trade","sid":2,"seq":411,"msg":{"trade_id":"8619acbe-d5b2-646c-6e18-3aabbe3a7949","market_ticker":"KXBTCPERP1","price":"6.3518","count":"1.00","taker_side":"ask","ts_ms":1781237160276}}

{"type":"trade","sid":2,"seq":412,"msg":{"trade_id":"0fbfd458-463e-6780-7c31-0e521bc61e84","market_ticker":"KXBTCPERP1","price":"6.3517","count":"1.00","taker_side":"ask","ts_ms":1781237160276}}

{"type":"trade","sid":2,"seq":413,"msg":{"trade_id":"60b24044-8c6d-692f-7219-9e2562f903e3","market_ticker":"KXBTCPERP1","price":"6.3517","count":"1.00","taker_side":"ask","ts_ms":1781237160276}}

{"type":"trade","sid":2,"seq":414,"msg":{"trade_id":"5cccbc31-257b-647f-4172-b79b669f0183","market_ticker":"KXBTCPERP1","price":"6.3516","count":"1.00","taker_side":"ask","ts_ms":1781237160276}}

{"type":"trade","sid":2,"seq":415,"msg":{"trade_id":"b948ea50-1491-6100-4c33-e72190ae9312","market_ticker":"KXBTCPERP1","price":"6.3516","count":"1.00","taker_side":"ask","ts_ms":1781237160276}}

{"type":"trade","sid":2,"seq":416,"msg":{"trade_id":"b2c7b4c1-87d3-67d1-4858-26d76b16e6f9","market_ticker":"KXBTCPERP1","price":"6.3516","count":"1.00","taker_side":"ask","ts_ms":1781237160276}}

{"type":"trade","sid":2,"seq":417,"msg":{"trade_id":"0cdaf595-bcec-6fef-47e2-8f46731da1ab","market_ticker":"KXBTCPERP1","price":"6.3515","count":"1.00","taker_side":"ask","ts_ms":1781237160276}}

{"type":"trade","sid":2,"seq":418,"msg":{"trade_id":"5d49d065-d8ba-626a-4682-dcd264e7009f","market_ticker":"KXBTCPERP1","price":"6.3515","count":"1.00","taker_side":"ask","ts_ms":1781237160276}}

{"type":"trade","sid":2,"seq":419,"msg":{"trade_id":"af9690eb-1e4f-617e-5ee5-18c12971ae62","market_ticker":"KXBTCPERP1","price":"6.3514","count":"1.00","taker_side":"ask","ts_ms":1781237160276}}

{"type":"trade","sid":2,"seq":420,"msg":{"trade_id":"790d904e-d68f-6b67-5e2a-701f765db94b","market_ticker":"KXBTCPERP1","price":"6.3514","count":"1.00","taker_side":"ask","ts_ms":1781237160276}}

{"type":"trade","sid":2,"seq":421,"msg":{"trade_id":"ef7fe96c-0f9c-6386-59e0-47ec48f93c76","market_ticker":"KXBTCPERP1","price":"6.3513","count":"1.00","taker_side":"ask","ts_ms":1781237160276}}

{"type":"trade","sid":2,"seq":422,"msg":{"trade_id":"6295a8a4-ce6a-6ab0-59eb-d801102503b8","market_ticker":"KXBTCPERP1","price":"6.3513","count":"1.00","taker_side":"ask","ts_ms":1781237160276}}

{"type":"trade","sid":2,"seq":423,"msg":{"trade_id":"ea298cd0-e168-60d7-5acc-bd31c228c218","market_ticker":"KXBTCPERP1","price":"6.3513","count":"1.00","taker_side":"ask","ts_ms":1781237160276}}

{"type":"trade","sid":2,"seq":424,"msg":{"trade_id":"bd782fb6-8768-6ae1-40c2-541218ea1a40","market_ticker":"KXBTCPERP1","price":"6.3512","count":"1.00","taker_side":"ask","ts_ms":1781237160276}}

{"type":"trade","sid":2,"seq":425,"msg":{"trade_id":"f943849c-d12e-67a6-6c94-51247763a12c","market_ticker":"KXBTCPERP1","price":"6.3512","count":"1.00","taker_side":"ask","ts_ms":1781237160276}}

{"type":"trade","sid":2,"seq":426,"msg":{"trade_id":"a5ad4ca9-9f6f-695c-61bd-4b676560af64","market_ticker":"KXBTCPERP1","price":"6.3512","count":"1.00","taker_side":"ask","ts_ms":1781237160276}}

{"type":"trade","sid":2,"seq":427,"msg":{"trade_id":"9fa4a443-9f77-67e2-5f0f-9fb6a2992ee4","market_ticker":"KXBTCPERP1","price":"6.3512","count":"1.00","taker_side":"ask","ts_ms":1781237160276}}

{"type":"trade","sid":2,"seq":428,"msg":{"trade_id":"a9fd2629-a20b-69bb-5a11-51a4155141a3","market_ticker":"KXBTCPERP1","price":"6.3512","count":"1.00","taker_side":"ask","ts_ms":1781237160276}}

{"type":"trade","sid":2,"seq":429,"msg":{"trade_id":"29fb88ff-c5d1-636d-6570-1897077bf2e9","market_ticker":"KXBTCPERP1","price":"6.3511","count":"1.00","taker_side":"ask","ts_ms":1781237160276}}

{"type":"trade","sid":2,"seq":430,"msg":{"trade_id":"13388729-1d90-661c-4b0a-9e1ee2b7e3a1","market_ticker":"KXBTCPERP1","price":"6.3511","count":"1.00","taker_side":"ask","ts_ms":1781237160276}}

{"type":"trade","sid":2,"seq":431,"msg":{"trade_id":"6ba15b67-4d22-6daf-596a-4e598cb0b43d","market_ticker":"KXBTCPERP1","price":"6.3511","count":"1.00","taker_side":"ask","ts_ms":1781237160276}}

{"type":"trade","sid":2,"seq":432,"msg":{"trade_id":"9538cefb-115d-6f3c-64e6-6f5536aee9bc","market_ticker":"KXBTCPERP1","price":"6.3511","count":"1.00","taker_side":"ask","ts_ms":1781237160276}}

{"type":"trade","sid":2,"seq":433,"msg":{"trade_id":"e167b2c5-ce94-6e30-5951-c5dc6d8d619c","market_ticker":"KXBTCPERP1","price":"6.3510","count":"1.00","taker_side":"ask","ts_ms":1781237160276}}

{"type":"trade","sid":2,"seq":434,"msg":{"trade_id":"288c2b59-66a8-6686-7fec-9d3eba62cf17","market_ticker":"KXBTCPERP1","price":"6.3509","count":"1.00","taker_side":"ask","ts_ms":1781237160276}}

{"type":"trade","sid":2,"seq":435,"msg":{"trade_id":"54f5ce09-6c2b-6b3d-4453-9108dcd4510c","market_ticker":"KXBTCPERP1","price":"6.3509","count":"1.00","taker_side":"ask","ts_ms":1781237160276}}

{"type":"trade","sid":2,"seq":436,"msg":{"trade_id":"b7bfe0f3-1b99-6a8c-4ed4-febb0537810f","market_ticker":"KXBTCPERP1","price":"6.3509","count":"1.00","taker_side":"ask","ts_ms":1781237160276}}

{"type":"trade","sid":2,"seq":437,"msg":{"trade_id":"742fc0e6-cbd3-6e4d-5f6d-b0ff0f5c284f","market_ticker":"KXBTCPERP1","price":"6.3509","count":"1.00","taker_side":"ask","ts_ms":1781237160276}}

{"type":"trade","sid":2,"seq":438,"msg":{"trade_id":"c18af668-ae6d-63ef-6594-3ff95af94953","market_ticker":"KXBTCPERP1","price":"6.3508","count":"1.00","taker_side":"ask","ts_ms":1781237160276}}

{"type":"trade","sid":2,"seq":439,"msg":{"trade_id":"41961b98-0e83-65ff-706e-5f45b119e0b2","market_ticker":"KXBTCPERP1","price":"6.3508","count":"1.00","taker_side":"ask","ts_ms":1781237160276}}

{"type":"trade","sid":2,"seq":440,"msg":{"trade_id":"ef1ff51e-045b-6fc8-6953-90440bbcc70e","market_ticker":"KXBTCPERP1","price":"6.3508","count":"1.00","taker_side":"ask","ts_ms":1781237160276}}

{"type":"trade","sid":2,"seq":441,"msg":{"trade_id":"9e8705b4-e578-6888-4253-19ef58b605ab","market_ticker":"KXBTCPERP1","price":"6.3508","count":"1.00","taker_side":"ask","ts_ms":1781237160276}}

{"type":"trade","sid":2,"seq":442,"msg":{"trade_id":"110bc9aa-0920-6b3e-5097-12d6cd018a1e","market_ticker":"KXBTCPERP1","price":"6.3508","count":"1.00","taker_side":"ask","ts_ms":1781237160276}}

{"type":"trade","sid":2,"seq":443,"msg":{"trade_id":"a0a39c38-d74f-6e7b-51c0-e51356c09308","market_ticker":"KXBTCPERP1","price":"6.3507","count":"1.00","taker_side":"ask","ts_ms":1781237160276}}

{"type":"trade","sid":2,"seq":444,"msg":{"trade_id":"d817733e-38fc-6ca9-41da-5f93e7dcc3e6","market_ticker":"KXBTCPERP1","price":"6.3507","count":"1.00","taker_side":"ask","ts_ms":1781237160276}}

{"type":"trade","sid":2,"seq":445,"msg":{"trade_id":"cb4e7162-8197-6d83-43cb-4442d0072c73","market_ticker":"KXBTCPERP1","price":"6.3507","count":"1.00","taker_side":"ask","ts_ms":1781237160276}}

{"type":"trade","sid":2,"seq":446,"msg":{"trade_id":"8b1862f9-9087-6c60-5ebe-faaf42e1ad77","market_ticker":"KXBTCPERP1","price":"6.3506","count":"1.00","taker_side":"ask","ts_ms":1781237160276}}

{"type":"trade","sid":2,"seq":447,"msg":{"trade_id":"f2052e52-c959-6406-59fb-b1758b234da7","market_ticker":"KXBTCPERP1","price":"6.3506","count":"1.00","taker_side":"ask","ts_ms":1781237160276}}

{"type":"trade","sid":2,"seq":448,"msg":{"trade_id":"41a86ef4-408d-619c-6af9-491d1494bd24","market_ticker":"KXBTCPERP1","price":"6.3505","count":"1.00","taker_side":"ask","ts_ms":1781237160276}}

{"type":"trade","sid":2,"seq":449,"msg":{"trade_id":"58aa47da-54bc-6f0d-6ec6-3c8667bbd559","market_ticker":"KXBTCPERP1","price":"6.3505","count":"1.00","taker_side":"ask","ts_ms":1781237160276}}

{"type":"trade","sid":2,"seq":450,"msg":{"trade_id":"cafe1716-adc2-64f3-4efa-8ebdad1fab7b","market_ticker":"KXBTCPERP1","price":"6.3504","count":"1.00","taker_side":"ask","ts_ms":1781237160276}}

{"type":"trade","sid":2,"seq":451,"msg":{"trade_id":"d94aa9dc-6646-6310-4445-44e1a70e8e85","market_ticker":"KXBTCPERP1","price":"6.3504","count":"1.00","taker_side":"ask","ts_ms":1781237160276}}

{"type":"trade","sid":2,"seq":452,"msg":{"trade_id":"11440cdb-5e15-640b-4c51-508a8c26fbbf","market_ticker":"KXBTCPERP1","price":"6.3503","count":"1.00","taker_side":"ask","ts_ms":1781237160276}}

{"type":"trade","sid":2,"seq":453,"msg":{"trade_id":"b851d245-c33c-6760-78d0-cc3fe99c166c","market_ticker":"KXBTCPERP1","price":"6.3503","count":"1.00","taker_side":"ask","ts_ms":1781237160276}}

{"type":"trade","sid":2,"seq":454,"msg":{"trade_id":"ac200246-f2cd-62ee-71ab-51946af55c5f","market_ticker":"KXBTCPERP1","price":"6.3502","count":"1.00","taker_side":"ask","ts_ms":1781237160276}}

{"type":"trade","sid":2,"seq":455,"msg":{"trade_id":"f8cb6198-15d5-6a50-5ee1-aa4fdff71bd0","market_ticker":"KXBTCPERP1","price":"6.3502","count":"1.00","taker_side":"ask","ts_ms":1781237160276}}

{"type":"trade","sid":2,"seq":456,"msg":{"trade_id":"feaf5304-7651-6d6a-5fcc-d1d413aad4bd","market_ticker":"KXBTCPERP1","price":"6.3501","count":"1.00","taker_side":"ask","ts_ms":1781237160276}}

{"type":"trade","sid":2,"seq":457,"msg":{"trade_id":"a7da6fc0-7804-6d02-4157-b637882633b7","market_ticker":"KXBTCPERP1","price":"6.3501","count":"1.00","taker_side":"ask","ts_ms":1781237160276}}

{"type":"trade","sid":2,"seq":458,"msg":{"trade_id":"786f8cc6-59de-6605-7bfb-776fa7542dca","market_ticker":"KXBTCPERP1","price":"6.3501","count":"1.00","taker_side":"ask","ts_ms":1781237160276}}

{"type":"trade","sid":2,"seq":459,"msg":{"trade_id":"ec29e01c-9565-6213-60f8-c9d331252daa","market_ticker":"KXBTCPERP1","price":"6.3500","count":"1.00","taker_side":"ask","ts_ms":1781237160276}}

{"type":"trade","sid":2,"seq":460,"msg":{"trade_id":"0f48e975-3e14-6691-5dc8-e26a677a60d3","market_ticker":"KXBTCPERP1","price":"6.3500","count":"1.00","taker_side":"ask","ts_ms":1781237160276}}

{"type":"trade","sid":2,"seq":461,"msg":{"trade_id":"e87bead4-75ec-6473-775e-f1e0de26b452","market_ticker":"KXBTCPERP1","price":"6.3500","count":"1.00","taker_side":"ask","ts_ms":1781237160276}}

{"type":"trade","sid":2,"seq":462,"msg":{"trade_id":"7c7ca135-acd0-6472-4789-fcc9f5e4e0f3","market_ticker":"KXBTCPERP1","price":"6.3499","count":"1.00","taker_side":"ask","ts_ms":1781237160276}}

{"type":"trade","sid":2,"seq":463,"msg":{"trade_id":"46956594-94d2-667d-749d-078e2238d827","market_ticker":"KXBTCPERP1","price":"6.3499","count":"1.00","taker_side":"ask","ts_ms":1781237160276}}

{"type":"trade","sid":2,"seq":464,"msg":{"trade_id":"988f433b-bb06-69fb-6b72-e86e374e686b","market_ticker":"KXBTCPERP1","price":"6.3499","count":"1.00","taker_side":"ask","ts_ms":1781237160276}}

{"type":"trade","sid":2,"seq":465,"msg":{"trade_id":"6d9dc420-be23-6918-62f2-0f41cbb36506","market_ticker":"KXBTCPERP1","price":"6.3498","count":"1.00","taker_side":"ask","ts_ms":1781237160276}}

{"type":"trade","sid":2,"seq":466,"msg":{"trade_id":"5740cfc3-331d-6efe-613f-b567caa443a6","market_ticker":"KXBTCPERP1","price":"6.3498","count":"1.00","taker_side":"ask","ts_ms":1781237160276}}

{"type":"trade","sid":2,"seq":467,"msg":{"trade_id":"c41ddc0a-d89b-691b-4038-2402799e4002","market_ticker":"KXBTCPERP1","price":"6.3497","count":"1.00","taker_side":"ask","ts_ms":1781237160276}}

{"type":"trade","sid":2,"seq":468,"msg":{"trade_id":"1089635b-3a39-6fc0-52ca-428880b7d14b","market_ticker":"KXBTCPERP1","price":"6.3497","count":"1.00","taker_side":"ask","ts_ms":1781237160276}}

{"type":"trade","sid":2,"seq":469,"msg":{"trade_id":"a3f1129f-ff7b-6b3c-56f0-e5c1b2cf127a","market_ticker":"KXBTCPERP1","price":"6.3497","count":"1.00","taker_side":"ask","ts_ms":1781237160276}}

{"type":"trade","sid":2,"seq":470,"msg":{"trade_id":"b6497b66-fa88-675f-7bfa-e2d057fdde29","market_ticker":"KXBTCPERP1","price":"6.3497","count":"1.00","taker_side":"ask","ts_ms":1781237160276}}

{"type":"trade","sid":2,"seq":471,"msg":{"trade_id":"aab15bd3-f39b-6821-5051-b9345879ee66","market_ticker":"KXBTCPERP1","price":"6.3497","count":"1.00","taker_side":"ask","ts_ms":1781237160276}}

{"type":"trade","sid":2,"seq":472,"msg":{"trade_id":"bcf0fb37-b65d-62a0-6094-415d4f362e64","market_ticker":"KXBTCPERP1","price":"6.3496","count":"1.00","taker_side":"ask","ts_ms":1781237160276}}

{"type":"trade","sid":2,"seq":473,"msg":{"trade_id":"64aac857-f1c7-6a5f-5a67-0849760b91b7","market_ticker":"KXBTCPERP1","price":"6.3495","count":"1.00","taker_side":"ask","ts_ms":1781237160276}}

{"type":"trade","sid":2,"seq":474,"msg":{"trade_id":"53320098-5b3e-6cf2-7e01-ec979b7aa8cb","market_ticker":"KXBTCPERP1","price":"6.3495","count":"1.00","taker_side":"ask","ts_ms":1781237160276}}

{"type":"trade","sid":2,"seq":475,"msg":{"trade_id":"57ca9e6d-0fbf-6cc2-57f7-9e050acda803","market_ticker":"KXBTCPERP1","price":"6.3495","count":"1.00","taker_side":"ask","ts_ms":1781237160276}}

{"type":"trade","sid":2,"seq":476,"msg":{"trade_id":"24f9348c-17e7-6d49-464e-1924dc72c744","market_ticker":"KXBTCPERP1","price":"6.3494","count":"1.00","taker_side":"ask","ts_ms":1781237160276}}

{"type":"trade","sid":2,"seq":477,"msg":{"trade_id":"fab47f95-36de-652e-765d-9120f92175fe","market_ticker":"KXBTCPERP1","price":"6.3494","count":"1.00","taker_side":"ask","ts_ms":1781237160276}}

{"type":"trade","sid":2,"seq":478,"msg":{"trade_id":"d050750c-a7bf-6651-571d-e3bbc3c7374c","market_ticker":"KXBTCPERP1","price":"6.3494","count":"1.00","taker_side":"ask","ts_ms":1781237160276}}

{"type":"trade","sid":2,"seq":479,"msg":{"trade_id":"94a432b0-7ca6-6c24-5678-65c91e436962","market_ticker":"KXBTCPERP1","price":"6.3493","count":"1.00","taker_side":"ask","ts_ms":1781237160276}}

{"type":"trade","sid":2,"seq":480,"msg":{"trade_id":"ab70476f-cf62-671b-66c7-7c8ac02dea73","market_ticker":"KXBTCPERP1","price":"6.3493","count":"1.00","taker_side":"ask","ts_ms":1781237160276}}

{"type":"trade","sid":2,"seq":481,"msg":{"trade_id":"48f28517-c62d-6b90-546d-deb1ad65f5a7","market_ticker":"KXBTCPERP1","price":"6.3493","count":"1.00","taker_side":"ask","ts_ms":1781237160276}}

{"type":"trade","sid":2,"seq":482,"msg":{"trade_id":"2a05fea9-b4e4-63ec-7822-f84a81e90b07","market_ticker":"KXBTCPERP1","price":"6.3492","count":"1.00","taker_side":"ask","ts_ms":1781237160276}}

{"type":"trade","sid":2,"seq":483,"msg":{"trade_id":"c1240136-0ad4-6838-418d-37a6ba41fb4f","market_ticker":"KXBTCPERP1","price":"6.3492","count":"1.00","taker_side":"ask","ts_ms":1781237160276}}

{"type":"trade","sid":2,"seq":484,"msg":{"trade_id":"a003b527-f4cf-6d02-6070-86d365d3bd63","market_ticker":"KXBTCPERP1","price":"6.3492","count":"1.00","taker_side":"ask","ts_ms":1781237160276}}

{"type":"trade","sid":2,"seq":485,"msg":{"trade_id":"471700a2-fd48-6f9c-60ce-8cae45b5cbbe","market_ticker":"KXBTCPERP1","price":"6.3492","count":"1.00","taker_side":"ask","ts_ms":1781237160276}}

{"type":"trade","sid":2,"seq":486,"msg":{"trade_id":"23cbda14-9fe8-6fbd-72a5-a6777c4dd20c","market_ticker":"KXBTCPERP1","price":"6.3491","count":"1.00","taker_side":"ask","ts_ms":1781237160276}}

{"type":"trade","sid":2,"seq":487,"msg":{"trade_id":"797eac3f-347d-6e68-6be7-fe7f1594bdff","market_ticker":"KXBTCPERP1","price":"6.3491","count":"1.00","taker_side":"ask","ts_ms":1781237160276}}

{"type":"trade","sid":2,"seq":488,"msg":{"trade_id":"bda6a826-8276-65bc-63e1-9edc24b24d48","market_ticker":"KXBTCPERP1","price":"6.3491","count":"1.00","taker_side":"ask","ts_ms":1781237160276}}

{"type":"trade","sid":2,"seq":489,"msg":{"trade_id":"46948512-e377-6e77-51e3-d0a86356f6fc","market_ticker":"KXBTCPERP1","price":"6.3491","count":"1.00","taker_side":"ask","ts_ms":1781237160276}}

{"type":"trade","sid":2,"seq":490,"msg":{"trade_id":"34cb5820-3c87-6f6e-6d9a-406c22b9cde1","market_ticker":"KXBTCPERP1","price":"6.3491","count":"1.00","taker_side":"ask","ts_ms":1781237160276}}

{"type":"trade","sid":2,"seq":491,"msg":{"trade_id":"c88fe926-2168-67ec-49e4-44a7ff3af66d","market_ticker":"KXBTCPERP1","price":"6.3489","count":"1.00","taker_side":"ask","ts_ms":1781237160276}}

{"type":"trade","sid":2,"seq":492,"msg":{"trade_id":"b78c1807-8feb-6857-6d46-9849fc557ff4","market_ticker":"KXBTCPERP1","price":"6.3489","count":"1.00","taker_side":"ask","ts_ms":1781237160276}}

{"type":"trade","sid":2,"seq":493,"msg":{"trade_id":"b1ef6ac4-a5b6-6d36-7a25-1d71cabe3c9b","market_ticker":"KXBTCPERP1","price":"6.3489","count":"1.00","taker_side":"ask","ts_ms":1781237160276}}

{"type":"trade","sid":2,"seq":494,"msg":{"trade_id":"21135636-60bb-63df-52b2-f6bf8e544323","market_ticker":"KXBTCPERP1","price":"6.3488","count":"1.00","taker_side":"ask","ts_ms":1781237160276}}

{"type":"trade","sid":2,"seq":495,"msg":{"trade_id":"d32e5581-6530-6524-72d3-2a5e17872f50","market_ticker":"KXBTCPERP1","price":"6.3488","count":"1.00","taker_side":"ask","ts_ms":1781237160276}}

{"type":"trade","sid":2,"seq":496,"msg":{"trade_id":"6e8420b4-dbae-6297-702d-f21f083f4da8","market_ticker":"KXBTCPERP1","price":"6.3488","count":"1.00","taker_side":"ask","ts_ms":1781237160276}}

{"type":"trade","sid":2,"seq":497,"msg":{"trade_id":"a6241e9e-0fef-680b-7e5c-c96dd4dec42e","market_ticker":"KXBTCPERP1","price":"6.3488","count":"1.00","taker_side":"ask","ts_ms":1781237160276}}

{"type":"trade","sid":2,"seq":498,"msg":{"trade_id":"6ed03e68-0a91-6a87-5e94-a6a2763eb8a6","market_ticker":"KXBTCPERP1","price":"6.3488","count":"1.00","taker_side":"ask","ts_ms":1781237160276}}

{"type":"trade","sid":2,"seq":499,"msg":{"trade_id":"3f35f083-662c-6e72-60fb-e6317de98e08","market_ticker":"KXBTCPERP1","price":"6.3488","count":"1.00","taker_side":"ask","ts_ms":1781237160276}}

{"type":"trade","sid":2,"seq":500,"msg":{"trade_id":"75ed0771-162f-679c-6bef-b3ea9f2f1a21","market_ticker":"KXBTCPERP1","price":"6.3488","count":"1.00","taker_side":"ask","ts_ms":1781237160276}}

{"type":"trade","sid":2,"seq":501,"msg":{"trade_id":"41c51922-ea3a-69ac-49cc-2da491b66e96","market_ticker":"KXBTCPERP1","price":"6.3488","count":"1.00","taker_side":"ask","ts_ms":1781237160276}}

{"type":"trade","sid":2,"seq":502,"msg":{"trade_id":"96d5cbdd-e7cb-6c67-7fbb-ced5027aa3cf","market_ticker":"KXBTCPERP1","price":"6.3488","count":"1.00","taker_side":"ask","ts_ms":1781237160276}}

{"type":"trade","sid":2,"seq":503,"msg":{"trade_id":"d2ad1c42-575f-6612-510e-ff856342e682","market_ticker":"KXBTCPERP1","price":"6.3488","count":"1.00","taker_side":"ask","ts_ms":1781237160276}}

{"type":"trade","sid":2,"seq":504,"msg":{"trade_id":"35e61f2b-e25c-6524-5e19-43f6fb9dcc3d","market_ticker":"KXBTCPERP1","price":"6.3488","count":"1.00","taker_side":"ask","ts_ms":1781237160276}}

{"type":"trade","sid":2,"seq":505,"msg":{"trade_id":"ee7b2d38-6ed7-6ab0-4979-b1665b3853bf","market_ticker":"KXBTCPERP1","price":"6.3487","count":"1.00","taker_side":"ask","ts_ms":1781237160276}}

{"type":"trade","sid":2,"seq":506,"msg":{"trade_id":"5bee57d6-54fd-6241-6284-f5d33fac17c2","market_ticker":"KXBTCPERP1","price":"6.3486","count":"1.00","taker_side":"ask","ts_ms":1781237160276}}

{"type":"trade","sid":2,"seq":507,"msg":{"trade_id":"f6f25166-ec18-65af-4372-c2743e16a7d3","market_ticker":"KXBTCPERP1","price":"6.3486","count":"1.00","taker_side":"ask","ts_ms":1781237160276}}

{"type":"trade","sid":2,"seq":508,"msg":{"trade_id":"ffd79b4e-46be-6983-6c95-3e364f5a7c97","market_ticker":"KXBTCPERP1","price":"6.3486","count":"1.00","taker_side":"ask","ts_ms":1781237160276}}

{"type":"trade","sid":2,"seq":509,"msg":{"trade_id":"2da8f44e-99ab-606e-77d5-415be57b1944","market_ticker":"KXBTCPERP1","price":"6.3484","count":"1.00","taker_side":"ask","ts_ms":1781237160276}}

{"type":"trade","sid":2,"seq":510,"msg":{"trade_id":"284e4b21-753c-6485-6c8e-ca5ba9745853","market_ticker":"KXBTCPERP1","price":"6.3484","count":"1.00","taker_side":"ask","ts_ms":1781237160276}}

{"type":"trade","sid":2,"seq":511,"msg":{"trade_id":"3282ae1d-80b6-6c65-5f1a-cff564676b57","market_ticker":"KXBTCPERP1","price":"6.3484","count":"1.00","taker_side":"ask","ts_ms":1781237160276}}

{"type":"trade","sid":2,"seq":512,"msg":{"trade_id":"60fd7074-af74-6f3d-40a1-817174b8ea00","market_ticker":"KXBTCPERP1","price":"6.3484","count":"1.00","taker_side":"ask","ts_ms":1781237160276}}

{"type":"trade","sid":2,"seq":513,"msg":{"trade_id":"1a0e62e0-444a-6aa6-524e-4d2bbfb5b20a","market_ticker":"KXBTCPERP1","price":"6.3484","count":"1.00","taker_side":"ask","ts_ms":1781237160276}}

{"type":"trade","sid":2,"seq":514,"msg":{"trade_id":"65c7ab20-f33e-608f-68f3-ce1ce35810f4","market_ticker":"KXBTCPERP1","price":"6.3484","count":"1.00","taker_side":"ask","ts_ms":1781237160276}}

{"type":"trade","sid":2,"seq":515,"msg":{"trade_id":"7adf9694-2234-6828-52f6-671bb375ab03","market_ticker":"KXBTCPERP1","price":"6.3484","count":"1.00","taker_side":"ask","ts_ms":1781237160276}}

{"type":"trade","sid":2,"seq":516,"msg":{"trade_id":"27a6a402-8f05-60fc-7523-485a4ff6a36e","market_ticker":"KXBTCPERP1","price":"6.3483","count":"1.00","taker_side":"ask","ts_ms":1781237160276}}

{"type":"trade","sid":2,"seq":517,"msg":{"trade_id":"d894255d-951b-6b34-70b2-5227d105c546","market_ticker":"KXBTCPERP1","price":"6.3481","count":"1.00","taker_side":"ask","ts_ms":1781237160276}}

{"type":"trade","sid":2,"seq":518,"msg":{"trade_id":"04ea0886-f1b3-67a2-5698-60e2e727c5a7","market_ticker":"KXBTCPERP1","price":"6.3481","count":"1.00","taker_side":"ask","ts_ms":1781237160276}}

{"type":"trade","sid":2,"seq":519,"msg":{"trade_id":"da1fc45b-3c3b-6bdf-7466-1c899bafa1e9","market_ticker":"KXBTCPERP1","price":"6.3480","count":"1.00","taker_side":"ask","ts_ms":1781237160276}}

{"type":"trade","sid":2,"seq":520,"msg":{"trade_id":"cf0437fe-2e8f-6c5e-5be7-33926d1a6455","market_ticker":"KXBTCPERP1","price":"6.3479","count":"1.00","taker_side":"ask","ts_ms":1781237160276}}

{"type":"trade","sid":2,"seq":521,"msg":{"trade_id":"0fcce211-9ae5-66af-4653-88aaa2a57ae4","market_ticker":"KXBTCPERP1","price":"6.3479","count":"1.00","taker_side":"ask","ts_ms":1781237160276}}

{"type":"trade","sid":2,"seq":522,"msg":{"trade_id":"81594379-d056-6b84-6759-a175105d52d5","market_ticker":"KXBTCPERP1","price":"6.3478","count":"1.00","taker_side":"ask","ts_ms":1781237160276}}

{"type":"trade","sid":2,"seq":523,"msg":{"trade_id":"19c11dd7-dbde-6d42-6654-1677eee17a49","market_ticker":"KXBTCPERP1","price":"6.3478","count":"1.00","taker_side":"ask","ts_ms":1781237160276}}

{"type":"trade","sid":2,"seq":524,"msg":{"trade_id":"665d98e3-ba1c-60db-7048-9daa7d697d1f","market_ticker":"KXBTCPERP1","price":"6.3476","count":"1.00","taker_side":"ask","ts_ms":1781237160276}}

{"type":"trade","sid":2,"seq":525,"msg":{"trade_id":"17cb9e76-4ad8-60c5-464c-a8f4c6388d90","market_ticker":"KXBTCPERP1","price":"6.3476","count":"1.00","taker_side":"ask","ts_ms":1781237160276}}

{"type":"trade","sid":2,"seq":526,"msg":{"trade_id":"fe2c4608-fed6-66f2-5f1a-40ec64bf89bb","market_ticker":"KXBTCPERP1","price":"6.3476","count":"1.00","taker_side":"ask","ts_ms":1781237160276}}

{"type":"trade","sid":2,"seq":527,"msg":{"trade_id":"cecf457c-4ae7-683e-671e-516741b8016b","market_ticker":"KXBTCPERP1","price":"6.3475","count":"1.00","taker_side":"ask","ts_ms":1781237160276}}

{"type":"trade","sid":2,"seq":528,"msg":{"trade_id":"9b1688e6-a2b3-6e00-5882-602b17af4ea8","market_ticker":"KXBTCPERP1","price":"6.3475","count":"1.00","taker_side":"ask","ts_ms":1781237160276}}

{"type":"trade","sid":2,"seq":529,"msg":{"trade_id":"be7692e0-7440-6729-4a2f-020d3389e720","market_ticker":"KXBTCPERP1","price":"6.3475","count":"1.00","taker_side":"ask","ts_ms":1781237160276}}

{"type":"trade","sid":2,"seq":530,"msg":{"trade_id":"59a7f86b-2498-6523-4101-88026d6c1f74","market_ticker":"KXBTCPERP1","price":"6.3475","count":"1.00","taker_side":"ask","ts_ms":1781237160276}}

{"type":"trade","sid":2,"seq":531,"msg":{"trade_id":"51679bfb-65ae-6819-56ad-7b379550d117","market_ticker":"KXBTCPERP1","price":"6.3475","count":"1.00","taker_side":"ask","ts_ms":1781237160276}}

{"type":"trade","sid":2,"seq":532,"msg":{"trade_id":"b7b478db-7e95-66c2-65d9-6522a3c6dfb3","market_ticker":"KXBTCPERP1","price":"6.3474","count":"1.00","taker_side":"ask","ts_ms":1781237160276}}

{"type":"trade","sid":2,"seq":533,"msg":{"trade_id":"78acfc26-424a-63bf-6aeb-d503d5a91dec","market_ticker":"KXBTCPERP1","price":"6.3474","count":"1.00","taker_side":"ask","ts_ms":1781237160276}}

{"type":"trade","sid":2,"seq":534,"msg":{"trade_id":"a2779ef4-e4f7-6996-6e05-1749f7686812","market_ticker":"KXBTCPERP1","price":"6.3473","count":"1.00","taker_side":"ask","ts_ms":1781237160276}}

{"type":"trade","sid":2,"seq":535,"msg":{"trade_id":"a5871e29-5aa1-6f84-6dcf-accc09b55241","market_ticker":"KXBTCPERP1","price":"6.3473","count":"1.00","taker_side":"ask","ts_ms":1781237160276}}

{"type":"orderbook_delta","sid":1,"seq":712,"msg":{"market_ticker":"KXBTCPERP1","price":"6.3473","delta":"-1.00","side":"bid","ts_ms":1781237160287}}

{"type":"orderbook_delta","sid":1,"seq":713,"msg":{"market_ticker":"KXBTCPERP1","price":"6.3473","delta":"-1.00","side":"bid","ts_ms":1781237160287}}

{"type":"orderbook_delta","sid":1,"seq":714,"msg":{"market_ticker":"KXBTCPERP1","price":"6.3472","delta":"-1.00","side":"bid","ts_ms":1781237160287}}

{"type":"orderbook_delta","sid":1,"seq":715,"msg":{"market_ticker":"KXBTCPERP1","price":"6.3472","delta":"-1.00","side":"bid","ts_ms":1781237160287}}

{"type":"orderbook_delta","sid":1,"seq":716,"msg":{"market_ticker":"KXBTCPERP1","price":"6.3472","delta":"-1.00","side":"bid","ts_ms":1781237160287}}

{"type":"orderbook_delta","sid":1,"seq":717,"msg":{"market_ticker":"KXBTCPERP1","price":"6.3471","delta":"-1.00","side":"bid","ts_ms":1781237160287}}

{"type":"orderbook_delta","sid":1,"seq":718,"msg":{"market_ticker":"KXBTCPERP1","price":"6.3471","delta":"-1.00","side":"bid","ts_ms":1781237160287}}

{"type":"orderbook_delta","sid":1,"seq":719,"msg":{"market_ticker":"KXBTCPERP1","price":"6.3471","delta":"-1.00","side":"bid","ts_ms":1781237160287}}

{"type":"orderbook_delta","sid":1,"seq":720,"msg":{"market_ticker":"KXBTCPERP1","price":"6.3471","delta":"-1.00","side":"bid","ts_ms":1781237160287}}

{"type":"orderbook_delta","sid":1,"seq":721,"msg":{"market_ticker":"KXBTCPERP1","price":"6.3470","delta":"-1.00","side":"bid","ts_ms":1781237160287}}

{"type":"orderbook_delta","sid":1,"seq":722,"msg":{"market_ticker":"KXBTCPERP1","price":"6.3470","delta":"-1.00","side":"bid","ts_ms":1781237160287}}

{"type":"orderbook_delta","sid":1,"seq":723,"msg":{"market_ticker":"KXBTCPERP1","price":"6.3470","delta":"-1.00","side":"bid","ts_ms":1781237160287}}

{"type":"orderbook_delta","sid":1,"seq":724,"msg":{"market_ticker":"KXBTCPERP1","price":"6.3470","delta":"-1.00","side":"bid","ts_ms":1781237160287}}

{"type":"orderbook_delta","sid":1,"seq":725,"msg":{"market_ticker":"KXBTCPERP1","price":"6.3469","delta":"-1.00","side":"bid","ts_ms":1781237160287}}

{"type":"orderbook_delta","sid":1,"seq":726,"msg":{"market_ticker":"KXBTCPERP1","price":"6.3469","delta":"-1.00","side":"bid","ts_ms":1781237160287}}

{"type":"orderbook_delta","sid":1,"seq":727,"msg":{"market_ticker":"KXBTCPERP1","price":"6.3469","delta":"-1.00","side":"bid","ts_ms":1781237160287}}

{"type":"orderbook_delta","sid":1,"seq":728,"msg":{"market_ticker":"KXBTCPERP1","price":"6.3469","delta":"-1.00","side":"bid","ts_ms":1781237160287}}

{"type":"orderbook_delta","sid":1,"seq":729,"msg":{"market_ticker":"KXBTCPERP1","price":"6.3469","delta":"-1.00","side":"bid","ts_ms":1781237160287}}

{"type":"orderbook_delta","sid":1,"seq":730,"msg":{"market_ticker":"KXBTCPERP1","price":"6.3469","delta":"-1.00","side":"bid","ts_ms":1781237160287}}

{"type":"orderbook_delta","sid":1,"seq":731,"msg":{"market_ticker":"KXBTCPERP1","price":"6.3468","delta":"-1.00","side":"bid","ts_ms":1781237160287}}

{"type":"orderbook_delta","sid":1,"seq":732,"msg":{"market_ticker":"KXBTCPERP1","price":"6.3468","delta":"-1.00","side":"bid","ts_ms":1781237160287}}

{"type":"orderbook_delta","sid":1,"seq":733,"msg":{"market_ticker":"KXBTCPERP1","price":"6.3468","delta":"-1.00","side":"bid","ts_ms":1781237160287}}

{"type":"orderbook_delta","sid":1,"seq":734,"msg":{"market_ticker":"KXBTCPERP1","price":"6.3468","delta":"-1.00","side":"bid","ts_ms":1781237160287}}

{"type":"orderbook_delta","sid":1,"seq":735,"msg":{"market_ticker":"KXBTCPERP1","price":"6.3467","delta":"-1.00","side":"bid","ts_ms":1781237160287}}

{"type":"orderbook_delta","sid":1,"seq":736,"msg":{"market_ticker":"KXBTCPERP1","price":"6.3467","delta":"-1.00","side":"bid","ts_ms":1781237160287}}

{"type":"orderbook_delta","sid":1,"seq":737,"msg":{"market_ticker":"KXBTCPERP1","price":"6.3466","delta":"-1.00","side":"bid","ts_ms":1781237160287}}

{"type":"orderbook_delta","sid":1,"seq":738,"msg":{"market_ticker":"KXBTCPERP1","price":"6.3466","delta":"-1.00","side":"bid","ts_ms":1781237160287}}

{"type":"orderbook_delta","sid":1,"seq":739,"msg":{"market_ticker":"KXBTCPERP1","price":"6.3466","delta":"-1.00","side":"bid","ts_ms":1781237160287}}

{"type":"orderbook_delta","sid":1,"seq":740,"msg":{"market_ticker":"KXBTCPERP1","price":"6.3466","delta":"-1.00","side":"bid","ts_ms":1781237160287}}

{"type":"orderbook_delta","sid":1,"seq":741,"msg":{"market_ticker":"KXBTCPERP1","price":"6.3466","delta":"-1.00","side":"bid","ts_ms":1781237160287}}

{"type":"orderbook_delta","sid":1,"seq":742,"msg":{"market_ticker":"KXBTCPERP1","price":"6.3466","delta":"-1.00","side":"bid","ts_ms":1781237160287}}

{"type":"orderbook_delta","sid":1,"seq":743,"msg":{"market_ticker":"KXBTCPERP1","price":"6.3465","delta":"-1.00","side":"bid","ts_ms":1781237160287}}

{"type":"orderbook_delta","sid":1,"seq":744,"msg":{"market_ticker":"KXBTCPERP1","price":"6.3465","delta":"-1.00","side":"bid","ts_ms":1781237160287}}

{"type":"orderbook_delta","sid":1,"seq":745,"msg":{"market_ticker":"KXBTCPERP1","price":"6.3465","delta":"-1.00","side":"bid","ts_ms":1781237160287}}

{"type":"orderbook_delta","sid":1,"seq":746,"msg":{"market_ticker":"KXBTCPERP1","price":"6.3465","delta":"-1.00","side":"bid","ts_ms":1781237160287}}

{"type":"orderbook_delta","sid":1,"seq":747,"msg":{"market_ticker":"KXBTCPERP1","price":"6.3465","delta":"-1.00","side":"bid","ts_ms":1781237160287}}

{"type":"orderbook_delta","sid":1,"seq":748,"msg":{"market_ticker":"KXBTCPERP1","price":"6.3465","delta":"-1.00","side":"bid","ts_ms":1781237160287}}

{"type":"orderbook_delta","sid":1,"seq":749,"msg":{"market_ticker":"KXBTCPERP1","price":"6.3465","delta":"-1.00","side":"bid","ts_ms":1781237160287}}

{"type":"orderbook_delta","sid":1,"seq":750,"msg":{"market_ticker":"KXBTCPERP1","price":"6.3465","delta":"-1.00","side":"bid","ts_ms":1781237160287}}

{"type":"orderbook_delta","sid":1,"seq":751,"msg":{"market_ticker":"KXBTCPERP1","price":"6.3464","delta":"-1.00","side":"bid","ts_ms":1781237160287}}

{"type":"orderbook_delta","sid":1,"seq":752,"msg":{"market_ticker":"KXBTCPERP1","price":"6.3464","delta":"-1.00","side":"bid","ts_ms":1781237160287}}

{"type":"orderbook_delta","sid":1,"seq":753,"msg":{"market_ticker":"KXBTCPERP1","price":"6.3464","delta":"-1.00","side":"bid","ts_ms":1781237160287}}

{"type":"orderbook_delta","sid":1,"seq":754,"msg":{"market_ticker":"KXBTCPERP1","price":"6.3463","delta":"-1.00","side":"bid","ts_ms":1781237160287}}

{"type":"orderbook_delta","sid":1,"seq":755,"msg":{"market_ticker":"KXBTCPERP1","price":"6.3462","delta":"-1.00","side":"bid","ts_ms":1781237160287}}

{"type":"orderbook_delta","sid":1,"seq":756,"msg":{"market_ticker":"KXBTCPERP1","price":"6.3462","delta":"-1.00","side":"bid","ts_ms":1781237160287}}

{"type":"orderbook_delta","sid":1,"seq":757,"msg":{"market_ticker":"KXBTCPERP1","price":"6.3462","delta":"-1.00","side":"bid","ts_ms":1781237160287}}

{"type":"orderbook_delta","sid":1,"seq":758,"msg":{"market_ticker":"KXBTCPERP1","price":"6.3462","delta":"-1.00","side":"bid","ts_ms":1781237160287}}

{"type":"orderbook_delta","sid":1,"seq":759,"msg":{"market_ticker":"KXBTCPERP1","price":"6.3461","delta":"-1.00","side":"bid","ts_ms":1781237160287}}

{"type":"orderbook_delta","sid":1,"seq":760,"msg":{"market_ticker":"KXBTCPERP1","price":"6.3461","delta":"-1.00","side":"bid","ts_ms":1781237160287}}

{"type":"orderbook_delta","sid":1,"seq":761,"msg":{"market_ticker":"KXBTCPERP1","price":"6.3461","delta":"-1.00","side":"bid","ts_ms":1781237160287}}

{"type":"orderbook_delta","sid":1,"seq":762,"msg":{"market_ticker":"KXBTCPERP1","price":"6.3460","delta":"-1.00","side":"bid","ts_ms":1781237160287}}

{"type":"orderbook_delta","sid":1,"seq":763,"msg":{"market_ticker":"KXBTCPERP1","price":"6.3460","delta":"-1.00","side":"bid","ts_ms":1781237160287}}

{"type":"orderbook_delta","sid":1,"seq":764,"msg":{"market_ticker":"KXBTCPERP1","price":"6.3460","delta":"-1.00","side":"bid","ts_ms":1781237160287}}

{"type":"orderbook_delta","sid":1,"seq":765,"msg":{"market_ticker":"KXBTCPERP1","price":"6.3460","delta":"-1.00","side":"bid","ts_ms":1781237160287}}

{"type":"orderbook_delta","sid":1,"seq":766,"msg":{"market_ticker":"KXBTCPERP1","price":"6.3459","delta":"-1.00","side":"bid","ts_ms":1781237160287}}

{"type":"orderbook_delta","sid":1,"seq":767,"msg":{"market_ticker":"KXBTCPERP1","price":"6.3459","delta":"-1.00","side":"bid","ts_ms":1781237160287}}

{"type":"orderbook_delta","sid":1,"seq":768,"msg":{"market_ticker":"KXBTCPERP1","price":"6.3459","delta":"-1.00","side":"bid","ts_ms":1781237160287}}

{"type":"orderbook_delta","sid":1,"seq":769,"msg":{"market_ticker":"KXBTCPERP1","price":"6.3459","delta":"-1.00","side":"bid","ts_ms":1781237160287}}

{"type":"orderbook_delta","sid":1,"seq":770,"msg":{"market_ticker":"KXBTCPERP1","price":"6.3459","delta":"-1.00","side":"bid","ts_ms":1781237160287}}

{"type":"orderbook_delta","sid":1,"seq":771,"msg":{"market_ticker":"KXBTCPERP1","price":"6.3458","delta":"-1.00","side":"bid","ts_ms":1781237160287}}

{"type":"orderbook_delta","sid":1,"seq":772,"msg":{"market_ticker":"KXBTCPERP1","price":"6.3458","delta":"-1.00","side":"bid","ts_ms":1781237160287}}

{"type":"orderbook_delta","sid":1,"seq":773,"msg":{"market_ticker":"KXBTCPERP1","price":"6.3458","delta":"-1.00","side":"bid","ts_ms":1781237160287}}

{"type":"orderbook_delta","sid":1,"seq":774,"msg":{"market_ticker":"KXBTCPERP1","price":"6.3458","delta":"-1.00","side":"bid","ts_ms":1781237160287}}

{"type":"orderbook_delta","sid":1,"seq":775,"msg":{"market_ticker":"KXBTCPERP1","price":"6.3457","delta":"-1.00","side":"bid","ts_ms":1781237160287}}

{"type":"orderbook_delta","sid":1,"seq":776,"msg":{"market_ticker":"KXBTCPERP1","price":"6.3457","delta":"-1.00","side":"bid","ts_ms":1781237160287}}

{"type":"orderbook_delta","sid":1,"seq":777,"msg":{"market_ticker":"KXBTCPERP1","price":"6.3457","delta":"-1.00","side":"bid","ts_ms":1781237160287}}

{"type":"orderbook_delta","sid":1,"seq":778,"msg":{"market_ticker":"KXBTCPERP1","price":"6.3457","delta":"-1.00","side":"bid","ts_ms":1781237160287}}

{"type":"orderbook_delta","sid":1,"seq":779,"msg":{"market_ticker":"KXBTCPERP1","price":"6.3457","delta":"-1.00","side":"bid","ts_ms":1781237160287}}

{"type":"orderbook_delta","sid":1,"seq":780,"msg":{"market_ticker":"KXBTCPERP1","price":"6.3456","delta":"-1.00","side":"bid","ts_ms":1781237160287}}

{"type":"orderbook_delta","sid":1,"seq":781,"msg":{"market_ticker":"KXBTCPERP1","price":"6.3456","delta":"-1.00","side":"bid","ts_ms":1781237160287}}

{"type":"orderbook_delta","sid":1,"seq":782,"msg":{"market_ticker":"KXBTCPERP1","price":"6.3455","delta":"-1.00","side":"bid","ts_ms":1781237160287}}

{"type":"orderbook_delta","sid":1,"seq":783,"msg":{"market_ticker":"KXBTCPERP1","price":"6.3455","delta":"-1.00","side":"bid","ts_ms":1781237160287}}

{"type":"orderbook_delta","sid":1,"seq":784,"msg":{"market_ticker":"KXBTCPERP1","price":"6.3454","delta":"-1.00","side":"bid","ts_ms":1781237160287}}

{"type":"orderbook_delta","sid":1,"seq":785,"msg":{"market_ticker":"KXBTCPERP1","price":"6.3454","delta":"-1.00","side":"bid","ts_ms":1781237160287}}

{"type":"orderbook_delta","sid":1,"seq":786,"msg":{"market_ticker":"KXBTCPERP1","price":"6.3454","delta":"-1.00","side":"bid","ts_ms":1781237160287}}

{"type":"orderbook_delta","sid":1,"seq":787,"msg":{"market_ticker":"KXBTCPERP1","price":"6.3453","delta":"-1.00","side":"bid","ts_ms":1781237160287}}

{"type":"orderbook_delta","sid":1,"seq":788,"msg":{"market_ticker":"KXBTCPERP1","price":"6.3453","delta":"-1.00","side":"bid","ts_ms":1781237160287}}

{"type":"orderbook_delta","sid":1,"seq":789,"msg":{"market_ticker":"KXBTCPERP1","price":"6.3453","delta":"-1.00","side":"bid","ts_ms":1781237160287}}

{"type":"orderbook_delta","sid":1,"seq":790,"msg":{"market_ticker":"KXBTCPERP1","price":"6.3452","delta":"-1.00","side":"bid","ts_ms":1781237160287}}

{"type":"orderbook_delta","sid":1,"seq":791,"msg":{"market_ticker":"KXBTCPERP1","price":"6.3452","delta":"-1.00","side":"bid","ts_ms":1781237160287}}

{"type":"orderbook_delta","sid":1,"seq":792,"msg":{"market_ticker":"KXBTCPERP1","price":"6.3452","delta":"-1.00","side":"bid","ts_ms":1781237160287}}

{"type":"orderbook_delta","sid":1,"seq":793,"msg":{"market_ticker":"KXBTCPERP1","price":"6.3452","delta":"-1.00","side":"bid","ts_ms":1781237160287}}

{"type":"orderbook_delta","sid":1,"seq":794,"msg":{"market_ticker":"KXBTCPERP1","price":"6.3451","delta":"-1.00","side":"bid","ts_ms":1781237160287}}

{"type":"orderbook_delta","sid":1,"seq":795,"msg":{"market_ticker":"KXBTCPERP1","price":"6.3451","delta":"-1.00","side":"bid","ts_ms":1781237160287}}

{"type":"orderbook_delta","sid":1,"seq":796,"msg":{"market_ticker":"KXBTCPERP1","price":"6.3451","delta":"-1.00","side":"bid","ts_ms":1781237160287}}

{"type":"orderbook_delta","sid":1,"seq":797,"msg":{"market_ticker":"KXBTCPERP1","price":"6.3451","delta":"-1.00","side":"bid","ts_ms":1781237160287}}

{"type":"orderbook_delta","sid":1,"seq":798,"msg":{"market_ticker":"KXBTCPERP1","price":"6.3450","delta":"-1.00","side":"bid","ts_ms":1781237160287}}

{"type":"orderbook_delta","sid":1,"seq":799,"msg":{"market_ticker":"KXBTCPERP1","price":"6.3449","delta":"-1.00","side":"bid","ts_ms":1781237160287}}

{"type":"orderbook_delta","sid":1,"seq":800,"msg":{"market_ticker":"KXBTCPERP1","price":"6.3449","delta":"-1.00","side":"bid","ts_ms":1781237160287}}

{"type":"orderbook_delta","sid":1,"seq":801,"msg":{"market_ticker":"KXBTCPERP1","price":"6.3449","delta":"-1.00","side":"bid","ts_ms":1781237160287}}

{"type":"orderbook_delta","sid":1,"seq":802,"msg":{"market_ticker":"KXBTCPERP1","price":"6.3449","delta":"-1.00","side":"bid","ts_ms":1781237160287}}

{"type":"orderbook_delta","sid":1,"seq":803,"msg":{"market_ticker":"KXBTCPERP1","price":"6.3447","delta":"-1.00","side":"bid","ts_ms":1781237160287}}

{"type":"orderbook_delta","sid":1,"seq":804,"msg":{"market_ticker":"KXBTCPERP1","price":"6.3446","delta":"-1.00","side":"bid","ts_ms":1781237160287}}

{"type":"orderbook_delta","sid":1,"seq":805,"msg":{"market_ticker":"KXBTCPERP1","price":"6.3446","delta":"-1.00","side":"bid","ts_ms":1781237160287}}

{"type":"orderbook_delta","sid":1,"seq":806,"msg":{"market_ticker":"KXBTCPERP1","price":"6.3445","delta":"-1.00","side":"bid","ts_ms":1781237160287}}

{"type":"orderbook_delta","sid":1,"seq":807,"msg":{"market_ticker":"KXBTCPERP1","price":"6.3445","delta":"-1.00","side":"bid","ts_ms":1781237160287}}

{"type":"orderbook_delta","sid":1,"seq":808,"msg":{"market_ticker":"KXBTCPERP1","price":"6.3444","delta":"-1.00","side":"bid","ts_ms":1781237160287}}

{"type":"orderbook_delta","sid":1,"seq":809,"msg":{"market_ticker":"KXBTCPERP1","price":"6.3444","delta":"-1.00","side":"bid","ts_ms":1781237160287}}

{"type":"orderbook_delta","sid":1,"seq":810,"msg":{"market_ticker":"KXBTCPERP1","price":"6.3444","delta":"-1.00","side":"bid","ts_ms":1781237160287}}

{"type":"orderbook_delta","sid":1,"seq":811,"msg":{"market_ticker":"KXBTCPERP1","price":"6.3444","delta":"-1.00","side":"bid","ts_ms":1781237160287}}

{"type":"orderbook_delta","sid":1,"seq":812,"msg":{"market_ticker":"KXBTCPERP1","price":"6.3444","delta":"-1.00","side":"bid","ts_ms":1781237160287}}

{"type":"orderbook_delta","sid":1,"seq":813,"msg":{"market_ticker":"KXBTCPERP1","price":"6.3443","delta":"-1.00","side":"bid","ts_ms":1781237160287}}

{"type":"orderbook_delta","sid":1,"seq":814,"msg":{"market_ticker":"KXBTCPERP1","price":"6.3442","delta":"-1.00","side":"bid","ts_ms":1781237160287}}

{"type":"orderbook_delta","sid":1,"seq":815,"msg":{"market_ticker":"KXBTCPERP1","price":"6.3442","delta":"-1.00","side":"bid","ts_ms":1781237160287}}

{"type":"orderbook_delta","sid":1,"seq":816,"msg":{"market_ticker":"KXBTCPERP1","price":"6.3442","delta":"-1.00","side":"bid","ts_ms":1781237160287}}

{"type":"orderbook_delta","sid":1,"seq":817,"msg":{"market_ticker":"KXBTCPERP1","price":"6.3442","delta":"-1.00","side":"bid","ts_ms":1781237160287}}

{"type":"orderbook_delta","sid":1,"seq":818,"msg":{"market_ticker":"KXBTCPERP1","price":"6.3442","delta":"-1.00","side":"bid","ts_ms":1781237160287}}

{"type":"orderbook_delta","sid":1,"seq":819,"msg":{"market_ticker":"KXBTCPERP1","price":"6.3441","delta":"-1.00","side":"bid","ts_ms":1781237160287}}

{"type":"orderbook_delta","sid":1,"seq":820,"msg":{"market_ticker":"KXBTCPERP1","price":"6.3441","delta":"-1.00","side":"bid","ts_ms":1781237160287}}

{"type":"orderbook_delta","sid":1,"seq":821,"msg":{"market_ticker":"KXBTCPERP1","price":"6.3441","delta":"-1.00","side":"bid","ts_ms":1781237160287}}

{"type":"orderbook_delta","sid":1,"seq":822,"msg":{"market_ticker":"KXBTCPERP1","price":"6.3441","delta":"-1.00","side":"bid","ts_ms":1781237160287}}

{"type":"orderbook_delta","sid":1,"seq":823,"msg":{"market_ticker":"KXBTCPERP1","price":"6.3440","delta":"-1.00","side":"bid","ts_ms":1781237160287}}

{"type":"orderbook_delta","sid":1,"seq":824,"msg":{"market_ticker":"KXBTCPERP1","price":"6.3440","delta":"-1.00","side":"bid","ts_ms":1781237160287}}

{"type":"orderbook_delta","sid":1,"seq":825,"msg":{"market_ticker":"KXBTCPERP1","price":"6.3439","delta":"-1.00","side":"bid","ts_ms":1781237160287}}

{"type":"orderbook_delta","sid":1,"seq":826,"msg":{"market_ticker":"KXBTCPERP1","price":"6.3438","delta":"-1.00","side":"bid","ts_ms":1781237160287}}

{"type":"orderbook_delta","sid":1,"seq":827,"msg":{"market_ticker":"KXBTCPERP1","price":"6.3438","delta":"-1.00","side":"bid","ts_ms":1781237160287}}

{"type":"orderbook_delta","sid":1,"seq":828,"msg":{"market_ticker":"KXBTCPERP1","price":"6.3436","delta":"-1.00","side":"bid","ts_ms":1781237160287}}

{"type":"orderbook_delta","sid":1,"seq":829,"msg":{"market_ticker":"KXBTCPERP1","price":"6.3436","delta":"-1.00","side":"bid","ts_ms":1781237160287}}

{"type":"orderbook_delta","sid":1,"seq":830,"msg":{"market_ticker":"KXBTCPERP1","price":"6.3436","delta":"-1.00","side":"bid","ts_ms":1781237160287}}

{"type":"orderbook_delta","sid":1,"seq":831,"msg":{"market_ticker":"KXBTCPERP1","price":"6.3436","delta":"-1.00","side":"bid","ts_ms":1781237160287}}

{"type":"orderbook_delta","sid":1,"seq":832,"msg":{"market_ticker":"KXBTCPERP1","price":"6.3436","delta":"-1.00","side":"bid","ts_ms":1781237160287}}

{"type":"orderbook_delta","sid":1,"seq":833,"msg":{"market_ticker":"KXBTCPERP1","price":"6.3435","delta":"-1.00","side":"bid","ts_ms":1781237160287}}

{"type":"orderbook_delta","sid":1,"seq":834,"msg":{"market_ticker":"KXBTCPERP1","price":"6.3435","delta":"-1.00","side":"bid","ts_ms":1781237160287}}

{"type":"orderbook_delta","sid":1,"seq":835,"msg":{"market_ticker":"KXBTCPERP1","price":"6.3435","delta":"-1.00","side":"bid","ts_ms":1781237160287}}

{"type":"orderbook_delta","sid":1,"seq":836,"msg":{"market_ticker":"KXBTCPERP1","price":"6.3435","delta":"-1.00","side":"bid","ts_ms":1781237160287}}

{"type":"orderbook_delta","sid":1,"seq":837,"msg":{"market_ticker":"KXBTCPERP1","price":"6.3433","delta":"-1.00","side":"bid","ts_ms":1781237160287}}

{"type":"orderbook_delta","sid":1,"seq":838,"msg":{"market_ticker":"KXBTCPERP1","price":"6.3432","delta":"-1.00","side":"bid","ts_ms":1781237160287}}

{"type":"orderbook_delta","sid":1,"seq":839,"msg":{"market_ticker":"KXBTCPERP1","price":"6.3432","delta":"-1.00","side":"bid","ts_ms":1781237160287}}

{"type":"orderbook_delta","sid":1,"seq":840,"msg":{"market_ticker":"KXBTCPERP1","price":"6.3431","delta":"-1.00","side":"bid","ts_ms":1781237160287}}

{"type":"orderbook_delta","sid":1,"seq":841,"msg":{"market_ticker":"KXBTCPERP1","price":"6.3431","delta":"-1.00","side":"bid","ts_ms":1781237160287}}

{"type":"orderbook_delta","sid":1,"seq":842,"msg":{"market_ticker":"KXBTCPERP1","price":"6.3431","delta":"-1.00","side":"bid","ts_ms":1781237160287}}

{"type":"orderbook_delta","sid":1,"seq":843,"msg":{"market_ticker":"KXBTCPERP1","price":"6.3431","delta":"-1.00","side":"bid","ts_ms":1781237160287}}

{"type":"orderbook_delta","sid":1,"seq":844,"msg":{"market_ticker":"KXBTCPERP1","price":"6.3430","delta":"-1.00","side":"bid","ts_ms":1781237160287}}

{"type":"orderbook_delta","sid":1,"seq":845,"msg":{"market_ticker":"KXBTCPERP1","price":"6.3430","delta":"-1.00","side":"bid","ts_ms":1781237160287}}

{"type":"orderbook_delta","sid":1,"seq":846,"msg":{"market_ticker":"KXBTCPERP1","price":"6.3430","delta":"-1.00","side":"bid","ts_ms":1781237160287}}

{"type":"orderbook_delta","sid":1,"seq":847,"msg":{"market_ticker":"KXBTCPERP1","price":"6.3430","delta":"-1.00","side":"bid","ts_ms":1781237160287}}

{"type":"orderbook_delta","sid":1,"seq":848,"msg":{"market_ticker":"KXBTCPERP1","price":"6.3429","delta":"-1.00","side":"bid","ts_ms":1781237160287}}

{"type":"orderbook_delta","sid":1,"seq":849,"msg":{"market_ticker":"KXBTCPERP1","price":"6.3429","delta":"-1.00","side":"bid","ts_ms":1781237160287}}

{"type":"orderbook_delta","sid":1,"seq":850,"msg":{"market_ticker":"KXBTCPERP1","price":"6.3429","delta":"-1.00","side":"bid","ts_ms":1781237160287}}

{"type":"orderbook_delta","sid":1,"seq":851,"msg":{"market_ticker":"KXBTCPERP1","price":"6.3428","delta":"-1.00","side":"bid","ts_ms":1781237160287}}

{"type":"orderbook_delta","sid":1,"seq":852,"msg":{"market_ticker":"KXBTCPERP1","price":"6.3428","delta":"-1.00","side":"bid","ts_ms":1781237160287}}

{"type":"orderbook_delta","sid":1,"seq":853,"msg":{"market_ticker":"KXBTCPERP1","price":"6.3428","delta":"-1.00","side":"bid","ts_ms":1781237160287}}

{"type":"orderbook_delta","sid":1,"seq":854,"msg":{"market_ticker":"KXBTCPERP1","price":"6.3428","delta":"-1.00","side":"bid","ts_ms":1781237160287}}

{"type":"orderbook_delta","sid":1,"seq":855,"msg":{"market_ticker":"KXBTCPERP1","price":"6.3428","delta":"-1.00","side":"bid","ts_ms":1781237160287}}

{"type":"orderbook_delta","sid":1,"seq":856,"msg":{"market_ticker":"KXBTCPERP1","price":"6.3427","delta":"-1.00","side":"bid","ts_ms":1781237160287}}

{"type":"orderbook_delta","sid":1,"seq":857,"msg":{"market_ticker":"KXBTCPERP1","price":"6.3427","delta":"-1.00","side":"bid","ts_ms":1781237160287}}

{"type":"orderbook_delta","sid":1,"seq":858,"msg":{"market_ticker":"KXBTCPERP1","price":"6.3426","delta":"-1.00","side":"bid","ts_ms":1781237160287}}

{"type":"orderbook_delta","sid":1,"seq":859,"msg":{"market_ticker":"KXBTCPERP1","price":"6.3426","delta":"-1.00","side":"bid","ts_ms":1781237160287}}

{"type":"orderbook_delta","sid":1,"seq":860,"msg":{"market_ticker":"KXBTCPERP1","price":"6.3425","delta":"-1.00","side":"bid","ts_ms":1781237160287}}

{"type":"orderbook_delta","sid":1,"seq":861,"msg":{"market_ticker":"KXBTCPERP1","price":"6.3425","delta":"-1.00","side":"bid","ts_ms":1781237160287}}

{"type":"orderbook_delta","sid":1,"seq":862,"msg":{"market_ticker":"KXBTCPERP1","price":"6.3425","delta":"-1.00","side":"bid","ts_ms":1781237160287}}

{"type":"orderbook_delta","sid":1,"seq":863,"msg":{"market_ticker":"KXBTCPERP1","price":"6.3425","delta":"-1.00","side":"bid","ts_ms":1781237160287}}

{"type":"orderbook_delta","sid":1,"seq":864,"msg":{"market_ticker":"KXBTCPERP1","price":"6.3424","delta":"-1.00","side":"bid","ts_ms":1781237160287}}

{"type":"orderbook_delta","sid":1,"seq":865,"msg":{"market_ticker":"KXBTCPERP1","price":"6.3423","delta":"-1.00","side":"bid","ts_ms":1781237160287}}

{"type":"orderbook_delta","sid":1,"seq":866,"msg":{"market_ticker":"KXBTCPERP1","price":"6.3423","delta":"-1.00","side":"bid","ts_ms":1781237160287}}

{"type":"orderbook_delta","sid":1,"seq":867,"msg":{"market_ticker":"KXBTCPERP1","price":"6.3423","delta":"-1.00","side":"bid","ts_ms":1781237160287}}

{"type":"orderbook_delta","sid":1,"seq":868,"msg":{"market_ticker":"KXBTCPERP1","price":"6.3423","delta":"-1.00","side":"bid","ts_ms":1781237160287}}

{"type":"orderbook_delta","sid":1,"seq":869,"msg":{"market_ticker":"KXBTCPERP1","price":"6.3422","delta":"-1.00","side":"bid","ts_ms":1781237160287}}

{"type":"orderbook_delta","sid":1,"seq":870,"msg":{"market_ticker":"KXBTCPERP1","price":"6.3422","delta":"-1.00","side":"bid","ts_ms":1781237160287}}

{"type":"orderbook_delta","sid":1,"seq":871,"msg":{"market_ticker":"KXBTCPERP1","price":"6.3421","delta":"-1.00","side":"bid","ts_ms":1781237160287}}

{"type":"orderbook_delta","sid":1,"seq":872,"msg":{"market_ticker":"KXBTCPERP1","price":"6.3421","delta":"-1.00","side":"bid","ts_ms":1781237160287}}

{"type":"orderbook_delta","sid":1,"seq":873,"msg":{"market_ticker":"KXBTCPERP1","price":"6.3421","delta":"-1.00","side":"bid","ts_ms":1781237160287}}

{"type":"orderbook_delta","sid":1,"seq":874,"msg":{"market_ticker":"KXBTCPERP1","price":"6.3420","delta":"-1.00","side":"bid","ts_ms":1781237160287}}

{"type":"orderbook_delta","sid":1,"seq":875,"msg":{"market_ticker":"KXBTCPERP1","price":"6.3420","delta":"-1.00","side":"bid","ts_ms":1781237160287}}

{"type":"orderbook_delta","sid":1,"seq":876,"msg":{"market_ticker":"KXBTCPERP1","price":"6.3419","delta":"-1.00","side":"bid","ts_ms":1781237160287}}

{"type":"orderbook_delta","sid":1,"seq":877,"msg":{"market_ticker":"KXBTCPERP1","price":"6.3418","delta":"-1.00","side":"bid","ts_ms":1781237160287}}

{"type":"orderbook_delta","sid":1,"seq":878,"msg":{"market_ticker":"KXBTCPERP1","price":"6.3418","delta":"-1.00","side":"bid","ts_ms":1781237160287}}

{"type":"orderbook_delta","sid":1,"seq":879,"msg":{"market_ticker":"KXBTCPERP1","price":"6.3418","delta":"-1.00","side":"bid","ts_ms":1781237160287}}

{"type":"orderbook_delta","sid":1,"seq":880,"msg":{"market_ticker":"KXBTCPERP1","price":"6.3418","delta":"-1.00","side":"bid","ts_ms":1781237160287}}

{"type":"orderbook_delta","sid":1,"seq":881,"msg":{"market_ticker":"KXBTCPERP1","price":"6.3417","delta":"-1.00","side":"bid","ts_ms":1781237160287}}

{"type":"orderbook_delta","sid":1,"seq":882,"msg":{"market_ticker":"KXBTCPERP1","price":"6.3417","delta":"-1.00","side":"bid","ts_ms":1781237160287}}

{"type":"orderbook_delta","sid":1,"seq":883,"msg":{"market_ticker":"KXBTCPERP1","price":"6.3417","delta":"-1.00","side":"bid","ts_ms":1781237160287}}

{"type":"orderbook_delta","sid":1,"seq":884,"msg":{"market_ticker":"KXBTCPERP1","price":"6.3416","delta":"-1.00","side":"bid","ts_ms":1781237160287}}

{"type":"orderbook_delta","sid":1,"seq":885,"msg":{"market_ticker":"KXBTCPERP1","price":"6.3416","delta":"-1.00","side":"bid","ts_ms":1781237160287}}

{"type":"orderbook_delta","sid":1,"seq":886,"msg":{"market_ticker":"KXBTCPERP1","price":"6.3416","delta":"-1.00","side":"bid","ts_ms":1781237160287}}

{"type":"orderbook_delta","sid":1,"seq":887,"msg":{"market_ticker":"KXBTCPERP1","price":"6.3416","delta":"-1.00","side":"bid","ts_ms":1781237160287}}

{"type":"orderbook_delta","sid":1,"seq":888,"msg":{"market_ticker":"KXBTCPERP1","price":"6.3416","delta":"-1.00","side":"bid","ts_ms":1781237160287}}

{"type":"orderbook_delta","sid":1,"seq":889,"msg":{"market_ticker":"KXBTCPERP1","price":"6.3416","delta":"-1.00","side":"bid","ts_ms":1781237160287}}

{"type":"orderbook_delta","sid":1,"seq":890,"msg":{"market_ticker":"KXBTCPERP1","price":"6.3415","delta":"-1.00","side":"bid","ts_ms":1781237160287}}

{"type":"orderbook_delta","sid":1,"seq":891,"msg":{"market_ticker":"KXBTCPERP1","price":"6.3415","delta":"-1.00","side":"bid","ts_ms":1781237160287}}

{"type":"orderbook_delta","sid":1,"seq":892,"msg":{"market_ticker":"KXBTCPERP1","price":"6.3415","delta":"-1.00","side":"bid","ts_ms":1781237160287}}

{"type":"orderbook_delta","sid":1,"seq":893,"msg":{"market_ticker":"KXBTCPERP1","price":"6.3414","delta":"-1.00","side":"bid","ts_ms":1781237160287}}

{"type":"orderbook_delta","sid":1,"seq":894,"msg":{"market_ticker":"KXBTCPERP1","price":"6.3414","delta":"-1.00","side":"bid","ts_ms":1781237160287}}

{"type":"orderbook_delta","sid":1,"seq":895,"msg":{"market_ticker":"KXBTCPERP1","price":"6.3414","delta":"-1.00","side":"bid","ts_ms":1781237160287}}

{"type":"orderbook_delta","sid":1,"seq":896,"msg":{"market_ticker":"KXBTCPERP1","price":"6.3413","delta":"-1.00","side":"bid","ts_ms":1781237160287}}

{"type":"orderbook_delta","sid":1,"seq":897,"msg":{"market_ticker":"KXBTCPERP1","price":"6.3412","delta":"-1.00","side":"bid","ts_ms":1781237160287}}

{"type":"orderbook_delta","sid":1,"seq":898,"msg":{"market_ticker":"KXBTCPERP1","price":"6.3412","delta":"-1.00","side":"bid","ts_ms":1781237160287}}

{"type":"orderbook_delta","sid":1,"seq":899,"msg":{"market_ticker":"KXBTCPERP1","price":"6.3412","delta":"-1.00","side":"bid","ts_ms":1781237160287}}

{"type":"orderbook_delta","sid":1,"seq":900,"msg":{"market_ticker":"KXBTCPERP1","price":"6.3412","delta":"-1.00","side":"bid","ts_ms":1781237160287}}

{"type":"orderbook_delta","sid":1,"seq":901,"msg":{"market_ticker":"KXBTCPERP1","price":"6.3411","delta":"-1.00","side":"bid","ts_ms":1781237160287}}

{"type":"orderbook_delta","sid":1,"seq":902,"msg":{"market_ticker":"KXBTCPERP1","price":"6.3411","delta":"-1.00","side":"bid","ts_ms":1781237160287}}

{"type":"orderbook_delta","sid":1,"seq":903,"msg":{"market_ticker":"KXBTCPERP1","price":"6.3411","delta":"-1.00","side":"bid","ts_ms":1781237160287}}

{"type":"orderbook_delta","sid":1,"seq":904,"msg":{"market_ticker":"KXBTCPERP1","price":"6.3411","delta":"-1.00","side":"bid","ts_ms":1781237160287}}

{"type":"orderbook_delta","sid":1,"seq":905,"msg":{"market_ticker":"KXBTCPERP1","price":"6.3410","delta":"-1.00","side":"bid","ts_ms":1781237160287}}

{"type":"orderbook_delta","sid":1,"seq":906,"msg":{"market_ticker":"KXBTCPERP1","price":"6.3410","delta":"-1.00","side":"bid","ts_ms":1781237160287}}

{"type":"orderbook_delta","sid":1,"seq":907,"msg":{"market_ticker":"KXBTCPERP1","price":"6.3410","delta":"-1.00","side":"bid","ts_ms":1781237160287}}

{"type":"orderbook_delta","sid":1,"seq":908,"msg":{"market_ticker":"KXBTCPERP1","price":"6.3410","delta":"-1.00","side":"bid","ts_ms":1781237160287}}

{"type":"orderbook_delta","sid":1,"seq":909,"msg":{"market_ticker":"KXBTCPERP1","price":"6.3410","delta":"-1.00","side":"bid","ts_ms":1781237160287}}

{"type":"orderbook_delta","sid":1,"seq":910,"msg":{"market_ticker":"KXBTCPERP1","price":"6.3409","delta":"-1.00","side":"bid","ts_ms":1781237160287}}

{"type":"orderbook_delta","sid":1,"seq":911,"msg":{"market_ticker":"KXBTCPERP1","price":"6.3408","delta":"-1.00","side":"bid","ts_ms":1781237160287}}

{"type":"orderbook_delta","sid":1,"seq":912,"msg":{"market_ticker":"KXBTCPERP1","price":"6.3408","delta":"-1.00","side":"bid","ts_ms":1781237160287}}

{"type":"orderbook_delta","sid":1,"seq":913,"msg":{"market_ticker":"KXBTCPERP1","price":"6.3408","delta":"-1.00","side":"bid","ts_ms":1781237160287}}

{"type":"orderbook_delta","sid":1,"seq":914,"msg":{"market_ticker":"KXBTCPERP1","price":"6.3408","delta":"-1.00","side":"bid","ts_ms":1781237160287}}

{"type":"orderbook_delta","sid":1,"seq":915,"msg":{"market_ticker":"KXBTCPERP1","price":"6.3407","delta":"-1.00","side":"bid","ts_ms":1781237160287}}

{"type":"orderbook_delta","sid":1,"seq":916,"msg":{"market_ticker":"KXBTCPERP1","price":"6.3407","delta":"-1.00","side":"bid","ts_ms":1781237160287}}

{"type":"orderbook_delta","sid":1,"seq":917,"msg":{"market_ticker":"KXBTCPERP1","price":"6.3407","delta":"-1.00","side":"bid","ts_ms":1781237160287}}

{"type":"orderbook_delta","sid":1,"seq":918,"msg":{"market_ticker":"KXBTCPERP1","price":"6.3407","delta":"-1.00","side":"bid","ts_ms":1781237160287}}

{"type":"orderbook_delta","sid":1,"seq":919,"msg":{"market_ticker":"KXBTCPERP1","price":"6.3406","delta":"-1.00","side":"bid","ts_ms":1781237160287}}

{"type":"orderbook_delta","sid":1,"seq":920,"msg":{"market_ticker":"KXBTCPERP1","price":"6.3406","delta":"-1.00","side":"bid","ts_ms":1781237160287}}

{"type":"orderbook_delta","sid":1,"seq":921,"msg":{"market_ticker":"KXBTCPERP1","price":"6.3406","delta":"-1.00","side":"bid","ts_ms":1781237160287}}

{"type":"orderbook_delta","sid":1,"seq":922,"msg":{"market_ticker":"KXBTCPERP1","price":"6.3406","delta":"-1.00","side":"bid","ts_ms":1781237160287}}

{"type":"orderbook_delta","sid":1,"seq":923,"msg":{"market_ticker":"KXBTCPERP1","price":"6.3406","delta":"-1.00","side":"bid","ts_ms":1781237160287}}

{"type":"orderbook_delta","sid":1,"seq":924,"msg":{"market_ticker":"KXBTCPERP1","price":"6.3406","delta":"-1.00","side":"bid","ts_ms":1781237160287}}

{"type":"orderbook_delta","sid":1,"seq":925,"msg":{"market_ticker":"KXBTCPERP1","price":"6.3406","delta":"-1.00","side":"bid","ts_ms":1781237160287}}

{"type":"orderbook_delta","sid":1,"seq":926,"msg":{"market_ticker":"KXBTCPERP1","price":"6.3405","delta":"-1.00","side":"bid","ts_ms":1781237160287}}

{"type":"orderbook_delta","sid":1,"seq":927,"msg":{"market_ticker":"KXBTCPERP1","price":"6.3404","delta":"-1.00","side":"bid","ts_ms":1781237160287}}

{"type":"orderbook_delta","sid":1,"seq":928,"msg":{"market_ticker":"KXBTCPERP1","price":"6.3404","delta":"-1.00","side":"bid","ts_ms":1781237160287}}

{"type":"orderbook_delta","sid":1,"seq":929,"msg":{"market_ticker":"KXBTCPERP1","price":"6.3404","delta":"-1.00","side":"bid","ts_ms":1781237160287}}

{"type":"orderbook_delta","sid":1,"seq":930,"msg":{"market_ticker":"KXBTCPERP1","price":"6.3404","delta":"-1.00","side":"bid","ts_ms":1781237160287}}

{"type":"orderbook_delta","sid":1,"seq":931,"msg":{"market_ticker":"KXBTCPERP1","price":"6.3404","delta":"-1.00","side":"bid","ts_ms":1781237160287}}

{"type":"orderbook_delta","sid":1,"seq":932,"msg":{"market_ticker":"KXBTCPERP1","price":"6.3404","delta":"-1.00","side":"bid","ts_ms":1781237160287}}

{"type":"orderbook_delta","sid":1,"seq":933,"msg":{"market_ticker":"KXBTCPERP1","price":"6.3403","delta":"-1.00","side":"bid","ts_ms":1781237160287}}

{"type":"orderbook_delta","sid":1,"seq":934,"msg":{"market_ticker":"KXBTCPERP1","price":"6.3403","delta":"-1.00","side":"bid","ts_ms":1781237160287}}

{"type":"orderbook_delta","sid":1,"seq":935,"msg":{"market_ticker":"KXBTCPERP1","price":"6.3403","delta":"-1.00","side":"bid","ts_ms":1781237160287}}

{"type":"orderbook_delta","sid":1,"seq":936,"msg":{"market_ticker":"KXBTCPERP1","price":"6.3403","delta":"-1.00","side":"bid","ts_ms":1781237160287}}

{"type":"orderbook_delta","sid":1,"seq":937,"msg":{"market_ticker":"KXBTCPERP1","price":"6.3401","delta":"-1.00","side":"bid","ts_ms":1781237160287}}

{"type":"orderbook_delta","sid":1,"seq":938,"msg":{"market_ticker":"KXBTCPERP1","price":"6.3401","delta":"-1.00","side":"bid","ts_ms":1781237160287}}

{"type":"orderbook_delta","sid":1,"seq":939,"msg":{"market_ticker":"KXBTCPERP1","price":"6.3401","delta":"-1.00","side":"bid","ts_ms":1781237160287}}

{"type":"orderbook_delta","sid":1,"seq":940,"msg":{"market_ticker":"KXBTCPERP1","price":"6.3401","delta":"-1.00","side":"bid","ts_ms":1781237160287}}

{"type":"orderbook_delta","sid":1,"seq":941,"msg":{"market_ticker":"KXBTCPERP1","price":"6.3401","delta":"-1.00","side":"bid","ts_ms":1781237160287}}

{"type":"orderbook_delta","sid":1,"seq":942,"msg":{"market_ticker":"KXBTCPERP1","price":"6.3401","delta":"-1.00","side":"bid","ts_ms":1781237160287}}

{"type":"orderbook_delta","sid":1,"seq":943,"msg":{"market_ticker":"KXBTCPERP1","price":"6.3400","delta":"-1.00","side":"bid","ts_ms":1781237160287}}

{"type":"orderbook_delta","sid":1,"seq":944,"msg":{"market_ticker":"KXBTCPERP1","price":"6.3399","delta":"-1.00","side":"bid","ts_ms":1781237160287}}

{"type":"orderbook_delta","sid":1,"seq":945,"msg":{"market_ticker":"KXBTCPERP1","price":"6.3399","delta":"-1.00","side":"bid","ts_ms":1781237160287}}

{"type":"orderbook_delta","sid":1,"seq":946,"msg":{"market_ticker":"KXBTCPERP1","price":"6.3399","delta":"-1.00","side":"bid","ts_ms":1781237160287}}

{"type":"orderbook_delta","sid":1,"seq":947,"msg":{"market_ticker":"KXBTCPERP1","price":"6.3399","delta":"-1.00","side":"bid","ts_ms":1781237160287}}

{"type":"orderbook_delta","sid":1,"seq":948,"msg":{"market_ticker":"KXBTCPERP1","price":"6.3398","delta":"-1.00","side":"bid","ts_ms":1781237160287}}

{"type":"orderbook_delta","sid":1,"seq":949,"msg":{"market_ticker":"KXBTCPERP1","price":"6.3397","delta":"-1.00","side":"bid","ts_ms":1781237160287}}

{"type":"orderbook_delta","sid":1,"seq":950,"msg":{"market_ticker":"KXBTCPERP1","price":"6.3397","delta":"-1.00","side":"bid","ts_ms":1781237160287}}

{"type":"orderbook_delta","sid":1,"seq":951,"msg":{"market_ticker":"KXBTCPERP1","price":"6.3397","delta":"-1.00","side":"bid","ts_ms":1781237160287}}

{"type":"orderbook_delta","sid":1,"seq":952,"msg":{"market_ticker":"KXBTCPERP1","price":"6.3396","delta":"-1.00","side":"bid","ts_ms":1781237160287}}

{"type":"orderbook_delta","sid":1,"seq":953,"msg":{"market_ticker":"KXBTCPERP1","price":"6.3396","delta":"-1.00","side":"bid","ts_ms":1781237160287}}

{"type":"orderbook_delta","sid":1,"seq":954,"msg":{"market_ticker":"KXBTCPERP1","price":"6.3396","delta":"-1.00","side":"bid","ts_ms":1781237160287}}

{"type":"orderbook_delta","sid":1,"seq":955,"msg":{"market_ticker":"KXBTCPERP1","price":"6.3396","delta":"-1.00","side":"bid","ts_ms":1781237160287}}

{"type":"orderbook_delta","sid":1,"seq":956,"msg":{"market_ticker":"KXBTCPERP1","price":"6.3395","delta":"-1.00","side":"bid","ts_ms":1781237160287}}

{"type":"orderbook_delta","sid":1,"seq":957,"msg":{"market_ticker":"KXBTCPERP1","price":"6.3395","delta":"-1.00","side":"bid","ts_ms":1781237160287}}

{"type":"orderbook_delta","sid":1,"seq":958,"msg":{"market_ticker":"KXBTCPERP1","price":"6.3394","delta":"-1.00","side":"bid","ts_ms":1781237160287}}

{"type":"orderbook_delta","sid":1,"seq":959,"msg":{"market_ticker":"KXBTCPERP1","price":"6.3394","delta":"-1.00","side":"bid","ts_ms":1781237160287}}

{"type":"orderbook_delta","sid":1,"seq":960,"msg":{"market_ticker":"KXBTCPERP1","price":"6.3392","delta":"-1.00","side":"bid","ts_ms":1781237160287}}

{"type":"orderbook_delta","sid":1,"seq":961,"msg":{"market_ticker":"KXBTCPERP1","price":"6.3391","delta":"-1.00","side":"bid","ts_ms":1781237160287}}

{"type":"orderbook_delta","sid":1,"seq":962,"msg":{"market_ticker":"KXBTCPERP1","price":"6.3391","delta":"-1.00","side":"bid","ts_ms":1781237160287}}

{"type":"orderbook_delta","sid":1,"seq":963,"msg":{"market_ticker":"KXBTCPERP1","price":"6.3390","delta":"-1.00","side":"bid","ts_ms":1781237160287}}

{"type":"orderbook_delta","sid":1,"seq":964,"msg":{"market_ticker":"KXBTCPERP1","price":"6.3390","delta":"-1.00","side":"bid","ts_ms":1781237160287}}

{"type":"orderbook_delta","sid":1,"seq":965,"msg":{"market_ticker":"KXBTCPERP1","price":"6.3390","delta":"-1.00","side":"bid","ts_ms":1781237160287}}

{"type":"orderbook_delta","sid":1,"seq":966,"msg":{"market_ticker":"KXBTCPERP1","price":"6.3389","delta":"-1.00","side":"bid","ts_ms":1781237160287}}

{"type":"orderbook_delta","sid":1,"seq":967,"msg":{"market_ticker":"KXBTCPERP1","price":"6.3388","delta":"-1.00","side":"bid","ts_ms":1781237160287}}

{"type":"orderbook_delta","sid":1,"seq":968,"msg":{"market_ticker":"KXBTCPERP1","price":"6.3388","delta":"-1.00","side":"bid","ts_ms":1781237160287}}

{"type":"orderbook_delta","sid":1,"seq":969,"msg":{"market_ticker":"KXBTCPERP1","price":"6.3388","delta":"-1.00","side":"bid","ts_ms":1781237160287}}

{"type":"orderbook_delta","sid":1,"seq":970,"msg":{"market_ticker":"KXBTCPERP1","price":"6.3388","delta":"-1.00","side":"bid","ts_ms":1781237160287}}

{"type":"orderbook_delta","sid":1,"seq":971,"msg":{"market_ticker":"KXBTCPERP1","price":"6.3387","delta":"-1.00","side":"bid","ts_ms":1781237160287}}

{"type":"orderbook_delta","sid":1,"seq":972,"msg":{"market_ticker":"KXBTCPERP1","price":"6.3386","delta":"-1.00","side":"bid","ts_ms":1781237160287}}

{"type":"orderbook_delta","sid":1,"seq":973,"msg":{"market_ticker":"KXBTCPERP1","price":"6.3386","delta":"-1.00","side":"bid","ts_ms":1781237160287}}

{"type":"orderbook_delta","sid":1,"seq":974,"msg":{"market_ticker":"KXBTCPERP1","price":"6.3386","delta":"-1.00","side":"bid","ts_ms":1781237160287}}

{"type":"orderbook_delta","sid":1,"seq":975,"msg":{"market_ticker":"KXBTCPERP1","price":"6.3385","delta":"-1.00","side":"bid","ts_ms":1781237160287}}

{"type":"orderbook_delta","sid":1,"seq":976,"msg":{"market_ticker":"KXBTCPERP1","price":"6.3385","delta":"-1.00","side":"bid","ts_ms":1781237160287}}

{"type":"orderbook_delta","sid":1,"seq":977,"msg":{"market_ticker":"KXBTCPERP1","price":"6.3384","delta":"-1.00","side":"bid","ts_ms":1781237160287}}

{"type":"orderbook_delta","sid":1,"seq":978,"msg":{"market_ticker":"KXBTCPERP1","price":"6.3384","delta":"-1.00","side":"bid","ts_ms":1781237160287}}

{"type":"orderbook_delta","sid":1,"seq":979,"msg":{"market_ticker":"KXBTCPERP1","price":"6.3383","delta":"-1.00","side":"bid","ts_ms":1781237160287}}

{"type":"orderbook_delta","sid":1,"seq":980,"msg":{"market_ticker":"KXBTCPERP1","price":"6.3383","delta":"-1.00","side":"bid","ts_ms":1781237160287}}

{"type":"orderbook_delta","sid":1,"seq":981,"msg":{"market_ticker":"KXBTCPERP1","price":"6.3383","delta":"-1.00","side":"bid","ts_ms":1781237160287}}

{"type":"orderbook_delta","sid":1,"seq":982,"msg":{"market_ticker":"KXBTCPERP1","price":"6.3382","delta":"-1.00","side":"bid","ts_ms":1781237160287}}

{"type":"orderbook_delta","sid":1,"seq":983,"msg":{"market_ticker":"KXBTCPERP1","price":"6.3382","delta":"-1.00","side":"bid","ts_ms":1781237160287}}

{"type":"orderbook_delta","sid":1,"seq":984,"msg":{"market_ticker":"KXBTCPERP1","price":"6.3382","delta":"-1.00","side":"bid","ts_ms":1781237160287}}

{"type":"orderbook_delta","sid":1,"seq":985,"msg":{"market_ticker":"KXBTCPERP1","price":"6.3382","delta":"-1.00","side":"bid","ts_ms":1781237160287}}

{"type":"orderbook_delta","sid":1,"seq":986,"msg":{"market_ticker":"KXBTCPERP1","price":"6.3382","delta":"-1.00","side":"bid","ts_ms":1781237160287}}

{"type":"orderbook_delta","sid":1,"seq":987,"msg":{"market_ticker":"KXBTCPERP1","price":"6.3381","delta":"-1.00","side":"bid","ts_ms":1781237160287}}

{"type":"orderbook_delta","sid":1,"seq":988,"msg":{"market_ticker":"KXBTCPERP1","price":"6.3381","delta":"-1.00","side":"bid","ts_ms":1781237160287}}

{"type":"orderbook_delta","sid":1,"seq":989,"msg":{"market_ticker":"KXBTCPERP1","price":"6.3381","delta":"-1.00","side":"bid","ts_ms":1781237160287}}

{"type":"orderbook_delta","sid":1,"seq":990,"msg":{"market_ticker":"KXBTCPERP1","price":"6.3381","delta":"-1.00","side":"bid","ts_ms":1781237160287}}

{"type":"orderbook_delta","sid":1,"seq":991,"msg":{"market_ticker":"KXBTCPERP1","price":"6.3380","delta":"-1.00","side":"bid","ts_ms":1781237160287}}

{"type":"orderbook_delta","sid":1,"seq":992,"msg":{"market_ticker":"KXBTCPERP1","price":"6.3380","delta":"-1.00","side":"bid","ts_ms":1781237160287}}

{"type":"orderbook_delta","sid":1,"seq":993,"msg":{"market_ticker":"KXBTCPERP1","price":"6.3380","delta":"-1.00","side":"bid","ts_ms":1781237160287}}

{"type":"orderbook_delta","sid":1,"seq":994,"msg":{"market_ticker":"KXBTCPERP1","price":"6.3380","delta":"-1.00","side":"bid","ts_ms":1781237160287}}

{"type":"orderbook_delta","sid":1,"seq":995,"msg":{"market_ticker":"KXBTCPERP1","price":"6.3380","delta":"-1.00","side":"bid","ts_ms":1781237160287}}

{"type":"orderbook_delta","sid":1,"seq":996,"msg":{"market_ticker":"KXBTCPERP1","price":"6.3379","delta":"-1.00","side":"bid","ts_ms":1781237160287}}

{"type":"orderbook_delta","sid":1,"seq":997,"msg":{"market_ticker":"KXBTCPERP1","price":"6.3379","delta":"-1.00","side":"bid","ts_ms":1781237160287}}

{"type":"orderbook_delta","sid":1,"seq":998,"msg":{"market_ticker":"KXBTCPERP1","price":"6.3379","delta":"-1.00","side":"bid","ts_ms":1781237160287}}

{"type":"orderbook_delta","sid":1,"seq":999,"msg":{"market_ticker":"KXBTCPERP1","price":"6.3378","delta":"-1.00","side":"bid","ts_ms":1781237160287}}

{"type":"orderbook_delta","sid":1,"seq":1000,"msg":{"market_ticker":"KXBTCPERP1","price":"6.3378","delta":"-1.00","side":"bid","ts_ms":1781237160287}}

{"type":"orderbook_delta","sid":1,"seq":1001,"msg":{"market_ticker":"KXBTCPERP1","price":"6.3378","delta":"-1.00","side":"bid","ts_ms":1781237160287}}

{"type":"orderbook_delta","sid":1,"seq":1002,"msg":{"market_ticker":"KXBTCPERP1","price":"6.3377","delta":"-1.00","side":"bid","ts_ms":1781237160287}}

{"type":"orderbook_delta","sid":1,"seq":1003,"msg":{"market_ticker":"KXBTCPERP1","price":"6.3376","delta":"-1.00","side":"bid","ts_ms":1781237160287}}

{"type":"orderbook_delta","sid":1,"seq":1004,"msg":{"market_ticker":"KXBTCPERP1","price":"6.3375","delta":"-1.00","side":"bid","ts_ms":1781237160287}}

{"type":"orderbook_delta","sid":1,"seq":1005,"msg":{"market_ticker":"KXBTCPERP1","price":"6.3374","delta":"-1.00","side":"bid","ts_ms":1781237160287}}

{"type":"orderbook_delta","sid":1,"seq":1006,"msg":{"market_ticker":"KXBTCPERP1","price":"6.3374","delta":"-1.00","side":"bid","ts_ms":1781237160287}}

{"type":"orderbook_delta","sid":1,"seq":1007,"msg":{"market_ticker":"KXBTCPERP1","price":"6.3374","delta":"-1.00","side":"bid","ts_ms":1781237160287}}

{"type":"orderbook_delta","sid":1,"seq":1008,"msg":{"market_ticker":"KXBTCPERP1","price":"6.3374","delta":"-1.00","side":"bid","ts_ms":1781237160287}}

{"type":"orderbook_delta","sid":1,"seq":1009,"msg":{"market_ticker":"KXBTCPERP1","price":"6.3373","delta":"-1.00","side":"bid","ts_ms":1781237160287}}

{"type":"orderbook_delta","sid":1,"seq":1010,"msg":{"market_ticker":"KXBTCPERP1","price":"6.3373","delta":"-1.00","side":"bid","ts_ms":1781237160287}}

{"type":"orderbook_delta","sid":1,"seq":1011,"msg":{"market_ticker":"KXBTCPERP1","price":"6.3373","delta":"-1.00","side":"bid","ts_ms":1781237160287}}

{"type":"orderbook_delta","sid":1,"seq":1012,"msg":{"market_ticker":"KXBTCPERP1","price":"6.3372","delta":"-1.00","side":"bid","ts_ms":1781237160287}}

{"type":"orderbook_delta","sid":1,"seq":1013,"msg":{"market_ticker":"KXBTCPERP1","price":"6.3372","delta":"-1.00","side":"bid","ts_ms":1781237160287}}

{"type":"orderbook_delta","sid":1,"seq":1014,"msg":{"market_ticker":"KXBTCPERP1","price":"6.3372","delta":"-1.00","side":"bid","ts_ms":1781237160287}}

{"type":"orderbook_delta","sid":1,"seq":1015,"msg":{"market_ticker":"KXBTCPERP1","price":"6.3372","delta":"-1.00","side":"bid","ts_ms":1781237160287}}

{"type":"orderbook_delta","sid":1,"seq":1016,"msg":{"market_ticker":"KXBTCPERP1","price":"6.3371","delta":"-1.00","side":"bid","ts_ms":1781237160287}}

{"type":"orderbook_delta","sid":1,"seq":1017,"msg":{"market_ticker":"KXBTCPERP1","price":"6.3371","delta":"-1.00","side":"bid","ts_ms":1781237160287}}

{"type":"orderbook_delta","sid":1,"seq":1018,"msg":{"market_ticker":"KXBTCPERP1","price":"6.3371","delta":"-1.00","side":"bid","ts_ms":1781237160287}}

{"type":"orderbook_delta","sid":1,"seq":1019,"msg":{"market_ticker":"KXBTCPERP1","price":"6.3370","delta":"-1.00","side":"bid","ts_ms":1781237160287}}

{"type":"orderbook_delta","sid":1,"seq":1020,"msg":{"market_ticker":"KXBTCPERP1","price":"6.3370","delta":"-1.00","side":"bid","ts_ms":1781237160287}}

{"type":"orderbook_delta","sid":1,"seq":1021,"msg":{"market_ticker":"KXBTCPERP1","price":"6.3370","delta":"-1.00","side":"bid","ts_ms":1781237160287}}

{"type":"orderbook_delta","sid":1,"seq":1022,"msg":{"market_ticker":"KXBTCPERP1","price":"6.3369","delta":"-1.00","side":"bid","ts_ms":1781237160287}}

{"type":"orderbook_delta","sid":1,"seq":1023,"msg":{"market_ticker":"KXBTCPERP1","price":"6.3369","delta":"-1.00","side":"bid","ts_ms":1781237160287}}

{"type":"orderbook_delta","sid":1,"seq":1024,"msg":{"market_ticker":"KXBTCPERP1","price":"6.3369","delta":"-1.00","side":"bid","ts_ms":1781237160287}}

{"type":"orderbook_delta","sid":1,"seq":1025,"msg":{"market_ticker":"KXBTCPERP1","price":"6.3368","delta":"-1.00","side":"bid","ts_ms":1781237160287}}

{"type":"orderbook_delta","sid":1,"seq":1026,"msg":{"market_ticker":"KXBTCPERP1","price":"6.3367","delta":"-1.00","side":"bid","ts_ms":1781237160287}}

{"type":"orderbook_delta","sid":1,"seq":1027,"msg":{"market_ticker":"KXBTCPERP1","price":"6.3366","delta":"-1.00","side":"bid","ts_ms":1781237160287}}

{"type":"orderbook_delta","sid":1,"seq":1028,"msg":{"market_ticker":"KXBTCPERP1","price":"6.3366","delta":"-1.00","side":"bid","ts_ms":1781237160287}}

{"type":"orderbook_delta","sid":1,"seq":1029,"msg":{"market_ticker":"KXBTCPERP1","price":"6.3365","delta":"-1.00","side":"bid","ts_ms":1781237160287}}

{"type":"orderbook_delta","sid":1,"seq":1030,"msg":{"market_ticker":"KXBTCPERP1","price":"6.3365","delta":"-1.00","side":"bid","ts_ms":1781237160287}}

{"type":"orderbook_delta","sid":1,"seq":1031,"msg":{"market_ticker":"KXBTCPERP1","price":"6.3364","delta":"-1.00","side":"bid","ts_ms":1781237160287}}

{"type":"orderbook_delta","sid":1,"seq":1032,"msg":{"market_ticker":"KXBTCPERP1","price":"6.3364","delta":"-1.00","side":"bid","ts_ms":1781237160287}}

{"type":"orderbook_delta","sid":1,"seq":1033,"msg":{"market_ticker":"KXBTCPERP1","price":"6.3364","delta":"-1.00","side":"bid","ts_ms":1781237160287}}

{"type":"orderbook_delta","sid":1,"seq":1034,"msg":{"market_ticker":"KXBTCPERP1","price":"6.3364","delta":"-1.00","side":"bid","ts_ms":1781237160287}}

{"type":"orderbook_delta","sid":1,"seq":1035,"msg":{"market_ticker":"KXBTCPERP1","price":"6.3364","delta":"-1.00","side":"bid","ts_ms":1781237160287}}

{"type":"orderbook_delta","sid":1,"seq":1036,"msg":{"market_ticker":"KXBTCPERP1","price":"6.3363","delta":"-1.00","side":"bid","ts_ms":1781237160287}}

{"type":"orderbook_delta","sid":1,"seq":1037,"msg":{"market_ticker":"KXBTCPERP1","price":"6.3363","delta":"-1.00","side":"bid","ts_ms":1781237160287}}

{"type":"orderbook_delta","sid":1,"seq":1038,"msg":{"market_ticker":"KXBTCPERP1","price":"6.3363","delta":"-1.00","side":"bid","ts_ms":1781237160287}}

{"type":"orderbook_delta","sid":1,"seq":1039,"msg":{"market_ticker":"KXBTCPERP1","price":"6.3363","delta":"-1.00","side":"bid","ts_ms":1781237160287}}

{"type":"orderbook_delta","sid":1,"seq":1040,"msg":{"market_ticker":"KXBTCPERP1","price":"6.3362","delta":"-1.00","side":"bid","ts_ms":1781237160287}}

{"type":"orderbook_delta","sid":1,"seq":1041,"msg":{"market_ticker":"KXBTCPERP1","price":"6.3362","delta":"-1.00","side":"bid","ts_ms":1781237160287}}

{"type":"orderbook_delta","sid":1,"seq":1042,"msg":{"market_ticker":"KXBTCPERP1","price":"6.3361","delta":"-1.00","side":"bid","ts_ms":1781237160287}}

{"type":"orderbook_delta","sid":1,"seq":1043,"msg":{"market_ticker":"KXBTCPERP1","price":"6.3361","delta":"-1.00","side":"bid","ts_ms":1781237160287}}

{"type":"orderbook_delta","sid":1,"seq":1044,"msg":{"market_ticker":"KXBTCPERP1","price":"6.3361","delta":"-1.00","side":"bid","ts_ms":1781237160287}}

{"type":"orderbook_delta","sid":1,"seq":1045,"msg":{"market_ticker":"KXBTCPERP1","price":"6.3359","delta":"-1.00","side":"bid","ts_ms":1781237160287}}

{"type":"orderbook_delta","sid":1,"seq":1046,"msg":{"market_ticker":"KXBTCPERP1","price":"6.3359","delta":"-1.00","side":"bid","ts_ms":1781237160287}}

{"type":"orderbook_delta","sid":1,"seq":1047,"msg":{"market_ticker":"KXBTCPERP1","price":"6.3358","delta":"-1.00","side":"bid","ts_ms":1781237160287}}

{"type":"orderbook_delta","sid":1,"seq":1048,"msg":{"market_ticker":"KXBTCPERP1","price":"6.3358","delta":"-1.00","side":"bid","ts_ms":1781237160287}}

{"type":"orderbook_delta","sid":1,"seq":1049,"msg":{"market_ticker":"KXBTCPERP1","price":"6.3357","delta":"-1.00","side":"bid","ts_ms":1781237160287}}

{"type":"orderbook_delta","sid":1,"seq":1050,"msg":{"market_ticker":"KXBTCPERP1","price":"6.3357","delta":"-1.00","side":"bid","ts_ms":1781237160287}}

{"type":"orderbook_delta","sid":1,"seq":1051,"msg":{"market_ticker":"KXBTCPERP1","price":"6.3357","delta":"-1.00","side":"bid","ts_ms":1781237160287}}

{"type":"orderbook_delta","sid":1,"seq":1052,"msg":{"market_ticker":"KXBTCPERP1","price":"6.3356","delta":"-1.00","side":"bid","ts_ms":1781237160287}}

{"type":"orderbook_delta","sid":1,"seq":1053,"msg":{"market_ticker":"KXBTCPERP1","price":"6.3356","delta":"-1.00","side":"bid","ts_ms":1781237160287}}

{"type":"orderbook_delta","sid":1,"seq":1054,"msg":{"market_ticker":"KXBTCPERP1","price":"6.3356","delta":"-1.00","side":"bid","ts_ms":1781237160287}}

{"type":"orderbook_delta","sid":1,"seq":1055,"msg":{"market_ticker":"KXBTCPERP1","price":"6.3356","delta":"-1.00","side":"bid","ts_ms":1781237160287}}

{"type":"orderbook_delta","sid":1,"seq":1056,"msg":{"market_ticker":"KXBTCPERP1","price":"6.3355","delta":"-1.00","side":"bid","ts_ms":1781237160287}}

{"type":"orderbook_delta","sid":1,"seq":1057,"msg":{"market_ticker":"KXBTCPERP1","price":"6.3355","delta":"-1.00","side":"bid","ts_ms":1781237160287}}

{"type":"orderbook_delta","sid":1,"seq":1058,"msg":{"market_ticker":"KXBTCPERP1","price":"6.3354","delta":"-1.00","side":"bid","ts_ms":1781237160287}}

{"type":"orderbook_delta","sid":1,"seq":1059,"msg":{"market_ticker":"KXBTCPERP1","price":"6.3354","delta":"-1.00","side":"bid","ts_ms":1781237160287}}

{"type":"orderbook_delta","sid":1,"seq":1060,"msg":{"market_ticker":"KXBTCPERP1","price":"6.3354","delta":"-1.00","side":"bid","ts_ms":1781237160287}}

{"type":"orderbook_delta","sid":1,"seq":1061,"msg":{"market_ticker":"KXBTCPERP1","price":"6.3353","delta":"-1.00","side":"bid","ts_ms":1781237160287}}

{"type":"orderbook_delta","sid":1,"seq":1062,"msg":{"market_ticker":"KXBTCPERP1","price":"6.3353","delta":"-1.00","side":"bid","ts_ms":1781237160287}}

{"type":"orderbook_delta","sid":1,"seq":1063,"msg":{"market_ticker":"KXBTCPERP1","price":"6.3353","delta":"-1.00","side":"bid","ts_ms":1781237160287}}

{"type":"orderbook_delta","sid":1,"seq":1064,"msg":{"market_ticker":"KXBTCPERP1","price":"6.3352","delta":"-1.00","side":"bid","ts_ms":1781237160287}}

{"type":"orderbook_delta","sid":1,"seq":1065,"msg":{"market_ticker":"KXBTCPERP1","price":"6.3351","delta":"-1.00","side":"bid","ts_ms":1781237160287}}

{"type":"orderbook_delta","sid":1,"seq":1066,"msg":{"market_ticker":"KXBTCPERP1","price":"6.3351","delta":"-1.00","side":"bid","ts_ms":1781237160287}}

{"type":"orderbook_delta","sid":1,"seq":1067,"msg":{"market_ticker":"KXBTCPERP1","price":"6.3351","delta":"-1.00","side":"bid","ts_ms":1781237160287}}

{"type":"orderbook_delta","sid":1,"seq":1068,"msg":{"market_ticker":"KXBTCPERP1","price":"6.3350","delta":"-1.00","side":"bid","ts_ms":1781237160287}}

{"type":"orderbook_delta","sid":1,"seq":1069,"msg":{"market_ticker":"KXBTCPERP1","price":"6.3350","delta":"-1.00","side":"bid","ts_ms":1781237160287}}

{"type":"orderbook_delta","sid":1,"seq":1070,"msg":{"market_ticker":"KXBTCPERP1","price":"6.3350","delta":"-1.00","side":"bid","ts_ms":1781237160287}}

{"type":"orderbook_delta","sid":1,"seq":1071,"msg":{"market_ticker":"KXBTCPERP1","price":"6.3350","delta":"-1.00","side":"bid","ts_ms":1781237160287}}

{"type":"orderbook_delta","sid":1,"seq":1072,"msg":{"market_ticker":"KXBTCPERP1","price":"6.3349","delta":"-1.00","side":"bid","ts_ms":1781237160287}}

{"type":"orderbook_delta","sid":1,"seq":1073,"msg":{"market_ticker":"KXBTCPERP1","price":"6.3349","delta":"-1.00","side":"bid","ts_ms":1781237160287}}

{"type":"orderbook_delta","sid":1,"seq":1074,"msg":{"market_ticker":"KXBTCPERP1","price":"6.3349","delta":"-1.00","side":"bid","ts_ms":1781237160287}}

{"type":"orderbook_delta","sid":1,"seq":1075,"msg":{"market_ticker":"KXBTCPERP1","price":"6.3348","delta":"-1.00","side":"bid","ts_ms":1781237160287}}

{"type":"orderbook_delta","sid":1,"seq":1076,"msg":{"market_ticker":"KXBTCPERP1","price":"6.3348","delta":"-1.00","side":"bid","ts_ms":1781237160287}}

{"type":"orderbook_delta","sid":1,"seq":1077,"msg":{"market_ticker":"KXBTCPERP1","price":"6.3348","delta":"-1.00","side":"bid","ts_ms":1781237160287}}

{"type":"orderbook_delta","sid":1,"seq":1078,"msg":{"market_ticker":"KXBTCPERP1","price":"6.3348","delta":"-1.00","side":"bid","ts_ms":1781237160287}}

{"type":"orderbook_delta","sid":1,"seq":1079,"msg":{"market_ticker":"KXBTCPERP1","price":"6.3348","delta":"-1.00","side":"bid","ts_ms":1781237160287}}

{"type":"orderbook_delta","sid":1,"seq":1080,"msg":{"market_ticker":"KXBTCPERP1","price":"6.3348","delta":"-1.00","side":"bid","ts_ms":1781237160287}}

{"type":"orderbook_delta","sid":1,"seq":1081,"msg":{"market_ticker":"KXBTCPERP1","price":"6.3348","delta":"-1.00","side":"bid","ts_ms":1781237160287}}

{"type":"orderbook_delta","sid":1,"seq":1082,"msg":{"market_ticker":"KXBTCPERP1","price":"6.3348","delta":"-1.00","side":"bid","ts_ms":1781237160287}}

{"type":"orderbook_delta","sid":1,"seq":1083,"msg":{"market_ticker":"KXBTCPERP1","price":"6.3347","delta":"-1.00","side":"bid","ts_ms":1781237160287}}

{"type":"orderbook_delta","sid":1,"seq":1084,"msg":{"market_ticker":"KXBTCPERP1","price":"6.3347","delta":"-1.00","side":"bid","ts_ms":1781237160287}}

{"type":"orderbook_delta","sid":1,"seq":1085,"msg":{"market_ticker":"KXBTCPERP1","price":"6.3346","delta":"-1.00","side":"bid","ts_ms":1781237160287}}

{"type":"orderbook_delta","sid":1,"seq":1086,"msg":{"market_ticker":"KXBTCPERP1","price":"6.3346","delta":"-1.00","side":"bid","ts_ms":1781237160287}}

{"type":"orderbook_delta","sid":1,"seq":1087,"msg":{"market_ticker":"KXBTCPERP1","price":"6.3346","delta":"-1.00","side":"bid","ts_ms":1781237160287}}

{"type":"orderbook_delta","sid":1,"seq":1088,"msg":{"market_ticker":"KXBTCPERP1","price":"6.3346","delta":"-1.00","side":"bid","ts_ms":1781237160287}}

{"type":"orderbook_delta","sid":1,"seq":1089,"msg":{"market_ticker":"KXBTCPERP1","price":"6.3345","delta":"-1.00","side":"bid","ts_ms":1781237160287}}

{"type":"orderbook_delta","sid":1,"seq":1090,"msg":{"market_ticker":"KXBTCPERP1","price":"6.3344","delta":"-1.00","side":"bid","ts_ms":1781237160287}}

{"type":"orderbook_delta","sid":1,"seq":1091,"msg":{"market_ticker":"KXBTCPERP1","price":"6.3344","delta":"-1.00","side":"bid","ts_ms":1781237160287}}

{"type":"orderbook_delta","sid":1,"seq":1092,"msg":{"market_ticker":"KXBTCPERP1","price":"6.3344","delta":"-1.00","side":"bid","ts_ms":1781237160287}}

{"type":"orderbook_delta","sid":1,"seq":1093,"msg":{"market_ticker":"KXBTCPERP1","price":"6.3343","delta":"-1.00","side":"bid","ts_ms":1781237160287}}

{"type":"orderbook_delta","sid":1,"seq":1094,"msg":{"market_ticker":"KXBTCPERP1","price":"6.3342","delta":"-1.00","side":"bid","ts_ms":1781237160287}}

{"type":"orderbook_delta","sid":1,"seq":1095,"msg":{"market_ticker":"KXBTCPERP1","price":"6.3342","delta":"-1.00","side":"bid","ts_ms":1781237160287}}

{"type":"orderbook_delta","sid":1,"seq":1096,"msg":{"market_ticker":"KXBTCPERP1","price":"6.3342","delta":"-1.00","side":"bid","ts_ms":1781237160287}}

{"type":"orderbook_delta","sid":1,"seq":1097,"msg":{"market_ticker":"KXBTCPERP1","price":"6.3342","delta":"-1.00","side":"bid","ts_ms":1781237160287}}

{"type":"orderbook_delta","sid":1,"seq":1098,"msg":{"market_ticker":"KXBTCPERP1","price":"6.3342","delta":"-1.00","side":"bid","ts_ms":1781237160287}}

{"type":"orderbook_delta","sid":1,"seq":1099,"msg":{"market_ticker":"KXBTCPERP1","price":"6.3341","delta":"-1.00","side":"bid","ts_ms":1781237160287}}

{"type":"orderbook_delta","sid":1,"seq":1100,"msg":{"market_ticker":"KXBTCPERP1","price":"6.3341","delta":"-1.00","side":"bid","ts_ms":1781237160287}}

{"type":"orderbook_delta","sid":1,"seq":1101,"msg":{"market_ticker":"KXBTCPERP1","price":"6.3341","delta":"-1.00","side":"bid","ts_ms":1781237160287}}

{"type":"orderbook_delta","sid":1,"seq":1102,"msg":{"market_ticker":"KXBTCPERP1","price":"6.3340","delta":"-1.00","side":"bid","ts_ms":1781237160287}}

{"type":"orderbook_delta","sid":1,"seq":1103,"msg":{"market_ticker":"KXBTCPERP1","price":"6.3340","delta":"-1.00","side":"bid","ts_ms":1781237160287}}

{"type":"orderbook_delta","sid":1,"seq":1104,"msg":{"market_ticker":"KXBTCPERP1","price":"6.3340","delta":"-1.00","side":"bid","ts_ms":1781237160287}}

{"type":"orderbook_delta","sid":1,"seq":1105,"msg":{"market_ticker":"KXBTCPERP1","price":"6.3339","delta":"-1.00","side":"bid","ts_ms":1781237160287}}

{"type":"orderbook_delta","sid":1,"seq":1106,"msg":{"market_ticker":"KXBTCPERP1","price":"6.3339","delta":"-1.00","side":"bid","ts_ms":1781237160287}}

{"type":"orderbook_delta","sid":1,"seq":1107,"msg":{"market_ticker":"KXBTCPERP1","price":"6.3339","delta":"-1.00","side":"bid","ts_ms":1781237160287}}

{"type":"orderbook_delta","sid":1,"seq":1108,"msg":{"market_ticker":"KXBTCPERP1","price":"6.3339","delta":"-1.00","side":"bid","ts_ms":1781237160287}}

{"type":"orderbook_delta","sid":1,"seq":1109,"msg":{"market_ticker":"KXBTCPERP1","price":"6.3339","delta":"-1.00","side":"bid","ts_ms":1781237160287}}

{"type":"orderbook_delta","sid":1,"seq":1110,"msg":{"market_ticker":"KXBTCPERP1","price":"6.3339","delta":"-1.00","side":"bid","ts_ms":1781237160287}}

{"type":"orderbook_delta","sid":1,"seq":1111,"msg":{"market_ticker":"KXBTCPERP1","price":"6.3338","delta":"-1.00","side":"bid","ts_ms":1781237160287}}

{"type":"orderbook_delta","sid":1,"seq":1112,"msg":{"market_ticker":"KXBTCPERP1","price":"6.3338","delta":"-1.00","side":"bid","ts_ms":1781237160287}}

{"type":"orderbook_delta","sid":1,"seq":1113,"msg":{"market_ticker":"KXBTCPERP1","price":"6.3337","delta":"-1.00","side":"bid","ts_ms":1781237160287}}

{"type":"orderbook_delta","sid":1,"seq":1114,"msg":{"market_ticker":"KXBTCPERP1","price":"6.3337","delta":"-1.00","side":"bid","ts_ms":1781237160287}}

{"type":"orderbook_delta","sid":1,"seq":1115,"msg":{"market_ticker":"KXBTCPERP1","price":"6.3337","delta":"-1.00","side":"bid","ts_ms":1781237160287}}

{"type":"orderbook_delta","sid":1,"seq":1116,"msg":{"market_ticker":"KXBTCPERP1","price":"6.3336","delta":"-1.00","side":"bid","ts_ms":1781237160287}}

{"type":"orderbook_delta","sid":1,"seq":1117,"msg":{"market_ticker":"KXBTCPERP1","price":"6.3335","delta":"-1.00","side":"bid","ts_ms":1781237160287}}

{"type":"orderbook_delta","sid":1,"seq":1118,"msg":{"market_ticker":"KXBTCPERP1","price":"6.3334","delta":"-1.00","side":"bid","ts_ms":1781237160287}}

{"type":"orderbook_delta","sid":1,"seq":1119,"msg":{"market_ticker":"KXBTCPERP1","price":"6.3334","delta":"-1.00","side":"bid","ts_ms":1781237160287}}

{"type":"orderbook_delta","sid":1,"seq":1120,"msg":{"market_ticker":"KXBTCPERP1","price":"6.3334","delta":"-1.00","side":"bid","ts_ms":1781237160287}}

{"type":"orderbook_delta","sid":1,"seq":1121,"msg":{"market_ticker":"KXBTCPERP1","price":"6.3334","delta":"-1.00","side":"bid","ts_ms":1781237160287}}

{"type":"orderbook_delta","sid":1,"seq":1122,"msg":{"market_ticker":"KXBTCPERP1","price":"6.3334","delta":"-1.00","side":"bid","ts_ms":1781237160287}}

{"type":"orderbook_delta","sid":1,"seq":1123,"msg":{"market_ticker":"KXBTCPERP1","price":"6.3334","delta":"-1.00","side":"bid","ts_ms":1781237160287}}

{"type":"orderbook_delta","sid":1,"seq":1124,"msg":{"market_ticker":"KXBTCPERP1","price":"6.3334","delta":"-1.00","side":"bid","ts_ms":1781237160287}}

{"type":"orderbook_delta","sid":1,"seq":1125,"msg":{"market_ticker":"KXBTCPERP1","price":"6.3333","delta":"-1.00","side":"bid","ts_ms":1781237160287}}

{"type":"orderbook_delta","sid":1,"seq":1126,"msg":{"market_ticker":"KXBTCPERP1","price":"6.3333","delta":"-1.00","side":"bid","ts_ms":1781237160287}}

{"type":"orderbook_delta","sid":1,"seq":1127,"msg":{"market_ticker":"KXBTCPERP1","price":"6.3333","delta":"-1.00","side":"bid","ts_ms":1781237160287}}

{"type":"orderbook_delta","sid":1,"seq":1128,"msg":{"market_ticker":"KXBTCPERP1","price":"6.3333","delta":"-1.00","side":"bid","ts_ms":1781237160287}}

{"type":"orderbook_delta","sid":1,"seq":1129,"msg":{"market_ticker":"KXBTCPERP1","price":"6.3333","delta":"-1.00","side":"bid","ts_ms":1781237160287}}

{"type":"orderbook_delta","sid":1,"seq":1130,"msg":{"market_ticker":"KXBTCPERP1","price":"6.3331","delta":"-1.00","side":"bid","ts_ms":1781237160287}}

{"type":"orderbook_delta","sid":1,"seq":1131,"msg":{"market_ticker":"KXBTCPERP1","price":"6.3330","delta":"-1.00","side":"bid","ts_ms":1781237160287}}

{"type":"orderbook_delta","sid":1,"seq":1132,"msg":{"market_ticker":"KXBTCPERP1","price":"6.3329","delta":"-1.00","side":"bid","ts_ms":1781237160287}}

{"type":"orderbook_delta","sid":1,"seq":1133,"msg":{"market_ticker":"KXBTCPERP1","price":"6.3329","delta":"-1.00","side":"bid","ts_ms":1781237160287}}

{"type":"orderbook_delta","sid":1,"seq":1134,"msg":{"market_ticker":"KXBTCPERP1","price":"6.3329","delta":"-1.00","side":"bid","ts_ms":1781237160287}}

{"type":"orderbook_delta","sid":1,"seq":1135,"msg":{"market_ticker":"KXBTCPERP1","price":"6.3328","delta":"-1.00","side":"bid","ts_ms":1781237160287}}

{"type":"orderbook_delta","sid":1,"seq":1136,"msg":{"market_ticker":"KXBTCPERP1","price":"6.3328","delta":"-1.00","side":"bid","ts_ms":1781237160287}}

{"type":"orderbook_delta","sid":1,"seq":1137,"msg":{"market_ticker":"KXBTCPERP1","price":"6.3328","delta":"-1.00","side":"bid","ts_ms":1781237160287}}

{"type":"orderbook_delta","sid":1,"seq":1138,"msg":{"market_ticker":"KXBTCPERP1","price":"6.3328","delta":"-1.00","side":"bid","ts_ms":1781237160287}}

{"type":"orderbook_delta","sid":1,"seq":1139,"msg":{"market_ticker":"KXBTCPERP1","price":"6.3328","delta":"-1.00","side":"bid","ts_ms":1781237160287}}

{"type":"orderbook_delta","sid":1,"seq":1140,"msg":{"market_ticker":"KXBTCPERP1","price":"6.3328","delta":"-1.00","side":"bid","ts_ms":1781237160287}}

{"type":"orderbook_delta","sid":1,"seq":1141,"msg":{"market_ticker":"KXBTCPERP1","price":"6.3328","delta":"-1.00","side":"bid","ts_ms":1781237160287}}

{"type":"orderbook_delta","sid":1,"seq":1142,"msg":{"market_ticker":"KXBTCPERP1","price":"6.3327","delta":"-1.00","side":"bid","ts_ms":1781237160287}}

{"type":"orderbook_delta","sid":1,"seq":1143,"msg":{"market_ticker":"KXBTCPERP1","price":"6.3326","delta":"-1.00","side":"bid","ts_ms":1781237160287}}

{"type":"orderbook_delta","sid":1,"seq":1144,"msg":{"market_ticker":"KXBTCPERP1","price":"6.3326","delta":"-1.00","side":"bid","ts_ms":1781237160287}}

{"type":"orderbook_delta","sid":1,"seq":1145,"msg":{"market_ticker":"KXBTCPERP1","price":"6.3326","delta":"-1.00","side":"bid","ts_ms":1781237160287}}

{"type":"orderbook_delta","sid":1,"seq":1146,"msg":{"market_ticker":"KXBTCPERP1","price":"6.3326","delta":"-1.00","side":"bid","ts_ms":1781237160287}}

{"type":"orderbook_delta","sid":1,"seq":1147,"msg":{"market_ticker":"KXBTCPERP1","price":"6.3325","delta":"-1.00","side":"bid","ts_ms":1781237160287}}

{"type":"orderbook_delta","sid":1,"seq":1148,"msg":{"market_ticker":"KXBTCPERP1","price":"6.3324","delta":"-1.00","side":"bid","ts_ms":1781237160287}}

{"type":"orderbook_delta","sid":1,"seq":1149,"msg":{"market_ticker":"KXBTCPERP1","price":"6.3324","delta":"-1.00","side":"bid","ts_ms":1781237160287}}

{"type":"orderbook_delta","sid":1,"seq":1150,"msg":{"market_ticker":"KXBTCPERP1","price":"6.3323","delta":"-1.00","side":"bid","ts_ms":1781237160287}}

{"type":"orderbook_delta","sid":1,"seq":1151,"msg":{"market_ticker":"KXBTCPERP1","price":"6.3323","delta":"-1.00","side":"bid","ts_ms":1781237160287}}

{"type":"orderbook_delta","sid":1,"seq":1152,"msg":{"market_ticker":"KXBTCPERP1","price":"6.3323","delta":"-1.00","side":"bid","ts_ms":1781237160287}}

{"type":"orderbook_delta","sid":1,"seq":1153,"msg":{"market_ticker":"KXBTCPERP1","price":"6.3323","delta":"-1.00","side":"bid","ts_ms":1781237160287}}

{"type":"orderbook_delta","sid":1,"seq":1154,"msg":{"market_ticker":"KXBTCPERP1","price":"6.3323","delta":"-1.00","side":"bid","ts_ms":1781237160287}}

{"type":"orderbook_delta","sid":1,"seq":1155,"msg":{"market_ticker":"KXBTCPERP1","price":"6.3322","delta":"-1.00","side":"bid","ts_ms":1781237160287}}

{"type":"orderbook_delta","sid":1,"seq":1156,"msg":{"market_ticker":"KXBTCPERP1","price":"6.3322","delta":"-1.00","side":"bid","ts_ms":1781237160287}}

{"type":"orderbook_delta","sid":1,"seq":1157,"msg":{"market_ticker":"KXBTCPERP1","price":"6.3321","delta":"-1.00","side":"bid","ts_ms":1781237160287}}

{"type":"orderbook_delta","sid":1,"seq":1158,"msg":{"market_ticker":"KXBTCPERP1","price":"6.3321","delta":"-1.00","side":"bid","ts_ms":1781237160287}}

{"type":"orderbook_delta","sid":1,"seq":1159,"msg":{"market_ticker":"KXBTCPERP1","price":"6.3321","delta":"-1.00","side":"bid","ts_ms":1781237160287}}

{"type":"orderbook_delta","sid":1,"seq":1160,"msg":{"market_ticker":"KXBTCPERP1","price":"6.3320","delta":"-1.00","side":"bid","ts_ms":1781237160287}}

{"type":"orderbook_delta","sid":1,"seq":1161,"msg":{"market_ticker":"KXBTCPERP1","price":"6.3320","delta":"-1.00","side":"bid","ts_ms":1781237160287}}

{"type":"orderbook_delta","sid":1,"seq":1162,"msg":{"market_ticker":"KXBTCPERP1","price":"6.3320","delta":"-1.00","side":"bid","ts_ms":1781237160287}}

{"type":"orderbook_delta","sid":1,"seq":1163,"msg":{"market_ticker":"KXBTCPERP1","price":"6.3320","delta":"-1.00","side":"bid","ts_ms":1781237160287}}

{"type":"orderbook_delta","sid":1,"seq":1164,"msg":{"market_ticker":"KXBTCPERP1","price":"6.3319","delta":"-1.00","side":"bid","ts_ms":1781237160287}}

{"type":"orderbook_delta","sid":1,"seq":1165,"msg":{"market_ticker":"KXBTCPERP1","price":"6.3319","delta":"-1.00","side":"bid","ts_ms":1781237160287}}

{"type":"orderbook_delta","sid":1,"seq":1166,"msg":{"market_ticker":"KXBTCPERP1","price":"6.3319","delta":"-1.00","side":"bid","ts_ms":1781237160287}}

{"type":"orderbook_delta","sid":1,"seq":1167,"msg":{"market_ticker":"KXBTCPERP1","price":"6.3318","delta":"-1.00","side":"bid","ts_ms":1781237160287}}

{"type":"orderbook_delta","sid":1,"seq":1168,"msg":{"market_ticker":"KXBTCPERP1","price":"6.3318","delta":"-1.00","side":"bid","ts_ms":1781237160287}}

{"type":"orderbook_delta","sid":1,"seq":1169,"msg":{"market_ticker":"KXBTCPERP1","price":"6.3318","delta":"-1.00","side":"bid","ts_ms":1781237160287}}

{"type":"orderbook_delta","sid":1,"seq":1170,"msg":{"market_ticker":"KXBTCPERP1","price":"6.3318","delta":"-1.00","side":"bid","ts_ms":1781237160287}}

{"type":"orderbook_delta","sid":1,"seq":1171,"msg":{"market_ticker":"KXBTCPERP1","price":"6.3318","delta":"-1.00","side":"bid","ts_ms":1781237160287}}

{"type":"orderbook_delta","sid":1,"seq":1172,"msg":{"market_ticker":"KXBTCPERP1","price":"6.3317","delta":"-1.00","side":"bid","ts_ms":1781237160287}}

{"type":"orderbook_delta","sid":1,"seq":1173,"msg":{"market_ticker":"KXBTCPERP1","price":"6.3317","delta":"-1.00","side":"bid","ts_ms":1781237160287}}

{"type":"orderbook_delta","sid":1,"seq":1174,"msg":{"market_ticker":"KXBTCPERP1","price":"6.3317","delta":"-1.00","side":"bid","ts_ms":1781237160287}}

{"type":"orderbook_delta","sid":1,"seq":1175,"msg":{"market_ticker":"KXBTCPERP1","price":"6.3317","delta":"-1.00","side":"bid","ts_ms":1781237160287}}

{"type":"orderbook_delta","sid":1,"seq":1176,"msg":{"market_ticker":"KXBTCPERP1","price":"6.3316","delta":"-1.00","side":"bid","ts_ms":1781237160287}}

{"type":"orderbook_delta","sid":1,"seq":1177,"msg":{"market_ticker":"KXBTCPERP1","price":"6.3316","delta":"-1.00","side":"bid","ts_ms":1781237160287}}

{"type":"orderbook_delta","sid":1,"seq":1178,"msg":{"market_ticker":"KXBTCPERP1","price":"6.3316","delta":"-1.00","side":"bid","ts_ms":1781237160287}}

{"type":"orderbook_delta","sid":1,"seq":1179,"msg":{"market_ticker":"KXBTCPERP1","price":"6.3316","delta":"-1.00","side":"bid","ts_ms":1781237160287}}

{"type":"orderbook_delta","sid":1,"seq":1180,"msg":{"market_ticker":"KXBTCPERP1","price":"6.3316","delta":"-1.00","side":"bid","ts_ms":1781237160287}}

{"type":"orderbook_delta","sid":1,"seq":1181,"msg":{"market_ticker":"KXBTCPERP1","price":"6.3315","delta":"-1.00","side":"bid","ts_ms":1781237160287}}

{"type":"orderbook_delta","sid":1,"seq":1182,"msg":{"market_ticker":"KXBTCPERP1","price":"6.3315","delta":"-1.00","side":"bid","ts_ms":1781237160287}}

{"type":"orderbook_delta","sid":1,"seq":1183,"msg":{"market_ticker":"KXBTCPERP1","price":"6.3315","delta":"-1.00","side":"bid","ts_ms":1781237160287}}

{"type":"orderbook_delta","sid":1,"seq":1184,"msg":{"market_ticker":"KXBTCPERP1","price":"6.3314","delta":"-1.00","side":"bid","ts_ms":1781237160287}}

{"type":"orderbook_delta","sid":1,"seq":1185,"msg":{"market_ticker":"KXBTCPERP1","price":"6.3314","delta":"-1.00","side":"bid","ts_ms":1781237160287}}

{"type":"orderbook_delta","sid":1,"seq":1186,"msg":{"market_ticker":"KXBTCPERP1","price":"6.3314","delta":"-1.00","side":"bid","ts_ms":1781237160287}}

{"type":"orderbook_delta","sid":1,"seq":1187,"msg":{"market_ticker":"KXBTCPERP1","price":"6.3314","delta":"-1.00","side":"bid","ts_ms":1781237160287}}

{"type":"orderbook_delta","sid":1,"seq":1188,"msg":{"market_ticker":"KXBTCPERP1","price":"6.3313","delta":"-1.00","side":"bid","ts_ms":1781237160287}}

{"type":"orderbook_delta","sid":1,"seq":1189,"msg":{"market_ticker":"KXBTCPERP1","price":"6.3312","delta":"-1.00","side":"bid","ts_ms":1781237160287}}

{"type":"orderbook_delta","sid":1,"seq":1190,"msg":{"market_ticker":"KXBTCPERP1","price":"6.3312","delta":"-1.00","side":"bid","ts_ms":1781237160287}}

{"type":"orderbook_delta","sid":1,"seq":1191,"msg":{"market_ticker":"KXBTCPERP1","price":"6.3312","delta":"-1.00","side":"bid","ts_ms":1781237160287}}

{"type":"orderbook_delta","sid":1,"seq":1192,"msg":{"market_ticker":"KXBTCPERP1","price":"6.3312","delta":"-1.00","side":"bid","ts_ms":1781237160287}}

{"type":"orderbook_delta","sid":1,"seq":1193,"msg":{"market_ticker":"KXBTCPERP1","price":"6.3312","delta":"-1.00","side":"bid","ts_ms":1781237160287}}

{"type":"orderbook_delta","sid":1,"seq":1194,"msg":{"market_ticker":"KXBTCPERP1","price":"6.3312","delta":"-1.00","side":"bid","ts_ms":1781237160287}}

{"type":"orderbook_delta","sid":1,"seq":1195,"msg":{"market_ticker":"KXBTCPERP1","price":"6.3311","delta":"-1.00","side":"bid","ts_ms":1781237160287}}

{"type":"orderbook_delta","sid":1,"seq":1196,"msg":{"market_ticker":"KXBTCPERP1","price":"6.3311","delta":"-1.00","side":"bid","ts_ms":1781237160287}}

{"type":"orderbook_delta","sid":1,"seq":1197,"msg":{"market_ticker":"KXBTCPERP1","price":"6.3310","delta":"-1.00","side":"bid","ts_ms":1781237160287}}

{"type":"orderbook_delta","sid":1,"seq":1198,"msg":{"market_ticker":"KXBTCPERP1","price":"6.3310","delta":"-1.00","side":"bid","ts_ms":1781237160287}}

{"type":"orderbook_delta","sid":1,"seq":1199,"msg":{"market_ticker":"KXBTCPERP1","price":"6.3310","delta":"-1.00","side":"bid","ts_ms":1781237160287}}

{"type":"orderbook_delta","sid":1,"seq":1200,"msg":{"market_ticker":"KXBTCPERP1","price":"6.3310","delta":"-1.00","side":"bid","ts_ms":1781237160287}}

{"type":"orderbook_delta","sid":1,"seq":1201,"msg":{"market_ticker":"KXBTCPERP1","price":"6.3310","delta":"-1.00","side":"bid","ts_ms":1781237160287}}

{"type":"orderbook_delta","sid":1,"seq":1202,"msg":{"market_ticker":"KXBTCPERP1","price":"6.3309","delta":"-1.00","side":"bid","ts_ms":1781237160287}}

{"type":"orderbook_delta","sid":1,"seq":1203,"msg":{"market_ticker":"KXBTCPERP1","price":"6.3309","delta":"-1.00","side":"bid","ts_ms":1781237160287}}

{"type":"orderbook_delta","sid":1,"seq":1204,"msg":{"market_ticker":"KXBTCPERP1","price":"6.3309","delta":"-1.00","side":"bid","ts_ms":1781237160287}}

{"type":"orderbook_delta","sid":1,"seq":1205,"msg":{"market_ticker":"KXBTCPERP1","price":"6.3308","delta":"-1.00","side":"bid","ts_ms":1781237160287}}

{"type":"orderbook_delta","sid":1,"seq":1206,"msg":{"market_ticker":"KXBTCPERP1","price":"6.3307","delta":"-1.00","side":"bid","ts_ms":1781237160287}}

{"type":"orderbook_delta","sid":1,"seq":1207,"msg":{"market_ticker":"KXBTCPERP1","price":"6.3307","delta":"-1.00","side":"bid","ts_ms":1781237160287}}

{"type":"orderbook_delta","sid":1,"seq":1208,"msg":{"market_ticker":"KXBTCPERP1","price":"6.3306","delta":"-1.00","side":"bid","ts_ms":1781237160287}}

{"type":"orderbook_delta","sid":1,"seq":1209,"msg":{"market_ticker":"KXBTCPERP1","price":"6.3305","delta":"-1.00","side":"bid","ts_ms":1781237160287}}

{"type":"orderbook_delta","sid":1,"seq":1210,"msg":{"market_ticker":"KXBTCPERP1","price":"6.3305","delta":"-1.00","side":"bid","ts_ms":1781237160287}}

{"type":"orderbook_delta","sid":1,"seq":1211,"msg":{"market_ticker":"KXBTCPERP1","price":"6.3305","delta":"-1.00","side":"bid","ts_ms":1781237160287}}

{"type":"orderbook_delta","sid":1,"seq":1212,"msg":{"market_ticker":"KXBTCPERP1","price":"6.3305","delta":"-1.00","side":"bid","ts_ms":1781237160287}}

{"type":"orderbook_delta","sid":1,"seq":1213,"msg":{"market_ticker":"KXBTCPERP1","price":"6.3305","delta":"-1.00","side":"bid","ts_ms":1781237160287}}

{"type":"orderbook_delta","sid":1,"seq":1214,"msg":{"market_ticker":"KXBTCPERP1","price":"6.3304","delta":"-1.00","side":"bid","ts_ms":1781237160287}}

{"type":"orderbook_delta","sid":1,"seq":1215,"msg":{"market_ticker":"KXBTCPERP1","price":"6.3303","delta":"-1.00","side":"bid","ts_ms":1781237160287}}

{"type":"orderbook_delta","sid":1,"seq":1216,"msg":{"market_ticker":"KXBTCPERP1","price":"6.3303","delta":"-1.00","side":"bid","ts_ms":1781237160287}}

{"type":"orderbook_delta","sid":1,"seq":1217,"msg":{"market_ticker":"KXBTCPERP1","price":"6.3302","delta":"-1.00","side":"bid","ts_ms":1781237160287}}

{"type":"orderbook_delta","sid":1,"seq":1218,"msg":{"market_ticker":"KXBTCPERP1","price":"6.3302","delta":"-1.00","side":"bid","ts_ms":1781237160287}}

{"type":"orderbook_delta","sid":1,"seq":1219,"msg":{"market_ticker":"KXBTCPERP1","price":"6.3302","delta":"-1.00","side":"bid","ts_ms":1781237160287}}

{"type":"orderbook_delta","sid":1,"seq":1220,"msg":{"market_ticker":"KXBTCPERP1","price":"6.3302","delta":"-1.00","side":"bid","ts_ms":1781237160287}}

{"type":"orderbook_delta","sid":1,"seq":1221,"msg":{"market_ticker":"KXBTCPERP1","price":"6.3301","delta":"-1.00","side":"bid","ts_ms":1781237160287}}

{"type":"orderbook_delta","sid":1,"seq":1222,"msg":{"market_ticker":"KXBTCPERP1","price":"6.3301","delta":"-1.00","side":"bid","ts_ms":1781237160287}}

{"type":"orderbook_delta","sid":1,"seq":1223,"msg":{"market_ticker":"KXBTCPERP1","price":"6.3301","delta":"-1.00","side":"bid","ts_ms":1781237160287}}

{"type":"orderbook_delta","sid":1,"seq":1224,"msg":{"market_ticker":"KXBTCPERP1","price":"6.3300","delta":"-1.00","side":"bid","ts_ms":1781237160287}}

{"type":"orderbook_delta","sid":1,"seq":1225,"msg":{"market_ticker":"KXBTCPERP1","price":"6.3300","delta":"-1.00","side":"bid","ts_ms":1781237160287}}

{"type":"orderbook_delta","sid":1,"seq":1226,"msg":{"market_ticker":"KXBTCPERP1","price":"6.3300","delta":"-1.00","side":"bid","ts_ms":1781237160287}}

{"type":"orderbook_delta","sid":1,"seq":1227,"msg":{"market_ticker":"KXBTCPERP1","price":"6.3300","delta":"-1.00","side":"bid","ts_ms":1781237160287}}

{"type":"orderbook_delta","sid":1,"seq":1228,"msg":{"market_ticker":"KXBTCPERP1","price":"6.3299","delta":"-1.00","side":"bid","ts_ms":1781237160287}}

{"type":"orderbook_delta","sid":1,"seq":1229,"msg":{"market_ticker":"KXBTCPERP1","price":"6.3299","delta":"-1.00","side":"bid","ts_ms":1781237160287}}

{"type":"orderbook_delta","sid":1,"seq":1230,"msg":{"market_ticker":"KXBTCPERP1","price":"6.3298","delta":"-1.00","side":"bid","ts_ms":1781237160287}}

{"type":"orderbook_delta","sid":1,"seq":1231,"msg":{"market_ticker":"KXBTCPERP1","price":"6.3298","delta":"-1.00","side":"bid","ts_ms":1781237160287}}

{"type":"orderbook_delta","sid":1,"seq":1232,"msg":{"market_ticker":"KXBTCPERP1","price":"6.3298","delta":"-1.00","side":"bid","ts_ms":1781237160287}}

{"type":"orderbook_delta","sid":1,"seq":1233,"msg":{"market_ticker":"KXBTCPERP1","price":"6.3298","delta":"-1.00","side":"bid","ts_ms":1781237160287}}

{"type":"orderbook_delta","sid":1,"seq":1234,"msg":{"market_ticker":"KXBTCPERP1","price":"6.3297","delta":"-1.00","side":"bid","ts_ms":1781237160287}}

{"type":"orderbook_delta","sid":1,"seq":1235,"msg":{"market_ticker":"KXBTCPERP1","price":"6.3297","delta":"-1.00","side":"bid","ts_ms":1781237160287}}

{"type":"orderbook_delta","sid":1,"seq":1236,"msg":{"market_ticker":"KXBTCPERP1","price":"6.3297","delta":"-1.00","side":"bid","ts_ms":1781237160287}}

{"type":"orderbook_delta","sid":1,"seq":1237,"msg":{"market_ticker":"KXBTCPERP1","price":"6.3296","delta":"-1.00","side":"bid","ts_ms":1781237160287}}

{"type":"orderbook_delta","sid":1,"seq":1238,"msg":{"market_ticker":"KXBTCPERP1","price":"6.3296","delta":"-1.00","side":"bid","ts_ms":1781237160287}}

{"type":"orderbook_delta","sid":1,"seq":1239,"msg":{"market_ticker":"KXBTCPERP1","price":"6.3296","delta":"-1.00","side":"bid","ts_ms":1781237160287}}

{"type":"orderbook_delta","sid":1,"seq":1240,"msg":{"market_ticker":"KXBTCPERP1","price":"6.3295","delta":"-1.00","side":"bid","ts_ms":1781237160287}}

{"type":"orderbook_delta","sid":1,"seq":1241,"msg":{"market_ticker":"KXBTCPERP1","price":"6.3294","delta":"-1.00","side":"bid","ts_ms":1781237160287}}

{"type":"orderbook_delta","sid":1,"seq":1242,"msg":{"market_ticker":"KXBTCPERP1","price":"6.3293","delta":"-1.00","side":"bid","ts_ms":1781237160287}}

{"type":"orderbook_delta","sid":1,"seq":1243,"msg":{"market_ticker":"KXBTCPERP1","price":"6.3293","delta":"-1.00","side":"bid","ts_ms":1781237160287}}

{"type":"orderbook_delta","sid":1,"seq":1244,"msg":{"market_ticker":"KXBTCPERP1","price":"6.3293","delta":"-1.00","side":"bid","ts_ms":1781237160287}}

{"type":"orderbook_delta","sid":1,"seq":1245,"msg":{"market_ticker":"KXBTCPERP1","price":"6.3292","delta":"-1.00","side":"bid","ts_ms":1781237160287}}

{"type":"orderbook_delta","sid":1,"seq":1246,"msg":{"market_ticker":"KXBTCPERP1","price":"6.3292","delta":"-1.00","side":"bid","ts_ms":1781237160287}}

{"type":"orderbook_delta","sid":1,"seq":1247,"msg":{"market_ticker":"KXBTCPERP1","price":"6.3291","delta":"-1.00","side":"bid","ts_ms":1781237160287}}

{"type":"orderbook_delta","sid":1,"seq":1248,"msg":{"market_ticker":"KXBTCPERP1","price":"6.3291","delta":"-1.00","side":"bid","ts_ms":1781237160287}}

{"type":"orderbook_delta","sid":1,"seq":1249,"msg":{"market_ticker":"KXBTCPERP1","price":"6.3291","delta":"-1.00","side":"bid","ts_ms":1781237160287}}

{"type":"orderbook_delta","sid":1,"seq":1250,"msg":{"market_ticker":"KXBTCPERP1","price":"6.3291","delta":"-1.00","side":"bid","ts_ms":1781237160287}}

{"type":"orderbook_delta","sid":1,"seq":1251,"msg":{"market_ticker":"KXBTCPERP1","price":"6.3291","delta":"-1.00","side":"bid","ts_ms":1781237160287}}

{"type":"orderbook_delta","sid":1,"seq":1252,"msg":{"market_ticker":"KXBTCPERP1","price":"6.3291","delta":"-1.00","side":"bid","ts_ms":1781237160287}}

{"type":"orderbook_delta","sid":1,"seq":1253,"msg":{"market_ticker":"KXBTCPERP1","price":"6.3291","delta":"-1.00","side":"bid","ts_ms":1781237160287}}

{"type":"orderbook_delta","sid":1,"seq":1254,"msg":{"market_ticker":"KXBTCPERP1","price":"6.3291","delta":"-1.00","side":"bid","ts_ms":1781237160287}}

{"type":"orderbook_delta","sid":1,"seq":1255,"msg":{"market_ticker":"KXBTCPERP1","price":"6.3291","delta":"-1.00","side":"bid","ts_ms":1781237160287}}

{"type":"orderbook_delta","sid":1,"seq":1256,"msg":{"market_ticker":"KXBTCPERP1","price":"6.3291","delta":"-1.00","side":"bid","ts_ms":1781237160287}}

{"type":"orderbook_delta","sid":1,"seq":1257,"msg":{"market_ticker":"KXBTCPERP1","price":"6.3291","delta":"-1.00","side":"bid","ts_ms":1781237160287}}

{"type":"orderbook_delta","sid":1,"seq":1258,"msg":{"market_ticker":"KXBTCPERP1","price":"6.3290","delta":"-1.00","side":"bid","ts_ms":1781237160287}}

{"type":"orderbook_delta","sid":1,"seq":1259,"msg":{"market_ticker":"KXBTCPERP1","price":"6.3290","delta":"-1.00","side":"bid","ts_ms":1781237160287}}

{"type":"orderbook_delta","sid":1,"seq":1260,"msg":{"market_ticker":"KXBTCPERP1","price":"6.3289","delta":"-1.00","side":"bid","ts_ms":1781237160287}}

{"type":"orderbook_delta","sid":1,"seq":1261,"msg":{"market_ticker":"KXBTCPERP1","price":"6.3289","delta":"-1.00","side":"bid","ts_ms":1781237160287}}

{"type":"orderbook_delta","sid":1,"seq":1262,"msg":{"market_ticker":"KXBTCPERP1","price":"6.3288","delta":"-1.00","side":"bid","ts_ms":1781237160287}}

{"type":"orderbook_delta","sid":1,"seq":1263,"msg":{"market_ticker":"KXBTCPERP1","price":"6.3288","delta":"-1.00","side":"bid","ts_ms":1781237160287}}

{"type":"orderbook_delta","sid":1,"seq":1264,"msg":{"market_ticker":"KXBTCPERP1","price":"6.3287","delta":"-1.00","side":"bid","ts_ms":1781237160287}}

{"type":"orderbook_delta","sid":1,"seq":1265,"msg":{"market_ticker":"KXBTCPERP1","price":"6.3287","delta":"-1.00","side":"bid","ts_ms":1781237160287}}

{"type":"orderbook_delta","sid":1,"seq":1266,"msg":{"market_ticker":"KXBTCPERP1","price":"6.3285","delta":"-1.00","side":"bid","ts_ms":1781237160287}}

{"type":"orderbook_delta","sid":1,"seq":1267,"msg":{"market_ticker":"KXBTCPERP1","price":"6.3285","delta":"-1.00","side":"bid","ts_ms":1781237160287}}

{"type":"orderbook_delta","sid":1,"seq":1268,"msg":{"market_ticker":"KXBTCPERP1","price":"6.3284","delta":"-1.00","side":"bid","ts_ms":1781237160287}}

{"type":"orderbook_delta","sid":1,"seq":1269,"msg":{"market_ticker":"KXBTCPERP1","price":"6.3284","delta":"-1.00","side":"bid","ts_ms":1781237160287}}

{"type":"orderbook_delta","sid":1,"seq":1270,"msg":{"market_ticker":"KXBTCPERP1","price":"6.3283","delta":"-1.00","side":"bid","ts_ms":1781237160287}}

{"type":"orderbook_delta","sid":1,"seq":1271,"msg":{"market_ticker":"KXBTCPERP1","price":"6.3282","delta":"-1.00","side":"bid","ts_ms":1781237160287}}

{"type":"orderbook_delta","sid":1,"seq":1272,"msg":{"market_ticker":"KXBTCPERP1","price":"6.3282","delta":"-1.00","side":"bid","ts_ms":1781237160287}}

{"type":"orderbook_delta","sid":1,"seq":1273,"msg":{"market_ticker":"KXBTCPERP1","price":"6.3281","delta":"-1.00","side":"bid","ts_ms":1781237160287}}

{"type":"orderbook_delta","sid":1,"seq":1274,"msg":{"market_ticker":"KXBTCPERP1","price":"6.3281","delta":"-1.00","side":"bid","ts_ms":1781237160287}}

{"type":"orderbook_delta","sid":1,"seq":1275,"msg":{"market_ticker":"KXBTCPERP1","price":"6.3280","delta":"-1.00","side":"bid","ts_ms":1781237160287}}

{"type":"orderbook_delta","sid":1,"seq":1276,"msg":{"market_ticker":"KXBTCPERP1","price":"6.3280","delta":"-1.00","side":"bid","ts_ms":1781237160287}}

{"type":"orderbook_delta","sid":1,"seq":1277,"msg":{"market_ticker":"KXBTCPERP1","price":"6.3279","delta":"-1.00","side":"bid","ts_ms":1781237160287}}

{"type":"orderbook_delta","sid":1,"seq":1278,"msg":{"market_ticker":"KXBTCPERP1","price":"6.3279","delta":"-1.00","side":"bid","ts_ms":1781237160287}}

{"type":"orderbook_delta","sid":1,"seq":1279,"msg":{"market_ticker":"KXBTCPERP1","price":"6.3279","delta":"-1.00","side":"bid","ts_ms":1781237160287}}

{"type":"orderbook_delta","sid":1,"seq":1280,"msg":{"market_ticker":"KXBTCPERP1","price":"6.3279","delta":"-1.00","side":"bid","ts_ms":1781237160287}}

{"type":"orderbook_delta","sid":1,"seq":1281,"msg":{"market_ticker":"KXBTCPERP1","price":"6.3279","delta":"-1.00","side":"bid","ts_ms":1781237160287}}

{"type":"orderbook_delta","sid":1,"seq":1282,"msg":{"market_ticker":"KXBTCPERP1","price":"6.3278","delta":"-1.00","side":"bid","ts_ms":1781237160287}}

{"type":"orderbook_delta","sid":1,"seq":1283,"msg":{"market_ticker":"KXBTCPERP1","price":"6.3278","delta":"-1.00","side":"bid","ts_ms":1781237160287}}

{"type":"orderbook_delta","sid":1,"seq":1284,"msg":{"market_ticker":"KXBTCPERP1","price":"6.3278","delta":"-1.00","side":"bid","ts_ms":1781237160287}}

{"type":"orderbook_delta","sid":1,"seq":1285,"msg":{"market_ticker":"KXBTCPERP1","price":"6.3278","delta":"-1.00","side":"bid","ts_ms":1781237160287}}

{"type":"orderbook_delta","sid":1,"seq":1286,"msg":{"market_ticker":"KXBTCPERP1","price":"6.3278","delta":"-1.00","side":"bid","ts_ms":1781237160287}}

{"type":"orderbook_delta","sid":1,"seq":1287,"msg":{"market_ticker":"KXBTCPERP1","price":"6.3277","delta":"-1.00","side":"bid","ts_ms":1781237160287}}

{"type":"orderbook_delta","sid":1,"seq":1288,"msg":{"market_ticker":"KXBTCPERP1","price":"6.3277","delta":"-1.00","side":"bid","ts_ms":1781237160287}}

{"type":"orderbook_delta","sid":1,"seq":1289,"msg":{"market_ticker":"KXBTCPERP1","price":"6.3277","delta":"-1.00","side":"bid","ts_ms":1781237160287}}

{"type":"orderbook_delta","sid":1,"seq":1290,"msg":{"market_ticker":"KXBTCPERP1","price":"6.3277","delta":"-1.00","side":"bid","ts_ms":1781237160287}}

{"type":"orderbook_delta","sid":1,"seq":1291,"msg":{"market_ticker":"KXBTCPERP1","price":"6.3277","delta":"-1.00","side":"bid","ts_ms":1781237160287}}

{"type":"orderbook_delta","sid":1,"seq":1292,"msg":{"market_ticker":"KXBTCPERP1","price":"6.3277","delta":"-1.00","side":"bid","ts_ms":1781237160287}}

{"type":"orderbook_delta","sid":1,"seq":1293,"msg":{"market_ticker":"KXBTCPERP1","price":"6.3276","delta":"-1.00","side":"bid","ts_ms":1781237160287}}

{"type":"orderbook_delta","sid":1,"seq":1294,"msg":{"market_ticker":"KXBTCPERP1","price":"6.3276","delta":"-1.00","side":"bid","ts_ms":1781237160287}}

{"type":"orderbook_delta","sid":1,"seq":1295,"msg":{"market_ticker":"KXBTCPERP1","price":"6.3276","delta":"-1.00","side":"bid","ts_ms":1781237160287}}

{"type":"orderbook_delta","sid":1,"seq":1296,"msg":{"market_ticker":"KXBTCPERP1","price":"6.3275","delta":"-1.00","side":"bid","ts_ms":1781237160287}}

{"type":"orderbook_delta","sid":1,"seq":1297,"msg":{"market_ticker":"KXBTCPERP1","price":"6.3275","delta":"-1.00","side":"bid","ts_ms":1781237160287}}

{"type":"orderbook_delta","sid":1,"seq":1298,"msg":{"market_ticker":"KXBTCPERP1","price":"6.3275","delta":"-1.00","side":"bid","ts_ms":1781237160287}}

{"type":"orderbook_delta","sid":1,"seq":1299,"msg":{"market_ticker":"KXBTCPERP1","price":"6.3274","delta":"-1.00","side":"bid","ts_ms":1781237160287}}

{"type":"orderbook_delta","sid":1,"seq":1300,"msg":{"market_ticker":"KXBTCPERP1","price":"6.3274","delta":"-1.00","side":"bid","ts_ms":1781237160287}}

{"type":"orderbook_delta","sid":1,"seq":1301,"msg":{"market_ticker":"KXBTCPERP1","price":"6.3273","delta":"-1.00","side":"bid","ts_ms":1781237160287}}

{"type":"orderbook_delta","sid":1,"seq":1302,"msg":{"market_ticker":"KXBTCPERP1","price":"6.3273","delta":"-1.00","side":"bid","ts_ms":1781237160287}}

{"type":"orderbook_delta","sid":1,"seq":1303,"msg":{"market_ticker":"KXBTCPERP1","price":"6.3273","delta":"-1.00","side":"bid","ts_ms":1781237160287}}

{"type":"orderbook_delta","sid":1,"seq":1304,"msg":{"market_ticker":"KXBTCPERP1","price":"6.3273","delta":"-1.00","side":"bid","ts_ms":1781237160287}}

{"type":"orderbook_delta","sid":1,"seq":1305,"msg":{"market_ticker":"KXBTCPERP1","price":"6.3273","delta":"-1.00","side":"bid","ts_ms":1781237160287}}

{"type":"orderbook_delta","sid":1,"seq":1306,"msg":{"market_ticker":"KXBTCPERP1","price":"6.3272","delta":"-1.00","side":"bid","ts_ms":1781237160287}}

{"type":"orderbook_delta","sid":1,"seq":1307,"msg":{"market_ticker":"KXBTCPERP1","price":"6.3272","delta":"-1.00","side":"bid","ts_ms":1781237160287}}

{"type":"orderbook_delta","sid":1,"seq":1308,"msg":{"market_ticker":"KXBTCPERP1","price":"6.3272","delta":"-1.00","side":"bid","ts_ms":1781237160287}}

{"type":"orderbook_delta","sid":1,"seq":1309,"msg":{"market_ticker":"KXBTCPERP1","price":"6.3272","delta":"-1.00","side":"bid","ts_ms":1781237160287}}

{"type":"orderbook_delta","sid":1,"seq":1310,"msg":{"market_ticker":"KXBTCPERP1","price":"6.3272","delta":"-1.00","side":"bid","ts_ms":1781237160287}}

{"type":"orderbook_delta","sid":1,"seq":1311,"msg":{"market_ticker":"KXBTCPERP1","price":"6.3272","delta":"-1.00","side":"bid","ts_ms":1781237160287}}

{"type":"orderbook_delta","sid":1,"seq":1312,"msg":{"market_ticker":"KXBTCPERP1","price":"6.3271","delta":"-1.00","side":"bid","ts_ms":1781237160287}}

{"type":"orderbook_delta","sid":1,"seq":1313,"msg":{"market_ticker":"KXBTCPERP1","price":"6.3271","delta":"-1.00","side":"bid","ts_ms":1781237160287}}

{"type":"orderbook_delta","sid":1,"seq":1314,"msg":{"market_ticker":"KXBTCPERP1","price":"6.3271","delta":"-1.00","side":"bid","ts_ms":1781237160287}}

{"type":"orderbook_delta","sid":1,"seq":1315,"msg":{"market_ticker":"KXBTCPERP1","price":"6.3271","delta":"-1.00","side":"bid","ts_ms":1781237160287}}

{"type":"orderbook_delta","sid":1,"seq":1316,"msg":{"market_ticker":"KXBTCPERP1","price":"6.3270","delta":"-1.00","side":"bid","ts_ms":1781237160287}}

{"type":"orderbook_delta","sid":1,"seq":1317,"msg":{"market_ticker":"KXBTCPERP1","price":"6.3270","delta":"-1.00","side":"bid","ts_ms":1781237160287}}

{"type":"orderbook_delta","sid":1,"seq":1318,"msg":{"market_ticker":"KXBTCPERP1","price":"6.3270","delta":"-1.00","side":"bid","ts_ms":1781237160287}}

{"type":"orderbook_delta","sid":1,"seq":1319,"msg":{"market_ticker":"KXBTCPERP1","price":"6.3269","delta":"-1.00","side":"bid","ts_ms":1781237160287}}

{"type":"orderbook_delta","sid":1,"seq":1320,"msg":{"market_ticker":"KXBTCPERP1","price":"6.3268","delta":"-1.00","side":"bid","ts_ms":1781237160287}}

{"type":"orderbook_delta","sid":1,"seq":1321,"msg":{"market_ticker":"KXBTCPERP1","price":"6.3268","delta":"-1.00","side":"bid","ts_ms":1781237160287}}

{"type":"orderbook_delta","sid":1,"seq":1322,"msg":{"market_ticker":"KXBTCPERP1","price":"6.3268","delta":"-1.00","side":"bid","ts_ms":1781237160287}}

{"type":"orderbook_delta","sid":1,"seq":1323,"msg":{"market_ticker":"KXBTCPERP1","price":"6.3268","delta":"-1.00","side":"bid","ts_ms":1781237160287}}

{"type":"orderbook_delta","sid":1,"seq":1324,"msg":{"market_ticker":"KXBTCPERP1","price":"6.3267","delta":"-1.00","side":"bid","ts_ms":1781237160287}}

{"type":"orderbook_delta","sid":1,"seq":1325,"msg":{"market_ticker":"KXBTCPERP1","price":"6.3267","delta":"-1.00","side":"bid","ts_ms":1781237160287}}

{"type":"orderbook_delta","sid":1,"seq":1326,"msg":{"market_ticker":"KXBTCPERP1","price":"6.3267","delta":"-1.00","side":"bid","ts_ms":1781237160287}}

{"type":"orderbook_delta","sid":1,"seq":1327,"msg":{"market_ticker":"KXBTCPERP1","price":"6.3267","delta":"-1.00","side":"bid","ts_ms":1781237160287}}

{"type":"orderbook_delta","sid":1,"seq":1328,"msg":{"market_ticker":"KXBTCPERP1","price":"6.3267","delta":"-1.00","side":"bid","ts_ms":1781237160287}}

{"type":"orderbook_delta","sid":1,"seq":1329,"msg":{"market_ticker":"KXBTCPERP1","price":"6.3267","delta":"-1.00","side":"bid","ts_ms":1781237160287}}

{"type":"orderbook_delta","sid":1,"seq":1330,"msg":{"market_ticker":"KXBTCPERP1","price":"6.3266","delta":"-1.00","side":"bid","ts_ms":1781237160287}}

{"type":"orderbook_delta","sid":1,"seq":1331,"msg":{"market_ticker":"KXBTCPERP1","price":"6.3266","delta":"-1.00","side":"bid","ts_ms":1781237160287}}

{"type":"orderbook_delta","sid":1,"seq":1332,"msg":{"market_ticker":"KXBTCPERP1","price":"6.3266","delta":"-1.00","side":"bid","ts_ms":1781237160287}}

{"type":"orderbook_delta","sid":1,"seq":1333,"msg":{"market_ticker":"KXBTCPERP1","price":"6.3266","delta":"-1.00","side":"bid","ts_ms":1781237160287}}

{"type":"orderbook_delta","sid":1,"seq":1334,"msg":{"market_ticker":"KXBTCPERP1","price":"6.3266","delta":"-1.00","side":"bid","ts_ms":1781237160287}}

{"type":"orderbook_delta","sid":1,"seq":1335,"msg":{"market_ticker":"KXBTCPERP1","price":"6.3266","delta":"-1.00","side":"bid","ts_ms":1781237160287}}

{"type":"orderbook_delta","sid":1,"seq":1336,"msg":{"market_ticker":"KXBTCPERP1","price":"6.3266","delta":"-1.00","side":"bid","ts_ms":1781237160287}}

{"type":"orderbook_delta","sid":1,"seq":1337,"msg":{"market_ticker":"KXBTCPERP1","price":"6.3265","delta":"-1.00","side":"bid","ts_ms":1781237160287}}

{"type":"orderbook_delta","sid":1,"seq":1338,"msg":{"market_ticker":"KXBTCPERP1","price":"6.3265","delta":"-1.00","side":"bid","ts_ms":1781237160287}}

{"type":"orderbook_delta","sid":1,"seq":1339,"msg":{"market_ticker":"KXBTCPERP1","price":"6.3265","delta":"-1.00","side":"bid","ts_ms":1781237160287}}

{"type":"orderbook_delta","sid":1,"seq":1340,"msg":{"market_ticker":"KXBTCPERP1","price":"6.3264","delta":"-1.00","side":"bid","ts_ms":1781237160287}}

{"type":"orderbook_delta","sid":1,"seq":1341,"msg":{"market_ticker":"KXBTCPERP1","price":"6.3264","delta":"-1.00","side":"bid","ts_ms":1781237160287}}

{"type":"orderbook_delta","sid":1,"seq":1342,"msg":{"market_ticker":"KXBTCPERP1","price":"6.3263","delta":"-1.00","side":"bid","ts_ms":1781237160287}}

{"type":"orderbook_delta","sid":1,"seq":1343,"msg":{"market_ticker":"KXBTCPERP1","price":"6.3263","delta":"-1.00","side":"bid","ts_ms":1781237160287}}

{"type":"orderbook_delta","sid":1,"seq":1344,"msg":{"market_ticker":"KXBTCPERP1","price":"6.3263","delta":"-1.00","side":"bid","ts_ms":1781237160287}}

{"type":"orderbook_delta","sid":1,"seq":1345,"msg":{"market_ticker":"KXBTCPERP1","price":"6.3263","delta":"-1.00","side":"bid","ts_ms":1781237160287}}

{"type":"orderbook_delta","sid":1,"seq":1346,"msg":{"market_ticker":"KXBTCPERP1","price":"6.3263","delta":"-1.00","side":"bid","ts_ms":1781237160287}}

{"type":"orderbook_delta","sid":1,"seq":1347,"msg":{"market_ticker":"KXBTCPERP1","price":"6.3263","delta":"-1.00","side":"bid","ts_ms":1781237160287}}

{"type":"orderbook_delta","sid":1,"seq":1348,"msg":{"market_ticker":"KXBTCPERP1","price":"6.3262","delta":"-1.00","side":"bid","ts_ms":1781237160287}}

{"type":"orderbook_delta","sid":1,"seq":1349,"msg":{"market_ticker":"KXBTCPERP1","price":"6.3262","delta":"-1.00","side":"bid","ts_ms":1781237160287}}

{"type":"orderbook_delta","sid":1,"seq":1350,"msg":{"market_ticker":"KXBTCPERP1","price":"6.3262","delta":"-1.00","side":"bid","ts_ms":1781237160287}}

{"type":"orderbook_delta","sid":1,"seq":1351,"msg":{"market_ticker":"KXBTCPERP1","price":"6.3261","delta":"-1.00","side":"bid","ts_ms":1781237160287}}

{"type":"orderbook_delta","sid":1,"seq":1352,"msg":{"market_ticker":"KXBTCPERP1","price":"6.3261","delta":"-1.00","side":"bid","ts_ms":1781237160287}}

{"type":"orderbook_delta","sid":1,"seq":1353,"msg":{"market_ticker":"KXBTCPERP1","price":"6.3261","delta":"-1.00","side":"bid","ts_ms":1781237160287}}

{"type":"orderbook_delta","sid":1,"seq":1354,"msg":{"market_ticker":"KXBTCPERP1","price":"6.3261","delta":"-1.00","side":"bid","ts_ms":1781237160287}}

{"type":"orderbook_delta","sid":1,"seq":1355,"msg":{"market_ticker":"KXBTCPERP1","price":"6.3261","delta":"-1.00","side":"bid","ts_ms":1781237160287}}

{"type":"orderbook_delta","sid":1,"seq":1356,"msg":{"market_ticker":"KXBTCPERP1","price":"6.3260","delta":"-1.00","side":"bid","ts_ms":1781237160287}}

{"type":"orderbook_delta","sid":1,"seq":1357,"msg":{"market_ticker":"KXBTCPERP1","price":"6.3260","delta":"-1.00","side":"bid","ts_ms":1781237160287}}

{"type":"orderbook_delta","sid":1,"seq":1358,"msg":{"market_ticker":"KXBTCPERP1","price":"6.3260","delta":"-1.00","side":"bid","ts_ms":1781237160287}}

{"type":"orderbook_delta","sid":1,"seq":1359,"msg":{"market_ticker":"KXBTCPERP1","price":"6.3260","delta":"-1.00","side":"bid","ts_ms":1781237160287}}

{"type":"orderbook_delta","sid":1,"seq":1360,"msg":{"market_ticker":"KXBTCPERP1","price":"6.3259","delta":"-1.00","side":"bid","ts_ms":1781237160287}}

{"type":"orderbook_delta","sid":1,"seq":1361,"msg":{"market_ticker":"KXBTCPERP1","price":"6.3259","delta":"-1.00","side":"bid","ts_ms":1781237160287}}

{"type":"orderbook_delta","sid":1,"seq":1362,"msg":{"market_ticker":"KXBTCPERP1","price":"6.3259","delta":"-1.00","side":"bid","ts_ms":1781237160287}}

{"type":"orderbook_delta","sid":1,"seq":1363,"msg":{"market_ticker":"KXBTCPERP1","price":"6.3259","delta":"-1.00","side":"bid","ts_ms":1781237160287}}

{"type":"orderbook_delta","sid":1,"seq":1364,"msg":{"market_ticker":"KXBTCPERP1","price":"6.3259","delta":"-1.00","side":"bid","ts_ms":1781237160287}}

{"type":"orderbook_delta","sid":1,"seq":1365,"msg":{"market_ticker":"KXBTCPERP1","price":"6.3258","delta":"-1.00","side":"bid","ts_ms":1781237160287}}

{"type":"orderbook_delta","sid":1,"seq":1366,"msg":{"market_ticker":"KXBTCPERP1","price":"6.3257","delta":"-1.00","side":"bid","ts_ms":1781237160287}}

{"type":"orderbook_delta","sid":1,"seq":1367,"msg":{"market_ticker":"KXBTCPERP1","price":"6.3257","delta":"-1.00","side":"bid","ts_ms":1781237160287}}

{"type":"orderbook_delta","sid":1,"seq":1368,"msg":{"market_ticker":"KXBTCPERP1","price":"6.3257","delta":"-1.00","side":"bid","ts_ms":1781237160287}}

{"type":"orderbook_delta","sid":1,"seq":1369,"msg":{"market_ticker":"KXBTCPERP1","price":"6.3257","delta":"-1.00","side":"bid","ts_ms":1781237160287}}

{"type":"orderbook_delta","sid":1,"seq":1370,"msg":{"market_ticker":"KXBTCPERP1","price":"6.3257","delta":"-1.00","side":"bid","ts_ms":1781237160287}}

{"type":"orderbook_delta","sid":1,"seq":1371,"msg":{"market_ticker":"KXBTCPERP1","price":"6.3256","delta":"-1.00","side":"bid","ts_ms":1781237160287}}

{"type":"orderbook_delta","sid":1,"seq":1372,"msg":{"market_ticker":"KXBTCPERP1","price":"6.3256","delta":"-1.00","side":"bid","ts_ms":1781237160287}}

{"type":"orderbook_delta","sid":1,"seq":1373,"msg":{"market_ticker":"KXBTCPERP1","price":"6.3256","delta":"-1.00","side":"bid","ts_ms":1781237160287}}

{"type":"orderbook_delta","sid":1,"seq":1374,"msg":{"market_ticker":"KXBTCPERP1","price":"6.3256","delta":"-1.00","side":"bid","ts_ms":1781237160287}}

{"type":"orderbook_delta","sid":1,"seq":1375,"msg":{"market_ticker":"KXBTCPERP1","price":"6.3255","delta":"-1.00","side":"bid","ts_ms":1781237160287}}

{"type":"orderbook_delta","sid":1,"seq":1376,"msg":{"market_ticker":"KXBTCPERP1","price":"6.3255","delta":"-1.00","side":"bid","ts_ms":1781237160287}}

{"type":"orderbook_delta","sid":1,"seq":1377,"msg":{"market_ticker":"KXBTCPERP1","price":"6.3254","delta":"-1.00","side":"bid","ts_ms":1781237160287}}

{"type":"orderbook_delta","sid":1,"seq":1378,"msg":{"market_ticker":"KXBTCPERP1","price":"6.3254","delta":"-1.00","side":"bid","ts_ms":1781237160287}}

{"type":"orderbook_delta","sid":1,"seq":1379,"msg":{"market_ticker":"KXBTCPERP1","price":"6.3254","delta":"-1.00","side":"bid","ts_ms":1781237160287}}

{"type":"orderbook_delta","sid":1,"seq":1380,"msg":{"market_ticker":"KXBTCPERP1","price":"6.3253","delta":"-1.00","side":"bid","ts_ms":1781237160287}}

{"type":"orderbook_delta","sid":1,"seq":1381,"msg":{"market_ticker":"KXBTCPERP1","price":"6.3253","delta":"-1.00","side":"bid","ts_ms":1781237160287}}

{"type":"orderbook_delta","sid":1,"seq":1382,"msg":{"market_ticker":"KXBTCPERP1","price":"6.3252","delta":"-1.00","side":"bid","ts_ms":1781237160287}}

{"type":"orderbook_delta","sid":1,"seq":1383,"msg":{"market_ticker":"KXBTCPERP1","price":"6.3252","delta":"-1.00","side":"bid","ts_ms":1781237160287}}

{"type":"orderbook_delta","sid":1,"seq":1384,"msg":{"market_ticker":"KXBTCPERP1","price":"6.3252","delta":"-1.00","side":"bid","ts_ms":1781237160287}}

{"type":"orderbook_delta","sid":1,"seq":1385,"msg":{"market_ticker":"KXBTCPERP1","price":"6.3252","delta":"-1.00","side":"bid","ts_ms":1781237160287}}

{"type":"orderbook_delta","sid":1,"seq":1386,"msg":{"market_ticker":"KXBTCPERP1","price":"6.3252","delta":"-1.00","side":"bid","ts_ms":1781237160287}}

{"type":"orderbook_delta","sid":1,"seq":1387,"msg":{"market_ticker":"KXBTCPERP1","price":"6.3251","delta":"-1.00","side":"bid","ts_ms":1781237160287}}

{"type":"orderbook_delta","sid":1,"seq":1388,"msg":{"market_ticker":"KXBTCPERP1","price":"6.3251","delta":"-1.00","side":"bid","ts_ms":1781237160287}}

{"type":"orderbook_delta","sid":1,"seq":1389,"msg":{"market_ticker":"KXBTCPERP1","price":"6.3250","delta":"-1.00","side":"bid","ts_ms":1781237160287}}

{"type":"orderbook_delta","sid":1,"seq":1390,"msg":{"market_ticker":"KXBTCPERP1","price":"6.3249","delta":"-1.00","side":"bid","ts_ms":1781237160287}}

{"type":"orderbook_delta","sid":1,"seq":1391,"msg":{"market_ticker":"KXBTCPERP1","price":"6.3249","delta":"-1.00","side":"bid","ts_ms":1781237160287}}

{"type":"orderbook_delta","sid":1,"seq":1392,"msg":{"market_ticker":"KXBTCPERP1","price":"6.3249","delta":"-1.00","side":"bid","ts_ms":1781237160287}}

{"type":"orderbook_delta","sid":1,"seq":1393,"msg":{"market_ticker":"KXBTCPERP1","price":"6.3248","delta":"-1.00","side":"bid","ts_ms":1781237160287}}

{"type":"orderbook_delta","sid":1,"seq":1394,"msg":{"market_ticker":"KXBTCPERP1","price":"6.3248","delta":"-1.00","side":"bid","ts_ms":1781237160287}}

{"type":"orderbook_delta","sid":1,"seq":1395,"msg":{"market_ticker":"KXBTCPERP1","price":"6.3248","delta":"-1.00","side":"bid","ts_ms":1781237160287}}

{"type":"orderbook_delta","sid":1,"seq":1396,"msg":{"market_ticker":"KXBTCPERP1","price":"6.3246","delta":"-1.00","side":"bid","ts_ms":1781237160287}}

{"type":"orderbook_delta","sid":1,"seq":1397,"msg":{"market_ticker":"KXBTCPERP1","price":"6.3246","delta":"-1.00","side":"bid","ts_ms":1781237160287}}

{"type":"orderbook_delta","sid":1,"seq":1398,"msg":{"market_ticker":"KXBTCPERP1","price":"6.3246","delta":"-1.00","side":"bid","ts_ms":1781237160287}}

{"type":"orderbook_delta","sid":1,"seq":1399,"msg":{"market_ticker":"KXBTCPERP1","price":"6.3245","delta":"-1.00","side":"bid","ts_ms":1781237160287}}

{"type":"orderbook_delta","sid":1,"seq":1400,"msg":{"market_ticker":"KXBTCPERP1","price":"6.3245","delta":"-1.00","side":"bid","ts_ms":1781237160287}}

{"type":"orderbook_delta","sid":1,"seq":1401,"msg":{"market_ticker":"KXBTCPERP1","price":"6.3244","delta":"-1.00","side":"bid","ts_ms":1781237160287}}

{"type":"orderbook_delta","sid":1,"seq":1402,"msg":{"market_ticker":"KXBTCPERP1","price":"6.3244","delta":"-1.00","side":"bid","ts_ms":1781237160287}}

{"type":"orderbook_delta","sid":1,"seq":1403,"msg":{"market_ticker":"KXBTCPERP1","price":"6.3244","delta":"-1.00","side":"bid","ts_ms":1781237160287}}

{"type":"orderbook_delta","sid":1,"seq":1404,"msg":{"market_ticker":"KXBTCPERP1","price":"6.3243","delta":"-1.00","side":"bid","ts_ms":1781237160287}}

{"type":"orderbook_delta","sid":1,"seq":1405,"msg":{"market_ticker":"KXBTCPERP1","price":"6.3243","delta":"-1.00","side":"bid","ts_ms":1781237160287}}

{"type":"orderbook_delta","sid":1,"seq":1406,"msg":{"market_ticker":"KXBTCPERP1","price":"6.3243","delta":"-1.00","side":"bid","ts_ms":1781237160287}}

{"type":"orderbook_delta","sid":1,"seq":1407,"msg":{"market_ticker":"KXBTCPERP1","price":"6.3242","delta":"-1.00","side":"bid","ts_ms":1781237160287}}

{"type":"orderbook_delta","sid":1,"seq":1408,"msg":{"market_ticker":"KXBTCPERP1","price":"6.3242","delta":"-1.00","side":"bid","ts_ms":1781237160287}}

{"type":"orderbook_delta","sid":1,"seq":1409,"msg":{"market_ticker":"KXBTCPERP1","price":"6.3242","delta":"-1.00","side":"bid","ts_ms":1781237160287}}

{"type":"orderbook_delta","sid":1,"seq":1410,"msg":{"market_ticker":"KXBTCPERP1","price":"6.3241","delta":"-1.00","side":"bid","ts_ms":1781237160287}}

{"type":"orderbook_delta","sid":1,"seq":1411,"msg":{"market_ticker":"KXBTCPERP1","price":"6.3240","delta":"-1.00","side":"bid","ts_ms":1781237160287}}

{"type":"orderbook_delta","sid":1,"seq":1412,"msg":{"market_ticker":"KXBTCPERP1","price":"6.3240","delta":"-1.00","side":"bid","ts_ms":1781237160287}}

{"type":"orderbook_delta","sid":1,"seq":1413,"msg":{"market_ticker":"KXBTCPERP1","price":"6.3239","delta":"-1.00","side":"bid","ts_ms":1781237160287}}

{"type":"orderbook_delta","sid":1,"seq":1414,"msg":{"market_ticker":"KXBTCPERP1","price":"6.3239","delta":"-1.00","side":"bid","ts_ms":1781237160287}}

{"type":"orderbook_delta","sid":1,"seq":1415,"msg":{"market_ticker":"KXBTCPERP1","price":"6.3239","delta":"-1.00","side":"bid","ts_ms":1781237160287}}

{"type":"orderbook_delta","sid":1,"seq":1416,"msg":{"market_ticker":"KXBTCPERP1","price":"6.3238","delta":"-1.00","side":"bid","ts_ms":1781237160287}}

{"type":"orderbook_delta","sid":1,"seq":1417,"msg":{"market_ticker":"KXBTCPERP1","price":"6.3237","delta":"-1.00","side":"bid","ts_ms":1781237160287}}

{"type":"orderbook_delta","sid":1,"seq":1418,"msg":{"market_ticker":"KXBTCPERP1","price":"6.3237","delta":"-1.00","side":"bid","ts_ms":1781237160287}}

{"type":"orderbook_delta","sid":1,"seq":1419,"msg":{"market_ticker":"KXBTCPERP1","price":"6.3236","delta":"-1.00","side":"bid","ts_ms":1781237160287}}

{"type":"orderbook_delta","sid":1,"seq":1420,"msg":{"market_ticker":"KXBTCPERP1","price":"6.3236","delta":"-1.00","side":"bid","ts_ms":1781237160287}}

{"type":"orderbook_delta","sid":1,"seq":1421,"msg":{"market_ticker":"KXBTCPERP1","price":"6.3236","delta":"-1.00","side":"bid","ts_ms":1781237160287}}

{"type":"orderbook_delta","sid":1,"seq":1422,"msg":{"market_ticker":"KXBTCPERP1","price":"6.3236","delta":"-1.00","side":"bid","ts_ms":1781237160287}}

{"type":"orderbook_delta","sid":1,"seq":1423,"msg":{"market_ticker":"KXBTCPERP1","price":"6.3236","delta":"-1.00","side":"bid","ts_ms":1781237160287}}

{"type":"orderbook_delta","sid":1,"seq":1424,"msg":{"market_ticker":"KXBTCPERP1","price":"6.3235","delta":"-1.00","side":"bid","ts_ms":1781237160287}}

{"type":"orderbook_delta","sid":1,"seq":1425,"msg":{"market_ticker":"KXBTCPERP1","price":"6.3235","delta":"-1.00","side":"bid","ts_ms":1781237160287}}

{"type":"orderbook_delta","sid":1,"seq":1426,"msg":{"market_ticker":"KXBTCPERP1","price":"6.3235","delta":"-1.00","side":"bid","ts_ms":1781237160287}}

{"type":"orderbook_delta","sid":1,"seq":1427,"msg":{"market_ticker":"KXBTCPERP1","price":"6.3235","delta":"-1.00","side":"bid","ts_ms":1781237160287}}

{"type":"orderbook_delta","sid":1,"seq":1428,"msg":{"market_ticker":"KXBTCPERP1","price":"6.3235","delta":"-1.00","side":"bid","ts_ms":1781237160287}}

{"type":"orderbook_delta","sid":1,"seq":1429,"msg":{"market_ticker":"KXBTCPERP1","price":"6.3234","delta":"-1.00","side":"bid","ts_ms":1781237160287}}

{"type":"orderbook_delta","sid":1,"seq":1430,"msg":{"market_ticker":"KXBTCPERP1","price":"6.3234","delta":"-1.00","side":"bid","ts_ms":1781237160287}}

{"type":"orderbook_delta","sid":1,"seq":1431,"msg":{"market_ticker":"KXBTCPERP1","price":"6.3233","delta":"-1.00","side":"bid","ts_ms":1781237160287}}

{"type":"orderbook_delta","sid":1,"seq":1432,"msg":{"market_ticker":"KXBTCPERP1","price":"6.3233","delta":"-1.00","side":"bid","ts_ms":1781237160287}}

{"type":"orderbook_delta","sid":1,"seq":1433,"msg":{"market_ticker":"KXBTCPERP1","price":"6.3232","delta":"-1.00","side":"bid","ts_ms":1781237160287}}

{"type":"orderbook_delta","sid":1,"seq":1434,"msg":{"market_ticker":"KXBTCPERP1","price":"6.3232","delta":"-1.00","side":"bid","ts_ms":1781237160287}}

{"type":"orderbook_delta","sid":1,"seq":1435,"msg":{"market_ticker":"KXBTCPERP1","price":"6.3232","delta":"-1.00","side":"bid","ts_ms":1781237160287}}

{"type":"orderbook_delta","sid":1,"seq":1436,"msg":{"market_ticker":"KXBTCPERP1","price":"6.3231","delta":"-1.00","side":"bid","ts_ms":1781237160287}}

{"type":"orderbook_delta","sid":1,"seq":1437,"msg":{"market_ticker":"KXBTCPERP1","price":"6.3231","delta":"-1.00","side":"bid","ts_ms":1781237160287}}

{"type":"orderbook_delta","sid":1,"seq":1438,"msg":{"market_ticker":"KXBTCPERP1","price":"6.3230","delta":"-1.00","side":"bid","ts_ms":1781237160287}}

{"type":"orderbook_delta","sid":1,"seq":1439,"msg":{"market_ticker":"KXBTCPERP1","price":"6.3230","delta":"-1.00","side":"bid","ts_ms":1781237160287}}

{"type":"orderbook_delta","sid":1,"seq":1440,"msg":{"market_ticker":"KXBTCPERP1","price":"6.3230","delta":"-1.00","side":"bid","ts_ms":1781237160287}}

{"type":"orderbook_delta","sid":1,"seq":1441,"msg":{"market_ticker":"KXBTCPERP1","price":"6.3229","delta":"-1.00","side":"bid","ts_ms":1781237160287}}

{"type":"orderbook_delta","sid":1,"seq":1442,"msg":{"market_ticker":"KXBTCPERP1","price":"6.3229","delta":"-1.00","side":"bid","ts_ms":1781237160287}}

{"type":"orderbook_delta","sid":1,"seq":1443,"msg":{"market_ticker":"KXBTCPERP1","price":"6.3229","delta":"-1.00","side":"bid","ts_ms":1781237160287}}

{"type":"orderbook_delta","sid":1,"seq":1444,"msg":{"market_ticker":"KXBTCPERP1","price":"6.3229","delta":"-1.00","side":"bid","ts_ms":1781237160287}}

{"type":"orderbook_delta","sid":1,"seq":1445,"msg":{"market_ticker":"KXBTCPERP1","price":"6.3229","delta":"-1.00","side":"bid","ts_ms":1781237160287}}

{"type":"orderbook_delta","sid":1,"seq":1446,"msg":{"market_ticker":"KXBTCPERP1","price":"6.3228","delta":"-1.00","side":"bid","ts_ms":1781237160287}}

{"type":"orderbook_delta","sid":1,"seq":1447,"msg":{"market_ticker":"KXBTCPERP1","price":"6.3228","delta":"-1.00","side":"bid","ts_ms":1781237160287}}

{"type":"orderbook_delta","sid":1,"seq":1448,"msg":{"market_ticker":"KXBTCPERP1","price":"6.3228","delta":"-1.00","side":"bid","ts_ms":1781237160287}}

{"type":"orderbook_delta","sid":1,"seq":1449,"msg":{"market_ticker":"KXBTCPERP1","price":"6.3227","delta":"-1.00","side":"bid","ts_ms":1781237160287}}

{"type":"orderbook_delta","sid":1,"seq":1450,"msg":{"market_ticker":"KXBTCPERP1","price":"6.3227","delta":"-1.00","side":"bid","ts_ms":1781237160287}}

{"type":"orderbook_delta","sid":1,"seq":1451,"msg":{"market_ticker":"KXBTCPERP1","price":"6.3227","delta":"-1.00","side":"bid","ts_ms":1781237160287}}

{"type":"orderbook_delta","sid":1,"seq":1452,"msg":{"market_ticker":"KXBTCPERP1","price":"6.3227","delta":"-1.00","side":"bid","ts_ms":1781237160287}}

{"type":"orderbook_delta","sid":1,"seq":1453,"msg":{"market_ticker":"KXBTCPERP1","price":"6.3227","delta":"-1.00","side":"bid","ts_ms":1781237160287}}

{"type":"orderbook_delta","sid":1,"seq":1454,"msg":{"market_ticker":"KXBTCPERP1","price":"6.3227","delta":"-1.00","side":"bid","ts_ms":1781237160287}}

{"type":"orderbook_delta","sid":1,"seq":1455,"msg":{"market_ticker":"KXBTCPERP1","price":"6.3227","delta":"-1.00","side":"bid","ts_ms":1781237160287}}

{"type":"orderbook_delta","sid":1,"seq":1456,"msg":{"market_ticker":"KXBTCPERP1","price":"6.3227","delta":"-1.00","side":"bid","ts_ms":1781237160287}}

{"type":"orderbook_delta","sid":1,"seq":1457,"msg":{"market_ticker":"KXBTCPERP1","price":"6.3226","delta":"-1.00","side":"bid","ts_ms":1781237160287}}

{"type":"orderbook_delta","sid":1,"seq":1458,"msg":{"market_ticker":"KXBTCPERP1","price":"6.3226","delta":"-1.00","side":"bid","ts_ms":1781237160287}}

{"type":"orderbook_delta","sid":1,"seq":1459,"msg":{"market_ticker":"KXBTCPERP1","price":"6.3226","delta":"-1.00","side":"bid","ts_ms":1781237160287}}

{"type":"orderbook_delta","sid":1,"seq":1460,"msg":{"market_ticker":"KXBTCPERP1","price":"6.3226","delta":"-1.00","side":"bid","ts_ms":1781237160287}}

{"type":"orderbook_delta","sid":1,"seq":1461,"msg":{"market_ticker":"KXBTCPERP1","price":"6.3225","delta":"-1.00","side":"bid","ts_ms":1781237160287}}

{"type":"orderbook_delta","sid":1,"seq":1462,"msg":{"market_ticker":"KXBTCPERP1","price":"6.3225","delta":"-1.00","side":"bid","ts_ms":1781237160287}}

{"type":"orderbook_delta","sid":1,"seq":1463,"msg":{"market_ticker":"KXBTCPERP1","price":"6.3225","delta":"-1.00","side":"bid","ts_ms":1781237160287}}

{"type":"orderbook_delta","sid":1,"seq":1464,"msg":{"market_ticker":"KXBTCPERP1","price":"6.3225","delta":"-1.00","side":"bid","ts_ms":1781237160287}}

{"type":"orderbook_delta","sid":1,"seq":1465,"msg":{"market_ticker":"KXBTCPERP1","price":"6.3225","delta":"-1.00","side":"bid","ts_ms":1781237160287}}

{"type":"orderbook_delta","sid":1,"seq":1466,"msg":{"market_ticker":"KXBTCPERP1","price":"6.3225","delta":"-1.00","side":"bid","ts_ms":1781237160287}}

{"type":"orderbook_delta","sid":1,"seq":1467,"msg":{"market_ticker":"KXBTCPERP1","price":"6.3224","delta":"-1.00","side":"bid","ts_ms":1781237160287}}

{"type":"orderbook_delta","sid":1,"seq":1468,"msg":{"market_ticker":"KXBTCPERP1","price":"6.3223","delta":"-1.00","side":"bid","ts_ms":1781237160287}}

{"type":"orderbook_delta","sid":1,"seq":1469,"msg":{"market_ticker":"KXBTCPERP1","price":"6.3223","delta":"-1.00","side":"bid","ts_ms":1781237160287}}

{"type":"orderbook_delta","sid":1,"seq":1470,"msg":{"market_ticker":"KXBTCPERP1","price":"6.3223","delta":"-1.00","side":"bid","ts_ms":1781237160287}}

{"type":"orderbook_delta","sid":1,"seq":1471,"msg":{"market_ticker":"KXBTCPERP1","price":"6.3223","delta":"-1.00","side":"bid","ts_ms":1781237160287}}

{"type":"orderbook_delta","sid":1,"seq":1472,"msg":{"market_ticker":"KXBTCPERP1","price":"6.3222","delta":"-1.00","side":"bid","ts_ms":1781237160287}}

{"type":"orderbook_delta","sid":1,"seq":1473,"msg":{"market_ticker":"KXBTCPERP1","price":"6.3222","delta":"-1.00","side":"bid","ts_ms":1781237160287}}

{"type":"orderbook_delta","sid":1,"seq":1474,"msg":{"market_ticker":"KXBTCPERP1","price":"6.3221","delta":"-1.00","side":"bid","ts_ms":1781237160287}}

{"type":"orderbook_delta","sid":1,"seq":1475,"msg":{"market_ticker":"KXBTCPERP1","price":"6.3221","delta":"-1.00","side":"bid","ts_ms":1781237160287}}

{"type":"orderbook_delta","sid":1,"seq":1476,"msg":{"market_ticker":"KXBTCPERP1","price":"6.3221","delta":"-1.00","side":"bid","ts_ms":1781237160287}}

{"type":"orderbook_delta","sid":1,"seq":1477,"msg":{"market_ticker":"KXBTCPERP1","price":"6.3220","delta":"-1.00","side":"bid","ts_ms":1781237160287}}

{"type":"orderbook_delta","sid":1,"seq":1478,"msg":{"market_ticker":"KXBTCPERP1","price":"6.3220","delta":"-1.00","side":"bid","ts_ms":1781237160287}}

{"type":"orderbook_delta","sid":1,"seq":1479,"msg":{"market_ticker":"KXBTCPERP1","price":"6.3220","delta":"-1.00","side":"bid","ts_ms":1781237160287}}

{"type":"orderbook_delta","sid":1,"seq":1480,"msg":{"market_ticker":"KXBTCPERP1","price":"6.3220","delta":"-1.00","side":"bid","ts_ms":1781237160287}}

{"type":"orderbook_delta","sid":1,"seq":1481,"msg":{"market_ticker":"KXBTCPERP1","price":"6.3220","delta":"-1.00","side":"bid","ts_ms":1781237160287}}

{"type":"orderbook_delta","sid":1,"seq":1482,"msg":{"market_ticker":"KXBTCPERP1","price":"6.3219","delta":"-1.00","side":"bid","ts_ms":1781237160287}}

{"type":"orderbook_delta","sid":1,"seq":1483,"msg":{"market_ticker":"KXBTCPERP1","price":"6.3219","delta":"-1.00","side":"bid","ts_ms":1781237160287}}

{"type":"orderbook_delta","sid":1,"seq":1484,"msg":{"market_ticker":"KXBTCPERP1","price":"6.3218","delta":"-1.00","side":"bid","ts_ms":1781237160287}}

{"type":"orderbook_delta","sid":1,"seq":1485,"msg":{"market_ticker":"KXBTCPERP1","price":"6.3217","delta":"-1.00","side":"bid","ts_ms":1781237160287}}

{"type":"orderbook_delta","sid":1,"seq":1486,"msg":{"market_ticker":"KXBTCPERP1","price":"6.3217","delta":"-1.00","side":"bid","ts_ms":1781237160287}}

{"type":"orderbook_delta","sid":1,"seq":1487,"msg":{"market_ticker":"KXBTCPERP1","price":"6.3217","delta":"-1.00","side":"bid","ts_ms":1781237160287}}

{"type":"orderbook_delta","sid":1,"seq":1488,"msg":{"market_ticker":"KXBTCPERP1","price":"6.3216","delta":"-1.00","side":"bid","ts_ms":1781237160287}}

{"type":"orderbook_delta","sid":1,"seq":1489,"msg":{"market_ticker":"KXBTCPERP1","price":"6.3216","delta":"-1.00","side":"bid","ts_ms":1781237160287}}

{"type":"orderbook_delta","sid":1,"seq":1490,"msg":{"market_ticker":"KXBTCPERP1","price":"6.3216","delta":"-1.00","side":"bid","ts_ms":1781237160287}}

{"type":"orderbook_delta","sid":1,"seq":1491,"msg":{"market_ticker":"KXBTCPERP1","price":"6.3215","delta":"-1.00","side":"bid","ts_ms":1781237160287}}

{"type":"orderbook_delta","sid":1,"seq":1492,"msg":{"market_ticker":"KXBTCPERP1","price":"6.3215","delta":"-1.00","side":"bid","ts_ms":1781237160287}}

{"type":"orderbook_delta","sid":1,"seq":1493,"msg":{"market_ticker":"KXBTCPERP1","price":"6.3215","delta":"-1.00","side":"bid","ts_ms":1781237160287}}

{"type":"orderbook_delta","sid":1,"seq":1494,"msg":{"market_ticker":"KXBTCPERP1","price":"6.3215","delta":"-1.00","side":"bid","ts_ms":1781237160287}}

{"type":"orderbook_delta","sid":1,"seq":1495,"msg":{"market_ticker":"KXBTCPERP1","price":"6.3214","delta":"-1.00","side":"bid","ts_ms":1781237160287}}

{"type":"orderbook_delta","sid":1,"seq":1496,"msg":{"market_ticker":"KXBTCPERP1","price":"6.3214","delta":"-1.00","side":"bid","ts_ms":1781237160287}}

{"type":"orderbook_delta","sid":1,"seq":1497,"msg":{"market_ticker":"KXBTCPERP1","price":"6.3214","delta":"-1.00","side":"bid","ts_ms":1781237160287}}

{"type":"orderbook_delta","sid":1,"seq":1498,"msg":{"market_ticker":"KXBTCPERP1","price":"6.3214","delta":"-1.00","side":"bid","ts_ms":1781237160287}}

{"type":"orderbook_delta","sid":1,"seq":1499,"msg":{"market_ticker":"KXBTCPERP1","price":"6.3213","delta":"-1.00","side":"bid","ts_ms":1781237160287}}

{"type":"orderbook_delta","sid":1,"seq":1500,"msg":{"market_ticker":"KXBTCPERP1","price":"6.3213","delta":"-1.00","side":"bid","ts_ms":1781237160287}}

{"type":"orderbook_delta","sid":1,"seq":1501,"msg":{"market_ticker":"KXBTCPERP1","price":"6.3213","delta":"-1.00","side":"bid","ts_ms":1781237160287}}

{"type":"orderbook_delta","sid":1,"seq":1502,"msg":{"market_ticker":"KXBTCPERP1","price":"6.3213","delta":"-1.00","side":"bid","ts_ms":1781237160287}}

{"type":"trade","sid":2,"seq":536,"msg":{"trade_id":"0d9e3be4-7007-6d49-968e-821f5d3f2d61","market_ticker":"KXBTCPERP1","price":"6.3473","count":"1.00","taker_side":"ask","ts_ms":1781237160287}}

{"type":"trade","sid":2,"seq":537,"msg":{"trade_id":"6f4dee52-cce2-6bd9-968c-820bb76712b6","market_ticker":"KXBTCPERP1","price":"6.3473","count":"1.00","taker_side":"ask","ts_ms":1781237160287}}

{"type":"trade","sid":2,"seq":538,"msg":{"trade_id":"b9cc6eb1-3cfa-6741-b30d-d8b445eabc9d","market_ticker":"KXBTCPERP1","price":"6.3472","count":"1.00","taker_side":"ask","ts_ms":1781237160287}}

{"type":"trade","sid":2,"seq":539,"msg":{"trade_id":"b83ed85f-46e6-6cd2-accc-c6ceddb71dad","market_ticker":"KXBTCPERP1","price":"6.3472","count":"1.00","taker_side":"ask","ts_ms":1781237160287}}

{"type":"trade","sid":2,"seq":540,"msg":{"trade_id":"59464771-4e26-6d47-8036-643fa0822de3","market_ticker":"KXBTCPERP1","price":"6.3472","count":"1.00","taker_side":"ask","ts_ms":1781237160287}}

{"type":"trade","sid":2,"seq":541,"msg":{"trade_id":"bf61f6a7-e332-6c54-a0d9-93ddb85472ad","market_ticker":"KXBTCPERP1","price":"6.3471","count":"1.00","taker_side":"ask","ts_ms":1781237160287}}

{"type":"trade","sid":2,"seq":542,"msg":{"trade_id":"751c07b3-5b3f-6270-a7bc-0d1f993f4068","market_ticker":"KXBTCPERP1","price":"6.3471","count":"1.00","taker_side":"ask","ts_ms":1781237160287}}

{"type":"trade","sid":2,"seq":543,"msg":{"trade_id":"9f1d07c9-c5a3-64f9-a4a1-945cf864da50","market_ticker":"KXBTCPERP1","price":"6.3471","count":"1.00","taker_side":"ask","ts_ms":1781237160287}}

