{"type":"orderbook_delta","sid":1,"seq":1804,"msg":{"market_ticker":"KXBTCPERP1","price":"6.3116","delta":"-1.00","side":"bid","ts_ms":1781237160302}}

{"type":"orderbook_delta","sid":1,"seq":1805,"msg":{"market_ticker":"KXBTCPERP1","price":"6.3116","delta":"-1.00","side":"bid","ts_ms":1781237160302}}

{"type":"orderbook_delta","sid":1,"seq":1806,"msg":{"market_ticker":"KXBTCPERP1","price":"6.3116","delta":"-1.00","side":"bid","ts_ms":1781237160302}}

{"type":"orderbook_delta","sid":1,"seq":1807,"msg":{"market_ticker":"KXBTCPERP1","price":"6.3116","delta":"-1.00","side":"bid","ts_ms":1781237160302}}

{"type":"orderbook_delta","sid":1,"seq":1808,"msg":{"market_ticker":"KXBTCPERP1","price":"6.3115","delta":"-1.00","side":"bid","ts_ms":1781237160302}}

{"type":"orderbook_delta","sid":1,"seq":1809,"msg":{"market_ticker":"KXBTCPERP1","price":"6.3115","delta":"-1.00","side":"bid","ts_ms":1781237160302}}

{"type":"orderbook_delta","sid":1,"seq":1810,"msg":{"market_ticker":"KXBTCPERP1","price":"6.3114","delta":"-1.00","side":"bid","ts_ms":1781237160302}}

{"type":"orderbook_delta","sid":1,"seq":1811,"msg":{"market_ticker":"KXBTCPERP1","price":"6.3114","delta":"-1.00","side":"bid","ts_ms":1781237160302}}

{"type":"orderbook_delta","sid":1,"seq":1812,"msg":{"market_ticker":"KXBTCPERP1","price":"6.3114","delta":"-1.00","side":"bid","ts_ms":1781237160302}}

{"type":"orderbook_delta","sid":1,"seq":1813,"msg":{"market_ticker":"KXBTCPERP1","price":"6.3113","delta":"-1.00","side":"bid","ts_ms":1781237160302}}

{"type":"orderbook_delta","sid":1,"seq":1814,"msg":{"market_ticker":"KXBTCPERP1","price":"6.3113","delta":"-1.00","side":"bid","ts_ms":1781237160302}}

{"type":"orderbook_delta","sid":1,"seq":1815,"msg":{"market_ticker":"KXBTCPERP1","price":"6.3113","delta":"-1.00","side":"bid","ts_ms":1781237160302}}

{"type":"orderbook_delta","sid":1,"seq":1816,"msg":{"market_ticker":"KXBTCPERP1","price":"6.3113","delta":"-1.00","side":"bid","ts_ms":1781237160302}}

{"type":"orderbook_delta","sid":1,"seq":1817,"msg":{"market_ticker":"KXBTCPERP1","price":"6.3113","delta":"-1.00","side":"bid","ts_ms":1781237160302}}

{"type":"orderbook_delta","sid":1,"seq":1818,"msg":{"market_ticker":"KXBTCPERP1","price":"6.3112","delta":"-1.00","side":"bid","ts_ms":1781237160302}}

{"type":"orderbook_delta","sid":1,"seq":1819,"msg":{"market_ticker":"KXBTCPERP1","price":"6.3112","delta":"-1.00","side":"bid","ts_ms":1781237160302}}

{"type":"orderbook_delta","sid":1,"seq":1820,"msg":{"market_ticker":"KXBTCPERP1","price":"6.3112","delta":"-1.00","side":"bid","ts_ms":1781237160302}}

{"type":"orderbook_delta","sid":1,"seq":1821,"msg":{"market_ticker":"KXBTCPERP1","price":"6.3112","delta":"-1.00","side":"bid","ts_ms":1781237160302}}

{"type":"orderbook_delta","sid":1,"seq":1822,"msg":{"market_ticker":"KXBTCPERP1","price":"6.3111","delta":"-1.00","side":"bid","ts_ms":1781237160302}}

{"type":"orderbook_delta","sid":1,"seq":1823,"msg":{"market_ticker":"KXBTCPERP1","price":"6.3111","delta":"-1.00","side":"bid","ts_ms":1781237160302}}

{"type":"orderbook_delta","sid":1,"seq":1824,"msg":{"market_ticker":"KXBTCPERP1","price":"6.3111","delta":"-1.00","side":"bid","ts_ms":1781237160302}}

{"type":"orderbook_delta","sid":1,"seq":1825,"msg":{"market_ticker":"KXBTCPERP1","price":"6.3110","delta":"-1.00","side":"bid","ts_ms":1781237160302}}

{"type":"orderbook_delta","sid":1,"seq":1826,"msg":{"market_ticker":"KXBTCPERP1","price":"6.3109","delta":"-1.00","side":"bid","ts_ms":1781237160302}}

{"type":"orderbook_delta","sid":1,"seq":1827,"msg":{"market_ticker":"KXBTCPERP1","price":"6.3109","delta":"-1.00","side":"bid","ts_ms":1781237160302}}

{"type":"orderbook_delta","sid":1,"seq":1828,"msg":{"market_ticker":"KXBTCPERP1","price":"6.3108","delta":"-1.00","side":"bid","ts_ms":1781237160302}}

{"type":"orderbook_delta","sid":1,"seq":1829,"msg":{"market_ticker":"KXBTCPERP1","price":"6.3107","delta":"-1.00","side":"bid","ts_ms":1781237160302}}

{"type":"orderbook_delta","sid":1,"seq":1830,"msg":{"market_ticker":"KXBTCPERP1","price":"6.3106","delta":"-1.00","side":"bid","ts_ms":1781237160302}}

{"type":"orderbook_delta","sid":1,"seq":1831,"msg":{"market_ticker":"KXBTCPERP1","price":"6.3106","delta":"-1.00","side":"bid","ts_ms":1781237160302}}

{"type":"orderbook_delta","sid":1,"seq":1832,"msg":{"market_ticker":"KXBTCPERP1","price":"6.3106","delta":"-1.00","side":"bid","ts_ms":1781237160302}}

{"type":"orderbook_delta","sid":1,"seq":1833,"msg":{"market_ticker":"KXBTCPERP1","price":"6.3106","delta":"-1.00","side":"bid","ts_ms":1781237160302}}

{"type":"orderbook_delta","sid":1,"seq":1834,"msg":{"market_ticker":"KXBTCPERP1","price":"6.3106","delta":"-1.00","side":"bid","ts_ms":1781237160302}}

{"type":"orderbook_delta","sid":1,"seq":1835,"msg":{"market_ticker":"KXBTCPERP1","price":"6.3105","delta":"-1.00","side":"bid","ts_ms":1781237160302}}

{"type":"orderbook_delta","sid":1,"seq":1836,"msg":{"market_ticker":"KXBTCPERP1","price":"6.3105","delta":"-1.00","side":"bid","ts_ms":1781237160302}}

{"type":"orderbook_delta","sid":1,"seq":1837,"msg":{"market_ticker":"KXBTCPERP1","price":"6.3105","delta":"-1.00","side":"bid","ts_ms":1781237160302}}

{"type":"orderbook_delta","sid":1,"seq":1838,"msg":{"market_ticker":"KXBTCPERP1","price":"6.3105","delta":"-1.00","side":"bid","ts_ms":1781237160302}}

{"type":"orderbook_delta","sid":1,"seq":1839,"msg":{"market_ticker":"KXBTCPERP1","price":"6.3104","delta":"-1.00","side":"bid","ts_ms":1781237160302}}

{"type":"orderbook_delta","sid":1,"seq":1840,"msg":{"market_ticker":"KXBTCPERP1","price":"6.3104","delta":"-1.00","side":"bid","ts_ms":1781237160302}}

{"type":"orderbook_delta","sid":1,"seq":1841,"msg":{"market_ticker":"KXBTCPERP1","price":"6.3104","delta":"-1.00","side":"bid","ts_ms":1781237160302}}

{"type":"orderbook_delta","sid":1,"seq":1842,"msg":{"market_ticker":"KXBTCPERP1","price":"6.3104","delta":"-1.00","side":"bid","ts_ms":1781237160302}}

{"type":"orderbook_delta","sid":1,"seq":1843,"msg":{"market_ticker":"KXBTCPERP1","price":"6.3104","delta":"-1.00","side":"bid","ts_ms":1781237160302}}

{"type":"orderbook_delta","sid":1,"seq":1844,"msg":{"market_ticker":"KXBTCPERP1","price":"6.3103","delta":"-1.00","side":"bid","ts_ms":1781237160302}}

{"type":"orderbook_delta","sid":1,"seq":1845,"msg":{"market_ticker":"KXBTCPERP1","price":"6.3103","delta":"-1.00","side":"bid","ts_ms":1781237160302}}

{"type":"orderbook_delta","sid":1,"seq":1846,"msg":{"market_ticker":"KXBTCPERP1","price":"6.3103","delta":"-1.00","side":"bid","ts_ms":1781237160302}}

{"type":"orderbook_delta","sid":1,"seq":1847,"msg":{"market_ticker":"KXBTCPERP1","price":"6.3103","delta":"-1.00","side":"bid","ts_ms":1781237160302}}

{"type":"orderbook_delta","sid":1,"seq":1848,"msg":{"market_ticker":"KXBTCPERP1","price":"6.3103","delta":"-1.00","side":"bid","ts_ms":1781237160302}}

{"type":"orderbook_delta","sid":1,"seq":1849,"msg":{"market_ticker":"KXBTCPERP1","price":"6.3103","delta":"-1.00","side":"bid","ts_ms":1781237160302}}

{"type":"orderbook_delta","sid":1,"seq":1850,"msg":{"market_ticker":"KXBTCPERP1","price":"6.3102","delta":"-1.00","side":"bid","ts_ms":1781237160302}}

{"type":"orderbook_delta","sid":1,"seq":1851,"msg":{"market_ticker":"KXBTCPERP1","price":"6.3102","delta":"-1.00","side":"bid","ts_ms":1781237160302}}

{"type":"orderbook_delta","sid":1,"seq":1852,"msg":{"market_ticker":"KXBTCPERP1","price":"6.3101","delta":"-1.00","side":"bid","ts_ms":1781237160302}}

{"type":"orderbook_delta","sid":1,"seq":1853,"msg":{"market_ticker":"KXBTCPERP1","price":"6.3101","delta":"-1.00","side":"bid","ts_ms":1781237160302}}

{"type":"orderbook_delta","sid":1,"seq":1854,"msg":{"market_ticker":"KXBTCPERP1","price":"6.3101","delta":"-1.00","side":"bid","ts_ms":1781237160302}}

{"type":"orderbook_delta","sid":1,"seq":1855,"msg":{"market_ticker":"KXBTCPERP1","price":"6.3101","delta":"-1.00","side":"bid","ts_ms":1781237160302}}

{"type":"orderbook_delta","sid":1,"seq":1856,"msg":{"market_ticker":"KXBTCPERP1","price":"6.3100","delta":"-1.00","side":"bid","ts_ms":1781237160302}}

{"type":"orderbook_delta","sid":1,"seq":1857,"msg":{"market_ticker":"KXBTCPERP1","price":"6.3100","delta":"-1.00","side":"bid","ts_ms":1781237160302}}

{"type":"orderbook_delta","sid":1,"seq":1858,"msg":{"market_ticker":"KXBTCPERP1","price":"6.3100","delta":"-1.00","side":"bid","ts_ms":1781237160302}}

{"type":"orderbook_delta","sid":1,"seq":1859,"msg":{"market_ticker":"KXBTCPERP1","price":"6.3099","delta":"-1.00","side":"bid","ts_ms":1781237160302}}

{"type":"orderbook_delta","sid":1,"seq":1860,"msg":{"market_ticker":"KXBTCPERP1","price":"6.3098","delta":"-1.00","side":"bid","ts_ms":1781237160302}}

{"type":"orderbook_delta","sid":1,"seq":1861,"msg":{"market_ticker":"KXBTCPERP1","price":"6.3098","delta":"-1.00","side":"bid","ts_ms":1781237160302}}

{"type":"orderbook_delta","sid":1,"seq":1862,"msg":{"market_ticker":"KXBTCPERP1","price":"6.3097","delta":"-1.00","side":"bid","ts_ms":1781237160302}}

{"type":"orderbook_delta","sid":1,"seq":1863,"msg":{"market_ticker":"KXBTCPERP1","price":"6.3096","delta":"-1.00","side":"bid","ts_ms":1781237160302}}

{"type":"orderbook_delta","sid":1,"seq":1864,"msg":{"market_ticker":"KXBTCPERP1","price":"6.3096","delta":"-1.00","side":"bid","ts_ms":1781237160302}}

{"type":"orderbook_delta","sid":1,"seq":1865,"msg":{"market_ticker":"KXBTCPERP1","price":"6.3095","delta":"-1.00","side":"bid","ts_ms":1781237160302}}

{"type":"orderbook_delta","sid":1,"seq":1866,"msg":{"market_ticker":"KXBTCPERP1","price":"6.3095","delta":"-1.00","side":"bid","ts_ms":1781237160302}}

{"type":"orderbook_delta","sid":1,"seq":1867,"msg":{"market_ticker":"KXBTCPERP1","price":"6.3095","delta":"-1.00","side":"bid","ts_ms":1781237160302}}

{"type":"orderbook_delta","sid":1,"seq":1868,"msg":{"market_ticker":"KXBTCPERP1","price":"6.3095","delta":"-1.00","side":"bid","ts_ms":1781237160302}}

{"type":"orderbook_delta","sid":1,"seq":1869,"msg":{"market_ticker":"KXBTCPERP1","price":"6.3095","delta":"-1.00","side":"bid","ts_ms":1781237160302}}

{"type":"orderbook_delta","sid":1,"seq":1870,"msg":{"market_ticker":"KXBTCPERP1","price":"6.3094","delta":"-1.00","side":"bid","ts_ms":1781237160302}}

{"type":"orderbook_delta","sid":1,"seq":1871,"msg":{"market_ticker":"KXBTCPERP1","price":"6.3094","delta":"-1.00","side":"bid","ts_ms":1781237160302}}

{"type":"orderbook_delta","sid":1,"seq":1872,"msg":{"market_ticker":"KXBTCPERP1","price":"6.3094","delta":"-1.00","side":"bid","ts_ms":1781237160302}}

{"type":"orderbook_delta","sid":1,"seq":1873,"msg":{"market_ticker":"KXBTCPERP1","price":"6.3093","delta":"-1.00","side":"bid","ts_ms":1781237160302}}

{"type":"orderbook_delta","sid":1,"seq":1874,"msg":{"market_ticker":"KXBTCPERP1","price":"6.3093","delta":"-1.00","side":"bid","ts_ms":1781237160302}}

{"type":"orderbook_delta","sid":1,"seq":1875,"msg":{"market_ticker":"KXBTCPERP1","price":"6.3093","delta":"-1.00","side":"bid","ts_ms":1781237160302}}

{"type":"orderbook_delta","sid":1,"seq":1876,"msg":{"market_ticker":"KXBTCPERP1","price":"6.3093","delta":"-1.00","side":"bid","ts_ms":1781237160302}}

{"type":"orderbook_delta","sid":1,"seq":1877,"msg":{"market_ticker":"KXBTCPERP1","price":"6.3093","delta":"-1.00","side":"bid","ts_ms":1781237160302}}

{"type":"orderbook_delta","sid":1,"seq":1878,"msg":{"market_ticker":"KXBTCPERP1","price":"6.3092","delta":"-1.00","side":"bid","ts_ms":1781237160302}}

{"type":"orderbook_delta","sid":1,"seq":1879,"msg":{"market_ticker":"KXBTCPERP1","price":"6.3092","delta":"-1.00","side":"bid","ts_ms":1781237160302}}

{"type":"orderbook_delta","sid":1,"seq":1880,"msg":{"market_ticker":"KXBTCPERP1","price":"6.3092","delta":"-1.00","side":"bid","ts_ms":1781237160302}}

{"type":"orderbook_delta","sid":1,"seq":1881,"msg":{"market_ticker":"KXBTCPERP1","price":"6.3090","delta":"-1.00","side":"bid","ts_ms":1781237160302}}

{"type":"orderbook_delta","sid":1,"seq":1882,"msg":{"market_ticker":"KXBTCPERP1","price":"6.3090","delta":"-1.00","side":"bid","ts_ms":1781237160302}}

{"type":"orderbook_delta","sid":1,"seq":1883,"msg":{"market_ticker":"KXBTCPERP1","price":"6.3089","delta":"-1.00","side":"bid","ts_ms":1781237160302}}

{"type":"orderbook_delta","sid":1,"seq":1884,"msg":{"market_ticker":"KXBTCPERP1","price":"6.3089","delta":"-1.00","side":"bid","ts_ms":1781237160302}}

{"type":"orderbook_delta","sid":1,"seq":1885,"msg":{"market_ticker":"KXBTCPERP1","price":"6.3089","delta":"-1.00","side":"bid","ts_ms":1781237160302}}

{"type":"orderbook_delta","sid":1,"seq":1886,"msg":{"market_ticker":"KXBTCPERP1","price":"6.3089","delta":"-1.00","side":"bid","ts_ms":1781237160302}}

{"type":"orderbook_delta","sid":1,"seq":1887,"msg":{"market_ticker":"KXBTCPERP1","price":"6.3088","delta":"-1.00","side":"bid","ts_ms":1781237160302}}

{"type":"orderbook_delta","sid":1,"seq":1888,"msg":{"market_ticker":"KXBTCPERP1","price":"6.3088","delta":"-1.00","side":"bid","ts_ms":1781237160302}}

{"type":"orderbook_delta","sid":1,"seq":1889,"msg":{"market_ticker":"KXBTCPERP1","price":"6.3088","delta":"-1.00","side":"bid","ts_ms":1781237160302}}

{"type":"orderbook_delta","sid":1,"seq":1890,"msg":{"market_ticker":"KXBTCPERP1","price":"6.3087","delta":"-1.00","side":"bid","ts_ms":1781237160302}}

{"type":"orderbook_delta","sid":1,"seq":1891,"msg":{"market_ticker":"KXBTCPERP1","price":"6.3086","delta":"-1.00","side":"bid","ts_ms":1781237160302}}

{"type":"orderbook_delta","sid":1,"seq":1892,"msg":{"market_ticker":"KXBTCPERP1","price":"6.3086","delta":"-1.00","side":"bid","ts_ms":1781237160302}}

{"type":"orderbook_delta","sid":1,"seq":1893,"msg":{"market_ticker":"KXBTCPERP1","price":"6.3086","delta":"-1.00","side":"bid","ts_ms":1781237160302}}

{"type":"orderbook_delta","sid":1,"seq":1894,"msg":{"market_ticker":"KXBTCPERP1","price":"6.3086","delta":"-1.00","side":"bid","ts_ms":1781237160302}}

{"type":"orderbook_delta","sid":1,"seq":1895,"msg":{"market_ticker":"KXBTCPERP1","price":"6.3085","delta":"-1.00","side":"bid","ts_ms":1781237160302}}

{"type":"orderbook_delta","sid":1,"seq":1896,"msg":{"market_ticker":"KXBTCPERP1","price":"6.3085","delta":"-1.00","side":"bid","ts_ms":1781237160302}}

{"type":"orderbook_delta","sid":1,"seq":1897,"msg":{"market_ticker":"KXBTCPERP1","price":"6.3085","delta":"-1.00","side":"bid","ts_ms":1781237160302}}

{"type":"orderbook_delta","sid":1,"seq":1898,"msg":{"market_ticker":"KXBTCPERP1","price":"6.3083","delta":"-1.00","side":"bid","ts_ms":1781237160302}}

{"type":"orderbook_delta","sid":1,"seq":1899,"msg":{"market_ticker":"KXBTCPERP1","price":"6.3083","delta":"-1.00","side":"bid","ts_ms":1781237160302}}

{"type":"orderbook_delta","sid":1,"seq":1900,"msg":{"market_ticker":"KXBTCPERP1","price":"6.3083","delta":"-1.00","side":"bid","ts_ms":1781237160302}}

{"type":"orderbook_delta","sid":1,"seq":1901,"msg":{"market_ticker":"KXBTCPERP1","price":"6.3083","delta":"-1.00","side":"bid","ts_ms":1781237160302}}

{"type":"orderbook_delta","sid":1,"seq":1902,"msg":{"market_ticker":"KXBTCPERP1","price":"6.3083","delta":"-1.00","side":"bid","ts_ms":1781237160302}}

{"type":"orderbook_delta","sid":1,"seq":1903,"msg":{"market_ticker":"KXBTCPERP1","price":"6.3082","delta":"-1.00","side":"bid","ts_ms":1781237160302}}

{"type":"orderbook_delta","sid":1,"seq":1904,"msg":{"market_ticker":"KXBTCPERP1","price":"6.3081","delta":"-1.00","side":"bid","ts_ms":1781237160302}}

{"type":"orderbook_delta","sid":1,"seq":1905,"msg":{"market_ticker":"KXBTCPERP1","price":"6.3081","delta":"-1.00","side":"bid","ts_ms":1781237160302}}

{"type":"orderbook_delta","sid":1,"seq":1906,"msg":{"market_ticker":"KXBTCPERP1","price":"6.3080","delta":"-1.00","side":"bid","ts_ms":1781237160302}}

{"type":"orderbook_delta","sid":1,"seq":1907,"msg":{"market_ticker":"KXBTCPERP1","price":"6.3080","delta":"-1.00","side":"bid","ts_ms":1781237160302}}

{"type":"orderbook_delta","sid":1,"seq":1908,"msg":{"market_ticker":"KXBTCPERP1","price":"6.3080","delta":"-1.00","side":"bid","ts_ms":1781237160302}}

{"type":"orderbook_delta","sid":1,"seq":1909,"msg":{"market_ticker":"KXBTCPERP1","price":"6.3080","delta":"-1.00","side":"bid","ts_ms":1781237160302}}

{"type":"orderbook_delta","sid":1,"seq":1910,"msg":{"market_ticker":"KXBTCPERP1","price":"6.3080","delta":"-1.00","side":"bid","ts_ms":1781237160302}}

{"type":"orderbook_delta","sid":1,"seq":1911,"msg":{"market_ticker":"KXBTCPERP1","price":"6.3079","delta":"-1.00","side":"bid","ts_ms":1781237160302}}

{"type":"orderbook_delta","sid":1,"seq":1912,"msg":{"market_ticker":"KXBTCPERP1","price":"6.3079","delta":"-1.00","side":"bid","ts_ms":1781237160302}}

{"type":"orderbook_delta","sid":1,"seq":1913,"msg":{"market_ticker":"KXBTCPERP1","price":"6.3079","delta":"-1.00","side":"bid","ts_ms":1781237160302}}

{"type":"orderbook_delta","sid":1,"seq":1914,"msg":{"market_ticker":"KXBTCPERP1","price":"6.3078","delta":"-1.00","side":"bid","ts_ms":1781237160302}}

{"type":"orderbook_delta","sid":1,"seq":1915,"msg":{"market_ticker":"KXBTCPERP1","price":"6.3078","delta":"-1.00","side":"bid","ts_ms":1781237160302}}

{"type":"orderbook_delta","sid":1,"seq":1916,"msg":{"market_ticker":"KXBTCPERP1","price":"6.3077","delta":"-1.00","side":"bid","ts_ms":1781237160302}}

{"type":"orderbook_delta","sid":1,"seq":1917,"msg":{"market_ticker":"KXBTCPERP1","price":"6.3076","delta":"-1.00","side":"bid","ts_ms":1781237160302}}

{"type":"orderbook_delta","sid":1,"seq":1918,"msg":{"market_ticker":"KXBTCPERP1","price":"6.3076","delta":"-1.00","side":"bid","ts_ms":1781237160302}}

{"type":"orderbook_delta","sid":1,"seq":1919,"msg":{"market_ticker":"KXBTCPERP1","price":"6.3076","delta":"-1.00","side":"bid","ts_ms":1781237160302}}

{"type":"orderbook_delta","sid":1,"seq":1920,"msg":{"market_ticker":"KXBTCPERP1","price":"6.3076","delta":"-1.00","side":"bid","ts_ms":1781237160302}}

{"type":"orderbook_delta","sid":1,"seq":1921,"msg":{"market_ticker":"KXBTCPERP1","price":"6.3076","delta":"-1.00","side":"bid","ts_ms":1781237160302}}

{"type":"orderbook_delta","sid":1,"seq":1922,"msg":{"market_ticker":"KXBTCPERP1","price":"6.3075","delta":"-1.00","side":"bid","ts_ms":1781237160302}}

{"type":"orderbook_delta","sid":1,"seq":1923,"msg":{"market_ticker":"KXBTCPERP1","price":"6.3075","delta":"-1.00","side":"bid","ts_ms":1781237160302}}

{"type":"orderbook_delta","sid":1,"seq":1924,"msg":{"market_ticker":"KXBTCPERP1","price":"6.3075","delta":"-1.00","side":"bid","ts_ms":1781237160302}}

{"type":"orderbook_delta","sid":1,"seq":1925,"msg":{"market_ticker":"KXBTCPERP1","price":"6.3075","delta":"-1.00","side":"bid","ts_ms":1781237160302}}

{"type":"orderbook_delta","sid":1,"seq":1926,"msg":{"market_ticker":"KXBTCPERP1","price":"6.3074","delta":"-1.00","side":"bid","ts_ms":1781237160302}}

{"type":"orderbook_delta","sid":1,"seq":1927,"msg":{"market_ticker":"KXBTCPERP1","price":"6.3074","delta":"-1.00","side":"bid","ts_ms":1781237160302}}

{"type":"orderbook_delta","sid":1,"seq":1928,"msg":{"market_ticker":"KXBTCPERP1","price":"6.3073","delta":"-1.00","side":"bid","ts_ms":1781237160302}}

{"type":"orderbook_delta","sid":1,"seq":1929,"msg":{"market_ticker":"KXBTCPERP1","price":"6.3073","delta":"-1.00","side":"bid","ts_ms":1781237160302}}

{"type":"orderbook_delta","sid":1,"seq":1930,"msg":{"market_ticker":"KXBTCPERP1","price":"6.3072","delta":"-1.00","side":"bid","ts_ms":1781237160302}}

{"type":"orderbook_delta","sid":1,"seq":1931,"msg":{"market_ticker":"KXBTCPERP1","price":"6.3072","delta":"-1.00","side":"bid","ts_ms":1781237160302}}

{"type":"orderbook_delta","sid":1,"seq":1932,"msg":{"market_ticker":"KXBTCPERP1","price":"6.3072","delta":"-1.00","side":"bid","ts_ms":1781237160302}}

{"type":"orderbook_delta","sid":1,"seq":1933,"msg":{"market_ticker":"KXBTCPERP1","price":"6.3072","delta":"-1.00","side":"bid","ts_ms":1781237160302}}

{"type":"orderbook_delta","sid":1,"seq":1934,"msg":{"market_ticker":"KXBTCPERP1","price":"6.3071","delta":"-1.00","side":"bid","ts_ms":1781237160302}}

{"type":"orderbook_delta","sid":1,"seq":1935,"msg":{"market_ticker":"KXBTCPERP1","price":"6.3071","delta":"-1.00","side":"bid","ts_ms":1781237160302}}

{"type":"orderbook_delta","sid":1,"seq":1936,"msg":{"market_ticker":"KXBTCPERP1","price":"6.3070","delta":"-1.00","side":"bid","ts_ms":1781237160302}}

{"type":"orderbook_delta","sid":1,"seq":1937,"msg":{"market_ticker":"KXBTCPERP1","price":"6.3070","delta":"-1.00","side":"bid","ts_ms":1781237160302}}

{"type":"orderbook_delta","sid":1,"seq":1938,"msg":{"market_ticker":"KXBTCPERP1","price":"6.3070","delta":"-1.00","side":"bid","ts_ms":1781237160302}}

{"type":"orderbook_delta","sid":1,"seq":1939,"msg":{"market_ticker":"KXBTCPERP1","price":"6.3070","delta":"-1.00","side":"bid","ts_ms":1781237160302}}

{"type":"orderbook_delta","sid":1,"seq":1940,"msg":{"market_ticker":"KXBTCPERP1","price":"6.3070","delta":"-1.00","side":"bid","ts_ms":1781237160302}}

{"type":"orderbook_delta","sid":1,"seq":1941,"msg":{"market_ticker":"KXBTCPERP1","price":"6.3070","delta":"-1.00","side":"bid","ts_ms":1781237160302}}

{"type":"orderbook_delta","sid":1,"seq":1942,"msg":{"market_ticker":"KXBTCPERP1","price":"6.3069","delta":"-1.00","side":"bid","ts_ms":1781237160302}}

{"type":"orderbook_delta","sid":1,"seq":1943,"msg":{"market_ticker":"KXBTCPERP1","price":"6.3069","delta":"-1.00","side":"bid","ts_ms":1781237160302}}

{"type":"orderbook_delta","sid":1,"seq":1944,"msg":{"market_ticker":"KXBTCPERP1","price":"6.3069","delta":"-1.00","side":"bid","ts_ms":1781237160302}}

{"type":"orderbook_delta","sid":1,"seq":1945,"msg":{"market_ticker":"KXBTCPERP1","price":"6.3068","delta":"-1.00","side":"bid","ts_ms":1781237160302}}

{"type":"orderbook_delta","sid":1,"seq":1946,"msg":{"market_ticker":"KXBTCPERP1","price":"6.3068","delta":"-1.00","side":"bid","ts_ms":1781237160302}}

{"type":"orderbook_delta","sid":1,"seq":1947,"msg":{"market_ticker":"KXBTCPERP1","price":"6.3068","delta":"-1.00","side":"bid","ts_ms":1781237160302}}

{"type":"orderbook_delta","sid":1,"seq":1948,"msg":{"market_ticker":"KXBTCPERP1","price":"6.3068","delta":"-1.00","side":"bid","ts_ms":1781237160302}}

{"type":"orderbook_delta","sid":1,"seq":1949,"msg":{"market_ticker":"KXBTCPERP1","price":"6.3068","delta":"-1.00","side":"bid","ts_ms":1781237160302}}

{"type":"orderbook_delta","sid":1,"seq":1950,"msg":{"market_ticker":"KXBTCPERP1","price":"6.3068","delta":"-1.00","side":"bid","ts_ms":1781237160302}}

{"type":"orderbook_delta","sid":1,"seq":1951,"msg":{"market_ticker":"KXBTCPERP1","price":"6.3067","delta":"-1.00","side":"bid","ts_ms":1781237160302}}

{"type":"orderbook_delta","sid":1,"seq":1952,"msg":{"market_ticker":"KXBTCPERP1","price":"6.3067","delta":"-1.00","side":"bid","ts_ms":1781237160302}}

{"type":"orderbook_delta","sid":1,"seq":1953,"msg":{"market_ticker":"KXBTCPERP1","price":"6.3067","delta":"-1.00","side":"bid","ts_ms":1781237160302}}

{"type":"orderbook_delta","sid":1,"seq":1954,"msg":{"market_ticker":"KXBTCPERP1","price":"6.3066","delta":"-1.00","side":"bid","ts_ms":1781237160302}}

{"type":"orderbook_delta","sid":1,"seq":1955,"msg":{"market_ticker":"KXBTCPERP1","price":"6.3066","delta":"-1.00","side":"bid","ts_ms":1781237160302}}

{"type":"orderbook_delta","sid":1,"seq":1956,"msg":{"market_ticker":"KXBTCPERP1","price":"6.3940","delta":"-781.00","side":"ask","ts_ms":1781237160302}}

{"type":"orderbook_delta","sid":1,"seq":1957,"msg":{"market_ticker":"KXBTCPERP1","price":"6.3066","delta":"342.00","side":"ask","ts_ms":1781237160302}}

{"type":"trade","sid":2,"seq":1329,"msg":{"trade_id":"97a58330-b5f2-585a-383e-ead92fde978c","market_ticker":"KXBTCPERP1","price":"6.3212","count":"1.00","taker_side":"ask","ts_ms":1781237160302}}

{"type":"trade","sid":2,"seq":1330,"msg":{"trade_id":"f7f69b45-c824-5965-25a1-e47a7a06b5a4","market_ticker":"KXBTCPERP1","price":"6.3211","count":"1.00","taker_side":"ask","ts_ms":1781237160302}}

{"type":"trade","sid":2,"seq":1331,"msg":{"trade_id":"40753510-9aa4-59a1-3dde-8cabdb43d84d","market_ticker":"KXBTCPERP1","price":"6.3210","count":"1.00","taker_side":"ask","ts_ms":1781237160302}}

{"type":"trade","sid":2,"seq":1332,"msg":{"trade_id":"ea70f5b1-8104-5882-15c0-8c4bbc3af9b4","market_ticker":"KXBTCPERP1","price":"6.3210","count":"1.00","taker_side":"ask","ts_ms":1781237160302}}

{"type":"trade","sid":2,"seq":1333,"msg":{"trade_id":"022ca745-10a5-5c6e-0909-8bc0840b6cc3","market_ticker":"KXBTCPERP1","price":"6.3209","count":"1.00","taker_side":"ask","ts_ms":1781237160302}}

{"type":"trade","sid":2,"seq":1334,"msg":{"trade_id":"1ee25f5f-4b28-503f-04dd-70d2bed88f91","market_ticker":"KXBTCPERP1","price":"6.3209","count":"1.00","taker_side":"ask","ts_ms":1781237160302}}

{"type":"trade","sid":2,"seq":1335,"msg":{"trade_id":"d7a476b8-5742-5336-27fa-a1e4d706fd19","market_ticker":"KXBTCPERP1","price":"6.3209","count":"1.00","taker_side":"ask","ts_ms":1781237160302}}

{"type":"trade","sid":2,"seq":1336,"msg":{"trade_id":"8af19f3b-d442-5460-2327-4aed3c4a5a2f","market_ticker":"KXBTCPERP1","price":"6.3209","count":"1.00","taker_side":"ask","ts_ms":1781237160302}}

{"type":"trade","sid":2,"seq":1337,"msg":{"trade_id":"81921019-4448-5d35-23d3-ce75995ea442","market_ticker":"KXBTCPERP1","price":"6.3209","count":"1.00","taker_side":"ask","ts_ms":1781237160302}}

{"type":"trade","sid":2,"seq":1338,"msg":{"trade_id":"b413101e-a125-5aea-131e-32ac78aedaaf","market_ticker":"KXBTCPERP1","price":"6.3208","count":"1.00","taker_side":"ask","ts_ms":1781237160302}}

{"type":"trade","sid":2,"seq":1339,"msg":{"trade_id":"2b6d2913-fb40-5769-37fe-8795fbc3a3b9","market_ticker":"KXBTCPERP1","price":"6.3207","count":"1.00","taker_side":"ask","ts_ms":1781237160302}}

{"type":"trade","sid":2,"seq":1340,"msg":{"trade_id":"8b7b26cd-d532-52a8-3a6a-1842ac3fa4df","market_ticker":"KXBTCPERP1","price":"6.3207","count":"1.00","taker_side":"ask","ts_ms":1781237160302}}

{"type":"trade","sid":2,"seq":1341,"msg":{"trade_id":"e4530054-e09c-5564-1fc7-35afaeb22b64","market_ticker":"KXBTCPERP1","price":"6.3206","count":"1.00","taker_side":"ask","ts_ms":1781237160302}}

{"type":"trade","sid":2,"seq":1342,"msg":{"trade_id":"cbccf11a-1ba9-57de-3faa-0173893a84f3","market_ticker":"KXBTCPERP1","price":"6.3206","count":"1.00","taker_side":"ask","ts_ms":1781237160302}}

{"type":"trade","sid":2,"seq":1343,"msg":{"trade_id":"62e71ab4-7502-5747-117a-8892359f439f","market_ticker":"KXBTCPERP1","price":"6.3205","count":"1.00","taker_side":"ask","ts_ms":1781237160302}}

{"type":"trade","sid":2,"seq":1344,"msg":{"trade_id":"489928bd-3c6a-524c-1875-725b56b7c8b4","market_ticker":"KXBTCPERP1","price":"6.3205","count":"1.00","taker_side":"ask","ts_ms":1781237160302}}

{"type":"trade","sid":2,"seq":1345,"msg":{"trade_id":"9a7e03d6-0637-5d88-29ff-372a74aa15c2","market_ticker":"KXBTCPERP1","price":"6.3205","count":"1.00","taker_side":"ask","ts_ms":1781237160302}}

{"type":"trade","sid":2,"seq":1346,"msg":{"trade_id":"ec356057-473c-5c89-2789-e267da7c6d35","market_ticker":"KXBTCPERP1","price":"6.3205","count":"1.00","taker_side":"ask","ts_ms":1781237160302}}

{"type":"trade","sid":2,"seq":1347,"msg":{"trade_id":"e2c122c8-d78b-509b-14cc-8549c80b646f","market_ticker":"KXBTCPERP1","price":"6.3205","count":"1.00","taker_side":"ask","ts_ms":1781237160302}}

{"type":"trade","sid":2,"seq":1348,"msg":{"trade_id":"113ed0ff-702a-5652-1543-d77f197aa4c8","market_ticker":"KXBTCPERP1","price":"6.3204","count":"1.00","taker_side":"ask","ts_ms":1781237160302}}

{"type":"trade","sid":2,"seq":1349,"msg":{"trade_id":"239ffff9-76e4-5344-3c58-484af66f89bf","market_ticker":"KXBTCPERP1","price":"6.3203","count":"1.00","taker_side":"ask","ts_ms":1781237160302}}

{"type":"trade","sid":2,"seq":1350,"msg":{"trade_id":"b56bb9f2-95d3-50c0-3767-eed3282b586f","market_ticker":"KXBTCPERP1","price":"6.3203","count":"1.00","taker_side":"ask","ts_ms":1781237160302}}

{"type":"trade","sid":2,"seq":1351,"msg":{"trade_id":"9fcd9a89-3db8-5617-203a-bbee8dc071e8","market_ticker":"KXBTCPERP1","price":"6.3203","count":"1.00","taker_side":"ask","ts_ms":1781237160302}}

{"type":"trade","sid":2,"seq":1352,"msg":{"trade_id":"b0dbdfd4-9fda-5680-1934-74e19df4c8c2","market_ticker":"KXBTCPERP1","price":"6.3203","count":"1.00","taker_side":"ask","ts_ms":1781237160302}}

{"type":"trade","sid":2,"seq":1353,"msg":{"trade_id":"1661dd85-ed98-55f2-3b25-91600be04f44","market_ticker":"KXBTCPERP1","price":"6.3202","count":"1.00","taker_side":"ask","ts_ms":1781237160302}}

{"type":"trade","sid":2,"seq":1354,"msg":{"trade_id":"1637800a-8403-5436-2748-3190b25da602","market_ticker":"KXBTCPERP1","price":"6.3202","count":"1.00","taker_side":"ask","ts_ms":1781237160302}}

{"type":"trade","sid":2,"seq":1355,"msg":{"trade_id":"2c2d21f1-02dc-5ee8-0654-b1f5407c6c94","market_ticker":"KXBTCPERP1","price":"6.3202","count":"1.00","taker_side":"ask","ts_ms":1781237160302}}

{"type":"trade","sid":2,"seq":1356,"msg":{"trade_id":"8bf31abf-c80e-5e31-3034-4b62708e3b84","market_ticker":"KXBTCPERP1","price":"6.3202","count":"1.00","taker_side":"ask","ts_ms":1781237160302}}

{"type":"trade","sid":2,"seq":1357,"msg":{"trade_id":"78c7cc3a-c6cd-5010-303b-250ace45de50","market_ticker":"KXBTCPERP1","price":"6.3201","count":"1.00","taker_side":"ask","ts_ms":1781237160302}}

{"type":"trade","sid":2,"seq":1358,"msg":{"trade_id":"4aaa9a9a-25ca-5ee7-080c-bba660853490","market_ticker":"KXBTCPERP1","price":"6.3201","count":"1.00","taker_side":"ask","ts_ms":1781237160302}}

{"type":"trade","sid":2,"seq":1359,"msg":{"trade_id":"ddda74cf-7139-598a-0811-4780ae90eb94","market_ticker":"KXBTCPERP1","price":"6.3201","count":"1.00","taker_side":"ask","ts_ms":1781237160302}}

{"type":"trade","sid":2,"seq":1360,"msg":{"trade_id":"b4fdfca0-bf50-5254-2d8a-cb19e2c65400","market_ticker":"KXBTCPERP1","price":"6.3201","count":"1.00","taker_side":"ask","ts_ms":1781237160302}}

{"type":"trade","sid":2,"seq":1361,"msg":{"trade_id":"12adb078-c331-5250-11f6-3ce6efd6533a","market_ticker":"KXBTCPERP1","price":"6.3201","count":"1.00","taker_side":"ask","ts_ms":1781237160302}}

{"type":"trade","sid":2,"seq":1362,"msg":{"trade_id":"5b5da789-fe04-5855-0dda-e9a4aa16f184","market_ticker":"KXBTCPERP1","price":"6.3200","count":"1.00","taker_side":"ask","ts_ms":1781237160302}}

{"type":"trade","sid":2,"seq":1363,"msg":{"trade_id":"fbbbd057-4b4d-5b6b-2236-64241b5326f9","market_ticker":"KXBTCPERP1","price":"6.3200","count":"1.00","taker_side":"ask","ts_ms":1781237160302}}

{"type":"trade","sid":2,"seq":1364,"msg":{"trade_id":"e54b01a1-ec7d-5c3c-27d3-2a356c8e4b87","market_ticker":"KXBTCPERP1","price":"6.3200","count":"1.00","taker_side":"ask","ts_ms":1781237160302}}

{"type":"trade","sid":2,"seq":1365,"msg":{"trade_id":"3f8670d9-17ce-59ed-0c98-b69e1c31a27a","market_ticker":"KXBTCPERP1","price":"6.3200","count":"1.00","taker_side":"ask","ts_ms":1781237160302}}

{"type":"trade","sid":2,"seq":1366,"msg":{"trade_id":"84e85462-dad8-5793-3bb4-9426c8d3b3c8","market_ticker":"KXBTCPERP1","price":"6.3200","count":"1.00","taker_side":"ask","ts_ms":1781237160302}}

{"type":"trade","sid":2,"seq":1367,"msg":{"trade_id":"d61f9ec4-5041-5c7e-3ff6-c026176be751","market_ticker":"KXBTCPERP1","price":"6.3200","count":"1.00","taker_side":"ask","ts_ms":1781237160302}}

{"type":"trade","sid":2,"seq":1368,"msg":{"trade_id":"d0030a30-b49f-5f68-00a3-8eb3b854ffdb","market_ticker":"KXBTCPERP1","price":"6.3200","count":"1.00","taker_side":"ask","ts_ms":1781237160302}}

{"type":"trade","sid":2,"seq":1369,"msg":{"trade_id":"3cd3cccc-19cd-5c1d-247a-6ba6268af8ea","market_ticker":"KXBTCPERP1","price":"6.3199","count":"1.00","taker_side":"ask","ts_ms":1781237160302}}

{"type":"trade","sid":2,"seq":1370,"msg":{"trade_id":"38d662e8-c425-58ea-3ee3-c1c3962bc901","market_ticker":"KXBTCPERP1","price":"6.3199","count":"1.00","taker_side":"ask","ts_ms":1781237160302}}

{"type":"trade","sid":2,"seq":1371,"msg":{"trade_id":"17e824e9-c4b3-5aef-07b6-710781c8f8b7","market_ticker":"KXBTCPERP1","price":"6.3199","count":"1.00","taker_side":"ask","ts_ms":1781237160302}}

{"type":"trade","sid":2,"seq":1372,"msg":{"trade_id":"1526b930-3e11-5d7e-160a-767223c1d39c","market_ticker":"KXBTCPERP1","price":"6.3199","count":"1.00","taker_side":"ask","ts_ms":1781237160302}}

{"type":"trade","sid":2,"seq":1373,"msg":{"trade_id":"e3b95c8d-b8c5-512b-2088-ded4c57a6e4b","market_ticker":"KXBTCPERP1","price":"6.3199","count":"1.00","taker_side":"ask","ts_ms":1781237160302}}

{"type":"trade","sid":2,"seq":1374,"msg":{"trade_id":"8a83e10d-2fc2-5ba9-2171-0dda6739cead","market_ticker":"KXBTCPERP1","price":"6.3198","count":"1.00","taker_side":"ask","ts_ms":1781237160302}}

{"type":"trade","sid":2,"seq":1375,"msg":{"trade_id":"58fcee9a-1a4b-5a2e-07ee-9b66d1d319e8","market_ticker":"KXBTCPERP1","price":"6.3198","count":"1.00","taker_side":"ask","ts_ms":1781237160302}}

{"type":"trade","sid":2,"seq":1376,"msg":{"trade_id":"547546a9-2710-5600-121c-8e954be181cf","market_ticker":"KXBTCPERP1","price":"6.3197","count":"1.00","taker_side":"ask","ts_ms":1781237160302}}

{"type":"trade","sid":2,"seq":1377,"msg":{"trade_id":"59d07f39-27da-5c17-2051-f886d702e5b9","market_ticker":"KXBTCPERP1","price":"6.3197","count":"1.00","taker_side":"ask","ts_ms":1781237160302}}

{"type":"trade","sid":2,"seq":1378,"msg":{"trade_id":"df4dd652-7cf1-5c76-0449-1c2ac7aa1e9a","market_ticker":"KXBTCPERP1","price":"6.3197","count":"1.00","taker_side":"ask","ts_ms":1781237160302}}

{"type":"trade","sid":2,"seq":1379,"msg":{"trade_id":"81c1ba64-909e-5e55-261b-02b8f9365eb9","market_ticker":"KXBTCPERP1","price":"6.3196","count":"1.00","taker_side":"ask","ts_ms":1781237160302}}

{"type":"trade","sid":2,"seq":1380,"msg":{"trade_id":"09cbaf82-7dd9-5d7e-2938-c4159c559a22","market_ticker":"KXBTCPERP1","price":"6.3196","count":"1.00","taker_side":"ask","ts_ms":1781237160302}}

{"type":"trade","sid":2,"seq":1381,"msg":{"trade_id":"5f3dbb08-c31e-5427-3e12-c2e7ccbe86af","market_ticker":"KXBTCPERP1","price":"6.3196","count":"1.00","taker_side":"ask","ts_ms":1781237160302}}

{"type":"trade","sid":2,"seq":1382,"msg":{"trade_id":"ed4a7729-05d0-56ec-04d2-399723edb3e4","market_ticker":"KXBTCPERP1","price":"6.3196","count":"1.00","taker_side":"ask","ts_ms":1781237160302}}

{"type":"trade","sid":2,"seq":1383,"msg":{"trade_id":"a2e5e332-7940-5305-0260-08495fdc20cc","market_ticker":"KXBTCPERP1","price":"6.3196","count":"1.00","taker_side":"ask","ts_ms":1781237160302}}

{"type":"trade","sid":2,"seq":1384,"msg":{"trade_id":"3b65a84f-36f0-5fbe-1ef8-c5105f6e4a52","market_ticker":"KXBTCPERP1","price":"6.3196","count":"1.00","taker_side":"ask","ts_ms":1781237160302}}

{"type":"trade","sid":2,"seq":1385,"msg":{"trade_id":"e0a5956c-8ebe-5d49-0a76-ce7bce594de5","market_ticker":"KXBTCPERP1","price":"6.3195","count":"1.00","taker_side":"ask","ts_ms":1781237160302}}

{"type":"trade","sid":2,"seq":1386,"msg":{"trade_id":"752ab12c-7f75-5b3c-045f-9a5e2c882ac4","market_ticker":"KXBTCPERP1","price":"6.3194","count":"1.00","taker_side":"ask","ts_ms":1781237160302}}

{"type":"trade","sid":2,"seq":1387,"msg":{"trade_id":"e062666f-3ccb-5b34-0456-6b53494de87e","market_ticker":"KXBTCPERP1","price":"6.3194","count":"1.00","taker_side":"ask","ts_ms":1781237160302}}

{"type":"trade","sid":2,"seq":1388,"msg":{"trade_id":"b3445503-9c36-5ef6-282b-f01eafbebed8","market_ticker":"KXBTCPERP1","price":"6.3194","count":"1.00","taker_side":"ask","ts_ms":1781237160302}}

{"type":"trade","sid":2,"seq":1389,"msg":{"trade_id":"7d3d8e73-8832-5e11-0c4f-2c35109b8849","market_ticker":"KXBTCPERP1","price":"6.3194","count":"1.00","taker_side":"ask","ts_ms":1781237160302}}

{"type":"trade","sid":2,"seq":1390,"msg":{"trade_id":"a944b075-b231-5a20-09ce-6b47ccc6e7ff","market_ticker":"KXBTCPERP1","price":"6.3194","count":"1.00","taker_side":"ask","ts_ms":1781237160302}}

{"type":"trade","sid":2,"seq":1391,"msg":{"trade_id":"6f5b586a-1b40-5e09-07f5-b1f583571928","market_ticker":"KXBTCPERP1","price":"6.3193","count":"1.00","taker_side":"ask","ts_ms":1781237160302}}

{"type":"trade","sid":2,"seq":1392,"msg":{"trade_id":"fde7e183-b042-5bc5-00fd-bca42cb293c7","market_ticker":"KXBTCPERP1","price":"6.3193","count":"1.00","taker_side":"ask","ts_ms":1781237160302}}

{"type":"trade","sid":2,"seq":1393,"msg":{"trade_id":"71fef019-1898-53eb-1ec3-0ada344204a3","market_ticker":"KXBTCPERP1","price":"6.3193","count":"1.00","taker_side":"ask","ts_ms":1781237160302}}

{"type":"trade","sid":2,"seq":1394,"msg":{"trade_id":"0e406bca-d67d-5815-1db7-849106827442","market_ticker":"KXBTCPERP1","price":"6.3193","count":"1.00","taker_side":"ask","ts_ms":1781237160302}}

{"type":"trade","sid":2,"seq":1395,"msg":{"trade_id":"94e634f9-ec3f-5425-3212-985cbf1850d0","market_ticker":"KXBTCPERP1","price":"6.3193","count":"1.00","taker_side":"ask","ts_ms":1781237160302}}

{"type":"trade","sid":2,"seq":1396,"msg":{"trade_id":"544daaef-97d2-5edb-2ee4-19ac7fddc8d5","market_ticker":"KXBTCPERP1","price":"6.3192","count":"1.00","taker_side":"ask","ts_ms":1781237160302}}

{"type":"trade","sid":2,"seq":1397,"msg":{"trade_id":"d07fbe7f-0dec-57ea-115b-57f0343bc69d","market_ticker":"KXBTCPERP1","price":"6.3192","count":"1.00","taker_side":"ask","ts_ms":1781237160302}}

{"type":"trade","sid":2,"seq":1398,"msg":{"trade_id":"a6706149-a684-5b20-070d-2e93a50a4081","market_ticker":"KXBTCPERP1","price":"6.3192","count":"1.00","taker_side":"ask","ts_ms":1781237160302}}

{"type":"trade","sid":2,"seq":1399,"msg":{"trade_id":"637df5c8-17c4-5c5f-2dfa-6d730da13dbf","market_ticker":"KXBTCPERP1","price":"6.3191","count":"1.00","taker_side":"ask","ts_ms":1781237160302}}

{"type":"trade","sid":2,"seq":1400,"msg":{"trade_id":"98fd8425-b609-5425-18ef-a70104d423a6","market_ticker":"KXBTCPERP1","price":"6.3191","count":"1.00","taker_side":"ask","ts_ms":1781237160302}}

{"type":"trade","sid":2,"seq":1401,"msg":{"trade_id":"e247353d-629d-5539-22de-d426a68844c4","market_ticker":"KXBTCPERP1","price":"6.3191","count":"1.00","taker_side":"ask","ts_ms":1781237160302}}

{"type":"trade","sid":2,"seq":1402,"msg":{"trade_id":"39948e83-f62b-5bb1-15b6-6d7f2e3a384f","market_ticker":"KXBTCPERP1","price":"6.3191","count":"1.00","taker_side":"ask","ts_ms":1781237160302}}

{"type":"trade","sid":2,"seq":1403,"msg":{"trade_id":"552dcd4a-0b07-5e4c-186f-883f8a2d5f07","market_ticker":"KXBTCPERP1","price":"6.3190","count":"1.00","taker_side":"ask","ts_ms":1781237160302}}

{"type":"trade","sid":2,"seq":1404,"msg":{"trade_id":"da1dd649-c491-5815-2ea9-747130966920","market_ticker":"KXBTCPERP1","price":"6.3190","count":"1.00","taker_side":"ask","ts_ms":1781237160302}}

{"type":"trade","sid":2,"seq":1405,"msg":{"trade_id":"1e962971-2997-5165-2475-e4956f18b8d0","market_ticker":"KXBTCPERP1","price":"6.3190","count":"1.00","taker_side":"ask","ts_ms":1781237160302}}

{"type":"trade","sid":2,"seq":1406,"msg":{"trade_id":"7cf85072-c327-5182-000e-e08fd25d5e91","market_ticker":"KXBTCPERP1","price":"6.3190","count":"1.00","taker_side":"ask","ts_ms":1781237160302}}

{"type":"trade","sid":2,"seq":1407,"msg":{"trade_id":"ab4aaee4-4920-5ff6-293f-fa6751f81418","market_ticker":"KXBTCPERP1","price":"6.3190","count":"1.00","taker_side":"ask","ts_ms":1781237160302}}

{"type":"trade","sid":2,"seq":1408,"msg":{"trade_id":"4b5b125b-cbbd-52c5-358f-698ba76dd2ec","market_ticker":"KXBTCPERP1","price":"6.3190","count":"1.00","taker_side":"ask","ts_ms":1781237160302}}

{"type":"trade","sid":2,"seq":1409,"msg":{"trade_id":"6233bd5f-1aa6-5b50-2393-59c906f206ea","market_ticker":"KXBTCPERP1","price":"6.3190","count":"1.00","taker_side":"ask","ts_ms":1781237160302}}

{"type":"trade","sid":2,"seq":1410,"msg":{"trade_id":"acb3c8ab-a760-5b8d-3073-426ee0070e1a","market_ticker":"KXBTCPERP1","price":"6.3189","count":"1.00","taker_side":"ask","ts_ms":1781237160302}}

{"type":"trade","sid":2,"seq":1411,"msg":{"trade_id":"0b65fa39-4a58-516e-1a00-12156945f871","market_ticker":"KXBTCPERP1","price":"6.3189","count":"1.00","taker_side":"ask","ts_ms":1781237160302}}

{"type":"trade","sid":2,"seq":1412,"msg":{"trade_id":"4f288cff-2770-58e6-0953-90969304bd2d","market_ticker":"KXBTCPERP1","price":"6.3189","count":"1.00","taker_side":"ask","ts_ms":1781237160302}}

{"type":"trade","sid":2,"seq":1413,"msg":{"trade_id":"9b10c234-25ad-5470-2dce-ee74c1949b11","market_ticker":"KXBTCPERP1","price":"6.3189","count":"1.00","taker_side":"ask","ts_ms":1781237160302}}

{"type":"trade","sid":2,"seq":1414,"msg":{"trade_id":"3fdd3c95-dc76-598e-03fc-92bca4d5fc3c","market_ticker":"KXBTCPERP1","price":"6.3189","count":"1.00","taker_side":"ask","ts_ms":1781237160302}}

{"type":"trade","sid":2,"seq":1415,"msg":{"trade_id":"6c5623c7-660e-5093-1f32-2bfe575a0502","market_ticker":"KXBTCPERP1","price":"6.3188","count":"1.00","taker_side":"ask","ts_ms":1781237160302}}

{"type":"trade","sid":2,"seq":1416,"msg":{"trade_id":"94e846ee-d883-5adc-1f9c-ef758ce3533b","market_ticker":"KXBTCPERP1","price":"6.3187","count":"1.00","taker_side":"ask","ts_ms":1781237160302}}

{"type":"trade","sid":2,"seq":1417,"msg":{"trade_id":"17710585-65a8-5485-3916-643a4143e56e","market_ticker":"KXBTCPERP1","price":"6.3187","count":"1.00","taker_side":"ask","ts_ms":1781237160302}}

{"type":"trade","sid":2,"seq":1418,"msg":{"trade_id":"e45b8077-1445-5b25-3727-8fd6ef9de603","market_ticker":"KXBTCPERP1","price":"6.3187","count":"1.00","taker_side":"ask","ts_ms":1781237160302}}

{"type":"trade","sid":2,"seq":1419,"msg":{"trade_id":"58be3089-8d6c-5ef3-3f76-8f8bb0200b44","market_ticker":"KXBTCPERP1","price":"6.3186","count":"1.00","taker_side":"ask","ts_ms":1781237160302}}

{"type":"trade","sid":2,"seq":1420,"msg":{"trade_id":"13f50105-b3d3-5983-022d-c4eba00c0cce","market_ticker":"KXBTCPERP1","price":"6.3186","count":"1.00","taker_side":"ask","ts_ms":1781237160302}}

{"type":"trade","sid":2,"seq":1421,"msg":{"trade_id":"89fd6e8c-93fa-5b71-1f4a-ffc494bf942b","market_ticker":"KXBTCPERP1","price":"6.3185","count":"1.00","taker_side":"ask","ts_ms":1781237160302}}

{"type":"trade","sid":2,"seq":1422,"msg":{"trade_id":"fb6585ac-2ca0-550f-1dd4-40423fb77adc","market_ticker":"KXBTCPERP1","price":"6.3185","count":"1.00","taker_side":"ask","ts_ms":1781237160302}}

{"type":"trade","sid":2,"seq":1423,"msg":{"trade_id":"7d4359ca-cf99-554b-17a9-d5dd072a87c4","market_ticker":"KXBTCPERP1","price":"6.3185","count":"1.00","taker_side":"ask","ts_ms":1781237160302}}

{"type":"trade","sid":2,"seq":1424,"msg":{"trade_id":"1674316b-f1f5-5428-39cd-f951cf8993b9","market_ticker":"KXBTCPERP1","price":"6.3185","count":"1.00","taker_side":"ask","ts_ms":1781237160302}}

{"type":"trade","sid":2,"seq":1425,"msg":{"trade_id":"497c50e3-b81e-5cb9-3f91-b9053037f434","market_ticker":"KXBTCPERP1","price":"6.3184","count":"1.00","taker_side":"ask","ts_ms":1781237160302}}

{"type":"trade","sid":2,"seq":1426,"msg":{"trade_id":"9ab78051-f687-5cd0-37a3-fa88d0025733","market_ticker":"KXBTCPERP1","price":"6.3184","count":"1.00","taker_side":"ask","ts_ms":1781237160302}}

{"type":"trade","sid":2,"seq":1427,"msg":{"trade_id":"0d7160e9-0771-540b-2f4a-60bd725ca985","market_ticker":"KXBTCPERP1","price":"6.3183","count":"1.00","taker_side":"ask","ts_ms":1781237160302}}

{"type":"trade","sid":2,"seq":1428,"msg":{"trade_id":"14de9732-3e87-524f-001f-92a7505a63cd","market_ticker":"KXBTCPERP1","price":"6.3183","count":"1.00","taker_side":"ask","ts_ms":1781237160302}}

{"type":"trade","sid":2,"seq":1429,"msg":{"trade_id":"9be9aeea-a695-581f-367b-041802c4a4dc","market_ticker":"KXBTCPERP1","price":"6.3182","count":"1.00","taker_side":"ask","ts_ms":1781237160302}}

{"type":"trade","sid":2,"seq":1430,"msg":{"trade_id":"c1fa5cee-813d-5c11-264d-b56682b089e0","market_ticker":"KXBTCPERP1","price":"6.3182","count":"1.00","taker_side":"ask","ts_ms":1781237160302}}

{"type":"trade","sid":2,"seq":1431,"msg":{"trade_id":"fe9a036e-8aa8-5dee-03fa-c461118ea3db","market_ticker":"KXBTCPERP1","price":"6.3182","count":"1.00","taker_side":"ask","ts_ms":1781237160302}}

{"type":"trade","sid":2,"seq":1432,"msg":{"trade_id":"d236067d-6cd2-5317-2908-e37ff29c5663","market_ticker":"KXBTCPERP1","price":"6.3182","count":"1.00","taker_side":"ask","ts_ms":1781237160302}}

{"type":"trade","sid":2,"seq":1433,"msg":{"trade_id":"1a93c211-4f2c-5598-2ff3-fa1b0e672bed","market_ticker":"KXBTCPERP1","price":"6.3181","count":"1.00","taker_side":"ask","ts_ms":1781237160302}}

{"type":"trade","sid":2,"seq":1434,"msg":{"trade_id":"03162c1b-b3bb-511b-0ada-2969f9e03831","market_ticker":"KXBTCPERP1","price":"6.3181","count":"1.00","taker_side":"ask","ts_ms":1781237160302}}

{"type":"trade","sid":2,"seq":1435,"msg":{"trade_id":"50303fb2-3a11-5d37-3559-922ae95756c9","market_ticker":"KXBTCPERP1","price":"6.3181","count":"1.00","taker_side":"ask","ts_ms":1781237160302}}

{"type":"trade","sid":2,"seq":1436,"msg":{"trade_id":"5ef0f6e8-a904-5bf9-2f13-f2ca251e2320","market_ticker":"KXBTCPERP1","price":"6.3181","count":"1.00","taker_side":"ask","ts_ms":1781237160302}}

{"type":"trade","sid":2,"seq":1437,"msg":{"trade_id":"3b4d3a6c-894d-54a4-3b50-899a9650cd50","market_ticker":"KXBTCPERP1","price":"6.3180","count":"1.00","taker_side":"ask","ts_ms":1781237160302}}

{"type":"trade","sid":2,"seq":1438,"msg":{"trade_id":"d246374d-a9b7-5415-07db-3baabdba0d48","market_ticker":"KXBTCPERP1","price":"6.3180","count":"1.00","taker_side":"ask","ts_ms":1781237160302}}

{"type":"trade","sid":2,"seq":1439,"msg":{"trade_id":"09c1b691-9e47-5d3c-17bc-3d19afef4132","market_ticker":"KXBTCPERP1","price":"6.3180","count":"1.00","taker_side":"ask","ts_ms":1781237160302}}

{"type":"trade","sid":2,"seq":1440,"msg":{"trade_id":"386805d0-3901-5858-0ee5-0b056155c769","market_ticker":"KXBTCPERP1","price":"6.3180","count":"1.00","taker_side":"ask","ts_ms":1781237160302}}

{"type":"trade","sid":2,"seq":1441,"msg":{"trade_id":"4592cf22-2707-50f3-186c-3c04042874a5","market_ticker":"KXBTCPERP1","price":"6.3180","count":"1.00","taker_side":"ask","ts_ms":1781237160302}}

{"type":"trade","sid":2,"seq":1442,"msg":{"trade_id":"0541d69b-f476-512e-07dd-d08478cae1ff","market_ticker":"KXBTCPERP1","price":"6.3180","count":"1.00","taker_side":"ask","ts_ms":1781237160302}}

{"type":"trade","sid":2,"seq":1443,"msg":{"trade_id":"e5784347-8514-5160-3e7a-53403b37ec06","market_ticker":"KXBTCPERP1","price":"6.3179","count":"1.00","taker_side":"ask","ts_ms":1781237160302}}

{"type":"trade","sid":2,"seq":1444,"msg":{"trade_id":"a77e4391-7ab8-5b50-1b44-be8bb2dd32d5","market_ticker":"KXBTCPERP1","price":"6.3179","count":"1.00","taker_side":"ask","ts_ms":1781237160302}}

{"type":"trade","sid":2,"seq":1445,"msg":{"trade_id":"d4f6f775-3150-5480-2be1-af4cda81a209","market_ticker":"KXBTCPERP1","price":"6.3179","count":"1.00","taker_side":"ask","ts_ms":1781237160302}}

{"type":"trade","sid":2,"seq":1446,"msg":{"trade_id":"7d1ec1f4-708a-530c-0553-7f34b84e22dd","market_ticker":"KXBTCPERP1","price":"6.3179","count":"1.00","taker_side":"ask","ts_ms":1781237160302}}

{"type":"trade","sid":2,"seq":1447,"msg":{"trade_id":"604e06c1-8c00-51a6-1bd2-30a429ee7796","market_ticker":"KXBTCPERP1","price":"6.3178","count":"1.00","taker_side":"ask","ts_ms":1781237160302}}

{"type":"trade","sid":2,"seq":1448,"msg":{"trade_id":"7a8ca002-e7e1-588b-3ab2-295073b8b4bd","market_ticker":"KXBTCPERP1","price":"6.3178","count":"1.00","taker_side":"ask","ts_ms":1781237160302}}

{"type":"trade","sid":2,"seq":1449,"msg":{"trade_id":"176a65b8-089a-534f-2104-d99b451f3586","market_ticker":"KXBTCPERP1","price":"6.3177","count":"1.00","taker_side":"ask","ts_ms":1781237160302}}

{"type":"trade","sid":2,"seq":1450,"msg":{"trade_id":"e5a8f283-5f09-5cda-2622-20816e2052ce","market_ticker":"KXBTCPERP1","price":"6.3177","count":"1.00","taker_side":"ask","ts_ms":1781237160302}}

{"type":"trade","sid":2,"seq":1451,"msg":{"trade_id":"01036cf2-d4cf-54d9-3fef-bb80d79600e7","market_ticker":"KXBTCPERP1","price":"6.3177","count":"1.00","taker_side":"ask","ts_ms":1781237160302}}

{"type":"trade","sid":2,"seq":1452,"msg":{"trade_id":"32073ffe-cc91-525c-130d-01684ba55fb7","market_ticker":"KXBTCPERP1","price":"6.3177","count":"1.00","taker_side":"ask","ts_ms":1781237160302}}

{"type":"trade","sid":2,"seq":1453,"msg":{"trade_id":"ab6761b9-c6a9-53a4-2e03-001da571c328","market_ticker":"KXBTCPERP1","price":"6.3177","count":"1.00","taker_side":"ask","ts_ms":1781237160302}}

{"type":"trade","sid":2,"seq":1454,"msg":{"trade_id":"5ece5fd0-b3e8-5ed2-2b3b-c71fcfd2d0e1","market_ticker":"KXBTCPERP1","price":"6.3176","count":"1.00","taker_side":"ask","ts_ms":1781237160302}}

{"type":"trade","sid":2,"seq":1455,"msg":{"trade_id":"5cd193c8-6085-56c8-004f-15eb6007463f","market_ticker":"KXBTCPERP1","price":"6.3176","count":"1.00","taker_side":"ask","ts_ms":1781237160302}}

{"type":"trade","sid":2,"seq":1456,"msg":{"trade_id":"3400a3e2-6440-586e-1b01-c5d1b387fc6e","market_ticker":"KXBTCPERP1","price":"6.3176","count":"1.00","taker_side":"ask","ts_ms":1781237160302}}

{"type":"trade","sid":2,"seq":1457,"msg":{"trade_id":"ab90b17d-e8e8-5922-0cc4-640213fa6333","market_ticker":"KXBTCPERP1","price":"6.3175","count":"1.00","taker_side":"ask","ts_ms":1781237160302}}

{"type":"trade","sid":2,"seq":1458,"msg":{"trade_id":"d5d25725-3340-522d-148a-3de2a1e72a5d","market_ticker":"KXBTCPERP1","price":"6.3175","count":"1.00","taker_side":"ask","ts_ms":1781237160302}}

{"type":"trade","sid":2,"seq":1459,"msg":{"trade_id":"12f9fa5e-04ab-5382-20f6-55782ac0de4c","market_ticker":"KXBTCPERP1","price":"6.3175","count":"1.00","taker_side":"ask","ts_ms":1781237160302}}

{"type":"trade","sid":2,"seq":1460,"msg":{"trade_id":"ed0e1244-3128-57c8-37e8-693755eee778","market_ticker":"KXBTCPERP1","price":"6.3175","count":"1.00","taker_side":"ask","ts_ms":1781237160302}}

{"type":"trade","sid":2,"seq":1461,"msg":{"trade_id":"c56ce90d-e51d-5bd8-28db-75b06c4f767f","market_ticker":"KXBTCPERP1","price":"6.3174","count":"1.00","taker_side":"ask","ts_ms":1781237160302}}

{"type":"trade","sid":2,"seq":1462,"msg":{"trade_id":"62a23b37-53e9-5de1-35bd-2899b72de8de","market_ticker":"KXBTCPERP1","price":"6.3174","count":"1.00","taker_side":"ask","ts_ms":1781237160302}}

{"type":"trade","sid":2,"seq":1463,"msg":{"trade_id":"b5cdc443-af29-5119-3426-0d98e4a8d7e0","market_ticker":"KXBTCPERP1","price":"6.3173","count":"1.00","taker_side":"ask","ts_ms":1781237160302}}

{"type":"trade","sid":2,"seq":1464,"msg":{"trade_id":"fd621d45-6097-5de4-1c7f-5a039900ab14","market_ticker":"KXBTCPERP1","price":"6.3172","count":"1.00","taker_side":"ask","ts_ms":1781237160302}}

{"type":"trade","sid":2,"seq":1465,"msg":{"trade_id":"2e092b22-8142-575b-0b89-b20882214e64","market_ticker":"KXBTCPERP1","price":"6.3172","count":"1.00","taker_side":"ask","ts_ms":1781237160302}}

{"type":"trade","sid":2,"seq":1466,"msg":{"trade_id":"f45d9d77-c731-5026-0969-24a45eeb2adf","market_ticker":"KXBTCPERP1","price":"6.3171","count":"1.00","taker_side":"ask","ts_ms":1781237160302}}

{"type":"trade","sid":2,"seq":1467,"msg":{"trade_id":"24ee2353-ab3d-5b3f-2c13-18bdcdbcabd9","market_ticker":"KXBTCPERP1","price":"6.3171","count":"1.00","taker_side":"ask","ts_ms":1781237160302}}

{"type":"trade","sid":2,"seq":1468,"msg":{"trade_id":"ffd76a48-369f-5f7c-1862-b2f2ac6a64a4","market_ticker":"KXBTCPERP1","price":"6.3171","count":"1.00","taker_side":"ask","ts_ms":1781237160302}}

{"type":"trade","sid":2,"seq":1469,"msg":{"trade_id":"dc70b1bd-5cab-5955-000c-47bd9e479e0c","market_ticker":"KXBTCPERP1","price":"6.3171","count":"1.00","taker_side":"ask","ts_ms":1781237160302}}

{"type":"trade","sid":2,"seq":1470,"msg":{"trade_id":"67e375f9-ddc7-56cb-3b0f-3dcf28ae3a36","market_ticker":"KXBTCPERP1","price":"6.3171","count":"1.00","taker_side":"ask","ts_ms":1781237160302}}

{"type":"trade","sid":2,"seq":1471,"msg":{"trade_id":"9d9f7848-92cf-5d80-2955-257bd8bad474","market_ticker":"KXBTCPERP1","price":"6.3171","count":"1.00","taker_side":"ask","ts_ms":1781237160302}}

{"type":"trade","sid":2,"seq":1472,"msg":{"trade_id":"db5fe86c-db1e-51f3-29cd-1bbf961ae0cb","market_ticker":"KXBTCPERP1","price":"6.3170","count":"1.00","taker_side":"ask","ts_ms":1781237160302}}

{"type":"trade","sid":2,"seq":1473,"msg":{"trade_id":"3863dea2-6cd1-5862-0ff0-6caaf00753be","market_ticker":"KXBTCPERP1","price":"6.3169","count":"1.00","taker_side":"ask","ts_ms":1781237160302}}

{"type":"trade","sid":2,"seq":1474,"msg":{"trade_id":"3c2ec43a-8214-5c60-2b78-8d18bf0444c7","market_ticker":"KXBTCPERP1","price":"6.3169","count":"1.00","taker_side":"ask","ts_ms":1781237160302}}

{"type":"trade","sid":2,"seq":1475,"msg":{"trade_id":"0549b78c-1f4a-5298-32c5-89853cb946a1","market_ticker":"KXBTCPERP1","price":"6.3169","count":"1.00","taker_side":"ask","ts_ms":1781237160302}}

{"type":"trade","sid":2,"seq":1476,"msg":{"trade_id":"b7a01963-6837-55a6-06c1-74e706b49b92","market_ticker":"KXBTCPERP1","price":"6.3169","count":"1.00","taker_side":"ask","ts_ms":1781237160302}}

{"type":"trade","sid":2,"seq":1477,"msg":{"trade_id":"cd7c9c54-2fdf-54d8-071d-fe818c75df92","market_ticker":"KXBTCPERP1","price":"6.3169","count":"1.00","taker_side":"ask","ts_ms":1781237160302}}

{"type":"trade","sid":2,"seq":1478,"msg":{"trade_id":"fe2710b5-ca28-5c47-2f25-55f8ccf7d712","market_ticker":"KXBTCPERP1","price":"6.3168","count":"1.00","taker_side":"ask","ts_ms":1781237160302}}

{"type":"trade","sid":2,"seq":1479,"msg":{"trade_id":"8285d601-4574-5a6d-1838-8874b44623b3","market_ticker":"KXBTCPERP1","price":"6.3168","count":"1.00","taker_side":"ask","ts_ms":1781237160302}}

{"type":"trade","sid":2,"seq":1480,"msg":{"trade_id":"fc58d49b-c2bb-5041-35bb-3e2d793dd31f","market_ticker":"KXBTCPERP1","price":"6.3168","count":"1.00","taker_side":"ask","ts_ms":1781237160302}}

{"type":"trade","sid":2,"seq":1481,"msg":{"trade_id":"8ec3b705-37a7-5d9d-36d5-c5b76c330f32","market_ticker":"KXBTCPERP1","price":"6.3168","count":"1.00","taker_side":"ask","ts_ms":1781237160302}}

{"type":"trade","sid":2,"seq":1482,"msg":{"trade_id":"d5726e67-f34a-5c14-2ec4-3e019d983ece","market_ticker":"KXBTCPERP1","price":"6.3168","count":"1.00","taker_side":"ask","ts_ms":1781237160302}}

{"type":"trade","sid":2,"seq":1483,"msg":{"trade_id":"317f9cbf-ac86-5a4e-3fc9-ab40476c9adf","market_ticker":"KXBTCPERP1","price":"6.3167","count":"1.00","taker_side":"ask","ts_ms":1781237160302}}

{"type":"trade","sid":2,"seq":1484,"msg":{"trade_id":"7fe1195b-eded-50ae-0054-53fcca49a79f","market_ticker":"KXBTCPERP1","price":"6.3167","count":"1.00","taker_side":"ask","ts_ms":1781237160302}}

{"type":"trade","sid":2,"seq":1485,"msg":{"trade_id":"196bf7a5-d339-59ce-3dee-766293817413","market_ticker":"KXBTCPERP1","price":"6.3167","count":"1.00","taker_side":"ask","ts_ms":1781237160302}}

{"type":"trade","sid":2,"seq":1486,"msg":{"trade_id":"6b5094b7-4672-5aa0-1b4a-b8954f2aae48","market_ticker":"KXBTCPERP1","price":"6.3167","count":"1.00","taker_side":"ask","ts_ms":1781237160302}}

{"type":"trade","sid":2,"seq":1487,"msg":{"trade_id":"5fb9a621-6c09-599c-22b4-f8b9a9b9e57a","market_ticker":"KXBTCPERP1","price":"6.3167","count":"1.00","taker_side":"ask","ts_ms":1781237160302}}

{"type":"trade","sid":2,"seq":1488,"msg":{"trade_id":"f9edf9ee-3e39-5d62-33cc-03a22b4fa5ba","market_ticker":"KXBTCPERP1","price":"6.3167","count":"1.00","taker_side":"ask","ts_ms":1781237160302}}

{"type":"trade","sid":2,"seq":1489,"msg":{"trade_id":"49115013-084f-5837-0332-aefbf5bf1638","market_ticker":"KXBTCPERP1","price":"6.3166","count":"1.00","taker_side":"ask","ts_ms":1781237160302}}

{"type":"trade","sid":2,"seq":1490,"msg":{"trade_id":"4352f60d-1a49-5ca9-3630-786ff2ab077a","market_ticker":"KXBTCPERP1","price":"6.3166","count":"1.00","taker_side":"ask","ts_ms":1781237160302}}

{"type":"trade","sid":2,"seq":1491,"msg":{"trade_id":"249fae87-b9b8-5faf-0133-aa6427cb58d6","market_ticker":"KXBTCPERP1","price":"6.3166","count":"1.00","taker_side":"ask","ts_ms":1781237160302}}

{"type":"trade","sid":2,"seq":1492,"msg":{"trade_id":"1e3db40b-954d-5e94-2130-17f583619525","market_ticker":"KXBTCPERP1","price":"6.3164","count":"1.00","taker_side":"ask","ts_ms":1781237160302}}

{"type":"trade","sid":2,"seq":1493,"msg":{"trade_id":"d9111e13-3107-57f6-3074-0162fc1dc931","market_ticker":"KXBTCPERP1","price":"6.3164","count":"1.00","taker_side":"ask","ts_ms":1781237160302}}

{"type":"trade","sid":2,"seq":1494,"msg":{"trade_id":"8c49f1cb-a5c0-5e3c-2eb0-81f6f4c6d468","market_ticker":"KXBTCPERP1","price":"6.3163","count":"1.00","taker_side":"ask","ts_ms":1781237160302}}

{"type":"trade","sid":2,"seq":1495,"msg":{"trade_id":"289e19ec-3ba9-5a32-2056-45edd0097f1b","market_ticker":"KXBTCPERP1","price":"6.3163","count":"1.00","taker_side":"ask","ts_ms":1781237160302}}

{"type":"trade","sid":2,"seq":1496,"msg":{"trade_id":"8bb32288-712b-50b8-24d0-768cfa7496ce","market_ticker":"KXBTCPERP1","price":"6.3163","count":"1.00","taker_side":"ask","ts_ms":1781237160302}}

{"type":"trade","sid":2,"seq":1497,"msg":{"trade_id":"5df51815-7f8f-5a25-1083-1673e8c3232d","market_ticker":"KXBTCPERP1","price":"6.3162","count":"1.00","taker_side":"ask","ts_ms":1781237160302}}

{"type":"trade","sid":2,"seq":1498,"msg":{"trade_id":"866a2d9f-9b81-5205-0c1f-de1033e8c5f7","market_ticker":"KXBTCPERP1","price":"6.3161","count":"1.00","taker_side":"ask","ts_ms":1781237160302}}

{"type":"trade","sid":2,"seq":1499,"msg":{"trade_id":"5184747b-5fb1-531c-270a-0dc3a787ef1b","market_ticker":"KXBTCPERP1","price":"6.3161","count":"1.00","taker_side":"ask","ts_ms":1781237160302}}

{"type":"trade","sid":2,"seq":1500,"msg":{"trade_id":"ca7b59de-953f-574c-200e-10f870972a9c","market_ticker":"KXBTCPERP1","price":"6.3160","count":"1.00","taker_side":"ask","ts_ms":1781237160302}}

{"type":"trade","sid":2,"seq":1501,"msg":{"trade_id":"dee3f69d-b565-59b7-3ec3-9c727ebfbb15","market_ticker":"KXBTCPERP1","price":"6.3160","count":"1.00","taker_side":"ask","ts_ms":1781237160302}}

{"type":"trade","sid":2,"seq":1502,"msg":{"trade_id":"eea15db2-83aa-5d11-0386-7a9a5df4c1c0","market_ticker":"KXBTCPERP1","price":"6.3160","count":"1.00","taker_side":"ask","ts_ms":1781237160302}}

{"type":"trade","sid":2,"seq":1503,"msg":{"trade_id":"07433272-4f9b-599b-2b9a-66bc215d9a93","market_ticker":"KXBTCPERP1","price":"6.3160","count":"1.00","taker_side":"ask","ts_ms":1781237160302}}

{"type":"trade","sid":2,"seq":1504,"msg":{"trade_id":"d635b5f2-d7b6-5c41-26dc-af1af38ae904","market_ticker":"KXBTCPERP1","price":"6.3160","count":"1.00","taker_side":"ask","ts_ms":1781237160302}}

{"type":"trade","sid":2,"seq":1505,"msg":{"trade_id":"3f85195a-f872-5a07-1142-9bbd7c37f822","market_ticker":"KXBTCPERP1","price":"6.3159","count":"1.00","taker_side":"ask","ts_ms":1781237160302}}

{"type":"trade","sid":2,"seq":1506,"msg":{"trade_id":"7d93447f-1b78-5d97-0258-3b529aca9717","market_ticker":"KXBTCPERP1","price":"6.3158","count":"1.00","taker_side":"ask","ts_ms":1781237160302}}

{"type":"trade","sid":2,"seq":1507,"msg":{"trade_id":"c7577def-8564-5307-05b9-b66bfed51d87","market_ticker":"KXBTCPERP1","price":"6.3156","count":"1.00","taker_side":"ask","ts_ms":1781237160302}}

{"type":"trade","sid":2,"seq":1508,"msg":{"trade_id":"e8723d4b-610c-5fdc-3c12-6fa34e3ed4d2","market_ticker":"KXBTCPERP1","price":"6.3156","count":"1.00","taker_side":"ask","ts_ms":1781237160302}}

{"type":"trade","sid":2,"seq":1509,"msg":{"trade_id":"4a66cd55-41dd-581e-06b9-de1fbaa34d3a","market_ticker":"KXBTCPERP1","price":"6.3156","count":"1.00","taker_side":"ask","ts_ms":1781237160302}}

{"type":"trade","sid":2,"seq":1510,"msg":{"trade_id":"158f59ae-077c-5812-2456-9da5c0a94f1d","market_ticker":"KXBTCPERP1","price":"6.3156","count":"1.00","taker_side":"ask","ts_ms":1781237160302}}

{"type":"trade","sid":2,"seq":1511,"msg":{"trade_id":"e2612833-756a-50fc-1c36-15c1c8605c17","market_ticker":"KXBTCPERP1","price":"6.3156","count":"1.00","taker_side":"ask","ts_ms":1781237160302}}

{"type":"trade","sid":2,"seq":1512,"msg":{"trade_id":"4a9539b9-c9a1-5a55-1e79-32a2111e0998","market_ticker":"KXBTCPERP1","price":"6.3155","count":"1.00","taker_side":"ask","ts_ms":1781237160302}}

{"type":"trade","sid":2,"seq":1513,"msg":{"trade_id":"87a10c7d-63be-53a9-10b6-491b7c1a26ed","market_ticker":"KXBTCPERP1","price":"6.3154","count":"1.00","taker_side":"ask","ts_ms":1781237160302}}

{"type":"trade","sid":2,"seq":1514,"msg":{"trade_id":"979ad8c9-117c-5b3a-0d36-a22a37b2b848","market_ticker":"KXBTCPERP1","price":"6.3154","count":"1.00","taker_side":"ask","ts_ms":1781237160302}}

{"type":"trade","sid":2,"seq":1515,"msg":{"trade_id":"9c60f0f9-f50c-5438-31cc-9bb3ee10666a","market_ticker":"KXBTCPERP1","price":"6.3154","count":"1.00","taker_side":"ask","ts_ms":1781237160302}}

{"type":"trade","sid":2,"seq":1516,"msg":{"trade_id":"da66077a-c6b8-5871-0bb5-8b8715178033","market_ticker":"KXBTCPERP1","price":"6.3154","count":"1.00","taker_side":"ask","ts_ms":1781237160302}}

{"type":"trade","sid":2,"seq":1517,"msg":{"trade_id":"7b4708a0-3536-5ec5-223a-3fb8064d23c9","market_ticker":"KXBTCPERP1","price":"6.3154","count":"1.00","taker_side":"ask","ts_ms":1781237160302}}

{"type":"trade","sid":2,"seq":1518,"msg":{"trade_id":"76bea5f8-25e9-5a82-3beb-c0b09429d25b","market_ticker":"KXBTCPERP1","price":"6.3153","count":"1.00","taker_side":"ask","ts_ms":1781237160302}}

{"type":"trade","sid":2,"seq":1519,"msg":{"trade_id":"c7c7f534-85e3-54b3-1f7d-68aa488403e6","market_ticker":"KXBTCPERP1","price":"6.3153","count":"1.00","taker_side":"ask","ts_ms":1781237160302}}

{"type":"trade","sid":2,"seq":1520,"msg":{"trade_id":"b76119a5-adae-50e1-0595-3e918001b2c4","market_ticker":"KXBTCPERP1","price":"6.3153","count":"1.00","taker_side":"ask","ts_ms":1781237160302}}

{"type":"trade","sid":2,"seq":1521,"msg":{"trade_id":"8a4ae72f-43f0-5eff-0a1d-63bac083f3c3","market_ticker":"KXBTCPERP1","price":"6.3153","count":"1.00","taker_side":"ask","ts_ms":1781237160302}}

{"type":"trade","sid":2,"seq":1522,"msg":{"trade_id":"fbbeb2ac-2c5b-5060-08c3-53692fb0de18","market_ticker":"KXBTCPERP1","price":"6.3152","count":"1.00","taker_side":"ask","ts_ms":1781237160302}}

{"type":"trade","sid":2,"seq":1523,"msg":{"trade_id":"4223425e-916e-501a-0e8b-91b22e0b81cc","market_ticker":"KXBTCPERP1","price":"6.3151","count":"1.00","taker_side":"ask","ts_ms":1781237160302}}

{"type":"trade","sid":2,"seq":1524,"msg":{"trade_id":"1b14e5a1-ef80-5eae-17f9-790ba0830ee1","market_ticker":"KXBTCPERP1","price":"6.3151","count":"1.00","taker_side":"ask","ts_ms":1781237160302}}

{"type":"trade","sid":2,"seq":1525,"msg":{"trade_id":"121cb886-8d1c-54f9-01bb-1c72740c3a2d","market_ticker":"KXBTCPERP1","price":"6.3151","count":"1.00","taker_side":"ask","ts_ms":1781237160302}}

{"type":"trade","sid":2,"seq":1526,"msg":{"trade_id":"54547797-6c1a-5f1d-00ca-575b475763df","market_ticker":"KXBTCPERP1","price":"6.3151","count":"1.00","taker_side":"ask","ts_ms":1781237160302}}

{"type":"trade","sid":2,"seq":1527,"msg":{"trade_id":"0ef24a29-5f98-59c2-3df4-96efb0f7f5f4","market_ticker":"KXBTCPERP1","price":"6.3151","count":"1.00","taker_side":"ask","ts_ms":1781237160302}}

{"type":"trade","sid":2,"seq":1528,"msg":{"trade_id":"9435d187-956d-521f-09bb-7f056cb6d9b0","market_ticker":"KXBTCPERP1","price":"6.3151","count":"1.00","taker_side":"ask","ts_ms":1781237160302}}

{"type":"trade","sid":2,"seq":1529,"msg":{"trade_id":"0b556b06-8fd5-5ebd-22fc-21e5e93a6ce0","market_ticker":"KXBTCPERP1","price":"6.3150","count":"1.00","taker_side":"ask","ts_ms":1781237160302}}

{"type":"trade","sid":2,"seq":1530,"msg":{"trade_id":"f604d18b-6f43-5d9c-1d85-570f3cb3fc0c","market_ticker":"KXBTCPERP1","price":"6.3150","count":"1.00","taker_side":"ask","ts_ms":1781237160302}}

{"type":"trade","sid":2,"seq":1531,"msg":{"trade_id":"c501e4af-264b-50cc-0b8a-a6b90e9a1609","market_ticker":"KXBTCPERP1","price":"6.3150","count":"1.00","taker_side":"ask","ts_ms":1781237160302}}

{"type":"trade","sid":2,"seq":1532,"msg":{"trade_id":"16ceb571-4e92-5ceb-36e3-9d9836f7a8a0","market_ticker":"KXBTCPERP1","price":"6.3150","count":"1.00","taker_side":"ask","ts_ms":1781237160302}}

{"type":"trade","sid":2,"seq":1533,"msg":{"trade_id":"6a963352-7bc0-520a-0ff9-da43f09206c4","market_ticker":"KXBTCPERP1","price":"6.3149","count":"1.00","taker_side":"ask","ts_ms":1781237160302}}

{"type":"trade","sid":2,"seq":1534,"msg":{"trade_id":"951b7f8c-cdce-56fe-1484-7cc78e1062f9","market_ticker":"KXBTCPERP1","price":"6.3148","count":"1.00","taker_side":"ask","ts_ms":1781237160302}}

{"type":"trade","sid":2,"seq":1535,"msg":{"trade_id":"59586f74-905b-593f-0b31-2273ee542db1","market_ticker":"KXBTCPERP1","price":"6.3148","count":"1.00","taker_side":"ask","ts_ms":1781237160302}}

{"type":"trade","sid":2,"seq":1536,"msg":{"trade_id":"0a9ac70e-3217-5075-01da-97954b86add3","market_ticker":"KXBTCPERP1","price":"6.3148","count":"1.00","taker_side":"ask","ts_ms":1781237160302}}

{"type":"trade","sid":2,"seq":1537,"msg":{"trade_id":"e3acd66c-df2f-5f75-2db4-1df86e462ab6","market_ticker":"KXBTCPERP1","price":"6.3146","count":"1.00","taker_side":"ask","ts_ms":1781237160302}}

{"type":"trade","sid":2,"seq":1538,"msg":{"trade_id":"8b5de87f-f0ac-5339-1ae0-92d47e9a5eb5","market_ticker":"KXBTCPERP1","price":"6.3146","count":"1.00","taker_side":"ask","ts_ms":1781237160302}}

{"type":"trade","sid":2,"seq":1539,"msg":{"trade_id":"cddc7928-6db8-5c6d-310c-f57810024209","market_ticker":"KXBTCPERP1","price":"6.3145","count":"1.00","taker_side":"ask","ts_ms":1781237160302}}

{"type":"trade","sid":2,"seq":1540,"msg":{"trade_id":"b836484c-4b5b-57f6-3a7e-ba4aba9d2b9f","market_ticker":"KXBTCPERP1","price":"6.3145","count":"1.00","taker_side":"ask","ts_ms":1781237160302}}

{"type":"trade","sid":2,"seq":1541,"msg":{"trade_id":"1e3df1d4-0031-5093-1d9a-7331c1b763f6","market_ticker":"KXBTCPERP1","price":"6.3144","count":"1.00","taker_side":"ask","ts_ms":1781237160302}}

{"type":"trade","sid":2,"seq":1542,"msg":{"trade_id":"63248554-8ffb-5497-335f-70b15e8ac83a","market_ticker":"KXBTCPERP1","price":"6.3143","count":"1.00","taker_side":"ask","ts_ms":1781237160302}}

{"type":"trade","sid":2,"seq":1543,"msg":{"trade_id":"c2e7da5a-3112-5d2d-3497-3c0654f9e107","market_ticker":"KXBTCPERP1","price":"6.3143","count":"1.00","taker_side":"ask","ts_ms":1781237160302}}

{"type":"trade","sid":2,"seq":1544,"msg":{"trade_id":"086245e5-335c-5c5f-1bca-afad24889e2c","market_ticker":"KXBTCPERP1","price":"6.3143","count":"1.00","taker_side":"ask","ts_ms":1781237160302}}

{"type":"trade","sid":2,"seq":1545,"msg":{"trade_id":"ecdd55cb-ca8e-56dc-22bf-49a8da4ff407","market_ticker":"KXBTCPERP1","price":"6.3142","count":"1.00","taker_side":"ask","ts_ms":1781237160302}}

{"type":"trade","sid":2,"seq":1546,"msg":{"trade_id":"98350446-bd5e-5b1a-00c8-56b145ba1c5b","market_ticker":"KXBTCPERP1","price":"6.3141","count":"1.00","taker_side":"ask","ts_ms":1781237160302}}

{"type":"trade","sid":2,"seq":1547,"msg":{"trade_id":"139bb947-f558-5235-0886-b674591c1d79","market_ticker":"KXBTCPERP1","price":"6.3141","count":"1.00","taker_side":"ask","ts_ms":1781237160302}}

{"type":"trade","sid":2,"seq":1548,"msg":{"trade_id":"001832d6-3e58-53ca-1050-7e63fe1045f4","market_ticker":"KXBTCPERP1","price":"6.3140","count":"1.00","taker_side":"ask","ts_ms":1781237160302}}

{"type":"trade","sid":2,"seq":1549,"msg":{"trade_id":"061a01e9-316d-5d3e-2f61-bf3a3720ede7","market_ticker":"KXBTCPERP1","price":"6.3140","count":"1.00","taker_side":"ask","ts_ms":1781237160302}}

{"type":"trade","sid":2,"seq":1550,"msg":{"trade_id":"eec99566-f425-5d1d-3076-2c232ed72b30","market_ticker":"KXBTCPERP1","price":"6.3139","count":"1.00","taker_side":"ask","ts_ms":1781237160302}}

{"type":"trade","sid":2,"seq":1551,"msg":{"trade_id":"1fa6112e-2647-51e6-1a00-f7eab28779b0","market_ticker":"KXBTCPERP1","price":"6.3139","count":"1.00","taker_side":"ask","ts_ms":1781237160302}}

{"type":"trade","sid":2,"seq":1552,"msg":{"trade_id":"f6b68856-e13b-5aaf-2809-581d27b9b5fa","market_ticker":"KXBTCPERP1","price":"6.3139","count":"1.00","taker_side":"ask","ts_ms":1781237160302}}

{"type":"trade","sid":2,"seq":1553,"msg":{"trade_id":"81e5b8ca-0fcc-5b6f-29bc-499f6aac82aa","market_ticker":"KXBTCPERP1","price":"6.3139","count":"1.00","taker_side":"ask","ts_ms":1781237160302}}

{"type":"trade","sid":2,"seq":1554,"msg":{"trade_id":"8c1aa1a1-0b1a-5079-268b-37ae3ea005c3","market_ticker":"KXBTCPERP1","price":"6.3139","count":"1.00","taker_side":"ask","ts_ms":1781237160302}}

{"type":"trade","sid":2,"seq":1555,"msg":{"trade_id":"9207bb0d-7395-5f15-31d4-96f9935da745","market_ticker":"KXBTCPERP1","price":"6.3138","count":"1.00","taker_side":"ask","ts_ms":1781237160302}}

{"type":"trade","sid":2,"seq":1556,"msg":{"trade_id":"7ef347b2-0ace-5f8a-0f68-44ae3772961c","market_ticker":"KXBTCPERP1","price":"6.3137","count":"1.00","taker_side":"ask","ts_ms":1781237160302}}

{"type":"trade","sid":2,"seq":1557,"msg":{"trade_id":"a86dbbf5-6111-5adc-0154-224f95169449","market_ticker":"KXBTCPERP1","price":"6.3137","count":"1.00","taker_side":"ask","ts_ms":1781237160302}}

{"type":"trade","sid":2,"seq":1558,"msg":{"trade_id":"8fd87ca6-b1ae-50ff-11c5-397f241c731e","market_ticker":"KXBTCPERP1","price":"6.3137","count":"1.00","taker_side":"ask","ts_ms":1781237160302}}

{"type":"trade","sid":2,"seq":1559,"msg":{"trade_id":"d796184e-5b37-5d8e-2db3-fa339d1326a0","market_ticker":"KXBTCPERP1","price":"6.3137","count":"1.00","taker_side":"ask","ts_ms":1781237160302}}

{"type":"trade","sid":2,"seq":1560,"msg":{"trade_id":"70abe4ce-ccdd-5f0b-2360-6a4abbc25b2b","market_ticker":"KXBTCPERP1","price":"6.3136","count":"1.00","taker_side":"ask","ts_ms":1781237160302}}

{"type":"trade","sid":2,"seq":1561,"msg":{"trade_id":"ed032270-dc33-572e-2537-6d8ba06ee748","market_ticker":"KXBTCPERP1","price":"6.3135","count":"1.00","taker_side":"ask","ts_ms":1781237160302}}

{"type":"trade","sid":2,"seq":1562,"msg":{"trade_id":"45c21303-204e-568b-3286-0ec5c1d1233b","market_ticker":"KXBTCPERP1","price":"6.3135","count":"1.00","taker_side":"ask","ts_ms":1781237160302}}

{"type":"trade","sid":2,"seq":1563,"msg":{"trade_id":"e416fde3-2793-5e17-09c9-c4dc5ffdefab","market_ticker":"KXBTCPERP1","price":"6.3134","count":"1.00","taker_side":"ask","ts_ms":1781237160302}}

{"type":"trade","sid":2,"seq":1564,"msg":{"trade_id":"094f1955-cfae-5b31-2df5-350fc279ff1f","market_ticker":"KXBTCPERP1","price":"6.3134","count":"1.00","taker_side":"ask","ts_ms":1781237160302}}

{"type":"trade","sid":2,"seq":1565,"msg":{"trade_id":"dc077ac5-f387-5663-1d54-66ba92429380","market_ticker":"KXBTCPERP1","price":"6.3133","count":"1.00","taker_side":"ask","ts_ms":1781237160302}}

{"type":"trade","sid":2,"seq":1566,"msg":{"trade_id":"a9e8111f-cdec-5cf7-368b-8c65e628eb5b","market_ticker":"KXBTCPERP1","price":"6.3133","count":"1.00","taker_side":"ask","ts_ms":1781237160302}}

{"type":"trade","sid":2,"seq":1567,"msg":{"trade_id":"e1f2d780-f14a-5d59-3df0-0e80e8e2fe7c","market_ticker":"KXBTCPERP1","price":"6.3133","count":"1.00","taker_side":"ask","ts_ms":1781237160302}}

{"type":"trade","sid":2,"seq":1568,"msg":{"trade_id":"a95afc3c-6b22-5a2c-202b-3ab6c3129ec6","market_ticker":"KXBTCPERP1","price":"6.3133","count":"1.00","taker_side":"ask","ts_ms":1781237160302}}

{"type":"trade","sid":2,"seq":1569,"msg":{"trade_id":"33ddf63f-ee81-5db5-236f-a11d2d20f65c","market_ticker":"KXBTCPERP1","price":"6.3132","count":"1.00","taker_side":"ask","ts_ms":1781237160302}}

{"type":"trade","sid":2,"seq":1570,"msg":{"trade_id":"b74b7915-f3a6-5c09-0860-dce7ee412638","market_ticker":"KXBTCPERP1","price":"6.3132","count":"1.00","taker_side":"ask","ts_ms":1781237160302}}

{"type":"trade","sid":2,"seq":1571,"msg":{"trade_id":"2421a7d8-9c66-547e-3914-8aaa1b36e3d4","market_ticker":"KXBTCPERP1","price":"6.3130","count":"1.00","taker_side":"ask","ts_ms":1781237160302}}

{"type":"trade","sid":2,"seq":1572,"msg":{"trade_id":"f4a425eb-4ec9-5d02-0a87-8bdd83d74284","market_ticker":"KXBTCPERP1","price":"6.3130","count":"1.00","taker_side":"ask","ts_ms":1781237160302}}

{"type":"trade","sid":2,"seq":1573,"msg":{"trade_id":"0d3ad71c-1228-5e3f-2499-a0972cbc6335","market_ticker":"KXBTCPERP1","price":"6.3130","count":"1.00","taker_side":"ask","ts_ms":1781237160302}}

{"type":"trade","sid":2,"seq":1574,"msg":{"trade_id":"93b6a784-7b35-5bbe-0ab9-85d3425d703c","market_ticker":"KXBTCPERP1","price":"6.3130","count":"1.00","taker_side":"ask","ts_ms":1781237160302}}

{"type":"trade","sid":2,"seq":1575,"msg":{"trade_id":"f718e7e5-bf78-52a3-05a3-b3afcd620e1e","market_ticker":"KXBTCPERP1","price":"6.3130","count":"1.00","taker_side":"ask","ts_ms":1781237160302}}

{"type":"trade","sid":2,"seq":1576,"msg":{"trade_id":"bacb359e-4c8d-5de7-0b3d-4003c38859e0","market_ticker":"KXBTCPERP1","price":"6.3130","count":"1.00","taker_side":"ask","ts_ms":1781237160302}}

{"type":"trade","sid":2,"seq":1577,"msg":{"trade_id":"89630ef4-9e1f-59cc-0228-0459866508ab","market_ticker":"KXBTCPERP1","price":"6.3129","count":"1.00","taker_side":"ask","ts_ms":1781237160302}}

{"type":"trade","sid":2,"seq":1578,"msg":{"trade_id":"d3b555cd-9997-572c-23a7-d246172aa9c0","market_ticker":"KXBTCPERP1","price":"6.3129","count":"1.00","taker_side":"ask","ts_ms":1781237160302}}

{"type":"trade","sid":2,"seq":1579,"msg":{"trade_id":"a74f6fb3-1d2e-5ae0-240d-5beefea78ed9","market_ticker":"KXBTCPERP1","price":"6.3129","count":"1.00","taker_side":"ask","ts_ms":1781237160302}}

{"type":"trade","sid":2,"seq":1580,"msg":{"trade_id":"f563dec3-7718-51d5-03b5-3569851f890b","market_ticker":"KXBTCPERP1","price":"6.3129","count":"1.00","taker_side":"ask","ts_ms":1781237160302}}

{"type":"trade","sid":2,"seq":1581,"msg":{"trade_id":"2ab12f62-2bc6-5dc6-2894-cc0b0483a01e","market_ticker":"KXBTCPERP1","price":"6.3129","count":"1.00","taker_side":"ask","ts_ms":1781237160302}}

{"type":"trade","sid":2,"seq":1582,"msg":{"trade_id":"1950d72e-0c3c-54cf-3627-afccde17652a","market_ticker":"KXBTCPERP1","price":"6.3129","count":"1.00","taker_side":"ask","ts_ms":1781237160302}}

{"type":"trade","sid":2,"seq":1583,"msg":{"trade_id":"9d656a9b-dbe9-5e3f-3b60-73af62a507f3","market_ticker":"KXBTCPERP1","price":"6.3128","count":"1.00","taker_side":"ask","ts_ms":1781237160302}}

{"type":"trade","sid":2,"seq":1584,"msg":{"trade_id":"d254c285-bd8e-57e1-3a26-7fa7737a6e9b","market_ticker":"KXBTCPERP1","price":"6.3128","count":"1.00","taker_side":"ask","ts_ms":1781237160302}}

{"type":"trade","sid":2,"seq":1585,"msg":{"trade_id":"e52cc6e9-c96e-57f4-17ee-32e8fa5a7fe0","market_ticker":"KXBTCPERP1","price":"6.3128","count":"1.00","taker_side":"ask","ts_ms":1781237160302}}

{"type":"trade","sid":2,"seq":1586,"msg":{"trade_id":"61bc6290-1160-51ca-2410-1777e26e4584","market_ticker":"KXBTCPERP1","price":"6.3127","count":"1.00","taker_side":"ask","ts_ms":1781237160302}}

{"type":"trade","sid":2,"seq":1587,"msg":{"trade_id":"0a57aad0-6921-56c6-3b11-01bfcbf73c5b","market_ticker":"KXBTCPERP1","price":"6.3127","count":"1.00","taker_side":"ask","ts_ms":1781237160302}}

{"type":"trade","sid":2,"seq":1588,"msg":{"trade_id":"ef42113b-eda9-537c-03f9-6dcb008cfeea","market_ticker":"KXBTCPERP1","price":"6.3127","count":"1.00","taker_side":"ask","ts_ms":1781237160302}}

{"type":"trade","sid":2,"seq":1589,"msg":{"trade_id":"148ef147-350a-5245-2c41-7329f6f2ee95","market_ticker":"KXBTCPERP1","price":"6.3126","count":"1.00","taker_side":"ask","ts_ms":1781237160302}}

{"type":"trade","sid":2,"seq":1590,"msg":{"trade_id":"376bb1ca-2ca0-5c4e-2ed1-34dc985cd77e","market_ticker":"KXBTCPERP1","price":"6.3126","count":"1.00","taker_side":"ask","ts_ms":1781237160302}}

{"type":"trade","sid":2,"seq":1591,"msg":{"trade_id":"db17da62-3007-5af5-37a1-0d2b767d1838","market_ticker":"KXBTCPERP1","price":"6.3126","count":"1.00","taker_side":"ask","ts_ms":1781237160302}}

{"type":"trade","sid":2,"seq":1592,"msg":{"trade_id":"931cd992-da46-503b-105d-aa66ceea0ec8","market_ticker":"KXBTCPERP1","price":"6.3126","count":"1.00","taker_side":"ask","ts_ms":1781237160302}}

{"type":"trade","sid":2,"seq":1593,"msg":{"trade_id":"91fa2e5e-7317-5a73-13e6-b790c37434fc","market_ticker":"KXBTCPERP1","price":"6.3125","count":"1.00","taker_side":"ask","ts_ms":1781237160302}}

{"type":"trade","sid":2,"seq":1594,"msg":{"trade_id":"2c3789fc-a576-5673-3ab7-42484a9a4bd7","market_ticker":"KXBTCPERP1","price":"6.3125","count":"1.00","taker_side":"ask","ts_ms":1781237160302}}

{"type":"trade","sid":2,"seq":1595,"msg":{"trade_id":"78a34e61-d9b9-561f-1399-953de20260cc","market_ticker":"KXBTCPERP1","price":"6.3125","count":"1.00","taker_side":"ask","ts_ms":1781237160302}}

{"type":"trade","sid":2,"seq":1596,"msg":{"trade_id":"4fefe712-600d-5c6d-12d0-e8004e5ba92f","market_ticker":"KXBTCPERP1","price":"6.3124","count":"1.00","taker_side":"ask","ts_ms":1781237160302}}

{"type":"trade","sid":2,"seq":1597,"msg":{"trade_id":"6772029b-73da-5556-2b67-88754d84e2be","market_ticker":"KXBTCPERP1","price":"6.3124","count":"1.00","taker_side":"ask","ts_ms":1781237160302}}

{"type":"trade","sid":2,"seq":1598,"msg":{"trade_id":"b3216e96-7943-59c3-1328-4d1d4d9f66b5","market_ticker":"KXBTCPERP1","price":"6.3124","count":"1.00","taker_side":"ask","ts_ms":1781237160302}}

{"type":"trade","sid":2,"seq":1599,"msg":{"trade_id":"8411af50-9584-5638-1a7d-d799f558241f","market_ticker":"KXBTCPERP1","price":"6.3124","count":"1.00","taker_side":"ask","ts_ms":1781237160302}}

{"type":"trade","sid":2,"seq":1600,"msg":{"trade_id":"7657f5fb-ce27-5469-3084-5bb395e1fc66","market_ticker":"KXBTCPERP1","price":"6.3124","count":"1.00","taker_side":"ask","ts_ms":1781237160302}}

{"type":"trade","sid":2,"seq":1601,"msg":{"trade_id":"23372b9e-55bd-5392-0b88-b982c00287a1","market_ticker":"KXBTCPERP1","price":"6.3124","count":"1.00","taker_side":"ask","ts_ms":1781237160302}}

{"type":"trade","sid":2,"seq":1602,"msg":{"trade_id":"b09bc387-0c17-5f4d-3f89-985fc819f612","market_ticker":"KXBTCPERP1","price":"6.3123","count":"1.00","taker_side":"ask","ts_ms":1781237160302}}

{"type":"trade","sid":2,"seq":1603,"msg":{"trade_id":"0586f9a5-a06d-5856-356f-49171266976a","market_ticker":"KXBTCPERP1","price":"6.3123","count":"1.00","taker_side":"ask","ts_ms":1781237160302}}

{"type":"trade","sid":2,"seq":1604,"msg":{"trade_id":"6f5fe80d-d73a-5374-2acf-0936be077e76","market_ticker":"KXBTCPERP1","price":"6.3122","count":"1.00","taker_side":"ask","ts_ms":1781237160302}}

{"type":"trade","sid":2,"seq":1605,"msg":{"trade_id":"b82b8e4a-5296-5d43-0410-e77b563c504a","market_ticker":"KXBTCPERP1","price":"6.3122","count":"1.00","taker_side":"ask","ts_ms":1781237160302}}

{"type":"trade","sid":2,"seq":1606,"msg":{"trade_id":"6f5b38d5-0f23-59af-026e-3d07526be62b","market_ticker":"KXBTCPERP1","price":"6.3122","count":"1.00","taker_side":"ask","ts_ms":1781237160302}}

{"type":"trade","sid":2,"seq":1607,"msg":{"trade_id":"f63af4c9-644c-5320-0560-1afd2c007913","market_ticker":"KXBTCPERP1","price":"6.3122","count":"1.00","taker_side":"ask","ts_ms":1781237160302}}

{"type":"trade","sid":2,"seq":1608,"msg":{"trade_id":"a5873753-a28e-5227-3d47-c9af8b92eced","market_ticker":"KXBTCPERP1","price":"6.3122","count":"1.00","taker_side":"ask","ts_ms":1781237160302}}

{"type":"trade","sid":2,"seq":1609,"msg":{"trade_id":"06c0b246-af6d-52ed-3403-4c5462664b88","market_ticker":"KXBTCPERP1","price":"6.3121","count":"1.00","taker_side":"ask","ts_ms":1781237160302}}

{"type":"trade","sid":2,"seq":1610,"msg":{"trade_id":"5e805c57-9822-5538-183e-3492598abe37","market_ticker":"KXBTCPERP1","price":"6.3121","count":"1.00","taker_side":"ask","ts_ms":1781237160302}}

{"type":"trade","sid":2,"seq":1611,"msg":{"trade_id":"620f39ed-9aaf-5ca6-144c-4a16b831dde4","market_ticker":"KXBTCPERP1","price":"6.3121","count":"1.00","taker_side":"ask","ts_ms":1781237160302}}

{"type":"trade","sid":2,"seq":1612,"msg":{"trade_id":"61f7ccb4-dc11-5203-214f-a00a80f2dbfc","market_ticker":"KXBTCPERP1","price":"6.3120","count":"1.00","taker_side":"ask","ts_ms":1781237160302}}

{"type":"trade","sid":2,"seq":1613,"msg":{"trade_id":"3ce9de6c-7acd-5e67-1575-46ed0527f8a2","market_ticker":"KXBTCPERP1","price":"6.3120","count":"1.00","taker_side":"ask","ts_ms":1781237160302}}

{"type":"trade","sid":2,"seq":1614,"msg":{"trade_id":"2bd0f8e0-0bfe-5468-12c6-807842f02806","market_ticker":"KXBTCPERP1","price":"6.3120","count":"1.00","taker_side":"ask","ts_ms":1781237160302}}

{"type":"trade","sid":2,"seq":1615,"msg":{"trade_id":"35ae34df-d9d4-5919-0461-7a7ead92b16b","market_ticker":"KXBTCPERP1","price":"6.3119","count":"1.00","taker_side":"ask","ts_ms":1781237160302}}

{"type":"trade","sid":2,"seq":1616,"msg":{"trade_id":"c3df5b8d-0ee8-54d5-2b5b-29924689f1a7","market_ticker":"KXBTCPERP1","price":"6.3119","count":"1.00","taker_side":"ask","ts_ms":1781237160302}}

{"type":"trade","sid":2,"seq":1617,"msg":{"trade_id":"ecb67e39-e024-5ea6-004e-d6cb224d361a","market_ticker":"KXBTCPERP1","price":"6.3118","count":"1.00","taker_side":"ask","ts_ms":1781237160302}}

{"type":"trade","sid":2,"seq":1618,"msg":{"trade_id":"3e0bb8c7-8a34-50ad-3e10-a2f4176873d2","market_ticker":"KXBTCPERP1","price":"6.3118","count":"1.00","taker_side":"ask","ts_ms":1781237160302}}

{"type":"trade","sid":2,"seq":1619,"msg":{"trade_id":"62e2a35e-c315-5d57-146d-d346a76135d4","market_ticker":"KXBTCPERP1","price":"6.3118","count":"1.00","taker_side":"ask","ts_ms":1781237160302}}

{"type":"trade","sid":2,"seq":1620,"msg":{"trade_id":"9993b289-2d22-5dc3-3323-4eb0966b3a3c","market_ticker":"KXBTCPERP1","price":"6.3118","count":"1.00","taker_side":"ask","ts_ms":1781237160302}}

{"type":"trade","sid":2,"seq":1621,"msg":{"trade_id":"3d489bab-22a4-5163-306b-96aaa0defa51","market_ticker":"KXBTCPERP1","price":"6.3118","count":"1.00","taker_side":"ask","ts_ms":1781237160302}}

{"type":"trade","sid":2,"seq":1622,"msg":{"trade_id":"e941d8d3-3e96-5779-07f4-4f66b09a7e29","market_ticker":"KXBTCPERP1","price":"6.3117","count":"1.00","taker_side":"ask","ts_ms":1781237160302}}

{"type":"trade","sid":2,"seq":1623,"msg":{"trade_id":"98a5f9e1-56f6-5070-2fd0-ef6b8986c578","market_ticker":"KXBTCPERP1","price":"6.3117","count":"1.00","taker_side":"ask","ts_ms":1781237160302}}

{"type":"trade","sid":2,"seq":1624,"msg":{"trade_id":"14f35a7b-3750-5742-2620-b3ba7d1efab0","market_ticker":"KXBTCPERP1","price":"6.3116","count":"1.00","taker_side":"ask","ts_ms":1781237160302}}

{"type":"trade","sid":2,"seq":1625,"msg":{"trade_id":"1ea2fb6c-de0e-56e8-2ce9-1a21162c5c7d","market_ticker":"KXBTCPERP1","price":"6.3116","count":"1.00","taker_side":"ask","ts_ms":1781237160302}}

{"type":"trade","sid":2,"seq":1626,"msg":{"trade_id":"7b601f71-d7a1-59ef-22e7-6f13c015c7f0","market_ticker":"KXBTCPERP1","price":"6.3116","count":"1.00","taker_side":"ask","ts_ms":1781237160302}}

{"type":"trade","sid":2,"seq":1627,"msg":{"trade_id":"5e1130be-84da-5aa4-2b98-9d494af6cbbe","market_ticker":"KXBTCPERP1","price":"6.3116","count":"1.00","taker_side":"ask","ts_ms":1781237160302}}

{"type":"trade","sid":2,"seq":1628,"msg":{"trade_id":"84450dd9-a870-5cd3-28e4-a53adf5ff534","market_ticker":"KXBTCPERP1","price":"6.3116","count":"1.00","taker_side":"ask","ts_ms":1781237160302}}

{"type":"trade","sid":2,"seq":1629,"msg":{"trade_id":"7e6438ef-12a1-5393-1dee-c476c9a0162e","market_ticker":"KXBTCPERP1","price":"6.3116","count":"1.00","taker_side":"ask","ts_ms":1781237160302}}

{"type":"trade","sid":2,"seq":1630,"msg":{"trade_id":"a7f88c8e-b98e-5ba8-08c6-43a1fdf1ec45","market_ticker":"KXBTCPERP1","price":"6.3116","count":"1.00","taker_side":"ask","ts_ms":1781237160302}}

{"type":"trade","sid":2,"seq":1631,"msg":{"trade_id":"1a5cf13f-3819-59eb-3a9d-e05ec679ec79","market_ticker":"KXBTCPERP1","price":"6.3115","count":"1.00","taker_side":"ask","ts_ms":1781237160302}}

{"type":"trade","sid":2,"seq":1632,"msg":{"trade_id":"eff0fe63-afe6-56f6-36fd-e6e387bf76ff","market_ticker":"KXBTCPERP1","price":"6.3115","count":"1.00","taker_side":"ask","ts_ms":1781237160302}}

{"type":"trade","sid":2,"seq":1633,"msg":{"trade_id":"4464eda1-4783-5c64-0d1b-a75333edf8d3","market_ticker":"KXBTCPERP1","price":"6.3114","count":"1.00","taker_side":"ask","ts_ms":1781237160302}}

{"type":"trade","sid":2,"seq":1634,"msg":{"trade_id":"3dddd349-6cdf-5c8d-2ee4-47017513f586","market_ticker":"KXBTCPERP1","price":"6.3114","count":"1.00","taker_side":"ask","ts_ms":1781237160302}}

{"type":"trade","sid":2,"seq":1635,"msg":{"trade_id":"a44a8541-a3cd-5496-3757-ec7198d832dd","market_ticker":"KXBTCPERP1","price":"6.3114","count":"1.00","taker_side":"ask","ts_ms":1781237160302}}

{"type":"trade","sid":2,"seq":1636,"msg":{"trade_id":"20779760-91a7-514f-286c-5954076e5df3","market_ticker":"KXBTCPERP1","price":"6.3113","count":"1.00","taker_side":"ask","ts_ms":1781237160302}}

{"type":"trade","sid":2,"seq":1637,"msg":{"trade_id":"65df9d63-7d73-5e33-268f-723d22806bb8","market_ticker":"KXBTCPERP1","price":"6.3113","count":"1.00","taker_side":"ask","ts_ms":1781237160302}}

{"type":"trade","sid":2,"seq":1638,"msg":{"trade_id":"52b5f9bb-a125-510a-3cd5-86c36a247c36","market_ticker":"KXBTCPERP1","price":"6.3113","count":"1.00","taker_side":"ask","ts_ms":1781237160302}}

{"type":"trade","sid":2,"seq":1639,"msg":{"trade_id":"90d1fbd5-a2e5-59f0-3bd5-809979bf143b","market_ticker":"KXBTCPERP1","price":"6.3113","count":"1.00","taker_side":"ask","ts_ms":1781237160302}}

{"type":"trade","sid":2,"seq":1640,"msg":{"trade_id":"ebab7d1d-f9e4-5cc5-1da0-d1d330d4635e","market_ticker":"KXBTCPERP1","price":"6.3113","count":"1.00","taker_side":"ask","ts_ms":1781237160302}}

{"type":"trade","sid":2,"seq":1641,"msg":{"trade_id":"467e11f3-6c3c-5b9f-26e2-42e6edda4bfc","market_ticker":"KXBTCPERP1","price":"6.3112","count":"1.00","taker_side":"ask","ts_ms":1781237160302}}

{"type":"trade","sid":2,"seq":1642,"msg":{"trade_id":"99e1cef8-23b2-52a5-2e98-ae7550b743fc","market_ticker":"KXBTCPERP1","price":"6.3112","count":"1.00","taker_side":"ask","ts_ms":1781237160302}}

{"type":"trade","sid":2,"seq":1643,"msg":{"trade_id":"f9f5b0fb-3dcb-509f-0b45-74852a74792a","market_ticker":"KXBTCPERP1","price":"6.3112","count":"1.00","taker_side":"ask","ts_ms":1781237160302}}

{"type":"trade","sid":2,"seq":1644,"msg":{"trade_id":"8d2dd567-730d-5a88-00f0-c273b2d0229d","market_ticker":"KXBTCPERP1","price":"6.3112","count":"1.00","taker_side":"ask","ts_ms":1781237160302}}

{"type":"trade","sid":2,"seq":1645,"msg":{"trade_id":"c0cb9ede-7b92-5ecc-0c34-ec71161ba62b","market_ticker":"KXBTCPERP1","price":"6.3111","count":"1.00","taker_side":"ask","ts_ms":1781237160302}}

{"type":"trade","sid":2,"seq":1646,"msg":{"trade_id":"60475c8f-ba8f-54a9-36e0-63007cdfbc8a","market_ticker":"KXBTCPERP1","price":"6.3111","count":"1.00","taker_side":"ask","ts_ms":1781237160302}}

{"type":"trade","sid":2,"seq":1647,"msg":{"trade_id":"b84f79a6-4e44-53f6-169b-65796ab24d04","market_ticker":"KXBTCPERP1","price":"6.3111","count":"1.00","taker_side":"ask","ts_ms":1781237160302}}

{"type":"trade","sid":2,"seq":1648,"msg":{"trade_id":"5ac6aed5-7882-5c97-27a2-0f73e579625a","market_ticker":"KXBTCPERP1","price":"6.3110","count":"1.00","taker_side":"ask","ts_ms":1781237160302}}

{"type":"trade","sid":2,"seq":1649,"msg":{"trade_id":"702ff1c2-b4bf-55f3-132b-fb6c5adf42f2","market_ticker":"KXBTCPERP1","price":"6.3109","count":"1.00","taker_side":"ask","ts_ms":1781237160302}}

{"type":"trade","sid":2,"seq":1650,"msg":{"trade_id":"1dc351b1-6d4a-56cd-23e8-e11bd7a2e464","market_ticker":"KXBTCPERP1","price":"6.3109","count":"1.00","taker_side":"ask","ts_ms":1781237160302}}

{"type":"trade","sid":2,"seq":1651,"msg":{"trade_id":"2bb7496f-02b2-5f26-33dc-4ec7c0235667","market_ticker":"KXBTCPERP1","price":"6.3108","count":"1.00","taker_side":"ask","ts_ms":1781237160302}}

{"type":"trade","sid":2,"seq":1652,"msg":{"trade_id":"4831ffc8-7574-56f7-3a3c-4c049073f3f5","market_ticker":"KXBTCPERP1","price":"6.3107","count":"1.00","taker_side":"ask","ts_ms":1781237160302}}

{"type":"trade","sid":2,"seq":1653,"msg":{"trade_id":"620cf339-8322-5e57-0572-6baa6393ac33","market_ticker":"KXBTCPERP1","price":"6.3106","count":"1.00","taker_side":"ask","ts_ms":1781237160302}}

{"type":"trade","sid":2,"seq":1654,"msg":{"trade_id":"c299a451-3cdc-536b-24f5-9f4cf931a95a","market_ticker":"KXBTCPERP1","price":"6.3106","count":"1.00","taker_side":"ask","ts_ms":1781237160302}}

{"type":"trade","sid":2,"seq":1655,"msg":{"trade_id":"515ff40b-e7c6-5c1c-0a49-a8a48fbc8be6","market_ticker":"KXBTCPERP1","price":"6.3106","count":"1.00","taker_side":"ask","ts_ms":1781237160302}}

{"type":"trade","sid":2,"seq":1656,"msg":{"trade_id":"9cf392d9-87a9-5aac-21a9-8cd39ac1605b","market_ticker":"KXBTCPERP1","price":"6.3106","count":"1.00","taker_side":"ask","ts_ms":1781237160302}}

{"type":"trade","sid":2,"seq":1657,"msg":{"trade_id":"03b35cc5-3cfc-513d-253d-109ddfc43ac4","market_ticker":"KXBTCPERP1","price":"6.3106","count":"1.00","taker_side":"ask","ts_ms":1781237160302}}

{"type":"trade","sid":2,"seq":1658,"msg":{"trade_id":"11ee12e0-6db4-58e5-3e18-72a678cf40d7","market_ticker":"KXBTCPERP1","price":"6.3105","count":"1.00","taker_side":"ask","ts_ms":1781237160302}}

{"type":"trade","sid":2,"seq":1659,"msg":{"trade_id":"a226c42c-aa72-5d18-1a84-c3e54490ef71","market_ticker":"KXBTCPERP1","price":"6.3105","count":"1.00","taker_side":"ask","ts_ms":1781237160302}}

{"type":"trade","sid":2,"seq":1660,"msg":{"trade_id":"34988766-b8cf-5386-2aa2-684c3a4c1ec7","market_ticker":"KXBTCPERP1","price":"6.3105","count":"1.00","taker_side":"ask","ts_ms":1781237160302}}

{"type":"trade","sid":2,"seq":1661,"msg":{"trade_id":"e15a2ddf-e6aa-5a9b-1fed-674143f2c4ae","market_ticker":"KXBTCPERP1","price":"6.3105","count":"1.00","taker_side":"ask","ts_ms":1781237160302}}

{"type":"trade","sid":2,"seq":1662,"msg":{"trade_id":"ce5365e6-9ba5-5ad0-0622-2f6b3c7d5167","market_ticker":"KXBTCPERP1","price":"6.3104","count":"1.00","taker_side":"ask","ts_ms":1781237160302}}

{"type":"trade","sid":2,"seq":1663,"msg":{"trade_id":"76522668-7233-5282-1df5-d871ad7061f1","market_ticker":"KXBTCPERP1","price":"6.3104","count":"1.00","taker_side":"ask","ts_ms":1781237160302}}

{"type":"trade","sid":2,"seq":1664,"msg":{"trade_id":"05e68d5c-2190-583d-0d50-31a874978aff","market_ticker":"KXBTCPERP1","price":"6.3104","count":"1.00","taker_side":"ask","ts_ms":1781237160302}}

{"type":"trade","sid":2,"seq":1665,"msg":{"trade_id":"b277cb6e-13d0-5fe7-0cb6-6c23d5fd7385","market_ticker":"KXBTCPERP1","price":"6.3104","count":"1.00","taker_side":"ask","ts_ms":1781237160302}}

{"type":"trade","sid":2,"seq":1666,"msg":{"trade_id":"2fb67ab6-e9f8-5c44-231d-571eafd1d6fb","market_ticker":"KXBTCPERP1","price":"6.3104","count":"1.00","taker_side":"ask","ts_ms":1781237160302}}

{"type":"trade","sid":2,"seq":1667,"msg":{"trade_id":"a05afa79-4d67-501e-3a8f-5af29c0b55f8","market_ticker":"KXBTCPERP1","price":"6.3103","count":"1.00","taker_side":"ask","ts_ms":1781237160302}}

{"type":"trade","sid":2,"seq":1668,"msg":{"trade_id":"94191c5e-3ae7-5b2b-1646-1898bf37bed3","market_ticker":"KXBTCPERP1","price":"6.3103","count":"1.00","taker_side":"ask","ts_ms":1781237160302}}

{"type":"trade","sid":2,"seq":1669,"msg":{"trade_id":"c46a6820-3af8-53a1-3852-e840cd58e8b1","market_ticker":"KXBTCPERP1","price":"6.3103","count":"1.00","taker_side":"ask","ts_ms":1781237160302}}

{"type":"trade","sid":2,"seq":1670,"msg":{"trade_id":"f0d930fa-5a2b-5723-0bab-7cd717afbb81","market_ticker":"KXBTCPERP1","price":"6.3103","count":"1.00","taker_side":"ask","ts_ms":1781237160302}}

{"type":"trade","sid":2,"seq":1671,"msg":{"trade_id":"a5e9a078-f996-5dde-0c9c-f2b05d3c9a7d","market_ticker":"KXBTCPERP1","price":"6.3103","count":"1.00","taker_side":"ask","ts_ms":1781237160302}}

{"type":"trade","sid":2,"seq":1672,"msg":{"trade_id":"99d6a2ae-398e-50bf-0790-635abebac0eb","market_ticker":"KXBTCPERP1","price":"6.3103","count":"1.00","taker_side":"ask","ts_ms":1781237160302}}

{"type":"trade","sid":2,"seq":1673,"msg":{"trade_id":"69f20ae2-9f03-5b15-0e05-c5a996c993d8","market_ticker":"KXBTCPERP1","price":"6.3102","count":"1.00","taker_side":"ask","ts_ms":1781237160302}}

{"type":"trade","sid":2,"seq":1674,"msg":{"trade_id":"5d040d6b-98d9-5dc7-261e-3dc3aec2a156","market_ticker":"KXBTCPERP1","price":"6.3102","count":"1.00","taker_side":"ask","ts_ms":1781237160302}}

{"type":"trade","sid":2,"seq":1675,"msg":{"trade_id":"e6670d53-0f54-52ee-3e29-09c9c80c1063","market_ticker":"KXBTCPERP1","price":"6.3101","count":"1.00","taker_side":"ask","ts_ms":1781237160302}}

{"type":"trade","sid":2,"seq":1676,"msg":{"trade_id":"274f8010-5384-5306-0592-470b7c0511e5","market_ticker":"KXBTCPERP1","price":"6.3101","count":"1.00","taker_side":"ask","ts_ms":1781237160302}}

{"type":"trade","sid":2,"seq":1677,"msg":{"trade_id":"64f6de65-b37c-5efc-1153-8bdb56e5280b","market_ticker":"KXBTCPERP1","price":"6.3101","count":"1.00","taker_side":"ask","ts_ms":1781237160302}}

{"type":"trade","sid":2,"seq":1678,"msg":{"trade_id":"551f62d8-50c4-587b-355f-16a4879c59f4","market_ticker":"KXBTCPERP1","price":"6.3101","count":"1.00","taker_side":"ask","ts_ms":1781237160302}}

{"type":"trade","sid":2,"seq":1679,"msg":{"trade_id":"441b3962-896f-5279-36cf-c9793415c9d2","market_ticker":"KXBTCPERP1","price":"6.3100","count":"1.00","taker_side":"ask","ts_ms":1781237160302}}

{"type":"trade","sid":2,"seq":1680,"msg":{"trade_id":"43129369-4a23-5fb7-128f-0b9957db533e","market_ticker":"KXBTCPERP1","price":"6.3100","count":"1.00","taker_side":"ask","ts_ms":1781237160302}}

{"type":"trade","sid":2,"seq":1681,"msg":{"trade_id":"8008cf3c-45f5-5358-3dec-53f6c94a1bc6","market_ticker":"KXBTCPERP1","price":"6.3100","count":"1.00","taker_side":"ask","ts_ms":1781237160302}}

{"type":"trade","sid":2,"seq":1682,"msg":{"trade_id":"c20ba6f6-07de-5f0d-15ac-e3acc2986534","market_ticker":"KXBTCPERP1","price":"6.3099","count":"1.00","taker_side":"ask","ts_ms":1781237160302}}

{"type":"trade","sid":2,"seq":1683,"msg":{"trade_id":"19c4b24e-efca-59aa-399d-cd5ce18a7077","market_ticker":"KXBTCPERP1","price":"6.3098","count":"1.00","taker_side":"ask","ts_ms":1781237160302}}

{"type":"trade","sid":2,"seq":1684,"msg":{"trade_id":"14370124-f72d-50c1-18da-fe19636e11df","market_ticker":"KXBTCPERP1","price":"6.3098","count":"1.00","taker_side":"ask","ts_ms":1781237160302}}

{"type":"trade","sid":2,"seq":1685,"msg":{"trade_id":"4781858d-3cca-5e0b-0460-891d68748fec","market_ticker":"KXBTCPERP1","price":"6.3097","count":"1.00","taker_side":"ask","ts_ms":1781237160302}}

{"type":"trade","sid":2,"seq":1686,"msg":{"trade_id":"12a0d0df-32b5-57c5-0bd4-ec5176c17a41","market_ticker":"KXBTCPERP1","price":"6.3096","count":"1.00","taker_side":"ask","ts_ms":1781237160302}}

{"type":"trade","sid":2,"seq":1687,"msg":{"trade_id":"b39e5f61-f2c3-5bb4-14c6-3baa5e116f44","market_ticker":"KXBTCPERP1","price":"6.3096","count":"1.00","taker_side":"ask","ts_ms":1781237160302}}

{"type":"trade","sid":2,"seq":1688,"msg":{"trade_id":"fbe89e6a-6bc0-5e3e-320c-2115c4b74b18","market_ticker":"KXBTCPERP1","price":"6.3095","count":"1.00","taker_side":"ask","ts_ms":1781237160302}}

{"type":"trade","sid":2,"seq":1689,"msg":{"trade_id":"adfc3fef-2cc2-5405-2071-8b2c2b9dc7a1","market_ticker":"KXBTCPERP1","price":"6.3095","count":"1.00","taker_side":"ask","ts_ms":1781237160302}}

{"type":"trade","sid":2,"seq":1690,"msg":{"trade_id":"f1896a2f-edb3-58fc-1cb8-0dde1b0e75df","market_ticker":"KXBTCPERP1","price":"6.3095","count":"1.00","taker_side":"ask","ts_ms":1781237160302}}

{"type":"trade","sid":2,"seq":1691,"msg":{"trade_id":"b8b1b6b9-67d2-5b9c-0d71-fbfb93ed2424","market_ticker":"KXBTCPERP1","price":"6.3095","count":"1.00","taker_side":"ask","ts_ms":1781237160302}}

{"type":"trade","sid":2,"seq":1692,"msg":{"trade_id":"687fdb32-cf96-5d95-0e21-520182cc260f","market_ticker":"KXBTCPERP1","price":"6.3095","count":"1.00","taker_side":"ask","ts_ms":1781237160302}}

{"type":"trade","sid":2,"seq":1693,"msg":{"trade_id":"9adf335d-a28f-5e7d-33d3-572f968f32a5","market_ticker":"KXBTCPERP1","price":"6.3094","count":"1.00","taker_side":"ask","ts_ms":1781237160302}}

{"type":"trade","sid":2,"seq":1694,"msg":{"trade_id":"e1e1726a-ee26-550b-0465-9e2da1adc55e","market_ticker":"KXBTCPERP1","price":"6.3094","count":"1.00","taker_side":"ask","ts_ms":1781237160302}}

{"type":"trade","sid":2,"seq":1695,"msg":{"trade_id":"beea7084-1b1c-5fd9-17c1-faff98030b25","market_ticker":"KXBTCPERP1","price":"6.3094","count":"1.00","taker_side":"ask","ts_ms":1781237160302}}

{"type":"trade","sid":2,"seq":1696,"msg":{"trade_id":"caf08af5-4a2b-5ede-2fb0-592eff712b0f","market_ticker":"KXBTCPERP1","price":"6.3093","count":"1.00","taker_side":"ask","ts_ms":1781237160302}}

{"type":"trade","sid":2,"seq":1697,"msg":{"trade_id":"1cdae9b7-f393-56ae-3ebc-7c02a143442b","market_ticker":"KXBTCPERP1","price":"6.3093","count":"1.00","taker_side":"ask","ts_ms":1781237160302}}

{"type":"trade","sid":2,"seq":1698,"msg":{"trade_id":"dda1733a-09fa-50aa-2de6-8760fe68534c","market_ticker":"KXBTCPERP1","price":"6.3093","count":"1.00","taker_side":"ask","ts_ms":1781237160302}}

{"type":"trade","sid":2,"seq":1699,"msg":{"trade_id":"44bc3657-af0f-51e8-39b5-2c38006ca31c","market_ticker":"KXBTCPERP1","price":"6.3093","count":"1.00","taker_side":"ask","ts_ms":1781237160302}}

{"type":"trade","sid":2,"seq":1700,"msg":{"trade_id":"baa0f37b-ce27-5c46-102c-9e64615ad769","market_ticker":"KXBTCPERP1","price":"6.3093","count":"1.00","taker_side":"ask","ts_ms":1781237160302}}

{"type":"trade","sid":2,"seq":1701,"msg":{"trade_id":"f68add7a-9168-5f0f-00f3-1e0d6e33a0d2","market_ticker":"KXBTCPERP1","price":"6.3092","count":"1.00","taker_side":"ask","ts_ms":1781237160302}}

{"type":"trade","sid":2,"seq":1702,"msg":{"trade_id":"e7b1a3ce-5618-5354-3859-150b543b92ed","market_ticker":"KXBTCPERP1","price":"6.3092","count":"1.00","taker_side":"ask","ts_ms":1781237160302}}

{"type":"trade","sid":2,"seq":1703,"msg":{"trade_id":"9dd14f18-947a-546c-2bd2-3c983fa4f38e","market_ticker":"KXBTCPERP1","price":"6.3092","count":"1.00","taker_side":"ask","ts_ms":1781237160302}}

{"type":"trade","sid":2,"seq":1704,"msg":{"trade_id":"7951db87-bed1-5d0b-04da-4c4421212d6c","market_ticker":"KXBTCPERP1","price":"6.3090","count":"1.00","taker_side":"ask","ts_ms":1781237160302}}

{"type":"trade","sid":2,"seq":1705,"msg":{"trade_id":"78c6ef1c-5147-5a5c-3b8b-6a9f5bb17518","market_ticker":"KXBTCPERP1","price":"6.3090","count":"1.00","taker_side":"ask","ts_ms":1781237160302}}

{"type":"trade","sid":2,"seq":1706,"msg":{"trade_id":"29fd66b7-e873-5c41-37df-c79dbd6a2f6f","market_ticker":"KXBTCPERP1","price":"6.3089","count":"1.00","taker_side":"ask","ts_ms":1781237160302}}

{"type":"trade","sid":2,"seq":1707,"msg":{"trade_id":"6891e97a-120f-591c-0e84-407e7e96faa3","market_ticker":"KXBTCPERP1","price":"6.3089","count":"1.00","taker_side":"ask","ts_ms":1781237160302}}

{"type":"trade","sid":2,"seq":1708,"msg":{"trade_id":"f3a43bb5-837c-5bbb-032c-dd77c4af598b","market_ticker":"KXBTCPERP1","price":"6.3089","count":"1.00","taker_side":"ask","ts_ms":1781237160302}}

{"type":"trade","sid":2,"seq":1709,"msg":{"trade_id":"88d0c260-2fd2-5dd7-2c19-9a11877293dc","market_ticker":"KXBTCPERP1","price":"6.3089","count":"1.00","taker_side":"ask","ts_ms":1781237160302}}

{"type":"trade","sid":2,"seq":1710,"msg":{"trade_id":"448fc953-f5cc-511d-1adc-f16ac09bb38d","market_ticker":"KXBTCPERP1","price":"6.3088","count":"1.00","taker_side":"ask","ts_ms":1781237160302}}

{"type":"trade","sid":2,"seq":1711,"msg":{"trade_id":"f6368545-7519-53ad-366e-95537405e869","market_ticker":"KXBTCPERP1","price":"6.3088","count":"1.00","taker_side":"ask","ts_ms":1781237160302}}

{"type":"trade","sid":2,"seq":1712,"msg":{"trade_id":"32bccaf5-3910-5566-2f41-862d5d2d163f","market_ticker":"KXBTCPERP1","price":"6.3088","count":"1.00","taker_side":"ask","ts_ms":1781237160302}}

{"type":"trade","sid":2,"seq":1713,"msg":{"trade_id":"6f126f43-d949-504b-39a8-941340cbcd85","market_ticker":"KXBTCPERP1","price":"6.3087","count":"1.00","taker_side":"ask","ts_ms":1781237160302}}

{"type":"trade","sid":2,"seq":1714,"msg":{"trade_id":"ca689989-5461-5578-1005-54ef23052dc7","market_ticker":"KXBTCPERP1","price":"6.3086","count":"1.00","taker_side":"ask","ts_ms":1781237160302}}

{"type":"trade","sid":2,"seq":1715,"msg":{"trade_id":"32ac5603-3360-54a2-33a4-143d1079ea08","market_ticker":"KXBTCPERP1","price":"6.3086","count":"1.00","taker_side":"ask","ts_ms":1781237160302}}

{"type":"trade","sid":2,"seq":1716,"msg":{"trade_id":"e3a12fb9-05d9-50fe-3a9d-f344e3303347","market_ticker":"KXBTCPERP1","price":"6.3086","count":"1.00","taker_side":"ask","ts_ms":1781237160302}}

{"type":"trade","sid":2,"seq":1717,"msg":{"trade_id":"40a7972d-dd77-59eb-39d7-09ec95403700","market_ticker":"KXBTCPERP1","price":"6.3086","count":"1.00","taker_side":"ask","ts_ms":1781237160302}}

{"type":"trade","sid":2,"seq":1718,"msg":{"trade_id":"d58bb293-d452-57a8-1545-5ae8609c69f6","market_ticker":"KXBTCPERP1","price":"6.3085","count":"1.00","taker_side":"ask","ts_ms":1781237160302}}

{"type":"trade","sid":2,"seq":1719,"msg":{"trade_id":"65a9ec67-33d6-5bb6-2b5e-7508a48e6c62","market_ticker":"KXBTCPERP1","price":"6.3085","count":"1.00","taker_side":"ask","ts_ms":1781237160302}}

{"type":"trade","sid":2,"seq":1720,"msg":{"trade_id":"4d51ef1d-7c4c-50d2-17c8-473cf3ca7637","market_ticker":"KXBTCPERP1","price":"6.3085","count":"1.00","taker_side":"ask","ts_ms":1781237160302}}

{"type":"trade","sid":2,"seq":1721,"msg":{"trade_id":"afd4e299-c2db-5fe5-0d4b-64e58daac0ee","market_ticker":"KXBTCPERP1","price":"6.3083","count":"1.00","taker_side":"ask","ts_ms":1781237160302}}

{"type":"trade","sid":2,"seq":1722,"msg":{"trade_id":"2ed73069-16e5-55f3-2325-6b71e7436c43","market_ticker":"KXBTCPERP1","price":"6.3083","count":"1.00","taker_side":"ask","ts_ms":1781237160302}}

{"type":"trade","sid":2,"seq":1723,"msg":{"trade_id":"dd0bf54c-cf70-5cb2-0d94-be4136ebe903","market_ticker":"KXBTCPERP1","price":"6.3083","count":"1.00","taker_side":"ask","ts_ms":1781237160302}}

{"type":"trade","sid":2,"seq":1724,"msg":{"trade_id":"17680ed8-938f-5854-2716-2acc209297b4","market_ticker":"KXBTCPERP1","price":"6.3083","count":"1.00","taker_side":"ask","ts_ms":1781237160302}}

{"type":"trade","sid":2,"seq":1725,"msg":{"trade_id":"3b2a6e2f-822e-568d-2d7a-487d262d0d3f","market_ticker":"KXBTCPERP1","price":"6.3083","count":"1.00","taker_side":"ask","ts_ms":1781237160302}}

{"type":"trade","sid":2,"seq":1726,"msg":{"trade_id":"e5ca22f4-74d1-5b69-2823-f3d422262ca5","market_ticker":"KXBTCPERP1","price":"6.3082","count":"1.00","taker_side":"ask","ts_ms":1781237160302}}

{"type":"trade","sid":2,"seq":1727,"msg":{"trade_id":"5b9e2cc9-c077-53ee-329d-625a47f91181","market_ticker":"KXBTCPERP1","price":"6.3081","count":"1.00","taker_side":"ask","ts_ms":1781237160302}}

{"type":"trade","sid":2,"seq":1728,"msg":{"trade_id":"5c307c7b-3be3-537e-08d7-054377cb3c5d","market_ticker":"KXBTCPERP1","price":"6.3081","count":"1.00","taker_side":"ask","ts_ms":1781237160302}}

{"type":"trade","sid":2,"seq":1729,"msg":{"trade_id":"3c545f68-17bf-59dd-06b5-48e0d4d5896a","market_ticker":"KXBTCPERP1","price":"6.3080","count":"1.00","taker_side":"ask","ts_ms":1781237160302}}

{"type":"trade","sid":2,"seq":1730,"msg":{"trade_id":"0cb1d7f2-4d78-5a77-028b-b50149ba0e83","market_ticker":"KXBTCPERP1","price":"6.3080","count":"1.00","taker_side":"ask","ts_ms":1781237160302}}

{"type":"trade","sid":2,"seq":1731,"msg":{"trade_id":"b35c2e5a-86b3-5083-1b52-9f19cecc32ef","market_ticker":"KXBTCPERP1","price":"6.3080","count":"1.00","taker_side":"ask","ts_ms":1781237160302}}

{"type":"trade","sid":2,"seq":1732,"msg":{"trade_id":"ea7b0fbd-20c2-5743-277a-dd14b999f2a0","market_ticker":"KXBTCPERP1","price":"6.3080","count":"1.00","taker_side":"ask","ts_ms":1781237160302}}

{"type":"trade","sid":2,"seq":1733,"msg":{"trade_id":"381d24f8-31ca-5998-33a4-447c76ea6164","market_ticker":"KXBTCPERP1","price":"6.3080","count":"1.00","taker_side":"ask","ts_ms":1781237160302}}

{"type":"trade","sid":2,"seq":1734,"msg":{"trade_id":"5f3d49b6-0cd0-5da1-0782-2f31e5a227e1","market_ticker":"KXBTCPERP1","price":"6.3079","count":"1.00","taker_side":"ask","ts_ms":1781237160302}}

{"type":"trade","sid":2,"seq":1735,"msg":{"trade_id":"a62c5f40-ad20-54e8-1c13-a1ff73948149","market_ticker":"KXBTCPERP1","price":"6.3079","count":"1.00","taker_side":"ask","ts_ms":1781237160302}}

{"type":"trade","sid":2,"seq":1736,"msg":{"trade_id":"78066707-d6f1-5990-3c53-0fef50e88892","market_ticker":"KXBTCPERP1","price":"6.3079","count":"1.00","taker_side":"ask","ts_ms":1781237160302}}

{"type":"trade","sid":2,"seq":1737,"msg":{"trade_id":"d0a8cbac-3011-5383-1504-0f40475afee2","market_ticker":"KXBTCPERP1","price":"6.3078","count":"1.00","taker_side":"ask","ts_ms":1781237160302}}

{"type":"trade","sid":2,"seq":1738,"msg":{"trade_id":"629d83a6-8221-5186-3af0-2d9a0f4720a0","market_ticker":"KXBTCPERP1","price":"6.3078","count":"1.00","taker_side":"ask","ts_ms":1781237160302}}

{"type":"trade","sid":2,"seq":1739,"msg":{"trade_id":"0ce6e890-1c07-585c-0d70-bac62ee71732","market_ticker":"KXBTCPERP1","price":"6.3077","count":"1.00","taker_side":"ask","ts_ms":1781237160302}}

{"type":"trade","sid":2,"seq":1740,"msg":{"trade_id":"4b7e5855-b744-52fb-1785-f8b95954cbbf","market_ticker":"KXBTCPERP1","price":"6.3076","count":"1.00","taker_side":"ask","ts_ms":1781237160302}}

{"type":"trade","sid":2,"seq":1741,"msg":{"trade_id":"3ec3fd09-42e7-569f-1cb4-4df1c0a8fea8","market_ticker":"KXBTCPERP1","price":"6.3076","count":"1.00","taker_side":"ask","ts_ms":1781237160302}}

{"type":"trade","sid":2,"seq":1742,"msg":{"trade_id":"ca94158d-daaa-5c99-2179-6a8aa21eb757","market_ticker":"KXBTCPERP1","price":"6.3076","count":"1.00","taker_side":"ask","ts_ms":1781237160302}}

{"type":"trade","sid":2,"seq":1743,"msg":{"trade_id":"5645b1dc-2e1b-542d-121b-43d4f572b957","market_ticker":"KXBTCPERP1","price":"6.3076","count":"1.00","taker_side":"ask","ts_ms":1781237160302}}

{"type":"trade","sid":2,"seq":1744,"msg":{"trade_id":"a8377d07-25c9-5199-1c75-1cf5c3b15a4f","market_ticker":"KXBTCPERP1","price":"6.3076","count":"1.00","taker_side":"ask","ts_ms":1781237160302}}

{"type":"trade","sid":2,"seq":1745,"msg":{"trade_id":"0551b1f7-6c2b-5436-2d8c-1f1c81e27c69","market_ticker":"KXBTCPERP1","price":"6.3075","count":"1.00","taker_side":"ask","ts_ms":1781237160302}}

{"type":"trade","sid":2,"seq":1746,"msg":{"trade_id":"ce937c36-9ef9-5bbc-20b6-8277bde31443","market_ticker":"KXBTCPERP1","price":"6.3075","count":"1.00","taker_side":"ask","ts_ms":1781237160302}}

{"type":"trade","sid":2,"seq":1747,"msg":{"trade_id":"d6ed4ceb-c656-505e-0e6f-4969c3aea1f9","market_ticker":"KXBTCPERP1","price":"6.3075","count":"1.00","taker_side":"ask","ts_ms":1781237160302}}

{"type":"trade","sid":2,"seq":1748,"msg":{"trade_id":"7501f7a7-0000-571f-124b-490a0ff02fd5","market_ticker":"KXBTCPERP1","price":"6.3075","count":"1.00","taker_side":"ask","ts_ms":1781237160302}}

{"type":"trade","sid":2,"seq":1749,"msg":{"trade_id":"be3ed914-121a-5e60-17ab-c5d0b0924425","market_ticker":"KXBTCPERP1","price":"6.3074","count":"1.00","taker_side":"ask","ts_ms":1781237160302}}

{"type":"trade","sid":2,"seq":1750,"msg":{"trade_id":"67f16a10-2293-5b68-03ff-301291d87fc0","market_ticker":"KXBTCPERP1","price":"6.3074","count":"1.00","taker_side":"ask","ts_ms":1781237160302}}

{"type":"trade","sid":2,"seq":1751,"msg":{"trade_id":"39c64dad-9561-5fd0-2c4b-eacf303b1062","market_ticker":"KXBTCPERP1","price":"6.3073","count":"1.00","taker_side":"ask","ts_ms":1781237160302}}

{"type":"trade","sid":2,"seq":1752,"msg":{"trade_id":"0f49ddba-9891-5f66-2e02-74e685211e09","market_ticker":"KXBTCPERP1","price":"6.3073","count":"1.00","taker_side":"ask","ts_ms":1781237160302}}

{"type":"trade","sid":2,"seq":1753,"msg":{"trade_id":"01adc5f9-cb96-5e61-2f36-d5a8640009d9","market_ticker":"KXBTCPERP1","price":"6.3072","count":"1.00","taker_side":"ask","ts_ms":1781237160302}}

{"type":"trade","sid":2,"seq":1754,"msg":{"trade_id":"8d6559b7-aa9e-5aac-0ddf-6136d720bf66","market_ticker":"KXBTCPERP1","price":"6.3072","count":"1.00","taker_side":"ask","ts_ms":1781237160302}}

{"type":"trade","sid":2,"seq":1755,"msg":{"trade_id":"7a8939d4-a4c0-5eed-2a1d-18df14a8835b","market_ticker":"KXBTCPERP1","price":"6.3072","count":"1.00","taker_side":"ask","ts_ms":1781237160302}}

{"type":"trade","sid":2,"seq":1756,"msg":{"trade_id":"8b99de40-00ed-5e4d-3ff1-596ed2bacfcc","market_ticker":"KXBTCPERP1","price":"6.3072","count":"1.00","taker_side":"ask","ts_ms":1781237160302}}

{"type":"trade","sid":2,"seq":1757,"msg":{"trade_id":"2a13ff8e-ce89-5df3-2866-0644b4fa672d","market_ticker":"KXBTCPERP1","price":"6.3071","count":"1.00","taker_side":"ask","ts_ms":1781237160302}}

{"type":"trade","sid":2,"seq":1758,"msg":{"trade_id":"1224d9f1-930b-5587-0f68-9a10c97203c0","market_ticker":"KXBTCPERP1","price":"6.3071","count":"1.00","taker_side":"ask","ts_ms":1781237160302}}

{"type":"trade","sid":2,"seq":1759,"msg":{"trade_id":"4c8a51ad-946a-5ac1-3f48-9de3108cbe61","market_ticker":"KXBTCPERP1","price":"6.3070","count":"1.00","taker_side":"ask","ts_ms":1781237160302}}

{"type":"trade","sid":2,"seq":1760,"msg":{"trade_id":"47a48872-42a0-5a30-3ec6-4adc7cee31f2","market_ticker":"KXBTCPERP1","price":"6.3070","count":"1.00","taker_side":"ask","ts_ms":1781237160302}}

{"type":"trade","sid":2,"seq":1761,"msg":{"trade_id":"e81c0219-c50b-5e3a-1870-98488d9f2c8b","market_ticker":"KXBTCPERP1","price":"6.3070","count":"1.00","taker_side":"ask","ts_ms":1781237160302}}

{"type":"trade","sid":2,"seq":1762,"msg":{"trade_id":"fb33f774-9d73-5a02-0d69-dae8da760d27","market_ticker":"KXBTCPERP1","price":"6.3070","count":"1.00","taker_side":"ask","ts_ms":1781237160302}}

{"type":"trade","sid":2,"seq":1763,"msg":{"trade_id":"465613fa-afd2-5e5d-143a-74767c22cb59","market_ticker":"KXBTCPERP1","price":"6.3070","count":"1.00","taker_side":"ask","ts_ms":1781237160302}}

{"type":"trade","sid":2,"seq":1764,"msg":{"trade_id":"72999a94-19b5-5add-2b82-f191e395b0ba","market_ticker":"KXBTCPERP1","price":"6.3070","count":"1.00","taker_side":"ask","ts_ms":1781237160302}}

{"type":"trade","sid":2,"seq":1765,"msg":{"trade_id":"894385cb-221b-5f19-28b3-85f6502ec84b","market_ticker":"KXBTCPERP1","price":"6.3069","count":"1.00","taker_side":"ask","ts_ms":1781237160302}}

{"type":"trade","sid":2,"seq":1766,"msg":{"trade_id":"4dac7b77-6b1f-5ff2-2034-bdd5bdac5e19","market_ticker":"KXBTCPERP1","price":"6.3069","count":"1.00","taker_side":"ask","ts_ms":1781237160302}}

{"type":"trade","sid":2,"seq":1767,"msg":{"trade_id":"237bfc55-f3c6-542d-3c5a-93f44bc81264","market_ticker":"KXBTCPERP1","price":"6.3069","count":"1.00","taker_side":"ask","ts_ms":1781237160302}}

{"type":"trade","sid":2,"seq":1768,"msg":{"trade_id":"9aa3c109-cd51-5c76-3bb9-ec8ffd077fed","market_ticker":"KXBTCPERP1","price":"6.3068","count":"1.00","taker_side":"ask","ts_ms":1781237160302}}

{"type":"trade","sid":2,"seq":1769,"msg":{"trade_id":"8c36d174-012e-573b-37f7-1f8d4f04ce41","market_ticker":"KXBTCPERP1","price":"6.3068","count":"1.00","taker_side":"ask","ts_ms":1781237160302}}

{"type":"trade","sid":2,"seq":1770,"msg":{"trade_id":"1762b822-eccb-521e-1bdb-13da9508ee8d","market_ticker":"KXBTCPERP1","price":"6.3068","count":"1.00","taker_side":"ask","ts_ms":1781237160302}}

{"type":"trade","sid":2,"seq":1771,"msg":{"trade_id":"c841c53d-7141-5ef7-3ea5-c42751610709","market_ticker":"KXBTCPERP1","price":"6.3068","count":"1.00","taker_side":"ask","ts_ms":1781237160302}}

{"type":"trade","sid":2,"seq":1772,"msg":{"trade_id":"ecab91ec-cbd0-5016-2d4a-8f6848131133","market_ticker":"KXBTCPERP1","price":"6.3068","count":"1.00","taker_side":"ask","ts_ms":1781237160302}}

{"type":"trade","sid":2,"seq":1773,"msg":{"trade_id":"f6a783b8-0a14-5a8d-1f40-47d799be3705","market_ticker":"KXBTCPERP1","price":"6.3068","count":"1.00","taker_side":"ask","ts_ms":1781237160302}}

{"type":"trade","sid":2,"seq":1774,"msg":{"trade_id":"938398d6-9738-53d1-1714-e70792a1ed32","market_ticker":"KXBTCPERP1","price":"6.3067","count":"1.00","taker_side":"ask","ts_ms":1781237160302}}

{"type":"trade","sid":2,"seq":1775,"msg":{"trade_id":"33db1105-0829-54a4-0be4-30eb182255b9","market_ticker":"KXBTCPERP1","price":"6.3067","count":"1.00","taker_side":"ask","ts_ms":1781237160302}}

{"type":"trade","sid":2,"seq":1776,"msg":{"trade_id":"4a5d9696-aad4-5d45-07c6-433b9d2d70cf","market_ticker":"KXBTCPERP1","price":"6.3067","count":"1.00","taker_side":"ask","ts_ms":1781237160302}}

{"type":"trade","sid":2,"seq":1777,"msg":{"trade_id":"1424a535-fd4a-5ea6-0926-c5a7a8e674c7","market_ticker":"KXBTCPERP1","price":"6.3066","count":"1.00","taker_side":"ask","ts_ms":1781237160302}}

{"type":"trade","sid":2,"seq":1778,"msg":{"trade_id":"5054b1cb-9264-573a-0bdd-aecb6ff3d4a8","market_ticker":"KXBTCPERP1","price":"6.3066","count":"1.00","taker_side":"ask","ts_ms":1781237160302}}

{"type":"ticker","sid":3,"msg":{"market_ticker":"KXBTCPERP1","price":"6.3329","bid":"6.3329","ask":"6.3416","bid_size_fp":"343.00","ask_size_fp":"658.00","last_trade_size_fp":"0.00","volume":"4179467045.00","volume_notional_value_dollars":"3245141294.960300","volume_24h":"1877080.00","volume_24h_notional_value_dollars":"11687174.591200","open_interest":"2332769.00","open_interest_notional_value_dollars":"14773192.800100","reference_price":{"price":"6.3414","ts_ms":1781237160000},"settlement_mark_price":{"price":"6.3801","ts_ms":1781237158039},"liquidation_mark_price":{"price":"6.3415","ts_ms":1781237160399},"funding_rate":{"rate":0,"next_funding_time_ms":1781265600000,"ts_ms":1781237158039},"ts_ms":1781217877584}}

{"type":"orderbook_delta","sid":1,"seq":1958,"msg":{"market_ticker":"KXBTCPERP1","price":"6.3942","delta":"-782.00","side":"ask","ts_ms":1781237160548}}

{"type":"orderbook_delta","sid":1,"seq":1959,"msg":{"market_ticker":"KXBTCPERP1","price":"6.3077","delta":"793.00","side":"ask","ts_ms":1781237160548}}

{"type":"orderbook_delta","sid":1,"seq":1960,"msg":{"market_ticker":"KXBTCPERP1","price":"6.2436","delta":"1.00","side":"bid","ts_ms":1781237160601}}

{"type":"orderbook_delta","sid":1,"seq":1961,"msg":{"market_ticker":"KXBTCPERP1","price":"6.3043","delta":"11.00","side":"bid","ts_ms":1781237160694}}

{"type":"orderbook_delta","sid":1,"seq":1962,"msg":{"market_ticker":"KXBTCPERP1","price":"6.3042","delta":"10.00","side":"bid","ts_ms":1781237160795}}

{"type":"orderbook_delta","sid":1,"seq":1963,"msg":{"market_ticker":"KXBTCPERP1","price":"6.3944","delta":"-782.00","side":"ask","ts_ms":1781237160855}}

{"type":"orderbook_delta","sid":1,"seq":1964,"msg":{"market_ticker":"KXBTCPERP1","price":"6.3088","delta":"793.00","side":"ask","ts_ms":1781237160855}}

{"type":"orderbook_delta","sid":1,"seq":1965,"msg":{"market_ticker":"KXBTCPERP1","price":"6.2994","delta":"139.00","side":"bid","ts_ms":1781237160895}}

{"type":"orderbook_delta","sid":1,"seq":1966,"msg":{"market_ticker":"KXBTCPERP1","price":"6.3946","delta":"-782.00","side":"ask","ts_ms":1781237160902}}

{"type":"orderbook_delta","sid":1,"seq":1967,"msg":{"market_ticker":"KXBTCPERP1","price":"6.3099","delta":"793.00","side":"ask","ts_ms":1781237160902}}

{"type":"orderbook_delta","sid":1,"seq":1968,"msg":{"market_ticker":"KXBTCPERP1","price":"6.3948","delta":"-782.00","side":"ask","ts_ms":1781237160907}}

{"type":"orderbook_delta","sid":1,"seq":1969,"msg":{"market_ticker":"KXBTCPERP1","price":"6.3110","delta":"793.00","side":"ask","ts_ms":1781237160907}}

{"type":"orderbook_delta","sid":1,"seq":1970,"msg":{"market_ticker":"KXBTCPERP1","price":"6.3950","delta":"-782.00","side":"ask","ts_ms":1781237160910}}

{"type":"orderbook_delta","sid":1,"seq":1971,"msg":{"market_ticker":"KXBTCPERP1","price":"6.3121","delta":"793.00","side":"ask","ts_ms":1781237160910}}

{"type":"orderbook_delta","sid":1,"seq":1972,"msg":{"market_ticker":"KXBTCPERP1","price":"6.3952","delta":"-782.00","side":"ask","ts_ms":1781237160913}}

{"type":"orderbook_delta","sid":1,"seq":1973,"msg":{"market_ticker":"KXBTCPERP1","price":"6.3132","delta":"792.00","side":"ask","ts_ms":1781237160913}}

{"type":"orderbook_delta","sid":1,"seq":1974,"msg":{"market_ticker":"KXBTCPERP1","price":"6.2923","delta":"554.00","side":"bid","ts_ms":1781237160996}}

{"type":"orderbook_delta","sid":1,"seq":1975,"msg":{"market_ticker":"KXBTCPERP1","price":"6.3066","delta":"-1.00","side":"ask","ts_ms":1781237161026}}

{"type":"trade","sid":2,"seq":1779,"msg":{"trade_id":"a9ff6abf-a35a-6621-13c1-94f13a9d7456","market_ticker":"KXBTCPERP1","price":"6.3066","count":"1.00","taker_side":"bid","ts_ms":1781237161026}}

{"type":"orderbook_delta","sid":1,"seq":1976,"msg":{"market_ticker":"KXBTCPERP1","price":"6.3066","delta":"-1.00","side":"ask","ts_ms":1781237161154}}

{"type":"trade","sid":2,"seq":1780,"msg":{"trade_id":"f8879bb6-3d32-5bc1-3ddf-aa296032a972","market_ticker":"KXBTCPERP1","price":"6.3066","count":"1.00","taker_side":"bid","ts_ms":1781237161154}}

{"type":"orderbook_delta","sid":1,"seq":1977,"msg":{"market_ticker":"KXBTCPERP1","price":"6.3065","delta":"-1.00","side":"bid","ts_ms":1781237161365}}

{"type":"trade","sid":2,"seq":1781,"msg":{"trade_id":"6448fbdf-229b-4b9d-7a44-16474c498ca8","market_ticker":"KXBTCPERP1","price":"6.3065","count":"1.00","taker_side":"ask","ts_ms":1781237161365}}

{"type":"orderbook_delta","sid":1,"seq":1978,"msg":{"market_ticker":"KXBTCPERP1","price":"6.3610","delta":"1.00","side":"ask","ts_ms":1781237161492}}

{"type":"ticker","sid":3,"msg":{"market_ticker":"KXBTCPERP1","price":"6.3329","bid":"6.3329","ask":"6.3416","bid_size_fp":"343.00","ask_size_fp":"658.00","last_trade_size_fp":"0.00","volume":"4179467045.00","volume_notional_value_dollars":"3245141294.960300","volume_24h":"1877080.00","volume_24h_notional_value_dollars":"11687174.591200","open_interest":"2332769.00","open_interest_notional_value_dollars":"14773192.800100","reference_price":{"price":"6.3412","ts_ms":1781237161000},"settlement_mark_price":{"price":"6.3801","ts_ms":1781237158039},"liquidation_mark_price":{"price":"6.3412","ts_ms":1781237161399},"funding_rate":{"rate":0,"next_funding_time_ms":1781265600000,"ts_ms":1781237158039},"ts_ms":1781217877584}}

{"type":"orderbook_delta","sid":1,"seq":1979,"msg":{"market_ticker":"KXBTCPERP1","price":"6.3644","delta":"1.00","side":"ask","ts_ms":1781237161630}}

{"type":"orderbook_delta","sid":1,"seq":1980,"msg":{"market_ticker":"KXBTCPERP1","price":"6.3938","delta":"-10.00","side":"ask","ts_ms":1781237161702}}

{"type":"orderbook_delta","sid":1,"seq":1981,"msg":{"market_ticker":"KXBTCPERP1","price":"6.3090","delta":"10.00","side":"ask","ts_ms":1781237161702}}

{"type":"orderbook_delta","sid":1,"seq":1982,"msg":{"market_ticker":"KXBTCPERP1","price":"6.2973","delta":"1.00","side":"bid","ts_ms":1781237161711}}

{"type":"orderbook_delta","sid":1,"seq":1983,"msg":{"market_ticker":"KXBTCPERP1","price":"6.3314","delta":"1.00","side":"ask","ts_ms":1781237161725}}

{"type":"orderbook_delta","sid":1,"seq":1984,"msg":{"market_ticker":"KXBTCPERP1","price":"6.3939","delta":"-10.00","side":"ask","ts_ms":1781237161803}}

{"type":"orderbook_delta","sid":1,"seq":1985,"msg":{"market_ticker":"KXBTCPERP1","price":"6.3091","delta":"10.00","side":"ask","ts_ms":1781237161803}}

{"type":"orderbook_delta","sid":1,"seq":1986,"msg":{"market_ticker":"KXBTCPERP1","price":"6.3066","delta":"-1.00","side":"ask","ts_ms":1781237161858}}

{"type":"trade","sid":2,"seq":1782,"msg":{"trade_id":"27284203-625e-57d5-df05-43f3ec7046e2","market_ticker":"KXBTCPERP1","price":"6.3066","count":"1.00","taker_side":"bid","ts_ms":1781237161858}}

{"type":"orderbook_delta","sid":1,"seq":1987,"msg":{"market_ticker":"KXBTCPERP1","price":"6.2023","delta":"-1.00","side":"bid","ts_ms":1781237161890}}

{"type":"orderbook_delta","sid":1,"seq":1988,"msg":{"market_ticker":"KXBTCPERP1","price":"6.3977","delta":"-136.00","side":"ask","ts_ms":1781237161904}}

{"type":"orderbook_delta","sid":1,"seq":1989,"msg":{"market_ticker":"KXBTCPERP1","price":"6.3144","delta":"133.00","side":"ask","ts_ms":1781237161904}}

{"type":"orderbook_delta","sid":1,"seq":1990,"msg":{"market_ticker":"KXBTCPERP1","price":"6.3066","delta":"-1.00","side":"ask","ts_ms":1781237161987}}

{"type":"trade","sid":2,"seq":1783,"msg":{"trade_id":"786c05a7-ccb2-53c1-bad3-75c16e773d72","market_ticker":"KXBTCPERP1","price":"6.3066","count":"1.00","taker_side":"bid","ts_ms":1781237161987}}

{"type":"orderbook_delta","sid":1,"seq":1991,"msg":{"market_ticker":"KXBTCPERP1","price":"6.4053","delta":"-544.00","side":"ask","ts_ms":1781237162004}}

{"type":"orderbook_delta","sid":1,"seq":1992,"msg":{"market_ticker":"KXBTCPERP1","price":"6.3223","delta":"531.00","side":"ask","ts_ms":1781237162004}}

{"type":"orderbook_delta","sid":1,"seq":1993,"msg":{"market_ticker":"KXBTCPERP1","price":"6.4534","delta":"1.00","side":"ask","ts_ms":1781237162044}}

{"type":"orderbook_delta","sid":1,"seq":1994,"msg":{"market_ticker":"KXBTCPERP1","price":"6.3066","delta":"-1.00","side":"ask","ts_ms":1781237162133}}

{"type":"trade","sid":2,"seq":1784,"msg":{"trade_id":"e1582b72-50c6-56f1-5ce0-810771e87a7a","market_ticker":"KXBTCPERP1","price":"6.3066","count":"1.00","taker_side":"bid","ts_ms":1781237162133}}

{"type":"orderbook_delta","sid":1,"seq":1995,"msg":{"market_ticker":"KXBTCPERP1","price":"6.2262","delta":"1.00","side":"bid","ts_ms":1781237162310}}

{"type":"orderbook_delta","sid":1,"seq":1996,"msg":{"market_ticker":"KXBTCPERP1","price":"6.3066","delta":"-1.00","side":"ask","ts_ms":1781237162484}}

{"type":"trade","sid":2,"seq":1785,"msg":{"trade_id":"8063ea6e-0df6-431d-aefa-d322bf1b3c02","market_ticker":"KXBTCPERP1","price":"6.3066","count":"1.00","taker_side":"bid","ts_ms":1781237162484}}

{"type":"ticker","sid":3,"msg":{"market_ticker":"KXBTCPERP1","price":"6.3329","bid":"6.3329","ask":"6.3416","bid_size_fp":"343.00","ask_size_fp":"658.00","last_trade_size_fp":"0.00","volume":"4179467045.00","volume_notional_value_dollars":"3245141294.960300","volume_24h":"1877080.00","volume_24h_notional_value_dollars":"11687174.591200","open_interest":"2332769.00","open_interest_notional_value_dollars":"14773192.800100","reference_price":{"price":"6.3415","ts_ms":1781237162000},"settlement_mark_price":{"price":"6.3801","ts_ms":1781237158039},"liquidation_mark_price":{"price":"6.3415","ts_ms":1781237162398},"funding_rate":{"rate":0,"next_funding_time_ms":1781265600000,"ts_ms":1781237158039},"ts_ms":1781217877584}}

{"type":"orderbook_delta","sid":1,"seq":1997,"msg":{"market_ticker":"KXBTCPERP1","price":"6.4416","delta":"1.00","side":"ask","ts_ms":1781237162768}}

{"type":"orderbook_delta","sid":1,"seq":1998,"msg":{"market_ticker":"KXBTCPERP1","price":"6.4325","delta":"1.00","side":"ask","ts_ms":1781237162877}}

{"type":"orderbook_delta","sid":1,"seq":1999,"msg":{"market_ticker":"KXBTCPERP1","price":"6.3066","delta":"-1.00","side":"ask","ts_ms":1781237163097}}

{"type":"trade","sid":2,"seq":1786,"msg":{"trade_id":"6392b73a-0b1e-6161-7ca8-28d124559b56","market_ticker":"KXBTCPERP1","price":"6.3066","count":"1.00","taker_side":"bid","ts_ms":1781237163097}}

{"type":"orderbook_delta","sid":1,"seq":2000,"msg":{"market_ticker":"KXBTCPERP1","price":"6.2585","delta":"1.00","side":"bid","ts_ms":1781237163391}}

{"type":"ticker","sid":3,"msg":{"market_ticker":"KXBTCPERP1","price":"6.3329","bid":"6.3329","ask":"6.3416","bid_size_fp":"343.00","ask_size_fp":"658.00","last_trade_size_fp":"0.00","volume":"4179467045.00","volume_notional_value_dollars":"3245141294.960300","volume_24h":"1877080.00","volume_24h_notional_value_dollars":"11687174.591200","open_interest":"2332769.00","open_interest_notional_value_dollars":"14773192.800100","reference_price":{"price":"6.3414","ts_ms":1781237163000},"settlement_mark_price":{"price":"6.3801","ts_ms":1781237158039},"liquidation_mark_price":{"price":"6.3415","ts_ms":1781237163398},"funding_rate":{"rate":0,"next_funding_time_ms":1781265600000,"ts_ms":1781237158039},"ts_ms":1781217877584}}

{"type":"orderbook_delta","sid":1,"seq":2001,"msg":{"market_ticker":"KXBTCPERP1","price":"6.2214","delta":"1.00","side":"bid","ts_ms":1781237163551}}

{"type":"orderbook_delta","sid":1,"seq":2002,"msg":{"market_ticker":"KXBTCPERP1","price":"6.4703","delta":"1.00","side":"ask","ts_ms":1781237163596}}

{"type":"orderbook_delta","sid":1,"seq":2003,"msg":{"market_ticker":"KXBTCPERP1","price":"6.3328","delta":"1.00","side":"ask","ts_ms":1781237163711}}

{"type":"orderbook_delta","sid":1,"seq":2004,"msg":{"market_ticker":"KXBTCPERP1","price":"6.3865","delta":"1.00","side":"ask","ts_ms":1781237163913}}

{"type":"orderbook_delta","sid":1,"seq":2005,"msg":{"market_ticker":"KXBTCPERP1","price":"6.3330","delta":"1.00","side":"ask","ts_ms":1781237164022}}

{"type":"orderbook_delta","sid":1,"seq":2006,"msg":{"market_ticker":"KXBTCPERP1","price":"6.2636","delta":"1.00","side":"bid","ts_ms":1781237164173}}

{"type":"orderbook_delta","sid":1,"seq":2007,"msg":{"market_ticker":"KXBTCPERP1","price":"6.5312","delta":"1.00","side":"ask","ts_ms":1781237164258}}

{"type":"orderbook_delta","sid":1,"seq":2008,"msg":{"market_ticker":"KXBTCPERP1","price":"6.3065","delta":"-1.00","side":"bid","ts_ms":1781237164363}}

{"type":"trade","sid":2,"seq":1787,"msg":{"trade_id":"aae82b82-4f29-6497-28c1-bf52d7cac3f0","market_ticker":"KXBTCPERP1","price":"6.3065","count":"1.00","taker_side":"ask","ts_ms":1781237164363}}

{"type":"ticker","sid":3,"msg":{"market_ticker":"KXBTCPERP1","price":"6.3329","bid":"6.3329","ask":"6.3416","bid_size_fp":"343.00","ask_size_fp":"658.00","last_trade_size_fp":"0.00","volume":"4179467045.00","volume_notional_value_dollars":"3245141294.960300","volume_24h":"1877080.00","volume_24h_notional_value_dollars":"11687174.591200","open_interest":"2332769.00","open_interest_notional_value_dollars":"14773192.800100","reference_price":{"price":"6.3415","ts_ms":1781237164000},"settlement_mark_price":{"price":"6.3742","ts_ms":1781237163039},"liquidation_mark_price":{"price":"6.3415","ts_ms":1781237164399},"funding_rate":{"rate":0,"next_funding_time_ms":1781265600000,"ts_ms":1781237163039},"ts_ms":1781217877584}}

{"type":"orderbook_delta","sid":1,"seq":2009,"msg":{"market_ticker":"KXBTCPERP1","price":"6.4899","delta":"1.00","side":"ask","ts_ms":1781237164513}}

{"type":"orderbook_delta","sid":1,"seq":2010,"msg":{"market_ticker":"KXBTCPERP1","price":"6.3066","delta":"-1.00","side":"ask","ts_ms":1781237164779}}

{"type":"trade","sid":2,"seq":1788,"msg":{"trade_id":"6773878f-d8b2-4621-c29f-eed4a26e1efa","market_ticker":"KXBTCPERP1","price":"6.3066","count":"1.00","taker_side":"bid","ts_ms":1781237164779}}

{"type":"orderbook_delta","sid":1,"seq":2011,"msg":{"market_ticker":"KXBTCPERP1","price":"6.2312","delta":"1.00","side":"bid","ts_ms":1781237164803}}

{"type":"orderbook_delta","sid":1,"seq":2012,"msg":{"market_ticker":"KXBTCPERP1","price":"6.2740","delta":"-1.00","side":"bid","ts_ms":1781237164926}}

{"type":"orderbook_delta","sid":1,"seq":2013,"msg":{"market_ticker":"KXBTCPERP1","price":"6.2356","delta":"1.00","side":"bid","ts_ms":1781237165017}}

{"type":"orderbook_delta","sid":1,"seq":2014,"msg":{"market_ticker":"KXBTCPERP1","price":"6.3697","delta":"1.00","side":"ask","ts_ms":1781237165121}}

{"type":"orderbook_delta","sid":1,"seq":2015,"msg":{"market_ticker":"KXBTCPERP1","price":"6.3265","delta":"1.00","side":"ask","ts_ms":1781237165222}}

{"type":"orderbook_delta","sid":1,"seq":2016,"msg":{"market_ticker":"KXBTCPERP1","price":"6.3066","delta":"-1.00","side":"ask","ts_ms":1781237165256}}

{"type":"trade","sid":2,"seq":1789,"msg":{"trade_id":"427890f2-0ff6-51b9-fb96-848831137c82","market_ticker":"KXBTCPERP1","price":"6.3066","count":"1.00","taker_side":"bid","ts_ms":1781237165256}}

{"type":"orderbook_delta","sid":1,"seq":2017,"msg":{"market_ticker":"KXBTCPERP1","price":"6.3066","delta":"-1.00","side":"ask","ts_ms":1781237165354}}

{"type":"trade","sid":2,"seq":1790,"msg":{"trade_id":"d37fd83a-5b96-65e9-5f55-7e93d0f543ce","market_ticker":"KXBTCPERP1","price":"6.3066","count":"1.00","taker_side":"bid","ts_ms":1781237165354}}

{"type":"orderbook_delta","sid":1,"seq":2018,"msg":{"market_ticker":"KXBTCPERP1","price":"6.3072","delta":"1.00","side":"ask","ts_ms":1781237165473}}

{"type":"ticker","sid":3,"msg":{"market_ticker":"KXBTCPERP1","price":"6.3329","bid":"6.3329","ask":"6.3416","bid_size_fp":"343.00","ask_size_fp":"658.00","last_trade_size_fp":"0.00","volume":"4179467045.00","volume_notional_value_dollars":"3245141294.960300","volume_24h":"1877080.00","volume_24h_notional_value_dollars":"11687174.591200","open_interest":"2332769.00","open_interest_notional_value_dollars":"14773192.800100","reference_price":{"price":"6.3415","ts_ms":1781237165000},"settlement_mark_price":{"price":"6.3742","ts_ms":1781237163039},"liquidation_mark_price":{"price":"6.3415","ts_ms":1781237165398},"funding_rate":{"rate":0,"next_funding_time_ms":1781265600000,"ts_ms":1781237163039},"ts_ms":1781217877584}}

{"type":"orderbook_delta","sid":1,"seq":2019,"msg":{"market_ticker":"KXBTCPERP1","price":"7.6637","delta":"-1.00","side":"ask","ts_ms":1781237165536}}

{"type":"trade","sid":2,"seq":1791,"msg":{"trade_id":"c3d40469-53bf-6b2a-50dd-67074606c311","market_ticker":"KXBTCPERP1","price":"6.3064","count":"1.00","taker_side":"ask","ts_ms":1781237165722}}

{"type":"orderbook_delta","sid":1,"seq":2020,"msg":{"market_ticker":"KXBTCPERP1","price":"6.3064","delta":"-1.00","side":"bid","ts_ms":1781237165722}}

{"type":"trade","sid":2,"seq":1792,"msg":{"trade_id":"c33a65e4-ae9a-4bf5-d29f-907bd0059902","market_ticker":"KXBTCPERP1","price":"6.3066","count":"1.00","taker_side":"bid","ts_ms":1781237165916}}

{"type":"orderbook_delta","sid":1,"seq":2021,"msg":{"market_ticker":"KXBTCPERP1","price":"6.3066","delta":"-1.00","side":"ask","ts_ms":1781237165916}}

{"type":"orderbook_delta","sid":1,"seq":2022,"msg":{"market_ticker":"KXBTCPERP1","price":"6.1961","delta":"-1.00","side":"bid","ts_ms":1781237165925}}

{"type":"orderbook_delta","sid":1,"seq":2023,"msg":{"market_ticker":"KXBTCPERP1","price":"6.2782","delta":"1.00","side":"bid","ts_ms":1781237165988}}

{"type":"orderbook_delta","sid":1,"seq":2024,"msg":{"market_ticker":"KXBTCPERP1","price":"6.3066","delta":"-1.00","side":"ask","ts_ms":1781237166099}}

{"type":"trade","sid":2,"seq":1793,"msg":{"trade_id":"46bf54b9-b866-4929-a05a-a4cb0a256552","market_ticker":"KXBTCPERP1","price":"6.3066","count":"1.00","taker_side":"bid","ts_ms":1781237166099}}

{"type":"orderbook_delta","sid":1,"seq":2025,"msg":{"market_ticker":"KXBTCPERP1","price":"6.3066","delta":"-1.00","side":"ask","ts_ms":1781237166117}}

{"type":"trade","sid":2,"seq":1794,"msg":{"trade_id":"f930f37e-1e76-54d1-e725-f4c63409c442","market_ticker":"KXBTCPERP1","price":"6.3066","count":"1.00","taker_side":"bid","ts_ms":1781237166117}}

{"type":"trade","sid":2,"seq":1795,"msg":{"trade_id":"16b3c9c8-51c1-72ee-884c-ac71e8683837","market_ticker":"KXBTCPERP1","price":"6.3064","count":"1.00","taker_side":"ask","ts_ms":1781237166191}}

{"type":"orderbook_delta","sid":1,"seq":2026,"msg":{"market_ticker":"KXBTCPERP1","price":"6.3064","delta":"-1.00","side":"bid","ts_ms":1781237166191}}

{"type":"trade","sid":2,"seq":1796,"msg":{"trade_id":"0d7faa2c-944a-51dd-df63-3cbcb15e1a76","market_ticker":"KXBTCPERP1","price":"6.3066","count":"1.00","taker_side":"bid","ts_ms":1781237166268}}

{"type":"orderbook_delta","sid":1,"seq":2027,"msg":{"market_ticker":"KXBTCPERP1","price":"6.3066","delta":"-1.00","side":"ask","ts_ms":1781237166268}}

{"type":"orderbook_delta","sid":1,"seq":2028,"msg":{"market_ticker":"KXBTCPERP1","price":"6.3132","delta":"1.00","side":"ask","ts_ms":1781237166347}}

{"type":"orderbook_delta","sid":1,"seq":2029,"msg":{"market_ticker":"KXBTCPERP1","price":"6.5165","delta":"-1.00","side":"ask","ts_ms":1781237166468}}

{"type":"ticker","sid":3,"msg":{"market_ticker":"KXBTCPERP1","price":"6.3329","bid":"6.3329","ask":"6.3416","bid_size_fp":"343.00","ask_size_fp":"658.00","last_trade_size_fp":"0.00","volume":"4179467045.00","volume_notional_value_dollars":"3245141294.960300","volume_24h":"1877080.00","volume_24h_notional_value_dollars":"11687174.591200","open_interest":"2332769.00","open_interest_notional_value_dollars":"14773192.800100","reference_price":{"price":"6.3415","ts_ms":1781237166000},"settlement_mark_price":{"price":"6.3742","ts_ms":1781237163039},"liquidation_mark_price":{"price":"6.3415","ts_ms":1781237166399},"funding_rate":{"rate":0,"next_funding_time_ms":1781265600000,"ts_ms":1781237163039},"ts_ms":1781217877584}}

{"type":"trade","sid":2,"seq":1797,"msg":{"trade_id":"00ae2eec-80e0-5d9f-e46b-05e3f52daefd","market_ticker":"KXBTCPERP1","price":"6.3064","count":"1.00","taker_side":"ask","ts_ms":1781237166565}}

{"type":"orderbook_delta","sid":1,"seq":2030,"msg":{"market_ticker":"KXBTCPERP1","price":"6.3064","delta":"-1.00","side":"bid","ts_ms":1781237166565}}

{"type":"orderbook_delta","sid":1,"seq":2031,"msg":{"market_ticker":"KXBTCPERP1","price":"6.3066","delta":"-1.00","side":"ask","ts_ms":1781237166724}}

{"type":"trade","sid":2,"seq":1798,"msg":{"trade_id":"b978c900-7052-45a1-cce7-69823b04412a","market_ticker":"KXBTCPERP1","price":"6.3066","count":"1.00","taker_side":"bid","ts_ms":1781237166724}}

{"type":"trade","sid":2,"seq":1799,"msg":{"trade_id":"2e8859b5-fc5a-448d-ed5c-2be67aa14462","market_ticker":"KXBTCPERP1","price":"6.3066","count":"1.00","taker_side":"bid","ts_ms":1781237166829}}

{"type":"orderbook_delta","sid":1,"seq":2032,"msg":{"market_ticker":"KXBTCPERP1","price":"6.3066","delta":"-1.00","side":"ask","ts_ms":1781237166829}}

{"type":"orderbook_delta","sid":1,"seq":2033,"msg":{"market_ticker":"KXBTCPERP1","price":"6.3531","delta":"1.00","side":"ask","ts_ms":1781237166999}}

{"type":"orderbook_delta","sid":1,"seq":2034,"msg":{"market_ticker":"KXBTCPERP1","price":"6.3066","delta":"-1.00","side":"ask","ts_ms":1781237167126}}

{"type":"trade","sid":2,"seq":1800,"msg":{"trade_id":"8bf8d193-3622-56e5-6cd6-8ea8a211989a","market_ticker":"KXBTCPERP1","price":"6.3066","count":"1.00","taker_side":"bid","ts_ms":1781237167126}}

{"type":"orderbook_delta","sid":1,"seq":2035,"msg":{"market_ticker":"KXBTCPERP1","price":"6.2333","delta":"1.00","side":"bid","ts_ms":1781237167241}}

{"type":"orderbook_delta","sid":1,"seq":2036,"msg":{"market_ticker":"KXBTCPERP1","price":"6.3578","delta":"1.00","side":"ask","ts_ms":1781237167313}}

{"type":"orderbook_delta","sid":1,"seq":2037,"msg":{"market_ticker":"KXBTCPERP1","price":"6.2292","delta":"1.00","side":"bid","ts_ms":1781237167319}}

{"type":"orderbook_delta","sid":1,"seq":2038,"msg":{"market_ticker":"KXBTCPERP1","price":"6.4720","delta":"1.00","side":"ask","ts_ms":1781237167422}}

{"type":"orderbook_delta","sid":1,"seq":2039,"msg":{"market_ticker":"KXBTCPERP1","price":"6.3066","delta":"-1.00","side":"ask","ts_ms":1781237167450}}

{"type":"trade","sid":2,"seq":1801,"msg":{"trade_id":"7f82cc18-6a52-68b5-1f37-b96b94a2a92a","market_ticker":"KXBTCPERP1","price":"6.3066","count":"1.00","taker_side":"bid","ts_ms":1781237167450}}

{"type":"ticker","sid":3,"msg":{"market_ticker":"KXBTCPERP1","price":"6.3329","bid":"6.3329","ask":"6.3416","bid_size_fp":"343.00","ask_size_fp":"658.00","last_trade_size_fp":"0.00","volume":"4179467045.00","volume_notional_value_dollars":"3245141294.960300","volume_24h":"1877080.00","volume_24h_notional_value_dollars":"11687174.591200","open_interest":"2332769.00","open_interest_notional_value_dollars":"14773192.800100","reference_price":{"price":"6.3415","ts_ms":1781237167000},"settlement_mark_price":{"price":"6.3742","ts_ms":1781237163039},"liquidation_mark_price":{"price":"6.3415","ts_ms":1781237167399},"funding_rate":{"rate":0,"next_funding_time_ms":1781265600000,"ts_ms":1781237163039},"ts_ms":1781217877584}}

{"type":"orderbook_delta","sid":1,"seq":2040,"msg":{"market_ticker":"KXBTCPERP1","price":"6.3066","delta":"-324.00","side":"ask","ts_ms":1781237167556}}

{"type":"orderbook_delta","sid":1,"seq":2041,"msg":{"market_ticker":"KXBTCPERP1","price":"6.3842","delta":"315.00","side":"ask","ts_ms":1781237167556}}

{"type":"orderbook_delta","sid":1,"seq":2042,"msg":{"market_ticker":"KXBTCPERP1","price":"6.3077","delta":"-793.00","side":"ask","ts_ms":1781237167560}}

{"type":"orderbook_delta","sid":1,"seq":2043,"msg":{"market_ticker":"KXBTCPERP1","price":"6.3844","delta":"784.00","side":"ask","ts_ms":1781237167560}}

{"type":"orderbook_delta","sid":1,"seq":2044,"msg":{"market_ticker":"KXBTCPERP1","price":"6.3088","delta":"-793.00","side":"ask","ts_ms":1781237167563}}

{"type":"orderbook_delta","sid":1,"seq":2045,"msg":{"market_ticker":"KXBTCPERP1","price":"6.3846","delta":"784.00","side":"ask","ts_ms":1781237167563}}

{"type":"orderbook_delta","sid":1,"seq":2046,"msg":{"market_ticker":"KXBTCPERP1","price":"6.3099","delta":"-793.00","side":"ask","ts_ms":1781237167566}}

{"type":"orderbook_delta","sid":1,"seq":2047,"msg":{"market_ticker":"KXBTCPERP1","price":"6.3848","delta":"784.00","side":"ask","ts_ms":1781237167566}}

{"type":"orderbook_delta","sid":1,"seq":2048,"msg":{"market_ticker":"KXBTCPERP1","price":"6.3110","delta":"-793.00","side":"ask","ts_ms":1781237167570}}

{"type":"orderbook_delta","sid":1,"seq":2049,"msg":{"market_ticker":"KXBTCPERP1","price":"6.3850","delta":"784.00","side":"ask","ts_ms":1781237167570}}

{"type":"orderbook_delta","sid":1,"seq":2050,"msg":{"market_ticker":"KXBTCPERP1","price":"6.3121","delta":"-793.00","side":"ask","ts_ms":1781237167573}}

{"type":"orderbook_delta","sid":1,"seq":2051,"msg":{"market_ticker":"KXBTCPERP1","price":"6.3852","delta":"784.00","side":"ask","ts_ms":1781237167573}}

{"type":"orderbook_delta","sid":1,"seq":2052,"msg":{"market_ticker":"KXBTCPERP1","price":"6.3132","delta":"-792.00","side":"ask","ts_ms":1781237167576}}

{"type":"orderbook_delta","sid":1,"seq":2053,"msg":{"market_ticker":"KXBTCPERP1","price":"6.3854","delta":"784.00","side":"ask","ts_ms":1781237167576}}

{"type":"orderbook_delta","sid":1,"seq":2054,"msg":{"market_ticker":"KXBTCPERP1","price":"6.3856","delta":"784.00","side":"ask","ts_ms":1781237167580}}

{"type":"orderbook_delta","sid":1,"seq":2055,"msg":{"market_ticker":"KXBTCPERP1","price":"6.3858","delta":"783.00","side":"ask","ts_ms":1781237167583}}

{"type":"orderbook_delta","sid":1,"seq":2056,"msg":{"market_ticker":"KXBTCPERP1","price":"6.3860","delta":"783.00","side":"ask","ts_ms":1781237167586}}

{"type":"orderbook_delta","sid":1,"seq":2057,"msg":{"market_ticker":"KXBTCPERP1","price":"6.3072","delta":"-1.00","side":"ask","ts_ms":1781237167590}}

{"type":"orderbook_delta","sid":1,"seq":2058,"msg":{"market_ticker":"KXBTCPERP1","price":"6.3090","delta":"-10.00","side":"ask","ts_ms":1781237167590}}

{"type":"orderbook_delta","sid":1,"seq":2059,"msg":{"market_ticker":"KXBTCPERP1","price":"6.3091","delta":"-10.00","side":"ask","ts_ms":1781237167590}}

{"type":"orderbook_delta","sid":1,"seq":2060,"msg":{"market_ticker":"KXBTCPERP1","price":"6.3132","delta":"-1.00","side":"ask","ts_ms":1781237167590}}

{"type":"orderbook_delta","sid":1,"seq":2061,"msg":{"market_ticker":"KXBTCPERP1","price":"6.3144","delta":"-133.00","side":"ask","ts_ms":1781237167590}}

{"type":"orderbook_delta","sid":1,"seq":2062,"msg":{"market_ticker":"KXBTCPERP1","price":"6.3223","delta":"-432.00","side":"ask","ts_ms":1781237167590}}

{"type":"orderbook_delta","sid":1,"seq":2063,"msg":{"market_ticker":"KXBTCPERP1","price":"6.2910","delta":"-598.00","side":"bid","ts_ms":1781237167590}}

{"type":"trade","sid":2,"seq":1802,"msg":{"trade_id":"247cfa05-0269-4d96-559e-64940d782968","market_ticker":"KXBTCPERP1","price":"6.3072","count":"1.00","taker_side":"bid","ts_ms":1781237167590}}

{"type":"trade","sid":2,"seq":1803,"msg":{"trade_id":"233417ce-c88f-4c1a-4704-72e9cba8ab57","market_ticker":"KXBTCPERP1","price":"6.3090","count":"10.00","taker_side":"bid","ts_ms":1781237167590}}

{"type":"trade","sid":2,"seq":1804,"msg":{"trade_id":"4388ab57-d1b6-4818-63d7-8cca94e4155b","market_ticker":"KXBTCPERP1","price":"6.3091","count":"10.00","taker_side":"bid","ts_ms":1781237167590}}

{"type":"trade","sid":2,"seq":1805,"msg":{"trade_id":"d6045a06-8829-4ccb-7d36-2e90e7221873","market_ticker":"KXBTCPERP1","price":"6.3132","count":"1.00","taker_side":"bid","ts_ms":1781237167590}}

{"type":"trade","sid":2,"seq":1806,"msg":{"trade_id":"3c16253b-b880-4e29-4a3a-a14213046549","market_ticker":"KXBTCPERP1","price":"6.3144","count":"133.00","taker_side":"bid","ts_ms":1781237167590}}

{"type":"trade","sid":2,"seq":1807,"msg":{"trade_id":"fea5ebc9-f586-428a-5f0c-99f14ab368d5","market_ticker":"KXBTCPERP1","price":"6.3223","count":"432.00","taker_side":"bid","ts_ms":1781237167590}}

{"type":"orderbook_delta","sid":1,"seq":2064,"msg":{"market_ticker":"KXBTCPERP1","price":"6.3223","delta":"-99.00","side":"ask","ts_ms":1781237167594}}

{"type":"orderbook_delta","sid":1,"seq":2065,"msg":{"market_ticker":"KXBTCPERP1","price":"6.3265","delta":"-1.00","side":"ask","ts_ms":1781237167594}}

{"type":"orderbook_delta","sid":1,"seq":2066,"msg":{"market_ticker":"KXBTCPERP1","price":"6.3314","delta":"-1.00","side":"ask","ts_ms":1781237167594}}

{"type":"orderbook_delta","sid":1,"seq":2067,"msg":{"market_ticker":"KXBTCPERP1","price":"6.3328","delta":"-1.00","side":"ask","ts_ms":1781237167594}}

{"type":"orderbook_delta","sid":1,"seq":2068,"msg":{"market_ticker":"KXBTCPERP1","price":"6.3330","delta":"-1.00","side":"ask","ts_ms":1781237167594}}

{"type":"orderbook_delta","sid":1,"seq":2069,"msg":{"market_ticker":"KXBTCPERP1","price":"6.3531","delta":"-1.00","side":"ask","ts_ms":1781237167594}}

{"type":"orderbook_delta","sid":1,"seq":2070,"msg":{"market_ticker":"KXBTCPERP1","price":"6.3578","delta":"-1.00","side":"ask","ts_ms":1781237167594}}

{"type":"orderbook_delta","sid":1,"seq":2071,"msg":{"market_ticker":"KXBTCPERP1","price":"6.3610","delta":"-1.00","side":"ask","ts_ms":1781237167594}}

{"type":"orderbook_delta","sid":1,"seq":2072,"msg":{"market_ticker":"KXBTCPERP1","price":"6.3644","delta":"-1.00","side":"ask","ts_ms":1781237167594}}

{"type":"orderbook_delta","sid":1,"seq":2073,"msg":{"market_ticker":"KXBTCPERP1","price":"6.3697","delta":"-1.00","side":"ask","ts_ms":1781237167594}}

{"type":"orderbook_delta","sid":1,"seq":2074,"msg":{"market_ticker":"KXBTCPERP1","price":"6.2899","delta":"-795.00","side":"bid","ts_ms":1781237167594}}

{"type":"orderbook_delta","sid":1,"seq":2075,"msg":{"market_ticker":"KXBTCPERP1","price":"6.3829","delta":"676.00","side":"bid","ts_ms":1781237167594}}

{"type":"trade","sid":2,"seq":1808,"msg":{"trade_id":"c66880a6-8e16-744a-b7aa-6e2884d05db1","market_ticker":"KXBTCPERP1","price":"6.3223","count":"99.00","taker_side":"bid","ts_ms":1781237167594}}

{"type":"trade","sid":2,"seq":1809,"msg":{"trade_id":"faace39e-dc12-7efe-8152-c9469fd6f1fc","market_ticker":"KXBTCPERP1","price":"6.3265","count":"1.00","taker_side":"bid","ts_ms":1781237167594}}

{"type":"trade","sid":2,"seq":1810,"msg":{"trade_id":"40725a06-20c6-76fe-aebd-9faefae6c927","market_ticker":"KXBTCPERP1","price":"6.3314","count":"1.00","taker_side":"bid","ts_ms":1781237167594}}

{"type":"trade","sid":2,"seq":1811,"msg":{"trade_id":"d1999e7e-e071-700b-a9d1-da6cdc468e34","market_ticker":"KXBTCPERP1","price":"6.3328","count":"1.00","taker_side":"bid","ts_ms":1781237167594}}

{"type":"trade","sid":2,"seq":1812,"msg":{"trade_id":"962c78df-4a0d-740f-ab4f-1b1b422b4ce3","market_ticker":"KXBTCPERP1","price":"6.3330","count":"1.00","taker_side":"bid","ts_ms":1781237167594}}

{"type":"trade","sid":2,"seq":1813,"msg":{"trade_id":"30c0e7a8-ff5d-7fad-a8e4-e46fe7b39158","market_ticker":"KXBTCPERP1","price":"6.3531","count":"1.00","taker_side":"bid","ts_ms":1781237167594}}

{"type":"trade","sid":2,"seq":1814,"msg":{"trade_id":"866d384b-3bbe-7519-acd9-b25c98c769d2","market_ticker":"KXBTCPERP1","price":"6.3578","count":"1.00","taker_side":"bid","ts_ms":1781237167594}}

{"type":"trade","sid":2,"seq":1815,"msg":{"trade_id":"fd17e564-fb91-7f0c-8d59-9d2a79188d59","market_ticker":"KXBTCPERP1","price":"6.3610","count":"1.00","taker_side":"bid","ts_ms":1781237167594}}

{"type":"trade","sid":2,"seq":1816,"msg":{"trade_id":"ea5645ea-c020-795c-925e-87b273943838","market_ticker":"KXBTCPERP1","price":"6.3644","count":"1.00","taker_side":"bid","ts_ms":1781237167594}}

{"type":"trade","sid":2,"seq":1817,"msg":{"trade_id":"0d8a7426-2c09-7cb0-8ede-cca15f275813","market_ticker":"KXBTCPERP1","price":"6.3697","count":"1.00","taker_side":"bid","ts_ms":1781237167594}}

{"type":"orderbook_delta","sid":1,"seq":2076,"msg":{"market_ticker":"KXBTCPERP1","price":"6.2888","delta":"-795.00","side":"bid","ts_ms":1781237167598}}

{"type":"orderbook_delta","sid":1,"seq":2077,"msg":{"market_ticker":"KXBTCPERP1","price":"6.3827","delta":"783.00","side":"bid","ts_ms":1781237167598}}

{"type":"orderbook_delta","sid":1,"seq":2078,"msg":{"market_ticker":"KXBTCPERP1","price":"6.2877","delta":"-796.00","side":"bid","ts_ms":1781237167601}}

{"type":"orderbook_delta","sid":1,"seq":2079,"msg":{"market_ticker":"KXBTCPERP1","price":"6.3825","delta":"784.00","side":"bid","ts_ms":1781237167601}}

{"type":"orderbook_delta","sid":1,"seq":2080,"msg":{"market_ticker":"KXBTCPERP1","price":"6.2866","delta":"-795.00","side":"bid","ts_ms":1781237167605}}

{"type":"orderbook_delta","sid":1,"seq":2081,"msg":{"market_ticker":"KXBTCPERP1","price":"6.3823","delta":"783.00","side":"bid","ts_ms":1781237167605}}

{"type":"orderbook_delta","sid":1,"seq":2082,"msg":{"market_ticker":"KXBTCPERP1","price":"6.2855","delta":"-796.00","side":"bid","ts_ms":1781237167608}}

{"type":"orderbook_delta","sid":1,"seq":2083,"msg":{"market_ticker":"KXBTCPERP1","price":"6.3821","delta":"784.00","side":"bid","ts_ms":1781237167608}}

{"type":"orderbook_delta","sid":1,"seq":2084,"msg":{"market_ticker":"KXBTCPERP1","price":"6.2844","delta":"-795.00","side":"bid","ts_ms":1781237167611}}

{"type":"orderbook_delta","sid":1,"seq":2085,"msg":{"market_ticker":"KXBTCPERP1","price":"6.3819","delta":"783.00","side":"bid","ts_ms":1781237167611}}

{"type":"orderbook_delta","sid":1,"seq":2086,"msg":{"market_ticker":"KXBTCPERP1","price":"6.2833","delta":"-796.00","side":"bid","ts_ms":1781237167614}}

{"type":"orderbook_delta","sid":1,"seq":2087,"msg":{"market_ticker":"KXBTCPERP1","price":"6.3817","delta":"784.00","side":"bid","ts_ms":1781237167614}}

{"type":"orderbook_delta","sid":1,"seq":2088,"msg":{"market_ticker":"KXBTCPERP1","price":"6.2822","delta":"-796.00","side":"bid","ts_ms":1781237167618}}

{"type":"orderbook_delta","sid":1,"seq":2089,"msg":{"market_ticker":"KXBTCPERP1","price":"6.3815","delta":"784.00","side":"bid","ts_ms":1781237167618}}

{"type":"orderbook_delta","sid":1,"seq":2090,"msg":{"market_ticker":"KXBTCPERP1","price":"6.2570","delta":"1.00","side":"bid","ts_ms":1781237167619}}

{"type":"orderbook_delta","sid":1,"seq":2091,"msg":{"market_ticker":"KXBTCPERP1","price":"6.2811","delta":"-797.00","side":"bid","ts_ms":1781237167621}}

{"type":"orderbook_delta","sid":1,"seq":2092,"msg":{"market_ticker":"KXBTCPERP1","price":"6.3813","delta":"784.00","side":"bid","ts_ms":1781237167621}}

{"type":"orderbook_delta","sid":1,"seq":2093,"msg":{"market_ticker":"KXBTCPERP1","price":"6.2319","delta":"1.00","side":"bid","ts_ms":1781237167774}}

{"type":"trade","sid":2,"seq":1818,"msg":{"trade_id":"9590cb71-b494-7f8b-178c-bdf2bde143af","market_ticker":"KXBTCPERP1","price":"6.3829","count":"1.00","taker_side":"ask","ts_ms":1781237167951}}

{"type":"orderbook_delta","sid":1,"seq":2094,"msg":{"market_ticker":"KXBTCPERP1","price":"6.3829","delta":"-1.00","side":"bid","ts_ms":1781237167951}}

{"type":"orderbook_delta","sid":1,"seq":2095,"msg":{"market_ticker":"KXBTCPERP1","price":"6.4039","delta":"1.00","side":"ask","ts_ms":1781237168042}}

{"type":"orderbook_delta","sid":1,"seq":2096,"msg":{"market_ticker":"KXBTCPERP1","price":"6.2214","delta":"-1.00","side":"bid","ts_ms":1781237168159}}

{"type":"trade","sid":2,"seq":1819,"msg":{"trade_id":"9004155f-ae54-6217-d058-01ea59a4fef7","market_ticker":"KXBTCPERP1","price":"6.3829","count":"1.00","taker_side":"ask","ts_ms":1781237168246}}

{"type":"orderbook_delta","sid":1,"seq":2097,"msg":{"market_ticker":"KXBTCPERP1","price":"6.3829","delta":"-1.00","side":"bid","ts_ms":1781237168246}}

{"type":"orderbook_delta","sid":1,"seq":2098,"msg":{"market_ticker":"KXBTCPERP1","price":"6.3829","delta":"-1.00","side":"bid","ts_ms":1781237168301}}

{"type":"trade","sid":2,"seq":1820,"msg":{"trade_id":"81b946e0-6d94-50fb-7714-ba087fbf4b8b","market_ticker":"KXBTCPERP1","price":"6.3829","count":"1.00","taker_side":"ask","ts_ms":1781237168301}}

{"type":"orderbook_delta","sid":1,"seq":2099,"msg":{"market_ticker":"KXBTCPERP1","price":"6.3829","delta":"-1.00","side":"bid","ts_ms":1781237168352}}

{"type":"trade","sid":2,"seq":1821,"msg":{"trade_id":"38f3e894-5240-7bbb-c298-494a910b14ab","market_ticker":"KXBTCPERP1","price":"6.3829","count":"1.00","taker_side":"ask","ts_ms":1781237168352}}

{"type":"trade","sid":2,"seq":1822,"msg":{"trade_id":"a7fbc210-33d2-617d-9332-3b1f4fa395f2","market_ticker":"KXBTCPERP1","price":"6.3842","count":"1.00","taker_side":"bid","ts_ms":1781237168404}}

{"type":"orderbook_delta","sid":1,"seq":2100,"msg":{"market_ticker":"KXBTCPERP1","price":"6.3842","delta":"-1.00","side":"ask","ts_ms":1781237168404}}

{"type":"orderbook_delta","sid":1,"seq":2101,"msg":{"market_ticker":"KXBTCPERP1","price":"7.6637","delta":"-1.00","side":"ask","ts_ms":1781237168405}}

{"type":"orderbook_delta","sid":1,"seq":2102,"msg":{"market_ticker":"KXBTCPERP1","price":"6.3829","delta":"-1.00","side":"bid","ts_ms":1781237168441}}

{"type":"trade","sid":2,"seq":1823,"msg":{"trade_id":"58c599ba-1544-6377-5b2d-f45f3ae36d07","market_ticker":"KXBTCPERP1","price":"6.3829","count":"1.00","taker_side":"ask","ts_ms":1781237168441}}

{"type":"orderbook_delta","sid":1,"seq":2103,"msg":{"market_ticker":"KXBTCPERP1","price":"6.2657","delta":"1.00","side":"bid","ts_ms":1781237168465}}

{"type":"ticker","sid":3,"msg":{"market_ticker":"KXBTCPERP1","price":"6.3329","bid":"6.3329","ask":"6.3416","bid_size_fp":"343.00","ask_size_fp":"658.00","last_trade_size_fp":"0.00","volume":"4179467045.00","volume_notional_value_dollars":"3245141294.960300","volume_24h":"1877080.00","volume_24h_notional_value_dollars":"11687174.591200","open_interest":"2332769.00","open_interest_notional_value_dollars":"14773192.800100","reference_price":{"price":"6.3414","ts_ms":1781237168000},"settlement_mark_price":{"price":"6.3742","ts_ms":1781237163039},"liquidation_mark_price":{"price":"6.3800","ts_ms":1781237168398},"funding_rate":{"rate":0,"next_funding_time_ms":1781265600000,"ts_ms":1781237163039},"ts_ms":1781217877584}}

{"type":"orderbook_delta","sid":1,"seq":2104,"msg":{"market_ticker":"KXBTCPERP1","price":"6.2263","delta":"-1.00","side":"bid","ts_ms":1781237168541}}

{"type":"orderbook_delta","sid":1,"seq":2105,"msg":{"market_ticker":"KXBTCPERP1","price":"6.2973","delta":"-1.00","side":"bid","ts_ms":1781237168594}}

{"type":"orderbook_delta","sid":1,"seq":2106,"msg":{"market_ticker":"KXBTCPERP1","price":"6.3842","delta":"-1.00","side":"ask","ts_ms":1781237168676}}

{"type":"trade","sid":2,"seq":1824,"msg":{"trade_id":"c2d191f5-569a-4975-73d3-e9bc12509c16","market_ticker":"KXBTCPERP1","price":"6.3842","count":"1.00","taker_side":"bid","ts_ms":1781237168676}}

{"type":"orderbook_delta","sid":1,"seq":2107,"msg":{"market_ticker":"KXBTCPERP1","price":"6.3829","delta":"-1.00","side":"bid","ts_ms":1781237168773}}

{"type":"trade","sid":2,"seq":1825,"msg":{"trade_id":"57a074ba-4b40-4867-569f-498b8e6b06cb","market_ticker":"KXBTCPERP1","price":"6.3829","count":"1.00","taker_side":"ask","ts_ms":1781237168773}}

{"type":"orderbook_delta","sid":1,"seq":2108,"msg":{"market_ticker":"KXBTCPERP1","price":"6.3859","delta":"10.00","side":"ask","ts_ms":1781237168941}}

{"type":"orderbook_delta","sid":1,"seq":2109,"msg":{"market_ticker":"KXBTCPERP1","price":"6.4224","delta":"1.00","side":"ask","ts_ms":1781237168960}}

{"type":"orderbook_delta","sid":1,"seq":2110,"msg":{"market_ticker":"KXBTCPERP1","price":"6.3858","delta":"11.00","side":"ask","ts_ms":1781237169045}}

{"type":"orderbook_delta","sid":1,"seq":2111,"msg":{"market_ticker":"KXBTCPERP1","price":"6.1803","delta":"-1.00","side":"bid","ts_ms":1781237169141}}

{"type":"orderbook_delta","sid":1,"seq":2112,"msg":{"market_ticker":"KXBTCPERP1","price":"6.3908","delta":"136.00","side":"ask","ts_ms":1781237169143}}

{"type":"orderbook_delta","sid":1,"seq":2113,"msg":{"market_ticker":"KXBTCPERP1","price":"6.3829","delta":"-1.00","side":"bid","ts_ms":1781237169168}}

{"type":"trade","sid":2,"seq":1826,"msg":{"trade_id":"bf49dcc5-0ba0-5343-4098-6fd7eac29033","market_ticker":"KXBTCPERP1","price":"6.3829","count":"1.00","taker_side":"ask","ts_ms":1781237169168}}

{"type":"orderbook_delta","sid":1,"seq":2114,"msg":{"market_ticker":"KXBTCPERP1","price":"6.3982","delta":"543.00","side":"ask","ts_ms":1781237169244}}

{"type":"orderbook_delta","sid":1,"seq":2115,"msg":{"market_ticker":"KXBTCPERP1","price":"6.3842","delta":"-1.00","side":"ask","ts_ms":1781237169348}}

{"type":"trade","sid":2,"seq":1827,"msg":{"trade_id":"d418f4cb-d2e2-7ead-d285-a6fe0c65175e","market_ticker":"KXBTCPERP1","price":"6.3842","count":"1.00","taker_side":"bid","ts_ms":1781237169348}}

{"type":"orderbook_delta","sid":1,"seq":2116,"msg":{"market_ticker":"KXBTCPERP1","price":"6.3829","delta":"-1.00","side":"bid","ts_ms":1781237169394}}

{"type":"trade","sid":2,"seq":1828,"msg":{"trade_id":"0fb24cb1-5614-730f-fd2e-034b88c84f33","market_ticker":"KXBTCPERP1","price":"6.3829","count":"1.00","taker_side":"ask","ts_ms":1781237169394}}

{"type":"orderbook_delta","sid":1,"seq":2117,"msg":{"market_ticker":"KXBTCPERP1","price":"6.3842","delta":"-1.00","side":"ask","ts_ms":1781237169452}}

{"type":"trade","sid":2,"seq":1829,"msg":{"trade_id":"a51a2d6a-5e3a-5a6d-1537-a1401ddcb4ca","market_ticker":"KXBTCPERP1","price":"6.3842","count":"1.00","taker_side":"bid","ts_ms":1781237169452}}

{"type":"ticker","sid":3,"msg":{"market_ticker":"KXBTCPERP1","price":"6.3329","bid":"6.3329","ask":"6.3416","bid_size_fp":"343.00","ask_size_fp":"658.00","last_trade_size_fp":"0.00","volume":"4179467045.00","volume_notional_value_dollars":"3245141294.960300","volume_24h":"1877080.00","volume_24h_notional_value_dollars":"11687174.591200","open_interest":"2332769.00","open_interest_notional_value_dollars":"14773192.800100","reference_price":{"price":"6.3413","ts_ms":1781237169000},"settlement_mark_price":{"price":"6.3512","ts_ms":1781237168036},"liquidation_mark_price":{"price":"6.3799","ts_ms":1781237169398},"funding_rate":{"rate":0,"next_funding_time_ms":1781265600000,"ts_ms":1781237168036},"ts_ms":1781217877584}}

{"type":"orderbook_delta","sid":1,"seq":2118,"msg":{"market_ticker":"KXBTCPERP1","price":"6.2969","delta":"1.00","side":"bid","ts_ms":1781237169544}}

{"type":"orderbook_delta","sid":1,"seq":2119,"msg":{"market_ticker":"KXBTCPERP1","price":"6.4219","delta":"1.00","side":"ask","ts_ms":1781237169723}}

{"type":"orderbook_delta","sid":1,"seq":2120,"msg":{"market_ticker":"KXBTCPERP1","price":"6.4014","delta":"1.00","side":"ask","ts_ms":1781237169794}}

{"type":"orderbook_delta","sid":1,"seq":2121,"msg":{"market_ticker":"KXBTCPERP1","price":"6.3167","delta":"1.00","side":"bid","ts_ms":1781237169802}}

{"type":"orderbook_delta","sid":1,"seq":2122,"msg":{"market_ticker":"KXBTCPERP1","price":"6.4899","delta":"-1.00","side":"ask","ts_ms":1781237169835}}

{"type":"orderbook_delta","sid":1,"seq":2123,"msg":{"market_ticker":"KXBTCPERP1","price":"6.3222","delta":"1.00","side":"bid","ts_ms":1781237169909}}

{"type":"orderbook_delta","sid":1,"seq":2124,"msg":{"market_ticker":"KXBTCPERP1","price":"6.3829","delta":"-1.00","side":"bid","ts_ms":1781237169986}}

{"type":"trade","sid":2,"seq":1830,"msg":{"trade_id":"083a182c-9864-6487-82df-48ed7c46c257","market_ticker":"KXBTCPERP1","price":"6.3829","count":"1.00","taker_side":"ask","ts_ms":1781237169986}}

{"type":"orderbook_delta","sid":1,"seq":2125,"msg":{"market_ticker":"KXBTCPERP1","price":"6.3829","delta":"-1.00","side":"bid","ts_ms":1781237170092}}

{"type":"trade","sid":2,"seq":1831,"msg":{"trade_id":"29936c21-cc64-77cf-08a5-d24c6fb5d48f","market_ticker":"KXBTCPERP1","price":"6.3829","count":"1.00","taker_side":"ask","ts_ms":1781237170092}}

{"type":"trade","sid":2,"seq":1832,"msg":{"trade_id":"a471a09d-691a-64c9-d4f3-6988fb62db52","market_ticker":"KXBTCPERP1","price":"6.3842","count":"1.00","taker_side":"bid","ts_ms":1781237170132}}

{"type":"orderbook_delta","sid":1,"seq":2126,"msg":{"market_ticker":"KXBTCPERP1","price":"6.3842","delta":"-1.00","side":"ask","ts_ms":1781237170132}}

{"type":"orderbook_delta","sid":1,"seq":2127,"msg":{"market_ticker":"KXBTCPERP1","price":"6.3043","delta":"-11.00","side":"bid","ts_ms":1781237170152}}

{"type":"orderbook_delta","sid":1,"seq":2128,"msg":{"market_ticker":"KXBTCPERP1","price":"6.3813","delta":"11.00","side":"bid","ts_ms":1781237170152}}

{"type":"orderbook_delta","sid":1,"seq":2129,"msg":{"market_ticker":"KXBTCPERP1","price":"6.3042","delta":"-10.00","side":"bid","ts_ms":1781237170253}}

{"type":"orderbook_delta","sid":1,"seq":2130,"msg":{"market_ticker":"KXBTCPERP1","price":"6.3812","delta":"10.00","side":"bid","ts_ms":1781237170253}}

{"type":"orderbook_delta","sid":1,"seq":2131,"msg":{"market_ticker":"KXBTCPERP1","price":"6.4156","delta":"1.00","side":"ask","ts_ms":1781237170266}}

{"type":"orderbook_delta","sid":1,"seq":2132,"msg":{"market_ticker":"KXBTCPERP1","price":"6.2333","delta":"-1.00","side":"bid","ts_ms":1781237170417}}

{"type":"orderbook_delta","sid":1,"seq":2133,"msg":{"market_ticker":"KXBTCPERP1","price":"6.4081","delta":"1.00","side":"ask","ts_ms":1781237170441}}

{"type":"orderbook_delta","sid":1,"seq":2134,"msg":{"market_ticker":"KXBTCPERP1","price":"6.2994","delta":"-139.00","side":"bid","ts_ms":1781237170454}}

{"type":"orderbook_delta","sid":1,"seq":2135,"msg":{"market_ticker":"KXBTCPERP1","price":"6.3764","delta":"137.00","side":"bid","ts_ms":1781237170454}}

{"type":"ticker","sid":3,"msg":{"market_ticker":"KXBTCPERP1","price":"6.3329","bid":"6.3329","ask":"6.3416","bid_size_fp":"343.00","ask_size_fp":"658.00","last_trade_size_fp":"0.00","volume":"4179467045.00","volume_notional_value_dollars":"3245141294.960300","volume_24h":"1877080.00","volume_24h_notional_value_dollars":"11687174.591200","open_interest":"2332769.00","open_interest_notional_value_dollars":"14773192.800100","reference_price":{"price":"6.3403","ts_ms":1781237170000},"settlement_mark_price":{"price":"6.3512","ts_ms":1781237168036},"liquidation_mark_price":{"price":"6.3789","ts_ms":1781237170398},"funding_rate":{"rate":0,"next_funding_time_ms":1781265600000,"ts_ms":1781237168036},"ts_ms":1781217877584}}

{"type":"orderbook_delta","sid":1,"seq":2136,"msg":{"market_ticker":"KXBTCPERP1","price":"6.2923","delta":"-554.00","side":"bid","ts_ms":1781237170555}}

{"type":"orderbook_delta","sid":1,"seq":2137,"msg":{"market_ticker":"KXBTCPERP1","price":"6.3691","delta":"547.00","side":"bid","ts_ms":1781237170555}}

{"type":"orderbook_delta","sid":1,"seq":2138,"msg":{"market_ticker":"KXBTCPERP1","price":"6.3504","delta":"1.00","side":"bid","ts_ms":1781237170631}}

{"type":"orderbook_delta","sid":1,"seq":2139,"msg":{"market_ticker":"KXBTCPERP1","price":"6.4125","delta":"1.00","side":"ask","ts_ms":1781237170735}}

{"type":"orderbook_delta","sid":1,"seq":2140,"msg":{"market_ticker":"KXBTCPERP1","price":"6.3829","delta":"-1.00","side":"bid","ts_ms":1781237170910}}

{"type":"trade","sid":2,"seq":1833,"msg":{"trade_id":"2de42042-262c-4c97-e8a6-883bc1e4e30f","market_ticker":"KXBTCPERP1","price":"6.3829","count":"1.00","taker_side":"ask","ts_ms":1781237170910}}

{"type":"orderbook_delta","sid":1,"seq":2141,"msg":{"market_ticker":"KXBTCPERP1","price":"6.4257","delta":"1.00","side":"ask","ts_ms":1781237170970}}

{"type":"orderbook_delta","sid":1,"seq":2142,"msg":{"market_ticker":"KXBTCPERP1","price":"6.3829","delta":"-1.00","side":"bid","ts_ms":1781237171002}}

{"type":"trade","sid":2,"seq":1834,"msg":{"trade_id":"e7ccc68c-c5d8-7ebb-fa0a-347fa08293a7","market_ticker":"KXBTCPERP1","price":"6.3829","count":"1.00","taker_side":"ask","ts_ms":1781237171002}}

{"type":"orderbook_delta","sid":1,"seq":2143,"msg":{"market_ticker":"KXBTCPERP1","price":"6.3842","delta":"-1.00","side":"ask","ts_ms":1781237171085}}

{"type":"trade","sid":2,"seq":1835,"msg":{"trade_id":"5b619820-2b16-71c9-3cd3-650bd80f08fe","market_ticker":"KXBTCPERP1","price":"6.3842","count":"1.00","taker_side":"bid","ts_ms":1781237171085}}

{"type":"orderbook_delta","sid":1,"seq":2144,"msg":{"market_ticker":"KXBTCPERP1","price":"6.2867","delta":"1.00","side":"bid","ts_ms":1781237171116}}

{"type":"orderbook_delta","sid":1,"seq":2145,"msg":{"market_ticker":"KXBTCPERP1","price":"6.4176","delta":"1.00","side":"ask","ts_ms":1781237171177}}

{"type":"orderbook_delta","sid":1,"seq":2146,"msg":{"market_ticker":"KXBTCPERP1","price":"6.3050","delta":"1.00","side":"bid","ts_ms":1781237171204}}

{"type":"orderbook_delta","sid":1,"seq":2147,"msg":{"market_ticker":"KXBTCPERP1","price":"6.2993","delta":"1.00","side":"bid","ts_ms":1781237171237}}

{"type":"orderbook_delta","sid":1,"seq":2148,"msg":{"market_ticker":"KXBTCPERP1","price":"6.3842","delta":"-1.00","side":"ask","ts_ms":1781237171328}}

{"type":"trade","sid":2,"seq":1836,"msg":{"trade_id":"5bafa993-b846-63c1-1ad3-c6cff579fac6","market_ticker":"KXBTCPERP1","price":"6.3842","count":"1.00","taker_side":"bid","ts_ms":1781237171328}}

{"type":"trade","sid":2,"seq":1837,"msg":{"trade_id":"6c57f34c-6fe2-56f5-2dcb-91b0b99954a6","market_ticker":"KXBTCPERP1","price":"6.3842","count":"1.00","taker_side":"bid","ts_ms":1781237171443}}

{"type":"orderbook_delta","sid":1,"seq":2149,"msg":{"market_ticker":"KXBTCPERP1","price":"6.3842","delta":"-1.00","side":"ask","ts_ms":1781237171443}}

{"type":"ticker","sid":3,"msg":{"market_ticker":"KXBTCPERP1","price":"6.3329","bid":"6.3329","ask":"6.3416","bid_size_fp":"343.00","ask_size_fp":"658.00","last_trade_size_fp":"0.00","volume":"4179467045.00","volume_notional_value_dollars":"3245141294.960300","volume_24h":"1877080.00","volume_24h_notional_value_dollars":"11687174.591200","open_interest":"2332769.00","open_interest_notional_value_dollars":"14773192.800100","reference_price":{"price":"6.3403","ts_ms":1781237171000},"settlement_mark_price":{"price":"6.3512","ts_ms":1781237168036},"liquidation_mark_price":{"price":"6.3789","ts_ms":1781237171398},"funding_rate":{"rate":0,"next_funding_time_ms":1781265600000,"ts_ms":1781237168036},"ts_ms":1781217877584}}

{"type":"trade","sid":2,"seq":1838,"msg":{"trade_id":"dcae8d6c-fa9a-4b79-035d-a4b0cdcfd85e","market_ticker":"KXBTCPERP1","price":"6.3842","count":"1.00","taker_side":"bid","ts_ms":1781237171509}}

{"type":"orderbook_delta","sid":1,"seq":2150,"msg":{"market_ticker":"KXBTCPERP1","price":"6.3842","delta":"-1.00","side":"ask","ts_ms":1781237171509}}

{"type":"orderbook_delta","sid":1,"seq":2151,"msg":{"market_ticker":"KXBTCPERP1","price":"6.4186","delta":"1.00","side":"ask","ts_ms":1781237171548}}

{"type":"orderbook_delta","sid":1,"seq":2152,"msg":{"market_ticker":"KXBTCPERP1","price":"6.3829","delta":"-1.00","side":"bid","ts_ms":1781237171556}}

{"type":"trade","sid":2,"seq":1839,"msg":{"trade_id":"71fb9b90-6c20-4d1b-091b-0259b8c3d893","market_ticker":"KXBTCPERP1","price":"6.3829","count":"1.00","taker_side":"ask","ts_ms":1781237171556}}

{"type":"orderbook_delta","sid":1,"seq":2153,"msg":{"market_ticker":"KXBTCPERP1","price":"6.3829","delta":"-1.00","side":"bid","ts_ms":1781237171609}}

{"type":"trade","sid":2,"seq":1840,"msg":{"trade_id":"6a202ebf-9470-4b4b-12a9-d5a3643d40c7","market_ticker":"KXBTCPERP1","price":"6.3829","count":"1.00","taker_side":"ask","ts_ms":1781237171609}}

{"type":"orderbook_delta","sid":1,"seq":2154,"msg":{"market_ticker":"KXBTCPERP1","price":"6.3490","delta":"1.00","side":"bid","ts_ms":1781237171782}}

{"type":"orderbook_delta","sid":1,"seq":2155,"msg":{"market_ticker":"KXBTCPERP1","price":"6.2451","delta":"1.00","side":"bid","ts_ms":1781237171951}}

{"type":"orderbook_delta","sid":1,"seq":2156,"msg":{"market_ticker":"KXBTCPERP1","price":"6.2179","delta":"1.00","side":"bid","ts_ms":1781237172163}}

{"type":"orderbook_delta","sid":1,"seq":2157,"msg":{"market_ticker":"KXBTCPERP1","price":"6.3829","delta":"-1.00","side":"bid","ts_ms":1781237172225}}

{"type":"trade","sid":2,"seq":1841,"msg":{"trade_id":"8d7e2738-24c0-6f3b-a4a5-4803aea9d6e7","market_ticker":"KXBTCPERP1","price":"6.3829","count":"1.00","taker_side":"ask","ts_ms":1781237172225}}

{"type":"orderbook_delta","sid":1,"seq":2158,"msg":{"market_ticker":"KXBTCPERP1","price":"6.3366","delta":"1.00","side":"bid","ts_ms":1781237172316}}

{"type":"orderbook_delta","sid":1,"seq":2159,"msg":{"market_ticker":"KXBTCPERP1","price":"6.4720","delta":"-1.00","side":"ask","ts_ms":1781237172326}}

{"type":"orderbook_delta","sid":1,"seq":2160,"msg":{"market_ticker":"KXBTCPERP1","price":"6.3842","delta":"-1.00","side":"ask","ts_ms":1781237172441}}

{"type":"trade","sid":2,"seq":1842,"msg":{"trade_id":"99aab48a-2456-7ca9-8d6d-d8bb380ada22","market_ticker":"KXBTCPERP1","price":"6.3842","count":"1.00","taker_side":"bid","ts_ms":1781237172441}}

{"type":"ticker","sid":3,"msg":{"market_ticker":"KXBTCPERP1","price":"6.3329","bid":"6.3329","ask":"6.3416","bid_size_fp":"343.00","ask_size_fp":"658.00","last_trade_size_fp":"0.00","volume":"4179467045.00","volume_notional_value_dollars":"3245141294.960300","volume_24h":"1877080.00","volume_24h_notional_value_dollars":"11687174.591200","open_interest":"2332769.00","open_interest_notional_value_dollars":"14773192.800100","reference_price":{"price":"6.3398","ts_ms":1781237172000},"settlement_mark_price":{"price":"6.3512","ts_ms":1781237168036},"liquidation_mark_price":{"price":"6.3785","ts_ms":1781237172399},"funding_rate":{"rate":0,"next_funding_time_ms":1781265600000,"ts_ms":1781237168036},"ts_ms":1781217877584}}

{"type":"orderbook_delta","sid":1,"seq":2161,"msg":{"market_ticker":"KXBTCPERP1","price":"6.3842","delta":"-305.00","side":"ask","ts_ms":1781237172513}}

{"type":"orderbook_delta","sid":1,"seq":2162,"msg":{"market_ticker":"KXBTCPERP1","price":"6.3916","delta":"304.00","side":"ask","ts_ms":1781237172513}}

{"type":"orderbook_delta","sid":1,"seq":2163,"msg":{"market_ticker":"KXBTCPERP1","price":"6.3844","delta":"-784.00","side":"ask","ts_ms":1781237172517}}

{"type":"orderbook_delta","sid":1,"seq":2164,"msg":{"market_ticker":"KXBTCPERP1","price":"6.3919","delta":"783.00","side":"ask","ts_ms":1781237172517}}

{"type":"orderbook_delta","sid":1,"seq":2165,"msg":{"market_ticker":"KXBTCPERP1","price":"6.3846","delta":"-784.00","side":"ask","ts_ms":1781237172520}}

{"type":"orderbook_delta","sid":1,"seq":2166,"msg":{"market_ticker":"KXBTCPERP1","price":"6.3922","delta":"783.00","side":"ask","ts_ms":1781237172520}}

{"type":"orderbook_delta","sid":1,"seq":2167,"msg":{"market_ticker":"KXBTCPERP1","price":"6.3848","delta":"-784.00","side":"ask","ts_ms":1781237172523}}

{"type":"orderbook_delta","sid":1,"seq":2168,"msg":{"market_ticker":"KXBTCPERP1","price":"6.3925","delta":"783.00","side":"ask","ts_ms":1781237172523}}

{"type":"orderbook_delta","sid":1,"seq":2169,"msg":{"market_ticker":"KXBTCPERP1","price":"6.3850","delta":"-784.00","side":"ask","ts_ms":1781237172526}}

{"type":"orderbook_delta","sid":1,"seq":2170,"msg":{"market_ticker":"KXBTCPERP1","price":"6.3928","delta":"783.00","side":"ask","ts_ms":1781237172526}}

{"type":"orderbook_delta","sid":1,"seq":2171,"msg":{"market_ticker":"KXBTCPERP1","price":"6.3852","delta":"-784.00","side":"ask","ts_ms":1781237172529}}

{"type":"orderbook_delta","sid":1,"seq":2172,"msg":{"market_ticker":"KXBTCPERP1","price":"6.3931","delta":"783.00","side":"ask","ts_ms":1781237172529}}

{"type":"orderbook_delta","sid":1,"seq":2173,"msg":{"market_ticker":"KXBTCPERP1","price":"6.3854","delta":"-784.00","side":"ask","ts_ms":1781237172533}}

{"type":"orderbook_delta","sid":1,"seq":2174,"msg":{"market_ticker":"KXBTCPERP1","price":"6.3934","delta":"783.00","side":"ask","ts_ms":1781237172533}}

{"type":"orderbook_delta","sid":1,"seq":2175,"msg":{"market_ticker":"KXBTCPERP1","price":"6.3856","delta":"-784.00","side":"ask","ts_ms":1781237172536}}

{"type":"orderbook_delta","sid":1,"seq":2176,"msg":{"market_ticker":"KXBTCPERP1","price":"6.3937","delta":"783.00","side":"ask","ts_ms":1781237172536}}

{"type":"orderbook_delta","sid":1,"seq":2177,"msg":{"market_ticker":"KXBTCPERP1","price":"6.3858","delta":"-783.00","side":"ask","ts_ms":1781237172539}}

{"type":"orderbook_delta","sid":1,"seq":2178,"msg":{"market_ticker":"KXBTCPERP1","price":"6.3940","delta":"782.00","side":"ask","ts_ms":1781237172539}}

{"type":"orderbook_delta","sid":1,"seq":2179,"msg":{"market_ticker":"KXBTCPERP1","price":"6.3860","delta":"-783.00","side":"ask","ts_ms":1781237172542}}

{"type":"orderbook_delta","sid":1,"seq":2180,"msg":{"market_ticker":"KXBTCPERP1","price":"6.3943","delta":"782.00","side":"ask","ts_ms":1781237172542}}

{"type":"orderbook_delta","sid":1,"seq":2181,"msg":{"market_ticker":"KXBTCPERP1","price":"6.3858","delta":"-1.00","side":"ask","ts_ms":1781237172544}}

{"type":"trade","sid":2,"seq":1843,"msg":{"trade_id":"e65b810d-cb1d-56d6-1ebc-fe561bc7a5d2","market_ticker":"KXBTCPERP1","price":"6.3858","count":"1.00","taker_side":"bid","ts_ms":1781237172544}}

{"type":"orderbook_delta","sid":1,"seq":2182,"msg":{"market_ticker":"KXBTCPERP1","price":"6.3858","delta":"-10.00","side":"ask","ts_ms":1781237172546}}

{"type":"orderbook_delta","sid":1,"seq":2183,"msg":{"market_ticker":"KXBTCPERP1","price":"6.3859","delta":"-10.00","side":"ask","ts_ms":1781237172546}}

{"type":"orderbook_delta","sid":1,"seq":2184,"msg":{"market_ticker":"KXBTCPERP1","price":"6.3829","delta":"-661.00","side":"bid","ts_ms":1781237172546}}

{"type":"orderbook_delta","sid":1,"seq":2185,"msg":{"market_ticker":"KXBTCPERP1","price":"6.3863","delta":"640.00","side":"bid","ts_ms":1781237172546}}

{"type":"trade","sid":2,"seq":1844,"msg":{"trade_id":"3cba1e90-b571-7432-bb5a-455b5f3540ee","market_ticker":"KXBTCPERP1","price":"6.3858","count":"10.00","taker_side":"bid","ts_ms":1781237172546}}

{"type":"trade","sid":2,"seq":1845,"msg":{"trade_id":"c2306f23-d7db-7d49-a525-7ff57a9fb525","market_ticker":"KXBTCPERP1","price":"6.3859","count":"10.00","taker_side":"bid","ts_ms":1781237172546}}

{"type":"orderbook_delta","sid":1,"seq":2186,"msg":{"market_ticker":"KXBTCPERP1","price":"6.3827","delta":"-783.00","side":"bid","ts_ms":1781237172549}}

{"type":"orderbook_delta","sid":1,"seq":2187,"msg":{"market_ticker":"KXBTCPERP1","price":"6.3860","delta":"782.00","side":"bid","ts_ms":1781237172549}}

{"type":"orderbook_delta","sid":1,"seq":2188,"msg":{"market_ticker":"KXBTCPERP1","price":"6.3825","delta":"-784.00","side":"bid","ts_ms":1781237172552}}

{"type":"orderbook_delta","sid":1,"seq":2189,"msg":{"market_ticker":"KXBTCPERP1","price":"6.3857","delta":"783.00","side":"bid","ts_ms":1781237172552}}

{"type":"orderbook_delta","sid":1,"seq":2190,"msg":{"market_ticker":"KXBTCPERP1","price":"6.3823","delta":"-783.00","side":"bid","ts_ms":1781237172555}}

{"type":"orderbook_delta","sid":1,"seq":2191,"msg":{"market_ticker":"KXBTCPERP1","price":"6.3854","delta":"783.00","side":"bid","ts_ms":1781237172555}}

{"type":"orderbook_delta","sid":1,"seq":2192,"msg":{"market_ticker":"KXBTCPERP1","price":"6.3821","delta":"-784.00","side":"bid","ts_ms":1781237172558}}

{"type":"orderbook_delta","sid":1,"seq":2193,"msg":{"market_ticker":"KXBTCPERP1","price":"6.3851","delta":"784.00","side":"bid","ts_ms":1781237172558}}

{"type":"orderbook_delta","sid":1,"seq":2194,"msg":{"market_ticker":"KXBTCPERP1","price":"6.3819","delta":"-783.00","side":"bid","ts_ms":1781237172562}}

{"type":"orderbook_delta","sid":1,"seq":2195,"msg":{"market_ticker":"KXBTCPERP1","price":"6.3848","delta":"783.00","side":"bid","ts_ms":1781237172562}}

{"type":"orderbook_delta","sid":1,"seq":2196,"msg":{"market_ticker":"KXBTCPERP1","price":"6.3817","delta":"-784.00","side":"bid","ts_ms":1781237172565}}

{"type":"orderbook_delta","sid":1,"seq":2197,"msg":{"market_ticker":"KXBTCPERP1","price":"6.3845","delta":"784.00","side":"bid","ts_ms":1781237172565}}

{"type":"orderbook_delta","sid":1,"seq":2198,"msg":{"market_ticker":"KXBTCPERP1","price":"6.3815","delta":"-784.00","side":"bid","ts_ms":1781237172568}}

{"type":"orderbook_delta","sid":1,"seq":2199,"msg":{"market_ticker":"KXBTCPERP1","price":"6.3842","delta":"784.00","side":"bid","ts_ms":1781237172568}}

{"type":"orderbook_delta","sid":1,"seq":2200,"msg":{"market_ticker":"KXBTCPERP1","price":"6.3813","delta":"-784.00","side":"bid","ts_ms":1781237172572}}

{"type":"orderbook_delta","sid":1,"seq":2201,"msg":{"market_ticker":"KXBTCPERP1","price":"6.3839","delta":"784.00","side":"bid","ts_ms":1781237172572}}

{"type":"orderbook_delta","sid":1,"seq":2202,"msg":{"market_ticker":"KXBTCPERP1","price":"6.3836","delta":"784.00","side":"bid","ts_ms":1781237172575}}

{"type":"orderbook_delta","sid":1,"seq":2203,"msg":{"market_ticker":"KXBTCPERP1","price":"6.3893","delta":"1.00","side":"ask","ts_ms":1781237172604}}

{"type":"orderbook_delta","sid":1,"seq":2204,"msg":{"market_ticker":"KXBTCPERP1","price":"6.4611","delta":"1.00","side":"ask","ts_ms":1781237172763}}

{"type":"trade","sid":2,"seq":1846,"msg":{"trade_id":"9c24bb27-4401-509e-9002-631e14cac23a","market_ticker":"KXBTCPERP1","price":"6.3865","count":"1.00","taker_side":"bid","ts_ms":1781237172815}}

{"type":"orderbook_delta","sid":1,"seq":2205,"msg":{"market_ticker":"KXBTCPERP1","price":"6.3865","delta":"-1.00","side":"ask","ts_ms":1781237172815}}

{"type":"orderbook_delta","sid":1,"seq":2206,"msg":{"market_ticker":"KXBTCPERP1","price":"6.3412","delta":"1.00","side":"bid","ts_ms":1781237172943}}

{"type":"orderbook_delta","sid":1,"seq":2207,"msg":{"market_ticker":"KXBTCPERP1","price":"6.3903","delta":"10.00","side":"ask","ts_ms":1781237173069}}

{"type":"orderbook_delta","sid":1,"seq":2208,"msg":{"market_ticker":"KXBTCPERP1","price":"6.3893","delta":"-1.00","side":"ask","ts_ms":1781237173081}}

{"type":"trade","sid":2,"seq":1847,"msg":{"trade_id":"8f97237b-9653-73a4-82a2-019dca522fcc","market_ticker":"KXBTCPERP1","price":"6.3893","count":"1.00","taker_side":"bid","ts_ms":1781237173081}}

{"type":"orderbook_delta","sid":1,"seq":2209,"msg":{"market_ticker":"KXBTCPERP1","price":"6.5389","delta":"-1.00","side":"ask","ts_ms":1781237173115}}

{"type":"orderbook_delta","sid":1,"seq":2210,"msg":{"market_ticker":"KXBTCPERP1","price":"6.3904","delta":"10.00","side":"ask","ts_ms":1781237173169}}

{"type":"orderbook_delta","sid":1,"seq":2211,"msg":{"market_ticker":"KXBTCPERP1","price":"6.3886","delta":"1.00","side":"bid","ts_ms":1781237173341}}

{"type":"ticker","sid":3,"msg":{"market_ticker":"KXBTCPERP1","price":"6.3329","bid":"6.3329","ask":"6.3416","bid_size_fp":"343.00","ask_size_fp":"658.00","last_trade_size_fp":"0.00","volume":"4179467045.00","volume_notional_value_dollars":"3245141294.960300","volume_24h":"1877080.00","volume_24h_notional_value_dollars":"11687174.591200","open_interest":"2332769.00","open_interest_notional_value_dollars":"14773192.800100","reference_price":{"price":"6.3394","ts_ms":1781237173000},"settlement_mark_price":{"price":"6.3512","ts_ms":1781237168036},"liquidation_mark_price":{"price":"6.3781","ts_ms":1781237173398},"funding_rate":{"rate":0,"next_funding_time_ms":1781265600000,"ts_ms":1781237168036},"ts_ms":1781217877584}}

{"type":"orderbook_delta","sid":1,"seq":2212,"msg":{"market_ticker":"KXBTCPERP1","price":"7.6637","delta":"-1.00","side":"ask","ts_ms":1781237173626}}

{"type":"orderbook_delta","sid":1,"seq":2213,"msg":{"market_ticker":"KXBTCPERP1","price":"6.4440","delta":"1.00","side":"ask","ts_ms":1781237173665}}

{"type":"orderbook_delta","sid":1,"seq":2214,"msg":{"market_ticker":"KXBTCPERP1","price":"6.3903","delta":"-1.00","side":"ask","ts_ms":1781237173826}}

{"type":"trade","sid":2,"seq":1848,"msg":{"trade_id":"8cb62997-b77c-68e1-eae8-c8dad2719a21","market_ticker":"KXBTCPERP1","price":"6.3903","count":"1.00","taker_side":"bid","ts_ms":1781237173826}}

{"type":"orderbook_delta","sid":1,"seq":2215,"msg":{"market_ticker":"KXBTCPERP1","price":"6.2782","delta":"-1.00","side":"bid","ts_ms":1781237173872}}

{"type":"orderbook_delta","sid":1,"seq":2216,"msg":{"market_ticker":"KXBTCPERP1","price":"6.3886","delta":"-1.00","side":"bid","ts_ms":1781237173974}}

{"type":"trade","sid":2,"seq":1849,"msg":{"trade_id":"66772c83-26bf-6973-aa7f-410f686c5e0b","market_ticker":"KXBTCPERP1","price":"6.3886","count":"1.00","taker_side":"ask","ts_ms":1781237173974}}

{"type":"orderbook_delta","sid":1,"seq":2217,"msg":{"market_ticker":"KXBTCPERP1","price":"6.3863","delta":"-1.00","side":"bid","ts_ms":1781237174048}}

{"type":"trade","sid":2,"seq":1850,"msg":{"trade_id":"099d1717-34f4-77e3-a672-2e058da3aacb","market_ticker":"KXBTCPERP1","price":"6.3863","count":"1.00","taker_side":"ask","ts_ms":1781237174048}}

{"type":"orderbook_delta","sid":1,"seq":2218,"msg":{"market_ticker":"KXBTCPERP1","price":"6.3813","delta":"-11.00","side":"bid","ts_ms":1781237174077}}

{"type":"orderbook_delta","sid":1,"seq":2219,"msg":{"market_ticker":"KXBTCPERP1","price":"6.3872","delta":"11.00","side":"bid","ts_ms":1781237174077}}

{"type":"orderbook_delta","sid":1,"seq":2220,"msg":{"market_ticker":"KXBTCPERP1","price":"6.3812","delta":"-10.00","side":"bid","ts_ms":1781237174178}}

{"type":"orderbook_delta","sid":1,"seq":2221,"msg":{"market_ticker":"KXBTCPERP1","price":"6.3871","delta":"10.00","side":"bid","ts_ms":1781237174178}}

{"type":"orderbook_delta","sid":1,"seq":2222,"msg":{"market_ticker":"KXBTCPERP1","price":"6.4560","delta":"1.00","side":"ask","ts_ms":1781237174246}}

{"type":"orderbook_delta","sid":1,"seq":2223,"msg":{"market_ticker":"KXBTCPERP1","price":"6.3903","delta":"-9.00","side":"ask","ts_ms":1781237174279}}

{"type":"orderbook_delta","sid":1,"seq":2224,"msg":{"market_ticker":"KXBTCPERP1","price":"6.3920","delta":"10.00","side":"ask","ts_ms":1781237174279}}

{"type":"orderbook_delta","sid":1,"seq":2225,"msg":{"market_ticker":"KXBTCPERP1","price":"6.3904","delta":"-10.00","side":"ask","ts_ms":1781237174379}}

{"type":"orderbook_delta","sid":1,"seq":2226,"msg":{"market_ticker":"KXBTCPERP1","price":"6.3921","delta":"10.00","side":"ask","ts_ms":1781237174379}}

{"type":"orderbook_delta","sid":1,"seq":2227,"msg":{"market_ticker":"KXBTCPERP1","price":"6.3007","delta":"-1.00","side":"bid","ts_ms":1781237174390}}

{"type":"orderbook_delta","sid":1,"seq":2228,"msg":{"market_ticker":"KXBTCPERP1","price":"6.3872","delta":"-1.00","side":"bid","ts_ms":1781237174410}}

{"type":"trade","sid":2,"seq":1851,"msg":{"trade_id":"48288055-e5ce-784c-aad5-621cb819e67b","market_ticker":"KXBTCPERP1","price":"6.3872","count":"1.00","taker_side":"ask","ts_ms":1781237174410}}

{"type":"orderbook_delta","sid":1,"seq":2229,"msg":{"market_ticker":"KXBTCPERP1","price":"6.3872","delta":"-1.00","side":"bid","ts_ms":1781237174484}}

{"type":"trade","sid":2,"seq":1852,"msg":{"trade_id":"33fded70-4396-7e5c-2258-86bc3141f563","market_ticker":"KXBTCPERP1","price":"6.3872","count":"1.00","taker_side":"ask","ts_ms":1781237174484}}

{"type":"ticker","sid":3,"msg":{"market_ticker":"KXBTCPERP1","price":"6.3329","bid":"6.3329","ask":"6.3416","bid_size_fp":"343.00","ask_size_fp":"658.00","last_trade_size_fp":"0.00","volume":"4179467045.00","volume_notional_value_dollars":"3245141294.960300","volume_24h":"1877080.00","volume_24h_notional_value_dollars":"11687174.591200","open_interest":"2332769.00","open_interest_notional_value_dollars":"14773192.800100","reference_price":{"price":"6.3394","ts_ms":1781237174000},"settlement_mark_price":{"price":"6.3514","ts_ms":1781237173038},"liquidation_mark_price":{"price":"6.3782","ts_ms":1781237174398},"funding_rate":{"rate":0,"next_funding_time_ms":1781265600000,"ts_ms":1781237173038},"ts_ms":1781217877584}}

{"type":"orderbook_delta","sid":1,"seq":2230,"msg":{"market_ticker":"KXBTCPERP1","price":"6.2562","delta":"1.00","side":"bid","ts_ms":1781237174533}}

{"type":"orderbook_delta","sid":1,"seq":2231,"msg":{"market_ticker":"KXBTCPERP1","price":"6.3764","delta":"-137.00","side":"bid","ts_ms":1781237174581}}

{"type":"orderbook_delta","sid":1,"seq":2232,"msg":{"market_ticker":"KXBTCPERP1","price":"6.3823","delta":"137.00","side":"bid","ts_ms":1781237174581}}

{"type":"orderbook_delta","sid":1,"seq":2233,"msg":{"market_ticker":"KXBTCPERP1","price":"6.2136","delta":"1.00","side":"bid","ts_ms":1781237174650}}

{"type":"orderbook_delta","sid":1,"seq":2234,"msg":{"market_ticker":"KXBTCPERP1","price":"6.2292","delta":"-1.00","side":"bid","ts_ms":1781237174680}}

{"type":"orderbook_delta","sid":1,"seq":2235,"msg":{"market_ticker":"KXBTCPERP1","price":"6.3908","delta":"-136.00","side":"ask","ts_ms":1781237174682}}

{"type":"orderbook_delta","sid":1,"seq":2236,"msg":{"market_ticker":"KXBTCPERP1","price":"6.3973","delta":"131.00","side":"ask","ts_ms":1781237174682}}

{"type":"orderbook_delta","sid":1,"seq":2237,"msg":{"market_ticker":"KXBTCPERP1","price":"6.2592","delta":"1.00","side":"bid","ts_ms":1781237174804}}

{"type":"orderbook_delta","sid":1,"seq":2238,"msg":{"market_ticker":"KXBTCPERP1","price":"6.4541","delta":"1.00","side":"ask","ts_ms":1781237174809}}

{"type":"orderbook_delta","sid":1,"seq":2239,"msg":{"market_ticker":"KXBTCPERP1","price":"6.3872","delta":"-1.00","side":"bid","ts_ms":1781237174925}}

{"type":"trade","sid":2,"seq":1853,"msg":{"trade_id":"135d3ab2-46a6-7a00-77d4-30f1a40aabf7","market_ticker":"KXBTCPERP1","price":"6.3872","count":"1.00","taker_side":"ask","ts_ms":1781237174925}}

{"type":"orderbook_delta","sid":1,"seq":2240,"msg":{"market_ticker":"KXBTCPERP1","price":"6.3872","delta":"3.00","side":"bid","ts_ms":1781237174984}}

{"type":"orderbook_delta","sid":1,"seq":2241,"msg":{"market_ticker":"KXBTCPERP1","price":"6.3872","delta":"-1.00","side":"bid","ts_ms":1781237175087}}

{"type":"trade","sid":2,"seq":1854,"msg":{"trade_id":"a40ff450-0dc2-76a4-6e97-a4aecd320af7","market_ticker":"KXBTCPERP1","price":"6.3872","count":"1.00","taker_side":"ask","ts_ms":1781237175087}}

{"type":"orderbook_delta","sid":1,"seq":2242,"msg":{"market_ticker":"KXBTCPERP1","price":"6.2239","delta":"1.00","side":"bid","ts_ms":1781237175238}}

{"type":"orderbook_delta","sid":1,"seq":2243,"msg":{"market_ticker":"KXBTCPERP1","price":"6.3872","delta":"-1.00","side":"bid","ts_ms":1781237175342}}

{"type":"trade","sid":2,"seq":1855,"msg":{"trade_id":"e36b82c4-30ae-43e8-ee4d-df6aaf72b977","market_ticker":"KXBTCPERP1","price":"6.3872","count":"1.00","taker_side":"ask","ts_ms":1781237175342}}

{"type":"trade","sid":2,"seq":1856,"msg":{"trade_id":"4804a7c6-870a-41e0-4fb1-6f2474e3906f","market_ticker":"KXBTCPERP1","price":"6.3872","count":"1.00","taker_side":"ask","ts_ms":1781237175401}}

{"type":"orderbook_delta","sid":1,"seq":2244,"msg":{"market_ticker":"KXBTCPERP1","price":"6.3872","delta":"-1.00","side":"bid","ts_ms":1781237175401}}

{"type":"orderbook_delta","sid":1,"seq":2245,"msg":{"market_ticker":"KXBTCPERP1","price":"6.3872","delta":"-1.00","side":"bid","ts_ms":1781237175444}}

{"type":"trade","sid":2,"seq":1857,"msg":{"trade_id":"5b34bbbd-ad7a-5278-ca8f-f17b29a34b03","market_ticker":"KXBTCPERP1","price":"6.3872","count":"1.00","taker_side":"ask","ts_ms":1781237175444}}

{"type":"orderbook_delta","sid":1,"seq":2246,"msg":{"market_ticker":"KXBTCPERP1","price":"6.3872","delta":"3.00","side":"bid","ts_ms":1781237175487}}

{"type":"orderbook_delta","sid":1,"seq":2247,"msg":{"market_ticker":"KXBTCPERP1","price":"6.5312","delta":"-1.00","side":"ask","ts_ms":1781237175489}}

{"type":"orderbook_delta","sid":1,"seq":2248,"msg":{"market_ticker":"KXBTCPERP1","price":"6.2597","delta":"1.00","side":"bid","ts_ms":1781237175491}}

{"type":"ticker","sid":3,"msg":{"market_ticker":"KXBTCPERP1","price":"6.3329","bid":"6.3329","ask":"6.3416","bid_size_fp":"343.00","ask_size_fp":"658.00","last_trade_size_fp":"0.00","volume":"4179467045.00","volume_notional_value_dollars":"3245141294.960300","volume_24h":"1877080.00","volume_24h_notional_value_dollars":"11687174.591200","open_interest":"2332769.00","open_interest_notional_value_dollars":"14773192.800100","reference_price":{"price":"6.3392","ts_ms":1781237175000},"settlement_mark_price":{"price":"6.3514","ts_ms":1781237173038},"liquidation_mark_price":{"price":"6.3781","ts_ms":1781237175399},"funding_rate":{"rate":0,"next_funding_time_ms":1781265600000,"ts_ms":1781237173038},"ts_ms":1781217877584}}

{"type":"orderbook_delta","sid":1,"seq":2249,"msg":{"market_ticker":"KXBTCPERP1","price":"6.3872","delta":"-1.00","side":"bid","ts_ms":1781237175560}}

{"type":"trade","sid":2,"seq":1858,"msg":{"trade_id":"d8245c5e-dfb6-5168-b829-bb7798eccf7b","market_ticker":"KXBTCPERP1","price":"6.3872","count":"1.00","taker_side":"ask","ts_ms":1781237175560}}

{"type":"orderbook_delta","sid":1,"seq":2250,"msg":{"market_ticker":"KXBTCPERP1","price":"6.3872","delta":"-1.00","side":"bid","ts_ms":1781237175612}}

{"type":"trade","sid":2,"seq":1859,"msg":{"trade_id":"b10eaea1-537e-6088-96fc-39c3a00712a7","market_ticker":"KXBTCPERP1","price":"6.3872","count":"1.00","taker_side":"ask","ts_ms":1781237175612}}

{"type":"orderbook_delta","sid":1,"seq":2251,"msg":{"market_ticker":"KXBTCPERP1","price":"7.6637","delta":"1.00","side":"ask","ts_ms":1781237175648}}

{"type":"orderbook_delta","sid":1,"seq":2252,"msg":{"market_ticker":"KXBTCPERP1","price":"6.3916","delta":"-1.00","side":"ask","ts_ms":1781237175775}}

{"type":"trade","sid":2,"seq":1860,"msg":{"trade_id":"2e7c2ddc-a6ca-42ed-ee1e-af6bc071abfa","market_ticker":"KXBTCPERP1","price":"6.3916","count":"1.00","taker_side":"bid","ts_ms":1781237175775}}

{"type":"orderbook_delta","sid":1,"seq":2253,"msg":{"market_ticker":"KXBTCPERP1","price":"6.3872","delta":"3.00","side":"bid","ts_ms":1781237175790}}

{"type":"trade","sid":2,"seq":1861,"msg":{"trade_id":"e9345d1f-42e6-57d8-ca99-047b4bcd33db","market_ticker":"KXBTCPERP1","price":"6.3872","count":"1.00","taker_side":"ask","ts_ms":1781237175912}}

{"type":"orderbook_delta","sid":1,"seq":2254,"msg":{"market_ticker":"KXBTCPERP1","price":"6.3872","delta":"-1.00","side":"bid","ts_ms":1781237175912}}

{"type":"orderbook_delta","sid":1,"seq":2255,"msg":{"market_ticker":"KXBTCPERP1","price":"6.2809","delta":"1.00","side":"bid","ts_ms":1781237176034}}

{"type":"orderbook_delta","sid":1,"seq":2256,"msg":{"market_ticker":"KXBTCPERP1","price":"6.3872","delta":"-1.00","side":"bid","ts_ms":1781237176215}}

{"type":"trade","sid":2,"seq":1862,"msg":{"trade_id":"94ebd787-232e-7cc0-12f6-59865cd6d673","market_ticker":"KXBTCPERP1","price":"6.3872","count":"1.00","taker_side":"ask","ts_ms":1781237176215}}

{"type":"orderbook_delta","sid":1,"seq":2257,"msg":{"market_ticker":"KXBTCPERP1","price":"6.3332","delta":"1.00","side":"bid","ts_ms":1781237176306}}

{"type":"orderbook_delta","sid":1,"seq":2258,"msg":{"market_ticker":"KXBTCPERP1","price":"6.2897","delta":"1.00","side":"bid","ts_ms":1781237176362}}

{"type":"orderbook_delta","sid":1,"seq":2259,"msg":{"market_ticker":"KXBTCPERP1","price":"6.2211","delta":"1.00","side":"bid","ts_ms":1781237176470}}

{"type":"ticker","sid":3,"msg":{"market_ticker":"KXBTCPERP1","price":"6.3329","bid":"6.3329","ask":"6.3416","bid_size_fp":"343.00","ask_size_fp":"658.00","last_trade_size_fp":"0.00","volume":"4179467045.00","volume_notional_value_dollars":"3245141294.960300","volume_24h":"1877080.00","volume_24h_notional_value_dollars":"11687174.591200","open_interest":"2332769.00","open_interest_notional_value_dollars":"14773192.800100","reference_price":{"price":"6.3392","ts_ms":1781237176000},"settlement_mark_price":{"price":"6.3514","ts_ms":1781237173038},"liquidation_mark_price":{"price":"6.3781","ts_ms":1781237176398},"funding_rate":{"rate":0,"next_funding_time_ms":1781265600000,"ts_ms":1781237173038},"ts_ms":1781217877584}}

{"type":"orderbook_delta","sid":1,"seq":2260,"msg":{"market_ticker":"KXBTCPERP1","price":"6.3916","delta":"-1.00","side":"ask","ts_ms":1781237176515}}

{"type":"trade","sid":2,"seq":1863,"msg":{"trade_id":"270a4cea-508a-55e9-c4e3-0289c20c1dd2","market_ticker":"KXBTCPERP1","price":"6.3916","count":"1.00","taker_side":"bid","ts_ms":1781237176515}}

{"type":"orderbook_delta","sid":1,"seq":2261,"msg":{"market_ticker":"KXBTCPERP1","price":"6.4603","delta":"1.00","side":"ask","ts_ms":1781237176604}}

{"type":"orderbook_delta","sid":1,"seq":2262,"msg":{"market_ticker":"KXBTCPERP1","price":"6.3872","delta":"-1.00","side":"bid","ts_ms":1781237176720}}

{"type":"trade","sid":2,"seq":1864,"msg":{"trade_id":"e2f9828c-c15a-7020-ccad-39e436a1f40f","market_ticker":"KXBTCPERP1","price":"6.3872","count":"1.00","taker_side":"ask","ts_ms":1781237176720}}

{"type":"orderbook_delta","sid":1,"seq":2263,"msg":{"market_ticker":"KXBTCPERP1","price":"6.2905","delta":"1.00","side":"bid","ts_ms":1781237176789}}

{"type":"orderbook_delta","sid":1,"seq":2264,"msg":{"market_ticker":"KXBTCPERP1","price":"6.3872","delta":"3.00","side":"bid","ts_ms":1781237176796}}

{"type":"orderbook_delta","sid":1,"seq":2265,"msg":{"market_ticker":"KXBTCPERP1","price":"6.3872","delta":"-1.00","side":"bid","ts_ms":1781237176888}}

{"type":"trade","sid":2,"seq":1865,"msg":{"trade_id":"72091de8-e1ea-4b68-97ac-2cb7f56da4b7","market_ticker":"KXBTCPERP1","price":"6.3872","count":"1.00","taker_side":"ask","ts_ms":1781237176888}}

{"type":"trade","sid":2,"seq":1866,"msg":{"trade_id":"52139ec4-6ff2-5958-dc10-965ec932ce03","market_ticker":"KXBTCPERP1","price":"6.3872","count":"1.00","taker_side":"ask","ts_ms":1781237176949}}

{"type":"orderbook_delta","sid":1,"seq":2266,"msg":{"market_ticker":"KXBTCPERP1","price":"6.3872","delta":"-1.00","side":"bid","ts_ms":1781237176949}}

{"type":"orderbook_delta","sid":1,"seq":2267,"msg":{"market_ticker":"KXBTCPERP1","price":"6.3614","delta":"1.00","side":"bid","ts_ms":1781237176962}}

{"type":"orderbook_delta","sid":1,"seq":2268,"msg":{"market_ticker":"KXBTCPERP1","price":"6.4239","delta":"1.00","side":"ask","ts_ms":1781237177055}}

{"type":"orderbook_delta","sid":1,"seq":2269,"msg":{"market_ticker":"KXBTCPERP1","price":"6.4126","delta":"1.00","side":"ask","ts_ms":1781237177079}}

{"type":"orderbook_delta","sid":1,"seq":2270,"msg":{"market_ticker":"KXBTCPERP1","price":"6.2848","delta":"1.00","side":"bid","ts_ms":1781237177122}}

{"type":"orderbook_delta","sid":1,"seq":2271,"msg":{"market_ticker":"KXBTCPERP1","price":"6.3872","delta":"-1.00","side":"bid","ts_ms":1781237177197}}

{"type":"trade","sid":2,"seq":1867,"msg":{"trade_id":"bdb0e914-4f0a-5d90-5104-b2848e313b5f","market_ticker":"KXBTCPERP1","price":"6.3872","count":"1.00","taker_side":"ask","ts_ms":1781237177197}}

{"type":"orderbook_delta","sid":1,"seq":2272,"msg":{"market_ticker":"KXBTCPERP1","price":"6.5438","delta":"1.00","side":"ask","ts_ms":1781237177208}}

{"type":"orderbook_delta","sid":1,"seq":2273,"msg":{"market_ticker":"KXBTCPERP1","price":"6.3872","delta":"3.00","side":"bid","ts_ms":1781237177299}}

{"type":"orderbook_delta","sid":1,"seq":2274,"msg":{"market_ticker":"KXBTCPERP1","price":"6.3934","delta":"1.00","side":"ask","ts_ms":1781237177359}}

{"type":"ticker","sid":3,"msg":{"market_ticker":"KXBTCPERP1","price":"6.3329","bid":"6.3329","ask":"6.3416","bid_size_fp":"343.00","ask_size_fp":"658.00","last_trade_size_fp":"0.00","volume":"4179467045.00","volume_notional_value_dollars":"3245141294.960300","volume_24h":"1877080.00","volume_24h_notional_value_dollars":"11687174.591200","open_interest":"2332769.00","open_interest_notional_value_dollars":"14773192.800100","reference_price":{"price":"6.3393","ts_ms":1781237177000},"settlement_mark_price":{"price":"6.3514","ts_ms":1781237173038},"liquidation_mark_price":{"price":"6.3783","ts_ms":1781237177398},"funding_rate":{"rate":0,"next_funding_time_ms":1781265600000,"ts_ms":1781237173038},"ts_ms":1781217877584}}

{"type":"orderbook_delta","sid":1,"seq":2275,"msg":{"market_ticker":"KXBTCPERP1","price":"6.4325","delta":"-1.00","side":"ask","ts_ms":1781237177542}}

{"type":"orderbook_delta","sid":1,"seq":2276,"msg":{"market_ticker":"KXBTCPERP1","price":"6.3916","delta":"-1.00","side":"ask","ts_ms":1781237177557}}

{"type":"trade","sid":2,"seq":1868,"msg":{"trade_id":"e341510d-c962-6205-7267-9b510bc752c6","market_ticker":"KXBTCPERP1","price":"6.3916","count":"1.00","taker_side":"bid","ts_ms":1781237177557}}

{"type":"orderbook_delta","sid":1,"seq":2277,"msg":{"market_ticker":"KXBTCPERP1","price":"6.3720","delta":"1.00","side":"bid","ts_ms":1781237177672}}

{"type":"orderbook_delta","sid":1,"seq":2278,"msg":{"market_ticker":"KXBTCPERP1","price":"6.2559","delta":"1.00","side":"bid","ts_ms":1781237177707}}

{"type":"orderbook_delta","sid":1,"seq":2279,"msg":{"market_ticker":"KXBTCPERP1","price":"6.3872","delta":"-1.00","side":"bid","ts_ms":1781237177724}}

{"type":"trade","sid":2,"seq":1869,"msg":{"trade_id":"d1abb148-21b2-40f8-6adf-e43fd20216df","market_ticker":"KXBTCPERP1","price":"6.3872","count":"1.00","taker_side":"ask","ts_ms":1781237177724}}

{"type":"trade","sid":2,"seq":1870,"msg":{"trade_id":"9e63f2d0-e352-5168-ce08-0a431843944b","market_ticker":"KXBTCPERP1","price":"6.3872","count":"1.00","taker_side":"ask","ts_ms":1781237177757}}

{"type":"orderbook_delta","sid":1,"seq":2280,"msg":{"market_ticker":"KXBTCPERP1","price":"6.3872","delta":"-1.00","side":"bid","ts_ms":1781237177757}}

{"type":"orderbook_delta","sid":1,"seq":2281,"msg":{"market_ticker":"KXBTCPERP1","price":"6.4017","delta":"1.00","side":"ask","ts_ms":1781237177827}}

{"type":"orderbook_delta","sid":1,"seq":2282,"msg":{"market_ticker":"KXBTCPERP1","price":"6.3872","delta":"-1.00","side":"bid","ts_ms":1781237177958}}

{"type":"trade","sid":2,"seq":1871,"msg":{"trade_id":"492711db-b12e-6690-73f4-03b91ddbdbc7","market_ticker":"KXBTCPERP1","price":"6.3872","count":"1.00","taker_side":"ask","ts_ms":1781237177958}}

{"type":"trade","sid":2,"seq":1872,"msg":{"trade_id":"5bed05b8-5a52-7cbc-ed6b-15e11d57844f","market_ticker":"KXBTCPERP1","price":"6.3872","count":"1.00","taker_side":"ask","ts_ms":1781237178063}}

{"type":"orderbook_delta","sid":1,"seq":2283,"msg":{"market_ticker":"KXBTCPERP1","price":"6.3872","delta":"-1.00","side":"bid","ts_ms":1781237178063}}

{"type":"orderbook_delta","sid":1,"seq":2284,"msg":{"market_ticker":"KXBTCPERP1","price":"6.5174","delta":"1.00","side":"ask","ts_ms":1781237178083}}

{"type":"orderbook_delta","sid":1,"seq":2285,"msg":{"market_ticker":"KXBTCPERP1","price":"6.3872","delta":"4.00","side":"bid","ts_ms":1781237178205}}

{"type":"orderbook_delta","sid":1,"seq":2286,"msg":{"market_ticker":"KXBTCPERP1","price":"6.3872","delta":"-1.00","side":"bid","ts_ms":1781237178267}}

{"type":"trade","sid":2,"seq":1873,"msg":{"trade_id":"35577213-6e9a-73e4-9cea-b2a5dc6b03b7","market_ticker":"KXBTCPERP1","price":"6.3872","count":"1.00","taker_side":"ask","ts_ms":1781237178267}}

{"type":"orderbook_delta","sid":1,"seq":2287,"msg":{"market_ticker":"KXBTCPERP1","price":"6.2990","delta":"1.00","side":"bid","ts_ms":1781237178340}}

{"type":"orderbook_delta","sid":1,"seq":2288,"msg":{"market_ticker":"KXBTCPERP1","price":"6.2592","delta":"-1.00","side":"bid","ts_ms":1781237178375}}

{"type":"orderbook_delta","sid":1,"seq":2289,"msg":{"market_ticker":"KXBTCPERP1","price":"6.3872","delta":"-1.00","side":"bid","ts_ms":1781237178452}}

{"type":"trade","sid":2,"seq":1874,"msg":{"trade_id":"f129b2dd-05de-5b84-e8fe-aefa9cdf2873","market_ticker":"KXBTCPERP1","price":"6.3872","count":"1.00","taker_side":"ask","ts_ms":1781237178452}}

{"type":"orderbook_delta","sid":1,"seq":2290,"msg":{"market_ticker":"KXBTCPERP1","price":"6.1614","delta":"1.00","side":"bid","ts_ms":1781237178489}}

{"type":"orderbook_delta","sid":1,"seq":2291,"msg":{"market_ticker":"KXBTCPERP1","price":"6.4448","delta":"1.00","side":"ask","ts_ms":1781237178498}}

{"type":"ticker","sid":3,"msg":{"market_ticker":"KXBTCPERP1","price":"6.3329","bid":"6.3329","ask":"6.3416","bid_size_fp":"343.00","ask_size_fp":"658.00","last_trade_size_fp":"0.00","volume":"4179467045.00","volume_notional_value_dollars":"3245141294.960300","volume_24h":"1877080.00","volume_24h_notional_value_dollars":"11687174.591200","open_interest":"2332769.00","open_interest_notional_value_dollars":"14773192.800100","reference_price":{"price":"6.3393","ts_ms":1781237178000},"settlement_mark_price":{"price":"6.3514","ts_ms":1781237173038},"liquidation_mark_price":{"price":"6.3784","ts_ms":1781237178398},"funding_rate":{"rate":0,"next_funding_time_ms":1781265600000,"ts_ms":1781237173038},"ts_ms":1781217877584}}

{"type":"orderbook_delta","sid":1,"seq":2292,"msg":{"market_ticker":"KXBTCPERP1","price":"6.3916","delta":"-1.00","side":"ask","ts_ms":1781237178636}}

{"type":"trade","sid":2,"seq":1875,"msg":{"trade_id":"713a58e1-0d12-4b19-e5f9-4314e32af01e","market_ticker":"KXBTCPERP1","price":"6.3916","count":"1.00","taker_side":"bid","ts_ms":1781237178636}}

{"type":"orderbook_delta","sid":1,"seq":2293,"msg":{"market_ticker":"KXBTCPERP1","price":"6.4655","delta":"1.00","side":"ask","ts_ms":1781237178710}}

{"type":"orderbook_delta","sid":1,"seq":2294,"msg":{"market_ticker":"KXBTCPERP1","price":"6.3916","delta":"-1.00","side":"ask","ts_ms":1781237178781}}

{"type":"trade","sid":2,"seq":1876,"msg":{"trade_id":"0cb4533c-587e-5c55-439c-b56e207dfd7a","market_ticker":"KXBTCPERP1","price":"6.3916","count":"1.00","taker_side":"bid","ts_ms":1781237178781}}

{"type":"orderbook_delta","sid":1,"seq":2295,"msg":{"market_ticker":"KXBTCPERP1","price":"6.3872","delta":"-1.00","side":"bid","ts_ms":1781237178906}}

{"type":"trade","sid":2,"seq":1877,"msg":{"trade_id":"fe89218f-3f1a-560c-40ce-b146467ffcc7","market_ticker":"KXBTCPERP1","price":"6.3872","count":"1.00","taker_side":"ask","ts_ms":1781237178906}}

{"type":"orderbook_delta","sid":1,"seq":2296,"msg":{"market_ticker":"KXBTCPERP1","price":"6.3872","delta":"-8.00","side":"bid","ts_ms":1781237179010}}

{"type":"orderbook_delta","sid":1,"seq":2297,"msg":{"market_ticker":"KXBTCPERP1","price":"6.3867","delta":"11.00","side":"bid","ts_ms":1781237179010}}

{"type":"orderbook_delta","sid":1,"seq":2298,"msg":{"market_ticker":"KXBTCPERP1","price":"6.3376","delta":"1.00","side":"bid","ts_ms":1781237179065}}

{"type":"orderbook_delta","sid":1,"seq":2299,"msg":{"market_ticker":"KXBTCPERP1","price":"6.3863","delta":"-639.00","side":"bid","ts_ms":1781237179178}}

{"type":"orderbook_delta","sid":1,"seq":2300,"msg":{"market_ticker":"KXBTCPERP1","price":"6.3814","delta":"640.00","side":"bid","ts_ms":1781237179178}}

{"type":"orderbook_delta","sid":1,"seq":2301,"msg":{"market_ticker":"KXBTCPERP1","price":"6.3860","delta":"-782.00","side":"bid","ts_ms":1781237179181}}

{"type":"orderbook_delta","sid":1,"seq":2302,"msg":{"market_ticker":"KXBTCPERP1","price":"6.3788","delta":"783.00","side":"bid","ts_ms":1781237179181}}

{"type":"orderbook_delta","sid":1,"seq":2303,"msg":{"market_ticker":"KXBTCPERP1","price":"6.3857","delta":"-783.00","side":"bid","ts_ms":1781237179186}}

{"type":"orderbook_delta","sid":1,"seq":2304,"msg":{"market_ticker":"KXBTCPERP1","price":"6.3762","delta":"785.00","side":"bid","ts_ms":1781237179186}}

{"type":"orderbook_delta","sid":1,"seq":2305,"msg":{"market_ticker":"KXBTCPERP1","price":"6.3854","delta":"-783.00","side":"bid","ts_ms":1781237179189}}

{"type":"orderbook_delta","sid":1,"seq":2306,"msg":{"market_ticker":"KXBTCPERP1","price":"6.3736","delta":"784.00","side":"bid","ts_ms":1781237179189}}

{"type":"orderbook_delta","sid":1,"seq":2307,"msg":{"market_ticker":"KXBTCPERP1","price":"6.3851","delta":"-784.00","side":"bid","ts_ms":1781237179193}}

{"type":"orderbook_delta","sid":1,"seq":2308,"msg":{"market_ticker":"KXBTCPERP1","price":"6.3710","delta":"785.00","side":"bid","ts_ms":1781237179193}}

{"type":"orderbook_delta","sid":1,"seq":2309,"msg":{"market_ticker":"KXBTCPERP1","price":"6.3848","delta":"-783.00","side":"bid","ts_ms":1781237179196}}

{"type":"orderbook_delta","sid":1,"seq":2310,"msg":{"market_ticker":"KXBTCPERP1","price":"6.3684","delta":"785.00","side":"bid","ts_ms":1781237179196}}

{"type":"orderbook_delta","sid":1,"seq":2311,"msg":{"market_ticker":"KXBTCPERP1","price":"6.3845","delta":"-784.00","side":"bid","ts_ms":1781237179200}}

{"type":"orderbook_delta","sid":1,"seq":2312,"msg":{"market_ticker":"KXBTCPERP1","price":"6.3658","delta":"786.00","side":"bid","ts_ms":1781237179200}}

{"type":"orderbook_delta","sid":1,"seq":2313,"msg":{"market_ticker":"KXBTCPERP1","price":"6.3842","delta":"-784.00","side":"bid","ts_ms":1781237179203}}

{"type":"orderbook_delta","sid":1,"seq":2314,"msg":{"market_ticker":"KXBTCPERP1","price":"6.3632","delta":"786.00","side":"bid","ts_ms":1781237179203}}

{"type":"orderbook_delta","sid":1,"seq":2315,"msg":{"market_ticker":"KXBTCPERP1","price":"6.3839","delta":"-784.00","side":"bid","ts_ms":1781237179206}}

