{"type":"orderbook_delta","sid":1,"seq":2316,"msg":{"market_ticker":"KXBTCPERP1","price":"6.3606","delta":"787.00","side":"bid","ts_ms":1781237179206}}

{"type":"orderbook_delta","sid":1,"seq":2317,"msg":{"market_ticker":"KXBTCPERP1","price":"6.3836","delta":"-784.00","side":"bid","ts_ms":1781237179209}}

{"type":"orderbook_delta","sid":1,"seq":2318,"msg":{"market_ticker":"KXBTCPERP1","price":"6.3580","delta":"787.00","side":"bid","ts_ms":1781237179209}}

{"type":"orderbook_delta","sid":1,"seq":2319,"msg":{"market_ticker":"KXBTCPERP1","price":"6.3916","delta":"-299.00","side":"ask","ts_ms":1781237179213}}

{"type":"orderbook_delta","sid":1,"seq":2320,"msg":{"market_ticker":"KXBTCPERP1","price":"6.4009","delta":"298.00","side":"ask","ts_ms":1781237179213}}

{"type":"orderbook_delta","sid":1,"seq":2321,"msg":{"market_ticker":"KXBTCPERP1","price":"6.3919","delta":"-783.00","side":"ask","ts_ms":1781237179216}}

{"type":"orderbook_delta","sid":1,"seq":2322,"msg":{"market_ticker":"KXBTCPERP1","price":"6.4035","delta":"781.00","side":"ask","ts_ms":1781237179216}}

{"type":"orderbook_delta","sid":1,"seq":2323,"msg":{"market_ticker":"KXBTCPERP1","price":"6.3922","delta":"-783.00","side":"ask","ts_ms":1781237179219}}

{"type":"orderbook_delta","sid":1,"seq":2324,"msg":{"market_ticker":"KXBTCPERP1","price":"6.4061","delta":"781.00","side":"ask","ts_ms":1781237179219}}

{"type":"orderbook_delta","sid":1,"seq":2325,"msg":{"market_ticker":"KXBTCPERP1","price":"6.3925","delta":"-783.00","side":"ask","ts_ms":1781237179222}}

{"type":"orderbook_delta","sid":1,"seq":2326,"msg":{"market_ticker":"KXBTCPERP1","price":"6.4087","delta":"781.00","side":"ask","ts_ms":1781237179222}}

{"type":"orderbook_delta","sid":1,"seq":2327,"msg":{"market_ticker":"KXBTCPERP1","price":"6.4171","delta":"1.00","side":"ask","ts_ms":1781237179226}}

{"type":"orderbook_delta","sid":1,"seq":2328,"msg":{"market_ticker":"KXBTCPERP1","price":"6.3928","delta":"-783.00","side":"ask","ts_ms":1781237179226}}

{"type":"orderbook_delta","sid":1,"seq":2329,"msg":{"market_ticker":"KXBTCPERP1","price":"6.4113","delta":"780.00","side":"ask","ts_ms":1781237179226}}

{"type":"orderbook_delta","sid":1,"seq":2330,"msg":{"market_ticker":"KXBTCPERP1","price":"6.3931","delta":"-783.00","side":"ask","ts_ms":1781237179230}}

{"type":"orderbook_delta","sid":1,"seq":2331,"msg":{"market_ticker":"KXBTCPERP1","price":"6.4139","delta":"780.00","side":"ask","ts_ms":1781237179230}}

{"type":"orderbook_delta","sid":1,"seq":2332,"msg":{"market_ticker":"KXBTCPERP1","price":"6.3934","delta":"-783.00","side":"ask","ts_ms":1781237179233}}

{"type":"orderbook_delta","sid":1,"seq":2333,"msg":{"market_ticker":"KXBTCPERP1","price":"6.4165","delta":"780.00","side":"ask","ts_ms":1781237179233}}

{"type":"orderbook_delta","sid":1,"seq":2334,"msg":{"market_ticker":"KXBTCPERP1","price":"6.3937","delta":"-783.00","side":"ask","ts_ms":1781237179236}}

{"type":"orderbook_delta","sid":1,"seq":2335,"msg":{"market_ticker":"KXBTCPERP1","price":"6.4191","delta":"779.00","side":"ask","ts_ms":1781237179236}}

{"type":"orderbook_delta","sid":1,"seq":2336,"msg":{"market_ticker":"KXBTCPERP1","price":"6.3940","delta":"-782.00","side":"ask","ts_ms":1781237179239}}

{"type":"orderbook_delta","sid":1,"seq":2337,"msg":{"market_ticker":"KXBTCPERP1","price":"6.4217","delta":"779.00","side":"ask","ts_ms":1781237179239}}

{"type":"orderbook_delta","sid":1,"seq":2338,"msg":{"market_ticker":"KXBTCPERP1","price":"6.3943","delta":"-782.00","side":"ask","ts_ms":1781237179242}}

{"type":"orderbook_delta","sid":1,"seq":2339,"msg":{"market_ticker":"KXBTCPERP1","price":"6.4243","delta":"779.00","side":"ask","ts_ms":1781237179242}}

{"type":"orderbook_delta","sid":1,"seq":2340,"msg":{"market_ticker":"KXBTCPERP1","price":"6.3871","delta":"-1.00","side":"bid","ts_ms":1781237179375}}

{"type":"trade","sid":2,"seq":1878,"msg":{"trade_id":"b094dba7-8c27-6407-1d52-38548c5c3741","market_ticker":"KXBTCPERP1","price":"6.3871","count":"1.00","taker_side":"ask","ts_ms":1781237179375}}

{"type":"orderbook_delta","sid":1,"seq":2341,"msg":{"market_ticker":"KXBTCPERP1","price":"6.3920","delta":"-1.00","side":"ask","ts_ms":1781237179452}}

{"type":"trade","sid":2,"seq":1879,"msg":{"trade_id":"5a3d3e9d-88b4-5a79-4f68-afab0eb17419","market_ticker":"KXBTCPERP1","price":"6.3920","count":"1.00","taker_side":"bid","ts_ms":1781237179452}}

{"type":"ticker","sid":3,"msg":{"market_ticker":"KXBTCPERP1","price":"6.3329","bid":"6.3329","ask":"6.3416","bid_size_fp":"343.00","ask_size_fp":"658.00","last_trade_size_fp":"0.00","volume":"4179467045.00","volume_notional_value_dollars":"3245141294.960300","volume_24h":"1877080.00","volume_24h_notional_value_dollars":"11687174.591200","open_interest":"2332769.00","open_interest_notional_value_dollars":"14773192.800100","reference_price":{"price":"6.3393","ts_ms":1781237179000},"settlement_mark_price":{"price":"6.3515","ts_ms":1781237178040},"liquidation_mark_price":{"price":"6.3785","ts_ms":1781237179398},"funding_rate":{"rate":0,"next_funding_time_ms":1781265600000,"ts_ms":1781237178040},"ts_ms":1781217877584}}

{"type":"orderbook_delta","sid":1,"seq":2342,"msg":{"market_ticker":"KXBTCPERP1","price":"6.3871","delta":"-1.00","side":"bid","ts_ms":1781237179520}}

{"type":"trade","sid":2,"seq":1880,"msg":{"trade_id":"f8582441-4347-6c3b-78d8-85e0a7e38191","market_ticker":"KXBTCPERP1","price":"6.3871","count":"1.00","taker_side":"ask","ts_ms":1781237179520}}

{"type":"orderbook_delta","sid":1,"seq":2343,"msg":{"market_ticker":"KXBTCPERP1","price":"7.6637","delta":"1.00","side":"ask","ts_ms":1781237179539}}

{"type":"orderbook_delta","sid":1,"seq":2344,"msg":{"market_ticker":"KXBTCPERP1","price":"6.2993","delta":"-1.00","side":"bid","ts_ms":1781237179556}}

{"type":"orderbook_delta","sid":1,"seq":2345,"msg":{"market_ticker":"KXBTCPERP1","price":"6.3871","delta":"-1.00","side":"bid","ts_ms":1781237179662}}

{"type":"trade","sid":2,"seq":1881,"msg":{"trade_id":"c2dacade-948b-5a43-462e-366a4f17d4c9","market_ticker":"KXBTCPERP1","price":"6.3871","count":"1.00","taker_side":"ask","ts_ms":1781237179662}}

{"type":"orderbook_delta","sid":1,"seq":2346,"msg":{"market_ticker":"KXBTCPERP1","price":"6.3920","delta":"-1.00","side":"ask","ts_ms":1781237179716}}

{"type":"trade","sid":2,"seq":1882,"msg":{"trade_id":"fb2fb06b-f9a8-64e9-96c3-054821f48295","market_ticker":"KXBTCPERP1","price":"6.3920","count":"1.00","taker_side":"bid","ts_ms":1781237179716}}

{"type":"orderbook_delta","sid":1,"seq":2347,"msg":{"market_ticker":"KXBTCPERP1","price":"6.2142","delta":"1.00","side":"bid","ts_ms":1781237179777}}

{"type":"orderbook_delta","sid":1,"seq":2348,"msg":{"market_ticker":"KXBTCPERP1","price":"7.6637","delta":"1.00","side":"ask","ts_ms":1781237179917}}

{"type":"trade","sid":2,"seq":1883,"msg":{"trade_id":"21bbbefc-181b-518f-cabf-7a5edd1df435","market_ticker":"KXBTCPERP1","price":"6.3871","count":"1.00","taker_side":"ask","ts_ms":1781237179980}}

{"type":"orderbook_delta","sid":1,"seq":2349,"msg":{"market_ticker":"KXBTCPERP1","price":"6.3871","delta":"-1.00","side":"bid","ts_ms":1781237179980}}

{"type":"orderbook_delta","sid":1,"seq":2350,"msg":{"market_ticker":"KXBTCPERP1","price":"6.2207","delta":"1.00","side":"bid","ts_ms":1781237180021}}

{"type":"orderbook_delta","sid":1,"seq":2351,"msg":{"market_ticker":"KXBTCPERP1","price":"6.3920","delta":"-1.00","side":"ask","ts_ms":1781237180071}}

{"type":"trade","sid":2,"seq":1884,"msg":{"trade_id":"d17a80c5-fbd4-4769-4d1d-b39d98ae394d","market_ticker":"KXBTCPERP1","price":"6.3920","count":"1.00","taker_side":"bid","ts_ms":1781237180071}}

{"type":"orderbook_delta","sid":1,"seq":2352,"msg":{"market_ticker":"KXBTCPERP1","price":"6.3920","delta":"-1.00","side":"ask","ts_ms":1781237180226}}

{"type":"trade","sid":2,"seq":1885,"msg":{"trade_id":"0cb29389-489c-7d55-5db0-6a5d53ee8139","market_ticker":"KXBTCPERP1","price":"6.3920","count":"1.00","taker_side":"bid","ts_ms":1781237180226}}

{"type":"orderbook_delta","sid":1,"seq":2353,"msg":{"market_ticker":"KXBTCPERP1","price":"6.3167","delta":"-1.00","side":"bid","ts_ms":1781237180333}}

{"type":"orderbook_delta","sid":1,"seq":2354,"msg":{"market_ticker":"KXBTCPERP1","price":"6.3219","delta":"1.00","side":"bid","ts_ms":1781237180376}}

{"type":"orderbook_delta","sid":1,"seq":2355,"msg":{"market_ticker":"KXBTCPERP1","price":"6.3867","delta":"-11.00","side":"bid","ts_ms":1781237180419}}

{"type":"orderbook_delta","sid":1,"seq":2356,"msg":{"market_ticker":"KXBTCPERP1","price":"6.3878","delta":"11.00","side":"bid","ts_ms":1781237180419}}

{"type":"ticker","sid":3,"msg":{"market_ticker":"KXBTCPERP1","price":"6.3329","bid":"6.3329","ask":"6.3416","bid_size_fp":"343.00","ask_size_fp":"658.00","last_trade_size_fp":"0.00","volume":"4179467045.00","volume_notional_value_dollars":"3245141294.960300","volume_24h":"1877080.00","volume_24h_notional_value_dollars":"11687174.591200","open_interest":"2332769.00","open_interest_notional_value_dollars":"14773192.800100","reference_price":{"price":"6.3394","ts_ms":1781237180000},"settlement_mark_price":{"price":"6.3515","ts_ms":1781237178040},"liquidation_mark_price":{"price":"6.3785","ts_ms":1781237180398},"funding_rate":{"rate":0,"next_funding_time_ms":1781265600000,"ts_ms":1781237178040},"ts_ms":1781217877584}}

{"type":"orderbook_delta","sid":1,"seq":2357,"msg":{"market_ticker":"KXBTCPERP1","price":"6.3871","delta":"-6.00","side":"bid","ts_ms":1781237180522}}

{"type":"orderbook_delta","sid":1,"seq":2358,"msg":{"market_ticker":"KXBTCPERP1","price":"6.3877","delta":"10.00","side":"bid","ts_ms":1781237180522}}

{"type":"orderbook_delta","sid":1,"seq":2359,"msg":{"market_ticker":"KXBTCPERP1","price":"6.3920","delta":"-1.00","side":"ask","ts_ms":1781237180535}}

{"type":"trade","sid":2,"seq":1886,"msg":{"trade_id":"f3834eb2-a150-703d-b581-c5abc9a86b3d","market_ticker":"KXBTCPERP1","price":"6.3920","count":"1.00","taker_side":"bid","ts_ms":1781237180535}}

{"type":"orderbook_delta","sid":1,"seq":2360,"msg":{"market_ticker":"KXBTCPERP1","price":"6.3920","delta":"-5.00","side":"ask","ts_ms":1781237180621}}

{"type":"orderbook_delta","sid":1,"seq":2361,"msg":{"market_ticker":"KXBTCPERP1","price":"6.3926","delta":"10.00","side":"ask","ts_ms":1781237180621}}

{"type":"orderbook_delta","sid":1,"seq":2362,"msg":{"market_ticker":"KXBTCPERP1","price":"6.2243","delta":"1.00","side":"bid","ts_ms":1781237180732}}

{"type":"orderbook_delta","sid":1,"seq":2363,"msg":{"market_ticker":"KXBTCPERP1","price":"6.2529","delta":"1.00","side":"bid","ts_ms":1781237180808}}

{"type":"orderbook_delta","sid":1,"seq":2364,"msg":{"market_ticker":"KXBTCPERP1","price":"6.3878","delta":"-1.00","side":"bid","ts_ms":1781237181154}}

{"type":"trade","sid":2,"seq":1887,"msg":{"trade_id":"b9ceec26-e4f6-5594-f75b-734a63019333","market_ticker":"KXBTCPERP1","price":"6.3878","count":"1.00","taker_side":"ask","ts_ms":1781237181154}}

{"type":"orderbook_delta","sid":1,"seq":2365,"msg":{"market_ticker":"KXBTCPERP1","price":"6.3878","delta":"-1.00","side":"bid","ts_ms":1781237181331}}

{"type":"trade","sid":2,"seq":1888,"msg":{"trade_id":"2e72e720-078e-53ec-f5eb-93d0ca96e417","market_ticker":"KXBTCPERP1","price":"6.3878","count":"1.00","taker_side":"ask","ts_ms":1781237181331}}

{"type":"orderbook_delta","sid":1,"seq":2366,"msg":{"market_ticker":"KXBTCPERP1","price":"6.3878","delta":"-1.00","side":"bid","ts_ms":1781237181363}}

{"type":"trade","sid":2,"seq":1889,"msg":{"trade_id":"36b057b1-ff6e-56cc-d157-e1903d67983b","market_ticker":"KXBTCPERP1","price":"6.3878","count":"1.00","taker_side":"ask","ts_ms":1781237181363}}

{"type":"orderbook_delta","sid":1,"seq":2367,"msg":{"market_ticker":"KXBTCPERP1","price":"6.3878","delta":"-1.00","side":"bid","ts_ms":1781237181383}}

{"type":"trade","sid":2,"seq":1890,"msg":{"trade_id":"817eb5cb-58be-5994-fa3f-b5650ddb901b","market_ticker":"KXBTCPERP1","price":"6.3878","count":"1.00","taker_side":"ask","ts_ms":1781237181383}}

{"type":"orderbook_delta","sid":1,"seq":2368,"msg":{"market_ticker":"KXBTCPERP1","price":"6.3878","delta":"-7.00","side":"bid","ts_ms":1781237181427}}

{"type":"orderbook_delta","sid":1,"seq":2369,"msg":{"market_ticker":"KXBTCPERP1","price":"6.3879","delta":"10.00","side":"bid","ts_ms":1781237181427}}

{"type":"ticker","sid":3,"msg":{"market_ticker":"KXBTCPERP1","price":"6.3329","bid":"6.3329","ask":"6.3416","bid_size_fp":"343.00","ask_size_fp":"658.00","last_trade_size_fp":"0.00","volume":"4179467045.00","volume_notional_value_dollars":"3245141294.960300","volume_24h":"1877080.00","volume_24h_notional_value_dollars":"11687174.591200","open_interest":"2332769.00","open_interest_notional_value_dollars":"14773192.800100","reference_price":{"price":"6.3397","ts_ms":1781237181000},"settlement_mark_price":{"price":"6.3515","ts_ms":1781237178040},"liquidation_mark_price":{"price":"6.3790","ts_ms":1781237181398},"funding_rate":{"rate":0,"next_funding_time_ms":1781265600000,"ts_ms":1781237178040},"ts_ms":1781217877584}}

{"type":"orderbook_delta","sid":1,"seq":2370,"msg":{"market_ticker":"KXBTCPERP1","price":"6.3921","delta":"-1.00","side":"ask","ts_ms":1781237181523}}

{"type":"trade","sid":2,"seq":1891,"msg":{"trade_id":"5b99d386-8148-5ab1-c641-366144375d3a","market_ticker":"KXBTCPERP1","price":"6.3921","count":"1.00","taker_side":"bid","ts_ms":1781237181523}}

{"type":"orderbook_delta","sid":1,"seq":2371,"msg":{"market_ticker":"KXBTCPERP1","price":"6.3003","delta":"1.00","side":"bid","ts_ms":1781237181737}}

{"type":"orderbook_delta","sid":1,"seq":2372,"msg":{"market_ticker":"KXBTCPERP1","price":"6.2897","delta":"-1.00","side":"bid","ts_ms":1781237181765}}

{"type":"orderbook_delta","sid":1,"seq":2373,"msg":{"market_ticker":"KXBTCPERP1","price":"6.3180","delta":"1.00","side":"bid","ts_ms":1781237181927}}

{"type":"orderbook_delta","sid":1,"seq":2374,"msg":{"market_ticker":"KXBTCPERP1","price":"6.3879","delta":"-1.00","side":"bid","ts_ms":1781237182000}}

{"type":"trade","sid":2,"seq":1892,"msg":{"trade_id":"4342bcbe-7a4e-7728-b47a-56a6e37c15e3","market_ticker":"KXBTCPERP1","price":"6.3879","count":"1.00","taker_side":"ask","ts_ms":1781237182000}}

{"type":"orderbook_delta","sid":1,"seq":2375,"msg":{"market_ticker":"KXBTCPERP1","price":"6.2207","delta":"1.00","side":"bid","ts_ms":1781237182020}}

{"type":"orderbook_delta","sid":1,"seq":2376,"msg":{"market_ticker":"KXBTCPERP1","price":"6.3879","delta":"-1.00","side":"bid","ts_ms":1781237182201}}

{"type":"trade","sid":2,"seq":1893,"msg":{"trade_id":"8bc81839-d296-7a5c-2465-6bcb48673f97","market_ticker":"KXBTCPERP1","price":"6.3879","count":"1.00","taker_side":"ask","ts_ms":1781237182201}}

{"type":"orderbook_delta","sid":1,"seq":2377,"msg":{"market_ticker":"KXBTCPERP1","price":"6.4404","delta":"1.00","side":"ask","ts_ms":1781237182238}}

{"type":"orderbook_delta","sid":1,"seq":2378,"msg":{"market_ticker":"KXBTCPERP1","price":"6.2153","delta":"1.00","side":"bid","ts_ms":1781237182375}}

{"type":"orderbook_delta","sid":1,"seq":2379,"msg":{"market_ticker":"KXBTCPERP1","price":"6.2437","delta":"1.00","side":"bid","ts_ms":1781237182426}}

{"type":"orderbook_delta","sid":1,"seq":2380,"msg":{"market_ticker":"KXBTCPERP1","price":"6.3921","delta":"-1.00","side":"ask","ts_ms":1781237182498}}

{"type":"trade","sid":2,"seq":1894,"msg":{"trade_id":"d63f6d64-c6d0-68fd-0fc8-09691b5c3a32","market_ticker":"KXBTCPERP1","price":"6.3921","count":"1.00","taker_side":"bid","ts_ms":1781237182498}}

{"type":"ticker","sid":3,"msg":{"market_ticker":"KXBTCPERP1","price":"6.3329","bid":"6.3329","ask":"6.3416","bid_size_fp":"343.00","ask_size_fp":"658.00","last_trade_size_fp":"0.00","volume":"4179467045.00","volume_notional_value_dollars":"3245141294.960300","volume_24h":"1877080.00","volume_24h_notional_value_dollars":"11687174.591200","open_interest":"2332769.00","open_interest_notional_value_dollars":"14773192.800100","reference_price":{"price":"6.3395","ts_ms":1781237182000},"settlement_mark_price":{"price":"6.3515","ts_ms":1781237178040},"liquidation_mark_price":{"price":"6.3789","ts_ms":1781237182399},"funding_rate":{"rate":0,"next_funding_time_ms":1781265600000,"ts_ms":1781237178040},"ts_ms":1781217877584}}

{"type":"orderbook_delta","sid":1,"seq":2381,"msg":{"market_ticker":"KXBTCPERP1","price":"6.3879","delta":"-8.00","side":"bid","ts_ms":1781237182534}}

{"type":"orderbook_delta","sid":1,"seq":2382,"msg":{"market_ticker":"KXBTCPERP1","price":"6.3880","delta":"11.00","side":"bid","ts_ms":1781237182534}}

{"type":"orderbook_delta","sid":1,"seq":2383,"msg":{"market_ticker":"KXBTCPERP1","price":"6.3880","delta":"-1.00","side":"bid","ts_ms":1781237182708}}

{"type":"trade","sid":2,"seq":1895,"msg":{"trade_id":"14668aac-ffaa-582c-4879-e266087cb9f3","market_ticker":"KXBTCPERP1","price":"6.3880","count":"1.00","taker_side":"ask","ts_ms":1781237182708}}

{"type":"orderbook_delta","sid":1,"seq":2384,"msg":{"market_ticker":"KXBTCPERP1","price":"6.1762","delta":"1.00","side":"bid","ts_ms":1781237182740}}

{"type":"orderbook_delta","sid":1,"seq":2385,"msg":{"market_ticker":"KXBTCPERP1","price":"6.2940","delta":"1.00","side":"bid","ts_ms":1781237182911}}

{"type":"orderbook_delta","sid":1,"seq":2386,"msg":{"market_ticker":"KXBTCPERP1","price":"6.3880","delta":"-1.00","side":"bid","ts_ms":1781237183017}}

{"type":"trade","sid":2,"seq":1896,"msg":{"trade_id":"da4f2927-71fa-7e88-9aae-ca5de8d45a2b","market_ticker":"KXBTCPERP1","price":"6.3880","count":"1.00","taker_side":"ask","ts_ms":1781237183017}}

{"type":"orderbook_delta","sid":1,"seq":2387,"msg":{"market_ticker":"KXBTCPERP1","price":"6.3880","delta":"-9.00","side":"bid","ts_ms":1781237183038}}

{"type":"orderbook_delta","sid":1,"seq":2388,"msg":{"market_ticker":"KXBTCPERP1","price":"6.3851","delta":"10.00","side":"bid","ts_ms":1781237183038}}

{"type":"orderbook_delta","sid":1,"seq":2389,"msg":{"market_ticker":"KXBTCPERP1","price":"6.3877","delta":"-10.00","side":"bid","ts_ms":1781237183139}}

{"type":"orderbook_delta","sid":1,"seq":2390,"msg":{"market_ticker":"KXBTCPERP1","price":"6.3850","delta":"10.00","side":"bid","ts_ms":1781237183139}}

{"type":"orderbook_delta","sid":1,"seq":2391,"msg":{"market_ticker":"KXBTCPERP1","price":"6.4050","delta":"1.00","side":"ask","ts_ms":1781237183199}}

{"type":"orderbook_delta","sid":1,"seq":2392,"msg":{"market_ticker":"KXBTCPERP1","price":"6.3926","delta":"-10.00","side":"ask","ts_ms":1781237183239}}

{"type":"orderbook_delta","sid":1,"seq":2393,"msg":{"market_ticker":"KXBTCPERP1","price":"6.3899","delta":"10.00","side":"ask","ts_ms":1781237183239}}

{"type":"orderbook_delta","sid":1,"seq":2394,"msg":{"market_ticker":"KXBTCPERP1","price":"6.3851","delta":"-1.00","side":"bid","ts_ms":1781237183336}}

{"type":"trade","sid":2,"seq":1897,"msg":{"trade_id":"58b7e1e7-f91e-6cac-425e-c8b4af6487bb","market_ticker":"KXBTCPERP1","price":"6.3851","count":"1.00","taker_side":"ask","ts_ms":1781237183336}}

{"type":"orderbook_delta","sid":1,"seq":2395,"msg":{"market_ticker":"KXBTCPERP1","price":"6.3921","delta":"-8.00","side":"ask","ts_ms":1781237183440}}

{"type":"orderbook_delta","sid":1,"seq":2396,"msg":{"market_ticker":"KXBTCPERP1","price":"6.3900","delta":"10.00","side":"ask","ts_ms":1781237183440}}

{"type":"ticker","sid":3,"msg":{"market_ticker":"KXBTCPERP1","price":"6.3329","bid":"6.3329","ask":"6.3416","bid_size_fp":"343.00","ask_size_fp":"658.00","last_trade_size_fp":"0.00","volume":"4179467045.00","volume_notional_value_dollars":"3245141294.960300","volume_24h":"1877080.00","volume_24h_notional_value_dollars":"11687174.591200","open_interest":"2332769.00","open_interest_notional_value_dollars":"14773192.800100","reference_price":{"price":"6.3394","ts_ms":1781237183000},"settlement_mark_price":{"price":"6.3515","ts_ms":1781237178040},"liquidation_mark_price":{"price":"6.3789","ts_ms":1781237183398},"funding_rate":{"rate":0,"next_funding_time_ms":1781265600000,"ts_ms":1781237178040},"ts_ms":1781217877584}}

{"type":"trade","sid":2,"seq":1898,"msg":{"trade_id":"67aea2c8-c09e-4854-5952-c9f9e5ceb487","market_ticker":"KXBTCPERP1","price":"6.3851","count":"1.00","taker_side":"ask","ts_ms":1781237183537}}

{"type":"orderbook_delta","sid":1,"seq":2397,"msg":{"market_ticker":"KXBTCPERP1","price":"6.3851","delta":"-1.00","side":"bid","ts_ms":1781237183537}}

{"type":"orderbook_delta","sid":1,"seq":2398,"msg":{"market_ticker":"KXBTCPERP1","price":"6.3851","delta":"-8.00","side":"bid","ts_ms":1781237183641}}

{"type":"orderbook_delta","sid":1,"seq":2399,"msg":{"market_ticker":"KXBTCPERP1","price":"6.3852","delta":"11.00","side":"bid","ts_ms":1781237183641}}

{"type":"orderbook_delta","sid":1,"seq":2400,"msg":{"market_ticker":"KXBTCPERP1","price":"6.3899","delta":"-1.00","side":"ask","ts_ms":1781237183662}}

{"type":"trade","sid":2,"seq":1899,"msg":{"trade_id":"70ae4e53-9b4c-4a7d-aa1c-439650a0603d","market_ticker":"KXBTCPERP1","price":"6.3899","count":"1.00","taker_side":"bid","ts_ms":1781237183662}}

{"type":"orderbook_delta","sid":1,"seq":2401,"msg":{"market_ticker":"KXBTCPERP1","price":"6.3852","delta":"-1.00","side":"bid","ts_ms":1781237183783}}

{"type":"trade","sid":2,"seq":1900,"msg":{"trade_id":"e4e5e4ec-7d8a-7a84-a0b6-442f8a47177b","market_ticker":"KXBTCPERP1","price":"6.3852","count":"1.00","taker_side":"ask","ts_ms":1781237183783}}

{"type":"orderbook_delta","sid":1,"seq":2402,"msg":{"market_ticker":"KXBTCPERP1","price":"6.4551","delta":"1.00","side":"ask","ts_ms":1781237183982}}

{"type":"orderbook_delta","sid":1,"seq":2403,"msg":{"market_ticker":"KXBTCPERP1","price":"6.3814","delta":"-640.00","side":"bid","ts_ms":1781237184125}}

{"type":"orderbook_delta","sid":1,"seq":2404,"msg":{"market_ticker":"KXBTCPERP1","price":"6.3786","delta":"640.00","side":"bid","ts_ms":1781237184125}}

{"type":"orderbook_delta","sid":1,"seq":2405,"msg":{"market_ticker":"KXBTCPERP1","price":"6.3788","delta":"-783.00","side":"bid","ts_ms":1781237184129}}

{"type":"orderbook_delta","sid":1,"seq":2406,"msg":{"market_ticker":"KXBTCPERP1","price":"6.3776","delta":"783.00","side":"bid","ts_ms":1781237184129}}

{"type":"orderbook_delta","sid":1,"seq":2407,"msg":{"market_ticker":"KXBTCPERP1","price":"6.3762","delta":"-785.00","side":"bid","ts_ms":1781237184132}}

{"type":"orderbook_delta","sid":1,"seq":2408,"msg":{"market_ticker":"KXBTCPERP1","price":"6.3766","delta":"785.00","side":"bid","ts_ms":1781237184132}}

{"type":"orderbook_delta","sid":1,"seq":2409,"msg":{"market_ticker":"KXBTCPERP1","price":"6.3736","delta":"-784.00","side":"bid","ts_ms":1781237184138}}

{"type":"orderbook_delta","sid":1,"seq":2410,"msg":{"market_ticker":"KXBTCPERP1","price":"6.3756","delta":"784.00","side":"bid","ts_ms":1781237184138}}

{"type":"orderbook_delta","sid":1,"seq":2411,"msg":{"market_ticker":"KXBTCPERP1","price":"6.3710","delta":"-785.00","side":"bid","ts_ms":1781237184149}}

{"type":"orderbook_delta","sid":1,"seq":2412,"msg":{"market_ticker":"KXBTCPERP1","price":"6.3746","delta":"785.00","side":"bid","ts_ms":1781237184149}}

{"type":"orderbook_delta","sid":1,"seq":2413,"msg":{"market_ticker":"KXBTCPERP1","price":"6.3684","delta":"-785.00","side":"bid","ts_ms":1781237184152}}

{"type":"orderbook_delta","sid":1,"seq":2414,"msg":{"market_ticker":"KXBTCPERP1","price":"6.3736","delta":"784.00","side":"bid","ts_ms":1781237184152}}

{"type":"orderbook_delta","sid":1,"seq":2415,"msg":{"market_ticker":"KXBTCPERP1","price":"6.3658","delta":"-786.00","side":"bid","ts_ms":1781237184156}}

{"type":"orderbook_delta","sid":1,"seq":2416,"msg":{"market_ticker":"KXBTCPERP1","price":"6.3726","delta":"785.00","side":"bid","ts_ms":1781237184156}}

{"type":"orderbook_delta","sid":1,"seq":2417,"msg":{"market_ticker":"KXBTCPERP1","price":"6.3632","delta":"-786.00","side":"bid","ts_ms":1781237184160}}

{"type":"orderbook_delta","sid":1,"seq":2418,"msg":{"market_ticker":"KXBTCPERP1","price":"6.3716","delta":"785.00","side":"bid","ts_ms":1781237184160}}

{"type":"orderbook_delta","sid":1,"seq":2419,"msg":{"market_ticker":"KXBTCPERP1","price":"6.3606","delta":"-787.00","side":"bid","ts_ms":1781237184163}}

{"type":"orderbook_delta","sid":1,"seq":2420,"msg":{"market_ticker":"KXBTCPERP1","price":"6.3706","delta":"785.00","side":"bid","ts_ms":1781237184163}}

{"type":"orderbook_delta","sid":1,"seq":2421,"msg":{"market_ticker":"KXBTCPERP1","price":"6.3580","delta":"-787.00","side":"bid","ts_ms":1781237184167}}

{"type":"orderbook_delta","sid":1,"seq":2422,"msg":{"market_ticker":"KXBTCPERP1","price":"6.3696","delta":"785.00","side":"bid","ts_ms":1781237184167}}

{"type":"orderbook_delta","sid":1,"seq":2423,"msg":{"market_ticker":"KXBTCPERP1","price":"6.3378","delta":"1.00","side":"bid","ts_ms":1781237184167}}

{"type":"orderbook_delta","sid":1,"seq":2424,"msg":{"market_ticker":"KXBTCPERP1","price":"6.4009","delta":"-298.00","side":"ask","ts_ms":1781237184171}}

{"type":"orderbook_delta","sid":1,"seq":2425,"msg":{"market_ticker":"KXBTCPERP1","price":"6.3862","delta":"299.00","side":"ask","ts_ms":1781237184171}}

{"type":"orderbook_delta","sid":1,"seq":2426,"msg":{"market_ticker":"KXBTCPERP1","price":"6.4035","delta":"-781.00","side":"ask","ts_ms":1781237184174}}

{"type":"orderbook_delta","sid":1,"seq":2427,"msg":{"market_ticker":"KXBTCPERP1","price":"6.3872","delta":"783.00","side":"ask","ts_ms":1781237184174}}

{"type":"orderbook_delta","sid":1,"seq":2428,"msg":{"market_ticker":"KXBTCPERP1","price":"6.4061","delta":"-781.00","side":"ask","ts_ms":1781237184177}}

{"type":"orderbook_delta","sid":1,"seq":2429,"msg":{"market_ticker":"KXBTCPERP1","price":"6.3882","delta":"783.00","side":"ask","ts_ms":1781237184177}}

{"type":"orderbook_delta","sid":1,"seq":2430,"msg":{"market_ticker":"KXBTCPERP1","price":"6.4087","delta":"-781.00","side":"ask","ts_ms":1781237184181}}

{"type":"orderbook_delta","sid":1,"seq":2431,"msg":{"market_ticker":"KXBTCPERP1","price":"6.3892","delta":"783.00","side":"ask","ts_ms":1781237184181}}

{"type":"orderbook_delta","sid":1,"seq":2432,"msg":{"market_ticker":"KXBTCPERP1","price":"6.4113","delta":"-780.00","side":"ask","ts_ms":1781237184184}}

{"type":"orderbook_delta","sid":1,"seq":2433,"msg":{"market_ticker":"KXBTCPERP1","price":"6.3902","delta":"783.00","side":"ask","ts_ms":1781237184184}}

{"type":"orderbook_delta","sid":1,"seq":2434,"msg":{"market_ticker":"KXBTCPERP1","price":"6.4139","delta":"-780.00","side":"ask","ts_ms":1781237184187}}

{"type":"orderbook_delta","sid":1,"seq":2435,"msg":{"market_ticker":"KXBTCPERP1","price":"6.3912","delta":"783.00","side":"ask","ts_ms":1781237184187}}

{"type":"orderbook_delta","sid":1,"seq":2436,"msg":{"market_ticker":"KXBTCPERP1","price":"6.4165","delta":"-780.00","side":"ask","ts_ms":1781237184191}}

{"type":"orderbook_delta","sid":1,"seq":2437,"msg":{"market_ticker":"KXBTCPERP1","price":"6.3922","delta":"783.00","side":"ask","ts_ms":1781237184191}}

{"type":"orderbook_delta","sid":1,"seq":2438,"msg":{"market_ticker":"KXBTCPERP1","price":"6.4191","delta":"-779.00","side":"ask","ts_ms":1781237184195}}

{"type":"orderbook_delta","sid":1,"seq":2439,"msg":{"market_ticker":"KXBTCPERP1","price":"6.3932","delta":"783.00","side":"ask","ts_ms":1781237184195}}

{"type":"orderbook_delta","sid":1,"seq":2440,"msg":{"market_ticker":"KXBTCPERP1","price":"6.4217","delta":"-779.00","side":"ask","ts_ms":1781237184198}}

{"type":"orderbook_delta","sid":1,"seq":2441,"msg":{"market_ticker":"KXBTCPERP1","price":"6.3942","delta":"782.00","side":"ask","ts_ms":1781237184198}}

{"type":"orderbook_delta","sid":1,"seq":2442,"msg":{"market_ticker":"KXBTCPERP1","price":"6.4243","delta":"-779.00","side":"ask","ts_ms":1781237184201}}

{"type":"orderbook_delta","sid":1,"seq":2443,"msg":{"market_ticker":"KXBTCPERP1","price":"6.3952","delta":"782.00","side":"ask","ts_ms":1781237184201}}

{"type":"orderbook_delta","sid":1,"seq":2444,"msg":{"market_ticker":"KXBTCPERP1","price":"6.2848","delta":"-1.00","side":"bid","ts_ms":1781237184388}}

{"type":"ticker","sid":3,"msg":{"market_ticker":"KXBTCPERP1","price":"6.3329","bid":"6.3329","ask":"6.3416","bid_size_fp":"343.00","ask_size_fp":"658.00","last_trade_size_fp":"0.00","volume":"4179467045.00","volume_notional_value_dollars":"3245141294.960300","volume_24h":"1877080.00","volume_24h_notional_value_dollars":"11687174.591200","open_interest":"2332769.00","open_interest_notional_value_dollars":"14773192.800100","reference_price":{"price":"6.3393","ts_ms":1781237184000},"settlement_mark_price":{"price":"6.3516","ts_ms":1781237183032},"liquidation_mark_price":{"price":"6.3788","ts_ms":1781237184398},"funding_rate":{"rate":0,"next_funding_time_ms":1781265600000,"ts_ms":1781237183032},"ts_ms":1781217877584}}

{"type":"orderbook_delta","sid":1,"seq":2445,"msg":{"market_ticker":"KXBTCPERP1","price":"6.3942","delta":"1.00","side":"ask","ts_ms":1781237184548}}

{"type":"orderbook_delta","sid":1,"seq":2446,"msg":{"market_ticker":"KXBTCPERP1","price":"6.3852","delta":"-1.00","side":"bid","ts_ms":1781237184557}}

{"type":"trade","sid":2,"seq":1901,"msg":{"trade_id":"bfbaa997-465a-6ec0-da98-7ad8ee90cbb7","market_ticker":"KXBTCPERP1","price":"6.3852","count":"1.00","taker_side":"ask","ts_ms":1781237184557}}

{"type":"orderbook_delta","sid":1,"seq":2447,"msg":{"market_ticker":"KXBTCPERP1","price":"6.4133","delta":"1.00","side":"ask","ts_ms":1781237184632}}

{"type":"orderbook_delta","sid":1,"seq":2448,"msg":{"market_ticker":"KXBTCPERP1","price":"6.3852","delta":"-1.00","side":"bid","ts_ms":1781237184674}}

{"type":"trade","sid":2,"seq":1902,"msg":{"trade_id":"4dc98cc7-25de-6494-c14f-cca0e074a9b7","market_ticker":"KXBTCPERP1","price":"6.3852","count":"1.00","taker_side":"ask","ts_ms":1781237184674}}

{"type":"orderbook_delta","sid":1,"seq":2449,"msg":{"market_ticker":"KXBTCPERP1","price":"6.3852","delta":"-8.00","side":"bid","ts_ms":1781237185052}}

{"type":"orderbook_delta","sid":1,"seq":2450,"msg":{"market_ticker":"KXBTCPERP1","price":"6.3834","delta":"11.00","side":"bid","ts_ms":1781237185052}}

{"type":"orderbook_delta","sid":1,"seq":2451,"msg":{"market_ticker":"KXBTCPERP1","price":"6.3850","delta":"-1.00","side":"bid","ts_ms":1781237185099}}

{"type":"trade","sid":2,"seq":1903,"msg":{"trade_id":"ce3e3d9c-ae9b-5c13-ceac-22db9eacd2dd","market_ticker":"KXBTCPERP1","price":"6.3850","count":"1.00","taker_side":"ask","ts_ms":1781237185099}}

{"type":"orderbook_delta","sid":1,"seq":2452,"msg":{"market_ticker":"KXBTCPERP1","price":"6.3850","delta":"-9.00","side":"bid","ts_ms":1781237185152}}

{"type":"orderbook_delta","sid":1,"seq":2453,"msg":{"market_ticker":"KXBTCPERP1","price":"6.3833","delta":"9.00","side":"bid","ts_ms":1781237185152}}

{"type":"orderbook_delta","sid":1,"seq":2454,"msg":{"market_ticker":"KXBTCPERP1","price":"6.4006","delta":"1.00","side":"ask","ts_ms":1781237185206}}

{"type":"orderbook_delta","sid":1,"seq":2455,"msg":{"market_ticker":"KXBTCPERP1","price":"6.3862","delta":"-1.00","side":"ask","ts_ms":1781237185235}}

{"type":"trade","sid":2,"seq":1904,"msg":{"trade_id":"61eb7d33-2426-664d-2965-75dd5eca17ba","market_ticker":"KXBTCPERP1","price":"6.3862","count":"1.00","taker_side":"bid","ts_ms":1781237185235}}

{"type":"orderbook_delta","sid":1,"seq":2456,"msg":{"market_ticker":"KXBTCPERP1","price":"6.3899","delta":"-9.00","side":"ask","ts_ms":1781237185252}}

{"type":"orderbook_delta","sid":1,"seq":2457,"msg":{"market_ticker":"KXBTCPERP1","price":"6.3882","delta":"10.00","side":"ask","ts_ms":1781237185252}}

{"type":"orderbook_delta","sid":1,"seq":2458,"msg":{"market_ticker":"KXBTCPERP1","price":"6.2814","delta":"1.00","side":"bid","ts_ms":1781237185358}}

{"type":"orderbook_delta","sid":1,"seq":2459,"msg":{"market_ticker":"KXBTCPERP1","price":"6.3410","delta":"1.00","side":"bid","ts_ms":1781237185363}}

{"type":"orderbook_delta","sid":1,"seq":2460,"msg":{"market_ticker":"KXBTCPERP1","price":"6.3862","delta":"-1.00","side":"ask","ts_ms":1781237185380}}

{"type":"trade","sid":2,"seq":1905,"msg":{"trade_id":"7a6617f4-8282-7d09-93d7-750f42166846","market_ticker":"KXBTCPERP1","price":"6.3862","count":"1.00","taker_side":"bid","ts_ms":1781237185380}}

{"type":"orderbook_delta","sid":1,"seq":2461,"msg":{"market_ticker":"KXBTCPERP1","price":"6.3900","delta":"-10.00","side":"ask","ts_ms":1781237185454}}

{"type":"orderbook_delta","sid":1,"seq":2462,"msg":{"market_ticker":"KXBTCPERP1","price":"6.3883","delta":"10.00","side":"ask","ts_ms":1781237185454}}

{"type":"orderbook_delta","sid":1,"seq":2463,"msg":{"market_ticker":"KXBTCPERP1","price":"6.3151","delta":"1.00","side":"bid","ts_ms":1781237185473}}

{"type":"ticker","sid":3,"msg":{"market_ticker":"KXBTCPERP1","price":"6.3329","bid":"6.3329","ask":"6.3416","bid_size_fp":"343.00","ask_size_fp":"658.00","last_trade_size_fp":"0.00","volume":"4179467045.00","volume_notional_value_dollars":"3245141294.960300","volume_24h":"1877080.00","volume_24h_notional_value_dollars":"11687174.591200","open_interest":"2332769.00","open_interest_notional_value_dollars":"14773192.800100","reference_price":{"price":"6.3393","ts_ms":1781237185000},"settlement_mark_price":{"price":"6.3516","ts_ms":1781237183032},"liquidation_mark_price":{"price":"6.3789","ts_ms":1781237185398},"funding_rate":{"rate":0,"next_funding_time_ms":1781265600000,"ts_ms":1781237183032},"ts_ms":1781217877584}}

{"type":"orderbook_delta","sid":1,"seq":2464,"msg":{"market_ticker":"KXBTCPERP1","price":"6.3823","delta":"-137.00","side":"bid","ts_ms":1781237185555}}

{"type":"orderbook_delta","sid":1,"seq":2465,"msg":{"market_ticker":"KXBTCPERP1","price":"6.3785","delta":"137.00","side":"bid","ts_ms":1781237185555}}

{"type":"trade","sid":2,"seq":1906,"msg":{"trade_id":"b0c7d2ce-a412-7f34-3e2d-17bdc76269d7","market_ticker":"KXBTCPERP1","price":"6.3834","count":"1.00","taker_side":"ask","ts_ms":1781237185566}}

{"type":"orderbook_delta","sid":1,"seq":2466,"msg":{"market_ticker":"KXBTCPERP1","price":"6.3834","delta":"-1.00","side":"bid","ts_ms":1781237185566}}

{"type":"orderbook_delta","sid":1,"seq":2467,"msg":{"market_ticker":"KXBTCPERP1","price":"6.3445","delta":"1.00","side":"bid","ts_ms":1781237185626}}

{"type":"orderbook_delta","sid":1,"seq":2468,"msg":{"market_ticker":"KXBTCPERP1","price":"6.3834","delta":"-10.00","side":"bid","ts_ms":1781237185656}}

{"type":"orderbook_delta","sid":1,"seq":2469,"msg":{"market_ticker":"KXBTCPERP1","price":"6.3825","delta":"11.00","side":"bid","ts_ms":1781237185656}}

{"type":"orderbook_delta","sid":1,"seq":2470,"msg":{"market_ticker":"KXBTCPERP1","price":"6.3862","delta":"-1.00","side":"ask","ts_ms":1781237185684}}

{"type":"trade","sid":2,"seq":1907,"msg":{"trade_id":"cbe554ff-cb3e-753d-8982-3fe6506df05a","market_ticker":"KXBTCPERP1","price":"6.3862","count":"1.00","taker_side":"bid","ts_ms":1781237185684}}

{"type":"orderbook_delta","sid":1,"seq":2471,"msg":{"market_ticker":"KXBTCPERP1","price":"6.3833","delta":"-1.00","side":"bid","ts_ms":1781237185714}}

{"type":"trade","sid":2,"seq":1908,"msg":{"trade_id":"8910cbd7-f6a3-7687-cf1f-e7fd73d7b709","market_ticker":"KXBTCPERP1","price":"6.3833","count":"1.00","taker_side":"ask","ts_ms":1781237185714}}

{"type":"orderbook_delta","sid":1,"seq":2472,"msg":{"market_ticker":"KXBTCPERP1","price":"6.3833","delta":"-8.00","side":"bid","ts_ms":1781237185757}}

{"type":"orderbook_delta","sid":1,"seq":2473,"msg":{"market_ticker":"KXBTCPERP1","price":"6.3824","delta":"9.00","side":"bid","ts_ms":1781237185757}}

{"type":"orderbook_delta","sid":1,"seq":2474,"msg":{"market_ticker":"KXBTCPERP1","price":"6.3651","delta":"1.00","side":"bid","ts_ms":1781237185794}}

{"type":"orderbook_delta","sid":1,"seq":2475,"msg":{"market_ticker":"KXBTCPERP1","price":"6.3723","delta":"1.00","side":"bid","ts_ms":1781237185855}}

{"type":"orderbook_delta","sid":1,"seq":2476,"msg":{"market_ticker":"KXBTCPERP1","price":"6.1762","delta":"-1.00","side":"bid","ts_ms":1781237185855}}

{"type":"orderbook_delta","sid":1,"seq":2477,"msg":{"market_ticker":"KXBTCPERP1","price":"6.3882","delta":"-10.00","side":"ask","ts_ms":1781237185857}}

{"type":"orderbook_delta","sid":1,"seq":2478,"msg":{"market_ticker":"KXBTCPERP1","price":"6.3873","delta":"10.00","side":"ask","ts_ms":1781237185857}}

{"type":"orderbook_delta","sid":1,"seq":2479,"msg":{"market_ticker":"KXBTCPERP1","price":"6.3693","delta":"1.00","side":"bid","ts_ms":1781237185986}}

{"type":"orderbook_delta","sid":1,"seq":2480,"msg":{"market_ticker":"KXBTCPERP1","price":"6.3883","delta":"-10.00","side":"ask","ts_ms":1781237186059}}

{"type":"orderbook_delta","sid":1,"seq":2481,"msg":{"market_ticker":"KXBTCPERP1","price":"6.3874","delta":"10.00","side":"ask","ts_ms":1781237186059}}

{"type":"orderbook_delta","sid":1,"seq":2482,"msg":{"market_ticker":"KXBTCPERP1","price":"6.4102","delta":"1.00","side":"ask","ts_ms":1781237186156}}

{"type":"orderbook_delta","sid":1,"seq":2483,"msg":{"market_ticker":"KXBTCPERP1","price":"6.3973","delta":"-131.00","side":"ask","ts_ms":1781237186160}}

{"type":"orderbook_delta","sid":1,"seq":2484,"msg":{"market_ticker":"KXBTCPERP1","price":"6.3923","delta":"132.00","side":"ask","ts_ms":1781237186160}}

{"type":"orderbook_delta","sid":1,"seq":2485,"msg":{"market_ticker":"KXBTCPERP1","price":"6.2186","delta":"1.00","side":"bid","ts_ms":1781237186265}}

{"type":"orderbook_delta","sid":1,"seq":2486,"msg":{"market_ticker":"KXBTCPERP1","price":"6.2450","delta":"1.00","side":"bid","ts_ms":1781237186367}}

{"type":"orderbook_delta","sid":1,"seq":2487,"msg":{"market_ticker":"KXBTCPERP1","price":"6.3862","delta":"-1.00","side":"ask","ts_ms":1781237186413}}

{"type":"trade","sid":2,"seq":1909,"msg":{"trade_id":"ea3684de-0072-57c5-f636-21219c643cd6","market_ticker":"KXBTCPERP1","price":"6.3862","count":"1.00","taker_side":"bid","ts_ms":1781237186413}}

{"type":"orderbook_delta","sid":1,"seq":2488,"msg":{"market_ticker":"KXBTCPERP1","price":"6.2104","delta":"1.00","side":"bid","ts_ms":1781237186453}}

{"type":"ticker","sid":3,"msg":{"market_ticker":"KXBTCPERP1","price":"6.3329","bid":"6.3329","ask":"6.3416","bid_size_fp":"343.00","ask_size_fp":"658.00","last_trade_size_fp":"0.00","volume":"4179467045.00","volume_notional_value_dollars":"3245141294.960300","volume_24h":"1877080.00","volume_24h_notional_value_dollars":"11687174.591200","open_interest":"2332769.00","open_interest_notional_value_dollars":"14773192.800100","reference_price":{"price":"6.3393","ts_ms":1781237186000},"settlement_mark_price":{"price":"6.3516","ts_ms":1781237183032},"liquidation_mark_price":{"price":"6.3789","ts_ms":1781237186398},"funding_rate":{"rate":0,"next_funding_time_ms":1781265600000,"ts_ms":1781237183032},"ts_ms":1781217877584}}

{"type":"orderbook_delta","sid":1,"seq":2489,"msg":{"market_ticker":"KXBTCPERP1","price":"6.2136","delta":"-1.00","side":"bid","ts_ms":1781237186543}}

{"type":"orderbook_delta","sid":1,"seq":2490,"msg":{"market_ticker":"KXBTCPERP1","price":"6.3862","delta":"-1.00","side":"ask","ts_ms":1781237186576}}

{"type":"trade","sid":2,"seq":1910,"msg":{"trade_id":"8042ab6e-7a8e-5d0d-cdc2-f7888d15487e","market_ticker":"KXBTCPERP1","price":"6.3862","count":"1.00","taker_side":"bid","ts_ms":1781237186576}}

{"type":"orderbook_delta","sid":1,"seq":2491,"msg":{"market_ticker":"KXBTCPERP1","price":"6.3862","delta":"-1.00","side":"ask","ts_ms":1781237186689}}

{"type":"trade","sid":2,"seq":1911,"msg":{"trade_id":"28ef2d2c-9ace-570d-7213-934bbe75b90a","market_ticker":"KXBTCPERP1","price":"6.3862","count":"1.00","taker_side":"bid","ts_ms":1781237186689}}

{"type":"orderbook_delta","sid":1,"seq":2492,"msg":{"market_ticker":"KXBTCPERP1","price":"7.6637","delta":"-1.00","side":"ask","ts_ms":1781237186779}}

{"type":"orderbook_delta","sid":1,"seq":2493,"msg":{"market_ticker":"KXBTCPERP1","price":"6.3560","delta":"1.00","side":"bid","ts_ms":1781237186791}}

{"type":"orderbook_delta","sid":1,"seq":2494,"msg":{"market_ticker":"KXBTCPERP1","price":"6.3825","delta":"-1.00","side":"bid","ts_ms":1781237186942}}

{"type":"trade","sid":2,"seq":1912,"msg":{"trade_id":"8b3dac93-0546-6814-0514-7121a58b545f","market_ticker":"KXBTCPERP1","price":"6.3825","count":"1.00","taker_side":"ask","ts_ms":1781237186942}}

{"type":"orderbook_delta","sid":1,"seq":2495,"msg":{"market_ticker":"KXBTCPERP1","price":"6.4186","delta":"-1.00","side":"ask","ts_ms":1781237186998}}

{"type":"orderbook_delta","sid":1,"seq":2496,"msg":{"market_ticker":"KXBTCPERP1","price":"6.5174","delta":"-1.00","side":"ask","ts_ms":1781237187015}}

{"type":"orderbook_delta","sid":1,"seq":2497,"msg":{"market_ticker":"KXBTCPERP1","price":"6.3961","delta":"1.00","side":"ask","ts_ms":1781237187036}}

{"type":"orderbook_delta","sid":1,"seq":2498,"msg":{"market_ticker":"KXBTCPERP1","price":"6.3825","delta":"-1.00","side":"bid","ts_ms":1781237187102}}

{"type":"trade","sid":2,"seq":1913,"msg":{"trade_id":"e907661f-dd42-6130-58d4-de4f37f07c5f","market_ticker":"KXBTCPERP1","price":"6.3825","count":"1.00","taker_side":"ask","ts_ms":1781237187102}}

{"type":"orderbook_delta","sid":1,"seq":2499,"msg":{"market_ticker":"KXBTCPERP1","price":"6.3669","delta":"1.00","side":"bid","ts_ms":1781237187125}}

{"type":"orderbook_delta","sid":1,"seq":2500,"msg":{"market_ticker":"KXBTCPERP1","price":"6.2231","delta":"1.00","side":"bid","ts_ms":1781237187182}}

{"type":"trade","sid":2,"seq":1914,"msg":{"trade_id":"c32d0908-8d82-7520-75ac-b1b8c485c657","market_ticker":"KXBTCPERP1","price":"6.3825","count":"1.00","taker_side":"ask","ts_ms":1781237187284}}

{"type":"orderbook_delta","sid":1,"seq":2501,"msg":{"market_ticker":"KXBTCPERP1","price":"6.3825","delta":"-1.00","side":"bid","ts_ms":1781237187284}}

{"type":"trade","sid":2,"seq":1915,"msg":{"trade_id":"4c2af6b7-cfde-4644-0468-7e41b2b1dbc3","market_ticker":"KXBTCPERP1","price":"6.3825","count":"1.00","taker_side":"ask","ts_ms":1781237187349}}

{"type":"orderbook_delta","sid":1,"seq":2502,"msg":{"market_ticker":"KXBTCPERP1","price":"6.3825","delta":"-1.00","side":"bid","ts_ms":1781237187349}}

{"type":"orderbook_delta","sid":1,"seq":2503,"msg":{"market_ticker":"KXBTCPERP1","price":"6.3825","delta":"-7.00","side":"bid","ts_ms":1781237187368}}

{"type":"orderbook_delta","sid":1,"seq":2504,"msg":{"market_ticker":"KXBTCPERP1","price":"6.3821","delta":"10.00","side":"bid","ts_ms":1781237187368}}

{"type":"orderbook_delta","sid":1,"seq":2505,"msg":{"market_ticker":"KXBTCPERP1","price":"6.2292","delta":"1.00","side":"bid","ts_ms":1781237187373}}

{"type":"orderbook_delta","sid":1,"seq":2506,"msg":{"market_ticker":"KXBTCPERP1","price":"6.3824","delta":"-1.00","side":"bid","ts_ms":1781237187419}}

{"type":"trade","sid":2,"seq":1916,"msg":{"trade_id":"8747b1e6-95b7-6357-c152-d73fcca0e1e1","market_ticker":"KXBTCPERP1","price":"6.3824","count":"1.00","taker_side":"ask","ts_ms":1781237187419}}

{"type":"orderbook_delta","sid":1,"seq":2507,"msg":{"market_ticker":"KXBTCPERP1","price":"6.4339","delta":"1.00","side":"ask","ts_ms":1781237187456}}

{"type":"ticker","sid":3,"msg":{"market_ticker":"KXBTCPERP1","price":"6.3329","bid":"6.3329","ask":"6.3416","bid_size_fp":"343.00","ask_size_fp":"658.00","last_trade_size_fp":"0.00","volume":"4179467045.00","volume_notional_value_dollars":"3245141294.960300","volume_24h":"1877080.00","volume_24h_notional_value_dollars":"11687174.591200","open_interest":"2332769.00","open_interest_notional_value_dollars":"14773192.800100","reference_price":{"price":"6.3394","ts_ms":1781237187000},"settlement_mark_price":{"price":"6.3516","ts_ms":1781237183032},"liquidation_mark_price":{"price":"6.3789","ts_ms":1781237187398},"funding_rate":{"rate":0,"next_funding_time_ms":1781265600000,"ts_ms":1781237183032},"ts_ms":1781217877584}}

{"type":"orderbook_delta","sid":1,"seq":2508,"msg":{"market_ticker":"KXBTCPERP1","price":"6.5365","delta":"1.00","side":"ask","ts_ms":1781237187507}}

{"type":"trade","sid":2,"seq":1917,"msg":{"trade_id":"36359fec-d16f-4f2b-9405-982c08d28525","market_ticker":"KXBTCPERP1","price":"6.3824","count":"1.00","taker_side":"ask","ts_ms":1781237187507}}

{"type":"orderbook_delta","sid":1,"seq":2509,"msg":{"market_ticker":"KXBTCPERP1","price":"6.3824","delta":"-1.00","side":"bid","ts_ms":1781237187507}}

{"type":"orderbook_delta","sid":1,"seq":2510,"msg":{"market_ticker":"KXBTCPERP1","price":"6.3824","delta":"-7.00","side":"bid","ts_ms":1781237187570}}

{"type":"orderbook_delta","sid":1,"seq":2511,"msg":{"market_ticker":"KXBTCPERP1","price":"6.3820","delta":"10.00","side":"bid","ts_ms":1781237187570}}

{"type":"orderbook_delta","sid":1,"seq":2512,"msg":{"market_ticker":"KXBTCPERP1","price":"6.4558","delta":"1.00","side":"ask","ts_ms":1781237187619}}

{"type":"orderbook_delta","sid":1,"seq":2513,"msg":{"market_ticker":"KXBTCPERP1","price":"6.3377","delta":"1.00","side":"bid","ts_ms":1781237187822}}

{"type":"orderbook_delta","sid":1,"seq":2514,"msg":{"market_ticker":"KXBTCPERP1","price":"6.3821","delta":"-1.00","side":"bid","ts_ms":1781237187864}}

{"type":"trade","sid":2,"seq":1918,"msg":{"trade_id":"f0e3c546-a50e-74ec-3e08-69021ac284cf","market_ticker":"KXBTCPERP1","price":"6.3821","count":"1.00","taker_side":"ask","ts_ms":1781237187864}}

{"type":"orderbook_delta","sid":1,"seq":2515,"msg":{"market_ticker":"KXBTCPERP1","price":"6.3698","delta":"1.00","side":"bid","ts_ms":1781237188068}}

{"type":"orderbook_delta","sid":1,"seq":2516,"msg":{"market_ticker":"KXBTCPERP1","price":"6.2366","delta":"1.00","side":"bid","ts_ms":1781237188225}}

{"type":"orderbook_delta","sid":1,"seq":2517,"msg":{"market_ticker":"KXBTCPERP1","price":"6.3821","delta":"-9.00","side":"bid","ts_ms":1781237188282}}

{"type":"orderbook_delta","sid":1,"seq":2518,"msg":{"market_ticker":"KXBTCPERP1","price":"6.3801","delta":"11.00","side":"bid","ts_ms":1781237188282}}

{"type":"orderbook_delta","sid":1,"seq":2519,"msg":{"market_ticker":"KXBTCPERP1","price":"6.3862","delta":"-1.00","side":"ask","ts_ms":1781237188338}}

{"type":"trade","sid":2,"seq":1919,"msg":{"trade_id":"fe756c8f-4f8e-64d9-e852-e883566c972a","market_ticker":"KXBTCPERP1","price":"6.3862","count":"1.00","taker_side":"bid","ts_ms":1781237188338}}

{"type":"orderbook_delta","sid":1,"seq":2520,"msg":{"market_ticker":"KXBTCPERP1","price":"6.3820","delta":"-10.00","side":"bid","ts_ms":1781237188376}}

{"type":"orderbook_delta","sid":1,"seq":2521,"msg":{"market_ticker":"KXBTCPERP1","price":"6.3800","delta":"10.00","side":"bid","ts_ms":1781237188376}}

{"type":"orderbook_delta","sid":1,"seq":2522,"msg":{"market_ticker":"KXBTCPERP1","price":"6.3686","delta":"1.00","side":"bid","ts_ms":1781237188444}}

{"type":"ticker","sid":3,"msg":{"market_ticker":"KXBTCPERP1","price":"6.3329","bid":"6.3329","ask":"6.3416","bid_size_fp":"343.00","ask_size_fp":"658.00","last_trade_size_fp":"0.00","volume":"4179467045.00","volume_notional_value_dollars":"3245141294.960300","volume_24h":"1877080.00","volume_24h_notional_value_dollars":"11687174.591200","open_interest":"2332769.00","open_interest_notional_value_dollars":"14773192.800100","reference_price":{"price":"6.3397","ts_ms":1781237188000},"settlement_mark_price":{"price":"6.3516","ts_ms":1781237183032},"liquidation_mark_price":{"price":"6.3794","ts_ms":1781237188398},"funding_rate":{"rate":0,"next_funding_time_ms":1781265600000,"ts_ms":1781237183032},"ts_ms":1781217877584}}

{"type":"orderbook_delta","sid":1,"seq":2523,"msg":{"market_ticker":"KXBTCPERP1","price":"6.3070","delta":"1.00","side":"bid","ts_ms":1781237188557}}

{"type":"orderbook_delta","sid":1,"seq":2524,"msg":{"market_ticker":"KXBTCPERP1","price":"6.3873","delta":"-10.00","side":"ask","ts_ms":1781237188678}}

{"type":"orderbook_delta","sid":1,"seq":2525,"msg":{"market_ticker":"KXBTCPERP1","price":"6.3849","delta":"10.00","side":"ask","ts_ms":1781237188678}}

{"type":"orderbook_delta","sid":1,"seq":2526,"msg":{"market_ticker":"KXBTCPERP1","price":"6.2277","delta":"1.00","side":"bid","ts_ms":1781237188698}}

{"type":"orderbook_delta","sid":1,"seq":2527,"msg":{"market_ticker":"KXBTCPERP1","price":"6.2990","delta":"-1.00","side":"bid","ts_ms":1781237188733}}

{"type":"orderbook_delta","sid":1,"seq":2528,"msg":{"market_ticker":"KXBTCPERP1","price":"6.3874","delta":"-10.00","side":"ask","ts_ms":1781237188780}}

{"type":"orderbook_delta","sid":1,"seq":2529,"msg":{"market_ticker":"KXBTCPERP1","price":"6.3858","delta":"10.00","side":"ask","ts_ms":1781237188780}}

{"type":"orderbook_delta","sid":1,"seq":2530,"msg":{"market_ticker":"KXBTCPERP1","price":"6.3801","delta":"-1.00","side":"bid","ts_ms":1781237188906}}

{"type":"trade","sid":2,"seq":1920,"msg":{"trade_id":"5036a096-d8d6-5520-53f7-66a48e9031f7","market_ticker":"KXBTCPERP1","price":"6.3801","count":"1.00","taker_side":"ask","ts_ms":1781237188906}}

{"type":"orderbook_delta","sid":1,"seq":2531,"msg":{"market_ticker":"KXBTCPERP1","price":"6.3801","delta":"-1.00","side":"bid","ts_ms":1781237188941}}

{"type":"trade","sid":2,"seq":1921,"msg":{"trade_id":"11e8eff5-260e-5048-5304-731e77f05b87","market_ticker":"KXBTCPERP1","price":"6.3801","count":"1.00","taker_side":"ask","ts_ms":1781237188941}}

{"type":"orderbook_delta","sid":1,"seq":2532,"msg":{"market_ticker":"KXBTCPERP1","price":"6.3801","delta":"-1.00","side":"bid","ts_ms":1781237189099}}

{"type":"trade","sid":2,"seq":1922,"msg":{"trade_id":"fb94fbb6-9406-75e0-f66f-e5ac4d53e7f3","market_ticker":"KXBTCPERP1","price":"6.3801","count":"1.00","taker_side":"ask","ts_ms":1781237189099}}

{"type":"orderbook_delta","sid":1,"seq":2533,"msg":{"market_ticker":"KXBTCPERP1","price":"6.3801","delta":"-8.00","side":"bid","ts_ms":1781237189182}}

{"type":"orderbook_delta","sid":1,"seq":2534,"msg":{"market_ticker":"KXBTCPERP1","price":"6.3809","delta":"11.00","side":"bid","ts_ms":1781237189182}}

{"type":"orderbook_delta","sid":1,"seq":2535,"msg":{"market_ticker":"KXBTCPERP1","price":"6.3809","delta":"-1.00","side":"bid","ts_ms":1781237189205}}

{"type":"trade","sid":2,"seq":1923,"msg":{"trade_id":"0fadca20-7816-6274-be0d-75e57e513973","market_ticker":"KXBTCPERP1","price":"6.3809","count":"1.00","taker_side":"ask","ts_ms":1781237189205}}

{"type":"orderbook_delta","sid":1,"seq":2536,"msg":{"market_ticker":"KXBTCPERP1","price":"6.3809","delta":"-1.00","side":"bid","ts_ms":1781237189293}}

{"type":"trade","sid":2,"seq":1924,"msg":{"trade_id":"084eca13-c0de-7c00-4405-a94552b364cb","market_ticker":"KXBTCPERP1","price":"6.3809","count":"1.00","taker_side":"ask","ts_ms":1781237189293}}

{"type":"orderbook_delta","sid":1,"seq":2537,"msg":{"market_ticker":"KXBTCPERP1","price":"6.3809","delta":"-1.00","side":"bid","ts_ms":1781237189447}}

{"type":"trade","sid":2,"seq":1925,"msg":{"trade_id":"91d9285e-660a-6944-3b9a-b1a14e921e83","market_ticker":"KXBTCPERP1","price":"6.3809","count":"1.00","taker_side":"ask","ts_ms":1781237189447}}

{"type":"ticker","sid":3,"msg":{"market_ticker":"KXBTCPERP1","price":"6.3329","bid":"6.3329","ask":"6.3416","bid_size_fp":"343.00","ask_size_fp":"658.00","last_trade_size_fp":"0.00","volume":"4179467045.00","volume_notional_value_dollars":"3245141294.960300","volume_24h":"1877080.00","volume_24h_notional_value_dollars":"11687174.591200","open_interest":"2332769.00","open_interest_notional_value_dollars":"14773192.800100","reference_price":{"price":"6.3396","ts_ms":1781237189000},"settlement_mark_price":{"price":"6.3516","ts_ms":1781237188036},"liquidation_mark_price":{"price":"6.3792","ts_ms":1781237189399},"funding_rate":{"rate":0,"next_funding_time_ms":1781265600000,"ts_ms":1781237188036},"ts_ms":1781217877584}}

{"type":"orderbook_delta","sid":1,"seq":2538,"msg":{"market_ticker":"KXBTCPERP1","price":"6.3809","delta":"-1.00","side":"bid","ts_ms":1781237189589}}

{"type":"trade","sid":2,"seq":1926,"msg":{"trade_id":"93b0868b-8e62-5cb4-68d4-86445baeeb97","market_ticker":"KXBTCPERP1","price":"6.3809","count":"1.00","taker_side":"ask","ts_ms":1781237189589}}

{"type":"orderbook_delta","sid":1,"seq":2539,"msg":{"market_ticker":"KXBTCPERP1","price":"6.4100","delta":"1.00","side":"ask","ts_ms":1781237189618}}

{"type":"orderbook_delta","sid":1,"seq":2540,"msg":{"market_ticker":"KXBTCPERP1","price":"6.4691","delta":"1.00","side":"ask","ts_ms":1781237189700}}

{"type":"orderbook_delta","sid":1,"seq":2541,"msg":{"market_ticker":"KXBTCPERP1","price":"6.3355","delta":"1.00","side":"bid","ts_ms":1781237189782}}

{"type":"orderbook_delta","sid":1,"seq":2542,"msg":{"market_ticker":"KXBTCPERP1","price":"6.1614","delta":"-1.00","side":"bid","ts_ms":1781237189783}}

{"type":"orderbook_delta","sid":1,"seq":2543,"msg":{"market_ticker":"KXBTCPERP1","price":"6.3809","delta":"-7.00","side":"bid","ts_ms":1781237189786}}

{"type":"orderbook_delta","sid":1,"seq":2544,"msg":{"market_ticker":"KXBTCPERP1","price":"6.3806","delta":"11.00","side":"bid","ts_ms":1781237189786}}

{"type":"orderbook_delta","sid":1,"seq":2545,"msg":{"market_ticker":"KXBTCPERP1","price":"6.3872","delta":"1.00","side":"ask","ts_ms":1781237189959}}

{"type":"orderbook_delta","sid":1,"seq":2546,"msg":{"market_ticker":"KXBTCPERP1","price":"6.3806","delta":"-1.00","side":"bid","ts_ms":1781237190092}}

{"type":"trade","sid":2,"seq":1927,"msg":{"trade_id":"f9b26e4f-334a-5300-9fca-c08a844cfeff","market_ticker":"KXBTCPERP1","price":"6.3806","count":"1.00","taker_side":"ask","ts_ms":1781237190092}}

{"type":"orderbook_delta","sid":1,"seq":2547,"msg":{"market_ticker":"KXBTCPERP1","price":"6.2688","delta":"1.00","side":"bid","ts_ms":1781237190216}}

{"type":"orderbook_delta","sid":1,"seq":2548,"msg":{"market_ticker":"KXBTCPERP1","price":"6.3621","delta":"1.00","side":"bid","ts_ms":1781237190373}}

{"type":"ticker","sid":3,"msg":{"market_ticker":"KXBTCPERP1","price":"6.3329","bid":"6.3329","ask":"6.3416","bid_size_fp":"343.00","ask_size_fp":"658.00","last_trade_size_fp":"0.00","volume":"4179467045.00","volume_notional_value_dollars":"3245141294.960300","volume_24h":"1877080.00","volume_24h_notional_value_dollars":"11687174.591200","open_interest":"2332769.00","open_interest_notional_value_dollars":"14773192.800100","reference_price":{"price":"6.3394","ts_ms":1781237190000},"settlement_mark_price":{"price":"6.3516","ts_ms":1781237188036},"liquidation_mark_price":{"price":"6.3791","ts_ms":1781237190398},"funding_rate":{"rate":0,"next_funding_time_ms":1781265600000,"ts_ms":1781237188036},"ts_ms":1781217877584}}

{"type":"orderbook_delta","sid":1,"seq":2549,"msg":{"market_ticker":"KXBTCPERP1","price":"6.3806","delta":"-1.00","side":"bid","ts_ms":1781237190540}}

{"type":"trade","sid":2,"seq":1928,"msg":{"trade_id":"79b06f5a-12d2-73e4-dfce-8bb48c5f16c3","market_ticker":"KXBTCPERP1","price":"6.3806","count":"1.00","taker_side":"ask","ts_ms":1781237190540}}

{"type":"orderbook_delta","sid":1,"seq":2550,"msg":{"market_ticker":"KXBTCPERP1","price":"6.3806","delta":"-1.00","side":"bid","ts_ms":1781237190579}}

{"type":"trade","sid":2,"seq":1929,"msg":{"trade_id":"c6f22ac3-0bae-6e40-8cc5-43537bf47b13","market_ticker":"KXBTCPERP1","price":"6.3806","count":"1.00","taker_side":"ask","ts_ms":1781237190579}}

{"type":"orderbook_delta","sid":1,"seq":2551,"msg":{"market_ticker":"KXBTCPERP1","price":"6.3806","delta":"-8.00","side":"bid","ts_ms":1781237190692}}

{"type":"orderbook_delta","sid":1,"seq":2552,"msg":{"market_ticker":"KXBTCPERP1","price":"6.3805","delta":"11.00","side":"bid","ts_ms":1781237190692}}

{"type":"orderbook_delta","sid":1,"seq":2553,"msg":{"market_ticker":"KXBTCPERP1","price":"6.3786","delta":"-640.00","side":"bid","ts_ms":1781237190768}}

{"type":"orderbook_delta","sid":1,"seq":2554,"msg":{"market_ticker":"KXBTCPERP1","price":"6.3811","delta":"640.00","side":"bid","ts_ms":1781237190768}}

{"type":"orderbook_delta","sid":1,"seq":2555,"msg":{"market_ticker":"KXBTCPERP1","price":"6.3776","delta":"-783.00","side":"bid","ts_ms":1781237190771}}

{"type":"orderbook_delta","sid":1,"seq":2556,"msg":{"market_ticker":"KXBTCPERP1","price":"6.3806","delta":"783.00","side":"bid","ts_ms":1781237190771}}

{"type":"orderbook_delta","sid":1,"seq":2557,"msg":{"market_ticker":"KXBTCPERP1","price":"6.3766","delta":"-785.00","side":"bid","ts_ms":1781237190774}}

{"type":"orderbook_delta","sid":1,"seq":2558,"msg":{"market_ticker":"KXBTCPERP1","price":"6.3801","delta":"784.00","side":"bid","ts_ms":1781237190774}}

{"type":"orderbook_delta","sid":1,"seq":2559,"msg":{"market_ticker":"KXBTCPERP1","price":"6.3844","delta":"1.00","side":"ask","ts_ms":1781237190774}}

{"type":"orderbook_delta","sid":1,"seq":2560,"msg":{"market_ticker":"KXBTCPERP1","price":"6.3756","delta":"-784.00","side":"bid","ts_ms":1781237190778}}

{"type":"orderbook_delta","sid":1,"seq":2561,"msg":{"market_ticker":"KXBTCPERP1","price":"6.3796","delta":"783.00","side":"bid","ts_ms":1781237190778}}

{"type":"orderbook_delta","sid":1,"seq":2562,"msg":{"market_ticker":"KXBTCPERP1","price":"6.3746","delta":"-785.00","side":"bid","ts_ms":1781237190781}}

{"type":"orderbook_delta","sid":1,"seq":2563,"msg":{"market_ticker":"KXBTCPERP1","price":"6.3791","delta":"784.00","side":"bid","ts_ms":1781237190781}}

{"type":"orderbook_delta","sid":1,"seq":2564,"msg":{"market_ticker":"KXBTCPERP1","price":"6.3736","delta":"-784.00","side":"bid","ts_ms":1781237190785}}

{"type":"orderbook_delta","sid":1,"seq":2565,"msg":{"market_ticker":"KXBTCPERP1","price":"6.3786","delta":"783.00","side":"bid","ts_ms":1781237190785}}

{"type":"orderbook_delta","sid":1,"seq":2566,"msg":{"market_ticker":"KXBTCPERP1","price":"6.3726","delta":"-785.00","side":"bid","ts_ms":1781237190788}}

{"type":"orderbook_delta","sid":1,"seq":2567,"msg":{"market_ticker":"KXBTCPERP1","price":"6.3781","delta":"784.00","side":"bid","ts_ms":1781237190788}}

{"type":"orderbook_delta","sid":1,"seq":2568,"msg":{"market_ticker":"KXBTCPERP1","price":"6.3716","delta":"-785.00","side":"bid","ts_ms":1781237190791}}

{"type":"orderbook_delta","sid":1,"seq":2569,"msg":{"market_ticker":"KXBTCPERP1","price":"6.3776","delta":"784.00","side":"bid","ts_ms":1781237190791}}

{"type":"orderbook_delta","sid":1,"seq":2570,"msg":{"market_ticker":"KXBTCPERP1","price":"6.3706","delta":"-785.00","side":"bid","ts_ms":1781237190794}}

{"type":"orderbook_delta","sid":1,"seq":2571,"msg":{"market_ticker":"KXBTCPERP1","price":"6.3771","delta":"785.00","side":"bid","ts_ms":1781237190794}}

{"type":"orderbook_delta","sid":1,"seq":2572,"msg":{"market_ticker":"KXBTCPERP1","price":"6.3696","delta":"-785.00","side":"bid","ts_ms":1781237190797}}

{"type":"orderbook_delta","sid":1,"seq":2573,"msg":{"market_ticker":"KXBTCPERP1","price":"6.3766","delta":"785.00","side":"bid","ts_ms":1781237190797}}

{"type":"orderbook_delta","sid":1,"seq":2574,"msg":{"market_ticker":"KXBTCPERP1","price":"6.3862","delta":"-292.00","side":"ask","ts_ms":1781237190800}}

{"type":"orderbook_delta","sid":1,"seq":2575,"msg":{"market_ticker":"KXBTCPERP1","price":"6.4005","delta":"291.00","side":"ask","ts_ms":1781237190800}}

{"type":"orderbook_delta","sid":1,"seq":2576,"msg":{"market_ticker":"KXBTCPERP1","price":"6.3872","delta":"-783.00","side":"ask","ts_ms":1781237190804}}

{"type":"orderbook_delta","sid":1,"seq":2577,"msg":{"market_ticker":"KXBTCPERP1","price":"6.4010","delta":"782.00","side":"ask","ts_ms":1781237190804}}

{"type":"orderbook_delta","sid":1,"seq":2578,"msg":{"market_ticker":"KXBTCPERP1","price":"6.3882","delta":"-783.00","side":"ask","ts_ms":1781237190807}}

{"type":"orderbook_delta","sid":1,"seq":2579,"msg":{"market_ticker":"KXBTCPERP1","price":"6.4015","delta":"782.00","side":"ask","ts_ms":1781237190807}}

{"type":"orderbook_delta","sid":1,"seq":2580,"msg":{"market_ticker":"KXBTCPERP1","price":"6.3892","delta":"-783.00","side":"ask","ts_ms":1781237190810}}

{"type":"orderbook_delta","sid":1,"seq":2581,"msg":{"market_ticker":"KXBTCPERP1","price":"6.4020","delta":"782.00","side":"ask","ts_ms":1781237190810}}

{"type":"orderbook_delta","sid":1,"seq":2582,"msg":{"market_ticker":"KXBTCPERP1","price":"6.3902","delta":"-783.00","side":"ask","ts_ms":1781237190813}}

{"type":"orderbook_delta","sid":1,"seq":2583,"msg":{"market_ticker":"KXBTCPERP1","price":"6.4025","delta":"781.00","side":"ask","ts_ms":1781237190813}}

{"type":"orderbook_delta","sid":1,"seq":2584,"msg":{"market_ticker":"KXBTCPERP1","price":"6.3912","delta":"-783.00","side":"ask","ts_ms":1781237190816}}

{"type":"orderbook_delta","sid":1,"seq":2585,"msg":{"market_ticker":"KXBTCPERP1","price":"6.4030","delta":"781.00","side":"ask","ts_ms":1781237190816}}

{"type":"orderbook_delta","sid":1,"seq":2586,"msg":{"market_ticker":"KXBTCPERP1","price":"6.3922","delta":"-783.00","side":"ask","ts_ms":1781237190819}}

{"type":"orderbook_delta","sid":1,"seq":2587,"msg":{"market_ticker":"KXBTCPERP1","price":"6.4035","delta":"781.00","side":"ask","ts_ms":1781237190819}}

{"type":"orderbook_delta","sid":1,"seq":2588,"msg":{"market_ticker":"KXBTCPERP1","price":"6.3932","delta":"-783.00","side":"ask","ts_ms":1781237190822}}

{"type":"orderbook_delta","sid":1,"seq":2589,"msg":{"market_ticker":"KXBTCPERP1","price":"6.4040","delta":"781.00","side":"ask","ts_ms":1781237190822}}

{"type":"orderbook_delta","sid":1,"seq":2590,"msg":{"market_ticker":"KXBTCPERP1","price":"6.3942","delta":"-782.00","side":"ask","ts_ms":1781237190825}}

{"type":"orderbook_delta","sid":1,"seq":2591,"msg":{"market_ticker":"KXBTCPERP1","price":"6.4045","delta":"781.00","side":"ask","ts_ms":1781237190825}}

{"type":"orderbook_delta","sid":1,"seq":2592,"msg":{"market_ticker":"KXBTCPERP1","price":"6.3952","delta":"-782.00","side":"ask","ts_ms":1781237190828}}

{"type":"orderbook_delta","sid":1,"seq":2593,"msg":{"market_ticker":"KXBTCPERP1","price":"6.4050","delta":"781.00","side":"ask","ts_ms":1781237190828}}

{"type":"orderbook_delta","sid":1,"seq":2594,"msg":{"market_ticker":"KXBTCPERP1","price":"6.3561","delta":"1.00","side":"bid","ts_ms":1781237190872}}

{"type":"orderbook_delta","sid":1,"seq":2595,"msg":{"market_ticker":"KXBTCPERP1","price":"6.5438","delta":"-1.00","side":"ask","ts_ms":1781237190927}}

{"type":"orderbook_delta","sid":1,"seq":2596,"msg":{"market_ticker":"KXBTCPERP1","price":"6.4655","delta":"-1.00","side":"ask","ts_ms":1781237190945}}

{"type":"orderbook_delta","sid":1,"seq":2597,"msg":{"market_ticker":"KXBTCPERP1","price":"6.3811","delta":"-1.00","side":"bid","ts_ms":1781237191056}}

{"type":"trade","sid":2,"seq":1930,"msg":{"trade_id":"9299e133-3abc-66b7-4b1d-ac60db48fdff","market_ticker":"KXBTCPERP1","price":"6.3811","count":"1.00","taker_side":"ask","ts_ms":1781237191056}}

{"type":"orderbook_delta","sid":1,"seq":2598,"msg":{"market_ticker":"KXBTCPERP1","price":"6.3961","delta":"-1.00","side":"ask","ts_ms":1781237191110}}

{"type":"orderbook_delta","sid":1,"seq":2599,"msg":{"market_ticker":"KXBTCPERP1","price":"6.2584","delta":"1.00","side":"bid","ts_ms":1781237191118}}

{"type":"trade","sid":2,"seq":1931,"msg":{"trade_id":"9d169118-7fc9-479c-d0c9-16ee2c19a2b1","market_ticker":"KXBTCPERP1","price":"6.3844","count":"1.00","taker_side":"bid","ts_ms":1781237191199}}

{"type":"orderbook_delta","sid":1,"seq":2600,"msg":{"market_ticker":"KXBTCPERP1","price":"6.3844","delta":"-1.00","side":"ask","ts_ms":1781237191199}}

{"type":"orderbook_delta","sid":1,"seq":2601,"msg":{"market_ticker":"KXBTCPERP1","price":"6.3654","delta":"1.00","side":"bid","ts_ms":1781237191233}}

{"type":"orderbook_delta","sid":1,"seq":2602,"msg":{"market_ticker":"KXBTCPERP1","price":"6.2106","delta":"1.00","side":"bid","ts_ms":1781237191322}}

{"type":"orderbook_delta","sid":1,"seq":2603,"msg":{"market_ticker":"KXBTCPERP1","price":"6.3811","delta":"-1.00","side":"bid","ts_ms":1781237191427}}

{"type":"trade","sid":2,"seq":1932,"msg":{"trade_id":"21280b8b-81fc-65ff-b93d-23058c2f9963","market_ticker":"KXBTCPERP1","price":"6.3811","count":"1.00","taker_side":"ask","ts_ms":1781237191427}}

{"type":"ticker","sid":3,"msg":{"market_ticker":"KXBTCPERP1","price":"6.3329","bid":"6.3329","ask":"6.3416","bid_size_fp":"343.00","ask_size_fp":"658.00","last_trade_size_fp":"0.00","volume":"4179467045.00","volume_notional_value_dollars":"3245141294.960300","volume_24h":"1877080.00","volume_24h_notional_value_dollars":"11687174.591200","open_interest":"2332769.00","open_interest_notional_value_dollars":"14773192.800100","reference_price":{"price":"6.3394","ts_ms":1781237191000},"settlement_mark_price":{"price":"6.3516","ts_ms":1781237188036},"liquidation_mark_price":{"price":"6.3790","ts_ms":1781237191398},"funding_rate":{"rate":0,"next_funding_time_ms":1781265600000,"ts_ms":1781237188036},"ts_ms":1781217877584}}

{"type":"orderbook_delta","sid":1,"seq":2604,"msg":{"market_ticker":"KXBTCPERP1","price":"6.4017","delta":"-1.00","side":"ask","ts_ms":1781237191509}}

{"type":"orderbook_delta","sid":1,"seq":2605,"msg":{"market_ticker":"KXBTCPERP1","price":"6.3410","delta":"-1.00","side":"bid","ts_ms":1781237191527}}

{"type":"orderbook_delta","sid":1,"seq":2606,"msg":{"market_ticker":"KXBTCPERP1","price":"6.3811","delta":"-1.00","side":"bid","ts_ms":1781237191557}}

{"type":"trade","sid":2,"seq":1933,"msg":{"trade_id":"304caf04-3e90-43d7-3ef5-38061debd07f","market_ticker":"KXBTCPERP1","price":"6.3811","count":"1.00","taker_side":"ask","ts_ms":1781237191557}}

{"type":"orderbook_delta","sid":1,"seq":2607,"msg":{"market_ticker":"KXBTCPERP1","price":"7.6637","delta":"-1.00","side":"ask","ts_ms":1781237191576}}

{"type":"orderbook_delta","sid":1,"seq":2608,"msg":{"market_ticker":"KXBTCPERP1","price":"6.4687","delta":"1.00","side":"ask","ts_ms":1781237191598}}

{"type":"orderbook_delta","sid":1,"seq":2609,"msg":{"market_ticker":"KXBTCPERP1","price":"6.2992","delta":"1.00","side":"bid","ts_ms":1781237191848}}

{"type":"orderbook_delta","sid":1,"seq":2610,"msg":{"market_ticker":"KXBTCPERP1","price":"6.3811","delta":"-1.00","side":"bid","ts_ms":1781237191964}}

{"type":"trade","sid":2,"seq":1934,"msg":{"trade_id":"a982f3b1-f740-4b53-fa6a-10f2597eac97","market_ticker":"KXBTCPERP1","price":"6.3811","count":"1.00","taker_side":"ask","ts_ms":1781237191964}}

{"type":"orderbook_delta","sid":1,"seq":2611,"msg":{"market_ticker":"KXBTCPERP1","price":"6.4445","delta":"1.00","side":"ask","ts_ms":1781237192162}}

{"type":"orderbook_delta","sid":1,"seq":2612,"msg":{"market_ticker":"KXBTCPERP1","price":"6.4300","delta":"1.00","side":"ask","ts_ms":1781237192330}}

{"type":"orderbook_delta","sid":1,"seq":2613,"msg":{"market_ticker":"KXBTCPERP1","price":"6.3811","delta":"-1.00","side":"bid","ts_ms":1781237192385}}

{"type":"trade","sid":2,"seq":1935,"msg":{"trade_id":"e26a84e5-3d38-77ef-5668-0831390f62eb","market_ticker":"KXBTCPERP1","price":"6.3811","count":"1.00","taker_side":"ask","ts_ms":1781237192385}}

{"type":"orderbook_delta","sid":1,"seq":2614,"msg":{"market_ticker":"KXBTCPERP1","price":"6.5365","delta":"-1.00","side":"ask","ts_ms":1781237192469}}

{"type":"ticker","sid":3,"msg":{"market_ticker":"KXBTCPERP1","price":"6.3329","bid":"6.3329","ask":"6.3416","bid_size_fp":"343.00","ask_size_fp":"658.00","last_trade_size_fp":"0.00","volume":"4179467045.00","volume_notional_value_dollars":"3245141294.960300","volume_24h":"1877080.00","volume_24h_notional_value_dollars":"11687174.591200","open_interest":"2332769.00","open_interest_notional_value_dollars":"14773192.800100","reference_price":{"price":"6.3394","ts_ms":1781237192000},"settlement_mark_price":{"price":"6.3516","ts_ms":1781237188036},"liquidation_mark_price":{"price":"6.3791","ts_ms":1781237192399},"funding_rate":{"rate":0,"next_funding_time_ms":1781265600000,"ts_ms":1781237188036},"ts_ms":1781217877584}}

{"type":"orderbook_delta","sid":1,"seq":2615,"msg":{"market_ticker":"KXBTCPERP1","price":"6.2134","delta":"1.00","side":"bid","ts_ms":1781237192530}}

{"type":"orderbook_delta","sid":1,"seq":2616,"msg":{"market_ticker":"KXBTCPERP1","price":"6.3188","delta":"1.00","side":"bid","ts_ms":1781237192742}}

{"type":"orderbook_delta","sid":1,"seq":2617,"msg":{"market_ticker":"KXBTCPERP1","price":"6.2855","delta":"1.00","side":"bid","ts_ms":1781237192818}}

{"type":"orderbook_delta","sid":1,"seq":2618,"msg":{"market_ticker":"KXBTCPERP1","price":"6.3811","delta":"-1.00","side":"bid","ts_ms":1781237192980}}

{"type":"trade","sid":2,"seq":1936,"msg":{"trade_id":"57af4718-74e0-4bb7-9865-e806d6a173ab","market_ticker":"KXBTCPERP1","price":"6.3811","count":"1.00","taker_side":"ask","ts_ms":1781237192980}}

{"type":"orderbook_delta","sid":1,"seq":2619,"msg":{"market_ticker":"KXBTCPERP1","price":"6.3805","delta":"-11.00","side":"bid","ts_ms":1781237193007}}

{"type":"orderbook_delta","sid":1,"seq":2620,"msg":{"market_ticker":"KXBTCPERP1","price":"6.3819","delta":"11.00","side":"bid","ts_ms":1781237193007}}

{"type":"orderbook_delta","sid":1,"seq":2621,"msg":{"market_ticker":"KXBTCPERP1","price":"6.3800","delta":"-10.00","side":"bid","ts_ms":1781237193108}}

{"type":"orderbook_delta","sid":1,"seq":2622,"msg":{"market_ticker":"KXBTCPERP1","price":"6.3818","delta":"10.00","side":"bid","ts_ms":1781237193108}}

{"type":"orderbook_delta","sid":1,"seq":2623,"msg":{"market_ticker":"KXBTCPERP1","price":"6.4097","delta":"1.00","side":"ask","ts_ms":1781237193204}}

{"type":"orderbook_delta","sid":1,"seq":2624,"msg":{"market_ticker":"KXBTCPERP1","price":"6.3293","delta":"1.00","side":"bid","ts_ms":1781237193284}}

{"type":"orderbook_delta","sid":1,"seq":2625,"msg":{"market_ticker":"KXBTCPERP1","price":"6.3849","delta":"-10.00","side":"ask","ts_ms":1781237193310}}

{"type":"orderbook_delta","sid":1,"seq":2626,"msg":{"market_ticker":"KXBTCPERP1","price":"6.3867","delta":"10.00","side":"ask","ts_ms":1781237193310}}

{"type":"orderbook_delta","sid":1,"seq":2627,"msg":{"market_ticker":"KXBTCPERP1","price":"6.3904","delta":"1.00","side":"ask","ts_ms":1781237193364}}

{"type":"orderbook_delta","sid":1,"seq":2628,"msg":{"market_ticker":"KXBTCPERP1","price":"6.3799","delta":"1.00","side":"bid","ts_ms":1781237193373}}

{"type":"orderbook_delta","sid":1,"seq":2629,"msg":{"market_ticker":"KXBTCPERP1","price":"6.3858","delta":"-10.00","side":"ask","ts_ms":1781237193410}}

{"type":"orderbook_delta","sid":1,"seq":2630,"msg":{"market_ticker":"KXBTCPERP1","price":"6.3868","delta":"10.00","side":"ask","ts_ms":1781237193410}}

{"type":"orderbook_delta","sid":1,"seq":2631,"msg":{"market_ticker":"KXBTCPERP1","price":"6.3819","delta":"-1.00","side":"bid","ts_ms":1781237193411}}

{"type":"trade","sid":2,"seq":1937,"msg":{"trade_id":"f4d04bb8-ac32-4db8-fb0b-ff9654c08e13","market_ticker":"KXBTCPERP1","price":"6.3819","count":"1.00","taker_side":"ask","ts_ms":1781237193411}}

{"type":"orderbook_delta","sid":1,"seq":2632,"msg":{"market_ticker":"KXBTCPERP1","price":"7.6637","delta":"-1.00","side":"ask","ts_ms":1781237193439}}

{"type":"trade","sid":2,"seq":1938,"msg":{"trade_id":"86b67038-c53e-66b4-ec73-12cc23589143","market_ticker":"KXBTCPERP1","price":"6.3819","count":"1.00","taker_side":"ask","ts_ms":1781237193479}}

{"type":"orderbook_delta","sid":1,"seq":2633,"msg":{"market_ticker":"KXBTCPERP1","price":"6.3819","delta":"-1.00","side":"bid","ts_ms":1781237193479}}

{"type":"ticker","sid":3,"msg":{"market_ticker":"KXBTCPERP1","price":"6.3329","bid":"6.3329","ask":"6.3416","bid_size_fp":"343.00","ask_size_fp":"658.00","last_trade_size_fp":"0.00","volume":"4179467045.00","volume_notional_value_dollars":"3245141294.960300","volume_24h":"1877080.00","volume_24h_notional_value_dollars":"11687174.591200","open_interest":"2332769.00","open_interest_notional_value_dollars":"14773192.800100","reference_price":{"price":"6.3395","ts_ms":1781237193000},"settlement_mark_price":{"price":"6.3516","ts_ms":1781237188036},"liquidation_mark_price":{"price":"6.3792","ts_ms":1781237193399},"funding_rate":{"rate":0,"next_funding_time_ms":1781265600000,"ts_ms":1781237188036},"ts_ms":1781217877584}}

{"type":"orderbook_delta","sid":1,"seq":2634,"msg":{"market_ticker":"KXBTCPERP1","price":"6.3867","delta":"-1.00","side":"ask","ts_ms":1781237193502}}

{"type":"trade","sid":2,"seq":1939,"msg":{"trade_id":"1762b777-7410-5849-2561-bf817220944d","market_ticker":"KXBTCPERP1","price":"6.3867","count":"1.00","taker_side":"bid","ts_ms":1781237193502}}

{"type":"orderbook_delta","sid":1,"seq":2635,"msg":{"market_ticker":"KXBTCPERP1","price":"6.3819","delta":"-1.00","side":"bid","ts_ms":1781237193531}}

{"type":"trade","sid":2,"seq":1940,"msg":{"trade_id":"d907d4e5-ea4a-6bdc-a1e0-6d60ba5b74a3","market_ticker":"KXBTCPERP1","price":"6.3819","count":"1.00","taker_side":"ask","ts_ms":1781237193531}}

{"type":"orderbook_delta","sid":1,"seq":2636,"msg":{"market_ticker":"KXBTCPERP1","price":"6.3819","delta":"-8.00","side":"bid","ts_ms":1781237193611}}

{"type":"orderbook_delta","sid":1,"seq":2637,"msg":{"market_ticker":"KXBTCPERP1","price":"6.3820","delta":"11.00","side":"bid","ts_ms":1781237193611}}

{"type":"orderbook_delta","sid":1,"seq":2638,"msg":{"market_ticker":"KXBTCPERP1","price":"6.3820","delta":"-1.00","side":"bid","ts_ms":1781237193747}}

{"type":"trade","sid":2,"seq":1941,"msg":{"trade_id":"16f029e5-27ce-524c-3dd4-daadbc77c467","market_ticker":"KXBTCPERP1","price":"6.3820","count":"1.00","taker_side":"ask","ts_ms":1781237193747}}

{"type":"orderbook_delta","sid":1,"seq":2639,"msg":{"market_ticker":"KXBTCPERP1","price":"6.4563","delta":"1.00","side":"ask","ts_ms":1781237194014}}

{"type":"orderbook_delta","sid":1,"seq":2640,"msg":{"market_ticker":"KXBTCPERP1","price":"6.3903","delta":"1.00","side":"ask","ts_ms":1781237194152}}

{"type":"orderbook_delta","sid":1,"seq":2641,"msg":{"market_ticker":"KXBTCPERP1","price":"6.3330","delta":"1.00","side":"bid","ts_ms":1781237194240}}

{"type":"orderbook_delta","sid":1,"seq":2642,"msg":{"market_ticker":"KXBTCPERP1","price":"7.6637","delta":"1.00","side":"ask","ts_ms":1781237194348}}

{"type":"orderbook_delta","sid":1,"seq":2643,"msg":{"market_ticker":"KXBTCPERP1","price":"6.3820","delta":"-1.00","side":"bid","ts_ms":1781237194374}}

{"type":"trade","sid":2,"seq":1942,"msg":{"trade_id":"d896fa33-442e-5664-c276-225dd0f0d547","market_ticker":"KXBTCPERP1","price":"6.3820","count":"1.00","taker_side":"ask","ts_ms":1781237194374}}

{"type":"orderbook_delta","sid":1,"seq":2644,"msg":{"market_ticker":"KXBTCPERP1","price":"6.2186","delta":"-1.00","side":"bid","ts_ms":1781237194395}}

{"type":"ticker","sid":3,"msg":{"market_ticker":"KXBTCPERP1","price":"6.3329","bid":"6.3329","ask":"6.3416","bid_size_fp":"343.00","ask_size_fp":"658.00","last_trade_size_fp":"0.00","volume":"4179467045.00","volume_notional_value_dollars":"3245141294.960300","volume_24h":"1877080.00","volume_24h_notional_value_dollars":"11687174.591200","open_interest":"2332769.00","open_interest_notional_value_dollars":"14773192.800100","reference_price":{"price":"6.3395","ts_ms":1781237194000},"settlement_mark_price":{"price":"6.3515","ts_ms":1781237193034},"liquidation_mark_price":{"price":"6.3792","ts_ms":1781237194398},"funding_rate":{"rate":0,"next_funding_time_ms":1781265600000,"ts_ms":1781237193034},"ts_ms":1781217877584}}

{"type":"trade","sid":2,"seq":1943,"msg":{"trade_id":"d9b8982f-5112-794c-8144-208711e073a7","market_ticker":"KXBTCPERP1","price":"6.3820","count":"1.00","taker_side":"ask","ts_ms":1781237194578}}

{"type":"orderbook_delta","sid":1,"seq":2645,"msg":{"market_ticker":"KXBTCPERP1","price":"6.3820","delta":"-1.00","side":"bid","ts_ms":1781237194578}}

{"type":"orderbook_delta","sid":1,"seq":2646,"msg":{"market_ticker":"KXBTCPERP1","price":"6.3820","delta":"-8.00","side":"bid","ts_ms":1781237194817}}

{"type":"orderbook_delta","sid":1,"seq":2647,"msg":{"market_ticker":"KXBTCPERP1","price":"6.3821","delta":"11.00","side":"bid","ts_ms":1781237194817}}

{"type":"orderbook_delta","sid":1,"seq":2648,"msg":{"market_ticker":"KXBTCPERP1","price":"6.3137","delta":"1.00","side":"bid","ts_ms":1781237194854}}

{"type":"orderbook_delta","sid":1,"seq":2649,"msg":{"market_ticker":"KXBTCPERP1","price":"7.6637","delta":"1.00","side":"ask","ts_ms":1781237195107}}

{"type":"orderbook_delta","sid":1,"seq":2650,"msg":{"market_ticker":"KXBTCPERP1","price":"6.2390","delta":"1.00","side":"bid","ts_ms":1781237195178}}

{"type":"orderbook_delta","sid":1,"seq":2651,"msg":{"market_ticker":"KXBTCPERP1","price":"6.2491","delta":"1.00","side":"bid","ts_ms":1781237195199}}

{"type":"orderbook_delta","sid":1,"seq":2652,"msg":{"market_ticker":"KXBTCPERP1","price":"6.3464","delta":"1.00","side":"bid","ts_ms":1781237195306}}

{"type":"orderbook_delta","sid":1,"seq":2653,"msg":{"market_ticker":"KXBTCPERP1","price":"7.6637","delta":"1.00","side":"ask","ts_ms":1781237195313}}

{"type":"orderbook_delta","sid":1,"seq":2654,"msg":{"market_ticker":"KXBTCPERP1","price":"6.2538","delta":"1.00","side":"bid","ts_ms":1781237195391}}

{"type":"orderbook_delta","sid":1,"seq":2655,"msg":{"market_ticker":"KXBTCPERP1","price":"6.3867","delta":"-1.00","side":"ask","ts_ms":1781237195496}}

{"type":"trade","sid":2,"seq":1944,"msg":{"trade_id":"12267717-87b0-4ba9-bc02-6dc3e0dd1d75","market_ticker":"KXBTCPERP1","price":"6.3867","count":"1.00","taker_side":"bid","ts_ms":1781237195496}}

{"type":"ticker","sid":3,"msg":{"market_ticker":"KXBTCPERP1","price":"6.3329","bid":"6.3329","ask":"6.3416","bid_size_fp":"343.00","ask_size_fp":"658.00","last_trade_size_fp":"0.00","volume":"4179467045.00","volume_notional_value_dollars":"3245141294.960300","volume_24h":"1877080.00","volume_24h_notional_value_dollars":"11687174.591200","open_interest":"2332769.00","open_interest_notional_value_dollars":"14773192.800100","reference_price":{"price":"6.3394","ts_ms":1781237195000},"settlement_mark_price":{"price":"6.3515","ts_ms":1781237193034},"liquidation_mark_price":{"price":"6.3792","ts_ms":1781237195398},"funding_rate":{"rate":0,"next_funding_time_ms":1781265600000,"ts_ms":1781237193034},"ts_ms":1781217877584}}

{"type":"orderbook_delta","sid":1,"seq":2656,"msg":{"market_ticker":"KXBTCPERP1","price":"6.4651","delta":"1.00","side":"ask","ts_ms":1781237195606}}

{"type":"orderbook_delta","sid":1,"seq":2657,"msg":{"market_ticker":"KXBTCPERP1","price":"6.3436","delta":"1.00","side":"bid","ts_ms":1781237195682}}

{"type":"orderbook_delta","sid":1,"seq":2658,"msg":{"market_ticker":"KXBTCPERP1","price":"6.2791","delta":"1.00","side":"bid","ts_ms":1781237195705}}

{"type":"orderbook_delta","sid":1,"seq":2659,"msg":{"market_ticker":"KXBTCPERP1","price":"6.3811","delta":"-634.00","side":"bid","ts_ms":1781237195728}}

{"type":"orderbook_delta","sid":1,"seq":2660,"msg":{"market_ticker":"KXBTCPERP1","price":"6.3854","delta":"634.00","side":"bid","ts_ms":1781237195728}}

{"type":"orderbook_delta","sid":1,"seq":2661,"msg":{"market_ticker":"KXBTCPERP1","price":"6.3806","delta":"-783.00","side":"bid","ts_ms":1781237195731}}

{"type":"orderbook_delta","sid":1,"seq":2662,"msg":{"market_ticker":"KXBTCPERP1","price":"6.3834","delta":"783.00","side":"bid","ts_ms":1781237195731}}

{"type":"orderbook_delta","sid":1,"seq":2663,"msg":{"market_ticker":"KXBTCPERP1","price":"6.3801","delta":"-784.00","side":"bid","ts_ms":1781237195734}}

{"type":"orderbook_delta","sid":1,"seq":2664,"msg":{"market_ticker":"KXBTCPERP1","price":"6.3814","delta":"784.00","side":"bid","ts_ms":1781237195734}}

{"type":"orderbook_delta","sid":1,"seq":2665,"msg":{"market_ticker":"KXBTCPERP1","price":"6.3796","delta":"-783.00","side":"bid","ts_ms":1781237195738}}

{"type":"orderbook_delta","sid":1,"seq":2666,"msg":{"market_ticker":"KXBTCPERP1","price":"6.3794","delta":"783.00","side":"bid","ts_ms":1781237195738}}

{"type":"orderbook_delta","sid":1,"seq":2667,"msg":{"market_ticker":"KXBTCPERP1","price":"6.3791","delta":"-784.00","side":"bid","ts_ms":1781237195742}}

{"type":"orderbook_delta","sid":1,"seq":2668,"msg":{"market_ticker":"KXBTCPERP1","price":"6.3774","delta":"785.00","side":"bid","ts_ms":1781237195742}}

{"type":"orderbook_delta","sid":1,"seq":2669,"msg":{"market_ticker":"KXBTCPERP1","price":"6.3786","delta":"-783.00","side":"bid","ts_ms":1781237195746}}

{"type":"orderbook_delta","sid":1,"seq":2670,"msg":{"market_ticker":"KXBTCPERP1","price":"6.3754","delta":"784.00","side":"bid","ts_ms":1781237195746}}

{"type":"orderbook_delta","sid":1,"seq":2671,"msg":{"market_ticker":"KXBTCPERP1","price":"6.3781","delta":"-784.00","side":"bid","ts_ms":1781237195749}}

{"type":"orderbook_delta","sid":1,"seq":2672,"msg":{"market_ticker":"KXBTCPERP1","price":"6.3734","delta":"785.00","side":"bid","ts_ms":1781237195749}}

{"type":"orderbook_delta","sid":1,"seq":2673,"msg":{"market_ticker":"KXBTCPERP1","price":"6.3776","delta":"-784.00","side":"bid","ts_ms":1781237195752}}

{"type":"orderbook_delta","sid":1,"seq":2674,"msg":{"market_ticker":"KXBTCPERP1","price":"6.3714","delta":"785.00","side":"bid","ts_ms":1781237195752}}

{"type":"orderbook_delta","sid":1,"seq":2675,"msg":{"market_ticker":"KXBTCPERP1","price":"6.3771","delta":"-785.00","side":"bid","ts_ms":1781237195756}}

{"type":"orderbook_delta","sid":1,"seq":2676,"msg":{"market_ticker":"KXBTCPERP1","price":"6.3694","delta":"786.00","side":"bid","ts_ms":1781237195756}}

{"type":"orderbook_delta","sid":1,"seq":2677,"msg":{"market_ticker":"KXBTCPERP1","price":"6.3766","delta":"-785.00","side":"bid","ts_ms":1781237195759}}

{"type":"orderbook_delta","sid":1,"seq":2678,"msg":{"market_ticker":"KXBTCPERP1","price":"6.3674","delta":"786.00","side":"bid","ts_ms":1781237195759}}

{"type":"orderbook_delta","sid":1,"seq":2679,"msg":{"market_ticker":"KXBTCPERP1","price":"6.4005","delta":"-291.00","side":"ask","ts_ms":1781237195762}}

{"type":"orderbook_delta","sid":1,"seq":2680,"msg":{"market_ticker":"KXBTCPERP1","price":"6.4006","delta":"291.00","side":"ask","ts_ms":1781237195762}}

{"type":"orderbook_delta","sid":1,"seq":2681,"msg":{"market_ticker":"KXBTCPERP1","price":"6.4010","delta":"-782.00","side":"ask","ts_ms":1781237195766}}

{"type":"orderbook_delta","sid":1,"seq":2682,"msg":{"market_ticker":"KXBTCPERP1","price":"6.4026","delta":"781.00","side":"ask","ts_ms":1781237195766}}

{"type":"orderbook_delta","sid":1,"seq":2683,"msg":{"market_ticker":"KXBTCPERP1","price":"6.4015","delta":"-782.00","side":"ask","ts_ms":1781237195769}}

{"type":"orderbook_delta","sid":1,"seq":2684,"msg":{"market_ticker":"KXBTCPERP1","price":"6.4046","delta":"781.00","side":"ask","ts_ms":1781237195769}}

{"type":"orderbook_delta","sid":1,"seq":2685,"msg":{"market_ticker":"KXBTCPERP1","price":"6.4020","delta":"-782.00","side":"ask","ts_ms":1781237195772}}

{"type":"orderbook_delta","sid":1,"seq":2686,"msg":{"market_ticker":"KXBTCPERP1","price":"6.4066","delta":"781.00","side":"ask","ts_ms":1781237195772}}

{"type":"orderbook_delta","sid":1,"seq":2687,"msg":{"market_ticker":"KXBTCPERP1","price":"6.4025","delta":"-781.00","side":"ask","ts_ms":1781237195775}}

{"type":"orderbook_delta","sid":1,"seq":2688,"msg":{"market_ticker":"KXBTCPERP1","price":"6.4086","delta":"781.00","side":"ask","ts_ms":1781237195775}}

{"type":"orderbook_delta","sid":1,"seq":2689,"msg":{"market_ticker":"KXBTCPERP1","price":"6.4030","delta":"-781.00","side":"ask","ts_ms":1781237195778}}

{"type":"orderbook_delta","sid":1,"seq":2690,"msg":{"market_ticker":"KXBTCPERP1","price":"6.4106","delta":"780.00","side":"ask","ts_ms":1781237195778}}

{"type":"orderbook_delta","sid":1,"seq":2691,"msg":{"market_ticker":"KXBTCPERP1","price":"6.4035","delta":"-781.00","side":"ask","ts_ms":1781237195782}}

{"type":"orderbook_delta","sid":1,"seq":2692,"msg":{"market_ticker":"KXBTCPERP1","price":"6.4126","delta":"780.00","side":"ask","ts_ms":1781237195782}}

{"type":"orderbook_delta","sid":1,"seq":2693,"msg":{"market_ticker":"KXBTCPERP1","price":"6.4040","delta":"-781.00","side":"ask","ts_ms":1781237195785}}

{"type":"orderbook_delta","sid":1,"seq":2694,"msg":{"market_ticker":"KXBTCPERP1","price":"6.4146","delta":"780.00","side":"ask","ts_ms":1781237195785}}

{"type":"orderbook_delta","sid":1,"seq":2695,"msg":{"market_ticker":"KXBTCPERP1","price":"6.4045","delta":"-781.00","side":"ask","ts_ms":1781237195789}}

{"type":"orderbook_delta","sid":1,"seq":2696,"msg":{"market_ticker":"KXBTCPERP1","price":"6.4166","delta":"780.00","side":"ask","ts_ms":1781237195789}}

{"type":"orderbook_delta","sid":1,"seq":2697,"msg":{"market_ticker":"KXBTCPERP1","price":"6.4050","delta":"-781.00","side":"ask","ts_ms":1781237195793}}

{"type":"orderbook_delta","sid":1,"seq":2698,"msg":{"market_ticker":"KXBTCPERP1","price":"6.4186","delta":"779.00","side":"ask","ts_ms":1781237195793}}

{"type":"orderbook_delta","sid":1,"seq":2699,"msg":{"market_ticker":"KXBTCPERP1","price":"6.3854","delta":"-1.00","side":"bid","ts_ms":1781237195858}}

{"type":"trade","sid":2,"seq":1945,"msg":{"trade_id":"70ddcf1c-eef4-636b-74ee-a195be12a35b","market_ticker":"KXBTCPERP1","price":"6.3854","count":"1.00","taker_side":"ask","ts_ms":1781237195858}}

{"type":"orderbook_delta","sid":1,"seq":2700,"msg":{"market_ticker":"KXBTCPERP1","price":"7.6637","delta":"1.00","side":"ask","ts_ms":1781237195942}}

{"type":"trade","sid":2,"seq":1946,"msg":{"trade_id":"fe01745d-f9e8-6e83-17d4-c017da64774f","market_ticker":"KXBTCPERP1","price":"6.3854","count":"1.00","taker_side":"ask","ts_ms":1781237195967}}

{"type":"orderbook_delta","sid":1,"seq":2701,"msg":{"market_ticker":"KXBTCPERP1","price":"6.3854","delta":"-1.00","side":"bid","ts_ms":1781237195967}}

{"type":"orderbook_delta","sid":1,"seq":2702,"msg":{"market_ticker":"KXBTCPERP1","price":"6.2141","delta":"1.00","side":"bid","ts_ms":1781237196139}}

{"type":"orderbook_delta","sid":1,"seq":2703,"msg":{"market_ticker":"KXBTCPERP1","price":"7.6637","delta":"1.00","side":"ask","ts_ms":1781237196194}}

{"type":"orderbook_delta","sid":1,"seq":2704,"msg":{"market_ticker":"KXBTCPERP1","price":"6.3854","delta":"-1.00","side":"bid","ts_ms":1781237196329}}

{"type":"trade","sid":2,"seq":1947,"msg":{"trade_id":"0df95bf7-b8b4-7953-d307-ea25843c56a7","market_ticker":"KXBTCPERP1","price":"6.3854","count":"1.00","taker_side":"ask","ts_ms":1781237196329}}

{"type":"ticker","sid":3,"msg":{"market_ticker":"KXBTCPERP1","price":"6.3329","bid":"6.3329","ask":"6.3416","bid_size_fp":"343.00","ask_size_fp":"658.00","last_trade_size_fp":"0.00","volume":"4179467045.00","volume_notional_value_dollars":"3245141294.960300","volume_24h":"1877080.00","volume_24h_notional_value_dollars":"11687174.591200","open_interest":"2332769.00","open_interest_notional_value_dollars":"14773192.800100","reference_price":{"price":"6.3393","ts_ms":1781237196000},"settlement_mark_price":{"price":"6.3515","ts_ms":1781237193034},"liquidation_mark_price":{"price":"6.3792","ts_ms":1781237196398},"funding_rate":{"rate":0,"next_funding_time_ms":1781265600000,"ts_ms":1781237193034},"ts_ms":1781217877584}}

{"type":"orderbook_delta","sid":1,"seq":2705,"msg":{"market_ticker":"KXBTCPERP1","price":"6.4546","delta":"1.00","side":"ask","ts_ms":1781237196595}}

{"type":"orderbook_delta","sid":1,"seq":2706,"msg":{"market_ticker":"KXBTCPERP1","price":"6.4591","delta":"1.00","side":"ask","ts_ms":1781237196617}}

{"type":"orderbook_delta","sid":1,"seq":2707,"msg":{"market_ticker":"KXBTCPERP1","price":"6.3486","delta":"1.00","side":"bid","ts_ms":1781237196809}}

{"type":"orderbook_delta","sid":1,"seq":2708,"msg":{"market_ticker":"KXBTCPERP1","price":"6.3854","delta":"-1.00","side":"bid","ts_ms":1781237196923}}

{"type":"trade","sid":2,"seq":1948,"msg":{"trade_id":"fcaf0373-7dcc-53a7-a5f1-797763c804f7","market_ticker":"KXBTCPERP1","price":"6.3854","count":"1.00","taker_side":"ask","ts_ms":1781237196923}}

{"type":"orderbook_delta","sid":1,"seq":2709,"msg":{"market_ticker":"KXBTCPERP1","price":"6.3821","delta":"-11.00","side":"bid","ts_ms":1781237197028}}

{"type":"orderbook_delta","sid":1,"seq":2710,"msg":{"market_ticker":"KXBTCPERP1","price":"6.3838","delta":"11.00","side":"bid","ts_ms":1781237197028}}

{"type":"orderbook_delta","sid":1,"seq":2711,"msg":{"market_ticker":"KXBTCPERP1","price":"6.3854","delta":"-1.00","side":"bid","ts_ms":1781237197034}}

{"type":"trade","sid":2,"seq":1949,"msg":{"trade_id":"8b47f47f-9f98-6bd3-e461-65b5dc9b9a73","market_ticker":"KXBTCPERP1","price":"6.3854","count":"1.00","taker_side":"ask","ts_ms":1781237197034}}

{"type":"orderbook_delta","sid":1,"seq":2712,"msg":{"market_ticker":"KXBTCPERP1","price":"6.4466","delta":"1.00","side":"ask","ts_ms":1781237197066}}

{"type":"orderbook_delta","sid":1,"seq":2713,"msg":{"market_ticker":"KXBTCPERP1","price":"6.3818","delta":"-10.00","side":"bid","ts_ms":1781237197129}}

{"type":"orderbook_delta","sid":1,"seq":2714,"msg":{"market_ticker":"KXBTCPERP1","price":"6.3837","delta":"10.00","side":"bid","ts_ms":1781237197129}}

{"type":"orderbook_delta","sid":1,"seq":2715,"msg":{"market_ticker":"KXBTCPERP1","price":"6.4395","delta":"1.00","side":"ask","ts_ms":1781237197130}}

{"type":"orderbook_delta","sid":1,"seq":2716,"msg":{"market_ticker":"KXBTCPERP1","price":"6.3410","delta":"1.00","side":"bid","ts_ms":1781237197288}}

{"type":"orderbook_delta","sid":1,"seq":2717,"msg":{"market_ticker":"KXBTCPERP1","price":"6.3867","delta":"-8.00","side":"ask","ts_ms":1781237197331}}

{"type":"orderbook_delta","sid":1,"seq":2718,"msg":{"market_ticker":"KXBTCPERP1","price":"6.3886","delta":"10.00","side":"ask","ts_ms":1781237197331}}

{"type":"orderbook_delta","sid":1,"seq":2719,"msg":{"market_ticker":"KXBTCPERP1","price":"6.3873","delta":"1.00","side":"ask","ts_ms":1781237197338}}

{"type":"orderbook_delta","sid":1,"seq":2720,"msg":{"market_ticker":"KXBTCPERP1","price":"6.3868","delta":"-10.00","side":"ask","ts_ms":1781237197431}}

{"type":"orderbook_delta","sid":1,"seq":2721,"msg":{"market_ticker":"KXBTCPERP1","price":"6.3887","delta":"10.00","side":"ask","ts_ms":1781237197431}}

{"type":"orderbook_delta","sid":1,"seq":2722,"msg":{"market_ticker":"KXBTCPERP1","price":"6.3854","delta":"-1.00","side":"bid","ts_ms":1781237197442}}

{"type":"trade","sid":2,"seq":1950,"msg":{"trade_id":"1b5065d1-4de8-6b5f-081b-931a79c9550f","market_ticker":"KXBTCPERP1","price":"6.3854","count":"1.00","taker_side":"ask","ts_ms":1781237197442}}

{"type":"orderbook_delta","sid":1,"seq":2723,"msg":{"market_ticker":"KXBTCPERP1","price":"6.2595","delta":"1.00","side":"bid","ts_ms":1781237197457}}

{"type":"ticker","sid":3,"msg":{"market_ticker":"KXBTCPERP1","price":"6.3329","bid":"6.3329","ask":"6.3416","bid_size_fp":"343.00","ask_size_fp":"658.00","last_trade_size_fp":"0.00","volume":"4179467045.00","volume_notional_value_dollars":"3245141294.960300","volume_24h":"1877080.00","volume_24h_notional_value_dollars":"11687174.591200","open_interest":"2332769.00","open_interest_notional_value_dollars":"14773192.800100","reference_price":{"price":"6.3379","ts_ms":1781237197000},"settlement_mark_price":{"price":"6.3515","ts_ms":1781237193034},"liquidation_mark_price":{"price":"6.3778","ts_ms":1781237197398},"funding_rate":{"rate":0,"next_funding_time_ms":1781265600000,"ts_ms":1781237193034},"ts_ms":1781217877584}}

{"type":"orderbook_delta","sid":1,"seq":2724,"msg":{"market_ticker":"KXBTCPERP1","price":"6.3942","delta":"-1.00","side":"ask","ts_ms":1781237197610}}

{"type":"orderbook_delta","sid":1,"seq":2725,"msg":{"market_ticker":"KXBTCPERP1","price":"6.3254","delta":"1.00","side":"bid","ts_ms":1781237197619}}

{"type":"orderbook_delta","sid":1,"seq":2726,"msg":{"market_ticker":"KXBTCPERP1","price":"6.3204","delta":"1.00","side":"bid","ts_ms":1781237197756}}

{"type":"orderbook_delta","sid":1,"seq":2727,"msg":{"market_ticker":"KXBTCPERP1","price":"6.3358","delta":"1.00","side":"bid","ts_ms":1781237197778}}

{"type":"orderbook_delta","sid":1,"seq":2728,"msg":{"market_ticker":"KXBTCPERP1","price":"6.2915","delta":"1.00","side":"bid","ts_ms":1781237197807}}

{"type":"orderbook_delta","sid":1,"seq":2729,"msg":{"market_ticker":"KXBTCPERP1","price":"7.6637","delta":"1.00","side":"ask","ts_ms":1781237197841}}

{"type":"orderbook_delta","sid":1,"seq":2730,"msg":{"market_ticker":"KXBTCPERP1","price":"6.3854","delta":"-1.00","side":"bid","ts_ms":1781237197980}}

{"type":"trade","sid":2,"seq":1951,"msg":{"trade_id":"895d9b4f-8f70-5953-73c6-94b2a60a8e47","market_ticker":"KXBTCPERP1","price":"6.3854","count":"1.00","taker_side":"ask","ts_ms":1781237197980}}

{"type":"orderbook_delta","sid":1,"seq":2731,"msg":{"market_ticker":"KXBTCPERP1","price":"6.3854","delta":"-1.00","side":"bid","ts_ms":1781237198112}}

{"type":"trade","sid":2,"seq":1952,"msg":{"trade_id":"e5785435-7e64-6e4f-121e-7135c81f8643","market_ticker":"KXBTCPERP1","price":"6.3854","count":"1.00","taker_side":"ask","ts_ms":1781237198112}}

{"type":"orderbook_delta","sid":1,"seq":2732,"msg":{"market_ticker":"KXBTCPERP1","price":"6.3854","delta":"-1.00","side":"bid","ts_ms":1781237198127}}

{"type":"trade","sid":2,"seq":1953,"msg":{"trade_id":"8066fb9d-7780-4fbf-a0bf-fb9393380947","market_ticker":"KXBTCPERP1","price":"6.3854","count":"1.00","taker_side":"ask","ts_ms":1781237198127}}

{"type":"orderbook_delta","sid":1,"seq":2733,"msg":{"market_ticker":"KXBTCPERP1","price":"6.3854","delta":"-1.00","side":"bid","ts_ms":1781237198194}}

{"type":"trade","sid":2,"seq":1954,"msg":{"trade_id":"63db21a5-4488-6ee3-3dd9-d2ca79ef16cf","market_ticker":"KXBTCPERP1","price":"6.3854","count":"1.00","taker_side":"ask","ts_ms":1781237198194}}

{"type":"orderbook_delta","sid":1,"seq":2734,"msg":{"market_ticker":"KXBTCPERP1","price":"6.3854","delta":"-1.00","side":"bid","ts_ms":1781237198251}}

{"type":"trade","sid":2,"seq":1955,"msg":{"trade_id":"c96b8a2f-1124-46db-e92d-1eb723db7763","market_ticker":"KXBTCPERP1","price":"6.3854","count":"1.00","taker_side":"ask","ts_ms":1781237198251}}

{"type":"trade","sid":2,"seq":1956,"msg":{"trade_id":"11b1309d-6944-66a7-4964-445bf5e29983","market_ticker":"KXBTCPERP1","price":"6.3854","count":"1.00","taker_side":"ask","ts_ms":1781237198451}}

{"type":"orderbook_delta","sid":1,"seq":2735,"msg":{"market_ticker":"KXBTCPERP1","price":"6.3854","delta":"-1.00","side":"bid","ts_ms":1781237198451}}

{"type":"ticker","sid":3,"msg":{"market_ticker":"KXBTCPERP1","price":"6.3329","bid":"6.3329","ask":"6.3416","bid_size_fp":"343.00","ask_size_fp":"658.00","last_trade_size_fp":"0.00","volume":"4179467045.00","volume_notional_value_dollars":"3245141294.960300","volume_24h":"1877080.00","volume_24h_notional_value_dollars":"11687174.591200","open_interest":"2332769.00","open_interest_notional_value_dollars":"14773192.800100","reference_price":{"price":"6.3379","ts_ms":1781237198000},"settlement_mark_price":{"price":"6.3515","ts_ms":1781237193034},"liquidation_mark_price":{"price":"6.3779","ts_ms":1781237198399},"funding_rate":{"rate":0,"next_funding_time_ms":1781265600000,"ts_ms":1781237193034},"ts_ms":1781217877584}}

{"type":"orderbook_delta","sid":1,"seq":2736,"msg":{"market_ticker":"KXBTCPERP1","price":"6.3854","delta":"-1.00","side":"bid","ts_ms":1781237198544}}

{"type":"trade","sid":2,"seq":1957,"msg":{"trade_id":"dd60ef03-1cec-4d9b-9310-d9f74a5e242f","market_ticker":"KXBTCPERP1","price":"6.3854","count":"1.00","taker_side":"ask","ts_ms":1781237198544}}

{"type":"orderbook_delta","sid":1,"seq":2737,"msg":{"market_ticker":"KXBTCPERP1","price":"6.3854","delta":"-1.00","side":"bid","ts_ms":1781237198594}}

{"type":"trade","sid":2,"seq":1958,"msg":{"trade_id":"360c7959-06e8-5883-faf3-c4928c8de113","market_ticker":"KXBTCPERP1","price":"6.3854","count":"1.00","taker_side":"ask","ts_ms":1781237198594}}

{"type":"orderbook_delta","sid":1,"seq":2738,"msg":{"market_ticker":"KXBTCPERP1","price":"7.6637","delta":"1.00","side":"ask","ts_ms":1781237198708}}

{"type":"orderbook_delta","sid":1,"seq":2739,"msg":{"market_ticker":"KXBTCPERP1","price":"6.3854","delta":"-1.00","side":"bid","ts_ms":1781237198715}}

{"type":"trade","sid":2,"seq":1959,"msg":{"trade_id":"f212a186-57e0-4b6f-454d-9ba12842125b","market_ticker":"KXBTCPERP1","price":"6.3854","count":"1.00","taker_side":"ask","ts_ms":1781237198715}}

{"type":"orderbook_delta","sid":1,"seq":2740,"msg":{"market_ticker":"KXBTCPERP1","price":"6.3854","delta":"-1.00","side":"bid","ts_ms":1781237198715}}

{"type":"trade","sid":2,"seq":1960,"msg":{"trade_id":"397f7d14-8568-7413-fdc8-87193485d037","market_ticker":"KXBTCPERP1","price":"6.3854","count":"1.00","taker_side":"ask","ts_ms":1781237198715}}

{"type":"orderbook_delta","sid":1,"seq":2741,"msg":{"market_ticker":"KXBTCPERP1","price":"6.4905","delta":"1.00","side":"ask","ts_ms":1781237198732}}

{"type":"trade","sid":2,"seq":1961,"msg":{"trade_id":"7a42282c-4280-7fcf-a3e3-0d0f3e9a38cb","market_ticker":"KXBTCPERP1","price":"6.3854","count":"1.00","taker_side":"ask","ts_ms":1781237198883}}

{"type":"orderbook_delta","sid":1,"seq":2742,"msg":{"market_ticker":"KXBTCPERP1","price":"6.3854","delta":"-1.00","side":"bid","ts_ms":1781237198883}}

{"type":"orderbook_delta","sid":1,"seq":2743,"msg":{"market_ticker":"KXBTCPERP1","price":"6.3854","delta":"-1.00","side":"bid","ts_ms":1781237198939}}

{"type":"trade","sid":2,"seq":1962,"msg":{"trade_id":"854e3cff-47a4-7333-3f77-8c1a307cefa7","market_ticker":"KXBTCPERP1","price":"6.3854","count":"1.00","taker_side":"ask","ts_ms":1781237198939}}

{"type":"trade","sid":2,"seq":1963,"msg":{"trade_id":"b09c481e-431c-7d3f-03fa-eafe74d04e8b","market_ticker":"KXBTCPERP1","price":"6.3854","count":"1.00","taker_side":"ask","ts_ms":1781237198993}}

{"type":"orderbook_delta","sid":1,"seq":2744,"msg":{"market_ticker":"KXBTCPERP1","price":"6.3854","delta":"-1.00","side":"bid","ts_ms":1781237198993}}

{"type":"orderbook_delta","sid":1,"seq":2745,"msg":{"market_ticker":"KXBTCPERP1","price":"6.4590","delta":"1.00","side":"ask","ts_ms":1781237199059}}

{"type":"orderbook_delta","sid":1,"seq":2746,"msg":{"market_ticker":"KXBTCPERP1","price":"6.3436","delta":"-1.00","side":"bid","ts_ms":1781237199077}}

{"type":"trade","sid":2,"seq":1964,"msg":{"trade_id":"5bf1ce87-f8e3-6132-c687-163bae702753","market_ticker":"KXBTCPERP1","price":"6.3872","count":"1.00","taker_side":"bid","ts_ms":1781237199124}}

{"type":"orderbook_delta","sid":1,"seq":2747,"msg":{"market_ticker":"KXBTCPERP1","price":"6.3872","delta":"-1.00","side":"ask","ts_ms":1781237199124}}

{"type":"orderbook_delta","sid":1,"seq":2748,"msg":{"market_ticker":"KXBTCPERP1","price":"6.3873","delta":"-1.00","side":"ask","ts_ms":1781237199232}}

{"type":"trade","sid":2,"seq":1965,"msg":{"trade_id":"f4bf5d8a-c927-4391-668d-fabbd73e0015","market_ticker":"KXBTCPERP1","price":"6.3873","count":"1.00","taker_side":"bid","ts_ms":1781237199232}}

{"type":"orderbook_delta","sid":1,"seq":2749,"msg":{"market_ticker":"KXBTCPERP1","price":"6.2231","delta":"-1.00","side":"bid","ts_ms":1781237199266}}

{"type":"orderbook_delta","sid":1,"seq":2750,"msg":{"market_ticker":"KXBTCPERP1","price":"6.3854","delta":"-1.00","side":"bid","ts_ms":1781237199294}}

{"type":"trade","sid":2,"seq":1966,"msg":{"trade_id":"708e465a-c0ac-4593-2835-472c812b732f","market_ticker":"KXBTCPERP1","price":"6.3854","count":"1.00","taker_side":"ask","ts_ms":1781237199294}}

{"type":"orderbook_delta","sid":1,"seq":2751,"msg":{"market_ticker":"KXBTCPERP1","price":"6.3838","delta":"-11.00","side":"bid","ts_ms":1781237199445}}

{"type":"orderbook_delta","sid":1,"seq":2752,"msg":{"market_ticker":"KXBTCPERP1","price":"6.3855","delta":"11.00","side":"bid","ts_ms":1781237199445}}

{"type":"orderbook_delta","sid":1,"seq":2753,"msg":{"market_ticker":"KXBTCPERP1","price":"6.3549","delta":"1.00","side":"bid","ts_ms":1781237199474}}

{"type":"ticker","sid":3,"msg":{"market_ticker":"KXBTCPERP1","price":"6.3329","bid":"6.3329","ask":"6.3416","bid_size_fp":"343.00","ask_size_fp":"658.00","last_trade_size_fp":"0.00","volume":"4179467045.00","volume_notional_value_dollars":"3245141294.960300","volume_24h":"1877080.00","volume_24h_notional_value_dollars":"11687174.591200","open_interest":"2332769.00","open_interest_notional_value_dollars":"14773192.800100","reference_price":{"price":"6.3375","ts_ms":1781237199000},"settlement_mark_price":{"price":"6.3515","ts_ms":1781237198034},"liquidation_mark_price":{"price":"6.3776","ts_ms":1781237199399},"funding_rate":{"rate":0,"next_funding_time_ms":1781265600000,"ts_ms":1781237198034},"ts_ms":1781217877584}}

{"type":"orderbook_delta","sid":1,"seq":2754,"msg":{"market_ticker":"KXBTCPERP1","price":"6.3837","delta":"-10.00","side":"bid","ts_ms":1781237199545}}

{"type":"orderbook_delta","sid":1,"seq":2755,"msg":{"market_ticker":"KXBTCPERP1","price":"6.3854","delta":"10.00","side":"bid","ts_ms":1781237199545}}

{"type":"orderbook_delta","sid":1,"seq":2756,"msg":{"market_ticker":"KXBTCPERP1","price":"6.3886","delta":"-1.00","side":"ask","ts_ms":1781237199610}}

{"type":"trade","sid":2,"seq":1967,"msg":{"trade_id":"3452c15d-f97c-7af1-2dea-b98fbc038365","market_ticker":"KXBTCPERP1","price":"6.3886","count":"1.00","taker_side":"bid","ts_ms":1781237199610}}

{"type":"orderbook_delta","sid":1,"seq":2757,"msg":{"market_ticker":"KXBTCPERP1","price":"6.3886","delta":"-9.00","side":"ask","ts_ms":1781237199646}}

{"type":"orderbook_delta","sid":1,"seq":2758,"msg":{"market_ticker":"KXBTCPERP1","price":"6.3904","delta":"9.00","side":"ask","ts_ms":1781237199646}}

{"type":"orderbook_delta","sid":1,"seq":2759,"msg":{"market_ticker":"KXBTCPERP1","price":"6.4687","delta":"-1.00","side":"ask","ts_ms":1781237199668}}

{"type":"orderbook_delta","sid":1,"seq":2760,"msg":{"market_ticker":"KXBTCPERP1","price":"6.3887","delta":"-10.00","side":"ask","ts_ms":1781237199746}}

{"type":"orderbook_delta","sid":1,"seq":2761,"msg":{"market_ticker":"KXBTCPERP1","price":"6.3905","delta":"10.00","side":"ask","ts_ms":1781237199746}}

{"type":"orderbook_delta","sid":1,"seq":2762,"msg":{"market_ticker":"KXBTCPERP1","price":"6.4535","delta":"1.00","side":"ask","ts_ms":1781237199872}}

{"type":"orderbook_delta","sid":1,"seq":2763,"msg":{"market_ticker":"KXBTCPERP1","price":"6.3923","delta":"-132.00","side":"ask","ts_ms":1781237199948}}

{"type":"orderbook_delta","sid":1,"seq":2764,"msg":{"market_ticker":"KXBTCPERP1","price":"6.3958","delta":"132.00","side":"ask","ts_ms":1781237199948}}

{"type":"orderbook_delta","sid":1,"seq":2765,"msg":{"market_ticker":"KXBTCPERP1","price":"6.1839","delta":"1.00","side":"bid","ts_ms":1781237200045}}

{"type":"orderbook_delta","sid":1,"seq":2766,"msg":{"market_ticker":"KXBTCPERP1","price":"6.2482","delta":"1.00","side":"bid","ts_ms":1781237200082}}

{"type":"orderbook_delta","sid":1,"seq":2767,"msg":{"market_ticker":"KXBTCPERP1","price":"6.4097","delta":"1.00","side":"ask","ts_ms":1781237200183}}

{"type":"orderbook_delta","sid":1,"seq":2768,"msg":{"market_ticker":"KXBTCPERP1","price":"6.3855","delta":"-1.00","side":"bid","ts_ms":1781237200259}}

{"type":"trade","sid":2,"seq":1968,"msg":{"trade_id":"b5d0d6a6-47b6-5c94-f0ec-d6feba746717","market_ticker":"KXBTCPERP1","price":"6.3855","count":"1.00","taker_side":"ask","ts_ms":1781237200259}}

{"type":"orderbook_delta","sid":1,"seq":2769,"msg":{"market_ticker":"KXBTCPERP1","price":"6.2403","delta":"1.00","side":"bid","ts_ms":1781237200316}}

{"type":"orderbook_delta","sid":1,"seq":2770,"msg":{"market_ticker":"KXBTCPERP1","price":"6.3855","delta":"-1.00","side":"bid","ts_ms":1781237200347}}

{"type":"trade","sid":2,"seq":1969,"msg":{"trade_id":"1c3206e8-8982-7d5c-fd37-d404db61b9f7","market_ticker":"KXBTCPERP1","price":"6.3855","count":"1.00","taker_side":"ask","ts_ms":1781237200347}}

{"type":"ticker","sid":3,"msg":{"market_ticker":"KXBTCPERP1","price":"6.3329","bid":"6.3329","ask":"6.3416","bid_size_fp":"343.00","ask_size_fp":"658.00","last_trade_size_fp":"0.00","volume":"4179467045.00","volume_notional_value_dollars":"3245141294.960300","volume_24h":"1877080.00","volume_24h_notional_value_dollars":"11687174.591200","open_interest":"2332769.00","open_interest_notional_value_dollars":"14773192.800100","reference_price":{"price":"6.3374","ts_ms":1781237200000},"settlement_mark_price":{"price":"6.3515","ts_ms":1781237198034},"liquidation_mark_price":{"price":"6.3775","ts_ms":1781237200398},"funding_rate":{"rate":0,"next_funding_time_ms":1781265600000,"ts_ms":1781237198034},"ts_ms":1781217877584}}

{"type":"orderbook_delta","sid":1,"seq":2771,"msg":{"market_ticker":"KXBTCPERP1","price":"6.3855","delta":"-1.00","side":"bid","ts_ms":1781237200501}}

{"type":"trade","sid":2,"seq":1970,"msg":{"trade_id":"91d861dd-6a06-7bb8-f57f-f641bc32f1f3","market_ticker":"KXBTCPERP1","price":"6.3855","count":"1.00","taker_side":"ask","ts_ms":1781237200501}}

{"type":"orderbook_delta","sid":1,"seq":2772,"msg":{"market_ticker":"KXBTCPERP1","price":"6.4545","delta":"1.00","side":"ask","ts_ms":1781237200640}}

{"type":"orderbook_delta","sid":1,"seq":2773,"msg":{"market_ticker":"KXBTCPERP1","price":"6.3855","delta":"-8.00","side":"bid","ts_ms":1781237200651}}

{"type":"orderbook_delta","sid":1,"seq":2774,"msg":{"market_ticker":"KXBTCPERP1","price":"6.3856","delta":"11.00","side":"bid","ts_ms":1781237200651}}

{"type":"orderbook_delta","sid":1,"seq":2775,"msg":{"market_ticker":"KXBTCPERP1","price":"6.3809","delta":"1.00","side":"bid","ts_ms":1781237200724}}

{"type":"orderbook_delta","sid":1,"seq":2776,"msg":{"market_ticker":"KXBTCPERP1","price":"6.2948","delta":"1.00","side":"bid","ts_ms":1781237200837}}

{"type":"trade","sid":2,"seq":1971,"msg":{"trade_id":"37303b50-e63e-7138-079d-86c1fcd378ef","market_ticker":"KXBTCPERP1","price":"6.3856","count":"1.00","taker_side":"ask","ts_ms":1781237200885}}

{"type":"orderbook_delta","sid":1,"seq":2777,"msg":{"market_ticker":"KXBTCPERP1","price":"6.3856","delta":"-1.00","side":"bid","ts_ms":1781237200885}}

{"type":"orderbook_delta","sid":1,"seq":2778,"msg":{"market_ticker":"KXBTCPERP1","price":"6.3856","delta":"-1.00","side":"bid","ts_ms":1781237200911}}

{"type":"trade","sid":2,"seq":1972,"msg":{"trade_id":"f0d9ceba-510e-5450-ee77-3c91670f080f","market_ticker":"KXBTCPERP1","price":"6.3856","count":"1.00","taker_side":"ask","ts_ms":1781237200911}}

{"type":"orderbook_delta","sid":1,"seq":2779,"msg":{"market_ticker":"KXBTCPERP1","price":"6.3856","delta":"-1.00","side":"bid","ts_ms":1781237200959}}

{"type":"trade","sid":2,"seq":1973,"msg":{"trade_id":"b154d7f9-4302-4b58-09f1-08af55221d57","market_ticker":"KXBTCPERP1","price":"6.3856","count":"1.00","taker_side":"ask","ts_ms":1781237200959}}

{"type":"orderbook_delta","sid":1,"seq":2780,"msg":{"market_ticker":"KXBTCPERP1","price":"6.3856","delta":"3.00","side":"bid","ts_ms":1781237201053}}

{"type":"orderbook_delta","sid":1,"seq":2781,"msg":{"market_ticker":"KXBTCPERP1","price":"7.6637","delta":"1.00","side":"ask","ts_ms":1781237201089}}

{"type":"orderbook_delta","sid":1,"seq":2782,"msg":{"market_ticker":"KXBTCPERP1","price":"6.3861","delta":"1.00","side":"ask","ts_ms":1781237201168}}

{"type":"orderbook_delta","sid":1,"seq":2783,"msg":{"market_ticker":"KXBTCPERP1","price":"6.4101","delta":"1.00","side":"ask","ts_ms":1781237201243}}

{"type":"orderbook_delta","sid":1,"seq":2784,"msg":{"market_ticker":"KXBTCPERP1","price":"6.4119","delta":"1.00","side":"ask","ts_ms":1781237201353}}

{"type":"ticker","sid":3,"msg":{"market_ticker":"KXBTCPERP1","price":"6.3329","bid":"6.3329","ask":"6.3416","bid_size_fp":"343.00","ask_size_fp":"658.00","last_trade_size_fp":"0.00","volume":"4179467045.00","volume_notional_value_dollars":"3245141294.960300","volume_24h":"1877080.00","volume_24h_notional_value_dollars":"11687174.591200","open_interest":"2332769.00","open_interest_notional_value_dollars":"14773192.800100","reference_price":{"price":"6.3373","ts_ms":1781237201000},"settlement_mark_price":{"price":"6.3515","ts_ms":1781237198034},"liquidation_mark_price":{"price":"6.3774","ts_ms":1781237201399},"funding_rate":{"rate":0,"next_funding_time_ms":1781265600000,"ts_ms":1781237198034},"ts_ms":1781217877584}}

{"type":"orderbook_delta","sid":1,"seq":2785,"msg":{"market_ticker":"KXBTCPERP1","price":"6.3856","delta":"-1.00","side":"bid","ts_ms":1781237201511}}

{"type":"trade","sid":2,"seq":1974,"msg":{"trade_id":"f09db2ba-03c6-5e84-72d9-0c22c8912d23","market_ticker":"KXBTCPERP1","price":"6.3856","count":"1.00","taker_side":"ask","ts_ms":1781237201511}}

{"type":"orderbook_delta","sid":1,"seq":2786,"msg":{"market_ticker":"KXBTCPERP1","price":"6.1887","delta":"1.00","side":"bid","ts_ms":1781237201519}}

{"type":"orderbook_delta","sid":1,"seq":2787,"msg":{"market_ticker":"KXBTCPERP1","price":"6.3856","delta":"-10.00","side":"bid","ts_ms":1781237201556}}

{"type":"orderbook_delta","sid":1,"seq":2788,"msg":{"market_ticker":"KXBTCPERP1","price":"6.3835","delta":"10.00","side":"bid","ts_ms":1781237201556}}

{"type":"orderbook_delta","sid":1,"seq":2789,"msg":{"market_ticker":"KXBTCPERP1","price":"6.3854","delta":"-10.00","side":"bid","ts_ms":1781237201656}}

{"type":"orderbook_delta","sid":1,"seq":2790,"msg":{"market_ticker":"KXBTCPERP1","price":"6.3834","delta":"10.00","side":"bid","ts_ms":1781237201656}}

{"type":"orderbook_delta","sid":1,"seq":2791,"msg":{"market_ticker":"KXBTCPERP1","price":"6.3854","delta":"-1.00","side":"bid","ts_ms":1781237201721}}

{"type":"trade","sid":2,"seq":1975,"msg":{"trade_id":"903d6095-5618-5bab-9686-e9397960a05b","market_ticker":"KXBTCPERP1","price":"6.3854","count":"1.00","taker_side":"ask","ts_ms":1781237201721}}

{"type":"orderbook_delta","sid":1,"seq":2792,"msg":{"market_ticker":"KXBTCPERP1","price":"6.3904","delta":"-9.00","side":"ask","ts_ms":1781237201757}}

{"type":"orderbook_delta","sid":1,"seq":2793,"msg":{"market_ticker":"KXBTCPERP1","price":"6.3884","delta":"10.00","side":"ask","ts_ms":1781237201757}}

{"type":"orderbook_delta","sid":1,"seq":2794,"msg":{"market_ticker":"KXBTCPERP1","price":"6.2709","delta":"1.00","side":"bid","ts_ms":1781237201761}}

{"type":"orderbook_delta","sid":1,"seq":2795,"msg":{"market_ticker":"KXBTCPERP1","price":"6.3854","delta":"-1.00","side":"bid","ts_ms":1781237201836}}

{"type":"trade","sid":2,"seq":1976,"msg":{"trade_id":"b63e26bb-939c-4203-4451-3d0c4a666033","market_ticker":"KXBTCPERP1","price":"6.3854","count":"1.00","taker_side":"ask","ts_ms":1781237201836}}

{"type":"orderbook_delta","sid":1,"seq":2796,"msg":{"market_ticker":"KXBTCPERP1","price":"6.3905","delta":"-10.00","side":"ask","ts_ms":1781237201857}}

{"type":"orderbook_delta","sid":1,"seq":2797,"msg":{"market_ticker":"KXBTCPERP1","price":"6.3885","delta":"10.00","side":"ask","ts_ms":1781237201857}}

{"type":"orderbook_delta","sid":1,"seq":2798,"msg":{"market_ticker":"KXBTCPERP1","price":"6.2404","delta":"1.00","side":"bid","ts_ms":1781237202008}}

{"type":"orderbook_delta","sid":1,"seq":2799,"msg":{"market_ticker":"KXBTCPERP1","price":"6.2104","delta":"1.00","side":"bid","ts_ms":1781237202064}}

{"type":"orderbook_delta","sid":1,"seq":2800,"msg":{"market_ticker":"KXBTCPERP1","price":"6.3228","delta":"1.00","side":"bid","ts_ms":1781237202067}}

{"type":"orderbook_delta","sid":1,"seq":2801,"msg":{"market_ticker":"KXBTCPERP1","price":"6.2915","delta":"-1.00","side":"bid","ts_ms":1781237202085}}

{"type":"trade","sid":2,"seq":1977,"msg":{"trade_id":"579c992f-4a94-757b-dc6c-fbe116e5d76b","market_ticker":"KXBTCPERP1","price":"6.3854","count":"1.00","taker_side":"ask","ts_ms":1781237202105}}

{"type":"orderbook_delta","sid":1,"seq":2802,"msg":{"market_ticker":"KXBTCPERP1","price":"6.3854","delta":"-1.00","side":"bid","ts_ms":1781237202105}}

{"type":"orderbook_delta","sid":1,"seq":2803,"msg":{"market_ticker":"KXBTCPERP1","price":"6.3854","delta":"-1.00","side":"bid","ts_ms":1781237202168}}

{"type":"trade","sid":2,"seq":1978,"msg":{"trade_id":"e0e5f22f-8560-7ecf-eefe-400da265865f","market_ticker":"KXBTCPERP1","price":"6.3854","count":"1.00","taker_side":"ask","ts_ms":1781237202168}}

{"type":"orderbook_delta","sid":1,"seq":2804,"msg":{"market_ticker":"KXBTCPERP1","price":"6.2525","delta":"1.00","side":"bid","ts_ms":1781237202251}}

{"type":"orderbook_delta","sid":1,"seq":2805,"msg":{"market_ticker":"KXBTCPERP1","price":"6.3854","delta":"-610.00","side":"bid","ts_ms":1781237202398}}

{"type":"orderbook_delta","sid":1,"seq":2806,"msg":{"market_ticker":"KXBTCPERP1","price":"6.3676","delta":"612.00","side":"bid","ts_ms":1781237202398}}

{"type":"orderbook_delta","sid":1,"seq":2807,"msg":{"market_ticker":"KXBTCPERP1","price":"6.3834","delta":"-783.00","side":"bid","ts_ms":1781237202402}}

{"type":"orderbook_delta","sid":1,"seq":2808,"msg":{"market_ticker":"KXBTCPERP1","price":"6.3634","delta":"785.00","side":"bid","ts_ms":1781237202402}}

{"type":"orderbook_delta","sid":1,"seq":2809,"msg":{"market_ticker":"KXBTCPERP1","price":"6.3814","delta":"-784.00","side":"bid","ts_ms":1781237202405}}

{"type":"orderbook_delta","sid":1,"seq":2810,"msg":{"market_ticker":"KXBTCPERP1","price":"6.3592","delta":"787.00","side":"bid","ts_ms":1781237202405}}

{"type":"orderbook_delta","sid":1,"seq":2811,"msg":{"market_ticker":"KXBTCPERP1","price":"6.3794","delta":"-783.00","side":"bid","ts_ms":1781237202408}}

{"type":"orderbook_delta","sid":1,"seq":2812,"msg":{"market_ticker":"KXBTCPERP1","price":"6.3550","delta":"786.00","side":"bid","ts_ms":1781237202408}}

{"type":"orderbook_delta","sid":1,"seq":2813,"msg":{"market_ticker":"KXBTCPERP1","price":"6.3774","delta":"-785.00","side":"bid","ts_ms":1781237202411}}

{"type":"orderbook_delta","sid":1,"seq":2814,"msg":{"market_ticker":"KXBTCPERP1","price":"6.3508","delta":"788.00","side":"bid","ts_ms":1781237202411}}

{"type":"orderbook_delta","sid":1,"seq":2815,"msg":{"market_ticker":"KXBTCPERP1","price":"6.3754","delta":"-784.00","side":"bid","ts_ms":1781237202415}}

{"type":"orderbook_delta","sid":1,"seq":2816,"msg":{"market_ticker":"KXBTCPERP1","price":"6.3466","delta":"787.00","side":"bid","ts_ms":1781237202415}}

{"type":"orderbook_delta","sid":1,"seq":2817,"msg":{"market_ticker":"KXBTCPERP1","price":"6.3734","delta":"-785.00","side":"bid","ts_ms":1781237202418}}

{"type":"orderbook_delta","sid":1,"seq":2818,"msg":{"market_ticker":"KXBTCPERP1","price":"6.3424","delta":"789.00","side":"bid","ts_ms":1781237202418}}

{"type":"orderbook_delta","sid":1,"seq":2819,"msg":{"market_ticker":"KXBTCPERP1","price":"6.3714","delta":"-785.00","side":"bid","ts_ms":1781237202421}}

{"type":"orderbook_delta","sid":1,"seq":2820,"msg":{"market_ticker":"KXBTCPERP1","price":"6.3382","delta":"789.00","side":"bid","ts_ms":1781237202421}}

{"type":"orderbook_delta","sid":1,"seq":2821,"msg":{"market_ticker":"KXBTCPERP1","price":"6.3694","delta":"-786.00","side":"bid","ts_ms":1781237202424}}

{"type":"orderbook_delta","sid":1,"seq":2822,"msg":{"market_ticker":"KXBTCPERP1","price":"6.3340","delta":"790.00","side":"bid","ts_ms":1781237202424}}

{"type":"orderbook_delta","sid":1,"seq":2823,"msg":{"market_ticker":"KXBTCPERP1","price":"6.3674","delta":"-786.00","side":"bid","ts_ms":1781237202427}}

{"type":"orderbook_delta","sid":1,"seq":2824,"msg":{"market_ticker":"KXBTCPERP1","price":"6.3298","delta":"790.00","side":"bid","ts_ms":1781237202427}}

{"type":"orderbook_delta","sid":1,"seq":2825,"msg":{"market_ticker":"KXBTCPERP1","price":"6.4006","delta":"-291.00","side":"ask","ts_ms":1781237202431}}

{"type":"orderbook_delta","sid":1,"seq":2826,"msg":{"market_ticker":"KXBTCPERP1","price":"6.3993","delta":"291.00","side":"ask","ts_ms":1781237202431}}

{"type":"orderbook_delta","sid":1,"seq":2827,"msg":{"market_ticker":"KXBTCPERP1","price":"6.3270","delta":"1.00","side":"bid","ts_ms":1781237202432}}

{"type":"orderbook_delta","sid":1,"seq":2828,"msg":{"market_ticker":"KXBTCPERP1","price":"6.4026","delta":"-781.00","side":"ask","ts_ms":1781237202434}}

{"type":"orderbook_delta","sid":1,"seq":2829,"msg":{"market_ticker":"KXBTCPERP1","price":"6.4035","delta":"781.00","side":"ask","ts_ms":1781237202434}}

{"type":"orderbook_delta","sid":1,"seq":2830,"msg":{"market_ticker":"KXBTCPERP1","price":"6.4046","delta":"-781.00","side":"ask","ts_ms":1781237202438}}

{"type":"orderbook_delta","sid":1,"seq":2831,"msg":{"market_ticker":"KXBTCPERP1","price":"6.4077","delta":"781.00","side":"ask","ts_ms":1781237202438}}

{"type":"orderbook_delta","sid":1,"seq":2832,"msg":{"market_ticker":"KXBTCPERP1","price":"6.4066","delta":"-781.00","side":"ask","ts_ms":1781237202441}}

{"type":"orderbook_delta","sid":1,"seq":2833,"msg":{"market_ticker":"KXBTCPERP1","price":"6.4119","delta":"780.00","side":"ask","ts_ms":1781237202441}}

{"type":"orderbook_delta","sid":1,"seq":2834,"msg":{"market_ticker":"KXBTCPERP1","price":"6.4086","delta":"-781.00","side":"ask","ts_ms":1781237202444}}

{"type":"orderbook_delta","sid":1,"seq":2835,"msg":{"market_ticker":"KXBTCPERP1","price":"6.4161","delta":"780.00","side":"ask","ts_ms":1781237202444}}

{"type":"orderbook_delta","sid":1,"seq":2836,"msg":{"market_ticker":"KXBTCPERP1","price":"6.4106","delta":"-780.00","side":"ask","ts_ms":1781237202448}}

{"type":"orderbook_delta","sid":1,"seq":2837,"msg":{"market_ticker":"KXBTCPERP1","price":"6.4203","delta":"779.00","side":"ask","ts_ms":1781237202448}}

{"type":"orderbook_delta","sid":1,"seq":2838,"msg":{"market_ticker":"KXBTCPERP1","price":"6.4126","delta":"-780.00","side":"ask","ts_ms":1781237202451}}

{"type":"orderbook_delta","sid":1,"seq":2839,"msg":{"market_ticker":"KXBTCPERP1","price":"6.4245","delta":"779.00","side":"ask","ts_ms":1781237202451}}

{"type":"orderbook_delta","sid":1,"seq":2840,"msg":{"market_ticker":"KXBTCPERP1","price":"6.4146","delta":"-780.00","side":"ask","ts_ms":1781237202455}}

{"type":"orderbook_delta","sid":1,"seq":2841,"msg":{"market_ticker":"KXBTCPERP1","price":"6.4287","delta":"778.00","side":"ask","ts_ms":1781237202455}}

{"type":"orderbook_delta","sid":1,"seq":2842,"msg":{"market_ticker":"KXBTCPERP1","price":"6.4166","delta":"-780.00","side":"ask","ts_ms":1781237202459}}

{"type":"orderbook_delta","sid":1,"seq":2843,"msg":{"market_ticker":"KXBTCPERP1","price":"6.4329","delta":"778.00","side":"ask","ts_ms":1781237202459}}

{"type":"orderbook_delta","sid":1,"seq":2844,"msg":{"market_ticker":"KXBTCPERP1","price":"6.4186","delta":"-779.00","side":"ask","ts_ms":1781237202463}}

{"type":"orderbook_delta","sid":1,"seq":2845,"msg":{"market_ticker":"KXBTCPERP1","price":"6.4371","delta":"777.00","side":"ask","ts_ms":1781237202463}}

{"type":"orderbook_delta","sid":1,"seq":2846,"msg":{"market_ticker":"KXBTCPERP1","price":"6.3861","delta":"-1.00","side":"ask","ts_ms":1781237202487}}

{"type":"trade","sid":2,"seq":1979,"msg":{"trade_id":"5937eb73-c446-49e4-3493-fe08ca50d813","market_ticker":"KXBTCPERP1","price":"6.3861","count":"1.00","taker_side":"bid","ts_ms":1781237202487}}

{"type":"ticker","sid":3,"msg":{"market_ticker":"KXBTCPERP1","price":"6.3329","bid":"6.3329","ask":"6.3416","bid_size_fp":"343.00","ask_size_fp":"658.00","last_trade_size_fp":"0.00","volume":"4179467045.00","volume_notional_value_dollars":"3245141294.960300","volume_24h":"1877080.00","volume_24h_notional_value_dollars":"11687174.591200","open_interest":"2332769.00","open_interest_notional_value_dollars":"14773192.800100","reference_price":{"price":"6.3374","ts_ms":1781237202000},"settlement_mark_price":{"price":"6.3515","ts_ms":1781237198034},"liquidation_mark_price":{"price":"6.3776","ts_ms":1781237202398},"funding_rate":{"rate":0,"next_funding_time_ms":1781265600000,"ts_ms":1781237198034},"ts_ms":1781217877584}}

{"type":"orderbook_delta","sid":1,"seq":2847,"msg":{"market_ticker":"KXBTCPERP1","price":"6.4654","delta":"1.00","side":"ask","ts_ms":1781237202526}}

{"type":"orderbook_delta","sid":1,"seq":2848,"msg":{"market_ticker":"KXBTCPERP1","price":"6.3835","delta":"-10.00","side":"bid","ts_ms":1781237202562}}

{"type":"orderbook_delta","sid":1,"seq":2849,"msg":{"market_ticker":"KXBTCPERP1","price":"6.3825","delta":"11.00","side":"bid","ts_ms":1781237202562}}

{"type":"orderbook_delta","sid":1,"seq":2850,"msg":{"market_ticker":"KXBTCPERP1","price":"7.6637","delta":"-1.00","side":"ask","ts_ms":1781237202615}}

{"type":"orderbook_delta","sid":1,"seq":2851,"msg":{"market_ticker":"KXBTCPERP1","price":"6.3884","delta":"-1.00","side":"ask","ts_ms":1781237202848}}

{"type":"trade","sid":2,"seq":1980,"msg":{"trade_id":"b52cd41c-e760-43fd-6e08-1c3a4d3bfe21","market_ticker":"KXBTCPERP1","price":"6.3884","count":"1.00","taker_side":"bid","ts_ms":1781237202848}}

{"type":"orderbook_delta","sid":1,"seq":2852,"msg":{"market_ticker":"KXBTCPERP1","price":"6.3834","delta":"-10.00","side":"bid","ts_ms":1781237202863}}

{"type":"orderbook_delta","sid":1,"seq":2853,"msg":{"market_ticker":"KXBTCPERP1","price":"6.3824","delta":"10.00","side":"bid","ts_ms":1781237202863}}

{"type":"orderbook_delta","sid":1,"seq":2854,"msg":{"market_ticker":"KXBTCPERP1","price":"6.3825","delta":"-1.00","side":"bid","ts_ms":1781237202998}}

{"type":"trade","sid":2,"seq":1981,"msg":{"trade_id":"242545fb-62c6-6b14-7d6e-cbc9e7fbeeeb","market_ticker":"KXBTCPERP1","price":"6.3825","count":"1.00","taker_side":"ask","ts_ms":1781237202998}}

{"type":"orderbook_delta","sid":1,"seq":2855,"msg":{"market_ticker":"KXBTCPERP1","price":"6.4309","delta":"1.00","side":"ask","ts_ms":1781237203104}}

{"type":"orderbook_delta","sid":1,"seq":2856,"msg":{"market_ticker":"KXBTCPERP1","price":"6.3266","delta":"1.00","side":"bid","ts_ms":1781237203238}}

{"type":"orderbook_delta","sid":1,"seq":2857,"msg":{"market_ticker":"KXBTCPERP1","price":"6.3825","delta":"-1.00","side":"bid","ts_ms":1781237203269}}

{"type":"trade","sid":2,"seq":1982,"msg":{"trade_id":"3ccea5a1-429a-7260-d97f-5cd2e7cf2bfb","market_ticker":"KXBTCPERP1","price":"6.3825","count":"1.00","taker_side":"ask","ts_ms":1781237203269}}

{"type":"orderbook_delta","sid":1,"seq":2858,"msg":{"market_ticker":"KXBTCPERP1","price":"6.2457","delta":"1.00","side":"bid","ts_ms":1781237203403}}

{"type":"orderbook_delta","sid":1,"seq":2859,"msg":{"market_ticker":"KXBTCPERP1","price":"6.3825","delta":"-1.00","side":"bid","ts_ms":1781237203438}}

{"type":"trade","sid":2,"seq":1983,"msg":{"trade_id":"5a48a6b7-cb2e-4abc-2750-ce58bf383c03","market_ticker":"KXBTCPERP1","price":"6.3825","count":"1.00","taker_side":"ask","ts_ms":1781237203438}}

{"type":"orderbook_delta","sid":1,"seq":2860,"msg":{"market_ticker":"KXBTCPERP1","price":"7.6637","delta":"1.00","side":"ask","ts_ms":1781237203449}}

{"type":"ticker","sid":3,"msg":{"market_ticker":"KXBTCPERP1","price":"6.3329","bid":"6.3329","ask":"6.3416","bid_size_fp":"343.00","ask_size_fp":"658.00","last_trade_size_fp":"0.00","volume":"4179467045.00","volume_notional_value_dollars":"3245141294.960300","volume_24h":"1877080.00","volume_24h_notional_value_dollars":"11687174.591200","open_interest":"2332769.00","open_interest_notional_value_dollars":"14773192.800100","reference_price":{"price":"6.3374","ts_ms":1781237203000},"settlement_mark_price":{"price":"6.3515","ts_ms":1781237198034},"liquidation_mark_price":{"price":"6.3777","ts_ms":1781237203398},"funding_rate":{"rate":0,"next_funding_time_ms":1781265600000,"ts_ms":1781237198034},"ts_ms":1781217877584}}

{"type":"orderbook_delta","sid":1,"seq":2861,"msg":{"market_ticker":"KXBTCPERP1","price":"6.3825","delta":"-8.00","side":"bid","ts_ms":1781237203568}}

{"type":"orderbook_delta","sid":1,"seq":2862,"msg":{"market_ticker":"KXBTCPERP1","price":"6.3833","delta":"11.00","side":"bid","ts_ms":1781237203568}}

{"type":"orderbook_delta","sid":1,"seq":2863,"msg":{"market_ticker":"KXBTCPERP1","price":"6.3737","delta":"1.00","side":"bid","ts_ms":1781237203627}}

{"type":"orderbook_delta","sid":1,"seq":2864,"msg":{"market_ticker":"KXBTCPERP1","price":"6.3328","delta":"1.00","side":"bid","ts_ms":1781237203848}}

{"type":"orderbook_delta","sid":1,"seq":2865,"msg":{"market_ticker":"KXBTCPERP1","price":"6.2411","delta":"1.00","side":"bid","ts_ms":1781237203976}}

{"type":"orderbook_delta","sid":1,"seq":2866,"msg":{"market_ticker":"KXBTCPERP1","price":"6.3833","delta":"-11.00","side":"bid","ts_ms":1781237204173}}

{"type":"orderbook_delta","sid":1,"seq":2867,"msg":{"market_ticker":"KXBTCPERP1","price":"6.3845","delta":"11.00","side":"bid","ts_ms":1781237204173}}

{"type":"orderbook_delta","sid":1,"seq":2868,"msg":{"market_ticker":"KXBTCPERP1","price":"6.4773","delta":"1.00","side":"ask","ts_ms":1781237204200}}

{"type":"orderbook_delta","sid":1,"seq":2869,"msg":{"market_ticker":"KXBTCPERP1","price":"6.3037","delta":"1.00","side":"bid","ts_ms":1781237204202}}

{"type":"orderbook_delta","sid":1,"seq":2870,"msg":{"market_ticker":"KXBTCPERP1","price":"6.3824","delta":"-10.00","side":"bid","ts_ms":1781237204273}}

{"type":"orderbook_delta","sid":1,"seq":2871,"msg":{"market_ticker":"KXBTCPERP1","price":"6.3844","delta":"10.00","side":"bid","ts_ms":1781237204273}}

{"type":"orderbook_delta","sid":1,"seq":2872,"msg":{"market_ticker":"KXBTCPERP1","price":"6.3884","delta":"-9.00","side":"ask","ts_ms":1781237204374}}

{"type":"orderbook_delta","sid":1,"seq":2873,"msg":{"market_ticker":"KXBTCPERP1","price":"6.3893","delta":"10.00","side":"ask","ts_ms":1781237204374}}

{"type":"orderbook_delta","sid":1,"seq":2874,"msg":{"market_ticker":"KXBTCPERP1","price":"6.2559","delta":"1.00","side":"bid","ts_ms":1781237204392}}

{"type":"orderbook_delta","sid":1,"seq":2875,"msg":{"market_ticker":"KXBTCPERP1","price":"6.4350","delta":"1.00","side":"ask","ts_ms":1781237204472}}

{"type":"ticker","sid":3,"msg":{"market_ticker":"KXBTCPERP1","price":"6.3329","bid":"6.3329","ask":"6.3416","bid_size_fp":"343.00","ask_size_fp":"658.00","last_trade_size_fp":"0.00","volume":"4179467045.00","volume_notional_value_dollars":"3245141294.960300","volume_24h":"1877080.00","volume_24h_notional_value_dollars":"11687174.591200","open_interest":"2332769.00","open_interest_notional_value_dollars":"14773192.800100","reference_price":{"price":"6.3374","ts_ms":1781237204000},"settlement_mark_price":{"price":"6.3516","ts_ms":1781237203035},"liquidation_mark_price":{"price":"6.3778","ts_ms":1781237204398},"funding_rate":{"rate":0,"next_funding_time_ms":1781265600000,"ts_ms":1781237203035},"ts_ms":1781217877584}}

{"type":"orderbook_delta","sid":1,"seq":2876,"msg":{"market_ticker":"KXBTCPERP1","price":"6.3885","delta":"-10.00","side":"ask","ts_ms":1781237204575}}

{"type":"orderbook_delta","sid":1,"seq":2877,"msg":{"market_ticker":"KXBTCPERP1","price":"6.3894","delta":"10.00","side":"ask","ts_ms":1781237204575}}

{"type":"orderbook_delta","sid":1,"seq":2878,"msg":{"market_ticker":"KXBTCPERP1","price":"6.2263","delta":"1.00","side":"bid","ts_ms":1781237204634}}

{"type":"trade","sid":2,"seq":1984,"msg":{"trade_id":"0618d592-da32-7a34-bade-e3ab889c8c83","market_ticker":"KXBTCPERP1","price":"6.3845","count":"1.00","taker_side":"ask","ts_ms":1781237204697}}

{"type":"orderbook_delta","sid":1,"seq":2879,"msg":{"market_ticker":"KXBTCPERP1","price":"6.3845","delta":"-1.00","side":"bid","ts_ms":1781237204697}}

{"type":"orderbook_delta","sid":1,"seq":2880,"msg":{"market_ticker":"KXBTCPERP1","price":"6.4296","delta":"1.00","side":"ask","ts_ms":1781237204906}}

{"type":"orderbook_delta","sid":1,"seq":2881,"msg":{"market_ticker":"KXBTCPERP1","price":"6.3845","delta":"-1.00","side":"bid","ts_ms":1781237205014}}

{"type":"trade","sid":2,"seq":1985,"msg":{"trade_id":"71e5c042-8962-5b68-ffd5-f0abfbe4aa57","market_ticker":"KXBTCPERP1","price":"6.3845","count":"1.00","taker_side":"ask","ts_ms":1781237205014}}

{"type":"orderbook_delta","sid":1,"seq":2882,"msg":{"market_ticker":"KXBTCPERP1","price":"7.6637","delta":"-1.00","side":"ask","ts_ms":1781237205310}}

{"type":"orderbook_delta","sid":1,"seq":2883,"msg":{"market_ticker":"KXBTCPERP1","price":"7.6637","delta":"-1.00","side":"ask","ts_ms":1781237205329}}

{"type":"orderbook_delta","sid":1,"seq":2884,"msg":{"market_ticker":"KXBTCPERP1","price":"6.3893","delta":"-1.00","side":"ask","ts_ms":1781237205384}}

{"type":"trade","sid":2,"seq":1986,"msg":{"trade_id":"4dba6d1c-e4b8-4f9d-649f-2ba851becd2d","market_ticker":"KXBTCPERP1","price":"6.3893","count":"1.00","taker_side":"bid","ts_ms":1781237205384}}

{"type":"orderbook_delta","sid":1,"seq":2885,"msg":{"market_ticker":"KXBTCPERP1","price":"6.3048","delta":"1.00","side":"bid","ts_ms":1781237205441}}

{"type":"ticker","sid":3,"msg":{"market_ticker":"KXBTCPERP1","price":"6.3329","bid":"6.3329","ask":"6.3416","bid_size_fp":"343.00","ask_size_fp":"658.00","last_trade_size_fp":"0.00","volume":"4179467045.00","volume_notional_value_dollars":"3245141294.960300","volume_24h":"1877080.00","volume_24h_notional_value_dollars":"11687174.591200","open_interest":"2332769.00","open_interest_notional_value_dollars":"14773192.800100","reference_price":{"price":"6.3374","ts_ms":1781237205000},"settlement_mark_price":{"price":"6.3516","ts_ms":1781237203035},"liquidation_mark_price":{"price":"6.3778","ts_ms":1781237205399},"funding_rate":{"rate":0,"next_funding_time_ms":1781265600000,"ts_ms":1781237203035},"ts_ms":1781217877584}}

{"type":"orderbook_delta","sid":1,"seq":2886,"msg":{"market_ticker":"KXBTCPERP1","price":"7.6637","delta":"-1.00","side":"ask","ts_ms":1781237205509}}

{"type":"orderbook_delta","sid":1,"seq":2887,"msg":{"market_ticker":"KXBTCPERP1","price":"6.2287","delta":"1.00","side":"bid","ts_ms":1781237205533}}

{"type":"orderbook_delta","sid":1,"seq":2888,"msg":{"market_ticker":"KXBTCPERP1","price":"6.3845","delta":"-1.00","side":"bid","ts_ms":1781237205740}}

{"type":"trade","sid":2,"seq":1987,"msg":{"trade_id":"7be8cd05-41ae-41ac-923d-19d278d9d9e3","market_ticker":"KXBTCPERP1","price":"6.3845","count":"1.00","taker_side":"ask","ts_ms":1781237205740}}

{"type":"orderbook_delta","sid":1,"seq":2889,"msg":{"market_ticker":"KXBTCPERP1","price":"6.3845","delta":"-1.00","side":"bid","ts_ms":1781237205846}}

{"type":"trade","sid":2,"seq":1988,"msg":{"trade_id":"1c7d4161-1076-5be8-550f-b486ebddffef","market_ticker":"KXBTCPERP1","price":"6.3845","count":"1.00","taker_side":"ask","ts_ms":1781237205846}}

{"type":"orderbook_delta","sid":1,"seq":2890,"msg":{"market_ticker":"KXBTCPERP1","price":"6.3845","delta":"-7.00","side":"bid","ts_ms":1781237205883}}

{"type":"orderbook_delta","sid":1,"seq":2891,"msg":{"market_ticker":"KXBTCPERP1","price":"6.3846","delta":"10.00","side":"bid","ts_ms":1781237205883}}

{"type":"orderbook_delta","sid":1,"seq":2892,"msg":{"market_ticker":"KXBTCPERP1","price":"6.4158","delta":"1.00","side":"ask","ts_ms":1781237205995}}

{"type":"orderbook_delta","sid":1,"seq":2893,"msg":{"market_ticker":"KXBTCPERP1","price":"6.3109","delta":"1.00","side":"bid","ts_ms":1781237206019}}

{"type":"orderbook_delta","sid":1,"seq":2894,"msg":{"market_ticker":"KXBTCPERP1","price":"7.6637","delta":"-1.00","side":"ask","ts_ms":1781237206021}}

{"type":"orderbook_delta","sid":1,"seq":2895,"msg":{"market_ticker":"KXBTCPERP1","price":"6.2474","delta":"1.00","side":"bid","ts_ms":1781237206185}}

{"type":"orderbook_delta","sid":1,"seq":2896,"msg":{"market_ticker":"KXBTCPERP1","price":"6.3893","delta":"-1.00","side":"ask","ts_ms":1781237206354}}

{"type":"trade","sid":2,"seq":1989,"msg":{"trade_id":"37327387-f36c-6701-75af-f05bd34035bd","market_ticker":"KXBTCPERP1","price":"6.3893","count":"1.00","taker_side":"bid","ts_ms":1781237206354}}

{"type":"ticker","sid":3,"msg":{"market_ticker":"KXBTCPERP1","price":"6.3329","bid":"6.3329","ask":"6.3416","bid_size_fp":"343.00","ask_size_fp":"658.00","last_trade_size_fp":"0.00","volume":"4179467045.00","volume_notional_value_dollars":"3245141294.960300","volume_24h":"1877080.00","volume_24h_notional_value_dollars":"11687174.591200","open_interest":"2332769.00","open_interest_notional_value_dollars":"14773192.800100","reference_price":{"price":"6.3375","ts_ms":1781237206000},"settlement_mark_price":{"price":"6.3516","ts_ms":1781237203035},"liquidation_mark_price":{"price":"6.3779","ts_ms":1781237206398},"funding_rate":{"rate":0,"next_funding_time_ms":1781265600000,"ts_ms":1781237203035},"ts_ms":1781217877584}}

{"type":"orderbook_delta","sid":1,"seq":2897,"msg":{"market_ticker":"KXBTCPERP1","price":"6.2289","delta":"1.00","side":"bid","ts_ms":1781237206516}}

{"type":"orderbook_delta","sid":1,"seq":2898,"msg":{"market_ticker":"KXBTCPERP1","price":"6.3904","delta":"-1.00","side":"ask","ts_ms":1781237206649}}

{"type":"orderbook_delta","sid":1,"seq":2899,"msg":{"market_ticker":"KXBTCPERP1","price":"6.2676","delta":"1.00","side":"bid","ts_ms":1781237206708}}

{"type":"orderbook_delta","sid":1,"seq":2900,"msg":{"market_ticker":"KXBTCPERP1","price":"6.3846","delta":"-1.00","side":"bid","ts_ms":1781237206764}}

{"type":"trade","sid":2,"seq":1990,"msg":{"trade_id":"42907440-8486-6d80-9c0e-0fbcf3ddf097","market_ticker":"KXBTCPERP1","price":"6.3846","count":"1.00","taker_side":"ask","ts_ms":1781237206764}}

{"type":"orderbook_delta","sid":1,"seq":2901,"msg":{"market_ticker":"KXBTCPERP1","price":"6.4303","delta":"1.00","side":"ask","ts_ms":1781237206946}}

{"type":"orderbook_delta","sid":1,"seq":2902,"msg":{"market_ticker":"KXBTCPERP1","price":"6.3884","delta":"1.00","side":"ask","ts_ms":1781237206982}}

{"type":"orderbook_delta","sid":1,"seq":2903,"msg":{"market_ticker":"KXBTCPERP1","price":"6.3884","delta":"-1.00","side":"ask","ts_ms":1781237207141}}

{"type":"trade","sid":2,"seq":1991,"msg":{"trade_id":"ab88eb86-5d0c-7aa7-5bfd-b7b2cb95c189","market_ticker":"KXBTCPERP1","price":"6.3884","count":"1.00","taker_side":"bid","ts_ms":1781237207141}}

{"type":"orderbook_delta","sid":1,"seq":2904,"msg":{"market_ticker":"KXBTCPERP1","price":"6.2119","delta":"1.00","side":"bid","ts_ms":1781237207197}}

{"type":"orderbook_delta","sid":1,"seq":2905,"msg":{"market_ticker":"KXBTCPERP1","price":"7.6637","delta":"-1.00","side":"ask","ts_ms":1781237207210}}

{"type":"orderbook_delta","sid":1,"seq":2906,"msg":{"market_ticker":"KXBTCPERP1","price":"6.2711","delta":"1.00","side":"bid","ts_ms":1781237207333}}

{"type":"orderbook_delta","sid":1,"seq":2907,"msg":{"market_ticker":"KXBTCPERP1","price":"6.3676","delta":"-612.00","side":"bid","ts_ms":1781237207377}}

{"type":"orderbook_delta","sid":1,"seq":2908,"msg":{"market_ticker":"KXBTCPERP1","price":"6.3809","delta":"610.00","side":"bid","ts_ms":1781237207377}}

{"type":"orderbook_delta","sid":1,"seq":2909,"msg":{"market_ticker":"KXBTCPERP1","price":"6.3634","delta":"-785.00","side":"bid","ts_ms":1781237207381}}

{"type":"orderbook_delta","sid":1,"seq":2910,"msg":{"market_ticker":"KXBTCPERP1","price":"6.3793","delta":"783.00","side":"bid","ts_ms":1781237207381}}

{"type":"orderbook_delta","sid":1,"seq":2911,"msg":{"market_ticker":"KXBTCPERP1","price":"6.3592","delta":"-787.00","side":"bid","ts_ms":1781237207385}}

{"type":"orderbook_delta","sid":1,"seq":2912,"msg":{"market_ticker":"KXBTCPERP1","price":"6.3777","delta":"784.00","side":"bid","ts_ms":1781237207385}}

{"type":"orderbook_delta","sid":1,"seq":2913,"msg":{"market_ticker":"KXBTCPERP1","price":"6.3550","delta":"-786.00","side":"bid","ts_ms":1781237207389}}

{"type":"orderbook_delta","sid":1,"seq":2914,"msg":{"market_ticker":"KXBTCPERP1","price":"6.3761","delta":"784.00","side":"bid","ts_ms":1781237207389}}

{"type":"orderbook_delta","sid":1,"seq":2915,"msg":{"market_ticker":"KXBTCPERP1","price":"6.3508","delta":"-788.00","side":"bid","ts_ms":1781237207392}}

{"type":"orderbook_delta","sid":1,"seq":2916,"msg":{"market_ticker":"KXBTCPERP1","price":"6.3745","delta":"785.00","side":"bid","ts_ms":1781237207392}}

{"type":"orderbook_delta","sid":1,"seq":2917,"msg":{"market_ticker":"KXBTCPERP1","price":"6.3466","delta":"-787.00","side":"bid","ts_ms":1781237207397}}

{"type":"orderbook_delta","sid":1,"seq":2918,"msg":{"market_ticker":"KXBTCPERP1","price":"6.3729","delta":"784.00","side":"bid","ts_ms":1781237207397}}

{"type":"orderbook_delta","sid":1,"seq":2919,"msg":{"market_ticker":"KXBTCPERP1","price":"6.3424","delta":"-789.00","side":"bid","ts_ms":1781237207400}}

{"type":"orderbook_delta","sid":1,"seq":2920,"msg":{"market_ticker":"KXBTCPERP1","price":"6.3713","delta":"785.00","side":"bid","ts_ms":1781237207400}}

{"type":"orderbook_delta","sid":1,"seq":2921,"msg":{"market_ticker":"KXBTCPERP1","price":"6.3382","delta":"-789.00","side":"bid","ts_ms":1781237207404}}

{"type":"orderbook_delta","sid":1,"seq":2922,"msg":{"market_ticker":"KXBTCPERP1","price":"6.3697","delta":"785.00","side":"bid","ts_ms":1781237207404}}

{"type":"orderbook_delta","sid":1,"seq":2923,"msg":{"market_ticker":"KXBTCPERP1","price":"6.3340","delta":"-790.00","side":"bid","ts_ms":1781237207407}}

{"type":"orderbook_delta","sid":1,"seq":2924,"msg":{"market_ticker":"KXBTCPERP1","price":"6.3681","delta":"786.00","side":"bid","ts_ms":1781237207407}}

{"type":"orderbook_delta","sid":1,"seq":2925,"msg":{"market_ticker":"KXBTCPERP1","price":"6.3298","delta":"-790.00","side":"bid","ts_ms":1781237207411}}

{"type":"orderbook_delta","sid":1,"seq":2926,"msg":{"market_ticker":"KXBTCPERP1","price":"6.3665","delta":"786.00","side":"bid","ts_ms":1781237207411}}

{"type":"orderbook_delta","sid":1,"seq":2927,"msg":{"market_ticker":"KXBTCPERP1","price":"6.3993","delta":"-291.00","side":"ask","ts_ms":1781237207415}}

{"type":"orderbook_delta","sid":1,"seq":2928,"msg":{"market_ticker":"KXBTCPERP1","price":"6.3908","delta":"292.00","side":"ask","ts_ms":1781237207415}}

{"type":"orderbook_delta","sid":1,"seq":2929,"msg":{"market_ticker":"KXBTCPERP1","price":"6.4035","delta":"-781.00","side":"ask","ts_ms":1781237207419}}

{"type":"orderbook_delta","sid":1,"seq":2930,"msg":{"market_ticker":"KXBTCPERP1","price":"6.3924","delta":"783.00","side":"ask","ts_ms":1781237207419}}

{"type":"orderbook_delta","sid":1,"seq":2931,"msg":{"market_ticker":"KXBTCPERP1","price":"6.4077","delta":"-781.00","side":"ask","ts_ms":1781237207423}}

{"type":"orderbook_delta","sid":1,"seq":2932,"msg":{"market_ticker":"KXBTCPERP1","price":"6.3940","delta":"782.00","side":"ask","ts_ms":1781237207423}}

{"type":"orderbook_delta","sid":1,"seq":2933,"msg":{"market_ticker":"KXBTCPERP1","price":"6.4119","delta":"-780.00","side":"ask","ts_ms":1781237207426}}

{"type":"orderbook_delta","sid":1,"seq":2934,"msg":{"market_ticker":"KXBTCPERP1","price":"6.3956","delta":"782.00","side":"ask","ts_ms":1781237207426}}

{"type":"orderbook_delta","sid":1,"seq":2935,"msg":{"market_ticker":"KXBTCPERP1","price":"6.4161","delta":"-780.00","side":"ask","ts_ms":1781237207430}}

{"type":"orderbook_delta","sid":1,"seq":2936,"msg":{"market_ticker":"KXBTCPERP1","price":"6.3972","delta":"782.00","side":"ask","ts_ms":1781237207430}}

{"type":"orderbook_delta","sid":1,"seq":2937,"msg":{"market_ticker":"KXBTCPERP1","price":"6.4203","delta":"-779.00","side":"ask","ts_ms":1781237207434}}

{"type":"orderbook_delta","sid":1,"seq":2938,"msg":{"market_ticker":"KXBTCPERP1","price":"6.3988","delta":"782.00","side":"ask","ts_ms":1781237207434}}

{"type":"orderbook_delta","sid":1,"seq":2939,"msg":{"market_ticker":"KXBTCPERP1","price":"6.4245","delta":"-779.00","side":"ask","ts_ms":1781237207437}}

{"type":"orderbook_delta","sid":1,"seq":2940,"msg":{"market_ticker":"KXBTCPERP1","price":"6.4004","delta":"782.00","side":"ask","ts_ms":1781237207437}}

{"type":"orderbook_delta","sid":1,"seq":2941,"msg":{"market_ticker":"KXBTCPERP1","price":"6.4287","delta":"-778.00","side":"ask","ts_ms":1781237207440}}

{"type":"orderbook_delta","sid":1,"seq":2942,"msg":{"market_ticker":"KXBTCPERP1","price":"6.4020","delta":"782.00","side":"ask","ts_ms":1781237207440}}

{"type":"orderbook_delta","sid":1,"seq":2943,"msg":{"market_ticker":"KXBTCPERP1","price":"6.4329","delta":"-778.00","side":"ask","ts_ms":1781237207443}}

{"type":"orderbook_delta","sid":1,"seq":2944,"msg":{"market_ticker":"KXBTCPERP1","price":"6.4036","delta":"781.00","side":"ask","ts_ms":1781237207443}}

{"type":"orderbook_delta","sid":1,"seq":2945,"msg":{"market_ticker":"KXBTCPERP1","price":"6.4371","delta":"-777.00","side":"ask","ts_ms":1781237207446}}

{"type":"orderbook_delta","sid":1,"seq":2946,"msg":{"market_ticker":"KXBTCPERP1","price":"6.4052","delta":"781.00","side":"ask","ts_ms":1781237207446}}

{"type":"orderbook_delta","sid":1,"seq":2947,"msg":{"market_ticker":"KXBTCPERP1","price":"6.3846","delta":"-1.00","side":"bid","ts_ms":1781237207456}}

{"type":"trade","sid":2,"seq":1992,"msg":{"trade_id":"a0fc99bc-e092-4370-9429-7d4e0cedb42b","market_ticker":"KXBTCPERP1","price":"6.3846","count":"1.00","taker_side":"ask","ts_ms":1781237207456}}

{"type":"ticker","sid":3,"msg":{"market_ticker":"KXBTCPERP1","price":"6.3329","bid":"6.3329","ask":"6.3416","bid_size_fp":"343.00","ask_size_fp":"658.00","last_trade_size_fp":"0.00","volume":"4179467045.00","volume_notional_value_dollars":"3245141294.960300","volume_24h":"1877080.00","volume_24h_notional_value_dollars":"11687174.591200","open_interest":"2332769.00","open_interest_notional_value_dollars":"14773192.800100","reference_price":{"price":"6.3375","ts_ms":1781237207000},"settlement_mark_price":{"price":"6.3516","ts_ms":1781237203035},"liquidation_mark_price":{"price":"6.3780","ts_ms":1781237207398},"funding_rate":{"rate":0,"next_funding_time_ms":1781265600000,"ts_ms":1781237203035},"ts_ms":1781217877584}}
