{"type":"subscribed","id":1,"msg":{"channel":"orderbook_delta","sid":1}}

{"type":"subscribed","id":1,"msg":{"channel":"trade","sid":2}}

{"type":"orderbook_snapshot","sid":1,"seq":1,"msg":{"market_ticker":"KXBTCPERP1","bid":[["4.8368","3.00"],["4.8370","1.00"],["4.8372","2.00"],["4.8392","1.00"],["4.8394","2.00"],["4.8398","1.00"],["4.8402","3.00"],["4.8404","5.00"],["4.8408","1.00"],["4.8540","1.00"],["4.8542","4.00"],["4.8544","3.00"],["4.8546","2.00"],["4.8548","1.00"],["4.8550","1.00"],["4.8552","4.00"],["4.8568","1.00"],["4.8850","1.00"],["4.8852","3.00"],["4.8854","3.00"],["4.8856","2.00"],["4.8858","3.00"],["4.8860","1.00"],["4.8862","3.00"],["4.8990","2.00"],["4.8994","3.00"],["4.8996","3.00"],["4.9006","1.00"],["4.9120","2.00"],["4.9124","1.00"],["4.9126","1.00"],["4.9154","3.00"],["4.9156","3.00"],["4.9158","1.00"],["4.9160","3.00"],["4.9162","1.00"],["4.9164","1.00"],["4.9166","2.00"],["4.9170","1.00"],["4.9172","3.00"],["4.9174","2.00"],["4.9176","2.00"],["4.9180","2.00"],["4.9182","1.00"],["4.9184","1.00"],["4.9216","1.00"],["4.9218","3.00"],["4.9220","1.00"],["4.9224","3.00"],["4.9232","2.00"],["4.9236","1.00"],["5.0052","1.00"],["5.0056","2.00"],["5.0794","2.00"],["5.0796","3.00"],["5.0798","3.00"],["5.0800","3.00"],["5.0802","1.00"],["5.0804","2.00"],["5.0812","2.00"],["5.0814","1.00"],["5.0824","3.00"],["5.0826","2.00"],["5.0828","1.00"],["5.0830","1.00"],["5.0832","3.00"],["5.0836","2.00"],["5.0838","3.00"],["5.0850","1.00"],["5.1414","3.00"],["5.1418","3.00"],["5.1424","1.00"],["5.1428","1.00"],["5.1440","1.00"],["5.1450","2.00"],["5.2120","2.00"],["5.2122","3.00"],["5.2124","3.00"],["5.2126","2.00"],["5.2128","3.00"],["5.2130","2.00"],["5.2132","4.00"],["5.2134","2.00"],["5.2136","3.00"],["5.2138","2.00"],["5.2140","1.00"],["5.2756","1.00"],["5.2758","1.00"],["5.2762","1.00"],["5.2764","3.00"],["5.2766","3.00"],["5.2768","2.00"],["5.2772","3.00"],["5.2778","1.00"],["5.2780","3.00"],["5.2904","3.00"],["5.2906","3.00"],["5.2908","1.00"],["5.2910","2.00"],["5.2914","1.00"],["5.2916","3.00"],["5.2920","3.00"],["5.2922","4.00"],["5.2926","2.00"],["5.2944","1.00"],["5.3470","2.00"],["5.3474","3.00"],["5.3476","1.00"],["5.3478","2.00"],["5.3480","3.00"],["5.3482","3.00"],["5.3486","1.00"],["5.3488","1.00"],["5.3494","1.00"],["5.4264","3.00"],["5.4266","1.00"],["5.4268","3.00"],["5.5034","3.00"],["5.5036","2.00"],["5.5038","3.00"],["5.5040","2.00"],["5.5042","3.00"],["5.5050","1.00"],["5.5054","1.00"],["5.5062","2.00"],["5.5068","1.00"],["5.5308","1.00"],["5.5310","2.00"],["5.5312","3.00"],["5.5314","3.00"],["5.5316","1.00"],["5.5318","2.00"],["5.6046","1.00"],["5.6048","2.00"],["5.6050","2.00"],["5.6052","1.00"],["5.6054","2.00"],["5.6056","1.00"],["5.6188","1.00"],["5.6190","1.00"],["5.6192","1.00"],["5.6194","2.00"],["5.6202","1.00"],["5.6718","1.00"],["5.6720","3.00"],["5.6722","1.00"],["5.6724","2.00"],["5.6726","2.00"],["5.6728","3.00"],["5.6730","1.00"],["5.6836","2.00"],["5.6838","5.00"],["5.6840","2.00"],["5.6842","3.00"],["5.6848","1.00"],["5.6850","2.00"],["5.6854","2.00"],["5.6868","2.00"],["5.6880","1.00"],["5.6882","1.00"],["5.6884","3.00"],["5.6886","3.00"],["5.6888","1.00"],["5.6890","1.00"],["5.6892","2.00"],["5.6894","2.00"],["5.6896","1.00"],["5.6900","1.00"],["5.6904","1.00"],["5.6906","2.00"],["5.6908","1.00"],["5.8104","1.00"],["5.8192","1.00"],["5.8219","3.00"],["5.8253","1.00"],["5.8303","2.00"],["5.8307","1.00"],["5.8412","2.00"],["5.8443","3.00"],["5.8481","1.00"],["5.8538","1.00"],["5.8540","2.00"],["5.8544","1.00"],["5.8548","4.00"],["5.8550","2.00"],["5.8552","2.00"],["5.8554","3.00"],["5.8556","1.00"],["5.8566","1.00"],["5.8693","1.00"],["5.8698","2.00"],["5.8730","2.00"],["5.8732","3.00"],["5.8734","3.00"],["5.8766","2.00"],["5.8770","3.00"],["5.8813","3.00"],["5.8856","3.00"],["5.8858","1.00"],["5.8897","1.00"],["5.8901","1.00"],["5.8946","1.00"],["5.8951","1.00"],["5.8962","2.00"],["5.8968","1.00"],["5.8980","2.00"],["5.8985","3.00"],["5.9006","1.00"],["5.9017","3.00"],["5.9037","2.00"],["5.9042","1.00"],["5.9102","3.00"],["5.9114","1.00"],["5.9143","3.00"],["5.9173","1.00"],["5.9178","1.00"],["5.9214","2.00"],["5.9235","1.00"],["5.9242","1.00"],["5.9254","3.00"],["5.9260","1.00"],["5.9306","2.00"],["5.9330","2.00"],["5.9339","1.00"],["5.9340","1.00"],["5.9352","2.00"],["5.9365","3.00"],["5.9374","1.00"],["5.9393","1.00"],["5.9397","2.00"],["5.9398","1.00"],["5.9403","3.00"],["5.9413","1.00"],["5.9424","1.00"],["5.9425","1.00"],["5.9434","2.00"],["5.9437","1.00"],["5.9438","2.00"],["5.9441","3.00"],["5.9460","1.00"],["5.9463","3.00"],["5.9464","1.00"],["5.9468","1.00"],["5.9483","3.00"],["5.9490","2.00"],["5.9512","1.00"],["5.9516","2.00"],["5.9532","4.00"],["5.9534","1.00"],["5.9538","5.00"],["5.9539","3.00"],["5.9550","2.00"],["5.9551","2.00"],["5.9567","1.00"],["5.9586","3.00"],["5.9607","1.00"],["5.9610","3.00"],["5.9611","1.00"],["5.9614","1.00"],["5.9617","1.00"],["5.9636","3.00"],["5.9638","3.00"],["5.9639","2.00"],["5.9653","3.00"],["5.9654","1.00"],["5.9666","2.00"],["5.9675","1.00"],["5.9678","1.00"],["5.9694","4.00"],["5.9702","3.00"],["5.9704","3.00"],["5.9716","1.00"],["5.9723","1.00"],["5.9728","2.00"],["5.9729","1.00"],["5.9736","2.00"],["5.9738","2.00"],["5.9739","3.00"],["5.9742","1.00"],["5.9756","4.00"],["5.9760","1.00"],["5.9774","2.00"],["5.9778","1.00"],["5.9785","1.00"],["5.9788","1.00"],["5.9798","1.00"],["5.9799","1.00"],["5.9803","1.00"],["5.9824","1.00"],["5.9828","3.00"],["5.9834","2.00"],["5.9840","3.00"],["5.9846","2.00"],["5.9858","6.00"],["5.9861","2.00"],["5.9883","1.00"],["5.9886","1.00"],["5.9890","1.00"],["5.9897","1.00"],["5.9908","3.00"],["5.9918","1.00"],["5.9926","4.00"],["5.9929","2.00"],["5.9932","2.00"],["5.9937","3.00"],["5.9948","2.00"],["5.9959","1.00"],["5.9961","1.00"],["5.9962","3.00"],["5.9968","1.00"],["5.9977","2.00"],["5.9983","3.00"],["5.9988","2.00"],["5.9992","1.00"],["5.9999","1.00"],["6.0009","3.00"],["6.0030","1.00"],["6.0037","3.00"],["6.0040","1.00"],["6.0043","1.00"],["6.0073","1.00"],["6.0077","1.00"],["6.0095","1.00"],["6.0098","1.00"],["6.0110","1.00"],["6.0140","1.00"],["6.0142","1.00"],["6.0188","1.00"],["6.0200","1.00"],["6.0214","1.00"],["6.0221","1.00"],["6.0247","3.00"],["6.0255","1.00"],["6.0279","1.00"],["6.0283","1.00"],["6.0294","3.00"],["6.0300","1.00"],["6.0329","1.00"],["6.0333","2.00"],["6.0345","1.00"],["6.0363","1.00"],["6.0367","1.00"],["6.0389","1.00"],["6.0405","4.00"],["6.0412","1.00"],["6.0419","3.00"],["6.0426","1.00"],["6.0432","1.00"],["6.0449","2.00"],["6.0452","1.00"],["6.0455","2.00"],["6.0457","1.00"],["6.0473","1.00"],["6.0479","2.00"],["6.0482","3.00"],["6.0485","3.00"],["6.0486","1.00"],["6.0492","1.00"],["6.0508","1.00"],["6.0514","1.00"],["6.0518","3.00"],["6.0529","1.00"],["6.0540","2.00"],["6.0549","1.00"],["6.0575","1.00"],["6.0579","1.00"],["6.0591","1.00"],["6.0593","1.00"],["6.0604","1.00"],["6.0613","1.00"],["6.0616","3.00"],["6.0636","1.00"],["6.0642","1.00"],["6.0736","1.00"],["6.0758","1.00"],["6.0778","2.00"],["6.0799","1.00"],["6.0817","1.00"],["6.0836","1.00"],["6.0901","1.00"],["6.0952","1.00"],["6.0961","1.00"],["6.0969","2.00"],["6.0989","1.00"],["6.1002","1.00"],["6.1203","1.00"],["6.1215","1.00"],["6.1220","1.00"],["6.1227","1.00"],["6.1228","1.00"],["6.1267","1.00"],["6.1276","1.00"],["6.1277","1.00"],["6.1340","1.00"],["6.1384","1.00"],["6.1411","1.00"],["6.1417","1.00"],["6.1428","1.00"],["6.1435","1.00"],["6.1474","2.00"],["6.1514","1.00"],["6.1538","1.00"],["6.1543","1.00"],["6.1548","1.00"],["6.1586","1.00"],["6.1612","1.00"],["6.1636","1.00"],["6.1648","1.00"],["6.1661","1.00"],["6.1671","1.00"],["6.1675","1.00"],["6.1678","1.00"],["6.1683","1.00"],["6.1686","1.00"],["6.1706","1.00"],["6.1765","1.00"],["6.1773","1.00"],["6.1790","1.00"],["6.1812","1.00"],["6.1819","1.00"],["6.1851","1.00"],["6.1872","1.00"],["6.1873","1.00"],["6.1882","1.00"],["6.1897","1.00"],["6.1905","1.00"],["6.1942","2.00"],["6.1957","1.00"],["6.1963","1.00"],["6.1966","1.00"],["6.1967","1.00"],["6.1970","1.00"],["6.1978","1.00"],["6.1982","1.00"],["6.1983","2.00"],["6.1985","1.00"],["6.1990","2.00"],["6.1992","1.00"],["6.1994","1.00"],["6.1995","2.00"],["6.1996","1.00"],["6.1998","2.00"],["6.2000","1.00"],["6.2002","1.00"],["6.2003","2.00"],["6.2004","2.00"],["6.2005","2.00"],["6.2006","2.00"],["6.2007","2.00"],["6.2009","2.00"],["6.2010","2.00"],["6.2011","3.00"],["6.2012","2.00"],["6.2013","2.00"],["6.2015","2.00"],["6.2016","2.00"],["6.2021","1.00"],["6.2022","5.00"],["6.2023","2.00"],["6.2024","4.00"],["6.2025","1.00"],["6.2026","3.00"],["6.2027","1.00"],["6.2029","2.00"],["6.2030","2.00"],["6.2031","2.00"],["6.2034","2.00"],["6.2035","3.00"],["6.2037","2.00"],["6.2038","2.00"],["6.2039","2.00"],["6.2040","4.00"],["6.2041","9.00"],["6.2042","1.00"],["6.2043","4.00"],["6.2044","2.00"],["6.2045","3.00"],["6.2046","1.00"],["6.2047","2.00"],["6.2048","3.00"],["6.2049","4.00"],["6.2050","5.00"],["6.2051","5.00"],["6.2052","7.00"],["6.2053","4.00"],["6.2054","4.00"],["6.2055","5.00"],["6.2056","5.00"],["6.2057","5.00"],["6.2058","3.00"],["6.2059","3.00"],["6.2060","3.00"],["6.2061","4.00"],["6.2062","4.00"],["6.2063","6.00"],["6.2064","4.00"],["6.2065","5.00"],["6.2066","6.00"],["6.2067","3.00"],["6.2068","3.00"],["6.2069","7.00"],["6.2070","2.00"],["6.2071","6.00"],["6.2072","2.00"],["6.2073","3.00"],["6.2074","6.00"],["6.2075","2.00"],["6.2076","4.00"],["6.2077","2.00"],["6.2078","6.00"],["6.2079","4.00"],["6.2080","7.00"],["6.2081","2.00"],["6.2082","5.00"],["6.2083","4.00"],["6.2084","5.00"],["6.2085","4.00"],["6.2086","4.00"],["6.2087","5.00"],["6.2088","3.00"],["6.2089","4.00"],["6.2090","5.00"],["6.2091","8.00"],["6.2092","5.00"],["6.2093","5.00"],["6.2094","4.00"],["6.2095","4.00"],["6.2096","7.00"],["6.2097","7.00"],["6.2098","5.00"],["6.2099","3.00"],["6.2100","3.00"],["6.2101","8.00"],["6.2102","5.00"],["6.2103","6.00"],["6.2104","3.00"],["6.2105","9.00"],["6.2106","10.00"],["6.2107","7.00"],["6.2108","6.00"],["6.2109","9.00"],["6.2110","3.00"],["6.2111","11.00"],["6.2112","10.00"],["6.2113","8.00"],["6.2114","4.00"],["6.2115","11.00"],["6.2116","11.00"],["6.2117","5.00"],["6.2118","8.00"],["6.2119","7.00"],["6.2120","7.00"],["6.2121","15.00"],["6.2122","11.00"],["6.2123","9.00"],["6.2124","10.00"],["6.2125","10.00"],["6.2126","7.00"],["6.2127","11.00"],["6.2128","10.00"],["6.2129","7.00"],["6.2130","6.00"],["6.2131","7.00"],["6.2132","9.00"],["6.2133","10.00"],["6.2134","4.00"],["6.2135","5.00"],["6.2136","11.00"],["6.2137","9.00"],["6.2138","8.00"],["6.2139","10.00"],["6.2140","6.00"],["6.2141","10.00"],["6.2142","9.00"],["6.2143","7.00"],["6.2144","9.00"],["6.2145","9.00"],["6.2146","13.00"],["6.2147","2.00"],["6.2148","18.00"],["6.2149","9.00"],["6.2150","17.00"],["6.2151","7.00"],["6.2152","13.00"],["6.2153","8.00"],["6.2154","9.00"],["6.2155","16.00"],["6.2156","15.00"],["6.2157","16.00"],["6.2158","12.00"],["6.2159","15.00"],["6.2160","9.00"],["6.2161","17.00"],["6.2162","8.00"],["6.2163","11.00"],["6.2164","12.00"],["6.2165","14.00"],["6.2166","12.00"],["6.2167","8.00"],["6.2168","9.00"],["6.2169","15.00"],["6.2170","10.00"],["6.2171","23.00"],["6.2172","9.00"],["6.2173","14.00"],["6.2174","10.00"],["6.2175","11.00"],["6.2176","14.00"],["6.2177","19.00"],["6.2178","10.00"],["6.2179","12.00"],["6.2180","13.00"],["6.2181","9.00"],["6.2182","8.00"],["6.2183","14.00"],["6.2184","8.00"],["6.2185","16.00"],["6.2186","11.00"],["6.2187","12.00"],["6.2188","11.00"],["6.2189","8.00"],["6.2190","12.00"],["6.2191","14.00"],["6.2192","10.00"],["6.2193","10.00"],["6.2194","6.00"],["6.2195","8.00"],["6.2196","14.00"],["6.2197","20.00"],["6.2198","10.00"],["6.2199","9.00"],["6.2200","21.00"],["6.2201","13.00"],["6.2202","11.00"],["6.2203","6.00"],["6.2204","8.00"],["6.2205","10.00"],["6.2206","13.00"],["6.2207","9.00"],["6.2208","5.00"],["6.2209","8.00"],["6.2210","10.00"],["6.2211","16.00"],["6.2212","10.00"],["6.2213","14.00"],["6.2214","9.00"],["6.2215","20.00"],["6.2216","15.00"],["6.2217","15.00"],["6.2218","14.00"],["6.2219","18.00"],["6.2220","17.00"],["6.2221","15.00"],["6.2222","14.00"],["6.2223","10.00"],["6.2224","11.00"],["6.2225","11.00"],["6.2226","14.00"],["6.2227","18.00"],["6.2228","16.00"],["6.2229","12.00"],["6.2230","19.00"],["6.2231","15.00"],["6.2232","14.00"],["6.2233","13.00"],["6.2234","16.00"],["6.2235","8.00"],["6.2236","16.00"],["6.2237","20.00"],["6.2238","11.00"],["6.2239","13.00"],["6.2240","15.00"],["6.2241","14.00"],["6.2242","14.00"],["6.2243","18.00"],["6.2244","18.00"],["6.2245","18.00"],["6.2246","11.00"],["6.2247","19.00"],["6.2248","19.00"],["6.2249","16.00"],["6.2250","25.00"],["6.2251","17.00"],["6.2252","16.00"],["6.2253","23.00"],["6.2254","19.00"],["6.2255","11.00"],["6.2256","12.00"],["6.2257","22.00"],["6.2258","17.00"],["6.2259","17.00"],["6.2260","17.00"],["6.2261","14.00"],["6.2262","14.00"],["6.2263","21.00"],["6.2264","15.00"],["6.2265","21.00"],["6.2266","17.00"],["6.2267","24.00"],["6.2268","14.00"],["6.2269","19.00"],["6.2270","19.00"],["6.2271","25.00"],["6.2272","19.00"],["6.2273","17.00"],["6.2274","16.00"],["6.2275","24.00"],["6.2276","18.00"],["6.2277","23.00"],["6.2278","25.00"],["6.2279","16.00"],["6.2280","13.00"],["6.2281","18.00"],["6.2282","21.00"],["6.2283","24.00"],["6.2284","22.00"],["6.2285","16.00"],["6.2286","20.00"],["6.2287","15.00"],["6.2288","21.00"],["6.2289","9.00"],["6.2290","20.00"],["6.2291","15.00"],["6.2292","20.00"],["6.2293","23.00"],["6.2294","14.00"],["6.2295","17.00"],["6.2296","15.00"],["6.2297","15.00"],["6.2298","15.00"],["6.2299","19.00"],["6.2300","20.00"],["6.2301","22.00"],["6.2302","16.00"],["6.2303","18.00"],["6.2304","15.00"],["6.2305","12.00"],["6.2306","27.00"],["6.2307","18.00"],["6.2308","18.00"],["6.2309","20.00"],["6.2310","12.00"],["6.2311","19.00"],["6.2312","19.00"],["6.2313","19.00"],["6.2314","14.00"],["6.2315","26.00"],["6.2316","8.00"],["6.2317","11.00"],["6.2318","28.00"],["6.2319","23.00"],["6.2320","22.00"],["6.2321","25.00"],["6.2322","14.00"],["6.2323","23.00"],["6.2324","21.00"],["6.2325","29.00"],["6.2326","24.00"],["6.2327","24.00"],["6.2328","11.00"],["6.2329","19.00"],["6.2330","16.00"],["6.2331","21.00"],["6.2332","32.00"],["6.2333","10.00"],["6.2334","16.00"],["6.2335","18.00"],["6.2336","27.00"],["6.2337","30.00"],["6.2338","26.00"],["6.2339","16.00"],["6.2340","16.00"],["6.2341","19.00"],["6.2342","20.00"],["6.2343","28.00"],["6.2344","16.00"],["6.2345","18.00"],["6.2346","20.00"],["6.2347","22.00"],["6.2348","19.00"],["6.2349","18.00"],["6.2350","21.00"],["6.2351","18.00"],["6.2352","15.00"],["6.2353","22.00"],["6.2354","24.00"],["6.2355","22.00"],["6.2356","18.00"],["6.2357","20.00"],["6.2358","28.00"],["6.2359","23.00"],["6.2360","19.00"],["6.2361","22.00"],["6.2362","15.00"],["6.2363","21.00"],["6.2364","16.00"],["6.2365","26.00"],["6.2366","21.00"],["6.2367","20.00"],["6.2368","18.00"],["6.2369","25.00"],["6.2370","21.00"],["6.2371","19.00"],["6.2372","17.00"],["6.2373","26.00"],["6.2374","23.00"],["6.2375","20.00"],["6.2376","15.00"],["6.2377","24.00"],["6.2378","21.00"],["6.2379","21.00"],["6.2380","29.00"],["6.2381","22.00"],["6.2382","23.00"],["6.2383","21.00"],["6.2384","15.00"],["6.2385","20.00"],["6.2386","22.00"],["6.2387","21.00"],["6.2388","22.00"],["6.2389","10.00"],["6.2390","27.00"],["6.2391","19.00"],["6.2392","27.00"],["6.2393","18.00"],["6.2394","25.00"],["6.2395","24.00"],["6.2396","20.00"],["6.2397","16.00"],["6.2398","13.00"],["6.2399","19.00"],["6.2400","21.00"],["6.2401","26.00"],["6.2402","22.00"],["6.2403","14.00"],["6.2404","18.00"],["6.2405","25.00"],["6.2406","23.00"],["6.2407","19.00"],["6.2408","30.00"],["6.2409","24.00"],["6.2410","20.00"],["6.2411","18.00"],["6.2412","22.00"],["6.2413","13.00"],["6.2414","20.00"],["6.2415","23.00"],["6.2416","20.00"],["6.2417","25.00"],["6.2418","24.00"],["6.2419","22.00"],["6.2420","29.00"],["6.2421","17.00"],["6.2422","19.00"],["6.2423","29.00"],["6.2424","17.00"],["6.2425","20.00"],["6.2426","21.00"],["6.2427","28.00"],["6.2428","29.00"],["6.2429","16.00"],["6.2430","15.00"],["6.2431","18.00"],["6.2432","21.00"],["6.2433","27.00"],["6.2434","15.00"],["6.2435","13.00"],["6.2436","19.00"],["6.2437","19.00"],["6.2438","28.00"],["6.2439","25.00"],["6.2440","26.00"],["6.2441","32.00"],["6.2442","27.00"],["6.2443","21.00"],["6.2444","19.00"],["6.2445","22.00"],["6.2446","16.00"],["6.2447","19.00"],["6.2448","25.00"],["6.2449","29.00"],["6.2450","13.00"],["6.2451","21.00"],["6.2452","18.00"],["6.2453","23.00"],["6.2454","17.00"],["6.2455","27.00"],["6.2456","22.00"],["6.2457","18.00"],["6.2458","15.00"],["6.2459","19.00"],["6.2460","35.00"],["6.2461","21.00"],["6.2462","24.00"],["6.2463","20.00"],["6.2464","22.00"],["6.2465","13.00"],["6.2466","19.00"],["6.2467","19.00"],["6.2468","16.00"],["6.2469","18.00"],["6.2470","26.00"],["6.2471","13.00"],["6.2472","19.00"],["6.2473","30.00"],["6.2474","22.00"],["6.2475","25.00"],["6.2476","15.00"],["6.2477","16.00"],["6.2478","22.00"],["6.2479","17.00"],["6.2480","28.00"],["6.2481","13.00"],["6.2482","18.00"],["6.2483","23.00"],["6.2484","16.00"],["6.2485","15.00"],["6.2486","17.00"],["6.2487","21.00"],["6.2488","23.00"],["6.2489","26.00"],["6.2490","21.00"],["6.2491","19.00"],["6.2492","23.00"],["6.2493","23.00"],["6.2494","17.00"],["6.2495","26.00"],["6.2496","17.00"],["6.2497","21.00"],["6.2498","18.00"],["6.2499","17.00"],["6.2500","29.00"],["6.2501","18.00"],["6.2502","26.00"],["6.2503","22.00"],["6.2504","23.00"],["6.2505","19.00"],["6.2506","27.00"],["6.2507","19.00"],["6.2508","27.00"],["6.2509","23.00"],["6.2510","28.00"],["6.2511","27.00"],["6.2512","27.00"],["6.2513","15.00"],["6.2514","22.00"],["6.2515","28.00"],["6.2516","29.00"],["6.2517","26.00"],["6.2518","28.00"],["6.2519","22.00"],["6.2520","25.00"],["6.2521","31.00"],["6.2522","12.00"],["6.2523","28.00"],["6.2524","17.00"],["6.2525","21.00"],["6.2526","21.00"],["6.2527","22.00"],["6.2528","28.00"],["6.2529","17.00"],["6.2530","17.00"],["6.2531","17.00"],["6.2532","14.00"],["6.2533","21.00"],["6.2534","22.00"],["6.2535","23.00"],["6.2536","20.00"],["6.2537","23.00"],["6.2538","30.00"],["6.2539","26.00"],["6.2540","24.00"],["6.2541","20.00"],["6.2542","22.00"],["6.2543","19.00"],["6.2544","19.00"],["6.2545","20.00"],["6.2546","30.00"],["6.2547","12.00"],["6.2548","28.00"],["6.2549","25.00"],["6.2550","22.00"],["6.2551","16.00"],["6.2552","17.00"],["6.2553","23.00"],["6.2554","25.00"],["6.2555","22.00"],["6.2556","16.00"],["6.2557","20.00"],["6.2558","23.00"],["6.2559","30.00"],["6.2560","21.00"],["6.2561","17.00"],["6.2562","27.00"],["6.2563","19.00"],["6.2564","27.00"],["6.2565","27.00"],["6.2566","26.00"],["6.2567","21.00"],["6.2568","26.00"],["6.2569","18.00"],["6.2570","23.00"],["6.2571","19.00"],["6.2572","16.00"],["6.2573","24.00"],["6.2574","20.00"],["6.2575","21.00"],["6.2576","24.00"],["6.2577","21.00"],["6.2578","15.00"],["6.2579","22.00"],["6.2580","21.00"],["6.2581","21.00"],["6.2582","18.00"],["6.2583","30.00"],["6.2584","17.00"],["6.2585","31.00"],["6.2586","18.00"],["6.2587","19.00"],["6.2588","28.00"],["6.2589","17.00"],["6.2590","17.00"],["6.2591","26.00"],["6.2592","22.00"],["6.2593","28.00"],["6.2594","30.00"],["6.2595","19.00"],["6.2596","21.00"],["6.2597","20.00"],["6.2598","21.00"],["6.2599","17.00"],["6.2600","23.00"],["6.2601","23.00"],["6.2602","19.00"],["6.2603","22.00"],["6.2604","23.00"],["6.2605","16.00"],["6.2606","22.00"],["6.2607","27.00"],["6.2608","33.00"],["6.2609","20.00"],["6.2610","18.00"],["6.2611","15.00"],["6.2612","25.00"],["6.2613","23.00"],["6.2614","22.00"],["6.2615","27.00"],["6.2616","29.00"],["6.2617","19.00"],["6.2618","15.00"],["6.2619","29.00"],["6.2620","18.00"],["6.2621","18.00"],["6.2622","19.00"],["6.2623","13.00"],["6.2624","24.00"],["6.2625","23.00"],["6.2626","20.00"],["6.2627","24.00"],["6.2628","17.00"],["6.2629","32.00"],["6.2630","18.00"],["6.2631","28.00"],["6.2632","15.00"],["6.2633","18.00"],["6.2634","15.00"],["6.2635","24.00"],["6.2636","32.00"],["6.2637","17.00"],["6.2638","26.00"],["6.2639","23.00"],["6.2640","19.00"],["6.2641","23.00"],["6.2642","19.00"],["6.2643","19.00"],["6.2644","25.00"],["6.2645","21.00"],["6.2646","24.00"],["6.2647","14.00"],["6.2648","23.00"],["6.2649","23.00"],["6.2650","22.00"],["6.2651","23.00"],["6.2652","20.00"],["6.2653","18.00"],["6.2654","24.00"],["6.2655","29.00"],["6.2656","26.00"],["6.2657","27.00"],["6.2658","28.00"],["6.2659","31.00"],["6.2660","18.00"],["6.2661","17.00"],["6.2662","18.00"],["6.2663","20.00"],["6.2664","20.00"],["6.2665","20.00"],["6.2666","21.00"],["6.2667","22.00"],["6.2668","15.00"],["6.2669","22.00"],["6.2670","27.00"],["6.2671","18.00"],["6.2672","23.00"],["6.2673","22.00"],["6.2674","19.00"],["6.2675","19.00"],["6.2676","19.00"],["6.2677","28.00"],["6.2678","17.00"],["6.2679","18.00"],["6.2680","20.00"],["6.2681","14.00"],["6.2682","24.00"],["6.2683","21.00"],["6.2684","19.00"],["6.2685","16.00"],["6.2686","23.00"],["6.2687","22.00"],["6.2688","28.00"],["6.2689","32.00"],["6.2690","21.00"],["6.2691","34.00"],["6.2692","13.00"],["6.2693","16.00"],["6.2694","21.00"],["6.2695","13.00"],["6.2696","31.00"],["6.2697","19.00"],["6.2698","26.00"],["6.2699","24.00"],["6.2700","13.00"],["6.2701","17.00"],["6.2702","19.00"],["6.2703","22.00"],["6.2704","27.00"],["6.2705","31.00"],["6.2706","25.00"],["6.2707","28.00"],["6.2708","25.00"],["6.2709","19.00"],["6.2710","18.00"],["6.2711","22.00"],["6.2712","26.00"],["6.2713","22.00"],["6.2714","15.00"],["6.2715","17.00"],["6.2716","19.00"],["6.2717","24.00"],["6.2718","21.00"],["6.2719","27.00"],["6.2720","18.00"],["6.2721","29.00"],["6.2722","28.00"],["6.2723","21.00"],["6.2724","16.00"],["6.2725","22.00"],["6.2726","19.00"],["6.2727","27.00"],["6.2728","20.00"],["6.2729","12.00"],["6.2730","10.00"],["6.2731","28.00"],["6.2732","23.00"],["6.2733","29.00"],["6.2734","24.00"],["6.2735","15.00"],["6.2736","25.00"],["6.2737","24.00"],["6.2738","22.00"],["6.2739","21.00"],["6.2740","20.00"],["6.2741","30.00"],["6.2742","24.00"],["6.2743","28.00"],["6.2744","18.00"],["6.2745","20.00"],["6.2746","22.00"],["6.2747","22.00"],["6.2748","23.00"],["6.2749","25.00"],["6.2750","25.00"],["6.2751","30.00"],["6.2752","23.00"],["6.2753","19.00"],["6.2754","28.00"],["6.2755","16.00"],["6.2756","17.00"],["6.2757","17.00"],["6.2758","23.00"],["6.2759","24.00"],["6.2760","31.00"],["6.2761","24.00"],["6.2762","24.00"],["6.2763","19.00"],["6.2764","29.00"],["6.2765","17.00"],["6.2766","19.00"],["6.2767","18.00"],["6.2768","17.00"],["6.2769","20.00"],["6.2770","20.00"],["6.2771","26.00"],["6.2772","27.00"],["6.2773","26.00"],["6.2774","15.00"],["6.2775","24.00"],["6.2776","22.00"],["6.2777","28.00"],["6.2778","27.00"],["6.2779","25.00"],["6.2780","25.00"],["6.2781","27.00"],["6.2782","19.00"],["6.2783","20.00"],["6.2784","14.00"],["6.2785","26.00"],["6.2786","19.00"],["6.2787","20.00"],["6.2788","24.00"],["6.2789","21.00"],["6.2790","25.00"],["6.2791","21.00"],["6.2792","15.00"],["6.2793","26.00"],["6.2794","22.00"],["6.2795","23.00"],["6.2796","15.00"],["6.2797","21.00"],["6.2798","25.00"],["6.2799","26.00"],["6.2800","20.00"],["6.2801","20.00"],["6.2802","17.00"],["6.2803","12.00"],["6.2804","14.00"],["6.2805","17.00"],["6.2806","21.00"],["6.2807","22.00"],["6.2808","17.00"],["6.2809","29.00"],["6.2810","14.00"],["6.2811","26.00"],["6.2812","17.00"],["6.2813","20.00"],["6.2814","21.00"],["6.2815","23.00"],["6.2816","32.00"],["6.2817","23.00"],["6.2818","22.00"],["6.2819","24.00"],["6.2820","21.00"],["6.2821","23.00"],["6.2822","17.00"],["6.2823","26.00"],["6.2824","23.00"],["6.2825","23.00"],["6.2826","19.00"],["6.2827","17.00"],["6.2828","17.00"],["6.2829","23.00"],["6.2830","18.00"],["6.2831","13.00"],["6.2832","20.00"],["6.2833","24.00"],["6.2834","23.00"],["6.2835","21.00"],["6.2836","20.00"],["6.2837","20.00"],["6.2838","15.00"],["6.2839","18.00"],["6.2840","26.00"],["6.2841","22.00"],["6.2842","23.00"],["6.2843","28.00"],["6.2844","24.00"],["6.2845","17.00"],["6.2846","19.00"],["6.2847","22.00"],["6.2848","18.00"],["6.2849","20.00"],["6.2850","16.00"],["6.2851","21.00"],["6.2852","31.00"],["6.2853","19.00"],["6.2854","27.00"],["6.2855","20.00"],["6.2856","21.00"],["6.2857","23.00"],["6.2858","17.00"],["6.2859","26.00"],["6.2860","20.00"],["6.2861","20.00"],["6.2862","21.00"],["6.2863","16.00"],["6.2864","22.00"],["6.2865","30.00"],["6.2866","18.00"],["6.2867","26.00"],["6.2868","22.00"],["6.2869","19.00"],["6.2870","27.00"],["6.2871","23.00"],["6.2872","24.00"],["6.2873","15.00"],["6.2874","4.00"],["6.2875","1.00"],["6.2876","5.00"],["6.2877","3.00"],["6.2878","3.00"],["6.2879","3.00"],["6.2880","2.00"],["6.2881","1.00"],["6.2882","4.00"],["6.2883","2.00"],["6.2885","5.00"],["6.2886","6.00"],["6.2887","2.00"],["6.2888","3.00"],["6.2889","5.00"],["6.2890","2.00"],["6.2891","1.00"],["6.2892","3.00"],["6.2893","2.00"],["6.2894","1.00"],["6.2895","7.00"],["6.2896","2.00"],["6.2897","5.00"],["6.2898","5.00"],["6.2899","1.00"],["6.2900","2.00"],["6.2901","2.00"],["6.2902","4.00"],["6.2903","7.00"],["6.2904","7.00"],["6.2905","3.00"],["6.2906","1.00"],["6.2907","1.00"],["6.2908","1.00"],["6.2909","3.00"],["6.2911","3.00"],["6.2912","3.00"],["6.2914","3.00"],["6.2915","2.00"],["6.2916","4.00"],["6.2917","6.00"],["6.2918","3.00"],["6.2919","3.00"],["6.2920","3.00"],["6.2921","2.00"],["6.2922","2.00"],["6.2923","4.00"],["6.2924","4.00"],["6.2925","3.00"],["6.2927","4.00"],["6.2928","5.00"],["6.2929","5.00"],["6.2930","5.00"],["6.2931","4.00"],["6.2932","1.00"],["6.2933","3.00"],["6.2934","2.00"],["6.2936","2.00"],["6.2937","3.00"],["6.2938","5.00"],["6.2939","5.00"],["6.2941","4.00"],["6.2942","2.00"],["6.2943","3.00"],["6.2944","5.00"],["6.2945","3.00"],["6.2947","5.00"],["6.2948","2.00"],["6.2949","3.00"],["6.2950","2.00"],["6.2951","2.00"],["6.2952","4.00"],["6.2953","1.00"],["6.2954","2.00"],["6.2955","4.00"],["6.2956","3.00"],["6.2957","3.00"],["6.2958","5.00"],["6.2959","4.00"],["6.2960","2.00"],["6.2961","5.00"],["6.2962","3.00"],["6.2963","4.00"],["6.2964","3.00"],["6.2965","6.00"],["6.2966","2.00"],["6.2967","5.00"],["6.2968","2.00"],["6.2969","1.00"],["6.2970","3.00"],["6.2971","4.00"],["6.2972","6.00"],["6.2973","3.00"],["6.2974","1.00"],["6.2975","5.00"],["6.2976","3.00"],["6.2977","5.00"],["6.2978","3.00"],["6.2979","7.00"],["6.2980","5.00"],["6.2981","1.00"],["6.2982","3.00"],["6.2983","3.00"],["6.2984","2.00"],["6.2985","6.00"],["6.2986","3.00"],["6.2987","1.00"],["6.2988","5.00"],["6.2989","3.00"],["6.2990","5.00"],["6.2991","3.00"],["6.2992","4.00"],["6.2993","3.00"],["6.2994","3.00"],["6.2995","6.00"],["6.2997","1.00"],["6.2998","5.00"],["6.2999","5.00"],["6.3000","1.00"],["6.3001","5.00"],["6.3002","5.00"],["6.3003","1.00"],["6.3004","8.00"],["6.3005","4.00"],["6.3006","2.00"],["6.3007","3.00"],["6.3008","1.00"],["6.3009","5.00"],["6.3010","3.00"],["6.3011","3.00"],["6.3012","3.00"],["6.3013","4.00"],["6.3014","3.00"],["6.3015","2.00"],["6.3016","8.00"],["6.3017","3.00"],["6.3019","2.00"],["6.3020","3.00"],["6.3021","3.00"],["6.3022","2.00"],["6.3023","4.00"],["6.3024","2.00"],["6.3025","2.00"],["6.3026","3.00"],["6.3027","6.00"],["6.3028","3.00"],["6.3029","1.00"],["6.3030","4.00"],["6.3031","3.00"],["6.3032","1.00"],["6.3033","4.00"],["6.3035","6.00"],["6.3036","2.00"],["6.3037","3.00"],["6.3038","5.00"],["6.3039","3.00"],["6.3040","3.00"],["6.3041","2.00"],["6.3042","1.00"],["6.3043","2.00"],["6.3044","2.00"],["6.3045","1.00"],["6.3046","4.00"],["6.3047","6.00"],["6.3048","4.00"],["6.3049","2.00"],["6.3050","4.00"],["6.3051","4.00"],["6.3052","2.00"],["6.3053","5.00"],["6.3054","4.00"],["6.3056","2.00"],["6.3057","2.00"],["6.3058","4.00"],["6.3059","4.00"],["6.3060","6.00"],["6.3061","6.00"],["6.3062","1.00"],["6.3063","5.00"],["6.3064","4.00"],["6.3065","2.00"],["6.3066","2.00"],["6.3067","3.00"],["6.3068","6.00"],["6.3069","3.00"],["6.3070","6.00"],["6.3071","2.00"],["6.3072","4.00"],["6.3073","2.00"],["6.3074","2.00"],["6.3075","4.00"],["6.3076","5.00"],["6.3077","1.00"],["6.3078","2.00"],["6.3079","3.00"],["6.3080","4.00"],["6.3081","2.00"],["6.3082","1.00"],["6.3083","5.00"],["6.3085","3.00"],["6.3086","4.00"],["6.3087","1.00"],["6.3088","3.00"],["6.3089","4.00"],["6.3090","2.00"],["6.3092","3.00"],["6.3093","5.00"],["6.3094","3.00"],["6.3095","5.00"],["6.3096","2.00"],["6.3097","1.00"],["6.3098","2.00"],["6.3099","1.00"],["6.3100","3.00"],["6.3101","4.00"],["6.3102","2.00"],["6.3103","6.00"],["6.3104","5.00"],["6.3105","4.00"],["6.3106","5.00"],["6.3107","1.00"],["6.3108","1.00"],["6.3109","2.00"],["6.3110","1.00"],["6.3111","3.00"],["6.3112","4.00"],["6.3113","5.00"],["6.3114","3.00"],["6.3115","2.00"],["6.3116","7.00"],["6.3117","2.00"],["6.3118","5.00"],["6.3119","2.00"],["6.3120","3.00"],["6.3121","3.00"],["6.3122","5.00"],["6.3123","2.00"],["6.3124","5.00"],["6.3125","3.00"],["6.3126","4.00"],["6.3127","3.00"],["6.3128","3.00"],["6.3129","6.00"],["6.3130","6.00"],["6.3132","2.00"],["6.3133","4.00"],["6.3134","2.00"],["6.3135","2.00"],["6.3136","1.00"],["6.3137","4.00"],["6.3138","1.00"],["6.3139","5.00"],["6.3140","2.00"],["6.3141","2.00"],["6.3142","1.00"],["6.3143","3.00"],["6.3144","1.00"],["6.3145","2.00"],["6.3146","2.00"],["6.3148","3.00"],["6.3149","1.00"],["6.3150","4.00"],["6.3151","6.00"],["6.3152","1.00"],["6.3153","4.00"],["6.3154","5.00"],["6.3155","1.00"],["6.3156","5.00"],["6.3158","1.00"],["6.3159","1.00"],["6.3160","5.00"],["6.3161","2.00"],["6.3162","1.00"],["6.3163","3.00"],["6.3164","2.00"],["6.3166","3.00"],["6.3167","6.00"],["6.3168","5.00"],["6.3169","5.00"],["6.3170","1.00"],["6.3171","6.00"],["6.3172","2.00"],["6.3173","1.00"],["6.3174","2.00"],["6.3175","4.00"],["6.3176","3.00"],["6.3177","5.00"],["6.3178","2.00"],["6.3179","4.00"],["6.3180","6.00"],["6.3181","4.00"],["6.3182","4.00"],["6.3183","2.00"],["6.3184","2.00"],["6.3185","4.00"],["6.3186","2.00"],["6.3187","3.00"],["6.3188","1.00"],["6.3189","5.00"],["6.3190","7.00"],["6.3191","4.00"],["6.3192","3.00"],["6.3193","5.00"],["6.3194","5.00"],["6.3195","1.00"],["6.3196","6.00"],["6.3197","3.00"],["6.3198","2.00"],["6.3199","5.00"],["6.3200","7.00"],["6.3201","5.00"],["6.3202","4.00"],["6.3203","4.00"],["6.3204","1.00"],["6.3205","5.00"],["6.3206","2.00"],["6.3207","2.00"],["6.3208","1.00"],["6.3209","5.00"],["6.3210","2.00"],["6.3211","1.00"],["6.3212","3.00"],["6.3213","4.00"],["6.3214","4.00"],["6.3215","4.00"],["6.3216","3.00"],["6.3217","3.00"],["6.3218","1.00"],["6.3219","2.00"],["6.3220","5.00"],["6.3221","3.00"],["6.3222","2.00"],["6.3223","4.00"],["6.3224","2.00"],["6.3225","6.00"],["6.3226","4.00"],["6.3227","8.00"],["6.3228","3.00"],["6.3229","5.00"],["6.3230","3.00"],["6.3231","2.00"],["6.3232","3.00"],["6.3233","2.00"],["6.3234","2.00"],["6.3235","5.00"],["6.3236","5.00"],["6.3237","2.00"],["6.3238","1.00"],["6.3239","3.00"],["6.3240","2.00"],["6.3241","1.00"],["6.3242","3.00"],["6.3243","3.00"],["6.3244","3.00"],["6.3245","2.00"],["6.3246","2.00"],["6.3248","3.00"],["6.3249","3.00"],["6.3250","1.00"],["6.3251","2.00"],["6.3252","5.00"],["6.3253","2.00"],["6.3254","3.00"],["6.3255","2.00"],["6.3256","4.00"],["6.3257","5.00"],["6.3258","1.00"],["6.3259","5.00"],["6.3260","4.00"],["6.3261","5.00"],["6.3262","3.00"],["6.3263","6.00"],["6.3264","2.00"],["6.3265","3.00"],["6.3266","7.00"],["6.3267","6.00"],["6.3268","4.00"],["6.3269","1.00"],["6.3270","3.00"],["6.3271","4.00"],["6.3272","6.00"],["6.3273","5.00"],["6.3274","2.00"],["6.3275","3.00"],["6.3276","3.00"],["6.3277","6.00"],["6.3278","6.00"],["6.3279","5.00"],["6.3280","2.00"],["6.3281","2.00"],["6.3282","2.00"],["6.3283","1.00"],["6.3284","2.00"],["6.3285","2.00"],["6.3287","2.00"],["6.3288","2.00"],["6.3289","2.00"],["6.3290","2.00"],["6.3291","11.00"],["6.3292","2.00"],["6.3293","3.00"],["6.3294","1.00"],["6.3295","1.00"],["6.3296","3.00"],["6.3297","3.00"],["6.3298","4.00"],["6.3299","1.00"],["6.3300","4.00"],["6.3301","3.00"],["6.3302","4.00"],["6.3303","2.00"],["6.3304","1.00"],["6.3305","5.00"],["6.3306","1.00"],["6.3307","2.00"],["6.3308","1.00"],["6.3309","3.00"],["6.3310","5.00"],["6.3311","2.00"],["6.3312","5.00"],["6.3313","1.00"],["6.3314","4.00"],["6.3315","3.00"],["6.3316","5.00"],["6.3317","4.00"],["6.3318","5.00"],["6.3319","3.00"],["6.3320","4.00"],["6.3321","3.00"],["6.3322","2.00"],["6.3323","5.00"],["6.3324","2.00"],["6.3325","1.00"],["6.3326","4.00"],["6.3327","1.00"],["6.3328","7.00"],["6.3329","3.00"],["6.3330","1.00"],["6.3331","1.00"],["6.3333","5.00"],["6.3334","7.00"],["6.3335","1.00"],["6.3336","1.00"],["6.3337","3.00"],["6.3338","2.00"],["6.3339","6.00"],["6.3340","3.00"],["6.3341","3.00"],["6.3342","5.00"],["6.3343","1.00"],["6.3344","3.00"],["6.3345","1.00"],["6.3346","4.00"],["6.3347","2.00"],["6.3348","8.00"],["6.3349","3.00"],["6.3350","4.00"],["6.3351","3.00"],["6.3352","1.00"],["6.3353","3.00"],["6.3354","3.00"],["6.3355","2.00"],["6.3356","4.00"],["6.3357","3.00"],["6.3358","2.00"],["6.3359","2.00"],["6.3361","3.00"],["6.3362","2.00"],["6.3363","4.00"],["6.3364","795.00"],["6.3365","2.00"],["6.3366","2.00"],["6.3367","1.00"],["6.3368","1.00"],["6.3369","3.00"],["6.3370","3.00"],["6.3371","2.00"],["6.3372","3.00"],["6.3373","3.00"],["6.3374","4.00"],["6.3375","1.00"],["6.3376","1.00"],["6.3377","1.00"],["6.3378","2.00"],["6.3379","3.00"],["6.3380","5.00"],["6.3381","4.00"],["6.3382","5.00"],["6.3383","3.00"],["6.3384","2.00"],["6.3385","2.00"],["6.3386","792.00"],["6.3387","1.00"],["6.3388","4.00"],["6.3389","1.00"],["6.3390","3.00"],["6.3391","1.00"],["6.3392","1.00"],["6.3394","2.00"],["6.3395","2.00"],["6.3396","4.00"],["6.3397","3.00"],["6.3398","1.00"],["6.3399","4.00"],["6.3400","1.00"],["6.3401","6.00"],["6.3403","4.00"],["6.3404","6.00"],["6.3405","1.00"],["6.3406","7.00"],["6.3407","4.00"],["6.3408","792.00"],["6.3409","1.00"],["6.3410","5.00"],["6.3411","3.00"],["6.3412","4.00"],["6.3413","1.00"],["6.3414","3.00"],["6.3415","3.00"],["6.3416","6.00"],["6.3417","3.00"],["6.3418","4.00"],["6.3419","1.00"],["6.3420","2.00"],["6.3421","3.00"],["6.3422","2.00"],["6.3423","4.00"],["6.3424","1.00"],["6.3425","4.00"],["6.3426","2.00"],["6.3427","2.00"],["6.3428","5.00"],["6.3429","3.00"],["6.3430","793.00"],["6.3431","4.00"],["6.3432","2.00"],["6.3433","1.00"],["6.3435","4.00"],["6.3436","5.00"],["6.3438","2.00"],["6.3439","1.00"],["6.3440","2.00"],["6.3441","4.00"],["6.3442","5.00"],["6.3443","1.00"],["6.3444","5.00"],["6.3445","2.00"],["6.3446","2.00"],["6.3447","1.00"],["6.3449","4.00"],["6.3450","1.00"],["6.3451","4.00"],["6.3452","791.00"],["6.3453","3.00"],["6.3454","3.00"],["6.3455","2.00"],["6.3456","2.00"],["6.3457","5.00"],["6.3458","4.00"],["6.3459","4.00"],["6.3460","4.00"],["6.3461","3.00"],["6.3462","4.00"],["6.3463","1.00"],["6.3464","3.00"],["6.3465","8.00"],["6.3466","6.00"],["6.3467","2.00"],["6.3468","4.00"],["6.3469","6.00"],["6.3470","4.00"],["6.3471","4.00"],["6.3472","3.00"],["6.3473","4.00"],["6.3474","790.00"],["6.3475","5.00"],["6.3476","3.00"],["6.3478","2.00"],["6.3479","2.00"],["6.3480","1.00"],["6.3481","2.00"],["6.3483","1.00"],["6.3484","7.00"],["6.3486","3.00"],["6.3487","1.00"],["6.3488","11.00"],["6.3489","3.00"],["6.3491","5.00"],["6.3492","4.00"],["6.3493","3.00"],["6.3494","3.00"],["6.3495","3.00"],["6.3496","789.00"],["6.3497","5.00"],["6.3498","2.00"],["6.3499","3.00"],["6.3500","3.00"],["6.3501","3.00"],["6.3502","2.00"],["6.3503","2.00"],["6.3504","2.00"],["6.3505","2.00"],["6.3506","2.00"],["6.3507","3.00"],["6.3508","5.00"],["6.3509","4.00"],["6.3510","1.00"],["6.3511","4.00"],["6.3512","5.00"],["6.3513","3.00"],["6.3514","2.00"],["6.3515","2.00"],["6.3516","3.00"],["6.3517","2.00"],["6.3518","789.00"],["6.3519","3.00"],["6.3520","1.00"],["6.3521","4.00"],["6.3522","3.00"],["6.3523","4.00"],["6.3524","3.00"],["6.3525","3.00"],["6.3526","5.00"],["6.3527","3.00"],["6.3528","4.00"],["6.3530","3.00"],["6.3531","1.00"],["6.3533","3.00"],["6.3534","2.00"],["6.3535","3.00"],["6.3536","3.00"],["6.3537","2.00"],["6.3538","5.00"],["6.3539","5.00"],["6.3540","792.00"],["6.3541","4.00"],["6.3542","1.00"],["6.3543","2.00"],["6.3544","3.00"],["6.3545","3.00"],["6.3546","3.00"],["6.3547","5.00"],["6.3548","2.00"],["6.3549","7.00"],["6.3550","4.00"],["6.3551","1.00"],["6.3552","2.00"],["6.3553","4.00"],["6.3554","5.00"],["6.3555","1.00"],["6.3556","2.00"],["6.3557","4.00"],["6.3558","4.00"],["6.3559","2.00"],["6.3560","1.00"],["6.3561","3.00"],["6.3562","526.00"],["6.3563","2.00"],["6.3564","4.00"],["6.3565","3.00"],["6.3566","2.00"],["6.3567","2.00"],["6.3568","4.00"],["6.3569","2.00"],["6.3570","4.00"],["6.3571","2.00"],["6.3572","3.00"],["6.3573","5.00"],["6.3574","1.00"],["6.3575","4.00"],["6.3576","4.00"],["6.3577","4.00"],["6.3578","3.00"],["6.3579","2.00"],["6.3580","4.00"],["6.3581","2.00"],["6.3582","3.00"],["6.3583","1.00"],["6.3584","1.00"],["6.3585","2.00"],["6.3586","3.00"],["6.3587","1.00"],["6.3588","4.00"],["6.3589","3.00"],["6.3590","1.00"],["6.3591","135.00"],["6.3592","3.00"],["6.3593","4.00"],["6.3594","5.00"],["6.3595","1.00"],["6.3596","3.00"],["6.3597","6.00"],["6.3598","2.00"],["6.3599","2.00"],["6.3602","3.00"],["6.3603","4.00"],["6.3604","2.00"],["6.3605","4.00"],["6.3606","4.00"],["6.3608","3.00"],["6.3609","1.00"],["6.3610","4.00"],["6.3611","1.00"],["6.3612","3.00"],["6.3613","3.00"],["6.3614","5.00"],["6.3615","1.00"],["6.3616","3.00"],["6.3617","3.00"],["6.3618","2.00"],["6.3619","2.00"],["6.3620","5.00"],["6.3621","1.00"],["6.3622","1.00"],["6.3623","4.00"],["6.3624","5.00"],["6.3625","3.00"],["6.3626","2.00"],["6.3627","1.00"],["6.3628","2.00"],["6.3629","2.00"],["6.3630","3.00"],["6.3631","2.00"],["6.3632","4.00"],["6.3633","1.00"],["6.3634","6.00"],["6.3635","3.00"],["6.3636","4.00"],["6.3637","2.00"],["6.3638","2.00"],["6.3639","6.00"],["6.3640","2.00"],["6.3641","2.00"],["6.3642","4.00"],["6.3643","2.00"],["6.3645","12.00"],["6.3646","10.00"],["6.3649","1.00"],["6.3652","1.00"],["6.3661","1.00"],["6.3662","534.00"]],"ask":[["7.6637","9.00"],["7.6635","1.00"],["7.6633","3.00"],["7.6631","2.00"],["7.6629","3.00"],["7.6627","3.00"],["7.6625","2.00"],["7.6623","2.00"],["7.6621","1.00"],["7.6619","3.00"],["7.6617","2.00"],["7.6611","1.00"],["7.6609","1.00"],["7.6515","1.00"],["7.6511","3.00"],["7.6505","1.00"],["7.6501","1.00"],["7.6307","2.00"],["7.6305","1.00"],["7.6303","3.00"],["7.6301","1.00"],["7.6299","2.00"],["7.6295","2.00"],["7.6061","5.00"],["7.6059","1.00"],["7.6057","3.00"],["7.6055","1.00"],["7.6053","1.00"],["7.6045","1.00"],["7.6041","1.00"],["7.6039","3.00"],["7.6037","1.00"],["7.6035","1.00"],["7.6031","2.00"],["7.5819","1.00"],["7.5649","1.00"],["7.5647","2.00"],["7.5641","1.00"],["7.5631","1.00"],["7.5629","2.00"],["7.5627","3.00"],["7.5623","2.00"],["7.5619","1.00"],["7.5073","2.00"],["7.5069","2.00"],["7.5065","2.00"],["7.5063","1.00"],["7.4989","2.00"],["7.4987","3.00"],["7.4983","1.00"],["7.4963","2.00"],["7.4961","3.00"],["7.4959","3.00"],["7.4957","1.00"],["7.4955","3.00"],["7.4953","3.00"],["7.4951","1.00"],["7.4949","1.00"],["7.4947","1.00"],["7.4945","2.00"],["7.4943","2.00"],["7.4941","1.00"],["7.4939","3.00"],["7.3777","1.00"],["7.3775","2.00"],["7.3773","3.00"],["7.3729","7.00"],["6.9664","61.00"],["6.8416","1.00"],["6.5485","1.00"],["6.5443","1.00"],["6.5439","1.00"],["6.5318","1.00"],["6.5286","1.00"],["6.5268","1.00"],["6.5256","1.00"],["6.5250","1.00"],["6.5209","3.00"],["6.5199","1.00"],["6.5192","3.00"],["6.5182","1.00"],["6.5171","1.00"],["6.5164","3.00"],["6.5147","3.00"],["6.5131","1.00"],["6.5130","1.00"],["6.5124","3.00"],["6.5111","3.00"],["6.5100","1.00"],["6.5091","1.00"],["6.5078","3.00"],["6.5077","1.00"],["6.5068","2.00"],["6.5067","1.00"],["6.5066","1.00"],["6.5065","1.00"],["6.5061","1.00"],["6.5056","1.00"],["6.5045","2.00"],["6.5044","3.00"],["6.5026","1.00"],["6.5018","2.00"],["6.5001","1.00"],["6.4998","3.00"],["6.4993","1.00"],["6.4992","2.00"],["6.4987","1.00"],["6.4986","3.00"],["6.4974","1.00"],["6.4970","1.00"],["6.4968","1.00"],["6.4966","1.00"],["6.4964","1.00"],["6.4961","1.00"],["6.4960","1.00"],["6.4959","1.00"],["6.4957","1.00"],["6.4956","2.00"],["6.4955","1.00"],["6.4954","1.00"],["6.4949","1.00"],["6.4948","3.00"],["6.4946","2.00"],["6.4945","1.00"],["6.4944","4.00"],["6.4941","1.00"],["6.4939","1.00"],["6.4938","2.00"],["6.4937","2.00"],["6.4936","1.00"],["6.4935","1.00"],["6.4934","1.00"],["6.4933","5.00"],["6.4932","2.00"],["6.4931","1.00"],["6.4930","3.00"],["6.4929","1.00"],["6.4928","3.00"],["6.4927","1.00"],["6.4926","1.00"],["6.4925","1.00"],["6.4924","3.00"],["6.4923","4.00"],["6.4922","3.00"],["6.4921","1.00"],["6.4920","2.00"],["6.4919","6.00"],["6.4918","2.00"],["6.4917","4.00"],["6.4916","6.00"],["6.4915","3.00"],["6.4914","3.00"],["6.4913","1.00"],["6.4912","6.00"],["6.4911","4.00"],["6.4910","2.00"],["6.4909","4.00"],["6.4908","6.00"],["6.4907","4.00"],["6.4906","3.00"],["6.4905","6.00"],["6.4904","2.00"],["6.4903","8.00"],["6.4902","5.00"],["6.4901","3.00"],["6.4900","3.00"],["6.4899","2.00"],["6.4898","7.00"],["6.4897","3.00"],["6.4896","3.00"],["6.4895","4.00"],["6.4894","2.00"],["6.4893","4.00"],["6.4892","5.00"],["6.4891","4.00"],["6.4890","4.00"],["6.4889","7.00"],["6.4888","4.00"],["6.4887","1.00"],["6.4886","8.00"],["6.4885","6.00"],["6.4884","5.00"],["6.4883","4.00"],["6.4882","6.00"],["6.4881","1.00"],["6.4880","3.00"],["6.4879","3.00"],["6.4878","8.00"],["6.4877","5.00"],["6.4876","6.00"],["6.4875","6.00"],["6.4874","3.00"],["6.4873","5.00"],["6.4872","5.00"],["6.4871","8.00"],["6.4870","7.00"],["6.4869","4.00"],["6.4868","1.00"],["6.4867","4.00"],["6.4866","4.00"],["6.4865","5.00"],["6.4864","3.00"],["6.4863","3.00"],["6.4862","2.00"],["6.4861","7.00"],["6.4860","4.00"],["6.4859","3.00"],["6.4858","2.00"],["6.4857","6.00"],["6.4856","2.00"],["6.4855","5.00"],["6.4854","4.00"],["6.4853","7.00"],["6.4852","5.00"],["6.4851","4.00"],["6.4850","6.00"],["6.4849","4.00"],["6.4848","9.00"],["6.4847","6.00"],["6.4846","8.00"],["6.4845","3.00"],["6.4844","4.00"],["6.4843","6.00"],["6.4842","4.00"],["6.4841","9.00"],["6.4840","9.00"],["6.4839","4.00"],["6.4838","5.00"],["6.4837","6.00"],["6.4836","6.00"],["6.4835","7.00"],["6.4834","6.00"],["6.4833","5.00"],["6.4832","9.00"],["6.4831","5.00"],["6.4830","8.00"],["6.4829","3.00"],["6.4828","9.00"],["6.4827","8.00"],["6.4826","14.00"],["6.4825","10.00"],["6.4824","11.00"],["6.4823","7.00"],["6.4822","8.00"],["6.4821","10.00"],["6.4820","12.00"],["6.4819","8.00"],["6.4818","6.00"],["6.4817","7.00"],["6.4816","10.00"],["6.4815","4.00"],["6.4814","12.00"],["6.4813","13.00"],["6.4812","9.00"],["6.4811","8.00"],["6.4810","8.00"],["6.4809","11.00"],["6.4808","11.00"],["6.4807","9.00"],["6.4806","9.00"],["6.4805","5.00"],["6.4804","11.00"],["6.4803","4.00"],["6.4802","8.00"],["6.4801","12.00"],["6.4800","13.00"],["6.4799","8.00"],["6.4798","9.00"],["6.4797","8.00"],["6.4796","23.00"],["6.4795","16.00"],["6.4794","8.00"],["6.4793","13.00"],["6.4792","9.00"],["6.4791","17.00"],["6.4790","14.00"],["6.4789","19.00"],["6.4788","10.00"],["6.4787","8.00"],["6.4786","7.00"],["6.4785","17.00"],["6.4784","11.00"],["6.4783","8.00"],["6.4782","7.00"],["6.4781","23.00"],["6.4780","6.00"],["6.4779","10.00"],["6.4778","8.00"],["6.4777","9.00"],["6.4776","11.00"],["6.4775","10.00"],["6.4774","9.00"],["6.4773","14.00"],["6.4772","12.00"],["6.4771","11.00"],["6.4770","8.00"],["6.4769","14.00"],["6.4768","15.00"],["6.4767","10.00"],["6.4766","12.00"],["6.4765","12.00"],["6.4764","12.00"],["6.4763","11.00"],["6.4762","13.00"],["6.4761","14.00"],["6.4760","12.00"],["6.4759","10.00"],["6.4758","9.00"],["6.4757","12.00"],["6.4756","13.00"],["6.4755","6.00"],["6.4754","17.00"],["6.4753","8.00"],["6.4752","8.00"],["6.4751","11.00"],["6.4750","20.00"],["6.4749","15.00"],["6.4748","18.00"],["6.4747","14.00"],["6.4746","9.00"],["6.4745","12.00"],["6.4744","8.00"],["6.4743","13.00"],["6.4742","8.00"],["6.4741","13.00"],["6.4740","18.00"],["6.4739","18.00"],["6.4738","14.00"],["6.4737","21.00"],["6.4736","13.00"],["6.4735","16.00"],["6.4734","13.00"],["6.4733","17.00"],["6.4732","12.00"],["6.4731","21.00"],["6.4730","17.00"],["6.4729","17.00"],["6.4728","17.00"],["6.4727","15.00"],["6.4726","12.00"],["6.4725","13.00"],["6.4724","17.00"],["6.4723","12.00"],["6.4722","11.00"],["6.4721","18.00"],["6.4720","8.00"],["6.4719","10.00"],["6.4718","16.00"],["6.4717","13.00"],["6.4716","9.00"],["6.4715","10.00"],["6.4714","14.00"],["6.4713","13.00"],["6.4712","11.00"],["6.4711","13.00"],["6.4710","17.00"],["6.4709","13.00"],["6.4708","14.00"],["6.4707","22.00"],["6.4706","13.00"],["6.4705","10.00"],["6.4704","11.00"],["6.4703","13.00"],["6.4702","13.00"],["6.4701","19.00"],["6.4700","21.00"],["6.4699","9.00"],["6.4698","20.00"],["6.4697","21.00"],["6.4696","15.00"],["6.4695","18.00"],["6.4694","17.00"],["6.4693","16.00"],["6.4692","14.00"],["6.4691","15.00"],["6.4690","17.00"],["6.4689","16.00"],["6.4688","18.00"],["6.4687","14.00"],["6.4686","16.00"],["6.4685","11.00"],["6.4684","13.00"],["6.4683","13.00"],["6.4682","16.00"],["6.4681","14.00"],["6.4680","16.00"],["6.4679","13.00"],["6.4678","14.00"],["6.4677","13.00"],["6.4676","18.00"],["6.4675","16.00"],["6.4674","15.00"],["6.4673","20.00"],["6.4672","14.00"],["6.4671","13.00"],["6.4670","14.00"],["6.4669","16.00"],["6.4668","18.00"],["6.4667","10.00"],["6.4666","13.00"],["6.4665","24.00"],["6.4664","18.00"],["6.4663","21.00"],["6.4662","17.00"],["6.4661","16.00"],["6.4660","19.00"],["6.4659","19.00"],["6.4658","19.00"],["6.4657","15.00"],["6.4656","17.00"],["6.4655","14.00"],["6.4654","22.00"],["6.4653","21.00"],["6.4652","16.00"],["6.4651","22.00"],["6.4650","14.00"],["6.4649","18.00"],["6.4648","23.00"],["6.4647","33.00"],["6.4646","19.00"],["6.4645","21.00"],["6.4644","13.00"],["6.4643","25.00"],["6.4642","17.00"],["6.4641","17.00"],["6.4640","23.00"],["6.4639","15.00"],["6.4638","19.00"],["6.4637","26.00"],["6.4636","22.00"],["6.4635","20.00"],["6.4634","17.00"],["6.4633","17.00"],["6.4632","24.00"],["6.4631","12.00"],["6.4630","10.00"],["6.4629","30.00"],["6.4628","20.00"],["6.4627","16.00"],["6.4626","29.00"],["6.4625","19.00"],["6.4624","25.00"],["6.4623","16.00"],["6.4622","21.00"],["6.4621","23.00"],["6.4620","25.00"],["6.4619","20.00"],["6.4618","29.00"],["6.4617","25.00"],["6.4616","14.00"],["6.4615","17.00"],["6.4614","17.00"],["6.4613","19.00"],["6.4612","29.00"],["6.4611","15.00"],["6.4610","22.00"],["6.4609","28.00"],["6.4608","23.00"],["6.4607","19.00"],["6.4606","21.00"],["6.4605","11.00"],["6.4604","25.00"],["6.4603","23.00"],["6.4602","21.00"],["6.4601","16.00"],["6.4600","28.00"],["6.4599","24.00"],["6.4598","21.00"],["6.4597","15.00"],["6.4596","27.00"],["6.4595","21.00"],["6.4594","26.00"],["6.4593","10.00"],["6.4592","28.00"],["6.4591","16.00"],["6.4590","15.00"],["6.4589","21.00"],["6.4588","14.00"],["6.4587","17.00"],["6.4586","19.00"],["6.4585","16.00"],["6.4584","20.00"],["6.4583","23.00"],["6.4582","17.00"],["6.4581","18.00"],["6.4580","27.00"],["6.4579","21.00"],["6.4578","20.00"],["6.4577","15.00"],["6.4576","27.00"],["6.4575","28.00"],["6.4574","16.00"],["6.4573","21.00"],["6.4572","22.00"],["6.4571","25.00"],["6.4570","28.00"],["6.4569","25.00"],["6.4568","16.00"],["6.4567","25.00"],["6.4566","17.00"],["6.4565","23.00"],["6.4564","21.00"],["6.4563","23.00"],["6.4562","22.00"],["6.4561","19.00"],["6.4560","14.00"],["6.4559","24.00"],["6.4558","21.00"],["6.4557","25.00"],["6.4556","16.00"],["6.4555","26.00"],["6.4554","16.00"],["6.4553","21.00"],["6.4552","19.00"],["6.4551","26.00"],["6.4550","31.00"],["6.4549","20.00"],["6.4548","18.00"],["6.4547","23.00"],["6.4546","30.00"],["6.4545","26.00"],["6.4544","14.00"],["6.4543","21.00"],["6.4542","18.00"],["6.4541","29.00"],["6.4540","16.00"],["6.4539","15.00"],["6.4538","20.00"],["6.4537","24.00"],["6.4536","32.00"],["6.4535","18.00"],["6.4534","23.00"],["6.4533","25.00"],["6.4532","21.00"],["6.4531","15.00"],["6.4530","26.00"],["6.4529","15.00"],["6.4528","26.00"],["6.4527","20.00"],["6.4526","22.00"],["6.4525","23.00"],["6.4524","21.00"],["6.4523","24.00"],["6.4522","21.00"],["6.4521","23.00"],["6.4520","16.00"],["6.4519","18.00"],["6.4518","30.00"],["6.4517","17.00"],["6.4516","17.00"],["6.4515","14.00"],["6.4514","17.00"],["6.4513","23.00"],["6.4512","24.00"],["6.4511","12.00"],["6.4510","27.00"],["6.4509","23.00"],["6.4508","18.00"],["6.4507","12.00"],["6.4506","21.00"],["6.4505","21.00"],["6.4504","24.00"],["6.4503","35.00"],["6.4502","22.00"],["6.4501","25.00"],["6.4500","24.00"],["6.4499","20.00"],["6.4498","19.00"],["6.4497","21.00"],["6.4496","17.00"],["6.4495","26.00"],["6.4494","20.00"],["6.4493","26.00"],["6.4492","13.00"],["6.4491","24.00"],["6.4490","24.00"],["6.4489","32.00"],["6.4488","18.00"],["6.4487","30.00"],["6.4486","27.00"],["6.4485","30.00"],["6.4484","30.00"],["6.4483","20.00"],["6.4482","20.00"],["6.4481","19.00"],["6.4480","27.00"],["6.4479","21.00"],["6.4478","23.00"],["6.4477","24.00"],["6.4476","12.00"],["6.4475","18.00"],["6.4474","22.00"],["6.4473","20.00"],["6.4472","17.00"],["6.4471","13.00"],["6.4470","21.00"],["6.4469","18.00"],["6.4468","17.00"],["6.4467","12.00"],["6.4466","31.00"],["6.4465","27.00"],["6.4464","33.00"],["6.4463","31.00"],["6.4462","21.00"],["6.4461","15.00"],["6.4460","17.00"],["6.4459","19.00"],["6.4458","22.00"],["6.4457","20.00"],["6.4456","13.00"],["6.4455","17.00"],["6.4454","19.00"],["6.4453","35.00"],["6.4452","14.00"],["6.4451","19.00"],["6.4450","18.00"],["6.4449","23.00"],["6.4448","22.00"],["6.4447","22.00"],["6.4446","16.00"],["6.4445","17.00"],["6.4444","21.00"],["6.4443","13.00"],["6.4442","14.00"],["6.4441","23.00"],["6.4440","17.00"],["6.4439","16.00"],["6.4438","28.00"],["6.4437","22.00"],["6.4436","27.00"],["6.4435","17.00"],["6.4434","23.00"],["6.4433","23.00"],["6.4432","24.00"],["6.4431","21.00"],["6.4430","24.00"],["6.4429","34.00"],["6.4428","17.00"],["6.4427","25.00"],["6.4426","14.00"],["6.4425","24.00"],["6.4424","17.00"],["6.4423","25.00"],["6.4422","17.00"],["6.4421","13.00"],["6.4420","23.00"],["6.4419","26.00"],["6.4418","22.00"],["6.4417","19.00"],["6.4416","25.00"],["6.4415","20.00"],["6.4414","20.00"],["6.4413","22.00"],["6.4412","24.00"],["6.4411","26.00"],["6.4410","24.00"],["6.4409","25.00"],["6.4408","18.00"],["6.4407","26.00"],["6.4406","24.00"],["6.4405","27.00"],["6.4404","23.00"],["6.4403","22.00"],["6.4402","33.00"],["6.4401","20.00"],["6.4400","16.00"],["6.4399","11.00"],["6.4398","22.00"],["6.4397","25.00"],["6.4396","18.00"],["6.4395","24.00"],["6.4394","20.00"],["6.4393","23.00"],["6.4392","25.00"],["6.4391","22.00"],["6.4390","24.00"],["6.4389","17.00"],["6.4388","17.00"],["6.4387","19.00"],["6.4386","18.00"],["6.4385","18.00"],["6.4384","18.00"],["6.4383","29.00"],["6.4382","23.00"],["6.4381","17.00"],["6.4380","29.00"],["6.4379","19.00"],["6.4378","21.00"],["6.4377","26.00"],["6.4376","19.00"],["6.4375","18.00"],["6.4374","10.00"],["6.4373","20.00"],["6.4372","20.00"],["6.4371","19.00"],["6.4370","20.00"],["6.4369","25.00"],["6.4368","23.00"],["6.4367","21.00"],["6.4366","23.00"],["6.4365","21.00"],["6.4364","17.00"],["6.4363","14.00"],["6.4362","20.00"],["6.4361","20.00"],["6.4360","26.00"],["6.4359","27.00"],["6.4358","26.00"],["6.4357","30.00"],["6.4356","30.00"],["6.4355","18.00"],["6.4354","17.00"],["6.4353","17.00"],["6.4352","21.00"],["6.4351","18.00"],["6.4350","31.00"],["6.4349","23.00"],["6.4348","20.00"],["6.4347","20.00"],["6.4346","28.00"],["6.4345","27.00"],["6.4344","17.00"],["6.4343","26.00"],["6.4342","24.00"],["6.4341","26.00"],["6.4340","21.00"],["6.4339","21.00"],["6.4338","26.00"],["6.4337","32.00"],["6.4336","18.00"],["6.4335","34.00"],["6.4334","31.00"],["6.4333","26.00"],["6.4332","24.00"],["6.4331","22.00"],["6.4330","16.00"],["6.4329","16.00"],["6.4328","26.00"],["6.4327","24.00"],["6.4326","19.00"],["6.4325","19.00"],["6.4324","12.00"],["6.4323","18.00"],["6.4322","18.00"],["6.4321","24.00"],["6.4320","21.00"],["6.4319","21.00"],["6.4318","22.00"],["6.4317","17.00"],["6.4316","23.00"],["6.4315","24.00"],["6.4314","16.00"],["6.4313","21.00"],["6.4312","22.00"],["6.4311","29.00"],["6.4310","24.00"],["6.4309","17.00"],["6.4308","35.00"],["6.4307","25.00"],["6.4306","26.00"],["6.4305","15.00"],["6.4304","24.00"],["6.4303","18.00"],["6.4302","23.00"],["6.4301","26.00"],["6.4300","34.00"],["6.4299","26.00"],["6.4298","16.00"],["6.4297","17.00"],["6.4296","20.00"],["6.4295","24.00"],["6.4294","21.00"],["6.4293","29.00"],["6.4292","19.00"],["6.4291","16.00"],["6.4290","23.00"],["6.4289","25.00"],["6.4288","29.00"],["6.4287","26.00"],["6.4286","12.00"],["6.4285","19.00"],["6.4284","25.00"],["6.4283","28.00"],["6.4282","19.00"],["6.4281","29.00"],["6.4280","18.00"],["6.4279","28.00"],["6.4278","21.00"],["6.4277","24.00"],["6.4276","25.00"],["6.4275","19.00"],["6.4274","19.00"],["6.4273","11.00"],["6.4272","22.00"],["6.4271","23.00"],["6.4270","20.00"],["6.4269","24.00"],["6.4268","22.00"],["6.4267","27.00"],["6.4266","23.00"],["6.4265","21.00"],["6.4264","16.00"],["6.4263","34.00"],["6.4262","19.00"],["6.4261","21.00"],["6.4260","24.00"],["6.4259","28.00"],["6.4258","20.00"],["6.4257","15.00"],["6.4256","19.00"],["6.4255","21.00"],["6.4254","32.00"],["6.4253","17.00"],["6.4252","24.00"],["6.4251","24.00"],["6.4250","29.00"],["6.4249","17.00"],["6.4248","19.00"],["6.4247","23.00"],["6.4246","20.00"],["6.4245","18.00"],["6.4244","18.00"],["6.4243","21.00"],["6.4242","27.00"],["6.4241","18.00"],["6.4240","14.00"],["6.4239","32.00"],["6.4238","31.00"],["6.4237","25.00"],["6.4236","20.00"],["6.4235","22.00"],["6.4234","22.00"],["6.4233","31.00"],["6.4232","27.00"],["6.4231","16.00"],["6.4230","20.00"],["6.4229","13.00"],["6.4228","20.00"],["6.4227","16.00"],["6.4226","26.00"],["6.4225","17.00"],["6.4224","23.00"],["6.4223","28.00"],["6.4222","27.00"],["6.4221","15.00"],["6.4220","27.00"],["6.4219","24.00"],["6.4218","17.00"],["6.4217","17.00"],["6.4216","21.00"],["6.4215","24.00"],["6.4214","17.00"],["6.4213","22.00"],["6.4212","35.00"],["6.4211","14.00"],["6.4210","29.00"],["6.4209","13.00"],["6.4208","17.00"],["6.4207","14.00"],["6.4206","23.00"],["6.4205","20.00"],["6.4204","24.00"],["6.4203","16.00"],["6.4202","24.00"],["6.4201","21.00"],["6.4200","21.00"],["6.4199","31.00"],["6.4198","21.00"],["6.4197","21.00"],["6.4196","18.00"],["6.4195","21.00"],["6.4194","19.00"],["6.4193","23.00"],["6.4192","17.00"],["6.4191","21.00"],["6.4190","23.00"],["6.4189","24.00"],["6.4188","15.00"],["6.4187","25.00"],["6.4186","26.00"],["6.4185","29.00"],["6.4184","23.00"],["6.4183","23.00"],["6.4182","23.00"],["6.4181","18.00"],["6.4180","18.00"],["6.4179","25.00"],["6.4178","29.00"],["6.4177","27.00"],["6.4176","26.00"],["6.4175","22.00"],["6.4174","26.00"],["6.4173","24.00"],["6.4172","14.00"],["6.4171","13.00"],["6.4170","32.00"],["6.4169","11.00"],["6.4168","24.00"],["6.4167","14.00"],["6.4166","16.00"],["6.4165","26.00"],["6.4164","19.00"],["6.4163","15.00"],["6.4162","23.00"],["6.4161","27.00"],["6.4160","27.00"],["6.4159","25.00"],["6.4158","19.00"],["6.4157","18.00"],["6.4156","17.00"],["6.4155","18.00"],["6.4154","26.00"],["6.4153","21.00"],["6.4152","21.00"],["6.4151","13.00"],["6.4150","27.00"],["6.4149","30.00"],["6.4148","14.00"],["6.4147","14.00"],["6.4146","21.00"],["6.4145","18.00"],["6.4144","24.00"],["6.4143","22.00"],["6.4142","15.00"],["6.4141","22.00"],["6.4140","19.00"],["6.4139","15.00"],["6.4138","26.00"],["6.4137","22.00"],["6.4136","26.00"],["6.4135","32.00"],["6.4134","23.00"],["6.4133","25.00"],["6.4132","24.00"],["6.4131","19.00"],["6.4130","21.00"],["6.4129","24.00"],["6.4128","22.00"],["6.4127","21.00"],["6.4126","24.00"],["6.4125","19.00"],["6.4124","22.00"],["6.4123","16.00"],["6.4122","20.00"],["6.4121","19.00"],["6.4120","21.00"],["6.4119","20.00"],["6.4118","25.00"],["6.4117","20.00"],["6.4116","23.00"],["6.4115","23.00"],["6.4114","18.00"],["6.4113","27.00"],["6.4112","19.00"],["6.4111","21.00"],["6.4110","19.00"],["6.4109","18.00"],["6.4108","24.00"],["6.4107","28.00"],["6.4106","19.00"],["6.4105","16.00"],["6.4104","21.00"],["6.4103","22.00"],["6.4102","22.00"],["6.4101","27.00"],["6.4100","13.00"],["6.4099","19.00"],["6.4098","20.00"],["6.4097","19.00"],["6.4096","23.00"],["6.4095","18.00"],["6.4094","13.00"],["6.4093","18.00"],["6.4092","24.00"],["6.4091","20.00"],["6.4090","19.00"],["6.4089","17.00"],["6.4088","20.00"],["6.4087","16.00"],["6.4086","27.00"],["6.4085","19.00"],["6.4084","21.00"],["6.4083","23.00"],["6.4082","23.00"],["6.4081","31.00"],["6.4080","28.00"],["6.4079","23.00"],["6.4078","19.00"],["6.4077","18.00"],["6.4076","20.00"],["6.4075","26.00"],["6.4074","16.00"],["6.4073","21.00"],["6.4072","20.00"],["6.4071","18.00"],["6.4070","24.00"],["6.4069","18.00"],["6.4068","26.00"],["6.4067","20.00"],["6.4066","24.00"],["6.4065","21.00"],["6.4064","22.00"],["6.4063","26.00"],["6.4062","21.00"],["6.4061","19.00"],["6.4060","25.00"],["6.4059","20.00"],["6.4058","21.00"],["6.4057","22.00"],["6.4056","15.00"],["6.4055","31.00"],["6.4054","21.00"],["6.4053","18.00"],["6.4052","15.00"],["6.4051","22.00"],["6.4050","18.00"],["6.4049","23.00"],["6.4048","14.00"],["6.4047","22.00"],["6.4046","19.00"],["6.4045","18.00"],["6.4044","26.00"],["6.4043","22.00"],["6.4042","23.00"],["6.4041","24.00"],["6.4040","14.00"],["6.4039","19.00"],["6.4038","21.00"],["6.4037","19.00"],["6.4036","19.00"],["6.4035","23.00"],["6.4034","19.00"],["6.4033","22.00"],["6.4032","16.00"],["6.4031","24.00"],["6.4030","20.00"],["6.4029","20.00"],["6.4028","16.00"],["6.4027","16.00"],["6.4026","31.00"],["6.4025","21.00"],["6.4024","17.00"],["6.4023","24.00"],["6.4022","22.00"],["6.4021","28.00"],["6.4020","24.00"],["6.4019","16.00"],["6.4018","15.00"],["6.4017","14.00"],["6.4016","17.00"],["6.4015","24.00"],["6.4014","26.00"],["6.4013","21.00"],["6.4012","24.00"],["6.4011","21.00"],["6.4010","21.00"],["6.4009","20.00"],["6.4008","22.00"],["6.4007","25.00"],["6.4006","15.00"],["6.4005","23.00"],["6.4004","13.00"],["6.4003","20.00"],["6.4002","22.00"],["6.4001","21.00"],["6.4000","17.00"],["6.3999","19.00"],["6.3998","22.00"],["6.3997","18.00"],["6.3996","21.00"],["6.3995","24.00"],["6.3994","29.00"],["6.3993","20.00"],["6.3992","24.00"],["6.3991","21.00"],["6.3990","18.00"],["6.3989","25.00"],["6.3988","19.00"],["6.3987","23.00"],["6.3986","30.00"],["6.3985","18.00"],["6.3984","16.00"],["6.3983","32.00"],["6.3982","25.00"],["6.3981","19.00"],["6.3980","27.00"],["6.3979","19.00"],["6.3978","16.00"],["6.3977","24.00"],["6.3976","576.00"],["6.3975","27.00"],["6.3974","12.00"],["6.3973","20.00"],["6.3972","23.00"],["6.3971","28.00"],["6.3970","29.00"],["6.3969","25.00"],["6.3968","20.00"],["6.3967","22.00"],["6.3966","21.00"],["6.3965","22.00"],["6.3964","23.00"],["6.3963","24.00"],["6.3962","12.00"],["6.3961","24.00"],["6.3960","12.00"],["6.3959","7.00"],["6.3958","1.00"],["6.3954","135.00"],["6.3953","1.00"],["6.3952","1.00"],["6.3951","3.00"],["6.3950","1.00"],["6.3945","3.00"],["6.3942","1.00"],["6.3940","1.00"],["6.3935","1.00"],["6.3927","1.00"],["6.3925","1.00"],["6.3924","1.00"],["6.3918","2.00"],["6.3915","1.00"],["6.3911","1.00"],["6.3909","1.00"],["6.3903","10.00"],["6.3902","11.00"],["6.3878","783.00"],["6.3856","784.00"],["6.3834","784.00"],["6.3812","784.00"],["6.3790","784.00"],["6.3768","785.00"],["6.3746","784.00"],["6.3724","785.00"],["6.3702","785.00"],["6.3680","361.00"]]}}

{"type":"subscribed","id":2,"msg":{"channel":"ticker","sid":3}}

{"type":"orderbook_delta","sid":1,"seq":2,"msg":{"market_ticker":"KXBTCPERP1","price":"6.2330","delta":"1.00","side":"bid","ts_ms":1781237149507}}

{"type":"orderbook_delta","sid":1,"seq":3,"msg":{"market_ticker":"KXBTCPERP1","price":"6.1857","delta":"1.00","side":"bid","ts_ms":1781237149781}}

{"type":"orderbook_delta","sid":1,"seq":4,"msg":{"market_ticker":"KXBTCPERP1","price":"6.2571","delta":"1.00","side":"bid","ts_ms":1781237149834}}

{"type":"orderbook_delta","sid":1,"seq":5,"msg":{"market_ticker":"KXBTCPERP1","price":"6.3902","delta":"-11.00","side":"ask","ts_ms":1781237149933}}

{"type":"orderbook_delta","sid":1,"seq":6,"msg":{"market_ticker":"KXBTCPERP1","price":"6.3695","delta":"11.00","side":"ask","ts_ms":1781237149933}}

{"type":"orderbook_delta","sid":1,"seq":7,"msg":{"market_ticker":"KXBTCPERP1","price":"6.2755","delta":"1.00","side":"bid","ts_ms":1781237149985}}

{"type":"orderbook_delta","sid":1,"seq":8,"msg":{"market_ticker":"KXBTCPERP1","price":"6.3903","delta":"-10.00","side":"ask","ts_ms":1781237150034}}

{"type":"orderbook_delta","sid":1,"seq":9,"msg":{"market_ticker":"KXBTCPERP1","price":"6.3696","delta":"10.00","side":"ask","ts_ms":1781237150034}}

{"type":"orderbook_delta","sid":1,"seq":10,"msg":{"market_ticker":"KXBTCPERP1","price":"6.3224","delta":"-1.00","side":"bid","ts_ms":1781237150063}}

{"type":"orderbook_delta","sid":1,"seq":11,"msg":{"market_ticker":"KXBTCPERP1","price":"6.3724","delta":"1.00","side":"ask","ts_ms":1781237150112}}

{"type":"orderbook_delta","sid":1,"seq":12,"msg":{"market_ticker":"KXBTCPERP1","price":"6.3954","delta":"-135.00","side":"ask","ts_ms":1781237150135}}

{"type":"orderbook_delta","sid":1,"seq":13,"msg":{"market_ticker":"KXBTCPERP1","price":"6.3747","delta":"136.00","side":"ask","ts_ms":1781237150135}}

{"type":"orderbook_delta","sid":1,"seq":14,"msg":{"market_ticker":"KXBTCPERP1","price":"6.3662","delta":"-534.00","side":"bid","ts_ms":1781237150236}}

{"type":"orderbook_delta","sid":1,"seq":15,"msg":{"market_ticker":"KXBTCPERP1","price":"6.3512","delta":"535.00","side":"bid","ts_ms":1781237150236}}

{"type":"orderbook_delta","sid":1,"seq":16,"msg":{"market_ticker":"KXBTCPERP1","price":"6.3661","delta":"-1.00","side":"bid","ts_ms":1781237150264}}

{"type":"trade","sid":2,"seq":1,"msg":{"trade_id":"67c8b55d-b658-7cb8-9f5a-9feed294bc3e","market_ticker":"KXBTCPERP1","price":"6.3661","count":"1.00","taker_side":"ask","ts_ms":1781237150264}}

{"type":"orderbook_delta","sid":1,"seq":17,"msg":{"market_ticker":"KXBTCPERP1","price":"6.1837","delta":"1.00","side":"bid","ts_ms":1781237150354}}

{"type":"orderbook_delta","sid":1,"seq":18,"msg":{"market_ticker":"KXBTCPERP1","price":"6.3976","delta":"-537.00","side":"ask","ts_ms":1781237150438}}

{"type":"orderbook_delta","sid":1,"seq":19,"msg":{"market_ticker":"KXBTCPERP1","price":"6.3823","delta":"540.00","side":"ask","ts_ms":1781237150438}}

{"type":"orderbook_delta","sid":1,"seq":20,"msg":{"market_ticker":"KXBTCPERP1","price":"6.3652","delta":"-1.00","side":"bid","ts_ms":1781237150439}}

{"type":"trade","sid":2,"seq":2,"msg":{"trade_id":"d5104ca8-1712-439a-c17e-c66421d5ad26","market_ticker":"KXBTCPERP1","price":"6.3652","count":"1.00","taker_side":"ask","ts_ms":1781237150439}}

{"type":"orderbook_delta","sid":1,"seq":21,"msg":{"market_ticker":"KXBTCPERP1","price":"6.3680","delta":"-1.00","side":"ask","ts_ms":1781237150487}}

{"type":"trade","sid":2,"seq":3,"msg":{"trade_id":"485ed9c6-29d4-77fe-5ab3-9199c2dd95a1","market_ticker":"KXBTCPERP1","price":"6.3680","count":"1.00","taker_side":"bid","ts_ms":1781237150487}}

{"type":"ticker","sid":3,"msg":{"market_ticker":"KXBTCPERP1","price":"6.3329","bid":"6.3329","ask":"6.3416","bid_size_fp":"343.00","ask_size_fp":"658.00","last_trade_size_fp":"0.00","volume":"4179467045.00","volume_notional_value_dollars":"3245141294.960300","volume_24h":"1877080.00","volume_24h_notional_value_dollars":"11687174.591200","open_interest":"2332769.00","open_interest_notional_value_dollars":"14773192.800100","reference_price":{"price":"6.3418","ts_ms":1781237150000},"settlement_mark_price":{"price":"6.3805","ts_ms":1781237148040},"liquidation_mark_price":{"price":"6.3661","ts_ms":1781237150399},"funding_rate":{"rate":0,"next_funding_time_ms":1781265600000,"ts_ms":1781237148040},"ts_ms":1781217877584}}

{"type":"orderbook_delta","sid":1,"seq":22,"msg":{"market_ticker":"KXBTCPERP1","price":"6.3080","delta":"1.00","side":"bid","ts_ms":1781237150557}}

{"type":"orderbook_delta","sid":1,"seq":23,"msg":{"market_ticker":"KXBTCPERP1","price":"6.3926","delta":"1.00","side":"ask","ts_ms":1781237150724}}

{"type":"orderbook_delta","sid":1,"seq":24,"msg":{"market_ticker":"KXBTCPERP1","price":"6.4134","delta":"1.00","side":"ask","ts_ms":1781237150820}}

{"type":"orderbook_delta","sid":1,"seq":25,"msg":{"market_ticker":"KXBTCPERP1","price":"6.3628","delta":"-1.00","side":"bid","ts_ms":1781237150904}}

{"type":"orderbook_delta","sid":1,"seq":26,"msg":{"market_ticker":"KXBTCPERP1","price":"6.3378","delta":"1.00","side":"bid","ts_ms":1781237151017}}

{"type":"orderbook_delta","sid":1,"seq":27,"msg":{"market_ticker":"KXBTCPERP1","price":"6.3749","delta":"1.00","side":"ask","ts_ms":1781237151273}}

{"type":"orderbook_delta","sid":1,"seq":28,"msg":{"market_ticker":"KXBTCPERP1","price":"6.2638","delta":"1.00","side":"bid","ts_ms":1781237151434}}

{"type":"orderbook_delta","sid":1,"seq":29,"msg":{"market_ticker":"KXBTCPERP1","price":"6.3649","delta":"-1.00","side":"bid","ts_ms":1781237151474}}

{"type":"trade","sid":2,"seq":4,"msg":{"trade_id":"4bfe9ced-aba0-553d-52c8-270769a2182d","market_ticker":"KXBTCPERP1","price":"6.3649","count":"1.00","taker_side":"ask","ts_ms":1781237151474}}

{"type":"ticker","sid":3,"msg":{"market_ticker":"KXBTCPERP1","price":"6.3329","bid":"6.3329","ask":"6.3416","bid_size_fp":"343.00","ask_size_fp":"658.00","last_trade_size_fp":"0.00","volume":"4179467045.00","volume_notional_value_dollars":"3245141294.960300","volume_24h":"1877080.00","volume_24h_notional_value_dollars":"11687174.591200","open_interest":"2332769.00","open_interest_notional_value_dollars":"14773192.800100","reference_price":{"price":"6.3423","ts_ms":1781237151000},"settlement_mark_price":{"price":"6.3805","ts_ms":1781237148040},"liquidation_mark_price":{"price":"6.3680","ts_ms":1781237151398},"funding_rate":{"rate":0,"next_funding_time_ms":1781265600000,"ts_ms":1781237148040},"ts_ms":1781217877584}}

{"type":"orderbook_delta","sid":1,"seq":30,"msg":{"market_ticker":"KXBTCPERP1","price":"6.3680","delta":"-1.00","side":"ask","ts_ms":1781237151643}}

{"type":"trade","sid":2,"seq":5,"msg":{"trade_id":"41841ac5-d318-6912-47f2-5e3d3dfcc619","market_ticker":"KXBTCPERP1","price":"6.3680","count":"1.00","taker_side":"bid","ts_ms":1781237151643}}

{"type":"orderbook_delta","sid":1,"seq":31,"msg":{"market_ticker":"KXBTCPERP1","price":"6.3646","delta":"-1.00","side":"bid","ts_ms":1781237151764}}

{"type":"trade","sid":2,"seq":6,"msg":{"trade_id":"8d950d61-ede5-4a33-9f77-cf3748aff3b9","market_ticker":"KXBTCPERP1","price":"6.3646","count":"1.00","taker_side":"ask","ts_ms":1781237151764}}

{"type":"orderbook_delta","sid":1,"seq":32,"msg":{"market_ticker":"KXBTCPERP1","price":"6.3646","delta":"-1.00","side":"bid","ts_ms":1781237151897}}

{"type":"trade","sid":2,"seq":7,"msg":{"trade_id":"087edcea-e3f5-54d7-ccf0-9d2fcc8d7e8d","market_ticker":"KXBTCPERP1","price":"6.3646","count":"1.00","taker_side":"ask","ts_ms":1781237151897}}

{"type":"orderbook_delta","sid":1,"seq":33,"msg":{"market_ticker":"KXBTCPERP1","price":"6.3680","delta":"-1.00","side":"ask","ts_ms":1781237151935}}

{"type":"trade","sid":2,"seq":8,"msg":{"trade_id":"01b31f81-75dc-7ab6-4c06-c63dbb370581","market_ticker":"KXBTCPERP1","price":"6.3680","count":"1.00","taker_side":"bid","ts_ms":1781237151935}}

{"type":"orderbook_delta","sid":1,"seq":34,"msg":{"market_ticker":"KXBTCPERP1","price":"6.3278","delta":"-1.00","side":"bid","ts_ms":1781237151940}}

{"type":"orderbook_delta","sid":1,"seq":35,"msg":{"market_ticker":"KXBTCPERP1","price":"6.4021","delta":"1.00","side":"ask","ts_ms":1781237152089}}

{"type":"orderbook_delta","sid":1,"seq":36,"msg":{"market_ticker":"KXBTCPERP1","price":"6.4370","delta":"-1.00","side":"ask","ts_ms":1781237152092}}

{"type":"orderbook_delta","sid":1,"seq":37,"msg":{"market_ticker":"KXBTCPERP1","price":"6.3646","delta":"-1.00","side":"bid","ts_ms":1781237152235}}

{"type":"trade","sid":2,"seq":9,"msg":{"trade_id":"3a849854-7741-4f77-4f38-f398b6bce8f5","market_ticker":"KXBTCPERP1","price":"6.3646","count":"1.00","taker_side":"ask","ts_ms":1781237152235}}

{"type":"trade","sid":2,"seq":10,"msg":{"trade_id":"7d212856-2224-76ae-bbc2-3a831ae790d1","market_ticker":"KXBTCPERP1","price":"6.3680","count":"1.00","taker_side":"bid","ts_ms":1781237152289}}

{"type":"orderbook_delta","sid":1,"seq":38,"msg":{"market_ticker":"KXBTCPERP1","price":"6.3680","delta":"-1.00","side":"ask","ts_ms":1781237152289}}

{"type":"orderbook_delta","sid":1,"seq":39,"msg":{"market_ticker":"KXBTCPERP1","price":"6.3884","delta":"1.00","side":"ask","ts_ms":1781237152385}}

{"type":"orderbook_delta","sid":1,"seq":40,"msg":{"market_ticker":"KXBTCPERP1","price":"6.3680","delta":"-1.00","side":"ask","ts_ms":1781237152439}}

{"type":"trade","sid":2,"seq":11,"msg":{"trade_id":"01a070a3-e118-435e-526e-22eac77a1391","market_ticker":"KXBTCPERP1","price":"6.3680","count":"1.00","taker_side":"bid","ts_ms":1781237152439}}

{"type":"orderbook_delta","sid":1,"seq":41,"msg":{"market_ticker":"KXBTCPERP1","price":"6.3646","delta":"-7.00","side":"bid","ts_ms":1781237152448}}

{"type":"orderbook_delta","sid":1,"seq":42,"msg":{"market_ticker":"KXBTCPERP1","price":"6.3638","delta":"10.00","side":"bid","ts_ms":1781237152448}}

{"type":"orderbook_delta","sid":1,"seq":43,"msg":{"market_ticker":"KXBTCPERP1","price":"6.2484","delta":"1.00","side":"bid","ts_ms":1781237152464}}

{"type":"ticker","sid":3,"msg":{"market_ticker":"KXBTCPERP1","price":"6.3329","bid":"6.3329","ask":"6.3416","bid_size_fp":"343.00","ask_size_fp":"658.00","last_trade_size_fp":"0.00","volume":"4179467045.00","volume_notional_value_dollars":"3245141294.960300","volume_24h":"1877080.00","volume_24h_notional_value_dollars":"11687174.591200","open_interest":"2332769.00","open_interest_notional_value_dollars":"14773192.800100","reference_price":{"price":"6.3420","ts_ms":1781237152000},"settlement_mark_price":{"price":"6.3805","ts_ms":1781237148040},"liquidation_mark_price":{"price":"6.3680","ts_ms":1781237152398},"funding_rate":{"rate":0,"next_funding_time_ms":1781265600000,"ts_ms":1781237148040},"ts_ms":1781217877584}}

{"type":"orderbook_delta","sid":1,"seq":44,"msg":{"market_ticker":"KXBTCPERP1","price":"6.1961","delta":"1.00","side":"bid","ts_ms":1781237152563}}

{"type":"orderbook_delta","sid":1,"seq":45,"msg":{"market_ticker":"KXBTCPERP1","price":"6.3645","delta":"-1.00","side":"bid","ts_ms":1781237152787}}

{"type":"trade","sid":2,"seq":12,"msg":{"trade_id":"c39cb599-5c55-4448-1036-cc1b90d24bce","market_ticker":"KXBTCPERP1","price":"6.3645","count":"1.00","taker_side":"ask","ts_ms":1781237152787}}

{"type":"orderbook_delta","sid":1,"seq":46,"msg":{"market_ticker":"KXBTCPERP1","price":"6.3232","delta":"1.00","side":"bid","ts_ms":1781237152969}}

{"type":"orderbook_delta","sid":1,"seq":47,"msg":{"market_ticker":"KXBTCPERP1","price":"6.3680","delta":"-1.00","side":"ask","ts_ms":1781237153004}}

{"type":"trade","sid":2,"seq":13,"msg":{"trade_id":"952c0ed9-a828-6eae-76e6-ae96c53421b9","market_ticker":"KXBTCPERP1","price":"6.3680","count":"1.00","taker_side":"bid","ts_ms":1781237153004}}

{"type":"orderbook_delta","sid":1,"seq":48,"msg":{"market_ticker":"KXBTCPERP1","price":"6.3680","delta":"-1.00","side":"ask","ts_ms":1781237153174}}

{"type":"trade","sid":2,"seq":14,"msg":{"trade_id":"19423d17-b9f8-70ae-b3bc-bce89bb41af5","market_ticker":"KXBTCPERP1","price":"6.3680","count":"1.00","taker_side":"bid","ts_ms":1781237153174}}

{"type":"orderbook_delta","sid":1,"seq":49,"msg":{"market_ticker":"KXBTCPERP1","price":"6.1857","delta":"-1.00","side":"bid","ts_ms":1781237153209}}

{"type":"orderbook_delta","sid":1,"seq":50,"msg":{"market_ticker":"KXBTCPERP1","price":"6.3696","delta":"1.00","side":"ask","ts_ms":1781237153215}}

{"type":"orderbook_delta","sid":1,"seq":51,"msg":{"market_ticker":"KXBTCPERP1","price":"6.2538","delta":"1.00","side":"bid","ts_ms":1781237153356}}

{"type":"orderbook_delta","sid":1,"seq":52,"msg":{"market_ticker":"KXBTCPERP1","price":"6.3553","delta":"-1.00","side":"bid","ts_ms":1781237153411}}

{"type":"orderbook_delta","sid":1,"seq":53,"msg":{"market_ticker":"KXBTCPERP1","price":"6.3645","delta":"-1.00","side":"bid","ts_ms":1781237153462}}

{"type":"trade","sid":2,"seq":15,"msg":{"trade_id":"aa889f8d-1c98-7b7e-9f14-284fc0fb60c9","market_ticker":"KXBTCPERP1","price":"6.3645","count":"1.00","taker_side":"ask","ts_ms":1781237153462}}

{"type":"ticker","sid":3,"msg":{"market_ticker":"KXBTCPERP1","price":"6.3329","bid":"6.3329","ask":"6.3416","bid_size_fp":"343.00","ask_size_fp":"658.00","last_trade_size_fp":"0.00","volume":"4179467045.00","volume_notional_value_dollars":"3245141294.960300","volume_24h":"1877080.00","volume_24h_notional_value_dollars":"11687174.591200","open_interest":"2332769.00","open_interest_notional_value_dollars":"14773192.800100","reference_price":{"price":"6.3420","ts_ms":1781237153000},"settlement_mark_price":{"price":"6.3805","ts_ms":1781237148040},"liquidation_mark_price":{"price":"6.3680","ts_ms":1781237153398},"funding_rate":{"rate":0,"next_funding_time_ms":1781265600000,"ts_ms":1781237148040},"ts_ms":1781217877584}}

{"type":"orderbook_delta","sid":1,"seq":54,"msg":{"market_ticker":"KXBTCPERP1","price":"6.3945","delta":"1.00","side":"ask","ts_ms":1781237153599}}

{"type":"orderbook_delta","sid":1,"seq":55,"msg":{"market_ticker":"KXBTCPERP1","price":"6.3645","delta":"-1.00","side":"bid","ts_ms":1781237153710}}

{"type":"trade","sid":2,"seq":16,"msg":{"trade_id":"ae99b27d-278e-7e94-2255-8b2db54c244a","market_ticker":"KXBTCPERP1","price":"6.3645","count":"1.00","taker_side":"ask","ts_ms":1781237153710}}

{"type":"orderbook_delta","sid":1,"seq":56,"msg":{"market_ticker":"KXBTCPERP1","price":"6.3645","delta":"-9.00","side":"bid","ts_ms":1781237153852}}

{"type":"orderbook_delta","sid":1,"seq":57,"msg":{"market_ticker":"KXBTCPERP1","price":"6.3636","delta":"10.00","side":"bid","ts_ms":1781237153852}}

{"type":"orderbook_delta","sid":1,"seq":58,"msg":{"market_ticker":"KXBTCPERP1","price":"6.3695","delta":"-11.00","side":"ask","ts_ms":1781237153853}}

{"type":"orderbook_delta","sid":1,"seq":59,"msg":{"market_ticker":"KXBTCPERP1","price":"6.3684","delta":"11.00","side":"ask","ts_ms":1781237153853}}

{"type":"orderbook_delta","sid":1,"seq":60,"msg":{"market_ticker":"KXBTCPERP1","price":"6.3696","delta":"-10.00","side":"ask","ts_ms":1781237153853}}

{"type":"orderbook_delta","sid":1,"seq":61,"msg":{"market_ticker":"KXBTCPERP1","price":"6.3685","delta":"10.00","side":"ask","ts_ms":1781237153853}}

{"type":"orderbook_delta","sid":1,"seq":62,"msg":{"market_ticker":"KXBTCPERP1","price":"6.3643","delta":"-1.00","side":"bid","ts_ms":1781237153862}}

{"type":"trade","sid":2,"seq":17,"msg":{"trade_id":"7df18321-e450-4ea7-df56-ff4ac483d922","market_ticker":"KXBTCPERP1","price":"6.3643","count":"1.00","taker_side":"ask","ts_ms":1781237153862}}

{"type":"orderbook_delta","sid":1,"seq":63,"msg":{"market_ticker":"KXBTCPERP1","price":"6.3371","delta":"1.00","side":"bid","ts_ms":1781237153979}}

{"type":"orderbook_delta","sid":1,"seq":64,"msg":{"market_ticker":"KXBTCPERP1","price":"6.3643","delta":"-1.00","side":"bid","ts_ms":1781237154010}}

{"type":"trade","sid":2,"seq":18,"msg":{"trade_id":"43716352-67e5-5d88-c160-39a460cecffa","market_ticker":"KXBTCPERP1","price":"6.3643","count":"1.00","taker_side":"ask","ts_ms":1781237154010}}

{"type":"orderbook_delta","sid":1,"seq":65,"msg":{"market_ticker":"KXBTCPERP1","price":"6.2263","delta":"1.00","side":"bid","ts_ms":1781237154173}}

{"type":"orderbook_delta","sid":1,"seq":66,"msg":{"market_ticker":"KXBTCPERP1","price":"6.3124","delta":"1.00","side":"bid","ts_ms":1781237154248}}

{"type":"orderbook_delta","sid":1,"seq":67,"msg":{"market_ticker":"KXBTCPERP1","price":"6.4992","delta":"-1.00","side":"ask","ts_ms":1781237154479}}

{"type":"ticker","sid":3,"msg":{"market_ticker":"KXBTCPERP1","price":"6.3329","bid":"6.3329","ask":"6.3416","bid_size_fp":"343.00","ask_size_fp":"658.00","last_trade_size_fp":"0.00","volume":"4179467045.00","volume_notional_value_dollars":"3245141294.960300","volume_24h":"1877080.00","volume_24h_notional_value_dollars":"11687174.591200","open_interest":"2332769.00","open_interest_notional_value_dollars":"14773192.800100","reference_price":{"price":"6.3420","ts_ms":1781237154000},"settlement_mark_price":{"price":"6.3796","ts_ms":1781237153035},"liquidation_mark_price":{"price":"6.3643","ts_ms":1781237154398},"funding_rate":{"rate":0,"next_funding_time_ms":1781265600000,"ts_ms":1781237153035},"ts_ms":1781217877584}}

{"type":"orderbook_delta","sid":1,"seq":68,"msg":{"market_ticker":"KXBTCPERP1","price":"6.2331","delta":"1.00","side":"bid","ts_ms":1781237154547}}

{"type":"orderbook_delta","sid":1,"seq":69,"msg":{"market_ticker":"KXBTCPERP1","price":"6.3700","delta":"1.00","side":"ask","ts_ms":1781237154591}}

{"type":"orderbook_delta","sid":1,"seq":70,"msg":{"market_ticker":"KXBTCPERP1","price":"6.3459","delta":"1.00","side":"bid","ts_ms":1781237154723}}

{"type":"orderbook_delta","sid":1,"seq":71,"msg":{"market_ticker":"KXBTCPERP1","price":"6.2824","delta":"-1.00","side":"bid","ts_ms":1781237154871}}

{"type":"orderbook_delta","sid":1,"seq":72,"msg":{"market_ticker":"KXBTCPERP1","price":"6.3642","delta":"-1.00","side":"bid","ts_ms":1781237154930}}

{"type":"trade","sid":2,"seq":19,"msg":{"trade_id":"d5db99f4-3746-46e2-eede-20cebc61bd23","market_ticker":"KXBTCPERP1","price":"6.3642","count":"1.00","taker_side":"ask","ts_ms":1781237154930}}

{"type":"orderbook_delta","sid":1,"seq":73,"msg":{"market_ticker":"KXBTCPERP1","price":"6.2233","delta":"1.00","side":"bid","ts_ms":1781237155005}}

{"type":"orderbook_delta","sid":1,"seq":74,"msg":{"market_ticker":"KXBTCPERP1","price":"6.2404","delta":"1.00","side":"bid","ts_ms":1781237155140}}

{"type":"orderbook_delta","sid":1,"seq":75,"msg":{"market_ticker":"KXBTCPERP1","price":"6.3680","delta":"-1.00","side":"ask","ts_ms":1781237155213}}

{"type":"trade","sid":2,"seq":20,"msg":{"trade_id":"3a229071-1dd4-4f5e-9360-f23cce37a8c5","market_ticker":"KXBTCPERP1","price":"6.3680","count":"1.00","taker_side":"bid","ts_ms":1781237155213}}

{"type":"orderbook_delta","sid":1,"seq":76,"msg":{"market_ticker":"KXBTCPERP1","price":"6.3680","delta":"-353.00","side":"ask","ts_ms":1781237155285}}

{"type":"orderbook_delta","sid":1,"seq":77,"msg":{"market_ticker":"KXBTCPERP1","price":"6.3934","delta":"350.00","side":"ask","ts_ms":1781237155285}}

{"type":"orderbook_delta","sid":1,"seq":78,"msg":{"market_ticker":"KXBTCPERP1","price":"6.3702","delta":"-785.00","side":"ask","ts_ms":1781237155288}}

{"type":"orderbook_delta","sid":1,"seq":79,"msg":{"market_ticker":"KXBTCPERP1","price":"6.3936","delta":"783.00","side":"ask","ts_ms":1781237155288}}

{"type":"orderbook_delta","sid":1,"seq":80,"msg":{"market_ticker":"KXBTCPERP1","price":"6.3724","delta":"-785.00","side":"ask","ts_ms":1781237155292}}

{"type":"orderbook_delta","sid":1,"seq":81,"msg":{"market_ticker":"KXBTCPERP1","price":"6.3938","delta":"783.00","side":"ask","ts_ms":1781237155292}}

{"type":"orderbook_delta","sid":1,"seq":82,"msg":{"market_ticker":"KXBTCPERP1","price":"6.3746","delta":"-784.00","side":"ask","ts_ms":1781237155295}}

{"type":"orderbook_delta","sid":1,"seq":83,"msg":{"market_ticker":"KXBTCPERP1","price":"6.3940","delta":"781.00","side":"ask","ts_ms":1781237155295}}

{"type":"orderbook_delta","sid":1,"seq":84,"msg":{"market_ticker":"KXBTCPERP1","price":"6.3768","delta":"-785.00","side":"ask","ts_ms":1781237155298}}

{"type":"orderbook_delta","sid":1,"seq":85,"msg":{"market_ticker":"KXBTCPERP1","price":"6.3942","delta":"782.00","side":"ask","ts_ms":1781237155298}}

{"type":"orderbook_delta","sid":1,"seq":86,"msg":{"market_ticker":"KXBTCPERP1","price":"6.3790","delta":"-784.00","side":"ask","ts_ms":1781237155301}}

{"type":"orderbook_delta","sid":1,"seq":87,"msg":{"market_ticker":"KXBTCPERP1","price":"6.3944","delta":"782.00","side":"ask","ts_ms":1781237155301}}

{"type":"orderbook_delta","sid":1,"seq":88,"msg":{"market_ticker":"KXBTCPERP1","price":"6.3812","delta":"-784.00","side":"ask","ts_ms":1781237155304}}

{"type":"orderbook_delta","sid":1,"seq":89,"msg":{"market_ticker":"KXBTCPERP1","price":"6.3946","delta":"782.00","side":"ask","ts_ms":1781237155304}}

{"type":"orderbook_delta","sid":1,"seq":90,"msg":{"market_ticker":"KXBTCPERP1","price":"6.3834","delta":"-784.00","side":"ask","ts_ms":1781237155307}}

{"type":"orderbook_delta","sid":1,"seq":91,"msg":{"market_ticker":"KXBTCPERP1","price":"6.3948","delta":"782.00","side":"ask","ts_ms":1781237155307}}

{"type":"orderbook_delta","sid":1,"seq":92,"msg":{"market_ticker":"KXBTCPERP1","price":"6.3856","delta":"-784.00","side":"ask","ts_ms":1781237155310}}

{"type":"orderbook_delta","sid":1,"seq":93,"msg":{"market_ticker":"KXBTCPERP1","price":"6.3950","delta":"782.00","side":"ask","ts_ms":1781237155310}}

{"type":"orderbook_delta","sid":1,"seq":94,"msg":{"market_ticker":"KXBTCPERP1","price":"6.3878","delta":"-783.00","side":"ask","ts_ms":1781237155313}}

{"type":"orderbook_delta","sid":1,"seq":95,"msg":{"market_ticker":"KXBTCPERP1","price":"6.3952","delta":"782.00","side":"ask","ts_ms":1781237155313}}

{"type":"orderbook_delta","sid":1,"seq":96,"msg":{"market_ticker":"KXBTCPERP1","price":"6.3684","delta":"-11.00","side":"ask","ts_ms":1781237155318}}

{"type":"orderbook_delta","sid":1,"seq":97,"msg":{"market_ticker":"KXBTCPERP1","price":"6.3685","delta":"-10.00","side":"ask","ts_ms":1781237155318}}

{"type":"orderbook_delta","sid":1,"seq":98,"msg":{"market_ticker":"KXBTCPERP1","price":"6.3696","delta":"-1.00","side":"ask","ts_ms":1781237155318}}

{"type":"orderbook_delta","sid":1,"seq":99,"msg":{"market_ticker":"KXBTCPERP1","price":"6.3700","delta":"-1.00","side":"ask","ts_ms":1781237155318}}

{"type":"orderbook_delta","sid":1,"seq":100,"msg":{"market_ticker":"KXBTCPERP1","price":"6.3724","delta":"-1.00","side":"ask","ts_ms":1781237155318}}

{"type":"orderbook_delta","sid":1,"seq":101,"msg":{"market_ticker":"KXBTCPERP1","price":"6.3747","delta":"-136.00","side":"ask","ts_ms":1781237155318}}

{"type":"orderbook_delta","sid":1,"seq":102,"msg":{"market_ticker":"KXBTCPERP1","price":"6.3749","delta":"-1.00","side":"ask","ts_ms":1781237155318}}

{"type":"orderbook_delta","sid":1,"seq":103,"msg":{"market_ticker":"KXBTCPERP1","price":"6.3823","delta":"-359.00","side":"ask","ts_ms":1781237155318}}

{"type":"orderbook_delta","sid":1,"seq":104,"msg":{"market_ticker":"KXBTCPERP1","price":"6.3562","delta":"-524.00","side":"bid","ts_ms":1781237155318}}

{"type":"trade","sid":2,"seq":21,"msg":{"trade_id":"9f09665f-96f5-633c-bdcc-b491f2480648","market_ticker":"KXBTCPERP1","price":"6.3684","count":"11.00","taker_side":"bid","ts_ms":1781237155318}}

{"type":"trade","sid":2,"seq":22,"msg":{"trade_id":"02ea7174-6258-655d-9243-e244c0669efd","market_ticker":"KXBTCPERP1","price":"6.3685","count":"10.00","taker_side":"bid","ts_ms":1781237155318}}

{"type":"trade","sid":2,"seq":23,"msg":{"trade_id":"b5a0d08a-9ad7-69a1-a108-72d48797d618","market_ticker":"KXBTCPERP1","price":"6.3696","count":"1.00","taker_side":"bid","ts_ms":1781237155318}}

{"type":"trade","sid":2,"seq":24,"msg":{"trade_id":"d811fdfe-397f-636d-9027-8b93355edc41","market_ticker":"KXBTCPERP1","price":"6.3700","count":"1.00","taker_side":"bid","ts_ms":1781237155318}}

{"type":"trade","sid":2,"seq":25,"msg":{"trade_id":"3c00e8cd-db86-6807-ad02-2747ad1ed411","market_ticker":"KXBTCPERP1","price":"6.3724","count":"1.00","taker_side":"bid","ts_ms":1781237155318}}

{"type":"trade","sid":2,"seq":26,"msg":{"trade_id":"f60c76cf-63a0-620f-9baa-dad4306692bf","market_ticker":"KXBTCPERP1","price":"6.3747","count":"136.00","taker_side":"bid","ts_ms":1781237155318}}

{"type":"trade","sid":2,"seq":27,"msg":{"trade_id":"3d5522c2-6f7e-657c-a22d-5c63ac125989","market_ticker":"KXBTCPERP1","price":"6.3749","count":"1.00","taker_side":"bid","ts_ms":1781237155318}}

{"type":"trade","sid":2,"seq":28,"msg":{"trade_id":"3f2e17aa-c6dc-6ab5-acd7-f5ceb6d8978e","market_ticker":"KXBTCPERP1","price":"6.3823","count":"359.00","taker_side":"bid","ts_ms":1781237155318}}

{"type":"orderbook_delta","sid":1,"seq":105,"msg":{"market_ticker":"KXBTCPERP1","price":"6.3823","delta":"-181.00","side":"ask","ts_ms":1781237155321}}

{"type":"orderbook_delta","sid":1,"seq":106,"msg":{"market_ticker":"KXBTCPERP1","price":"6.3884","delta":"-1.00","side":"ask","ts_ms":1781237155321}}

{"type":"orderbook_delta","sid":1,"seq":107,"msg":{"market_ticker":"KXBTCPERP1","price":"6.3540","delta":"-786.00","side":"bid","ts_ms":1781237155321}}

{"type":"orderbook_delta","sid":1,"seq":108,"msg":{"market_ticker":"KXBTCPERP1","price":"6.3900","delta":"600.00","side":"bid","ts_ms":1781237155321}}

{"type":"trade","sid":2,"seq":29,"msg":{"trade_id":"797f08f0-7f20-4ce1-61c7-d6e5b6eb404a","market_ticker":"KXBTCPERP1","price":"6.3823","count":"181.00","taker_side":"bid","ts_ms":1781237155321}}

{"type":"trade","sid":2,"seq":30,"msg":{"trade_id":"fdb5e7cc-1537-4380-6009-531b6e0015e8","market_ticker":"KXBTCPERP1","price":"6.3884","count":"1.00","taker_side":"bid","ts_ms":1781237155321}}

{"type":"orderbook_delta","sid":1,"seq":109,"msg":{"market_ticker":"KXBTCPERP1","price":"6.3518","delta":"-788.00","side":"bid","ts_ms":1781237155325}}

{"type":"orderbook_delta","sid":1,"seq":110,"msg":{"market_ticker":"KXBTCPERP1","price":"6.3898","delta":"783.00","side":"bid","ts_ms":1781237155325}}

{"type":"orderbook_delta","sid":1,"seq":111,"msg":{"market_ticker":"KXBTCPERP1","price":"6.3496","delta":"-788.00","side":"bid","ts_ms":1781237155328}}

{"type":"orderbook_delta","sid":1,"seq":112,"msg":{"market_ticker":"KXBTCPERP1","price":"6.3896","delta":"783.00","side":"bid","ts_ms":1781237155328}}

{"type":"orderbook_delta","sid":1,"seq":113,"msg":{"market_ticker":"KXBTCPERP1","price":"6.3474","delta":"-788.00","side":"bid","ts_ms":1781237155331}}

{"type":"orderbook_delta","sid":1,"seq":114,"msg":{"market_ticker":"KXBTCPERP1","price":"6.3894","delta":"783.00","side":"bid","ts_ms":1781237155331}}

{"type":"orderbook_delta","sid":1,"seq":115,"msg":{"market_ticker":"KXBTCPERP1","price":"6.3452","delta":"-787.00","side":"bid","ts_ms":1781237155334}}

{"type":"orderbook_delta","sid":1,"seq":116,"msg":{"market_ticker":"KXBTCPERP1","price":"6.3892","delta":"782.00","side":"bid","ts_ms":1781237155334}}

{"type":"orderbook_delta","sid":1,"seq":117,"msg":{"market_ticker":"KXBTCPERP1","price":"6.3430","delta":"-789.00","side":"bid","ts_ms":1781237155338}}

{"type":"orderbook_delta","sid":1,"seq":118,"msg":{"market_ticker":"KXBTCPERP1","price":"6.3890","delta":"783.00","side":"bid","ts_ms":1781237155338}}

{"type":"orderbook_delta","sid":1,"seq":119,"msg":{"market_ticker":"KXBTCPERP1","price":"6.3408","delta":"-788.00","side":"bid","ts_ms":1781237155342}}

{"type":"orderbook_delta","sid":1,"seq":120,"msg":{"market_ticker":"KXBTCPERP1","price":"6.3888","delta":"782.00","side":"bid","ts_ms":1781237155342}}

{"type":"orderbook_delta","sid":1,"seq":121,"msg":{"market_ticker":"KXBTCPERP1","price":"6.3386","delta":"-789.00","side":"bid","ts_ms":1781237155345}}

{"type":"orderbook_delta","sid":1,"seq":122,"msg":{"market_ticker":"KXBTCPERP1","price":"6.3886","delta":"783.00","side":"bid","ts_ms":1781237155345}}

{"type":"orderbook_delta","sid":1,"seq":123,"msg":{"market_ticker":"KXBTCPERP1","price":"6.3364","delta":"-790.00","side":"bid","ts_ms":1781237155348}}

{"type":"orderbook_delta","sid":1,"seq":124,"msg":{"market_ticker":"KXBTCPERP1","price":"6.3884","delta":"783.00","side":"bid","ts_ms":1781237155348}}

{"type":"orderbook_delta","sid":1,"seq":125,"msg":{"market_ticker":"KXBTCPERP1","price":"6.3900","delta":"-1.00","side":"bid","ts_ms":1781237155393}}

{"type":"trade","sid":2,"seq":31,"msg":{"trade_id":"d80c22be-3b98-578b-eb81-add1b1a7139e","market_ticker":"KXBTCPERP1","price":"6.3900","count":"1.00","taker_side":"ask","ts_ms":1781237155393}}

{"type":"orderbook_delta","sid":1,"seq":126,"msg":{"market_ticker":"KXBTCPERP1","price":"6.4508","delta":"-1.00","side":"ask","ts_ms":1781237155444}}

{"type":"ticker","sid":3,"msg":{"market_ticker":"KXBTCPERP1","price":"6.3329","bid":"6.3329","ask":"6.3416","bid_size_fp":"343.00","ask_size_fp":"658.00","last_trade_size_fp":"0.00","volume":"4179467045.00","volume_notional_value_dollars":"3245141294.960300","volume_24h":"1877080.00","volume_24h_notional_value_dollars":"11687174.591200","open_interest":"2332769.00","open_interest_notional_value_dollars":"14773192.800100","reference_price":{"price":"6.3414","ts_ms":1781237155000},"settlement_mark_price":{"price":"6.3796","ts_ms":1781237153035},"liquidation_mark_price":{"price":"6.3832","ts_ms":1781237155399},"funding_rate":{"rate":0,"next_funding_time_ms":1781265600000,"ts_ms":1781237153035},"ts_ms":1781217877584}}

{"type":"orderbook_delta","sid":1,"seq":127,"msg":{"market_ticker":"KXBTCPERP1","price":"6.4473","delta":"1.00","side":"ask","ts_ms":1781237155508}}

{"type":"orderbook_delta","sid":1,"seq":128,"msg":{"market_ticker":"KXBTCPERP1","price":"6.3900","delta":"-1.00","side":"bid","ts_ms":1781237155545}}

{"type":"trade","sid":2,"seq":32,"msg":{"trade_id":"0d6318b7-fce0-55a3-2de0-c10b45372756","market_ticker":"KXBTCPERP1","price":"6.3900","count":"1.00","taker_side":"ask","ts_ms":1781237155545}}

{"type":"orderbook_delta","sid":1,"seq":129,"msg":{"market_ticker":"KXBTCPERP1","price":"6.3411","delta":"1.00","side":"bid","ts_ms":1781237155582}}

{"type":"orderbook_delta","sid":1,"seq":130,"msg":{"market_ticker":"KXBTCPERP1","price":"6.2297","delta":"1.00","side":"bid","ts_ms":1781237155695}}

{"type":"orderbook_delta","sid":1,"seq":131,"msg":{"market_ticker":"KXBTCPERP1","price":"6.4524","delta":"1.00","side":"ask","ts_ms":1781237155763}}

{"type":"orderbook_delta","sid":1,"seq":132,"msg":{"market_ticker":"KXBTCPERP1","price":"6.3900","delta":"-1.00","side":"bid","ts_ms":1781237155930}}

{"type":"trade","sid":2,"seq":33,"msg":{"trade_id":"4b986cc1-2748-683b-38d2-12ca4499a4b2","market_ticker":"KXBTCPERP1","price":"6.3900","count":"1.00","taker_side":"ask","ts_ms":1781237155930}}

{"type":"orderbook_delta","sid":1,"seq":133,"msg":{"market_ticker":"KXBTCPERP1","price":"6.2881","delta":"1.00","side":"bid","ts_ms":1781237156032}}

{"type":"orderbook_delta","sid":1,"seq":134,"msg":{"market_ticker":"KXBTCPERP1","price":"6.3927","delta":"11.00","side":"ask","ts_ms":1781237156061}}

{"type":"orderbook_delta","sid":1,"seq":135,"msg":{"market_ticker":"KXBTCPERP1","price":"6.3831","delta":"1.00","side":"bid","ts_ms":1781237156064}}

{"type":"orderbook_delta","sid":1,"seq":136,"msg":{"market_ticker":"KXBTCPERP1","price":"6.3900","delta":"-1.00","side":"bid","ts_ms":1781237156094}}

{"type":"trade","sid":2,"seq":34,"msg":{"trade_id":"bf01b295-56d4-645b-1334-f78120f8024a","market_ticker":"KXBTCPERP1","price":"6.3900","count":"1.00","taker_side":"ask","ts_ms":1781237156094}}

{"type":"orderbook_delta","sid":1,"seq":137,"msg":{"market_ticker":"KXBTCPERP1","price":"6.3928","delta":"10.00","side":"ask","ts_ms":1781237156162}}

{"type":"orderbook_delta","sid":1,"seq":138,"msg":{"market_ticker":"KXBTCPERP1","price":"7.6637","delta":"1.00","side":"ask","ts_ms":1781237156168}}

{"type":"orderbook_delta","sid":1,"seq":139,"msg":{"market_ticker":"KXBTCPERP1","price":"6.3909","delta":"-1.00","side":"ask","ts_ms":1781237156191}}

{"type":"trade","sid":2,"seq":35,"msg":{"trade_id":"8becfd9c-3d80-751f-1f12-a783dc8e2bbd","market_ticker":"KXBTCPERP1","price":"6.3909","count":"1.00","taker_side":"bid","ts_ms":1781237156191}}

{"type":"orderbook_delta","sid":1,"seq":140,"msg":{"market_ticker":"KXBTCPERP1","price":"6.3911","delta":"-1.00","side":"ask","ts_ms":1781237156256}}

{"type":"trade","sid":2,"seq":36,"msg":{"trade_id":"8d5492a2-f2e1-7587-0517-5229a0a66c37","market_ticker":"KXBTCPERP1","price":"6.3911","count":"1.00","taker_side":"bid","ts_ms":1781237156256}}

{"type":"orderbook_delta","sid":1,"seq":141,"msg":{"market_ticker":"KXBTCPERP1","price":"6.3977","delta":"136.00","side":"ask","ts_ms":1781237156263}}

{"type":"orderbook_delta","sid":1,"seq":142,"msg":{"market_ticker":"KXBTCPERP1","price":"6.3915","delta":"-1.00","side":"ask","ts_ms":1781237156298}}

{"type":"trade","sid":2,"seq":37,"msg":{"trade_id":"3ff98975-ce4c-7e09-cd9a-3bc2b1bded5d","market_ticker":"KXBTCPERP1","price":"6.3915","count":"1.00","taker_side":"bid","ts_ms":1781237156298}}

{"type":"orderbook_delta","sid":1,"seq":143,"msg":{"market_ticker":"KXBTCPERP1","price":"6.4053","delta":"544.00","side":"ask","ts_ms":1781237156364}}

{"type":"orderbook_delta","sid":1,"seq":144,"msg":{"market_ticker":"KXBTCPERP1","price":"6.2163","delta":"1.00","side":"bid","ts_ms":1781237156380}}

{"type":"ticker","sid":3,"msg":{"market_ticker":"KXBTCPERP1","price":"6.3329","bid":"6.3329","ask":"6.3416","bid_size_fp":"343.00","ask_size_fp":"658.00","last_trade_size_fp":"0.00","volume":"4179467045.00","volume_notional_value_dollars":"3245141294.960300","volume_24h":"1877080.00","volume_24h_notional_value_dollars":"11687174.591200","open_interest":"2332769.00","open_interest_notional_value_dollars":"14773192.800100","reference_price":{"price":"6.3415","ts_ms":1781237156000},"settlement_mark_price":{"price":"6.3796","ts_ms":1781237153035},"liquidation_mark_price":{"price":"6.3835","ts_ms":1781237156398},"funding_rate":{"rate":0,"next_funding_time_ms":1781265600000,"ts_ms":1781237153035},"ts_ms":1781217877584}}

{"type":"orderbook_delta","sid":1,"seq":145,"msg":{"market_ticker":"KXBTCPERP1","price":"6.3900","delta":"-1.00","side":"bid","ts_ms":1781237156551}}

{"type":"trade","sid":2,"seq":38,"msg":{"trade_id":"37f7b075-fee4-6ef7-e466-ec055aebf4e6","market_ticker":"KXBTCPERP1","price":"6.3900","count":"1.00","taker_side":"ask","ts_ms":1781237156551}}

{"type":"orderbook_delta","sid":1,"seq":146,"msg":{"market_ticker":"KXBTCPERP1","price":"6.2787","delta":"1.00","side":"bid","ts_ms":1781237156590}}

{"type":"orderbook_delta","sid":1,"seq":147,"msg":{"market_ticker":"KXBTCPERP1","price":"6.3918","delta":"-1.00","side":"ask","ts_ms":1781237156661}}

{"type":"trade","sid":2,"seq":39,"msg":{"trade_id":"2877e061-9d5f-4254-6c20-0f9523fbb667","market_ticker":"KXBTCPERP1","price":"6.3918","count":"1.00","taker_side":"bid","ts_ms":1781237156661}}

{"type":"orderbook_delta","sid":1,"seq":148,"msg":{"market_ticker":"KXBTCPERP1","price":"6.3372","delta":"1.00","side":"bid","ts_ms":1781237156678}}

{"type":"orderbook_delta","sid":1,"seq":149,"msg":{"market_ticker":"KXBTCPERP1","price":"6.3046","delta":"1.00","side":"bid","ts_ms":1781237156764}}

{"type":"orderbook_delta","sid":1,"seq":150,"msg":{"market_ticker":"KXBTCPERP1","price":"6.2817","delta":"1.00","side":"bid","ts_ms":1781237156975}}

{"type":"orderbook_delta","sid":1,"seq":151,"msg":{"market_ticker":"KXBTCPERP1","price":"6.1837","delta":"-1.00","side":"bid","ts_ms":1781237157064}}

{"type":"orderbook_delta","sid":1,"seq":152,"msg":{"market_ticker":"KXBTCPERP1","price":"6.3730","delta":"1.00","side":"bid","ts_ms":1781237157123}}

{"type":"orderbook_delta","sid":1,"seq":153,"msg":{"market_ticker":"KXBTCPERP1","price":"6.4207","delta":"1.00","side":"ask","ts_ms":1781237157225}}

{"type":"orderbook_delta","sid":1,"seq":154,"msg":{"market_ticker":"KXBTCPERP1","price":"6.3638","delta":"-10.00","side":"bid","ts_ms":1781237157272}}

{"type":"orderbook_delta","sid":1,"seq":155,"msg":{"market_ticker":"KXBTCPERP1","price":"6.3884","delta":"10.00","side":"bid","ts_ms":1781237157272}}

{"type":"orderbook_delta","sid":1,"seq":156,"msg":{"market_ticker":"KXBTCPERP1","price":"6.3900","delta":"-1.00","side":"bid","ts_ms":1781237157317}}

{"type":"trade","sid":2,"seq":40,"msg":{"trade_id":"1993065d-1e28-54db-1dfb-50cef64ab1ce","market_ticker":"KXBTCPERP1","price":"6.3900","count":"1.00","taker_side":"ask","ts_ms":1781237157317}}

{"type":"orderbook_delta","sid":1,"seq":157,"msg":{"market_ticker":"KXBTCPERP1","price":"7.6637","delta":"1.00","side":"ask","ts_ms":1781237157328}}

{"type":"orderbook_delta","sid":1,"seq":158,"msg":{"market_ticker":"KXBTCPERP1","price":"6.3901","delta":"1.00","side":"bid","ts_ms":1781237157343}}

{"type":"orderbook_delta","sid":1,"seq":159,"msg":{"market_ticker":"KXBTCPERP1","price":"6.2941","delta":"1.00","side":"bid","ts_ms":1781237157371}}

{"type":"orderbook_delta","sid":1,"seq":160,"msg":{"market_ticker":"KXBTCPERP1","price":"6.3636","delta":"-10.00","side":"bid","ts_ms":1781237157372}}

{"type":"orderbook_delta","sid":1,"seq":161,"msg":{"market_ticker":"KXBTCPERP1","price":"6.3883","delta":"10.00","side":"bid","ts_ms":1781237157372}}

{"type":"orderbook_delta","sid":1,"seq":162,"msg":{"market_ticker":"KXBTCPERP1","price":"6.3568","delta":"1.00","side":"bid","ts_ms":1781237157398}}

{"type":"orderbook_delta","sid":1,"seq":163,"msg":{"market_ticker":"KXBTCPERP1","price":"6.2502","delta":"1.00","side":"bid","ts_ms":1781237157440}}

{"type":"orderbook_delta","sid":1,"seq":164,"msg":{"market_ticker":"KXBTCPERP1","price":"6.1803","delta":"1.00","side":"bid","ts_ms":1781237157450}}

{"type":"ticker","sid":3,"msg":{"market_ticker":"KXBTCPERP1","price":"6.3329","bid":"6.3329","ask":"6.3416","bid_size_fp":"343.00","ask_size_fp":"658.00","last_trade_size_fp":"0.00","volume":"4179467045.00","volume_notional_value_dollars":"3245141294.960300","volume_24h":"1877080.00","volume_24h_notional_value_dollars":"11687174.591200","open_interest":"2332769.00","open_interest_notional_value_dollars":"14773192.800100","reference_price":{"price":"6.3413","ts_ms":1781237157000},"settlement_mark_price":{"price":"6.3796","ts_ms":1781237153035},"liquidation_mark_price":{"price":"6.3833","ts_ms":1781237157398},"funding_rate":{"rate":0,"next_funding_time_ms":1781265600000,"ts_ms":1781237153035},"ts_ms":1781217877584}}

{"type":"orderbook_delta","sid":1,"seq":165,"msg":{"market_ticker":"KXBTCPERP1","price":"6.2419","delta":"1.00","side":"bid","ts_ms":1781237157527}}

{"type":"orderbook_delta","sid":1,"seq":166,"msg":{"market_ticker":"KXBTCPERP1","price":"6.3591","delta":"-134.00","side":"bid","ts_ms":1781237157573}}

{"type":"orderbook_delta","sid":1,"seq":167,"msg":{"market_ticker":"KXBTCPERP1","price":"6.3830","delta":"132.00","side":"bid","ts_ms":1781237157573}}

{"type":"orderbook_delta","sid":1,"seq":168,"msg":{"market_ticker":"KXBTCPERP1","price":"6.3232","delta":"-1.00","side":"bid","ts_ms":1781237157576}}

{"type":"orderbook_delta","sid":1,"seq":169,"msg":{"market_ticker":"KXBTCPERP1","price":"6.2273","delta":"1.00","side":"bid","ts_ms":1781237157647}}

{"type":"orderbook_delta","sid":1,"seq":170,"msg":{"market_ticker":"KXBTCPERP1","price":"6.3512","delta":"-535.00","side":"bid","ts_ms":1781237157674}}

{"type":"orderbook_delta","sid":1,"seq":171,"msg":{"market_ticker":"KXBTCPERP1","price":"6.3750","delta":"527.00","side":"bid","ts_ms":1781237157674}}

{"type":"orderbook_delta","sid":1,"seq":172,"msg":{"market_ticker":"KXBTCPERP1","price":"6.3901","delta":"-1.00","side":"bid","ts_ms":1781237157786}}

{"type":"trade","sid":2,"seq":41,"msg":{"trade_id":"92e268ef-79fe-5bc7-0825-04c11dbda958","market_ticker":"KXBTCPERP1","price":"6.3901","count":"1.00","taker_side":"ask","ts_ms":1781237157786}}

{"type":"orderbook_delta","sid":1,"seq":173,"msg":{"market_ticker":"KXBTCPERP1","price":"6.3900","delta":"-1.00","side":"bid","ts_ms":1781237157955}}

{"type":"trade","sid":2,"seq":42,"msg":{"trade_id":"502fa9a3-9760-6333-0d00-f8eaac1706fe","market_ticker":"KXBTCPERP1","price":"6.3900","count":"1.00","taker_side":"ask","ts_ms":1781237157955}}

{"type":"orderbook_delta","sid":1,"seq":174,"msg":{"market_ticker":"KXBTCPERP1","price":"6.3299","delta":"1.00","side":"bid","ts_ms":1781237158007}}

{"type":"orderbook_delta","sid":1,"seq":175,"msg":{"market_ticker":"KXBTCPERP1","price":"6.4020","delta":"1.00","side":"ask","ts_ms":1781237158067}}

{"type":"orderbook_delta","sid":1,"seq":176,"msg":{"market_ticker":"KXBTCPERP1","price":"6.3391","delta":"1.00","side":"bid","ts_ms":1781237158108}}

{"type":"orderbook_delta","sid":1,"seq":177,"msg":{"market_ticker":"KXBTCPERP1","price":"6.5389","delta":"1.00","side":"ask","ts_ms":1781237158117}}

{"type":"orderbook_delta","sid":1,"seq":178,"msg":{"market_ticker":"KXBTCPERP1","price":"6.4194","delta":"1.00","side":"ask","ts_ms":1781237158172}}

{"type":"orderbook_delta","sid":1,"seq":179,"msg":{"market_ticker":"KXBTCPERP1","price":"6.3246","delta":"1.00","side":"bid","ts_ms":1781237158221}}

{"type":"orderbook_delta","sid":1,"seq":180,"msg":{"market_ticker":"KXBTCPERP1","price":"6.3900","delta":"-1.00","side":"bid","ts_ms":1781237158255}}

{"type":"trade","sid":2,"seq":43,"msg":{"trade_id":"946ab005-b860-44f7-a40d-046d026937ae","market_ticker":"KXBTCPERP1","price":"6.3900","count":"1.00","taker_side":"ask","ts_ms":1781237158255}}

{"type":"orderbook_delta","sid":1,"seq":181,"msg":{"market_ticker":"KXBTCPERP1","price":"6.3037","delta":"1.00","side":"bid","ts_ms":1781237158334}}

{"type":"orderbook_delta","sid":1,"seq":182,"msg":{"market_ticker":"KXBTCPERP1","price":"6.2740","delta":"1.00","side":"bid","ts_ms":1781237158382}}

{"type":"ticker","sid":3,"msg":{"market_ticker":"KXBTCPERP1","price":"6.3329","bid":"6.3329","ask":"6.3416","bid_size_fp":"343.00","ask_size_fp":"658.00","last_trade_size_fp":"0.00","volume":"4179467045.00","volume_notional_value_dollars":"3245141294.960300","volume_24h":"1877080.00","volume_24h_notional_value_dollars":"11687174.591200","open_interest":"2332769.00","open_interest_notional_value_dollars":"14773192.800100","reference_price":{"price":"6.3413","ts_ms":1781237158000},"settlement_mark_price":{"price":"6.3796","ts_ms":1781237153035},"liquidation_mark_price":{"price":"6.3834","ts_ms":1781237158398},"funding_rate":{"rate":0,"next_funding_time_ms":1781265600000,"ts_ms":1781237153035},"ts_ms":1781217877584}}

{"type":"orderbook_delta","sid":1,"seq":183,"msg":{"market_ticker":"KXBTCPERP1","price":"7.6637","delta":"1.00","side":"ask","ts_ms":1781237158528}}

{"type":"trade","sid":2,"seq":44,"msg":{"trade_id":"fd0f8ce0-ba65-40e8-322d-e59ff12addcb","market_ticker":"KXBTCPERP1","price":"6.3918","count":"1.00","taker_side":"bid","ts_ms":1781237158531}}

{"type":"orderbook_delta","sid":1,"seq":184,"msg":{"market_ticker":"KXBTCPERP1","price":"6.3918","delta":"-1.00","side":"ask","ts_ms":1781237158531}}

{"type":"orderbook_delta","sid":1,"seq":185,"msg":{"market_ticker":"KXBTCPERP1","price":"6.4228","delta":"1.00","side":"ask","ts_ms":1781237158557}}

{"type":"orderbook_delta","sid":1,"seq":186,"msg":{"market_ticker":"KXBTCPERP1","price":"6.3934","delta":"1.00","side":"ask","ts_ms":1781237158646}}

{"type":"orderbook_delta","sid":1,"seq":187,"msg":{"market_ticker":"KXBTCPERP1","price":"6.3924","delta":"-1.00","side":"ask","ts_ms":1781237158690}}

{"type":"trade","sid":2,"seq":45,"msg":{"trade_id":"e5a55625-0fef-559f-39af-2a1f82548934","market_ticker":"KXBTCPERP1","price":"6.3924","count":"1.00","taker_side":"bid","ts_ms":1781237158690}}

{"type":"orderbook_delta","sid":1,"seq":188,"msg":{"market_ticker":"KXBTCPERP1","price":"6.3925","delta":"-1.00","side":"ask","ts_ms":1781237158803}}

{"type":"trade","sid":2,"seq":46,"msg":{"trade_id":"8629e564-e294-7441-92f6-bb5305faf901","market_ticker":"KXBTCPERP1","price":"6.3925","count":"1.00","taker_side":"bid","ts_ms":1781237158803}}

{"type":"orderbook_delta","sid":1,"seq":189,"msg":{"market_ticker":"KXBTCPERP1","price":"6.3900","delta":"-1.00","side":"bid","ts_ms":1781237158883}}

{"type":"trade","sid":2,"seq":47,"msg":{"trade_id":"edc913e2-9454-6e4b-e47c-4b3ccd2e851e","market_ticker":"KXBTCPERP1","price":"6.3900","count":"1.00","taker_side":"ask","ts_ms":1781237158883}}

{"type":"trade","sid":2,"seq":48,"msg":{"trade_id":"ab4db0dd-aa44-470f-1291-d1372e3335ea","market_ticker":"KXBTCPERP1","price":"6.3900","count":"1.00","taker_side":"ask","ts_ms":1781237158989}}

{"type":"orderbook_delta","sid":1,"seq":190,"msg":{"market_ticker":"KXBTCPERP1","price":"6.3900","delta":"-1.00","side":"bid","ts_ms":1781237158989}}

{"type":"orderbook_delta","sid":1,"seq":191,"msg":{"market_ticker":"KXBTCPERP1","price":"6.3312","delta":"1.00","side":"bid","ts_ms":1781237159087}}

{"type":"orderbook_delta","sid":1,"seq":192,"msg":{"market_ticker":"KXBTCPERP1","price":"6.4515","delta":"1.00","side":"ask","ts_ms":1781237159101}}

{"type":"orderbook_delta","sid":1,"seq":193,"msg":{"market_ticker":"KXBTCPERP1","price":"6.3926","delta":"-1.00","side":"ask","ts_ms":1781237159235}}

{"type":"trade","sid":2,"seq":49,"msg":{"trade_id":"cbb6ffa5-ff91-63dc-08ce-9011b77eed4c","market_ticker":"KXBTCPERP1","price":"6.3926","count":"1.00","taker_side":"bid","ts_ms":1781237159235}}

{"type":"orderbook_delta","sid":1,"seq":194,"msg":{"market_ticker":"KXBTCPERP1","price":"6.3927","delta":"-1.00","side":"ask","ts_ms":1781237159268}}

{"type":"trade","sid":2,"seq":50,"msg":{"trade_id":"5679b6a8-1c04-69ee-1a46-9cf3159fd329","market_ticker":"KXBTCPERP1","price":"6.3927","count":"1.00","taker_side":"bid","ts_ms":1781237159268}}

{"type":"orderbook_delta","sid":1,"seq":195,"msg":{"market_ticker":"KXBTCPERP1","price":"6.3900","delta":"-1.00","side":"bid","ts_ms":1781237159273}}

{"type":"trade","sid":2,"seq":51,"msg":{"trade_id":"79f1b708-23bc-521b-e157-cfbc39d8278a","market_ticker":"KXBTCPERP1","price":"6.3900","count":"1.00","taker_side":"ask","ts_ms":1781237159273}}

{"type":"orderbook_delta","sid":1,"seq":196,"msg":{"market_ticker":"KXBTCPERP1","price":"6.3927","delta":"-11.00","side":"ask","ts_ms":1781237159285}}

{"type":"orderbook_delta","sid":1,"seq":197,"msg":{"market_ticker":"KXBTCPERP1","price":"6.3938","delta":"10.00","side":"ask","ts_ms":1781237159285}}

{"type":"orderbook_delta","sid":1,"seq":198,"msg":{"market_ticker":"KXBTCPERP1","price":"6.3928","delta":"-10.00","side":"ask","ts_ms":1781237159385}}

{"type":"orderbook_delta","sid":1,"seq":199,"msg":{"market_ticker":"KXBTCPERP1","price":"6.3939","delta":"10.00","side":"ask","ts_ms":1781237159385}}

{"type":"orderbook_delta","sid":1,"seq":200,"msg":{"market_ticker":"KXBTCPERP1","price":"6.3900","delta":"-1.00","side":"bid","ts_ms":1781237159486}}

{"type":"trade","sid":2,"seq":52,"msg":{"trade_id":"f675085a-409c-4323-0398-b72c02cfceda","market_ticker":"KXBTCPERP1","price":"6.3900","count":"1.00","taker_side":"ask","ts_ms":1781237159486}}

{"type":"ticker","sid":3,"msg":{"market_ticker":"KXBTCPERP1","price":"6.3329","bid":"6.3329","ask":"6.3416","bid_size_fp":"343.00","ask_size_fp":"658.00","last_trade_size_fp":"0.00","volume":"4179467045.00","volume_notional_value_dollars":"3245141294.960300","volume_24h":"1877080.00","volume_24h_notional_value_dollars":"11687174.591200","open_interest":"2332769.00","open_interest_notional_value_dollars":"14773192.800100","reference_price":{"price":"6.3414","ts_ms":1781237159000},"settlement_mark_price":{"price":"6.3801","ts_ms":1781237158039},"liquidation_mark_price":{"price":"6.3834","ts_ms":1781237159398},"funding_rate":{"rate":0,"next_funding_time_ms":1781265600000,"ts_ms":1781237158039},"ts_ms":1781217877584}}

{"type":"orderbook_delta","sid":1,"seq":201,"msg":{"market_ticker":"KXBTCPERP1","price":"6.3934","delta":"-1.00","side":"ask","ts_ms":1781237159637}}

{"type":"trade","sid":2,"seq":53,"msg":{"trade_id":"9689b4fd-23e8-527e-ae5f-949e523f58dd","market_ticker":"KXBTCPERP1","price":"6.3934","count":"1.00","taker_side":"bid","ts_ms":1781237159637}}

{"type":"orderbook_delta","sid":1,"seq":202,"msg":{"market_ticker":"KXBTCPERP1","price":"6.3884","delta":"-10.00","side":"bid","ts_ms":1781237159687}}

{"type":"orderbook_delta","sid":1,"seq":203,"msg":{"market_ticker":"KXBTCPERP1","price":"6.3894","delta":"11.00","side":"bid","ts_ms":1781237159687}}

{"type":"orderbook_delta","sid":1,"seq":204,"msg":{"market_ticker":"KXBTCPERP1","price":"6.4499","delta":"1.00","side":"ask","ts_ms":1781237159784}}

{"type":"orderbook_delta","sid":1,"seq":205,"msg":{"market_ticker":"KXBTCPERP1","price":"6.3883","delta":"-10.00","side":"bid","ts_ms":1781237159788}}

{"type":"orderbook_delta","sid":1,"seq":206,"msg":{"market_ticker":"KXBTCPERP1","price":"6.3893","delta":"10.00","side":"bid","ts_ms":1781237159788}}

{"type":"orderbook_delta","sid":1,"seq":207,"msg":{"market_ticker":"KXBTCPERP1","price":"6.3900","delta":"-1.00","side":"bid","ts_ms":1781237159939}}

{"type":"trade","sid":2,"seq":54,"msg":{"trade_id":"03880754-2124-406f-59c8-4d843b46460a","market_ticker":"KXBTCPERP1","price":"6.3900","count":"1.00","taker_side":"ask","ts_ms":1781237159939}}

{"type":"orderbook_delta","sid":1,"seq":208,"msg":{"market_ticker":"KXBTCPERP1","price":"6.3900","delta":"-1.00","side":"bid","ts_ms":1781237160030}}

{"type":"trade","sid":2,"seq":55,"msg":{"trade_id":"c3a608f9-6e38-790f-caf0-1c4a8bf8942a","market_ticker":"KXBTCPERP1","price":"6.3900","count":"1.00","taker_side":"ask","ts_ms":1781237160030}}

{"type":"orderbook_delta","sid":1,"seq":209,"msg":{"market_ticker":"KXBTCPERP1","price":"6.3007","delta":"1.00","side":"bid","ts_ms":1781237160183}}

{"type":"orderbook_delta","sid":1,"seq":210,"msg":{"market_ticker":"KXBTCPERP1","price":"6.5165","delta":"1.00","side":"ask","ts_ms":1781237160226}}

{"type":"orderbook_delta","sid":1,"seq":211,"msg":{"market_ticker":"KXBTCPERP1","price":"6.3900","delta":"-586.00","side":"bid","ts_ms":1781237160238}}

{"type":"orderbook_delta","sid":1,"seq":212,"msg":{"market_ticker":"KXBTCPERP1","price":"6.2910","delta":"598.00","side":"bid","ts_ms":1781237160238}}

{"type":"orderbook_delta","sid":1,"seq":213,"msg":{"market_ticker":"KXBTCPERP1","price":"6.3898","delta":"-783.00","side":"bid","ts_ms":1781237160242}}

{"type":"orderbook_delta","sid":1,"seq":214,"msg":{"market_ticker":"KXBTCPERP1","price":"6.2899","delta":"795.00","side":"bid","ts_ms":1781237160242}}

{"type":"trade","sid":2,"seq":56,"msg":{"trade_id":"227f7bea-77f1-5b08-8f1f-f6d2cc411061","market_ticker":"KXBTCPERP1","price":"6.3896","count":"1.00","taker_side":"ask","ts_ms":1781237160244}}

{"type":"orderbook_delta","sid":1,"seq":215,"msg":{"market_ticker":"KXBTCPERP1","price":"6.3896","delta":"-1.00","side":"bid","ts_ms":1781237160244}}

{"type":"orderbook_delta","sid":1,"seq":216,"msg":{"market_ticker":"KXBTCPERP1","price":"6.3896","delta":"-782.00","side":"bid","ts_ms":1781237160246}}

{"type":"orderbook_delta","sid":1,"seq":217,"msg":{"market_ticker":"KXBTCPERP1","price":"6.2888","delta":"795.00","side":"bid","ts_ms":1781237160246}}

{"type":"orderbook_delta","sid":1,"seq":218,"msg":{"market_ticker":"KXBTCPERP1","price":"6.3894","delta":"-783.00","side":"bid","ts_ms":1781237160248}}

{"type":"orderbook_delta","sid":1,"seq":219,"msg":{"market_ticker":"KXBTCPERP1","price":"6.2877","delta":"796.00","side":"bid","ts_ms":1781237160248}}

{"type":"orderbook_delta","sid":1,"seq":220,"msg":{"market_ticker":"KXBTCPERP1","price":"6.3892","delta":"-782.00","side":"bid","ts_ms":1781237160251}}

{"type":"orderbook_delta","sid":1,"seq":221,"msg":{"market_ticker":"KXBTCPERP1","price":"6.2866","delta":"795.00","side":"bid","ts_ms":1781237160251}}

{"type":"orderbook_delta","sid":1,"seq":222,"msg":{"market_ticker":"KXBTCPERP1","price":"6.3890","delta":"-783.00","side":"bid","ts_ms":1781237160255}}

{"type":"orderbook_delta","sid":1,"seq":223,"msg":{"market_ticker":"KXBTCPERP1","price":"6.2855","delta":"796.00","side":"bid","ts_ms":1781237160255}}

{"type":"orderbook_delta","sid":1,"seq":224,"msg":{"market_ticker":"KXBTCPERP1","price":"6.3888","delta":"-782.00","side":"bid","ts_ms":1781237160258}}

{"type":"orderbook_delta","sid":1,"seq":225,"msg":{"market_ticker":"KXBTCPERP1","price":"6.2844","delta":"795.00","side":"bid","ts_ms":1781237160258}}

{"type":"orderbook_delta","sid":1,"seq":226,"msg":{"market_ticker":"KXBTCPERP1","price":"6.3886","delta":"-783.00","side":"bid","ts_ms":1781237160261}}

{"type":"orderbook_delta","sid":1,"seq":227,"msg":{"market_ticker":"KXBTCPERP1","price":"6.2833","delta":"796.00","side":"bid","ts_ms":1781237160261}}

{"type":"orderbook_delta","sid":1,"seq":228,"msg":{"market_ticker":"KXBTCPERP1","price":"6.3884","delta":"-783.00","side":"bid","ts_ms":1781237160265}}

{"type":"orderbook_delta","sid":1,"seq":229,"msg":{"market_ticker":"KXBTCPERP1","price":"6.2822","delta":"796.00","side":"bid","ts_ms":1781237160265}}

{"type":"orderbook_delta","sid":1,"seq":230,"msg":{"market_ticker":"KXBTCPERP1","price":"6.2811","delta":"797.00","side":"bid","ts_ms":1781237160268}}

{"type":"orderbook_delta","sid":1,"seq":231,"msg":{"market_ticker":"KXBTCPERP1","price":"6.3894","delta":"-11.00","side":"bid","ts_ms":1781237160272}}

{"type":"orderbook_delta","sid":1,"seq":232,"msg":{"market_ticker":"KXBTCPERP1","price":"6.3893","delta":"-10.00","side":"bid","ts_ms":1781237160272}}

{"type":"orderbook_delta","sid":1,"seq":233,"msg":{"market_ticker":"KXBTCPERP1","price":"6.3831","delta":"-1.00","side":"bid","ts_ms":1781237160272}}

{"type":"orderbook_delta","sid":1,"seq":234,"msg":{"market_ticker":"KXBTCPERP1","price":"6.3830","delta":"-132.00","side":"bid","ts_ms":1781237160272}}

{"type":"orderbook_delta","sid":1,"seq":235,"msg":{"market_ticker":"KXBTCPERP1","price":"6.3750","delta":"-206.00","side":"bid","ts_ms":1781237160272}}

{"type":"orderbook_delta","sid":1,"seq":236,"msg":{"market_ticker":"KXBTCPERP1","price":"6.3934","delta":"-349.00","side":"ask","ts_ms":1781237160272}}

{"type":"trade","sid":2,"seq":57,"msg":{"trade_id":"0290d8ef-1569-4fd7-3bdc-2aa24413845d","market_ticker":"KXBTCPERP1","price":"6.3894","count":"11.00","taker_side":"ask","ts_ms":1781237160272}}

{"type":"trade","sid":2,"seq":58,"msg":{"trade_id":"7684939e-d8ca-4e4c-35d6-96c1b728eb82","market_ticker":"KXBTCPERP1","price":"6.3893","count":"10.00","taker_side":"ask","ts_ms":1781237160272}}

{"type":"trade","sid":2,"seq":59,"msg":{"trade_id":"f2b47078-b203-402e-0712-21fd25d44f40","market_ticker":"KXBTCPERP1","price":"6.3831","count":"1.00","taker_side":"ask","ts_ms":1781237160272}}

{"type":"trade","sid":2,"seq":60,"msg":{"trade_id":"dc7fa44d-3c3d-4332-2066-38ee8686b3cd","market_ticker":"KXBTCPERP1","price":"6.3830","count":"132.00","taker_side":"ask","ts_ms":1781237160272}}

{"type":"trade","sid":2,"seq":61,"msg":{"trade_id":"7b625ede-8472-4220-0b83-3c08643c6293","market_ticker":"KXBTCPERP1","price":"6.3750","count":"206.00","taker_side":"ask","ts_ms":1781237160272}}

{"type":"orderbook_delta","sid":1,"seq":237,"msg":{"market_ticker":"KXBTCPERP1","price":"6.3750","delta":"-321.00","side":"bid","ts_ms":1781237160276}}

{"type":"orderbook_delta","sid":1,"seq":238,"msg":{"market_ticker":"KXBTCPERP1","price":"6.3730","delta":"-1.00","side":"bid","ts_ms":1781237160276}}

{"type":"orderbook_delta","sid":1,"seq":239,"msg":{"market_ticker":"KXBTCPERP1","price":"6.3642","delta":"-1.00","side":"bid","ts_ms":1781237160276}}

{"type":"orderbook_delta","sid":1,"seq":240,"msg":{"market_ticker":"KXBTCPERP1","price":"6.3642","delta":"-1.00","side":"bid","ts_ms":1781237160276}}

{"type":"orderbook_delta","sid":1,"seq":241,"msg":{"market_ticker":"KXBTCPERP1","price":"6.3642","delta":"-1.00","side":"bid","ts_ms":1781237160276}}

{"type":"orderbook_delta","sid":1,"seq":242,"msg":{"market_ticker":"KXBTCPERP1","price":"6.3641","delta":"-1.00","side":"bid","ts_ms":1781237160276}}

{"type":"orderbook_delta","sid":1,"seq":243,"msg":{"market_ticker":"KXBTCPERP1","price":"6.3641","delta":"-1.00","side":"bid","ts_ms":1781237160276}}

{"type":"orderbook_delta","sid":1,"seq":244,"msg":{"market_ticker":"KXBTCPERP1","price":"6.3640","delta":"-1.00","side":"bid","ts_ms":1781237160276}}

{"type":"orderbook_delta","sid":1,"seq":245,"msg":{"market_ticker":"KXBTCPERP1","price":"6.3640","delta":"-1.00","side":"bid","ts_ms":1781237160276}}

{"type":"orderbook_delta","sid":1,"seq":246,"msg":{"market_ticker":"KXBTCPERP1","price":"6.3639","delta":"-1.00","side":"bid","ts_ms":1781237160276}}

{"type":"orderbook_delta","sid":1,"seq":247,"msg":{"market_ticker":"KXBTCPERP1","price":"6.3639","delta":"-1.00","side":"bid","ts_ms":1781237160276}}

{"type":"orderbook_delta","sid":1,"seq":248,"msg":{"market_ticker":"KXBTCPERP1","price":"6.3639","delta":"-1.00","side":"bid","ts_ms":1781237160276}}

{"type":"orderbook_delta","sid":1,"seq":249,"msg":{"market_ticker":"KXBTCPERP1","price":"6.3639","delta":"-1.00","side":"bid","ts_ms":1781237160276}}

{"type":"orderbook_delta","sid":1,"seq":250,"msg":{"market_ticker":"KXBTCPERP1","price":"6.3639","delta":"-1.00","side":"bid","ts_ms":1781237160276}}

{"type":"orderbook_delta","sid":1,"seq":251,"msg":{"market_ticker":"KXBTCPERP1","price":"6.3639","delta":"-1.00","side":"bid","ts_ms":1781237160276}}

{"type":"orderbook_delta","sid":1,"seq":252,"msg":{"market_ticker":"KXBTCPERP1","price":"6.3638","delta":"-1.00","side":"bid","ts_ms":1781237160276}}

{"type":"orderbook_delta","sid":1,"seq":253,"msg":{"market_ticker":"KXBTCPERP1","price":"6.3638","delta":"-1.00","side":"bid","ts_ms":1781237160276}}

{"type":"orderbook_delta","sid":1,"seq":254,"msg":{"market_ticker":"KXBTCPERP1","price":"6.3637","delta":"-1.00","side":"bid","ts_ms":1781237160276}}

{"type":"orderbook_delta","sid":1,"seq":255,"msg":{"market_ticker":"KXBTCPERP1","price":"6.3637","delta":"-1.00","side":"bid","ts_ms":1781237160276}}

{"type":"orderbook_delta","sid":1,"seq":256,"msg":{"market_ticker":"KXBTCPERP1","price":"6.3636","delta":"-1.00","side":"bid","ts_ms":1781237160276}}

{"type":"orderbook_delta","sid":1,"seq":257,"msg":{"market_ticker":"KXBTCPERP1","price":"6.3636","delta":"-1.00","side":"bid","ts_ms":1781237160276}}

{"type":"orderbook_delta","sid":1,"seq":258,"msg":{"market_ticker":"KXBTCPERP1","price":"6.3636","delta":"-1.00","side":"bid","ts_ms":1781237160276}}

{"type":"orderbook_delta","sid":1,"seq":259,"msg":{"market_ticker":"KXBTCPERP1","price":"6.3636","delta":"-1.00","side":"bid","ts_ms":1781237160276}}

{"type":"orderbook_delta","sid":1,"seq":260,"msg":{"market_ticker":"KXBTCPERP1","price":"6.3635","delta":"-1.00","side":"bid","ts_ms":1781237160276}}

{"type":"orderbook_delta","sid":1,"seq":261,"msg":{"market_ticker":"KXBTCPERP1","price":"6.3635","delta":"-1.00","side":"bid","ts_ms":1781237160276}}

{"type":"orderbook_delta","sid":1,"seq":262,"msg":{"market_ticker":"KXBTCPERP1","price":"6.3635","delta":"-1.00","side":"bid","ts_ms":1781237160276}}

{"type":"orderbook_delta","sid":1,"seq":263,"msg":{"market_ticker":"KXBTCPERP1","price":"6.3634","delta":"-1.00","side":"bid","ts_ms":1781237160276}}

{"type":"orderbook_delta","sid":1,"seq":264,"msg":{"market_ticker":"KXBTCPERP1","price":"6.3634","delta":"-1.00","side":"bid","ts_ms":1781237160276}}

{"type":"orderbook_delta","sid":1,"seq":265,"msg":{"market_ticker":"KXBTCPERP1","price":"6.3634","delta":"-1.00","side":"bid","ts_ms":1781237160276}}

{"type":"orderbook_delta","sid":1,"seq":266,"msg":{"market_ticker":"KXBTCPERP1","price":"6.3634","delta":"-1.00","side":"bid","ts_ms":1781237160276}}

{"type":"orderbook_delta","sid":1,"seq":267,"msg":{"market_ticker":"KXBTCPERP1","price":"6.3634","delta":"-1.00","side":"bid","ts_ms":1781237160276}}

{"type":"orderbook_delta","sid":1,"seq":268,"msg":{"market_ticker":"KXBTCPERP1","price":"6.3634","delta":"-1.00","side":"bid","ts_ms":1781237160276}}

{"type":"orderbook_delta","sid":1,"seq":269,"msg":{"market_ticker":"KXBTCPERP1","price":"6.3633","delta":"-1.00","side":"bid","ts_ms":1781237160276}}

{"type":"orderbook_delta","sid":1,"seq":270,"msg":{"market_ticker":"KXBTCPERP1","price":"6.3632","delta":"-1.00","side":"bid","ts_ms":1781237160276}}

{"type":"orderbook_delta","sid":1,"seq":271,"msg":{"market_ticker":"KXBTCPERP1","price":"6.3632","delta":"-1.00","side":"bid","ts_ms":1781237160276}}

{"type":"orderbook_delta","sid":1,"seq":272,"msg":{"market_ticker":"KXBTCPERP1","price":"6.3632","delta":"-1.00","side":"bid","ts_ms":1781237160276}}

{"type":"orderbook_delta","sid":1,"seq":273,"msg":{"market_ticker":"KXBTCPERP1","price":"6.3632","delta":"-1.00","side":"bid","ts_ms":1781237160276}}

{"type":"orderbook_delta","sid":1,"seq":274,"msg":{"market_ticker":"KXBTCPERP1","price":"6.3631","delta":"-1.00","side":"bid","ts_ms":1781237160276}}

{"type":"orderbook_delta","sid":1,"seq":275,"msg":{"market_ticker":"KXBTCPERP1","price":"6.3631","delta":"-1.00","side":"bid","ts_ms":1781237160276}}

{"type":"orderbook_delta","sid":1,"seq":276,"msg":{"market_ticker":"KXBTCPERP1","price":"6.3630","delta":"-1.00","side":"bid","ts_ms":1781237160276}}

{"type":"orderbook_delta","sid":1,"seq":277,"msg":{"market_ticker":"KXBTCPERP1","price":"6.3630","delta":"-1.00","side":"bid","ts_ms":1781237160276}}

{"type":"orderbook_delta","sid":1,"seq":278,"msg":{"market_ticker":"KXBTCPERP1","price":"6.3630","delta":"-1.00","side":"bid","ts_ms":1781237160276}}

{"type":"orderbook_delta","sid":1,"seq":279,"msg":{"market_ticker":"KXBTCPERP1","price":"6.3629","delta":"-1.00","side":"bid","ts_ms":1781237160276}}

{"type":"orderbook_delta","sid":1,"seq":280,"msg":{"market_ticker":"KXBTCPERP1","price":"6.3629","delta":"-1.00","side":"bid","ts_ms":1781237160276}}

{"type":"orderbook_delta","sid":1,"seq":281,"msg":{"market_ticker":"KXBTCPERP1","price":"6.3628","delta":"-1.00","side":"bid","ts_ms":1781237160276}}

{"type":"orderbook_delta","sid":1,"seq":282,"msg":{"market_ticker":"KXBTCPERP1","price":"6.3627","delta":"-1.00","side":"bid","ts_ms":1781237160276}}

{"type":"orderbook_delta","sid":1,"seq":283,"msg":{"market_ticker":"KXBTCPERP1","price":"6.3626","delta":"-1.00","side":"bid","ts_ms":1781237160276}}

{"type":"orderbook_delta","sid":1,"seq":284,"msg":{"market_ticker":"KXBTCPERP1","price":"6.3626","delta":"-1.00","side":"bid","ts_ms":1781237160276}}

{"type":"orderbook_delta","sid":1,"seq":285,"msg":{"market_ticker":"KXBTCPERP1","price":"6.3625","delta":"-1.00","side":"bid","ts_ms":1781237160276}}

{"type":"orderbook_delta","sid":1,"seq":286,"msg":{"market_ticker":"KXBTCPERP1","price":"6.3625","delta":"-1.00","side":"bid","ts_ms":1781237160276}}

{"type":"orderbook_delta","sid":1,"seq":287,"msg":{"market_ticker":"KXBTCPERP1","price":"6.3625","delta":"-1.00","side":"bid","ts_ms":1781237160276}}

{"type":"orderbook_delta","sid":1,"seq":288,"msg":{"market_ticker":"KXBTCPERP1","price":"6.3624","delta":"-1.00","side":"bid","ts_ms":1781237160276}}

{"type":"orderbook_delta","sid":1,"seq":289,"msg":{"market_ticker":"KXBTCPERP1","price":"6.3624","delta":"-1.00","side":"bid","ts_ms":1781237160276}}

{"type":"orderbook_delta","sid":1,"seq":290,"msg":{"market_ticker":"KXBTCPERP1","price":"6.3624","delta":"-1.00","side":"bid","ts_ms":1781237160276}}

{"type":"orderbook_delta","sid":1,"seq":291,"msg":{"market_ticker":"KXBTCPERP1","price":"6.3624","delta":"-1.00","side":"bid","ts_ms":1781237160276}}

{"type":"orderbook_delta","sid":1,"seq":292,"msg":{"market_ticker":"KXBTCPERP1","price":"6.3624","delta":"-1.00","side":"bid","ts_ms":1781237160276}}

{"type":"orderbook_delta","sid":1,"seq":293,"msg":{"market_ticker":"KXBTCPERP1","price":"6.3623","delta":"-1.00","side":"bid","ts_ms":1781237160276}}

{"type":"orderbook_delta","sid":1,"seq":294,"msg":{"market_ticker":"KXBTCPERP1","price":"6.3623","delta":"-1.00","side":"bid","ts_ms":1781237160276}}

{"type":"orderbook_delta","sid":1,"seq":295,"msg":{"market_ticker":"KXBTCPERP1","price":"6.3623","delta":"-1.00","side":"bid","ts_ms":1781237160276}}

{"type":"orderbook_delta","sid":1,"seq":296,"msg":{"market_ticker":"KXBTCPERP1","price":"6.3623","delta":"-1.00","side":"bid","ts_ms":1781237160276}}

{"type":"orderbook_delta","sid":1,"seq":297,"msg":{"market_ticker":"KXBTCPERP1","price":"6.3622","delta":"-1.00","side":"bid","ts_ms":1781237160276}}

{"type":"orderbook_delta","sid":1,"seq":298,"msg":{"market_ticker":"KXBTCPERP1","price":"6.3621","delta":"-1.00","side":"bid","ts_ms":1781237160276}}

{"type":"orderbook_delta","sid":1,"seq":299,"msg":{"market_ticker":"KXBTCPERP1","price":"6.3620","delta":"-1.00","side":"bid","ts_ms":1781237160276}}

{"type":"orderbook_delta","sid":1,"seq":300,"msg":{"market_ticker":"KXBTCPERP1","price":"6.3620","delta":"-1.00","side":"bid","ts_ms":1781237160276}}

{"type":"orderbook_delta","sid":1,"seq":301,"msg":{"market_ticker":"KXBTCPERP1","price":"6.3620","delta":"-1.00","side":"bid","ts_ms":1781237160276}}

{"type":"orderbook_delta","sid":1,"seq":302,"msg":{"market_ticker":"KXBTCPERP1","price":"6.3620","delta":"-1.00","side":"bid","ts_ms":1781237160276}}

{"type":"orderbook_delta","sid":1,"seq":303,"msg":{"market_ticker":"KXBTCPERP1","price":"6.3620","delta":"-1.00","side":"bid","ts_ms":1781237160276}}

{"type":"orderbook_delta","sid":1,"seq":304,"msg":{"market_ticker":"KXBTCPERP1","price":"6.3619","delta":"-1.00","side":"bid","ts_ms":1781237160276}}

{"type":"orderbook_delta","sid":1,"seq":305,"msg":{"market_ticker":"KXBTCPERP1","price":"6.3619","delta":"-1.00","side":"bid","ts_ms":1781237160276}}

{"type":"orderbook_delta","sid":1,"seq":306,"msg":{"market_ticker":"KXBTCPERP1","price":"6.3618","delta":"-1.00","side":"bid","ts_ms":1781237160276}}

{"type":"orderbook_delta","sid":1,"seq":307,"msg":{"market_ticker":"KXBTCPERP1","price":"6.3618","delta":"-1.00","side":"bid","ts_ms":1781237160276}}

{"type":"orderbook_delta","sid":1,"seq":308,"msg":{"market_ticker":"KXBTCPERP1","price":"6.3617","delta":"-1.00","side":"bid","ts_ms":1781237160276}}

{"type":"orderbook_delta","sid":1,"seq":309,"msg":{"market_ticker":"KXBTCPERP1","price":"6.3617","delta":"-1.00","side":"bid","ts_ms":1781237160276}}

{"type":"orderbook_delta","sid":1,"seq":310,"msg":{"market_ticker":"KXBTCPERP1","price":"6.3617","delta":"-1.00","side":"bid","ts_ms":1781237160276}}

{"type":"orderbook_delta","sid":1,"seq":311,"msg":{"market_ticker":"KXBTCPERP1","price":"6.3616","delta":"-1.00","side":"bid","ts_ms":1781237160276}}

{"type":"orderbook_delta","sid":1,"seq":312,"msg":{"market_ticker":"KXBTCPERP1","price":"6.3616","delta":"-1.00","side":"bid","ts_ms":1781237160276}}

{"type":"orderbook_delta","sid":1,"seq":313,"msg":{"market_ticker":"KXBTCPERP1","price":"6.3616","delta":"-1.00","side":"bid","ts_ms":1781237160276}}

{"type":"orderbook_delta","sid":1,"seq":314,"msg":{"market_ticker":"KXBTCPERP1","price":"6.3615","delta":"-1.00","side":"bid","ts_ms":1781237160276}}

{"type":"orderbook_delta","sid":1,"seq":315,"msg":{"market_ticker":"KXBTCPERP1","price":"6.3614","delta":"-1.00","side":"bid","ts_ms":1781237160276}}

{"type":"orderbook_delta","sid":1,"seq":316,"msg":{"market_ticker":"KXBTCPERP1","price":"6.3614","delta":"-1.00","side":"bid","ts_ms":1781237160276}}

{"type":"orderbook_delta","sid":1,"seq":317,"msg":{"market_ticker":"KXBTCPERP1","price":"6.3614","delta":"-1.00","side":"bid","ts_ms":1781237160276}}

{"type":"orderbook_delta","sid":1,"seq":318,"msg":{"market_ticker":"KXBTCPERP1","price":"6.3614","delta":"-1.00","side":"bid","ts_ms":1781237160276}}

{"type":"orderbook_delta","sid":1,"seq":319,"msg":{"market_ticker":"KXBTCPERP1","price":"6.3614","delta":"-1.00","side":"bid","ts_ms":1781237160276}}

{"type":"orderbook_delta","sid":1,"seq":320,"msg":{"market_ticker":"KXBTCPERP1","price":"6.3613","delta":"-1.00","side":"bid","ts_ms":1781237160276}}

{"type":"orderbook_delta","sid":1,"seq":321,"msg":{"market_ticker":"KXBTCPERP1","price":"6.3613","delta":"-1.00","side":"bid","ts_ms":1781237160276}}

{"type":"orderbook_delta","sid":1,"seq":322,"msg":{"market_ticker":"KXBTCPERP1","price":"6.3613","delta":"-1.00","side":"bid","ts_ms":1781237160276}}

{"type":"orderbook_delta","sid":1,"seq":323,"msg":{"market_ticker":"KXBTCPERP1","price":"6.3612","delta":"-1.00","side":"bid","ts_ms":1781237160276}}

{"type":"orderbook_delta","sid":1,"seq":324,"msg":{"market_ticker":"KXBTCPERP1","price":"6.3612","delta":"-1.00","side":"bid","ts_ms":1781237160276}}

{"type":"orderbook_delta","sid":1,"seq":325,"msg":{"market_ticker":"KXBTCPERP1","price":"6.3612","delta":"-1.00","side":"bid","ts_ms":1781237160276}}

{"type":"orderbook_delta","sid":1,"seq":326,"msg":{"market_ticker":"KXBTCPERP1","price":"6.3611","delta":"-1.00","side":"bid","ts_ms":1781237160276}}

{"type":"orderbook_delta","sid":1,"seq":327,"msg":{"market_ticker":"KXBTCPERP1","price":"6.3610","delta":"-1.00","side":"bid","ts_ms":1781237160276}}

{"type":"orderbook_delta","sid":1,"seq":328,"msg":{"market_ticker":"KXBTCPERP1","price":"6.3610","delta":"-1.00","side":"bid","ts_ms":1781237160276}}

{"type":"orderbook_delta","sid":1,"seq":329,"msg":{"market_ticker":"KXBTCPERP1","price":"6.3610","delta":"-1.00","side":"bid","ts_ms":1781237160276}}

{"type":"orderbook_delta","sid":1,"seq":330,"msg":{"market_ticker":"KXBTCPERP1","price":"6.3610","delta":"-1.00","side":"bid","ts_ms":1781237160276}}

{"type":"orderbook_delta","sid":1,"seq":331,"msg":{"market_ticker":"KXBTCPERP1","price":"6.3609","delta":"-1.00","side":"bid","ts_ms":1781237160276}}

{"type":"orderbook_delta","sid":1,"seq":332,"msg":{"market_ticker":"KXBTCPERP1","price":"6.3608","delta":"-1.00","side":"bid","ts_ms":1781237160276}}

{"type":"orderbook_delta","sid":1,"seq":333,"msg":{"market_ticker":"KXBTCPERP1","price":"6.3608","delta":"-1.00","side":"bid","ts_ms":1781237160276}}

{"type":"orderbook_delta","sid":1,"seq":334,"msg":{"market_ticker":"KXBTCPERP1","price":"6.3608","delta":"-1.00","side":"bid","ts_ms":1781237160276}}

{"type":"orderbook_delta","sid":1,"seq":335,"msg":{"market_ticker":"KXBTCPERP1","price":"6.3606","delta":"-1.00","side":"bid","ts_ms":1781237160276}}

{"type":"orderbook_delta","sid":1,"seq":336,"msg":{"market_ticker":"KXBTCPERP1","price":"6.3606","delta":"-1.00","side":"bid","ts_ms":1781237160276}}

{"type":"orderbook_delta","sid":1,"seq":337,"msg":{"market_ticker":"KXBTCPERP1","price":"6.3606","delta":"-1.00","side":"bid","ts_ms":1781237160276}}

{"type":"orderbook_delta","sid":1,"seq":338,"msg":{"market_ticker":"KXBTCPERP1","price":"6.3606","delta":"-1.00","side":"bid","ts_ms":1781237160276}}

{"type":"orderbook_delta","sid":1,"seq":339,"msg":{"market_ticker":"KXBTCPERP1","price":"6.3605","delta":"-1.00","side":"bid","ts_ms":1781237160276}}

{"type":"orderbook_delta","sid":1,"seq":340,"msg":{"market_ticker":"KXBTCPERP1","price":"6.3605","delta":"-1.00","side":"bid","ts_ms":1781237160276}}

{"type":"orderbook_delta","sid":1,"seq":341,"msg":{"market_ticker":"KXBTCPERP1","price":"6.3605","delta":"-1.00","side":"bid","ts_ms":1781237160276}}

{"type":"orderbook_delta","sid":1,"seq":342,"msg":{"market_ticker":"KXBTCPERP1","price":"6.3605","delta":"-1.00","side":"bid","ts_ms":1781237160276}}

{"type":"orderbook_delta","sid":1,"seq":343,"msg":{"market_ticker":"KXBTCPERP1","price":"6.3604","delta":"-1.00","side":"bid","ts_ms":1781237160276}}

{"type":"orderbook_delta","sid":1,"seq":344,"msg":{"market_ticker":"KXBTCPERP1","price":"6.3604","delta":"-1.00","side":"bid","ts_ms":1781237160276}}

{"type":"orderbook_delta","sid":1,"seq":345,"msg":{"market_ticker":"KXBTCPERP1","price":"6.3603","delta":"-1.00","side":"bid","ts_ms":1781237160276}}

{"type":"orderbook_delta","sid":1,"seq":346,"msg":{"market_ticker":"KXBTCPERP1","price":"6.3603","delta":"-1.00","side":"bid","ts_ms":1781237160276}}

{"type":"orderbook_delta","sid":1,"seq":347,"msg":{"market_ticker":"KXBTCPERP1","price":"6.3603","delta":"-1.00","side":"bid","ts_ms":1781237160276}}

{"type":"orderbook_delta","sid":1,"seq":348,"msg":{"market_ticker":"KXBTCPERP1","price":"6.3603","delta":"-1.00","side":"bid","ts_ms":1781237160276}}

{"type":"orderbook_delta","sid":1,"seq":349,"msg":{"market_ticker":"KXBTCPERP1","price":"6.3602","delta":"-1.00","side":"bid","ts_ms":1781237160276}}

{"type":"orderbook_delta","sid":1,"seq":350,"msg":{"market_ticker":"KXBTCPERP1","price":"6.3602","delta":"-1.00","side":"bid","ts_ms":1781237160276}}

{"type":"orderbook_delta","sid":1,"seq":351,"msg":{"market_ticker":"KXBTCPERP1","price":"6.3602","delta":"-1.00","side":"bid","ts_ms":1781237160276}}

{"type":"orderbook_delta","sid":1,"seq":352,"msg":{"market_ticker":"KXBTCPERP1","price":"6.3599","delta":"-1.00","side":"bid","ts_ms":1781237160276}}

{"type":"orderbook_delta","sid":1,"seq":353,"msg":{"market_ticker":"KXBTCPERP1","price":"6.3599","delta":"-1.00","side":"bid","ts_ms":1781237160276}}

{"type":"orderbook_delta","sid":1,"seq":354,"msg":{"market_ticker":"KXBTCPERP1","price":"6.3598","delta":"-1.00","side":"bid","ts_ms":1781237160276}}

{"type":"orderbook_delta","sid":1,"seq":355,"msg":{"market_ticker":"KXBTCPERP1","price":"6.3598","delta":"-1.00","side":"bid","ts_ms":1781237160276}}

{"type":"orderbook_delta","sid":1,"seq":356,"msg":{"market_ticker":"KXBTCPERP1","price":"6.3597","delta":"-1.00","side":"bid","ts_ms":1781237160276}}

{"type":"orderbook_delta","sid":1,"seq":357,"msg":{"market_ticker":"KXBTCPERP1","price":"6.3597","delta":"-1.00","side":"bid","ts_ms":1781237160276}}

{"type":"orderbook_delta","sid":1,"seq":358,"msg":{"market_ticker":"KXBTCPERP1","price":"6.3597","delta":"-1.00","side":"bid","ts_ms":1781237160276}}

{"type":"orderbook_delta","sid":1,"seq":359,"msg":{"market_ticker":"KXBTCPERP1","price":"6.3597","delta":"-1.00","side":"bid","ts_ms":1781237160276}}

{"type":"orderbook_delta","sid":1,"seq":360,"msg":{"market_ticker":"KXBTCPERP1","price":"6.3597","delta":"-1.00","side":"bid","ts_ms":1781237160276}}

{"type":"orderbook_delta","sid":1,"seq":361,"msg":{"market_ticker":"KXBTCPERP1","price":"6.3597","delta":"-1.00","side":"bid","ts_ms":1781237160276}}

{"type":"orderbook_delta","sid":1,"seq":362,"msg":{"market_ticker":"KXBTCPERP1","price":"6.3596","delta":"-1.00","side":"bid","ts_ms":1781237160276}}

{"type":"orderbook_delta","sid":1,"seq":363,"msg":{"market_ticker":"KXBTCPERP1","price":"6.3596","delta":"-1.00","side":"bid","ts_ms":1781237160276}}

{"type":"orderbook_delta","sid":1,"seq":364,"msg":{"market_ticker":"KXBTCPERP1","price":"6.3596","delta":"-1.00","side":"bid","ts_ms":1781237160276}}

{"type":"orderbook_delta","sid":1,"seq":365,"msg":{"market_ticker":"KXBTCPERP1","price":"6.3595","delta":"-1.00","side":"bid","ts_ms":1781237160276}}

{"type":"orderbook_delta","sid":1,"seq":366,"msg":{"market_ticker":"KXBTCPERP1","price":"6.3594","delta":"-1.00","side":"bid","ts_ms":1781237160276}}

{"type":"orderbook_delta","sid":1,"seq":367,"msg":{"market_ticker":"KXBTCPERP1","price":"6.3594","delta":"-1.00","side":"bid","ts_ms":1781237160276}}

{"type":"orderbook_delta","sid":1,"seq":368,"msg":{"market_ticker":"KXBTCPERP1","price":"6.3594","delta":"-1.00","side":"bid","ts_ms":1781237160276}}

{"type":"orderbook_delta","sid":1,"seq":369,"msg":{"market_ticker":"KXBTCPERP1","price":"6.3594","delta":"-1.00","side":"bid","ts_ms":1781237160276}}

{"type":"orderbook_delta","sid":1,"seq":370,"msg":{"market_ticker":"KXBTCPERP1","price":"6.3594","delta":"-1.00","side":"bid","ts_ms":1781237160276}}

{"type":"orderbook_delta","sid":1,"seq":371,"msg":{"market_ticker":"KXBTCPERP1","price":"6.3593","delta":"-1.00","side":"bid","ts_ms":1781237160276}}

{"type":"orderbook_delta","sid":1,"seq":372,"msg":{"market_ticker":"KXBTCPERP1","price":"6.3593","delta":"-1.00","side":"bid","ts_ms":1781237160276}}

{"type":"orderbook_delta","sid":1,"seq":373,"msg":{"market_ticker":"KXBTCPERP1","price":"6.3593","delta":"-1.00","side":"bid","ts_ms":1781237160276}}

{"type":"orderbook_delta","sid":1,"seq":374,"msg":{"market_ticker":"KXBTCPERP1","price":"6.3593","delta":"-1.00","side":"bid","ts_ms":1781237160276}}

{"type":"orderbook_delta","sid":1,"seq":375,"msg":{"market_ticker":"KXBTCPERP1","price":"6.3592","delta":"-1.00","side":"bid","ts_ms":1781237160276}}

{"type":"orderbook_delta","sid":1,"seq":376,"msg":{"market_ticker":"KXBTCPERP1","price":"6.3592","delta":"-1.00","side":"bid","ts_ms":1781237160276}}

{"type":"orderbook_delta","sid":1,"seq":377,"msg":{"market_ticker":"KXBTCPERP1","price":"6.3592","delta":"-1.00","side":"bid","ts_ms":1781237160276}}

{"type":"orderbook_delta","sid":1,"seq":378,"msg":{"market_ticker":"KXBTCPERP1","price":"6.3591","delta":"-1.00","side":"bid","ts_ms":1781237160276}}

{"type":"orderbook_delta","sid":1,"seq":379,"msg":{"market_ticker":"KXBTCPERP1","price":"6.3590","delta":"-1.00","side":"bid","ts_ms":1781237160276}}

{"type":"orderbook_delta","sid":1,"seq":380,"msg":{"market_ticker":"KXBTCPERP1","price":"6.3589","delta":"-1.00","side":"bid","ts_ms":1781237160276}}

{"type":"orderbook_delta","sid":1,"seq":381,"msg":{"market_ticker":"KXBTCPERP1","price":"6.3589","delta":"-1.00","side":"bid","ts_ms":1781237160276}}

{"type":"orderbook_delta","sid":1,"seq":382,"msg":{"market_ticker":"KXBTCPERP1","price":"6.3589","delta":"-1.00","side":"bid","ts_ms":1781237160276}}

{"type":"orderbook_delta","sid":1,"seq":383,"msg":{"market_ticker":"KXBTCPERP1","price":"6.3588","delta":"-1.00","side":"bid","ts_ms":1781237160276}}

{"type":"orderbook_delta","sid":1,"seq":384,"msg":{"market_ticker":"KXBTCPERP1","price":"6.3588","delta":"-1.00","side":"bid","ts_ms":1781237160276}}

{"type":"orderbook_delta","sid":1,"seq":385,"msg":{"market_ticker":"KXBTCPERP1","price":"6.3588","delta":"-1.00","side":"bid","ts_ms":1781237160276}}

{"type":"orderbook_delta","sid":1,"seq":386,"msg":{"market_ticker":"KXBTCPERP1","price":"6.3588","delta":"-1.00","side":"bid","ts_ms":1781237160276}}

{"type":"orderbook_delta","sid":1,"seq":387,"msg":{"market_ticker":"KXBTCPERP1","price":"6.3587","delta":"-1.00","side":"bid","ts_ms":1781237160276}}

{"type":"orderbook_delta","sid":1,"seq":388,"msg":{"market_ticker":"KXBTCPERP1","price":"6.3586","delta":"-1.00","side":"bid","ts_ms":1781237160276}}

{"type":"orderbook_delta","sid":1,"seq":389,"msg":{"market_ticker":"KXBTCPERP1","price":"6.3586","delta":"-1.00","side":"bid","ts_ms":1781237160276}}

{"type":"orderbook_delta","sid":1,"seq":390,"msg":{"market_ticker":"KXBTCPERP1","price":"6.3586","delta":"-1.00","side":"bid","ts_ms":1781237160276}}

{"type":"orderbook_delta","sid":1,"seq":391,"msg":{"market_ticker":"KXBTCPERP1","price":"6.3585","delta":"-1.00","side":"bid","ts_ms":1781237160276}}

{"type":"orderbook_delta","sid":1,"seq":392,"msg":{"market_ticker":"KXBTCPERP1","price":"6.3585","delta":"-1.00","side":"bid","ts_ms":1781237160276}}

{"type":"orderbook_delta","sid":1,"seq":393,"msg":{"market_ticker":"KXBTCPERP1","price":"6.3584","delta":"-1.00","side":"bid","ts_ms":1781237160276}}

{"type":"orderbook_delta","sid":1,"seq":394,"msg":{"market_ticker":"KXBTCPERP1","price":"6.3583","delta":"-1.00","side":"bid","ts_ms":1781237160276}}

{"type":"orderbook_delta","sid":1,"seq":395,"msg":{"market_ticker":"KXBTCPERP1","price":"6.3582","delta":"-1.00","side":"bid","ts_ms":1781237160276}}

{"type":"orderbook_delta","sid":1,"seq":396,"msg":{"market_ticker":"KXBTCPERP1","price":"6.3582","delta":"-1.00","side":"bid","ts_ms":1781237160276}}

{"type":"orderbook_delta","sid":1,"seq":397,"msg":{"market_ticker":"KXBTCPERP1","price":"6.3582","delta":"-1.00","side":"bid","ts_ms":1781237160276}}

{"type":"orderbook_delta","sid":1,"seq":398,"msg":{"market_ticker":"KXBTCPERP1","price":"6.3581","delta":"-1.00","side":"bid","ts_ms":1781237160276}}

{"type":"orderbook_delta","sid":1,"seq":399,"msg":{"market_ticker":"KXBTCPERP1","price":"6.3581","delta":"-1.00","side":"bid","ts_ms":1781237160276}}

{"type":"orderbook_delta","sid":1,"seq":400,"msg":{"market_ticker":"KXBTCPERP1","price":"6.3580","delta":"-1.00","side":"bid","ts_ms":1781237160276}}

{"type":"orderbook_delta","sid":1,"seq":401,"msg":{"market_ticker":"KXBTCPERP1","price":"6.3580","delta":"-1.00","side":"bid","ts_ms":1781237160276}}

{"type":"orderbook_delta","sid":1,"seq":402,"msg":{"market_ticker":"KXBTCPERP1","price":"6.3580","delta":"-1.00","side":"bid","ts_ms":1781237160276}}

{"type":"orderbook_delta","sid":1,"seq":403,"msg":{"market_ticker":"KXBTCPERP1","price":"6.3580","delta":"-1.00","side":"bid","ts_ms":1781237160276}}

{"type":"orderbook_delta","sid":1,"seq":404,"msg":{"market_ticker":"KXBTCPERP1","price":"6.3579","delta":"-1.00","side":"bid","ts_ms":1781237160276}}

{"type":"orderbook_delta","sid":1,"seq":405,"msg":{"market_ticker":"KXBTCPERP1","price":"6.3579","delta":"-1.00","side":"bid","ts_ms":1781237160276}}

{"type":"orderbook_delta","sid":1,"seq":406,"msg":{"market_ticker":"KXBTCPERP1","price":"6.3578","delta":"-1.00","side":"bid","ts_ms":1781237160276}}

{"type":"orderbook_delta","sid":1,"seq":407,"msg":{"market_ticker":"KXBTCPERP1","price":"6.3578","delta":"-1.00","side":"bid","ts_ms":1781237160276}}

{"type":"orderbook_delta","sid":1,"seq":408,"msg":{"market_ticker":"KXBTCPERP1","price":"6.3578","delta":"-1.00","side":"bid","ts_ms":1781237160276}}

{"type":"orderbook_delta","sid":1,"seq":409,"msg":{"market_ticker":"KXBTCPERP1","price":"6.3577","delta":"-1.00","side":"bid","ts_ms":1781237160276}}

{"type":"orderbook_delta","sid":1,"seq":410,"msg":{"market_ticker":"KXBTCPERP1","price":"6.3577","delta":"-1.00","side":"bid","ts_ms":1781237160276}}

{"type":"orderbook_delta","sid":1,"seq":411,"msg":{"market_ticker":"KXBTCPERP1","price":"6.3577","delta":"-1.00","side":"bid","ts_ms":1781237160276}}

{"type":"orderbook_delta","sid":1,"seq":412,"msg":{"market_ticker":"KXBTCPERP1","price":"6.3577","delta":"-1.00","side":"bid","ts_ms":1781237160276}}

{"type":"orderbook_delta","sid":1,"seq":413,"msg":{"market_ticker":"KXBTCPERP1","price":"6.3576","delta":"-1.00","side":"bid","ts_ms":1781237160276}}

{"type":"orderbook_delta","sid":1,"seq":414,"msg":{"market_ticker":"KXBTCPERP1","price":"6.3576","delta":"-1.00","side":"bid","ts_ms":1781237160276}}

{"type":"orderbook_delta","sid":1,"seq":415,"msg":{"market_ticker":"KXBTCPERP1","price":"6.3576","delta":"-1.00","side":"bid","ts_ms":1781237160276}}

{"type":"orderbook_delta","sid":1,"seq":416,"msg":{"market_ticker":"KXBTCPERP1","price":"6.3576","delta":"-1.00","side":"bid","ts_ms":1781237160276}}

{"type":"orderbook_delta","sid":1,"seq":417,"msg":{"market_ticker":"KXBTCPERP1","price":"6.3575","delta":"-1.00","side":"bid","ts_ms":1781237160276}}

{"type":"orderbook_delta","sid":1,"seq":418,"msg":{"market_ticker":"KXBTCPERP1","price":"6.3575","delta":"-1.00","side":"bid","ts_ms":1781237160276}}

{"type":"orderbook_delta","sid":1,"seq":419,"msg":{"market_ticker":"KXBTCPERP1","price":"6.3575","delta":"-1.00","side":"bid","ts_ms":1781237160276}}

{"type":"orderbook_delta","sid":1,"seq":420,"msg":{"market_ticker":"KXBTCPERP1","price":"6.3575","delta":"-1.00","side":"bid","ts_ms":1781237160276}}

{"type":"orderbook_delta","sid":1,"seq":421,"msg":{"market_ticker":"KXBTCPERP1","price":"6.3574","delta":"-1.00","side":"bid","ts_ms":1781237160276}}

{"type":"orderbook_delta","sid":1,"seq":422,"msg":{"market_ticker":"KXBTCPERP1","price":"6.3573","delta":"-1.00","side":"bid","ts_ms":1781237160276}}

{"type":"orderbook_delta","sid":1,"seq":423,"msg":{"market_ticker":"KXBTCPERP1","price":"6.3573","delta":"-1.00","side":"bid","ts_ms":1781237160276}}

{"type":"orderbook_delta","sid":1,"seq":424,"msg":{"market_ticker":"KXBTCPERP1","price":"6.3573","delta":"-1.00","side":"bid","ts_ms":1781237160276}}

{"type":"orderbook_delta","sid":1,"seq":425,"msg":{"market_ticker":"KXBTCPERP1","price":"6.3573","delta":"-1.00","side":"bid","ts_ms":1781237160276}}

{"type":"orderbook_delta","sid":1,"seq":426,"msg":{"market_ticker":"KXBTCPERP1","price":"6.3573","delta":"-1.00","side":"bid","ts_ms":1781237160276}}

{"type":"orderbook_delta","sid":1,"seq":427,"msg":{"market_ticker":"KXBTCPERP1","price":"6.3572","delta":"-1.00","side":"bid","ts_ms":1781237160276}}

{"type":"orderbook_delta","sid":1,"seq":428,"msg":{"market_ticker":"KXBTCPERP1","price":"6.3572","delta":"-1.00","side":"bid","ts_ms":1781237160276}}

{"type":"orderbook_delta","sid":1,"seq":429,"msg":{"market_ticker":"KXBTCPERP1","price":"6.3572","delta":"-1.00","side":"bid","ts_ms":1781237160276}}

{"type":"orderbook_delta","sid":1,"seq":430,"msg":{"market_ticker":"KXBTCPERP1","price":"6.3571","delta":"-1.00","side":"bid","ts_ms":1781237160276}}

{"type":"orderbook_delta","sid":1,"seq":431,"msg":{"market_ticker":"KXBTCPERP1","price":"6.3571","delta":"-1.00","side":"bid","ts_ms":1781237160276}}

{"type":"orderbook_delta","sid":1,"seq":432,"msg":{"market_ticker":"KXBTCPERP1","price":"6.3570","delta":"-1.00","side":"bid","ts_ms":1781237160276}}

{"type":"orderbook_delta","sid":1,"seq":433,"msg":{"market_ticker":"KXBTCPERP1","price":"6.3570","delta":"-1.00","side":"bid","ts_ms":1781237160276}}

{"type":"orderbook_delta","sid":1,"seq":434,"msg":{"market_ticker":"KXBTCPERP1","price":"6.3570","delta":"-1.00","side":"bid","ts_ms":1781237160276}}

{"type":"orderbook_delta","sid":1,"seq":435,"msg":{"market_ticker":"KXBTCPERP1","price":"6.3570","delta":"-1.00","side":"bid","ts_ms":1781237160276}}

{"type":"orderbook_delta","sid":1,"seq":436,"msg":{"market_ticker":"KXBTCPERP1","price":"6.3569","delta":"-1.00","side":"bid","ts_ms":1781237160276}}

{"type":"orderbook_delta","sid":1,"seq":437,"msg":{"market_ticker":"KXBTCPERP1","price":"6.3569","delta":"-1.00","side":"bid","ts_ms":1781237160276}}

{"type":"orderbook_delta","sid":1,"seq":438,"msg":{"market_ticker":"KXBTCPERP1","price":"6.3568","delta":"-1.00","side":"bid","ts_ms":1781237160276}}

{"type":"orderbook_delta","sid":1,"seq":439,"msg":{"market_ticker":"KXBTCPERP1","price":"6.3568","delta":"-1.00","side":"bid","ts_ms":1781237160276}}

{"type":"orderbook_delta","sid":1,"seq":440,"msg":{"market_ticker":"KXBTCPERP1","price":"6.3568","delta":"-1.00","side":"bid","ts_ms":1781237160276}}

{"type":"orderbook_delta","sid":1,"seq":441,"msg":{"market_ticker":"KXBTCPERP1","price":"6.3568","delta":"-1.00","side":"bid","ts_ms":1781237160276}}

{"type":"orderbook_delta","sid":1,"seq":442,"msg":{"market_ticker":"KXBTCPERP1","price":"6.3568","delta":"-1.00","side":"bid","ts_ms":1781237160276}}

{"type":"orderbook_delta","sid":1,"seq":443,"msg":{"market_ticker":"KXBTCPERP1","price":"6.3567","delta":"-1.00","side":"bid","ts_ms":1781237160276}}

{"type":"orderbook_delta","sid":1,"seq":444,"msg":{"market_ticker":"KXBTCPERP1","price":"6.3567","delta":"-1.00","side":"bid","ts_ms":1781237160276}}

{"type":"orderbook_delta","sid":1,"seq":445,"msg":{"market_ticker":"KXBTCPERP1","price":"6.3566","delta":"-1.00","side":"bid","ts_ms":1781237160276}}

{"type":"orderbook_delta","sid":1,"seq":446,"msg":{"market_ticker":"KXBTCPERP1","price":"6.3566","delta":"-1.00","side":"bid","ts_ms":1781237160276}}

{"type":"orderbook_delta","sid":1,"seq":447,"msg":{"market_ticker":"KXBTCPERP1","price":"6.3565","delta":"-1.00","side":"bid","ts_ms":1781237160276}}

{"type":"orderbook_delta","sid":1,"seq":448,"msg":{"market_ticker":"KXBTCPERP1","price":"6.3565","delta":"-1.00","side":"bid","ts_ms":1781237160276}}

{"type":"orderbook_delta","sid":1,"seq":449,"msg":{"market_ticker":"KXBTCPERP1","price":"6.3565","delta":"-1.00","side":"bid","ts_ms":1781237160276}}

{"type":"orderbook_delta","sid":1,"seq":450,"msg":{"market_ticker":"KXBTCPERP1","price":"6.3564","delta":"-1.00","side":"bid","ts_ms":1781237160276}}

{"type":"orderbook_delta","sid":1,"seq":451,"msg":{"market_ticker":"KXBTCPERP1","price":"6.3564","delta":"-1.00","side":"bid","ts_ms":1781237160276}}

{"type":"orderbook_delta","sid":1,"seq":452,"msg":{"market_ticker":"KXBTCPERP1","price":"6.3564","delta":"-1.00","side":"bid","ts_ms":1781237160276}}

{"type":"orderbook_delta","sid":1,"seq":453,"msg":{"market_ticker":"KXBTCPERP1","price":"6.3564","delta":"-1.00","side":"bid","ts_ms":1781237160276}}

{"type":"orderbook_delta","sid":1,"seq":454,"msg":{"market_ticker":"KXBTCPERP1","price":"6.3563","delta":"-1.00","side":"bid","ts_ms":1781237160276}}

{"type":"orderbook_delta","sid":1,"seq":455,"msg":{"market_ticker":"KXBTCPERP1","price":"6.3563","delta":"-1.00","side":"bid","ts_ms":1781237160276}}

{"type":"orderbook_delta","sid":1,"seq":456,"msg":{"market_ticker":"KXBTCPERP1","price":"6.3562","delta":"-1.00","side":"bid","ts_ms":1781237160276}}

{"type":"orderbook_delta","sid":1,"seq":457,"msg":{"market_ticker":"KXBTCPERP1","price":"6.3562","delta":"-1.00","side":"bid","ts_ms":1781237160276}}

{"type":"orderbook_delta","sid":1,"seq":458,"msg":{"market_ticker":"KXBTCPERP1","price":"6.3561","delta":"-1.00","side":"bid","ts_ms":1781237160276}}

{"type":"orderbook_delta","sid":1,"seq":459,"msg":{"market_ticker":"KXBTCPERP1","price":"6.3561","delta":"-1.00","side":"bid","ts_ms":1781237160276}}

{"type":"orderbook_delta","sid":1,"seq":460,"msg":{"market_ticker":"KXBTCPERP1","price":"6.3561","delta":"-1.00","side":"bid","ts_ms":1781237160276}}

{"type":"orderbook_delta","sid":1,"seq":461,"msg":{"market_ticker":"KXBTCPERP1","price":"6.3560","delta":"-1.00","side":"bid","ts_ms":1781237160276}}

{"type":"orderbook_delta","sid":1,"seq":462,"msg":{"market_ticker":"KXBTCPERP1","price":"6.3559","delta":"-1.00","side":"bid","ts_ms":1781237160276}}

{"type":"orderbook_delta","sid":1,"seq":463,"msg":{"market_ticker":"KXBTCPERP1","price":"6.3559","delta":"-1.00","side":"bid","ts_ms":1781237160276}}

{"type":"orderbook_delta","sid":1,"seq":464,"msg":{"market_ticker":"KXBTCPERP1","price":"6.3558","delta":"-1.00","side":"bid","ts_ms":1781237160276}}

{"type":"orderbook_delta","sid":1,"seq":465,"msg":{"market_ticker":"KXBTCPERP1","price":"6.3558","delta":"-1.00","side":"bid","ts_ms":1781237160276}}

{"type":"orderbook_delta","sid":1,"seq":466,"msg":{"market_ticker":"KXBTCPERP1","price":"6.3558","delta":"-1.00","side":"bid","ts_ms":1781237160276}}

{"type":"orderbook_delta","sid":1,"seq":467,"msg":{"market_ticker":"KXBTCPERP1","price":"6.3558","delta":"-1.00","side":"bid","ts_ms":1781237160276}}

{"type":"orderbook_delta","sid":1,"seq":468,"msg":{"market_ticker":"KXBTCPERP1","price":"6.3557","delta":"-1.00","side":"bid","ts_ms":1781237160276}}

{"type":"orderbook_delta","sid":1,"seq":469,"msg":{"market_ticker":"KXBTCPERP1","price":"6.3557","delta":"-1.00","side":"bid","ts_ms":1781237160276}}

{"type":"orderbook_delta","sid":1,"seq":470,"msg":{"market_ticker":"KXBTCPERP1","price":"6.3557","delta":"-1.00","side":"bid","ts_ms":1781237160276}}

{"type":"orderbook_delta","sid":1,"seq":471,"msg":{"market_ticker":"KXBTCPERP1","price":"6.3557","delta":"-1.00","side":"bid","ts_ms":1781237160276}}

{"type":"orderbook_delta","sid":1,"seq":472,"msg":{"market_ticker":"KXBTCPERP1","price":"6.3556","delta":"-1.00","side":"bid","ts_ms":1781237160276}}

{"type":"orderbook_delta","sid":1,"seq":473,"msg":{"market_ticker":"KXBTCPERP1","price":"6.3556","delta":"-1.00","side":"bid","ts_ms":1781237160276}}

{"type":"orderbook_delta","sid":1,"seq":474,"msg":{"market_ticker":"KXBTCPERP1","price":"6.3555","delta":"-1.00","side":"bid","ts_ms":1781237160276}}

{"type":"orderbook_delta","sid":1,"seq":475,"msg":{"market_ticker":"KXBTCPERP1","price":"6.3554","delta":"-1.00","side":"bid","ts_ms":1781237160276}}

{"type":"orderbook_delta","sid":1,"seq":476,"msg":{"market_ticker":"KXBTCPERP1","price":"6.3554","delta":"-1.00","side":"bid","ts_ms":1781237160276}}

{"type":"orderbook_delta","sid":1,"seq":477,"msg":{"market_ticker":"KXBTCPERP1","price":"6.3554","delta":"-1.00","side":"bid","ts_ms":1781237160276}}

{"type":"orderbook_delta","sid":1,"seq":478,"msg":{"market_ticker":"KXBTCPERP1","price":"6.3554","delta":"-1.00","side":"bid","ts_ms":1781237160276}}

{"type":"orderbook_delta","sid":1,"seq":479,"msg":{"market_ticker":"KXBTCPERP1","price":"6.3554","delta":"-1.00","side":"bid","ts_ms":1781237160276}}

{"type":"orderbook_delta","sid":1,"seq":480,"msg":{"market_ticker":"KXBTCPERP1","price":"6.3553","delta":"-1.00","side":"bid","ts_ms":1781237160276}}

{"type":"orderbook_delta","sid":1,"seq":481,"msg":{"market_ticker":"KXBTCPERP1","price":"6.3553","delta":"-1.00","side":"bid","ts_ms":1781237160276}}

{"type":"orderbook_delta","sid":1,"seq":482,"msg":{"market_ticker":"KXBTCPERP1","price":"6.3553","delta":"-1.00","side":"bid","ts_ms":1781237160276}}

{"type":"orderbook_delta","sid":1,"seq":483,"msg":{"market_ticker":"KXBTCPERP1","price":"6.3552","delta":"-1.00","side":"bid","ts_ms":1781237160276}}

{"type":"orderbook_delta","sid":1,"seq":484,"msg":{"market_ticker":"KXBTCPERP1","price":"6.3552","delta":"-1.00","side":"bid","ts_ms":1781237160276}}

{"type":"orderbook_delta","sid":1,"seq":485,"msg":{"market_ticker":"KXBTCPERP1","price":"6.3551","delta":"-1.00","side":"bid","ts_ms":1781237160276}}

{"type":"orderbook_delta","sid":1,"seq":486,"msg":{"market_ticker":"KXBTCPERP1","price":"6.3550","delta":"-1.00","side":"bid","ts_ms":1781237160276}}

{"type":"orderbook_delta","sid":1,"seq":487,"msg":{"market_ticker":"KXBTCPERP1","price":"6.3550","delta":"-1.00","side":"bid","ts_ms":1781237160276}}

{"type":"orderbook_delta","sid":1,"seq":488,"msg":{"market_ticker":"KXBTCPERP1","price":"6.3550","delta":"-1.00","side":"bid","ts_ms":1781237160276}}

{"type":"orderbook_delta","sid":1,"seq":489,"msg":{"market_ticker":"KXBTCPERP1","price":"6.3550","delta":"-1.00","side":"bid","ts_ms":1781237160276}}

{"type":"orderbook_delta","sid":1,"seq":490,"msg":{"market_ticker":"KXBTCPERP1","price":"6.3549","delta":"-1.00","side":"bid","ts_ms":1781237160276}}

{"type":"orderbook_delta","sid":1,"seq":491,"msg":{"market_ticker":"KXBTCPERP1","price":"6.3549","delta":"-1.00","side":"bid","ts_ms":1781237160276}}

{"type":"orderbook_delta","sid":1,"seq":492,"msg":{"market_ticker":"KXBTCPERP1","price":"6.3549","delta":"-1.00","side":"bid","ts_ms":1781237160276}}

{"type":"orderbook_delta","sid":1,"seq":493,"msg":{"market_ticker":"KXBTCPERP1","price":"6.3549","delta":"-1.00","side":"bid","ts_ms":1781237160276}}

{"type":"orderbook_delta","sid":1,"seq":494,"msg":{"market_ticker":"KXBTCPERP1","price":"6.3549","delta":"-1.00","side":"bid","ts_ms":1781237160276}}

{"type":"orderbook_delta","sid":1,"seq":495,"msg":{"market_ticker":"KXBTCPERP1","price":"6.3549","delta":"-1.00","side":"bid","ts_ms":1781237160276}}

{"type":"orderbook_delta","sid":1,"seq":496,"msg":{"market_ticker":"KXBTCPERP1","price":"6.3549","delta":"-1.00","side":"bid","ts_ms":1781237160276}}

{"type":"orderbook_delta","sid":1,"seq":497,"msg":{"market_ticker":"KXBTCPERP1","price":"6.3548","delta":"-1.00","side":"bid","ts_ms":1781237160276}}

{"type":"orderbook_delta","sid":1,"seq":498,"msg":{"market_ticker":"KXBTCPERP1","price":"6.3548","delta":"-1.00","side":"bid","ts_ms":1781237160276}}

{"type":"orderbook_delta","sid":1,"seq":499,"msg":{"market_ticker":"KXBTCPERP1","price":"6.3547","delta":"-1.00","side":"bid","ts_ms":1781237160276}}

{"type":"orderbook_delta","sid":1,"seq":500,"msg":{"market_ticker":"KXBTCPERP1","price":"6.3547","delta":"-1.00","side":"bid","ts_ms":1781237160276}}

{"type":"orderbook_delta","sid":1,"seq":501,"msg":{"market_ticker":"KXBTCPERP1","price":"6.3547","delta":"-1.00","side":"bid","ts_ms":1781237160276}}

{"type":"orderbook_delta","sid":1,"seq":502,"msg":{"market_ticker":"KXBTCPERP1","price":"6.3547","delta":"-1.00","side":"bid","ts_ms":1781237160276}}

{"type":"orderbook_delta","sid":1,"seq":503,"msg":{"market_ticker":"KXBTCPERP1","price":"6.3547","delta":"-1.00","side":"bid","ts_ms":1781237160276}}

{"type":"orderbook_delta","sid":1,"seq":504,"msg":{"market_ticker":"KXBTCPERP1","price":"6.3546","delta":"-1.00","side":"bid","ts_ms":1781237160276}}

{"type":"orderbook_delta","sid":1,"seq":505,"msg":{"market_ticker":"KXBTCPERP1","price":"6.3546","delta":"-1.00","side":"bid","ts_ms":1781237160276}}

{"type":"orderbook_delta","sid":1,"seq":506,"msg":{"market_ticker":"KXBTCPERP1","price":"6.3546","delta":"-1.00","side":"bid","ts_ms":1781237160276}}

{"type":"orderbook_delta","sid":1,"seq":507,"msg":{"market_ticker":"KXBTCPERP1","price":"6.3545","delta":"-1.00","side":"bid","ts_ms":1781237160276}}

{"type":"orderbook_delta","sid":1,"seq":508,"msg":{"market_ticker":"KXBTCPERP1","price":"6.3545","delta":"-1.00","side":"bid","ts_ms":1781237160276}}

{"type":"orderbook_delta","sid":1,"seq":509,"msg":{"market_ticker":"KXBTCPERP1","price":"6.3545","delta":"-1.00","side":"bid","ts_ms":1781237160276}}

{"type":"orderbook_delta","sid":1,"seq":510,"msg":{"market_ticker":"KXBTCPERP1","price":"6.3544","delta":"-1.00","side":"bid","ts_ms":1781237160276}}

{"type":"orderbook_delta","sid":1,"seq":511,"msg":{"market_ticker":"KXBTCPERP1","price":"6.3544","delta":"-1.00","side":"bid","ts_ms":1781237160276}}

{"type":"orderbook_delta","sid":1,"seq":512,"msg":{"market_ticker":"KXBTCPERP1","price":"6.3544","delta":"-1.00","side":"bid","ts_ms":1781237160276}}

{"type":"orderbook_delta","sid":1,"seq":513,"msg":{"market_ticker":"KXBTCPERP1","price":"6.3543","delta":"-1.00","side":"bid","ts_ms":1781237160276}}

{"type":"orderbook_delta","sid":1,"seq":514,"msg":{"market_ticker":"KXBTCPERP1","price":"6.3543","delta":"-1.00","side":"bid","ts_ms":1781237160276}}

{"type":"orderbook_delta","sid":1,"seq":515,"msg":{"market_ticker":"KXBTCPERP1","price":"6.3542","delta":"-1.00","side":"bid","ts_ms":1781237160276}}

{"type":"orderbook_delta","sid":1,"seq":516,"msg":{"market_ticker":"KXBTCPERP1","price":"6.3541","delta":"-1.00","side":"bid","ts_ms":1781237160276}}

{"type":"orderbook_delta","sid":1,"seq":517,"msg":{"market_ticker":"KXBTCPERP1","price":"6.3541","delta":"-1.00","side":"bid","ts_ms":1781237160276}}

{"type":"orderbook_delta","sid":1,"seq":518,"msg":{"market_ticker":"KXBTCPERP1","price":"6.3541","delta":"-1.00","side":"bid","ts_ms":1781237160276}}

{"type":"orderbook_delta","sid":1,"seq":519,"msg":{"market_ticker":"KXBTCPERP1","price":"6.3541","delta":"-1.00","side":"bid","ts_ms":1781237160276}}

{"type":"orderbook_delta","sid":1,"seq":520,"msg":{"market_ticker":"KXBTCPERP1","price":"6.3540","delta":"-1.00","side":"bid","ts_ms":1781237160276}}

{"type":"orderbook_delta","sid":1,"seq":521,"msg":{"market_ticker":"KXBTCPERP1","price":"6.3540","delta":"-1.00","side":"bid","ts_ms":1781237160276}}

{"type":"orderbook_delta","sid":1,"seq":522,"msg":{"market_ticker":"KXBTCPERP1","price":"6.3540","delta":"-1.00","side":"bid","ts_ms":1781237160276}}

{"type":"orderbook_delta","sid":1,"seq":523,"msg":{"market_ticker":"KXBTCPERP1","price":"6.3540","delta":"-1.00","side":"bid","ts_ms":1781237160276}}

{"type":"orderbook_delta","sid":1,"seq":524,"msg":{"market_ticker":"KXBTCPERP1","price":"6.3540","delta":"-1.00","side":"bid","ts_ms":1781237160276}}

{"type":"orderbook_delta","sid":1,"seq":525,"msg":{"market_ticker":"KXBTCPERP1","price":"6.3540","delta":"-1.00","side":"bid","ts_ms":1781237160276}}

{"type":"orderbook_delta","sid":1,"seq":526,"msg":{"market_ticker":"KXBTCPERP1","price":"6.3539","delta":"-1.00","side":"bid","ts_ms":1781237160276}}

{"type":"orderbook_delta","sid":1,"seq":527,"msg":{"market_ticker":"KXBTCPERP1","price":"6.3539","delta":"-1.00","side":"bid","ts_ms":1781237160276}}

{"type":"orderbook_delta","sid":1,"seq":528,"msg":{"market_ticker":"KXBTCPERP1","price":"6.3539","delta":"-1.00","side":"bid","ts_ms":1781237160276}}

{"type":"orderbook_delta","sid":1,"seq":529,"msg":{"market_ticker":"KXBTCPERP1","price":"6.3539","delta":"-1.00","side":"bid","ts_ms":1781237160276}}

{"type":"orderbook_delta","sid":1,"seq":530,"msg":{"market_ticker":"KXBTCPERP1","price":"6.3539","delta":"-1.00","side":"bid","ts_ms":1781237160276}}

{"type":"orderbook_delta","sid":1,"seq":531,"msg":{"market_ticker":"KXBTCPERP1","price":"6.3538","delta":"-1.00","side":"bid","ts_ms":1781237160276}}

{"type":"orderbook_delta","sid":1,"seq":532,"msg":{"market_ticker":"KXBTCPERP1","price":"6.3538","delta":"-1.00","side":"bid","ts_ms":1781237160276}}

{"type":"orderbook_delta","sid":1,"seq":533,"msg":{"market_ticker":"KXBTCPERP1","price":"6.3538","delta":"-1.00","side":"bid","ts_ms":1781237160276}}

{"type":"orderbook_delta","sid":1,"seq":534,"msg":{"market_ticker":"KXBTCPERP1","price":"6.3538","delta":"-1.00","side":"bid","ts_ms":1781237160276}}

{"type":"orderbook_delta","sid":1,"seq":535,"msg":{"market_ticker":"KXBTCPERP1","price":"6.3538","delta":"-1.00","side":"bid","ts_ms":1781237160276}}

{"type":"orderbook_delta","sid":1,"seq":536,"msg":{"market_ticker":"KXBTCPERP1","price":"6.3537","delta":"-1.00","side":"bid","ts_ms":1781237160276}}

{"type":"orderbook_delta","sid":1,"seq":537,"msg":{"market_ticker":"KXBTCPERP1","price":"6.3537","delta":"-1.00","side":"bid","ts_ms":1781237160276}}

{"type":"orderbook_delta","sid":1,"seq":538,"msg":{"market_ticker":"KXBTCPERP1","price":"6.3536","delta":"-1.00","side":"bid","ts_ms":1781237160276}}

{"type":"orderbook_delta","sid":1,"seq":539,"msg":{"market_ticker":"KXBTCPERP1","price":"6.3536","delta":"-1.00","side":"bid","ts_ms":1781237160276}}

{"type":"orderbook_delta","sid":1,"seq":540,"msg":{"market_ticker":"KXBTCPERP1","price":"6.3536","delta":"-1.00","side":"bid","ts_ms":1781237160276}}

{"type":"orderbook_delta","sid":1,"seq":541,"msg":{"market_ticker":"KXBTCPERP1","price":"6.3535","delta":"-1.00","side":"bid","ts_ms":1781237160276}}

{"type":"orderbook_delta","sid":1,"seq":542,"msg":{"market_ticker":"KXBTCPERP1","price":"6.3535","delta":"-1.00","side":"bid","ts_ms":1781237160276}}

{"type":"orderbook_delta","sid":1,"seq":543,"msg":{"market_ticker":"KXBTCPERP1","price":"6.3535","delta":"-1.00","side":"bid","ts_ms":1781237160276}}

{"type":"orderbook_delta","sid":1,"seq":544,"msg":{"market_ticker":"KXBTCPERP1","price":"6.3534","delta":"-1.00","side":"bid","ts_ms":1781237160276}}

{"type":"orderbook_delta","sid":1,"seq":545,"msg":{"market_ticker":"KXBTCPERP1","price":"6.3534","delta":"-1.00","side":"bid","ts_ms":1781237160276}}

{"type":"orderbook_delta","sid":1,"seq":546,"msg":{"market_ticker":"KXBTCPERP1","price":"6.3533","delta":"-1.00","side":"bid","ts_ms":1781237160276}}

{"type":"orderbook_delta","sid":1,"seq":547,"msg":{"market_ticker":"KXBTCPERP1","price":"6.3533","delta":"-1.00","side":"bid","ts_ms":1781237160276}}

{"type":"orderbook_delta","sid":1,"seq":548,"msg":{"market_ticker":"KXBTCPERP1","price":"6.3533","delta":"-1.00","side":"bid","ts_ms":1781237160276}}

{"type":"orderbook_delta","sid":1,"seq":549,"msg":{"market_ticker":"KXBTCPERP1","price":"6.3531","delta":"-1.00","side":"bid","ts_ms":1781237160276}}

{"type":"orderbook_delta","sid":1,"seq":550,"msg":{"market_ticker":"KXBTCPERP1","price":"6.3530","delta":"-1.00","side":"bid","ts_ms":1781237160276}}

{"type":"orderbook_delta","sid":1,"seq":551,"msg":{"market_ticker":"KXBTCPERP1","price":"6.3530","delta":"-1.00","side":"bid","ts_ms":1781237160276}}

{"type":"orderbook_delta","sid":1,"seq":552,"msg":{"market_ticker":"KXBTCPERP1","price":"6.3530","delta":"-1.00","side":"bid","ts_ms":1781237160276}}

{"type":"orderbook_delta","sid":1,"seq":553,"msg":{"market_ticker":"KXBTCPERP1","price":"6.3528","delta":"-1.00","side":"bid","ts_ms":1781237160276}}

{"type":"orderbook_delta","sid":1,"seq":554,"msg":{"market_ticker":"KXBTCPERP1","price":"6.3528","delta":"-1.00","side":"bid","ts_ms":1781237160276}}

{"type":"orderbook_delta","sid":1,"seq":555,"msg":{"market_ticker":"KXBTCPERP1","price":"6.3528","delta":"-1.00","side":"bid","ts_ms":1781237160276}}

{"type":"orderbook_delta","sid":1,"seq":556,"msg":{"market_ticker":"KXBTCPERP1","price":"6.3528","delta":"-1.00","side":"bid","ts_ms":1781237160276}}

{"type":"orderbook_delta","sid":1,"seq":557,"msg":{"market_ticker":"KXBTCPERP1","price":"6.3527","delta":"-1.00","side":"bid","ts_ms":1781237160276}}

{"type":"orderbook_delta","sid":1,"seq":558,"msg":{"market_ticker":"KXBTCPERP1","price":"6.3527","delta":"-1.00","side":"bid","ts_ms":1781237160276}}

{"type":"orderbook_delta","sid":1,"seq":559,"msg":{"market_ticker":"KXBTCPERP1","price":"6.3527","delta":"-1.00","side":"bid","ts_ms":1781237160276}}

{"type":"orderbook_delta","sid":1,"seq":560,"msg":{"market_ticker":"KXBTCPERP1","price":"6.3526","delta":"-1.00","side":"bid","ts_ms":1781237160276}}

{"type":"orderbook_delta","sid":1,"seq":561,"msg":{"market_ticker":"KXBTCPERP1","price":"6.3526","delta":"-1.00","side":"bid","ts_ms":1781237160276}}

{"type":"orderbook_delta","sid":1,"seq":562,"msg":{"market_ticker":"KXBTCPERP1","price":"6.3526","delta":"-1.00","side":"bid","ts_ms":1781237160276}}

{"type":"orderbook_delta","sid":1,"seq":563,"msg":{"market_ticker":"KXBTCPERP1","price":"6.3526","delta":"-1.00","side":"bid","ts_ms":1781237160276}}

{"type":"orderbook_delta","sid":1,"seq":564,"msg":{"market_ticker":"KXBTCPERP1","price":"6.3526","delta":"-1.00","side":"bid","ts_ms":1781237160276}}

{"type":"orderbook_delta","sid":1,"seq":565,"msg":{"market_ticker":"KXBTCPERP1","price":"6.3525","delta":"-1.00","side":"bid","ts_ms":1781237160276}}

{"type":"orderbook_delta","sid":1,"seq":566,"msg":{"market_ticker":"KXBTCPERP1","price":"6.3525","delta":"-1.00","side":"bid","ts_ms":1781237160276}}

{"type":"orderbook_delta","sid":1,"seq":567,"msg":{"market_ticker":"KXBTCPERP1","price":"6.3525","delta":"-1.00","side":"bid","ts_ms":1781237160276}}

{"type":"orderbook_delta","sid":1,"seq":568,"msg":{"market_ticker":"KXBTCPERP1","price":"6.3524","delta":"-1.00","side":"bid","ts_ms":1781237160276}}

{"type":"orderbook_delta","sid":1,"seq":569,"msg":{"market_ticker":"KXBTCPERP1","price":"6.3524","delta":"-1.00","side":"bid","ts_ms":1781237160276}}

{"type":"orderbook_delta","sid":1,"seq":570,"msg":{"market_ticker":"KXBTCPERP1","price":"6.3524","delta":"-1.00","side":"bid","ts_ms":1781237160276}}

{"type":"orderbook_delta","sid":1,"seq":571,"msg":{"market_ticker":"KXBTCPERP1","price":"6.3523","delta":"-1.00","side":"bid","ts_ms":1781237160276}}

{"type":"orderbook_delta","sid":1,"seq":572,"msg":{"market_ticker":"KXBTCPERP1","price":"6.3523","delta":"-1.00","side":"bid","ts_ms":1781237160276}}

{"type":"orderbook_delta","sid":1,"seq":573,"msg":{"market_ticker":"KXBTCPERP1","price":"6.3523","delta":"-1.00","side":"bid","ts_ms":1781237160276}}

{"type":"orderbook_delta","sid":1,"seq":574,"msg":{"market_ticker":"KXBTCPERP1","price":"6.3523","delta":"-1.00","side":"bid","ts_ms":1781237160276}}

{"type":"orderbook_delta","sid":1,"seq":575,"msg":{"market_ticker":"KXBTCPERP1","price":"6.3522","delta":"-1.00","side":"bid","ts_ms":1781237160276}}

{"type":"orderbook_delta","sid":1,"seq":576,"msg":{"market_ticker":"KXBTCPERP1","price":"6.3522","delta":"-1.00","side":"bid","ts_ms":1781237160276}}

{"type":"orderbook_delta","sid":1,"seq":577,"msg":{"market_ticker":"KXBTCPERP1","price":"6.3522","delta":"-1.00","side":"bid","ts_ms":1781237160276}}

{"type":"orderbook_delta","sid":1,"seq":578,"msg":{"market_ticker":"KXBTCPERP1","price":"6.3521","delta":"-1.00","side":"bid","ts_ms":1781237160276}}

{"type":"orderbook_delta","sid":1,"seq":579,"msg":{"market_ticker":"KXBTCPERP1","price":"6.3521","delta":"-1.00","side":"bid","ts_ms":1781237160276}}

{"type":"orderbook_delta","sid":1,"seq":580,"msg":{"market_ticker":"KXBTCPERP1","price":"6.3521","delta":"-1.00","side":"bid","ts_ms":1781237160276}}

{"type":"orderbook_delta","sid":1,"seq":581,"msg":{"market_ticker":"KXBTCPERP1","price":"6.3521","delta":"-1.00","side":"bid","ts_ms":1781237160276}}

{"type":"orderbook_delta","sid":1,"seq":582,"msg":{"market_ticker":"KXBTCPERP1","price":"6.3520","delta":"-1.00","side":"bid","ts_ms":1781237160276}}

{"type":"orderbook_delta","sid":1,"seq":583,"msg":{"market_ticker":"KXBTCPERP1","price":"6.3519","delta":"-1.00","side":"bid","ts_ms":1781237160276}}

{"type":"orderbook_delta","sid":1,"seq":584,"msg":{"market_ticker":"KXBTCPERP1","price":"6.3519","delta":"-1.00","side":"bid","ts_ms":1781237160276}}

{"type":"orderbook_delta","sid":1,"seq":585,"msg":{"market_ticker":"KXBTCPERP1","price":"6.3519","delta":"-1.00","side":"bid","ts_ms":1781237160276}}

{"type":"orderbook_delta","sid":1,"seq":586,"msg":{"market_ticker":"KXBTCPERP1","price":"6.3518","delta":"-1.00","side":"bid","ts_ms":1781237160276}}

{"type":"orderbook_delta","sid":1,"seq":587,"msg":{"market_ticker":"KXBTCPERP1","price":"6.3517","delta":"-1.00","side":"bid","ts_ms":1781237160276}}

{"type":"orderbook_delta","sid":1,"seq":588,"msg":{"market_ticker":"KXBTCPERP1","price":"6.3517","delta":"-1.00","side":"bid","ts_ms":1781237160276}}

{"type":"orderbook_delta","sid":1,"seq":589,"msg":{"market_ticker":"KXBTCPERP1","price":"6.3516","delta":"-1.00","side":"bid","ts_ms":1781237160276}}

{"type":"orderbook_delta","sid":1,"seq":590,"msg":{"market_ticker":"KXBTCPERP1","price":"6.3516","delta":"-1.00","side":"bid","ts_ms":1781237160276}}

{"type":"orderbook_delta","sid":1,"seq":591,"msg":{"market_ticker":"KXBTCPERP1","price":"6.3516","delta":"-1.00","side":"bid","ts_ms":1781237160276}}

{"type":"orderbook_delta","sid":1,"seq":592,"msg":{"market_ticker":"KXBTCPERP1","price":"6.3515","delta":"-1.00","side":"bid","ts_ms":1781237160276}}

{"type":"orderbook_delta","sid":1,"seq":593,"msg":{"market_ticker":"KXBTCPERP1","price":"6.3515","delta":"-1.00","side":"bid","ts_ms":1781237160276}}

{"type":"orderbook_delta","sid":1,"seq":594,"msg":{"market_ticker":"KXBTCPERP1","price":"6.3514","delta":"-1.00","side":"bid","ts_ms":1781237160276}}

{"type":"orderbook_delta","sid":1,"seq":595,"msg":{"market_ticker":"KXBTCPERP1","price":"6.3514","delta":"-1.00","side":"bid","ts_ms":1781237160276}}

{"type":"orderbook_delta","sid":1,"seq":596,"msg":{"market_ticker":"KXBTCPERP1","price":"6.3513","delta":"-1.00","side":"bid","ts_ms":1781237160276}}

{"type":"orderbook_delta","sid":1,"seq":597,"msg":{"market_ticker":"KXBTCPERP1","price":"6.3513","delta":"-1.00","side":"bid","ts_ms":1781237160276}}

{"type":"orderbook_delta","sid":1,"seq":598,"msg":{"market_ticker":"KXBTCPERP1","price":"6.3513","delta":"-1.00","side":"bid","ts_ms":1781237160276}}

{"type":"orderbook_delta","sid":1,"seq":599,"msg":{"market_ticker":"KXBTCPERP1","price":"6.3512","delta":"-1.00","side":"bid","ts_ms":1781237160276}}

{"type":"orderbook_delta","sid":1,"seq":600,"msg":{"market_ticker":"KXBTCPERP1","price":"6.3512","delta":"-1.00","side":"bid","ts_ms":1781237160276}}

{"type":"orderbook_delta","sid":1,"seq":601,"msg":{"market_ticker":"KXBTCPERP1","price":"6.3512","delta":"-1.00","side":"bid","ts_ms":1781237160276}}

{"type":"orderbook_delta","sid":1,"seq":602,"msg":{"market_ticker":"KXBTCPERP1","price":"6.3512","delta":"-1.00","side":"bid","ts_ms":1781237160276}}

{"type":"orderbook_delta","sid":1,"seq":603,"msg":{"market_ticker":"KXBTCPERP1","price":"6.3512","delta":"-1.00","side":"bid","ts_ms":1781237160276}}

{"type":"orderbook_delta","sid":1,"seq":604,"msg":{"market_ticker":"KXBTCPERP1","price":"6.3511","delta":"-1.00","side":"bid","ts_ms":1781237160276}}

{"type":"orderbook_delta","sid":1,"seq":605,"msg":{"market_ticker":"KXBTCPERP1","price":"6.3511","delta":"-1.00","side":"bid","ts_ms":1781237160276}}

{"type":"orderbook_delta","sid":1,"seq":606,"msg":{"market_ticker":"KXBTCPERP1","price":"6.3511","delta":"-1.00","side":"bid","ts_ms":1781237160276}}

{"type":"orderbook_delta","sid":1,"seq":607,"msg":{"market_ticker":"KXBTCPERP1","price":"6.3511","delta":"-1.00","side":"bid","ts_ms":1781237160276}}

{"type":"orderbook_delta","sid":1,"seq":608,"msg":{"market_ticker":"KXBTCPERP1","price":"6.3510","delta":"-1.00","side":"bid","ts_ms":1781237160276}}

{"type":"orderbook_delta","sid":1,"seq":609,"msg":{"market_ticker":"KXBTCPERP1","price":"6.3509","delta":"-1.00","side":"bid","ts_ms":1781237160276}}

{"type":"orderbook_delta","sid":1,"seq":610,"msg":{"market_ticker":"KXBTCPERP1","price":"6.3509","delta":"-1.00","side":"bid","ts_ms":1781237160276}}

{"type":"orderbook_delta","sid":1,"seq":611,"msg":{"market_ticker":"KXBTCPERP1","price":"6.3509","delta":"-1.00","side":"bid","ts_ms":1781237160276}}

{"type":"orderbook_delta","sid":1,"seq":612,"msg":{"market_ticker":"KXBTCPERP1","price":"6.3509","delta":"-1.00","side":"bid","ts_ms":1781237160276}}

{"type":"orderbook_delta","sid":1,"seq":613,"msg":{"market_ticker":"KXBTCPERP1","price":"6.3508","delta":"-1.00","side":"bid","ts_ms":1781237160276}}

{"type":"orderbook_delta","sid":1,"seq":614,"msg":{"market_ticker":"KXBTCPERP1","price":"6.3508","delta":"-1.00","side":"bid","ts_ms":1781237160276}}

{"type":"orderbook_delta","sid":1,"seq":615,"msg":{"market_ticker":"KXBTCPERP1","price":"6.3508","delta":"-1.00","side":"bid","ts_ms":1781237160276}}

{"type":"orderbook_delta","sid":1,"seq":616,"msg":{"market_ticker":"KXBTCPERP1","price":"6.3508","delta":"-1.00","side":"bid","ts_ms":1781237160276}}

{"type":"orderbook_delta","sid":1,"seq":617,"msg":{"market_ticker":"KXBTCPERP1","price":"6.3508","delta":"-1.00","side":"bid","ts_ms":1781237160276}}

{"type":"orderbook_delta","sid":1,"seq":618,"msg":{"market_ticker":"KXBTCPERP1","price":"6.3507","delta":"-1.00","side":"bid","ts_ms":1781237160276}}

{"type":"orderbook_delta","sid":1,"seq":619,"msg":{"market_ticker":"KXBTCPERP1","price":"6.3507","delta":"-1.00","side":"bid","ts_ms":1781237160276}}

{"type":"orderbook_delta","sid":1,"seq":620,"msg":{"market_ticker":"KXBTCPERP1","price":"6.3507","delta":"-1.00","side":"bid","ts_ms":1781237160276}}

{"type":"orderbook_delta","sid":1,"seq":621,"msg":{"market_ticker":"KXBTCPERP1","price":"6.3506","delta":"-1.00","side":"bid","ts_ms":1781237160276}}

{"type":"orderbook_delta","sid":1,"seq":622,"msg":{"market_ticker":"KXBTCPERP1","price":"6.3506","delta":"-1.00","side":"bid","ts_ms":1781237160276}}

{"type":"orderbook_delta","sid":1,"seq":623,"msg":{"market_ticker":"KXBTCPERP1","price":"6.3505","delta":"-1.00","side":"bid","ts_ms":1781237160276}}

{"type":"orderbook_delta","sid":1,"seq":624,"msg":{"market_ticker":"KXBTCPERP1","price":"6.3505","delta":"-1.00","side":"bid","ts_ms":1781237160276}}

{"type":"orderbook_delta","sid":1,"seq":625,"msg":{"market_ticker":"KXBTCPERP1","price":"6.3504","delta":"-1.00","side":"bid","ts_ms":1781237160276}}

{"type":"orderbook_delta","sid":1,"seq":626,"msg":{"market_ticker":"KXBTCPERP1","price":"6.3504","delta":"-1.00","side":"bid","ts_ms":1781237160276}}

{"type":"orderbook_delta","sid":1,"seq":627,"msg":{"market_ticker":"KXBTCPERP1","price":"6.3503","delta":"-1.00","side":"bid","ts_ms":1781237160276}}

{"type":"orderbook_delta","sid":1,"seq":628,"msg":{"market_ticker":"KXBTCPERP1","price":"6.3503","delta":"-1.00","side":"bid","ts_ms":1781237160276}}

{"type":"orderbook_delta","sid":1,"seq":629,"msg":{"market_ticker":"KXBTCPERP1","price":"6.3502","delta":"-1.00","side":"bid","ts_ms":1781237160276}}

{"type":"orderbook_delta","sid":1,"seq":630,"msg":{"market_ticker":"KXBTCPERP1","price":"6.3502","delta":"-1.00","side":"bid","ts_ms":1781237160276}}

{"type":"orderbook_delta","sid":1,"seq":631,"msg":{"market_ticker":"KXBTCPERP1","price":"6.3501","delta":"-1.00","side":"bid","ts_ms":1781237160276}}

{"type":"orderbook_delta","sid":1,"seq":632,"msg":{"market_ticker":"KXBTCPERP1","price":"6.3501","delta":"-1.00","side":"bid","ts_ms":1781237160276}}

{"type":"orderbook_delta","sid":1,"seq":633,"msg":{"market_ticker":"KXBTCPERP1","price":"6.3501","delta":"-1.00","side":"bid","ts_ms":1781237160276}}

{"type":"orderbook_delta","sid":1,"seq":634,"msg":{"market_ticker":"KXBTCPERP1","price":"6.3500","delta":"-1.00","side":"bid","ts_ms":1781237160276}}

{"type":"orderbook_delta","sid":1,"seq":635,"msg":{"market_ticker":"KXBTCPERP1","price":"6.3500","delta":"-1.00","side":"bid","ts_ms":1781237160276}}

{"type":"orderbook_delta","sid":1,"seq":636,"msg":{"market_ticker":"KXBTCPERP1","price":"6.3500","delta":"-1.00","side":"bid","ts_ms":1781237160276}}

{"type":"orderbook_delta","sid":1,"seq":637,"msg":{"market_ticker":"KXBTCPERP1","price":"6.3499","delta":"-1.00","side":"bid","ts_ms":1781237160276}}

{"type":"orderbook_delta","sid":1,"seq":638,"msg":{"market_ticker":"KXBTCPERP1","price":"6.3499","delta":"-1.00","side":"bid","ts_ms":1781237160276}}

{"type":"orderbook_delta","sid":1,"seq":639,"msg":{"market_ticker":"KXBTCPERP1","price":"6.3499","delta":"-1.00","side":"bid","ts_ms":1781237160276}}

{"type":"orderbook_delta","sid":1,"seq":640,"msg":{"market_ticker":"KXBTCPERP1","price":"6.3498","delta":"-1.00","side":"bid","ts_ms":1781237160276}}

{"type":"orderbook_delta","sid":1,"seq":641,"msg":{"market_ticker":"KXBTCPERP1","price":"6.3498","delta":"-1.00","side":"bid","ts_ms":1781237160276}}

{"type":"orderbook_delta","sid":1,"seq":642,"msg":{"market_ticker":"KXBTCPERP1","price":"6.3497","delta":"-1.00","side":"bid","ts_ms":1781237160276}}

{"type":"orderbook_delta","sid":1,"seq":643,"msg":{"market_ticker":"KXBTCPERP1","price":"6.3497","delta":"-1.00","side":"bid","ts_ms":1781237160276}}

{"type":"orderbook_delta","sid":1,"seq":644,"msg":{"market_ticker":"KXBTCPERP1","price":"6.3497","delta":"-1.00","side":"bid","ts_ms":1781237160276}}

{"type":"orderbook_delta","sid":1,"seq":645,"msg":{"market_ticker":"KXBTCPERP1","price":"6.3497","delta":"-1.00","side":"bid","ts_ms":1781237160276}}

{"type":"orderbook_delta","sid":1,"seq":646,"msg":{"market_ticker":"KXBTCPERP1","price":"6.3497","delta":"-1.00","side":"bid","ts_ms":1781237160276}}

{"type":"orderbook_delta","sid":1,"seq":647,"msg":{"market_ticker":"KXBTCPERP1","price":"6.3496","delta":"-1.00","side":"bid","ts_ms":1781237160276}}

{"type":"orderbook_delta","sid":1,"seq":648,"msg":{"market_ticker":"KXBTCPERP1","price":"6.3495","delta":"-1.00","side":"bid","ts_ms":1781237160276}}

{"type":"orderbook_delta","sid":1,"seq":649,"msg":{"market_ticker":"KXBTCPERP1","price":"6.3495","delta":"-1.00","side":"bid","ts_ms":1781237160276}}

{"type":"orderbook_delta","sid":1,"seq":650,"msg":{"market_ticker":"KXBTCPERP1","price":"6.3495","delta":"-1.00","side":"bid","ts_ms":1781237160276}}

{"type":"orderbook_delta","sid":1,"seq":651,"msg":{"market_ticker":"KXBTCPERP1","price":"6.3494","delta":"-1.00","side":"bid","ts_ms":1781237160276}}

{"type":"orderbook_delta","sid":1,"seq":652,"msg":{"market_ticker":"KXBTCPERP1","price":"6.3494","delta":"-1.00","side":"bid","ts_ms":1781237160276}}

{"type":"orderbook_delta","sid":1,"seq":653,"msg":{"market_ticker":"KXBTCPERP1","price":"6.3494","delta":"-1.00","side":"bid","ts_ms":1781237160276}}

{"type":"orderbook_delta","sid":1,"seq":654,"msg":{"market_ticker":"KXBTCPERP1","price":"6.3493","delta":"-1.00","side":"bid","ts_ms":1781237160276}}

{"type":"orderbook_delta","sid":1,"seq":655,"msg":{"market_ticker":"KXBTCPERP1","price":"6.3493","delta":"-1.00","side":"bid","ts_ms":1781237160276}}

{"type":"orderbook_delta","sid":1,"seq":656,"msg":{"market_ticker":"KXBTCPERP1","price":"6.3493","delta":"-1.00","side":"bid","ts_ms":1781237160276}}

{"type":"orderbook_delta","sid":1,"seq":657,"msg":{"market_ticker":"KXBTCPERP1","price":"6.3492","delta":"-1.00","side":"bid","ts_ms":1781237160276}}

{"type":"orderbook_delta","sid":1,"seq":658,"msg":{"market_ticker":"KXBTCPERP1","price":"6.3492","delta":"-1.00","side":"bid","ts_ms":1781237160276}}

{"type":"orderbook_delta","sid":1,"seq":659,"msg":{"market_ticker":"KXBTCPERP1","price":"6.3492","delta":"-1.00","side":"bid","ts_ms":1781237160276}}

{"type":"orderbook_delta","sid":1,"seq":660,"msg":{"market_ticker":"KXBTCPERP1","price":"6.3492","delta":"-1.00","side":"bid","ts_ms":1781237160276}}

{"type":"orderbook_delta","sid":1,"seq":661,"msg":{"market_ticker":"KXBTCPERP1","price":"6.3491","delta":"-1.00","side":"bid","ts_ms":1781237160276}}

{"type":"orderbook_delta","sid":1,"seq":662,"msg":{"market_ticker":"KXBTCPERP1","price":"6.3491","delta":"-1.00","side":"bid","ts_ms":1781237160276}}

{"type":"orderbook_delta","sid":1,"seq":663,"msg":{"market_ticker":"KXBTCPERP1","price":"6.3491","delta":"-1.00","side":"bid","ts_ms":1781237160276}}

{"type":"orderbook_delta","sid":1,"seq":664,"msg":{"market_ticker":"KXBTCPERP1","price":"6.3491","delta":"-1.00","side":"bid","ts_ms":1781237160276}}

{"type":"orderbook_delta","sid":1,"seq":665,"msg":{"market_ticker":"KXBTCPERP1","price":"6.3491","delta":"-1.00","side":"bid","ts_ms":1781237160276}}

{"type":"orderbook_delta","sid":1,"seq":666,"msg":{"market_ticker":"KXBTCPERP1","price":"6.3489","delta":"-1.00","side":"bid","ts_ms":1781237160276}}

{"type":"orderbook_delta","sid":1,"seq":667,"msg":{"market_ticker":"KXBTCPERP1","price":"6.3489","delta":"-1.00","side":"bid","ts_ms":1781237160276}}

{"type":"orderbook_delta","sid":1,"seq":668,"msg":{"market_ticker":"KXBTCPERP1","price":"6.3489","delta":"-1.00","side":"bid","ts_ms":1781237160276}}

{"type":"orderbook_delta","sid":1,"seq":669,"msg":{"market_ticker":"KXBTCPERP1","price":"6.3488","delta":"-1.00","side":"bid","ts_ms":1781237160276}}

{"type":"orderbook_delta","sid":1,"seq":670,"msg":{"market_ticker":"KXBTCPERP1","price":"6.3488","delta":"-1.00","side":"bid","ts_ms":1781237160276}}

{"type":"orderbook_delta","sid":1,"seq":671,"msg":{"market_ticker":"KXBTCPERP1","price":"6.3488","delta":"-1.00","side":"bid","ts_ms":1781237160276}}

{"type":"orderbook_delta","sid":1,"seq":672,"msg":{"market_ticker":"KXBTCPERP1","price":"6.3488","delta":"-1.00","side":"bid","ts_ms":1781237160276}}

{"type":"orderbook_delta","sid":1,"seq":673,"msg":{"market_ticker":"KXBTCPERP1","price":"6.3488","delta":"-1.00","side":"bid","ts_ms":1781237160276}}

{"type":"orderbook_delta","sid":1,"seq":674,"msg":{"market_ticker":"KXBTCPERP1","price":"6.3488","delta":"-1.00","side":"bid","ts_ms":1781237160276}}

{"type":"orderbook_delta","sid":1,"seq":675,"msg":{"market_ticker":"KXBTCPERP1","price":"6.3488","delta":"-1.00","side":"bid","ts_ms":1781237160276}}

{"type":"orderbook_delta","sid":1,"seq":676,"msg":{"market_ticker":"KXBTCPERP1","price":"6.3488","delta":"-1.00","side":"bid","ts_ms":1781237160276}}

{"type":"orderbook_delta","sid":1,"seq":677,"msg":{"market_ticker":"KXBTCPERP1","price":"6.3488","delta":"-1.00","side":"bid","ts_ms":1781237160276}}

{"type":"orderbook_delta","sid":1,"seq":678,"msg":{"market_ticker":"KXBTCPERP1","price":"6.3488","delta":"-1.00","side":"bid","ts_ms":1781237160276}}

{"type":"orderbook_delta","sid":1,"seq":679,"msg":{"market_ticker":"KXBTCPERP1","price":"6.3488","delta":"-1.00","side":"bid","ts_ms":1781237160276}}

{"type":"orderbook_delta","sid":1,"seq":680,"msg":{"market_ticker":"KXBTCPERP1","price":"6.3487","delta":"-1.00","side":"bid","ts_ms":1781237160276}}

{"type":"orderbook_delta","sid":1,"seq":681,"msg":{"market_ticker":"KXBTCPERP1","price":"6.3486","delta":"-1.00","side":"bid","ts_ms":1781237160276}}

{"type":"orderbook_delta","sid":1,"seq":682,"msg":{"market_ticker":"KXBTCPERP1","price":"6.3486","delta":"-1.00","side":"bid","ts_ms":1781237160276}}

{"type":"orderbook_delta","sid":1,"seq":683,"msg":{"market_ticker":"KXBTCPERP1","price":"6.3486","delta":"-1.00","side":"bid","ts_ms":1781237160276}}

{"type":"orderbook_delta","sid":1,"seq":684,"msg":{"market_ticker":"KXBTCPERP1","price":"6.3484","delta":"-1.00","side":"bid","ts_ms":1781237160276}}

{"type":"orderbook_delta","sid":1,"seq":685,"msg":{"market_ticker":"KXBTCPERP1","price":"6.3484","delta":"-1.00","side":"bid","ts_ms":1781237160276}}

{"type":"orderbook_delta","sid":1,"seq":686,"msg":{"market_ticker":"KXBTCPERP1","price":"6.3484","delta":"-1.00","side":"bid","ts_ms":1781237160276}}

{"type":"orderbook_delta","sid":1,"seq":687,"msg":{"market_ticker":"KXBTCPERP1","price":"6.3484","delta":"-1.00","side":"bid","ts_ms":1781237160276}}

{"type":"orderbook_delta","sid":1,"seq":688,"msg":{"market_ticker":"KXBTCPERP1","price":"6.3484","delta":"-1.00","side":"bid","ts_ms":1781237160276}}

{"type":"orderbook_delta","sid":1,"seq":689,"msg":{"market_ticker":"KXBTCPERP1","price":"6.3484","delta":"-1.00","side":"bid","ts_ms":1781237160276}}

{"type":"orderbook_delta","sid":1,"seq":690,"msg":{"market_ticker":"KXBTCPERP1","price":"6.3484","delta":"-1.00","side":"bid","ts_ms":1781237160276}}

{"type":"orderbook_delta","sid":1,"seq":691,"msg":{"market_ticker":"KXBTCPERP1","price":"6.3483","delta":"-1.00","side":"bid","ts_ms":1781237160276}}

{"type":"orderbook_delta","sid":1,"seq":692,"msg":{"market_ticker":"KXBTCPERP1","price":"6.3481","delta":"-1.00","side":"bid","ts_ms":1781237160276}}

{"type":"orderbook_delta","sid":1,"seq":693,"msg":{"market_ticker":"KXBTCPERP1","price":"6.3481","delta":"-1.00","side":"bid","ts_ms":1781237160276}}

{"type":"orderbook_delta","sid":1,"seq":694,"msg":{"market_ticker":"KXBTCPERP1","price":"6.3480","delta":"-1.00","side":"bid","ts_ms":1781237160276}}

{"type":"orderbook_delta","sid":1,"seq":695,"msg":{"market_ticker":"KXBTCPERP1","price":"6.3479","delta":"-1.00","side":"bid","ts_ms":1781237160276}}

{"type":"orderbook_delta","sid":1,"seq":696,"msg":{"market_ticker":"KXBTCPERP1","price":"6.3479","delta":"-1.00","side":"bid","ts_ms":1781237160276}}

{"type":"orderbook_delta","sid":1,"seq":697,"msg":{"market_ticker":"KXBTCPERP1","price":"6.3478","delta":"-1.00","side":"bid","ts_ms":1781237160276}}

{"type":"orderbook_delta","sid":1,"seq":698,"msg":{"market_ticker":"KXBTCPERP1","price":"6.3478","delta":"-1.00","side":"bid","ts_ms":1781237160276}}

{"type":"orderbook_delta","sid":1,"seq":699,"msg":{"market_ticker":"KXBTCPERP1","price":"6.3476","delta":"-1.00","side":"bid","ts_ms":1781237160276}}

{"type":"orderbook_delta","sid":1,"seq":700,"msg":{"market_ticker":"KXBTCPERP1","price":"6.3476","delta":"-1.00","side":"bid","ts_ms":1781237160276}}

{"type":"orderbook_delta","sid":1,"seq":701,"msg":{"market_ticker":"KXBTCPERP1","price":"6.3476","delta":"-1.00","side":"bid","ts_ms":1781237160276}}

{"type":"orderbook_delta","sid":1,"seq":702,"msg":{"market_ticker":"KXBTCPERP1","price":"6.3475","delta":"-1.00","side":"bid","ts_ms":1781237160276}}

{"type":"orderbook_delta","sid":1,"seq":703,"msg":{"market_ticker":"KXBTCPERP1","price":"6.3475","delta":"-1.00","side":"bid","ts_ms":1781237160276}}

{"type":"orderbook_delta","sid":1,"seq":704,"msg":{"market_ticker":"KXBTCPERP1","price":"6.3475","delta":"-1.00","side":"bid","ts_ms":1781237160276}}

{"type":"orderbook_delta","sid":1,"seq":705,"msg":{"market_ticker":"KXBTCPERP1","price":"6.3475","delta":"-1.00","side":"bid","ts_ms":1781237160276}}

{"type":"orderbook_delta","sid":1,"seq":706,"msg":{"market_ticker":"KXBTCPERP1","price":"6.3475","delta":"-1.00","side":"bid","ts_ms":1781237160276}}

{"type":"orderbook_delta","sid":1,"seq":707,"msg":{"market_ticker":"KXBTCPERP1","price":"6.3474","delta":"-1.00","side":"bid","ts_ms":1781237160276}}

{"type":"orderbook_delta","sid":1,"seq":708,"msg":{"market_ticker":"KXBTCPERP1","price":"6.3474","delta":"-1.00","side":"bid","ts_ms":1781237160276}}

{"type":"trade","sid":2,"seq":62,"msg":{"trade_id":"63e3ad48-09a2-6d88-658a-b87cc4c5d41f","market_ticker":"KXBTCPERP1","price":"6.3750","count":"321.00","taker_side":"ask","ts_ms":1781237160276}}

{"type":"trade","sid":2,"seq":63,"msg":{"trade_id":"04c9553c-4ee1-66dd-6873-8f380fa91f56","market_ticker":"KXBTCPERP1","price":"6.3730","count":"1.00","taker_side":"ask","ts_ms":1781237160276}}

{"type":"trade","sid":2,"seq":64,"msg":{"trade_id":"c2c5214a-667c-684a-7375-aac566ef5980","market_ticker":"KXBTCPERP1","price":"6.3642","count":"1.00","taker_side":"ask","ts_ms":1781237160276}}

{"type":"trade","sid":2,"seq":65,"msg":{"trade_id":"745f24c5-f39c-6ccc-573e-3c288c2dbaf5","market_ticker":"KXBTCPERP1","price":"6.3642","count":"1.00","taker_side":"ask","ts_ms":1781237160276}}

{"type":"trade","sid":2,"seq":66,"msg":{"trade_id":"dd49ef60-5e29-6f7c-60e2-45fcb30d8224","market_ticker":"KXBTCPERP1","price":"6.3642","count":"1.00","taker_side":"ask","ts_ms":1781237160276}}

{"type":"trade","sid":2,"seq":67,"msg":{"trade_id":"d92f28a9-50fa-62a0-6845-87ca84e56734","market_ticker":"KXBTCPERP1","price":"6.3641","count":"1.00","taker_side":"ask","ts_ms":1781237160276}}

{"type":"trade","sid":2,"seq":68,"msg":{"trade_id":"457aa49d-e4b0-67e9-75ee-4a6b5fb21963","market_ticker":"KXBTCPERP1","price":"6.3641","count":"1.00","taker_side":"ask","ts_ms":1781237160276}}

{"type":"trade","sid":2,"seq":69,"msg":{"trade_id":"8a47be9b-632e-6010-6ada-bde77ae09446","market_ticker":"KXBTCPERP1","price":"6.3640","count":"1.00","taker_side":"ask","ts_ms":1781237160276}}

{"type":"trade","sid":2,"seq":70,"msg":{"trade_id":"ffa08451-3d59-6781-6c34-e86943508ebc","market_ticker":"KXBTCPERP1","price":"6.3640","count":"1.00","taker_side":"ask","ts_ms":1781237160276}}

{"type":"trade","sid":2,"seq":71,"msg":{"trade_id":"80f33c77-e36c-6912-5846-c65c4c8def94","market_ticker":"KXBTCPERP1","price":"6.3639","count":"1.00","taker_side":"ask","ts_ms":1781237160276}}

{"type":"trade","sid":2,"seq":72,"msg":{"trade_id":"430b9d97-655b-6d58-4821-c8627df21389","market_ticker":"KXBTCPERP1","price":"6.3639","count":"1.00","taker_side":"ask","ts_ms":1781237160276}}

{"type":"trade","sid":2,"seq":73,"msg":{"trade_id":"a8976eca-dcbf-6268-786f-f3ceaea15e45","market_ticker":"KXBTCPERP1","price":"6.3639","count":"1.00","taker_side":"ask","ts_ms":1781237160276}}

{"type":"trade","sid":2,"seq":74,"msg":{"trade_id":"d971bc8b-9818-6767-52ba-e1fe9dd35506","market_ticker":"KXBTCPERP1","price":"6.3639","count":"1.00","taker_side":"ask","ts_ms":1781237160276}}

{"type":"trade","sid":2,"seq":75,"msg":{"trade_id":"96aab60e-8330-6c39-65ae-90b83dd1e8a8","market_ticker":"KXBTCPERP1","price":"6.3639","count":"1.00","taker_side":"ask","ts_ms":1781237160276}}

{"type":"trade","sid":2,"seq":76,"msg":{"trade_id":"af739507-4c2d-6527-47b5-d99b01b76d4f","market_ticker":"KXBTCPERP1","price":"6.3639","count":"1.00","taker_side":"ask","ts_ms":1781237160276}}

{"type":"trade","sid":2,"seq":77,"msg":{"trade_id":"6ec78a82-a50c-6ad9-4230-23d32c792110","market_ticker":"KXBTCPERP1","price":"6.3638","count":"1.00","taker_side":"ask","ts_ms":1781237160276}}

{"type":"trade","sid":2,"seq":78,"msg":{"trade_id":"40cf01ad-6e4c-6a69-5769-7542c1e4d845","market_ticker":"KXBTCPERP1","price":"6.3638","count":"1.00","taker_side":"ask","ts_ms":1781237160276}}

{"type":"trade","sid":2,"seq":79,"msg":{"trade_id":"49bf0785-ecdf-6741-7766-d37da2e041f9","market_ticker":"KXBTCPERP1","price":"6.3637","count":"1.00","taker_side":"ask","ts_ms":1781237160276}}

{"type":"orderbook_delta","sid":1,"seq":709,"msg":{"market_ticker":"KXBTCPERP1","price":"6.3473","delta":"-1.00","side":"bid","ts_ms":1781237160276}}

{"type":"trade","sid":2,"seq":80,"msg":{"trade_id":"5ccc5b81-af5f-6257-4875-457fab9d00aa","market_ticker":"KXBTCPERP1","price":"6.3637","count":"1.00","taker_side":"ask","ts_ms":1781237160276}}

{"type":"orderbook_delta","sid":1,"seq":710,"msg":{"market_ticker":"KXBTCPERP1","price":"6.3473","delta":"-1.00","side":"bid","ts_ms":1781237160276}}

{"type":"trade","sid":2,"seq":81,"msg":{"trade_id":"231f0869-b3ea-6f82-5e99-cc482c05458b","market_ticker":"KXBTCPERP1","price":"6.3636","count":"1.00","taker_side":"ask","ts_ms":1781237160276}}

{"type":"orderbook_delta","sid":1,"seq":711,"msg":{"market_ticker":"KXBTCPERP1","price":"6.3936","delta":"-783.00","side":"ask","ts_ms":1781237160276}}

{"type":"trade","sid":2,"seq":82,"msg":{"trade_id":"d73b92ce-e4f9-65c6-791f-850b2a514902","market_ticker":"KXBTCPERP1","price":"6.3636","count":"1.00","taker_side":"ask","ts_ms":1781237160276}}

{"type":"trade","sid":2,"seq":83,"msg":{"trade_id":"b5fcdd48-dbc9-646f-53b0-dd1abbc47433","market_ticker":"KXBTCPERP1","price":"6.3636","count":"1.00","taker_side":"ask","ts_ms":1781237160276}}

{"type":"trade","sid":2,"seq":84,"msg":{"trade_id":"8149b3b4-15e2-6633-6aa3-ba4d05f8872c","market_ticker":"KXBTCPERP1","price":"6.3636","count":"1.00","taker_side":"ask","ts_ms":1781237160276}}

{"type":"trade","sid":2,"seq":85,"msg":{"trade_id":"94e77b60-3184-648a-7d34-f1df3891a16d","market_ticker":"KXBTCPERP1","price":"6.3635","count":"1.00","taker_side":"ask","ts_ms":1781237160276}}

{"type":"trade","sid":2,"seq":86,"msg":{"trade_id":"7abb3169-022f-60dc-5680-283aebd1a51f","market_ticker":"KXBTCPERP1","price":"6.3635","count":"1.00","taker_side":"ask","ts_ms":1781237160276}}

{"type":"trade","sid":2,"seq":87,"msg":{"trade_id":"881334aa-dc24-6963-528e-b292994182b2","market_ticker":"KXBTCPERP1","price":"6.3635","count":"1.00","taker_side":"ask","ts_ms":1781237160276}}

{"type":"trade","sid":2,"seq":88,"msg":{"trade_id":"f6b55514-814d-6e14-529e-e9b7dedb0a43","market_ticker":"KXBTCPERP1","price":"6.3634","count":"1.00","taker_side":"ask","ts_ms":1781237160276}}

{"type":"trade","sid":2,"seq":89,"msg":{"trade_id":"6b525a96-5494-6fe4-6a1c-86d3ae8ea126","market_ticker":"KXBTCPERP1","price":"6.3634","count":"1.00","taker_side":"ask","ts_ms":1781237160276}}

{"type":"trade","sid":2,"seq":90,"msg":{"trade_id":"d4c0456a-30ea-6119-7a53-d5e5b07091f3","market_ticker":"KXBTCPERP1","price":"6.3634","count":"1.00","taker_side":"ask","ts_ms":1781237160276}}

{"type":"trade","sid":2,"seq":91,"msg":{"trade_id":"699bf593-1192-6878-5b1b-d63c801231d6","market_ticker":"KXBTCPERP1","price":"6.3634","count":"1.00","taker_side":"ask","ts_ms":1781237160276}}

{"type":"trade","sid":2,"seq":92,"msg":{"trade_id":"c124f06a-44a8-692f-6083-037e4c359b72","market_ticker":"KXBTCPERP1","price":"6.3634","count":"1.00","taker_side":"ask","ts_ms":1781237160276}}

{"type":"trade","sid":2,"seq":93,"msg":{"trade_id":"90f7d70c-b5a9-6ba2-6122-410befc15f01","market_ticker":"KXBTCPERP1","price":"6.3634","count":"1.00","taker_side":"ask","ts_ms":1781237160276}}

{"type":"trade","sid":2,"seq":94,"msg":{"trade_id":"a2c9a49a-f026-6051-4f84-832539f4c0b0","market_ticker":"KXBTCPERP1","price":"6.3633","count":"1.00","taker_side":"ask","ts_ms":1781237160276}}

{"type":"trade","sid":2,"seq":95,"msg":{"trade_id":"b14eb56c-b5f4-6da9-7352-2264f7ba3e42","market_ticker":"KXBTCPERP1","price":"6.3632","count":"1.00","taker_side":"ask","ts_ms":1781237160276}}

{"type":"trade","sid":2,"seq":96,"msg":{"trade_id":"18aa850d-cb58-6741-5a5e-6d8f3a62d8e5","market_ticker":"KXBTCPERP1","price":"6.3632","count":"1.00","taker_side":"ask","ts_ms":1781237160276}}

{"type":"trade","sid":2,"seq":97,"msg":{"trade_id":"22c625f9-a4c6-618e-72c6-5a4435256ac5","market_ticker":"KXBTCPERP1","price":"6.3632","count":"1.00","taker_side":"ask","ts_ms":1781237160276}}

{"type":"trade","sid":2,"seq":98,"msg":{"trade_id":"ec9c410e-d362-6f27-5ebe-5d0f264c2974","market_ticker":"KXBTCPERP1","price":"6.3632","count":"1.00","taker_side":"ask","ts_ms":1781237160276}}

{"type":"trade","sid":2,"seq":99,"msg":{"trade_id":"6d8f077c-3adf-6b38-7b34-99dcc1f449b0","market_ticker":"KXBTCPERP1","price":"6.3631","count":"1.00","taker_side":"ask","ts_ms":1781237160276}}

{"type":"trade","sid":2,"seq":100,"msg":{"trade_id":"ab597cee-5843-6a37-5f39-f13a15b52c89","market_ticker":"KXBTCPERP1","price":"6.3631","count":"1.00","taker_side":"ask","ts_ms":1781237160276}}

{"type":"trade","sid":2,"seq":101,"msg":{"trade_id":"92d5f746-77ce-68bf-4d07-15fd92ad4139","market_ticker":"KXBTCPERP1","price":"6.3630","count":"1.00","taker_side":"ask","ts_ms":1781237160276}}

{"type":"trade","sid":2,"seq":102,"msg":{"trade_id":"46d7e9b6-ecf0-6747-6b0f-18cf989da0b5","market_ticker":"KXBTCPERP1","price":"6.3630","count":"1.00","taker_side":"ask","ts_ms":1781237160276}}

{"type":"trade","sid":2,"seq":103,"msg":{"trade_id":"6945c1d2-895f-66bc-4796-9478d450786e","market_ticker":"KXBTCPERP1","price":"6.3630","count":"1.00","taker_side":"ask","ts_ms":1781237160276}}

{"type":"trade","sid":2,"seq":104,"msg":{"trade_id":"28f7d567-3ace-6002-4aff-25b4683cc950","market_ticker":"KXBTCPERP1","price":"6.3629","count":"1.00","taker_side":"ask","ts_ms":1781237160276}}

{"type":"trade","sid":2,"seq":105,"msg":{"trade_id":"36b2261f-26de-64de-485d-d21f2863a4e6","market_ticker":"KXBTCPERP1","price":"6.3629","count":"1.00","taker_side":"ask","ts_ms":1781237160276}}

{"type":"trade","sid":2,"seq":106,"msg":{"trade_id":"7f66bcf5-a574-6aee-74d7-229d3783e43c","market_ticker":"KXBTCPERP1","price":"6.3628","count":"1.00","taker_side":"ask","ts_ms":1781237160276}}

{"type":"trade","sid":2,"seq":107,"msg":{"trade_id":"0d56b5e6-bdd5-66ad-4ba0-61a52d98e66d","market_ticker":"KXBTCPERP1","price":"6.3627","count":"1.00","taker_side":"ask","ts_ms":1781237160276}}

{"type":"trade","sid":2,"seq":108,"msg":{"trade_id":"343b93a6-e948-663d-53f4-c702c38c7db3","market_ticker":"KXBTCPERP1","price":"6.3626","count":"1.00","taker_side":"ask","ts_ms":1781237160276}}

{"type":"trade","sid":2,"seq":109,"msg":{"trade_id":"c942c6f0-fd32-62ce-7445-ecf379f3e9c5","market_ticker":"KXBTCPERP1","price":"6.3626","count":"1.00","taker_side":"ask","ts_ms":1781237160276}}

{"type":"trade","sid":2,"seq":110,"msg":{"trade_id":"b63630bd-6609-6b7d-50d4-2de4b33c39d7","market_ticker":"KXBTCPERP1","price":"6.3625","count":"1.00","taker_side":"ask","ts_ms":1781237160276}}

{"type":"trade","sid":2,"seq":111,"msg":{"trade_id":"2542e2dd-8248-63c1-5479-fa4af1efc762","market_ticker":"KXBTCPERP1","price":"6.3625","count":"1.00","taker_side":"ask","ts_ms":1781237160276}}

{"type":"trade","sid":2,"seq":112,"msg":{"trade_id":"f1e8c11b-d4a1-6bde-626e-8f565e8ed3b8","market_ticker":"KXBTCPERP1","price":"6.3625","count":"1.00","taker_side":"ask","ts_ms":1781237160276}}

{"type":"trade","sid":2,"seq":113,"msg":{"trade_id":"def27b94-ef81-6bc9-52ca-44412cf23683","market_ticker":"KXBTCPERP1","price":"6.3624","count":"1.00","taker_side":"ask","ts_ms":1781237160276}}

{"type":"trade","sid":2,"seq":114,"msg":{"trade_id":"1848c430-0ead-6d4f-58ef-42f2339adaa5","market_ticker":"KXBTCPERP1","price":"6.3624","count":"1.00","taker_side":"ask","ts_ms":1781237160276}}

{"type":"trade","sid":2,"seq":115,"msg":{"trade_id":"4d50862e-4850-6261-7596-594455107021","market_ticker":"KXBTCPERP1","price":"6.3624","count":"1.00","taker_side":"ask","ts_ms":1781237160276}}

{"type":"trade","sid":2,"seq":116,"msg":{"trade_id":"c1f07c89-6812-68c5-7ab5-9b291a4fa2c4","market_ticker":"KXBTCPERP1","price":"6.3624","count":"1.00","taker_side":"ask","ts_ms":1781237160276}}

{"type":"trade","sid":2,"seq":117,"msg":{"trade_id":"208680fd-8973-610d-527e-d032303ee8db","market_ticker":"KXBTCPERP1","price":"6.3624","count":"1.00","taker_side":"ask","ts_ms":1781237160276}}

{"type":"trade","sid":2,"seq":118,"msg":{"trade_id":"74edf18b-bb62-626d-4769-2098116d65a0","market_ticker":"KXBTCPERP1","price":"6.3623","count":"1.00","taker_side":"ask","ts_ms":1781237160276}}

{"type":"trade","sid":2,"seq":119,"msg":{"trade_id":"a42185d7-e692-66c2-4037-7ed7db6b0869","market_ticker":"KXBTCPERP1","price":"6.3623","count":"1.00","taker_side":"ask","ts_ms":1781237160276}}

{"type":"trade","sid":2,"seq":120,"msg":{"trade_id":"a2e313b8-1e60-63eb-53e5-81be87205aa3","market_ticker":"KXBTCPERP1","price":"6.3623","count":"1.00","taker_side":"ask","ts_ms":1781237160276}}

{"type":"trade","sid":2,"seq":121,"msg":{"trade_id":"4d5bde0d-913d-6e30-5347-3362958689ff","market_ticker":"KXBTCPERP1","price":"6.3623","count":"1.00","taker_side":"ask","ts_ms":1781237160276}}

{"type":"trade","sid":2,"seq":122,"msg":{"trade_id":"6add5471-ea62-65d3-7802-69c53fa6fed7","market_ticker":"KXBTCPERP1","price":"6.3622","count":"1.00","taker_side":"ask","ts_ms":1781237160276}}

{"type":"trade","sid":2,"seq":123,"msg":{"trade_id":"db561657-4b3e-6a1a-58e1-c8b4cca55987","market_ticker":"KXBTCPERP1","price":"6.3621","count":"1.00","taker_side":"ask","ts_ms":1781237160276}}

{"type":"trade","sid":2,"seq":124,"msg":{"trade_id":"f778b202-b0c7-6cf7-7226-480f379e7cbd","market_ticker":"KXBTCPERP1","price":"6.3620","count":"1.00","taker_side":"ask","ts_ms":1781237160276}}

{"type":"trade","sid":2,"seq":125,"msg":{"trade_id":"fba621f3-2f2d-6a45-709f-9588e1262c9c","market_ticker":"KXBTCPERP1","price":"6.3620","count":"1.00","taker_side":"ask","ts_ms":1781237160276}}

{"type":"trade","sid":2,"seq":126,"msg":{"trade_id":"e0e0d521-a5f0-6c5f-6070-f3c885a29b11","market_ticker":"KXBTCPERP1","price":"6.3620","count":"1.00","taker_side":"ask","ts_ms":1781237160276}}

{"type":"trade","sid":2,"seq":127,"msg":{"trade_id":"c5e71c94-6cd0-67d1-5dc1-46de82aa3282","market_ticker":"KXBTCPERP1","price":"6.3620","count":"1.00","taker_side":"ask","ts_ms":1781237160276}}

{"type":"trade","sid":2,"seq":128,"msg":{"trade_id":"473c78ce-be53-6a20-7e0e-9cd6489a8061","market_ticker":"KXBTCPERP1","price":"6.3620","count":"1.00","taker_side":"ask","ts_ms":1781237160276}}

{"type":"trade","sid":2,"seq":129,"msg":{"trade_id":"ca6210e3-65eb-677d-6df8-496b6e30b6d3","market_ticker":"KXBTCPERP1","price":"6.3619","count":"1.00","taker_side":"ask","ts_ms":1781237160276}}

{"type":"trade","sid":2,"seq":130,"msg":{"trade_id":"67e2bdbb-b8a7-64db-4383-0f42cf7eede6","market_ticker":"KXBTCPERP1","price":"6.3619","count":"1.00","taker_side":"ask","ts_ms":1781237160276}}

{"type":"trade","sid":2,"seq":131,"msg":{"trade_id":"8fc721a5-d4e4-6865-6a8c-0ce5f675bd78","market_ticker":"KXBTCPERP1","price":"6.3618","count":"1.00","taker_side":"ask","ts_ms":1781237160276}}

{"type":"trade","sid":2,"seq":132,"msg":{"trade_id":"01f85b5e-a392-6979-5d6b-02c23f69c582","market_ticker":"KXBTCPERP1","price":"6.3618","count":"1.00","taker_side":"ask","ts_ms":1781237160276}}

{"type":"trade","sid":2,"seq":133,"msg":{"trade_id":"4a98338f-304e-6dde-78ba-0820e765854e","market_ticker":"KXBTCPERP1","price":"6.3617","count":"1.00","taker_side":"ask","ts_ms":1781237160276}}

{"type":"trade","sid":2,"seq":134,"msg":{"trade_id":"13f28060-380a-6a1d-7c0d-93d7b352788e","market_ticker":"KXBTCPERP1","price":"6.3617","count":"1.00","taker_side":"ask","ts_ms":1781237160276}}

{"type":"trade","sid":2,"seq":135,"msg":{"trade_id":"31f5227e-4b9a-6b0d-6c54-2dbfcb9df88e","market_ticker":"KXBTCPERP1","price":"6.3617","count":"1.00","taker_side":"ask","ts_ms":1781237160276}}

